File: spin_crossover/dane/Trt_TEOS — kopia/Big TEOS/FeTrz_Trt_big_XTvT_MCE.rso.dat
[Header]
TITLE,MPMS RSO Measurement
BYAPP,MPMS Measurement,1.1,Summary
FILEOPENTIME, 1656688876.396000 7/1/2022, 5:21:16 PM

INFO, APPNAME, MPMS MultiVu Application, Revision 1.60,  Build 081

INFO, NAME, FeTrz_Trt_big
INFO, WEIGHT, 6.310
INFO, AREA, 0.000
INFO, LENGTH, 0.000
INFO, SHAPE, 0
INFO, COMMENT, w torebce papierowej, na drucie Cu
INFO, SEQUENCE FILE: FeTrz_HTvT_MCE_reverse.seq


INFO, BACKGROUND DATA FILE:, None


STARTUPAXIS,X,4,LINEAR,AUTO,0.000000,0.000000
STARTUPAXIS,Y1,5,LINEAR,AUTO,0.000000,0.000000


STARTUPGROUP,Longitudinal
FIELDGROUP,Longitudinal,1,2,3,4,5,6,7,8,9,10,11,19,20,21,22,23,35
FIELDGROUP,Transverse,1,2,3,4,12,13,14,15,16,17,18,24,25,26,27,28,35

PLOT_APPEARANCE,ALL,HORZ_GRID_ON,VERT_GRID_ON,MARKERS_AND_LINES

[Data]
Time,Comment,Field (Oe),Temperature (K),Long Moment (emu),Long Scan Std Dev,Long Offset (cm),Long Offset Std Dev,Long Algorithm,Long Reg Fit,Long Reg Factor,Trans Moment (emu),Trans Scan Std Dev,Trans Offset (cm),Trans Offset Std Dev,Trans Algorithm,Trans Reg Fit,Trans Reg Factor,Long Moment [w/o ABS] (emu),Long Scan Std Dev [w/o ABS],Long Offset [w/o ABS] (cm),Long Offset Std Dev [w/o ABS],Long Reg Fit [w/o ABS],Trans Moment [w/o ABS] (emu),Trans Scan Std Dev [w/o ABS],Trans Offset [w/o ABS] (cm),Trans Offset Std Dev [w/o ABS],Trans Reg Fit [w/o ABS],RSO Position (deg),Amplitude (cm),Frequency,Cycles to Average,Scans per Measurement,Delta Temp (K),Error,EC Comp. Running,Using ABS,
1656688876.396,,7.000000e+004,4.000002e+002,9.037551e-003,3.292723e-007,-1.388583e-001,5.793084e-005,3,9.801284e-001,1.825000e+000,,,,,,,,,,,,,,,,,,0,4.000000e+000,1.000000e+000,2,2,1.300049e-002,0,,0,
1656689770.046,,7.000000e+004,3.691784e+002,9.496432e-003,5.126110e-006,-1.204459e-001,2.504260e-004,3,9.811668e-001,1.825000e+000,,,,,,,,,,,,,,,,,,0,4.000000e+000,1.000000e+000,2,2,8.578186e-001,0,,0,
1656690550.333,,7.000000e+004,3.418715e+002,2.953390e-003,2.090944e-008,-5.924709e-003,2.014488e-006,3,9.384273e-001,1.825000e+000,,,,,,,,,,,,,,,,,,0,4.000000e+000,1.000000e+000,2,2,1.871948e-001,0,,0,
1656691507.927,,7.000000e+004,3.124796e+002,2.983680e-003,8.137964e-007,4.898620e-003,1.194448e-004,3,9.386050e-001,1.825000e+000,,,,,,,,,,,,,,,,,,0,4.000000e+000,1.000000e+000,2,2,6.337891e-001,0,,0,
1656692933.851,,7.000000e+004,3.152455e+002,2.959168e-003,1.460323e-007,3.650706e-004,7.569825e-005,3,9.382133e-001,1.825000e+000,,,,,,,,,,,,,,,,,,0,4.000000e+000,1.000000e+000,2,2,3.859863e-001,0,,0,
1656693818.684,,7.000000e+004,3.442776e+002,2.906305e-003,1.340138e-007,-1.310925e-002,4.065129e-005,3,9.377591e-001,1.825000e+000,,,,,,,,,,,,,,,,,,0,4.000000e+000,1.000000e+000,2,2,4.082947e-001,0,,0,
1656694693.099,,7.000000e+004,3.732827e+002,3.277048e-003,7.862116e-005,-4.410400e-002,2.514829e-003,3,9.450557e-001,1.825000e+000,,,,,,,,,,,,,,,,,,0,4.000000e+000,1.000000e+000,2,2,4.051208e-001,0,,0,
1656696234.442,,6.500000e+004,3.988320e+002,8.485860e-003,2.071781e-006,-1.321153e-001,6.692920e-005,3,9.812391e-001,1.825000e+000,,,,,,,,,,,,,,,,,,0,4.000000e+000,1.000000e+000,2,2,2.445984e-001,0,,0,
1656697060.875,,6.500000e+004,3.683365e+002,8.901212e-003,1.154429e-006,-1.158663e-001,3.312110e-004,3,9.817584e-001,1.825000e+000,,,,,,,,,,,,,,,,,,0,4.000000e+000,1.000000e+000,2,2,8.860168e-001,0,,0,
1656698089.116,,6.500000e+004,3.406552e+002,2.747753e-003,4.878169e-007,-5.492003e-003,4.753374e-005,3,9.396241e-001,1.825000e+000,,,,,,,,,,,,,,,,,,0,4.000000e+000,1.000000e+000,2,2,4.455872e-001,0,,0,
1656698814.520,,6.500000e+004,3.112059e+002,2.784870e-003,1.162825e-006,6.694171e-003,4.386206e-004,3,9.388067e-001,1.825000e+000,,,,,,,,,,,,,,,,,,0,4.000000e+000,1.000000e+000,2,2,6.129150e-001,0,,0,
1656700264.463,,6.500000e+004,3.163088e+002,2.755630e-003,7.016792e-007,5.826760e-004,4.165463e-005,3,9.381249e-001,1.825000e+000,,,,,,,,,,,,,,,,,,0,4.000000e+000,1.000000e+000,2,2,3.966980e-001,0,,0,
1656701147.790,,6.500000e+004,3.452562e+002,2.706078e-003,7.156733e-007,-1.324045e-002,7.632070e-005,3,9.378593e-001,1.825000e+000,,,,,,,,,,,,,,,,,,0,4.000000e+000,1.000000e+000,2,2,4.011841e-001,0,,0,
1656702033.919,,6.500000e+004,3.742785e+002,6.338311e-003,2.068916e-004,-1.106086e-001,1.942912e-003,3,9.731867e-001,1.825000e+000,,,,,,,,,,,,,,,,,,0,4.000000e+000,1.000000e+000,2,2,3.508911e-001,0,,0,
1656703581.857,,6.000000e+004,3.978300e+002,7.863794e-003,1.674020e-006,-1.311392e-001,3.550872e-005,3,9.814515e-001,1.825000e+000,,,,,,,,,,,,,,,,,,0,4.000000e+000,1.000000e+000,2,2,2.947998e-001,0,,0,
1656704384.472,,6.000000e+004,3.671097e+002,8.242506e-003,1.356602e-006,-1.152155e-001,1.972683e-004,3,9.820532e-001,1.825000e+000,,,,,,,,,,,,,,,,,,0,4.000000e+000,1.000000e+000,2,2,6.846008e-001,0,,0,
1656705415.328,,6.000000e+004,3.395977e+002,2.539729e-003,1.433982e-007,-4.993732e-003,1.667040e-004,3,9.391649e-001,1.825000e+000,,,,,,,,,,,,,,,,,,0,4.000000e+000,1.000000e+000,2,2,5.995789e-001,0,,0,
1656706134.810,,6.000000e+004,3.104151e+002,2.578157e-003,6.447151e-007,6.810671e-003,2.731284e-004,3,9.389632e-001,1.825000e+000,,,,,,,,,,,,,,,,,,0,4.000000e+000,1.000000e+000,2,2,7.924805e-001,0,,0,
1656707587.031,,6.000000e+004,3.172379e+002,2.546681e-003,5.036219e-007,-3.334069e-004,3.691195e-004,3,9.383951e-001,1.825000e+000,,,,,,,,,,,,,,,,,,0,4.000000e+000,1.000000e+000,2,2,3.592834e-001,0,,0,
1656708474.662,,6.000000e+004,3.462527e+002,2.502691e-003,3.929865e-007,-1.415477e-002,1.607422e-004,3,9.379421e-001,1.825000e+000,,,,,,,,,,,,,,,,,,0,4.000000e+000,1.000000e+000,2,2,4.229126e-001,0,,0,
1656709361.542,,6.000000e+004,3.753197e+002,7.559466e-003,6.153966e-005,-1.241044e-001,5.054672e-004,3,9.799799e-001,1.825000e+000,,,,,,,,,,,,,,,,,,0,4.000000e+000,1.000000e+000,2,2,4.096985e-001,0,,0,
1656710925.839,,5.500000e+004,3.967112e+002,7.231190e-003,2.927560e-006,-1.304694e-001,2.756509e-004,3,9.816219e-001,1.825000e+000,,,,,,,,,,,,,,,,,,0,4.000000e+000,1.000000e+000,2,2,5.484009e-001,0,,0,
1656711704.351,,5.500000e+004,3.665618e+002,7.572416e-003,1.313800e-007,-1.149725e-001,2.671794e-004,3,9.822695e-001,1.825000e+000,,,,,,,,,,,,,,,,,,0,4.000000e+000,1.000000e+000,2,2,8.988953e-001,0,,0,
1656712735.184,,5.500000e+004,3.385038e+002,2.330265e-003,2.825156e-007,-4.399723e-003,2.776220e-004,3,9.392945e-001,1.825000e+000,,,,,,,,,,,,,,,,,,0,4.000000e+000,1.000000e+000,2,2,9.069824e-001,0,,0,
1656713456.194,,5.500000e+004,3.095620e+002,2.367231e-003,2.742838e-007,6.959793e-003,3.997102e-005,3,9.388367e-001,1.825000e+000,,,,,,,,,,,,,,,,,,0,4.000000e+000,1.000000e+000,2,2,4.772034e-001,0,,0,
1656714923.664,,5.500000e+004,3.182633e+002,2.335188e-003,4.053341e-007,-8.261640e-004,4.417776e-005,3,9.386520e-001,1.825000e+000,,,,,,,,,,,,,,,,,,0,4.000000e+000,1.000000e+000,2,2,4.099121e-001,0,,0,
1656715797.713,,5.500000e+004,3.472141e+002,2.296785e-003,2.568324e-008,-1.419258e-002,9.246953e-005,3,9.378644e-001,1.825000e+000,,,,,,,,,,,,,,,,,,0,4.000000e+000,1.000000e+000,2,2,3.578186e-001,0,,0,
1656716678.025,,5.500000e+004,3.762639e+002,7.197293e-003,6.742178e-006,-1.267349e-001,2.294685e-004,3,9.809659e-001,1.825000e+000,,,,,,,,,,,,,,,,,,0,4.000000e+000,1.000000e+000,2,2,4.003906e-001,0,,0,
1656718222.522,,5.000000e+004,3.955980e+002,6.594460e-003,4.041817e-006,-1.290457e-001,1.427514e-004,3,9.816779e-001,1.825000e+000,,,,,,,,,,,,,,,,,,0,4.000000e+000,1.000000e+000,2,2,7.742004e-001,0,,0,
1656718987.979,,5.000000e+004,3.655545e+002,6.893585e-003,4.448469e-007,-1.136593e-001,1.664221e-004,3,9.824602e-001,1.825000e+000,,,,,,,,,,,,,,,,,,0,4.000000e+000,1.000000e+000,2,2,7.755127e-001,0,,0,
1656720015.361,,5.000000e+004,3.373853e+002,2.119267e-003,1.141916e-006,-3.073161e-003,2.913458e-004,3,9.396869e-001,1.825000e+000,,,,,,,,,,,,,,,,,,0,4.000000e+000,1.000000e+000,2,2,9.461060e-001,0,,0,
1656720735.693,,5.000000e+004,3.086275e+002,2.156772e-003,1.249917e-006,8.293416e-003,9.330324e-005,3,9.393326e-001,1.825000e+000,,,,,,,,,,,,,,,,,,0,4.000000e+000,1.000000e+000,2,2,4.815979e-001,0,,0,
1656722205.482,,5.000000e+004,3.192674e+002,2.122715e-003,6.598616e-007,-2.820348e-005,1.853230e-004,3,9.384586e-001,1.825000e+000,,,,,,,,,,,,,,,,,,0,4.000000e+000,1.000000e+000,2,2,4.126892e-001,0,,0,
1656723074.588,,5.000000e+004,3.482664e+002,2.091158e-003,1.236418e-007,-1.412482e-002,6.038985e-005,3,9.385740e-001,1.825000e+000,,,,,,,,,,,,,,,,,,0,4.000000e+000,1.000000e+000,2,2,4.183960e-001,0,,0,
1656723943.846,,5.000000e+004,3.772535e+002,6.623087e-003,4.853144e-006,-1.270275e-001,1.519815e-004,3,9.817377e-001,1.825000e+000,,,,,,,,,,,,,,,,,,0,4.000000e+000,1.000000e+000,2,2,4.141235e-001,0,,0,
1656725476.162,,4.500000e+004,3.944870e+002,5.947459e-003,3.245637e-006,-1.270019e-001,6.044912e-005,3,9.817525e-001,1.825000e+000,,,,,,,,,,,,,,,,,,0,4.000000e+000,1.000000e+000,2,2,7.573853e-001,0,,0,
1656726241.614,,4.500000e+004,3.645502e+002,6.208501e-003,5.291406e-007,-1.117221e-001,2.277616e-004,3,9.824158e-001,1.825000e+000,,,,,,,,,,,,,,,,,,0,4.000000e+000,1.000000e+000,2,2,6.638184e-001,0,,0,
1656727268.789,,4.500000e+004,3.361977e+002,1.906127e-003,1.299226e-006,-1.065264e-003,2.123388e-004,3,9.394358e-001,1.825000e+000,,,,,,,,,,,,,,,,,,0,4.000000e+000,1.000000e+000,2,2,8.218994e-001,0,,0,
1656727995.705,,4.500000e+004,3.077083e+002,1.942834e-003,8.325649e-007,9.847984e-003,1.085966e-004,3,9.396425e-001,1.825000e+000,,,,,,,,,,,,,,,,,,0,4.000000e+000,1.000000e+000,2,2,4.187927e-001,0,,0,
1656734546.177,,4.500000e+004,3.202519e+002,1.903667e-003,2.008561e-008,-6.371619e-003,2.261649e-004,3,9.386107e-001,1.825000e+000,,,,,,,,,,,,,,,,,,0,4.000000e+000,1.000000e+000,2,2,4.397888e-001,0,,0,
1656735415.665,,4.500000e+004,3.492496e+002,1.876416e-003,4.162825e-007,-1.858859e-002,7.616989e-005,3,9.387234e-001,1.825000e+000,,,,,,,,,,,,,,,,,,0,4.000000e+000,1.000000e+000,2,2,4.110718e-001,0,,0,
1656736286.722,,4.500000e+004,3.782744e+002,5.986636e-003,1.769838e-006,-1.318437e-001,2.183312e-004,3,9.815172e-001,1.825000e+000,,,,,,,,,,,,,,,,,,0,4.000000e+000,1.000000e+000,2,2,4.049072e-001,0,,0,
1656737801.324,,4.000000e+004,3.934703e+002,5.291469e-003,2.593677e-006,-1.294541e-001,1.484939e-004,3,9.814634e-001,1.825000e+000,,,,,,,,,,,,,,,,,,0,4.000000e+000,1.000000e+000,2,2,8.161926e-001,0,,0,
1656738568.342,,4.000000e+004,3.637249e+002,5.516199e-003,3.957852e-007,-1.132785e-001,1.543365e-004,3,9.822049e-001,1.825000e+000,,,,,,,,,,,,,,,,,,0,4.000000e+000,1.000000e+000,2,2,5.862122e-001,0,,0,
1656739590.186,,4.000000e+004,3.352904e+002,1.691108e-003,2.518110e-007,-1.950067e-003,2.930918e-004,3,9.394287e-001,1.825000e+000,,,,,,,,,,,,,,,,,,0,4.000000e+000,1.000000e+000,2,2,8.441772e-001,0,,0,
1656740333.585,,4.000000e+004,3.067950e+002,1.727420e-003,3.586598e-007,9.545057e-003,1.924623e-004,3,9.395635e-001,1.825000e+000,,,,,,,,,,,,,,,,,,0,4.000000e+000,1.000000e+000,2,2,3.715820e-001,0,,0,
1656741814.264,,4.000000e+004,3.213782e+002,1.693468e-003,6.223246e-008,3.582262e-004,1.456972e-005,3,9.387021e-001,1.825000e+000,,,,,,,,,,,,,,,,,,0,4.000000e+000,1.000000e+000,2,2,4.021912e-001,0,,0,
1656742679.515,,4.000000e+004,3.502582e+002,1.672378e-003,1.928712e-007,-1.358293e-002,2.969904e-005,3,9.391459e-001,1.825000e+000,,,,,,,,,,,,,,,,,,0,4.000000e+000,1.000000e+000,2,2,4.234009e-001,0,,0,
1656743547.530,,4.000000e+004,3.792110e+002,5.344004e-003,1.183734e-006,-1.264691e-001,7.260848e-005,3,9.817740e-001,1.825000e+000,,,,,,,,,,,,,,,,,,0,4.000000e+000,1.000000e+000,2,2,4.069824e-001,0,,0,
1656745049.456,,3.500000e+004,3.923280e+002,4.637740e-003,2.802765e-006,-1.234214e-001,2.132789e-004,3,9.814329e-001,1.825000e+000,,,,,,,,,,,,,,,,,,0,4.000000e+000,1.000000e+000,2,2,8.610840e-001,0,,0,
1656745816.933,,3.500000e+004,3.629565e+002,4.822833e-003,5.788606e-007,-1.081058e-001,6.201908e-005,3,9.822454e-001,1.825000e+000,,,,,,,,,,,,,,,,,,0,4.000000e+000,1.000000e+000,2,2,5.307007e-001,0,,0,
1656746837.865,,3.500000e+004,3.339983e+002,1.478556e-003,2.593032e-008,2.589875e-003,5.790878e-004,3,9.395001e-001,1.825000e+000,,,,,,,,,,,,,,,,,,0,4.000000e+000,1.000000e+000,2,2,1.042206e+000,0,,0,
1656747611.821,,3.500000e+004,3.058579e+002,1.512645e-003,5.367961e-007,1.230391e-002,2.046440e-004,3,9.397305e-001,1.825000e+000,,,,,,,,,,,,,,,,,,0,4.000000e+000,1.000000e+000,2,2,1.772156e-001,0,,0,
1656749077.107,,3.500000e+004,3.222279e+002,1.479916e-003,1.591208e-007,1.626737e-003,3.220922e-004,3,9.387853e-001,1.825000e+000,,,,,,,,,,,,,,,,,,0,4.000000e+000,1.000000e+000,2,2,4.125977e-001,0,,0,
1656749946.145,,3.500000e+004,3.512607e+002,1.463457e-003,1.936944e-007,-1.276168e-002,1.449140e-004,3,9.395072e-001,1.825000e+000,,,,,,,,,,,,,,,,,,0,4.000000e+000,1.000000e+000,2,2,4.061890e-001,0,,0,
1656750816.675,,3.500000e+004,3.802840e+002,4.683355e-003,2.430029e-007,-1.253084e-001,1.628765e-004,3,9.814997e-001,1.825000e+000,,,,,,,,,,,,,,,,,,0,4.000000e+000,1.000000e+000,2,2,4.094238e-001,0,,0,
1656752299.134,,3.000000e+004,3.911801e+002,3.982108e-003,3.325650e-006,-1.209618e-001,3.881251e-004,3,9.811938e-001,1.825000e+000,,,,,,,,,,,,,,,,,,0,4.000000e+000,1.000000e+000,2,2,8.309937e-001,0,,0,
1656753060.098,,3.000000e+004,3.625458e+002,4.132641e-003,3.901878e-007,-1.063548e-001,9.527822e-005,3,9.822705e-001,1.825000e+000,,,,,,,,,,,,,,,,,,0,4.000000e+000,1.000000e+000,2,2,4.656982e-001,0,,0,
1656754080.863,,3.000000e+004,3.329109e+002,1.267273e-003,1.196082e-007,4.579462e-003,3.334860e-004,3,9.392354e-001,1.825000e+000,,,,,,,,,,,,,,,,,,0,4.000000e+000,1.000000e+000,2,2,9.818115e-001,0,,0,
1656754988.415,,3.000000e+004,3.049031e+002,1.299769e-003,3.659861e-007,1.235655e-002,1.080059e-004,3,9.402283e-001,1.825000e+000,,,,,,,,,,,,,,,,,,0,4.000000e+000,1.000000e+000,2,2,1.760864e-001,0,,0,
1656756330.810,,3.000000e+004,3.232423e+002,1.268631e-003,1.280046e-007,2.938371e-003,2.969278e-004,3,9.394037e-001,1.825000e+000,,,,,,,,,,,,,,,,,,0,4.000000e+000,1.000000e+000,2,2,4.154053e-001,0,,0,
1656757201.087,,3.000000e+004,3.522891e+002,1.256403e-003,3.556140e-008,-1.118416e-002,2.283483e-004,3,9.395121e-001,1.825000e+000,,,,,,,,,,,,,,,,,,0,4.000000e+000,1.000000e+000,2,2,4.086914e-001,0,,0,
1656758076.520,,3.000000e+004,3.814722e+002,4.020305e-003,8.067237e-008,-1.234829e-001,1.207296e-004,3,9.817199e-001,1.825000e+000,,,,,,,,,,,,,,,,,,0,4.000000e+000,1.000000e+000,2,2,3.530884e-001,0,,0,
1656759528.188,,2.500000e+004,3.903199e+002,3.326464e-003,2.350181e-006,-1.181622e-001,3.051485e-004,3,9.814839e-001,1.825000e+000,,,,,,,,,,,,,,,,,,0,4.000000e+000,1.000000e+000,2,2,8.148804e-001,0,,0,
1656760305.367,,2.500000e+004,3.617694e+002,3.443014e-003,7.597957e-007,-1.035034e-001,2.277510e-005,3,9.820274e-001,1.825000e+000,,,,,,,,,,,,,,,,,,0,4.000000e+000,1.000000e+000,2,2,3.688965e-001,0,,0,
1656761311.754,,2.500000e+004,3.317453e+002,1.057593e-003,3.037548e-008,6.700240e-003,7.558379e-005,3,9.396858e-001,1.825000e+000,,,,,,,,,,,,,,,,,,0,4.000000e+000,1.000000e+000,2,2,8.428955e-001,0,,0,
1656762252.578,,2.500000e+004,3.037583e+002,1.087120e-003,3.637635e-007,1.408894e-002,2.102035e-004,3,9.404784e-001,1.825000e+000,,,,,,,,,,,,,,,,,,0,4.000000e+000,1.000000e+000,2,2,4.801025e-001,0,,0,
1656763584.211,,2.500000e+004,3.242970e+002,1.058436e-003,5.523548e-008,3.649806e-003,2.334023e-004,3,9.392650e-001,1.825000e+000,,,,,,,,,,,,,,,,,,0,4.000000e+000,1.000000e+000,2,2,4.517212e-001,0,,0,
1656764453.899,,2.500000e+004,3.533163e+002,1.049558e-003,2.350181e-007,-1.097207e-002,4.247981e-004,3,9.396940e-001,1.825000e+000,,,,,,,,,,,,,,,,,,0,4.000000e+000,1.000000e+000,2,2,4.011841e-001,0,,0,
1656765321.750,,2.500000e+004,3.822539e+002,3.354912e-003,6.073427e-007,-1.226310e-001,3.565623e-005,3,9.816556e-001,1.825000e+000,,,,,,,,,,,,,,,,,,0,4.000000e+000,1.000000e+000,2,2,4.138184e-001,0,,0,
1656766765.623,,2.000000e+004,3.894882e+002,2.669709e-003,1.560421e-006,-1.159787e-001,1.460072e-004,3,9.815655e-001,1.825000e+000,,,,,,,,,,,,,,,,,,0,4.000000e+000,1.000000e+000,2,2,8.730164e-001,0,,0,
1656767576.128,,2.000000e+004,3.609048e+002,2.754526e-003,2.439907e-007,-1.014727e-001,6.159762e-005,3,9.821522e-001,1.825000e+000,,,,,,,,,,,,,,,,,,0,4.000000e+000,1.000000e+000,2,2,1.468201e-001,0,,0,
1656768549.403,,2.000000e+004,3.307541e+002,8.483331e-004,2.714438e-007,8.400592e-003,1.162634e-004,3,9.399192e-001,1.825000e+000,,,,,,,,,,,,,,,,,,0,4.000000e+000,1.000000e+000,2,2,7.941895e-001,0,,0,
1656769499.228,,2.000000e+004,3.026315e+002,8.721327e-004,2.901715e-008,1.532233e-002,1.755403e-004,3,9.410154e-001,1.825000e+000,,,,,,,,,,,,,,,,,,0,4.000000e+000,1.000000e+000,2,2,5.340271e-001,0,,0,
1656770828.944,,2.000000e+004,3.253296e+002,8.473037e-004,9.092031e-008,5.916018e-003,9.978727e-005,3,9.397292e-001,1.825000e+000,,,,,,,,,,,,,,,,,,0,4.000000e+000,1.000000e+000,2,2,4.126892e-001,0,,0,
1656771696.947,,2.000000e+004,3.542491e+002,8.419082e-004,7.449785e-008,-7.839217e-003,2.435163e-004,3,9.405005e-001,1.825000e+000,,,,,,,,,,,,,,,,,,0,4.000000e+000,1.000000e+000,2,2,4.135132e-001,0,,0,
1656772567.567,,2.000000e+004,3.832587e+002,2.683854e-003,2.410273e-007,-1.176028e-001,1.388423e-004,3,9.817883e-001,1.825000e+000,,,,,,,,,,,,,,,,,,0,4.000000e+000,1.000000e+000,2,2,4.042969e-001,0,,0,
1656773996.761,,1.500000e+004,3.882017e+002,2.008306e-003,4.950609e-007,-1.098246e-001,2.649614e-004,3,9.817489e-001,1.825000e+000,,,,,,,,,,,,,,,,,,0,4.000000e+000,1.000000e+000,2,2,7.690735e-001,0,,0,
1656775041.303,,1.500000e+004,3.596980e+002,2.066084e-003,1.646361e-007,-9.811059e-002,2.428027e-004,3,9.826313e-001,1.825000e+000,,,,,,,,,,,,,,,,,,0,4.000000e+000,1.000000e+000,2,2,4.996948e-001,0,,0,
1656775775.363,,1.500000e+004,3.298298e+002,6.384521e-004,7.195422e-007,1.243311e-002,3.638564e-004,3,9.405408e-001,1.825000e+000,,,,,,,,,,,,,,,,,,0,4.000000e+000,1.000000e+000,2,2,7.286987e-001,0,,0,
1656776728.677,,1.500000e+004,3.015389e+002,6.574220e-004,1.147102e-007,1.909759e-002,2.191030e-004,3,9.418328e-001,1.825000e+000,,,,,,,,,,,,,,,,,,0,4.000000e+000,1.000000e+000,2,2,8.020935e-001,0,,0,
1656778066.304,,1.500000e+004,3.263099e+002,6.375364e-004,8.742178e-008,7.652510e-003,3.485261e-004,3,9.407862e-001,1.825000e+000,,,,,,,,,,,,,,,,,,0,4.000000e+000,1.000000e+000,2,2,3.730164e-001,0,,0,
1656778936.042,,1.500000e+004,3.553164e+002,6.337874e-004,7.334540e-008,-7.068550e-003,5.928514e-004,3,9.408091e-001,1.825000e+000,,,,,,,,,,,,,,,,,,0,4.000000e+000,1.000000e+000,2,2,4.161072e-001,0,,0,
1656779803.043,,1.500000e+004,3.842213e+002,2.012366e-003,5.416529e-007,-1.158433e-001,6.047019e-005,3,9.817660e-001,1.825000e+000,,,,,,,,,,,,,,,,,,0,4.000000e+000,1.000000e+000,2,2,4.183044e-001,0,,0,
1656781217.306,,1.000000e+004,3.874919e+002,1.342165e-003,9.246788e-007,-1.072485e-001,2.723266e-004,3,9.818219e-001,1.825000e+000,,,,,,,,,,,,,,,,,,0,4.000000e+000,1.000000e+000,2,2,8.757935e-001,0,,0,
1656782276.173,,1.000000e+004,3.584841e+002,1.378264e-003,1.841455e-007,-9.547932e-002,1.405281e-004,3,9.828574e-001,1.825000e+000,,,,,,,,,,,,,,,,,,0,4.000000e+000,1.000000e+000,2,2,6.203003e-001,0,,0,
1656783003.347,,1.000000e+004,3.288034e+002,4.286781e-004,3.644633e-008,1.393403e-002,3.315047e-005,3,9.418331e-001,1.825000e+000,,,,,,,,,,,,,,,,,,0,4.000000e+000,1.000000e+000,2,2,8.356934e-001,0,,0,
1656784203.408,,1.000000e+004,3.001225e+002,4.416801e-004,1.354132e-008,2.007505e-002,3.364767e-005,3,9.426100e-001,1.825000e+000,,,,,,,,,,,,,,,,,,0,4.000000e+000,1.000000e+000,2,2,7.110596e-003,0,,0,
1656785301.914,,1.000000e+004,3.272495e+002,4.271490e-004,1.719007e-007,7.658334e-003,3.068110e-004,3,9.414241e-001,1.825000e+000,,,,,,,,,,,,,,,,,,0,4.000000e+000,1.000000e+000,2,2,4.094238e-001,0,,0,
1656786171.389,,1.000000e+004,3.562704e+002,4.254158e-004,5.183981e-008,-7.779287e-003,3.078643e-004,3,9.417321e-001,1.825000e+000,,,,,,,,,,,,,,,,,,0,4.000000e+000,1.000000e+000,2,2,4.081726e-001,0,,0,
1656787040.387,,1.000000e+004,3.852549e+002,1.341597e-003,2.586434e-007,-1.148315e-001,1.417030e-004,3,9.818516e-001,1.825000e+000,,,,,,,,,,,,,,,,,,0,4.000000e+000,1.000000e+000,2,2,4.085999e-001,0,,0,
1656788415.938,,9.000000e+003,3.865696e+002,1.210711e-003,8.377509e-007,-1.055605e-001,2.084425e-004,3,9.818562e-001,1.825000e+000,,,,,,,,,,,,,,,,,,0,4.000000e+000,1.000000e+000,2,2,7.503967e-001,0,,0,
1656789472.705,,9.000000e+003,3.574482e+002,1.238832e-003,9.451760e-007,-9.310468e-002,1.595680e-004,3,9.832344e-001,1.825000e+000,,,,,,,,,,,,,,,,,,0,4.000000e+000,1.000000e+000,2,2,7.809753e-001,0,,0,
1656790194.825,,9.000000e+003,3.282185e+002,3.867017e-004,1.204725e-007,1.469774e-002,6.270661e-006,3,9.417164e-001,1.825000e+000,,,,,,,,,,,,,,,,,,0,4.000000e+000,1.000000e+000,2,2,5.749817e-001,0,,0,
1656791399.482,,9.000000e+003,3.001154e+002,3.982281e-004,7.628827e-008,2.032504e-002,1.649865e-004,3,9.426966e-001,1.825000e+000,,,,,,,,,,,,,,,,,,0,4.000000e+000,1.000000e+000,2,2,7.080078e-003,0,,0,
1656792518.450,,9.000000e+003,3.283172e+002,3.850216e-004,1.312562e-007,7.285775e-003,1.950806e-005,3,9.417390e-001,1.825000e+000,,,,,,,,,,,,,,,,,,0,4.000000e+000,1.000000e+000,2,2,4.208069e-001,0,,0,
1656793386.318,,9.000000e+003,3.572632e+002,3.840326e-004,7.552710e-009,-7.111915e-003,5.757717e-004,3,9.423712e-001,1.825000e+000,,,,,,,,,,,,,,,,,,0,4.000000e+000,1.000000e+000,2,2,4.105835e-001,0,,0,
1656794255.660,,9.000000e+003,3.862551e+002,1.206262e-003,1.217484e-006,-1.144061e-001,7.370432e-006,3,9.820511e-001,1.825000e+000,,,,,,,,,,,,,,,,,,0,4.000000e+000,1.000000e+000,2,2,4.108887e-001,0,,0,
1656795624.462,,8.000000e+003,3.855467e+002,1.079013e-003,6.619196e-007,-1.040599e-001,1.272361e-004,3,9.822689e-001,1.825000e+000,,,,,,,,,,,,,,,,,,0,4.000000e+000,1.000000e+000,2,2,7.344055e-001,0,,0,
1656796678.403,,8.000000e+003,3.564519e+002,1.096906e-003,2.017040e-006,-9.110102e-002,3.043371e-004,3,9.829887e-001,1.825000e+000,,,,,,,,,,,,,,,,,,0,4.000000e+000,1.000000e+000,2,2,9.708862e-001,0,,0,
1656797405.050,,8.000000e+003,3.273455e+002,3.445740e-004,1.641216e-007,1.578460e-002,9.497924e-005,3,9.423180e-001,1.825000e+000,,,,,,,,,,,,,,,,,,0,4.000000e+000,1.000000e+000,2,2,5.718079e-001,0,,0,
1656798846.014,,8.000000e+003,3.000445e+002,3.547204e-004,8.803917e-008,2.154186e-002,2.396233e-004,3,9.433416e-001,1.825000e+000,,,,,,,,,,,,,,,,,,0,4.000000e+000,1.000000e+000,2,2,7.080078e-003,0,,0,
1656799736.712,,8.000000e+003,3.292670e+002,3.425936e-004,1.237035e-007,7.721934e-003,2.158752e-004,3,9.418705e-001,1.825000e+000,,,,,,,,,,,,,,,,,,0,4.000000e+000,1.000000e+000,2,2,4.494019e-001,0,,0,
1656800603.640,,8.000000e+003,3.582025e+002,3.423069e-004,8.437601e-008,-7.412444e-003,4.565195e-005,3,9.424760e-001,1.825000e+000,,,,,,,,,,,,,,,,,,0,4.000000e+000,1.000000e+000,2,2,4.025879e-001,0,,0,
1656801475.269,,8.000000e+003,3.872698e+002,1.072021e-003,1.200197e-007,-1.136651e-001,1.794929e-005,3,9.822490e-001,1.825000e+000,,,,,,,,,,,,,,,,,,0,4.000000e+000,1.000000e+000,2,2,4.252014e-001,0,,0,
1656802847.741,,7.000000e+003,3.847120e+002,9.480828e-004,4.188755e-007,-1.024770e-001,1.435627e-005,3,9.822156e-001,1.825000e+000,,,,,,,,,,,,,,,,,,0,4.000000e+000,1.000000e+000,2,2,5.631104e-001,0,,0,
1656803900.071,,7.000000e+003,3.552557e+002,9.536467e-004,3.412125e-006,-8.797912e-002,4.365729e-004,3,9.828581e-001,1.825000e+000,,,,,,,,,,,,,,,,,,0,4.000000e+000,1.000000e+000,2,2,9.437866e-001,0,,0,
1656804637.699,,7.000000e+003,3.262633e+002,3.030927e-004,1.174473e-007,1.710974e-002,2.351820e-004,3,9.427673e-001,1.825000e+000,,,,,,,,,,,,,,,,,,0,4.000000e+000,1.000000e+000,2,2,5.594177e-001,0,,0,
1656806133.789,,7.000000e+003,3.012346e+002,3.110830e-004,1.212133e-007,2.039702e-002,1.191610e-004,3,9.436108e-001,1.825000e+000,,,,,,,,,,,,,,,,,,0,4.000000e+000,1.000000e+000,2,2,3.716125e-001,0,,0,
1656806976.350,,7.000000e+003,3.303074e+002,3.009807e-004,7.995142e-008,7.655730e-003,1.855785e-004,3,9.426268e-001,1.825000e+000,,,,,,,,,,,,,,,,,,0,4.000000e+000,1.000000e+000,2,2,4.176025e-001,0,,0,
1656807845.276,,7.000000e+003,3.592924e+002,3.013434e-004,6.449621e-008,-7.679243e-003,2.418729e-004,3,9.432253e-001,1.825000e+000,,,,,,,,,,,,,,,,,,0,4.000000e+000,1.000000e+000,2,2,4.570007e-001,0,,0,
1656808712.999,,7.000000e+003,3.882412e+002,9.393633e-004,1.105120e-007,-1.129999e-001,1.821376e-004,3,9.822201e-001,1.825000e+000,,,,,,,,,,,,,,,,,,0,4.000000e+000,1.000000e+000,2,2,4.029846e-001,0,,0,
1656810078.276,,6.000000e+003,3.836843e+002,8.145334e-004,2.417270e-007,-1.007404e-001,4.501284e-005,3,9.820204e-001,1.825000e+000,,,,,,,,,,,,,,,,,,0,4.000000e+000,1.000000e+000,2,2,4.884949e-001,0,,0,
1656811128.058,,6.000000e+003,3.539547e+002,8.024496e-004,7.015557e-006,-8.426981e-002,1.149950e-003,3,9.826753e-001,1.825000e+000,,,,,,,,,,,,,,,,,,0,4.000000e+000,1.000000e+000,2,2,1.056915e+000,0,,0,
1656811871.557,,6.000000e+003,3.254582e+002,2.609474e-004,2.399572e-008,1.754217e-002,2.918274e-005,3,9.431417e-001,1.825000e+000,,,,,,,,,,,,,,,,,,0,4.000000e+000,1.000000e+000,2,2,4.637146e-001,0,,0,
1656813375.147,,6.000000e+003,3.022495e+002,2.672943e-004,8.799801e-008,2.037502e-002,4.022048e-004,3,9.441900e-001,1.825000e+000,,,,,,,,,,,,,,,,,,0,4.000000e+000,1.000000e+000,2,2,5.038757e-001,0,,0,
1656814215.538,,6.000000e+003,3.312563e+002,2.587003e-004,1.648420e-008,7.598035e-003,3.425186e-004,3,9.427671e-001,1.825000e+000,,,,,,,,,,,,,,,,,,0,4.000000e+000,1.000000e+000,2,2,4.114075e-001,0,,0,
1656815087.777,,6.000000e+003,3.603422e+002,2.596661e-004,6.593677e-008,-8.175028e-003,4.866710e-005,3,9.435055e-001,1.825000e+000,,,,,,,,,,,,,,,,,,0,4.000000e+000,1.000000e+000,2,2,4.493713e-001,0,,0,
1656815955.211,,6.000000e+003,3.892822e+002,8.045026e-004,3.163483e-007,-1.125184e-001,4.273691e-005,3,9.819239e-001,1.825000e+000,,,,,,,,,,,,,,,,,,0,4.000000e+000,1.000000e+000,2,2,4.176025e-001,0,,0,
1656817307.599,,5.000000e+003,3.827304e+002,6.813348e-004,2.754774e-007,-9.980050e-002,9.453011e-005,3,9.826254e-001,1.825000e+000,,,,,,,,,,,,,,,,,,0,4.000000e+000,1.000000e+000,2,2,4.505005e-001,0,,0,
1656818339.714,,5.000000e+003,3.528186e+002,6.469688e-004,8.667598e-006,-7.939329e-002,1.393048e-003,3,9.821817e-001,1.825000e+000,,,,,,,,,,,,,,,,,,0,4.000000e+000,1.000000e+000,2,2,1.030273e+000,0,,0,
1656819102.507,,5.000000e+003,3.248544e+002,2.186768e-004,9.038524e-008,1.755160e-002,2.620744e-004,3,9.434740e-001,1.825000e+000,,,,,,,,,,,,,,,,,,0,4.000000e+000,1.000000e+000,2,2,2.686157e-001,0,,0,
1656820602.735,,5.000000e+003,3.032626e+002,2.235508e-004,2.858495e-008,1.914206e-002,1.084783e-003,3,9.441926e-001,1.825000e+000,,,,,,,,,,,,,,,,,,0,4.000000e+000,1.000000e+000,2,2,4.422913e-001,0,,0,
1656821447.933,,5.000000e+003,3.322705e+002,2.164876e-004,2.386401e-007,7.545779e-003,7.773146e-004,3,9.423929e-001,1.825000e+000,,,,,,,,,,,,,,,,,,0,4.000000e+000,1.000000e+000,2,2,3.788757e-001,0,,0,
1656822321.282,,5.000000e+003,3.614167e+002,2.179510e-004,2.958306e-008,-9.082027e-003,1.325459e-004,3,9.442613e-001,1.825000e+000,,,,,,,,,,,,,,,,,,0,4.000000e+000,1.000000e+000,2,2,3.996887e-001,0,,0,
1656823187.359,,5.000000e+003,3.902642e+002,6.702025e-004,1.604791e-007,-1.123592e-001,7.613828e-005,3,9.822000e-001,1.825000e+000,,,,,,,,,,,,,,,,,,0,4.000000e+000,1.000000e+000,2,2,4.320068e-001,0,,0,
1656824534.338,,4.000000e+003,3.817196e+002,5.470293e-004,1.359483e-007,-9.894709e-002,1.923213e-004,3,9.825186e-001,1.825000e+000,,,,,,,,,,,,,,,,,,0,4.000000e+000,1.000000e+000,2,2,3.537292e-001,0,,0,
1656825559.576,,4.000000e+003,3.518192e+002,4.979386e-004,6.874011e-006,-7.441754e-002,1.466226e-003,3,9.816822e-001,1.825000e+000,,,,,,,,,,,,,,,,,,0,4.000000e+000,1.000000e+000,2,2,1.003906e+000,0,,0,
1656826352.744,,4.000000e+003,3.239022e+002,1.762391e-004,7.907679e-008,1.732106e-002,5.672320e-004,3,9.444081e-001,1.825000e+000,,,,,,,,,,,,,,,,,,0,4.000000e+000,1.000000e+000,2,2,1.250916e-001,0,,0,
1656827829.284,,4.000000e+003,3.042849e+002,1.798653e-004,2.597135e-008,1.864175e-002,4.280302e-004,3,9.452976e-001,1.825000e+000,,,,,,,,,,,,,,,,,,0,4.000000e+000,1.000000e+000,2,2,5.039978e-001,0,,0,
1656828679.710,,4.000000e+003,3.332914e+002,1.744119e-004,1.428630e-007,5.876747e-003,6.549024e-004,3,9.434454e-001,1.825000e+000,,,,,,,,,,,,,,,,,,0,4.000000e+000,1.000000e+000,2,2,4.523010e-001,0,,0,
1656829549.016,,4.000000e+003,3.622787e+002,1.757723e-004,8.996335e-008,-1.058664e-002,1.633316e-004,3,9.451839e-001,1.825000e+000,,,,,,,,,,,,,,,,,,0,4.000000e+000,1.000000e+000,2,2,4.544983e-001,0,,0,
1656830418.127,,4.000000e+003,3.912792e+002,5.362742e-004,1.066431e-007,-1.126087e-001,6.585445e-005,3,9.820360e-001,1.825000e+000,,,,,,,,,,,,,,,,,,0,4.000000e+000,1.000000e+000,2,2,4.094849e-001,0,,0,
1656831774.740,,3.000000e+003,3.808815e+002,4.119895e-004,3.272143e-008,-9.862550e-002,2.479288e-005,3,9.824651e-001,1.825000e+000,,,,,,,,,,,,,,,,,,0,4.000000e+000,1.000000e+000,2,2,1.995239e-001,0,,0,
1656832778.303,,3.000000e+003,3.506602e+002,3.569227e-004,5.656239e-006,-6.935809e-002,1.474139e-003,3,9.807270e-001,1.825000e+000,,,,,,,,,,,,,,,,,,0,4.000000e+000,1.000000e+000,2,2,9.574890e-001,0,,0,
1656833738.177,,3.000000e+003,3.228171e+002,1.337267e-004,1.092772e-008,1.495035e-002,1.695317e-004,3,9.456145e-001,1.825000e+000,,,,,,,,,,,,,,,,,,0,4.000000e+000,1.000000e+000,2,2,3.562012e-001,0,,0,
1656835054.644,,3.000000e+003,3.052778e+002,1.360176e-004,1.143089e-007,1.717106e-002,1.026990e-003,3,9.453413e-001,1.825000e+000,,,,,,,,,,,,,,,,,,0,4.000000e+000,1.000000e+000,2,2,5.515747e-001,0,,0,
1656835917.980,,3.000000e+003,3.343345e+002,1.320158e-004,2.301099e-007,4.793233e-003,1.360112e-004,3,9.443549e-001,1.825000e+000,,,,,,,,,,,,,,,,,,0,4.000000e+000,1.000000e+000,2,2,4.461975e-001,0,,0,
1656836799.750,,3.000000e+003,3.632433e+002,1.333711e-004,8.790540e-008,-1.220690e-002,2.248528e-004,3,9.454533e-001,1.825000e+000,,,,,,,,,,,,,,,,,,0,4.000000e+000,1.000000e+000,2,2,4.994812e-001,0,,0,
1656837674.968,,3.000000e+003,3.923216e+002,4.024584e-004,7.544450e-008,-1.126475e-001,5.032861e-005,3,9.818883e-001,1.825000e+000,,,,,,,,,,,,,,,,,,0,4.000000e+000,1.000000e+000,2,2,4.493103e-001,0,,0,
1656839271.848,,2.500000e+003,3.796622e+002,3.443909e-004,5.962709e-007,-1.003665e-001,8.081658e-005,3,9.821229e-001,1.825000e+000,,,,,,,,,,,,,,,,,,0,4.000000e+000,1.000000e+000,2,2,5.361938e-001,0,,0,
1656840031.330,,2.500000e+003,3.489469e+002,2.496102e-004,1.635764e-005,-5.750536e-002,4.389239e-003,3,9.764473e-001,1.825000e+000,,,,,,,,,,,,,,,,,,0,4.000000e+000,1.000000e+000,2,2,1.094025e+000,0,,0,
1656840998.042,,2.500000e+003,3.216062e+002,1.125230e-004,3.085898e-008,1.492667e-002,1.147316e-004,3,9.463009e-001,1.825000e+000,,,,,,,,,,,,,,,,,,0,4.000000e+000,1.000000e+000,2,2,6.409912e-001,0,,0,
1656842314.599,,2.500000e+003,3.063110e+002,1.141455e-004,5.601744e-008,1.647961e-002,2.581587e-004,3,9.462894e-001,1.825000e+000,,,,,,,,,,,,,,,,,,0,4.000000e+000,1.000000e+000,2,2,5.851135e-001,0,,0,
1656843173.506,,2.500000e+003,3.352498e+002,1.108842e-004,3.092072e-008,3.127391e-003,2.258179e-004,3,9.450892e-001,1.825000e+000,,,,,,,,,,,,,,,,,,0,4.000000e+000,1.000000e+000,2,2,4.579163e-001,0,,0,
1656844050.591,,2.500000e+003,3.642746e+002,1.123180e-004,1.141649e-008,-1.333364e-002,1.874481e-005,3,9.459169e-001,1.825000e+000,,,,,,,,,,,,,,,,,,0,4.000000e+000,1.000000e+000,2,2,4.384155e-001,0,,0,
1656844927.696,,2.500000e+003,3.932694e+002,3.354384e-004,9.030292e-008,-1.126260e-001,1.530721e-004,3,9.816906e-001,1.825000e+000,,,,,,,,,,,,,,,,,,0,4.000000e+000,1.000000e+000,2,2,4.391174e-001,0,,0,
1656846519.335,,2.000000e+003,3.785090e+002,2.772646e-004,1.572481e-007,-9.901303e-002,2.428607e-004,3,9.829818e-001,1.825000e+000,,,,,,,,,,,,,,,,,,0,4.000000e+000,1.000000e+000,2,2,6.950073e-001,0,,0,
1656847269.797,,2.000000e+003,3.479629e+002,1.576691e-004,1.462313e-005,-3.974077e-002,7.516848e-003,3,9.698280e-001,1.825000e+000,,,,,,,,,,,,,,,,,,0,4.000000e+000,1.000000e+000,2,2,7.185974e-001,0,,0,
1656848243.975,,2.000000e+003,3.206395e+002,9.104656e-005,7.202831e-010,1.444402e-002,1.714455e-004,3,9.471427e-001,1.825000e+000,,,,,,,,,,,,,,,,,,0,4.000000e+000,1.000000e+000,2,2,7.512207e-001,0,,0,
1656849577.529,,2.000000e+003,3.073572e+002,9.218747e-005,1.273358e-008,1.529019e-002,9.469258e-004,3,9.470260e-001,1.825000e+000,,,,,,,,,,,,,,,,,,0,4.000000e+000,1.000000e+000,2,2,5.223083e-001,0,,0,
1656850444.399,,2.000000e+003,3.362787e+002,8.957340e-005,6.056551e-008,2.524420e-003,4.121000e-004,3,9.451782e-001,1.825000e+000,,,,,,,,,,,,,,,,,,0,4.000000e+000,1.000000e+000,2,2,4.428101e-001,0,,0,
1656851324.978,,2.000000e+003,3.652342e+002,9.103838e-005,4.292372e-008,-1.459039e-002,1.169947e-003,3,9.467614e-001,1.825000e+000,,,,,,,,,,,,,,,,,,0,4.000000e+000,1.000000e+000,2,2,4.299927e-001,0,,0,
1656852201.974,,2.000000e+003,3.942408e+002,2.685978e-004,1.687520e-007,-1.125076e-001,1.990912e-005,3,9.815272e-001,1.825000e+000,,,,,,,,,,,,,,,,,,0,4.000000e+000,1.000000e+000,2,2,4.033813e-001,0,,0,
1656853781.189,,1.500000e+003,3.775184e+002,2.090583e-004,1.073428e-007,-9.827012e-002,2.128416e-006,3,9.823794e-001,1.825000e+000,,,,,,,,,,,,,,,,,,0,4.000000e+000,1.000000e+000,2,2,8.295288e-001,0,,0,
1656854531.011,,1.500000e+003,3.471274e+002,9.172771e-005,7.223127e-006,-2.053780e-002,5.392393e-003,3,9.606881e-001,1.825000e+000,,,,,,,,,,,,,,,,,,0,4.000000e+000,1.000000e+000,2,2,6.860962e-001,0,,0,
1656855511.059,,1.500000e+003,3.193770e+002,6.929917e-005,1.074251e-007,1.354269e-002,1.045466e-004,3,9.467827e-001,1.825000e+000,,,,,,,,,,,,,,,,,,0,4.000000e+000,1.000000e+000,2,2,8.504028e-001,0,,0,
1656856835.627,,1.500000e+003,3.082948e+002,7.005136e-005,3.050918e-009,1.417024e-002,4.295646e-004,3,9.473608e-001,1.825000e+000,,,,,,,,,,,,,,,,,,0,4.000000e+000,1.000000e+000,2,2,5.031128e-001,0,,0,
1656857714.069,,1.500000e+003,3.373145e+002,6.822671e-005,1.446226e-008,6.823073e-004,8.137675e-005,3,9.458120e-001,1.825000e+000,,,,,,,,,,,,,,,,,,0,4.000000e+000,1.000000e+000,2,2,4.457092e-001,0,,0,
1656858588.542,,1.500000e+003,3.662613e+002,6.954261e-005,7.327851e-008,-1.717775e-002,2.518143e-004,3,9.472799e-001,1.825000e+000,,,,,,,,,,,,,,,,,,0,4.000000e+000,1.000000e+000,2,2,4.108887e-001,0,,0,
1656859466.004,,1.500000e+003,3.953062e+002,2.017949e-004,6.352897e-008,-1.124327e-001,6.987421e-005,3,9.813207e-001,1.825000e+000,,,,,,,,,,,,,,,,,,0,4.000000e+000,1.000000e+000,2,2,4.436035e-001,0,,0,
1656861027.817,,1.000000e+003,3.763043e+002,1.403580e-004,1.282927e-007,-9.710319e-002,2.056029e-004,3,9.817188e-001,1.825000e+000,,,,,,,,,,,,,,,,,,0,4.000000e+000,1.000000e+000,2,2,9.956970e-001,0,,0,
1656861784.908,,1.000000e+003,3.458860e+002,5.055584e-005,2.217507e-006,-3.948804e-003,3.658799e-003,3,9.504541e-001,1.825000e+000,,,,,,,,,,,,,,,,,,0,4.000000e+000,1.000000e+000,2,2,1.122009e+000,0,,0,
1656862760.282,,1.000000e+003,3.183139e+002,4.735016e-005,4.955805e-008,1.210685e-002,9.187914e-004,3,9.472916e-001,1.825000e+000,,,,,,,,,,,,,,,,,,0,4.000000e+000,1.000000e+000,2,2,9.967957e-001,0,,0,
1656864100.868,,1.000000e+003,3.093481e+002,4.770496e-005,3.544822e-009,1.272874e-002,4.339813e-007,3,9.469408e-001,1.825000e+000,,,,,,,,,,,,,,,,,,0,4.000000e+000,1.000000e+000,2,2,4.841003e-001,0,,0,
1656864971.546,,1.000000e+003,3.382838e+002,4.647617e-005,5.744515e-008,-9.002759e-004,9.172424e-004,3,9.459230e-001,1.825000e+000,,,,,,,,,,,,,,,,,,0,4.000000e+000,1.000000e+000,2,2,4.666138e-001,0,,0,
1656865842.815,,1.000000e+003,3.673270e+002,4.768751e-005,8.596578e-008,-2.014589e-002,4.081712e-004,3,9.470757e-001,1.825000e+000,,,,,,,,,,,,,,,,,,0,4.000000e+000,1.000000e+000,2,2,4.460754e-001,0,,0,
1656866710.163,,1.000000e+003,3.962684e+002,1.349935e-004,3.889528e-008,-1.120967e-001,1.475140e-006,3,9.803914e-001,1.825000e+000,,,,,,,,,,,,,,,,,,0,4.000000e+000,1.000000e+000,2,2,4.074097e-001,0,,0,
1656868247.439,,9.000000e+002,3.750756e+002,1.266876e-004,9.652822e-008,-9.617071e-002,4.478103e-005,3,9.807125e-001,1.825000e+000,,,,,,,,,,,,,,,,,,0,4.000000e+000,1.000000e+000,2,2,1.136414e+000,0,,0,
1656869004.756,,9.000000e+002,3.448055e+002,4.399997e-005,5.446883e-008,1.493347e-004,6.712505e-004,3,9.483358e-001,1.825000e+000,,,,,,,,,,,,,,,,,,0,4.000000e+000,1.000000e+000,2,2,6.192932e-001,0,,0,
1656869985.319,,9.000000e+002,3.170986e+002,4.298532e-005,2.032227e-008,1.211943e-002,4.360217e-004,3,9.468962e-001,1.825000e+000,,,,,,,,,,,,,,,,,,0,4.000000e+000,1.000000e+000,2,2,9.492798e-001,0,,0,
1656871338.894,,9.000000e+002,3.103197e+002,4.314743e-005,1.138819e-008,1.027065e-002,7.037470e-004,3,9.472670e-001,1.825000e+000,,,,,,,,,,,,,,,,,,0,4.000000e+000,1.000000e+000,2,2,4.645996e-001,0,,0,
1656872210.366,,9.000000e+002,3.392543e+002,4.207151e-005,4.458809e-008,-1.927789e-003,2.835051e-004,3,9.436111e-001,1.825000e+000,,,,,,,,,,,,,,,,,,0,4.000000e+000,1.000000e+000,2,2,4.050903e-001,0,,0,
1656873080.837,,9.000000e+002,3.682762e+002,4.361172e-005,1.530602e-007,-2.195434e-002,9.806689e-004,3,9.473974e-001,1.825000e+000,,,,,,,,,,,,,,,,,,0,4.000000e+000,1.000000e+000,2,2,4.483948e-001,0,,0,
1656873951.465,,9.000000e+002,3.973019e+002,1.213964e-004,2.013191e-008,-1.122555e-001,4.218004e-004,3,9.796151e-001,1.825000e+000,,,,,,,,,,,,,,,,,,0,4.000000e+000,1.000000e+000,2,2,4.602966e-001,0,,0,
1656875483.926,,8.000000e+002,3.734913e+002,1.130146e-004,6.722298e-008,-9.488014e-002,2.047915e-004,3,9.807612e-001,1.825000e+000,,,,,,,,,,,,,,,,,,0,4.000000e+000,1.000000e+000,2,2,9.913025e-001,0,,0,
1656876229.294,,8.000000e+002,3.444391e+002,3.921166e-005,2.735532e-008,1.481200e-004,4.267964e-004,3,9.474757e-001,1.825000e+000,,,,,,,,,,,,,,,,,,0,4.000000e+000,1.000000e+000,2,2,5.417786e-001,0,,0,
1656877211.871,,8.000000e+002,3.161207e+002,3.849101e-005,2.407803e-009,1.189899e-002,1.233671e-003,3,9.466293e-001,1.825000e+000,,,,,,,,,,,,,,,,,,0,4.000000e+000,1.000000e+000,2,2,8.475037e-001,0,,0,
1656878566.998,,8.000000e+002,3.113266e+002,3.852999e-005,2.640609e-008,1.086615e-002,5.814770e-004,3,9.462378e-001,1.825000e+000,,,,,,,,,,,,,,,,,,0,4.000000e+000,1.000000e+000,2,2,4.525146e-001,0,,0,
1656879440.700,,8.000000e+002,3.403049e+002,3.769191e-005,6.551232e-008,-3.190896e-003,1.479781e-003,3,9.452378e-001,1.825000e+000,,,,,,,,,,,,,,,,,,0,4.000000e+000,1.000000e+000,2,2,4.541016e-001,0,,0,
1656880310.608,,8.000000e+002,3.693240e+002,4.148297e-005,8.258508e-007,-2.891254e-002,1.797073e-003,3,9.491697e-001,1.825000e+000,,,,,,,,,,,,,,,,,,0,4.000000e+000,1.000000e+000,2,2,4.071045e-001,0,,0,
1656881179.349,,8.000000e+002,3.982823e+002,1.078035e-004,5.873908e-008,-1.120247e-001,2.458320e-004,3,9.793035e-001,1.825000e+000,,,,,,,,,,,,,,,,,,0,4.000000e+000,1.000000e+000,2,2,4.496155e-001,0,,0,
1656882693.830,,7.000000e+002,3.725167e+002,9.914923e-005,6.263375e-008,-9.397479e-002,1.703576e-004,3,9.804594e-001,1.825000e+000,,,,,,,,,,,,,,,,,,0,4.000000e+000,1.000000e+000,2,2,1.064209e+000,0,,0,
1656883440.066,,7.000000e+002,3.440048e+002,3.451444e-005,6.132439e-008,-1.797227e-004,1.265944e-003,3,9.470150e-001,1.825000e+000,,,,,,,,,,,,,,,,,,0,4.000000e+000,1.000000e+000,2,2,5.307007e-001,0,,0,
1656884423.343,,7.000000e+002,3.149154e+002,3.398160e-005,6.999608e-009,1.230223e-002,1.539786e-003,3,9.459522e-001,1.825000e+000,,,,,,,,,,,,,,,,,,0,4.000000e+000,1.000000e+000,2,2,8.957825e-001,0,,0,
1656885799.135,,7.000000e+002,3.122613e+002,3.402300e-005,2.305163e-008,8.228924e-003,4.502008e-005,3,9.449752e-001,1.825000e+000,,,,,,,,,,,,,,,,,,0,4.000000e+000,1.000000e+000,2,2,4.476013e-001,0,,0,
1656886680.199,,7.000000e+002,3.414907e+002,3.323066e-005,1.250206e-009,-4.796726e-003,4.231389e-004,3,9.441899e-001,1.825000e+000,,,,,,,,,,,,,,,,,,0,4.000000e+000,1.000000e+000,2,2,4.573059e-001,0,,0,
1656887545.036,,7.000000e+002,3.703227e+002,4.553181e-005,2.032865e-006,-4.913566e-002,4.761548e-003,3,9.566748e-001,1.825000e+000,,,,,,,,,,,,,,,,,,0,4.000000e+000,1.000000e+000,2,2,4.095154e-001,0,,0,
1656888412.894,,7.000000e+002,3.992574e+002,9.424939e-005,4.652514e-008,-1.122909e-001,4.075442e-004,3,9.790528e-001,1.825000e+000,,,,,,,,,,,,,,,,,,0,4.000000e+000,1.000000e+000,2,2,4.515076e-001,0,,0,
1656889909.884,,6.000000e+002,3.713190e+002,8.515170e-005,5.776670e-008,-9.286734e-002,1.778650e-004,3,9.796809e-001,1.825000e+000,,,,,,,,,,,,,,,,,,0,4.000000e+000,1.000000e+000,2,2,1.023987e+000,0,,0,
1656890660.987,,6.000000e+002,3.433874e+002,2.975126e-005,1.788617e-008,-6.995640e-004,2.141417e-004,3,9.452010e-001,1.825000e+000,,,,,,,,,,,,,,,,,,0,4.000000e+000,1.000000e+000,2,2,4.627991e-001,0,,0,
1656891636.473,,6.000000e+002,3.139616e+002,2.944544e-005,2.064383e-008,1.177621e-002,1.201752e-004,3,9.445269e-001,1.825000e+000,,,,,,,,,,,,,,,,,,0,4.000000e+000,1.000000e+000,2,2,8.901062e-001,0,,0,
1656893020.132,,6.000000e+002,3.132370e+002,2.940194e-005,3.881683e-008,7.596356e-003,5.888498e-004,3,9.441897e-001,1.825000e+000,,,,,,,,,,,,,,,,,,0,4.000000e+000,1.000000e+000,2,2,4.816895e-001,0,,0,
1656893897.074,,6.000000e+002,3.423471e+002,2.877264e-005,2.763057e-008,-7.793265e-003,1.133926e-003,3,9.426293e-001,1.825000e+000,,,,,,,,,,,,,,,,,,0,4.000000e+000,1.000000e+000,2,2,4.410095e-001,0,,0,
1656894765.907,,6.000000e+002,3.713271e+002,5.300016e-005,2.244243e-006,-7.185307e-002,3.195200e-003,3,9.655740e-001,1.825000e+000,,,,,,,,,,,,,,,,,,0,4.000000e+000,1.000000e+000,2,2,4.118042e-001,0,,0,
1656895884.853,,6.000000e+002,3.999841e+002,8.076955e-005,6.055525e-009,-1.098802e-001,2.380981e-004,3,9.781018e-001,1.825000e+000,,,,,,,,,,,,,,,,,,0,4.000000e+000,1.000000e+000,2,2,1.290894e-002,0,,0,
1656897118.227,,5.000000e+002,3.700935e+002,7.113998e-005,6.612713e-008,-9.185086e-002,5.442159e-004,3,9.779451e-001,1.825000e+000,,,,,,,,,,,,,,,,,,0,4.000000e+000,1.000000e+000,2,2,1.061096e+000,0,,0,
1656897879.915,,5.000000e+002,3.428240e+002,2.502743e-005,1.148594e-008,-1.401668e-003,1.437562e-003,3,9.433218e-001,1.825000e+000,,,,,,,,,,,,,,,,,,0,4.000000e+000,1.000000e+000,2,2,2.447205e-001,0,,0,
1656898840.976,,5.000000e+002,3.131750e+002,2.481942e-005,6.423381e-009,1.010287e-002,5.080427e-004,3,9.419225e-001,1.825000e+000,,,,,,,,,,,,,,,,,,0,4.000000e+000,1.000000e+000,2,2,8.154907e-001,0,,0,
1656900241.164,,5.000000e+002,3.142349e+002,2.473703e-005,9.471722e-009,4.330004e-003,1.272580e-003,3,9.424817e-001,1.825000e+000,,,,,,,,,,,,,,,,,,0,4.000000e+000,1.000000e+000,2,2,3.989868e-001,0,,0,
1656901113.475,,5.000000e+002,3.432316e+002,2.420387e-005,3.921427e-008,-8.396288e-003,6.508105e-004,3,9.417528e-001,1.825000e+000,,,,,,,,,,,,,,,,,,0,4.000000e+000,1.000000e+000,2,2,4.527893e-001,0,,0,
1656901985.714,,5.000000e+002,3.723036e+002,5.548402e-005,1.574420e-006,-8.772891e-002,2.054069e-003,3,9.708787e-001,1.825000e+000,,,,,,,,,,,,,,,,,,0,4.000000e+000,1.000000e+000,2,2,4.588013e-001,0,,0,
1656903460.730,,4.000000e+002,3.999970e+002,5.353416e-005,3.131173e-008,-1.080160e-001,3.023510e-004,3,9.755450e-001,1.825000e+000,,,,,,,,,,,,,,,,,,0,4.000000e+000,1.000000e+000,2,2,1.300049e-002,0,,0,
1656904339.944,,4.000000e+002,3.690136e+002,5.696394e-005,2.731416e-008,-9.124807e-002,3.986038e-005,3,9.759725e-001,1.825000e+000,,,,,,,,,,,,,,,,,,0,4.000000e+000,1.000000e+000,2,2,1.010620e+000,0,,0,
1656905150.437,,4.000000e+002,3.419744e+002,2.019993e-005,9.707100e-009,-2.966666e-003,9.725381e-004,3,9.380930e-001,1.825000e+000,,,,,,,,,,,,,,,,,,0,4.000000e+000,1.000000e+000,2,2,3.741455e-002,0,,0,
1656906060.700,,4.000000e+002,3.124159e+002,2.015912e-005,1.956598e-008,1.047142e-002,5.479953e-004,3,9.385205e-001,1.825000e+000,,,,,,,,,,,,,,,,,,0,4.000000e+000,1.000000e+000,2,2,6.567993e-001,0,,0,
1656907479.341,,4.000000e+002,3.152711e+002,2.004772e-005,5.172790e-008,-1.751918e-003,1.721732e-003,3,9.392747e-001,1.825000e+000,,,,,,,,,,,,,,,,,,0,4.000000e+000,1.000000e+000,2,2,4.017029e-001,0,,0,
1656908352.141,,4.000000e+002,3.442989e+002,1.962544e-005,1.102548e-008,-1.064787e-002,2.385989e-003,3,9.351183e-001,1.825000e+000,,,,,,,,,,,,,,,,,,0,4.000000e+000,1.000000e+000,2,2,4.557800e-001,0,,0,
1656909221.404,,4.000000e+002,3.732799e+002,5.131396e-005,8.708248e-007,-9.637573e-002,1.139092e-003,3,9.730843e-001,1.825000e+000,,,,,,,,,,,,,,,,,,0,4.000000e+000,1.000000e+000,2,2,4.500122e-001,0,,0,
1656910722.223,,3.000000e+002,3.988031e+002,4.024216e-005,6.746222e-008,-1.055494e-001,6.637128e-004,3,9.712323e-001,1.825000e+000,,,,,,,,,,,,,,,,,,0,4.000000e+000,1.000000e+000,2,2,2.961121e-001,0,,0,
1656911553.891,,3.000000e+002,3.677902e+002,4.276092e-005,2.016793e-008,-9.067405e-002,4.091827e-004,3,9.732242e-001,1.825000e+000,,,,,,,,,,,,,,,,,,0,4.000000e+000,1.000000e+000,2,2,8.617859e-001,0,,0,
1656912551.723,,3.000000e+002,3.406436e+002,1.541660e-005,2.492437e-008,-6.487012e-003,2.471340e-004,3,9.357407e-001,1.825000e+000,,,,,,,,,,,,,,,,,,0,4.000000e+000,1.000000e+000,2,2,5.571289e-001,0,,0,
1656913280.266,,3.000000e+002,3.113459e+002,1.548465e-005,2.359313e-008,4.806917e-003,1.085743e-003,3,9.317427e-001,1.825000e+000,,,,,,,,,,,,,,,,,,0,4.000000e+000,1.000000e+000,2,2,7.441101e-001,0,,0,
1656914720.360,,3.000000e+002,3.162711e+002,1.530487e-005,5.183466e-009,-1.130810e-003,1.983718e-003,3,9.324671e-001,1.825000e+000,,,,,,,,,,,,,,,,,,0,4.000000e+000,1.000000e+000,2,2,4.363098e-001,0,,0,
1656915596.556,,3.000000e+002,3.452514e+002,1.499674e-005,2.525428e-008,-1.273388e-002,1.426947e-004,3,9.320848e-001,1.825000e+000,,,,,,,,,,,,,,,,,,0,4.000000e+000,1.000000e+000,2,2,4.585876e-001,0,,0,
1656916471.261,,3.000000e+002,3.743238e+002,4.081882e-005,1.232713e-007,-1.006998e-001,4.253934e-004,3,9.719365e-001,1.825000e+000,,,,,,,,,,,,,,,,,,0,4.000000e+000,1.000000e+000,2,2,4.187927e-001,0,,0,
1656923903.250,,3.000000e+002,3.182472e+002,1.474040e-005,2.506199e-008,5.409456e-003,9.159863e-004,3,9.385681e-001,1.825000e+000,,,,,,,,,,,,,,,,,,0,4.000000e+000,1.000000e+000,2,2,4.098816e-001,0,,0,
1656924785.117,,3.000000e+002,3.472988e+002,1.446648e-005,1.501340e-008,-1.253560e-002,2.158382e-003,3,9.338745e-001,1.825000e+000,,,,,,,,,,,,,,,,,,0,4.000000e+000,1.000000e+000,2,2,4.450073e-001,0,,0,
1656925668.098,,3.000000e+002,3.763183e+002,4.038335e-005,4.872972e-008,-1.036562e-001,1.127718e-003,3,9.724376e-001,1.825000e+000,,,,,,,,,,,,,,,,,,0,4.000000e+000,1.000000e+000,2,2,4.577026e-001,0,,0,
1656927194.487,,2.000000e+002,3.954996e+002,2.625914e-005,3.959885e-008,-1.079197e-001,8.279748e-004,3,9.672233e-001,1.825000e+000,,,,,,,,,,,,,,,,,,0,4.000000e+000,1.000000e+000,2,2,7.738037e-001,0,,0,
1656927978.782,,2.000000e+002,3.646038e+002,2.756514e-005,5.115425e-008,-9.224280e-002,1.357877e-003,3,9.687452e-001,1.825000e+000,,,,,,,,,,,,,,,,,,0,4.000000e+000,1.000000e+000,2,2,6.640930e-001,0,,0,
1656928987.062,,2.000000e+002,3.373376e+002,1.005769e-005,4.177256e-008,-9.706128e-003,2.460121e-003,3,9.207518e-001,1.825000e+000,,,,,,,,,,,,,,,,,,0,4.000000e+000,1.000000e+000,2,2,1.073090e+000,0,,0,
1656929713.416,,2.000000e+002,3.085692e+002,1.018563e-005,3.425718e-008,3.726202e-003,1.143125e-003,3,9.247892e-001,1.825000e+000,,,,,,,,,,,,,,,,,,0,4.000000e+000,1.000000e+000,2,2,5.191956e-001,0,,0,
1656931198.188,,2.000000e+002,3.193261e+002,1.003905e-005,1.247247e-008,-3.033042e-003,6.082537e-003,3,9.228064e-001,1.825000e+000,,,,,,,,,,,,,,,,,,0,4.000000e+000,1.000000e+000,2,2,4.370728e-001,0,,0,
1656932075.798,,2.000000e+002,3.482786e+002,9.829566e-006,1.898911e-008,-2.060468e-002,4.567004e-003,3,9.193490e-001,1.825000e+000,,,,,,,,,,,,,,,,,,0,4.000000e+000,1.000000e+000,2,2,4.865112e-001,0,,0,
1656932955.630,,2.000000e+002,3.772592e+002,2.674112e-005,5.860146e-008,-1.048737e-001,2.743496e-003,3,9.673524e-001,1.825000e+000,,,,,,,,,,,,,,,,,,0,4.000000e+000,1.000000e+000,2,2,4.371033e-001,0,,0,
1656934466.590,,1.000000e+002,3.945439e+002,1.247949e-005,6.594127e-008,-1.007270e-001,2.070885e-004,3,9.491176e-001,1.825000e+000,,,,,,,,,,,,,,,,,,0,4.000000e+000,1.000000e+000,2,2,9.595947e-001,0,,0,
1656935246.014,,1.000000e+002,3.641865e+002,1.308844e-005,2.319633e-008,-8.838712e-002,2.380233e-003,3,9.525547e-001,1.825000e+000,,,,,,,,,,,,,,,,,,0,4.000000e+000,1.000000e+000,2,2,6.410828e-001,0,,0,
1656936263.791,,1.000000e+002,3.360393e+002,5.217449e-006,1.606714e-008,-8.808911e-003,8.436732e-004,3,8.954512e-001,1.825000e+000,,,,,,,,,,,,,,,,,,0,4.000000e+000,1.000000e+000,2,2,1.112122e+000,0,,0,
1656937008.775,,1.000000e+002,3.077345e+002,5.311575e-006,1.696620e-008,5.786528e-005,2.407299e-003,3,8.921583e-001,1.825000e+000,,,,,,,,,,,,,,,,,,0,4.000000e+000,1.000000e+000,2,2,3.741150e-001,0,,0,
1656938484.354,,1.000000e+002,3.202478e+002,5.210228e-006,1.262810e-008,-1.369087e-002,5.848511e-003,3,8.886536e-001,1.825000e+000,,,,,,,,,,,,,,,,,,0,4.000000e+000,1.000000e+000,2,2,3.909912e-001,0,,0,
1656939365.063,,1.000000e+002,3.492937e+002,5.111934e-006,5.716025e-008,-3.022159e-002,2.187888e-003,3,8.926119e-001,1.825000e+000,,,,,,,,,,,,,,,,,,0,4.000000e+000,1.000000e+000,2,2,4.893799e-001,0,,0,
1656940247.014,,1.000000e+002,3.782773e+002,1.268404e-005,4.371861e-008,-1.012607e-001,2.278770e-003,3,9.542992e-001,1.825000e+000,,,,,,,,,,,,,,,,,,0,4.000000e+000,1.000000e+000,2,2,4.512024e-001,0,,0,
1656941743.657,,0.000000e+000,3.933794e+002,-1.779664e-006,6.856540e-008,-1.218183e-001,1.377207e-002,3,8.027148e-001,1.825000e+000,,,,,,,,,,,,,,,,,,0,4.000000e+000,1.000000e+000,2,2,1.041809e+000,0,,0,
1656942523.410,,0.000000e+000,3.634905e+002,-1.846692e-006,1.663532e-008,-8.666096e-002,3.542495e-003,3,8.184886e-001,1.825000e+000,,,,,,,,,,,,,,,,,,0,4.000000e+000,1.000000e+000,2,2,5.640869e-001,0,,0,
1656943541.990,,0.000000e+000,3.348624e+002,-6.395832e-008,3.508616e-010,0.000000e+000,0.000000e+000,3,0.000000e+000,1.825000e+000,,,,,,,,,,,,,,,,,,0,4.000000e+000,1.000000e+000,2,2,1.110199e+000,0,,0,
1656944305.358,,0.000000e+000,3.068637e+002,1.135902e-009,5.639022e-007,1.357400e-002,1.682050e+000,3,3.462074e-001,1.825000e+000,,,,,,,,,,,,,,,,,,0,4.000000e+000,1.000000e+000,2,2,2.304993e-001,0,,0,
1656945789.981,,0.000000e+000,3.215280e+002,-3.774350e-007,3.546369e-009,1.150813e+000,1.391310e-002,3,2.885116e-001,1.825000e+000,,,,,,,,,,,,,,,,,,0,4.000000e+000,1.000000e+000,2,2,4.107971e-001,0,,0,
1656946660.168,,0.000000e+000,3.502558e+002,-5.989722e-008,2.736065e-008,0.000000e+000,0.000000e+000,3,0.000000e+000,1.825000e+000,,,,,,,,,,,,,,,,,,0,4.000000e+000,1.000000e+000,2,2,4.134827e-001,0,,0,
1656947546.666,,0.000000e+000,3.793215e+002,-1.791129e-006,3.353175e-009,-1.090956e-001,8.401316e-003,3,8.237677e-001,1.825000e+000,,,,,,,,,,,,,,,,,,0,4.000000e+000,1.000000e+000,2,2,4.073181e-001,0,,0,
1656948432.760,,0.000000e+000,3.999905e+002,-1.857432e-006,1.736517e-008,-1.255777e-001,1.837750e-003,3,8.411887e-001,1.825000e+000,,,,,,,,,,,,,,,,,,0,4.000000e+000,1.000000e+000,2,2,0.000000e+000,0,,0,