File: spin_crossover/dane/Trt_TEOS — kopia/Big TEOS/FeTrz_Trt_big_XTvT_MCE.rso.csv
Field (Oe),Temperature (K),Long Moment (emu),Long Offset (cm)
7.000000e+004,4.000002e+002,9.037551e-003,-1.388583e-001
7.000000e+004,3.913011e+002,9.210825e-003,-1.319972e-001
7.000000e+004,3.836396e+002,9.336397e-003,-1.270173e-001
7.000000e+004,3.752119e+002,9.462057e-003,-1.247024e-001
7.000000e+004,3.663047e+002,9.489220e-003,-1.184540e-001
7.000000e+004,3.597448e+002,9.249745e-003,-1.155257e-001
7.000000e+004,3.504556e+002,3.391251e-003,-2.577610e-002
7.000000e+004,3.435693e+002,2.960704e-003,-7.060822e-003
7.000000e+004,3.350616e+002,2.942824e-003,-3.884778e-003
7.000000e+004,3.274245e+002,2.949896e-003,7.423664e-004
7.000000e+004,3.194721e+002,2.964252e-003,1.949161e-003
7.000000e+004,3.114668e+002,2.986459e-003,5.488463e-003
7.000000e+004,3.037346e+002,3.011255e-003,6.085037e-003
7.000000e+004,3.032970e+002,3.006960e-003,5.589002e-003
7.000000e+004,3.112556e+002,2.973624e-003,2.018698e-003
7.000000e+004,3.192674e+002,2.946498e-003,-1.353946e-003
7.000000e+004,3.272815e+002,2.924680e-003,-4.716262e-003
7.000000e+004,3.353082e+002,2.910926e-003,-8.237812e-003
7.000000e+004,3.432834e+002,2.906504e-003,-1.258054e-002
7.000000e+004,3.512805e+002,2.908483e-003,-1.693184e-002
7.000000e+004,3.592222e+002,2.928499e-003,-2.202049e-002
7.000000e+004,3.673162e+002,2.968929e-003,-2.781767e-002
7.000000e+004,3.752543e+002,6.074195e-003,-1.048814e-001
7.000000e+004,3.832528e+002,9.115515e-003,-1.308219e-001
7.000000e+004,3.912668e+002,9.176577e-003,-1.344741e-001
7.000000e+004,3.993348e+002,9.077433e-003,-1.365793e-001
6.500000e+004,3.933479e+002,8.579591e-003,-1.282495e-001
6.500000e+004,3.855316e+002,8.695867e-003,-1.233331e-001
6.500000e+004,3.774521e+002,8.823568e-003,-1.218099e-001
6.500000e+004,3.683365e+002,8.901212e-003,-1.158663e-001
6.500000e+004,3.617931e+002,8.831501e-003,-1.111765e-001
6.500000e+004,3.524091e+002,7.196125e-003,-9.169605e-002
6.500000e+004,3.447912e+002,2.776897e-003,-6.237082e-003
6.500000e+004,3.373716e+002,2.741709e-003,-3.447122e-003
6.500000e+004,3.287086e+002,2.744728e-003,1.612485e-003
6.500000e+004,3.216246e+002,2.756353e-003,2.242459e-003
6.500000e+004,3.130683e+002,2.779451e-003,5.966489e-003
6.500000e+004,3.058782e+002,2.799832e-003,8.382199e-003
6.500000e+004,3.012526e+002,2.812727e-003,6.975349e-003
6.500000e+004,3.092517e+002,2.780414e-003,3.644141e-003
6.500000e+004,3.172020e+002,2.753199e-003,1.285195e-005
6.500000e+004,3.252328e+002,2.730900e-003,-3.590323e-003
6.500000e+004,3.332670e+002,2.715548e-003,-7.092190e-003
6.500000e+004,3.413741e+002,2.707427e-003,-1.115577e-002
6.500000e+004,3.492789e+002,2.708012e-003,-1.523831e-002
6.500000e+004,3.573146e+002,2.720123e-003,-2.011796e-002
6.500000e+004,3.652906e+002,2.752344e-003,-2.583565e-002
6.500000e+004,3.732490e+002,4.701491e-003,-8.889656e-002
6.500000e+004,3.815134e+002,8.562651e-003,-1.303418e-001
6.500000e+004,3.892607e+002,8.587020e-003,-1.338003e-001
6.500000e+004,3.972954e+002,8.487558e-003,-1.358559e-001
6.000000e+004,3.956138e+002,7.897763e-003,-1.295471e-001
6.000000e+004,3.874158e+002,8.015396e-003,-1.241607e-001
6.000000e+004,3.797555e+002,8.130195e-003,-1.230748e-001
6.000000e+004,3.703396e+002,8.234698e-003,-1.173176e-001
6.000000e+004,3.631768e+002,8.218098e-003,-1.123326e-001
6.000000e+004,3.551949e+002,7.875960e-003,-1.072341e-001
6.000000e+004,3.463226e+002,2.593670e-003,-8.528186e-003
6.000000e+004,3.395977e+002,2.539729e-003,-4.993732e-003
6.000000e+004,3.305385e+002,2.535405e-003,5.323380e-004
6.000000e+004,3.237833e+002,2.544937e-003,3.712808e-003
6.000000e+004,3.152261e+002,2.564864e-003,4.652433e-003
6.000000e+004,3.076148e+002,2.585451e-003,7.541051e-003
6.000000e+004,3.001385e+002,2.610161e-003,7.556641e-003
6.000000e+004,3.073292e+002,2.580375e-003,3.771546e-003
6.000000e+004,3.153264e+002,2.553169e-003,2.954475e-004
6.000000e+004,3.232756e+002,2.531142e-003,-3.009115e-003
6.000000e+004,3.312083e+002,2.515541e-003,-6.666652e-003
6.000000e+004,3.392129e+002,2.505137e-003,-1.052413e-002
6.000000e+004,3.472674e+002,2.503068e-003,-1.458838e-002
6.000000e+004,3.552479e+002,2.510597e-003,-1.949163e-002
6.000000e+004,3.632724e+002,2.535424e-003,-2.477079e-002
6.000000e+004,3.712631e+002,2.877536e-003,-4.573777e-002
6.000000e+004,3.792721e+002,7.918129e-003,-1.297408e-001
6.000000e+004,3.872181e+002,7.962368e-003,-1.335709e-001
6.000000e+004,3.952427e+002,7.875348e-003,-1.356855e-001
5.500000e+004,3.977723e+002,7.216295e-003,-1.313022e-001
5.500000e+004,3.893407e+002,7.332206e-003,-1.255748e-001
5.500000e+004,3.817874e+002,7.427357e-003,-1.215519e-001
5.500000e+004,3.728419e+002,7.540085e-003,-1.190775e-001
5.500000e+004,3.648852e+002,7.565906e-003,-1.139322e-001
5.500000e+004,3.574637e+002,7.453703e-003,-1.115922e-001
5.500000e+004,3.484175e+002,2.977578e-003,-2.787409e-002
5.500000e+004,3.419253e+002,2.342341e-003,-4.524898e-003
5.500000e+004,3.327959e+002,2.325951e-003,-7.909152e-004
5.500000e+004,3.257514e+002,2.332015e-003,2.853703e-003
5.500000e+004,3.173941e+002,2.348735e-003,3.880017e-003
5.500000e+004,3.095620e+002,2.367231e-003,6.959793e-003
5.500000e+004,3.014728e+002,2.394647e-003,7.311695e-003
5.500000e+004,3.053182e+002,2.375193e-003,5.094035e-003
5.500000e+004,3.132584e+002,2.349519e-003,1.390373e-003
5.500000e+004,3.213782e+002,2.328277e-003,-1.810954e-003
5.500000e+004,3.292324e+002,2.311950e-003,-5.471315e-003
5.500000e+004,3.372190e+002,2.300796e-003,-9.029670e-003
5.500000e+004,3.452371e+002,2.297157e-003,-1.309557e-002
5.500000e+004,3.532538e+002,2.301406e-003,-1.765359e-002
5.500000e+004,3.614588e+002,2.320448e-003,-2.288997e-002
5.500000e+004,3.692937e+002,2.390932e-003,-3.101483e-002
5.500000e+004,3.772592e+002,7.244935e-003,-1.277179e-001
5.500000e+004,3.852248e+002,7.325858e-003,-1.322465e-001
5.500000e+004,3.932725e+002,7.252216e-003,-1.346582e-001
5.000000e+004,4.000132e+002,6.519824e-003,-1.321237e-001
5.000000e+004,3.915372e+002,6.644264e-003,-1.263774e-001
5.000000e+004,3.836247e+002,6.737332e-003,-1.216922e-001
5.000000e+004,3.752858e+002,6.843942e-003,-1.201036e-001
5.000000e+004,3.664589e+002,6.896190e-003,-1.142531e-001
5.000000e+004,3.597761e+002,6.836677e-003,-1.127273e-001
5.000000e+004,3.501552e+002,5.032582e-003,-8.342442e-002
5.000000e+004,3.435362e+002,2.144351e-003,-5.179378e-003
5.000000e+004,3.350393e+002,2.115736e-003,-1.490942e-003
5.000000e+004,3.271387e+002,2.119400e-003,3.221535e-003
5.000000e+004,3.193829e+002,2.132069e-003,3.746723e-003
5.000000e+004,3.115071e+002,2.150556e-003,7.104751e-003
5.000000e+004,3.037073e+002,2.172179e-003,7.461379e-003
5.000000e+004,3.032898e+002,2.167757e-003,6.438036e-003
5.000000e+004,3.113093e+002,2.143491e-003,3.321838e-003
5.000000e+004,3.192674e+002,2.122715e-003,-2.820348e-005
5.000000e+004,3.272665e+002,2.107399e-003,-3.796523e-003
5.000000e+004,3.352925e+002,2.096311e-003,-7.146860e-003
5.000000e+004,3.432575e+002,2.090590e-003,-1.163728e-002
5.000000e+004,3.512978e+002,2.092902e-003,-1.569645e-002
5.000000e+004,3.592637e+002,2.104789e-003,-2.078229e-002
5.000000e+004,3.672916e+002,2.145865e-003,-2.737741e-002
5.000000e+004,3.752770e+002,6.509535e-003,-1.246545e-001
5.000000e+004,3.832468e+002,6.680260e-003,-1.305287e-001
5.000000e+004,3.912482e+002,6.625226e-003,-1.330971e-001
5.000000e+004,3.992541e+002,6.530948e-003,-1.350135e-001
4.500000e+004,3.933260e+002,5.960069e-003,-1.262962e-001
4.500000e+004,3.854925e+002,6.045131e-003,-1.212830e-001
4.500000e+004,3.774550e+002,6.139350e-003,-1.199881e-001
4.500000e+004,3.682490e+002,6.207587e-003,-1.141476e-001
4.500000e+004,3.617800e+002,6.186816e-003,-1.100360e-001
4.500000e+004,3.528961e+002,5.615208e-003,-9.916984e-002
4.500000e+004,3.452538e+002,1.947161e-003,-6.399544e-003
4.500000e+004,3.373352e+002,1.906560e-003,-1.932748e-003
4.500000e+004,3.288076e+002,1.905720e-003,3.611399e-003
4.500000e+004,3.216904e+002,1.914807e-003,4.082815e-003
4.500000e+004,3.131731e+002,1.930787e-003,7.652210e-003
4.500000e+004,3.058487e+002,1.947148e-003,1.019220e-002
4.500000e+004,3.012240e+002,1.949317e-003,6.923224e-005
4.500000e+004,3.093141e+002,1.929289e-003,-2.884143e-003
4.500000e+004,3.172858e+002,1.910328e-003,-5.307849e-003
4.500000e+004,3.252412e+002,1.894191e-003,-7.585031e-003
4.500000e+004,3.332980e+002,1.882814e-003,-1.106230e-002
4.500000e+004,3.414814e+002,1.876582e-003,-1.450907e-002
4.500000e+004,3.492496e+002,1.876416e-003,-1.858859e-002
4.500000e+004,3.572966e+002,1.884523e-003,-2.290344e-002
4.500000e+004,3.652691e+002,1.909091e-003,-2.883268e-002
4.500000e+004,3.732658e+002,4.629174e-003,-1.148102e-001
4.500000e+004,3.815576e+002,6.018246e-003,-1.338538e-001
4.500000e+004,3.892853e+002,5.986392e-003,-1.366999e-001
4.500000e+004,3.972891e+002,5.905964e-003,-1.385367e-001
4.000000e+004,3.956138e+002,5.269292e-003,-1.309554e-001
4.000000e+004,3.873915e+002,5.353170e-003,-1.252376e-001
4.000000e+004,3.798109e+002,5.430491e-003,-1.237463e-001
4.000000e+004,3.700659e+002,5.508837e-003,-1.174733e-001
4.000000e+004,3.630468e+002,5.511849e-003,-1.127388e-001
4.000000e+004,3.551365e+002,5.353663e-003,-1.082837e-001
4.000000e+004,3.464283e+002,1.751263e-003,-1.042501e-002
4.000000e+004,3.396739e+002,1.698515e-003,-5.014286e-003
4.000000e+004,3.309003e+002,1.690292e-003,9.293931e-004
4.000000e+004,3.238209e+002,1.696325e-003,4.881166e-003
4.000000e+004,3.152438e+002,1.710658e-003,5.901106e-003
4.000000e+004,3.077252e+002,1.725395e-003,9.011790e-003
4.000000e+004,3.001403e+002,1.742665e-003,9.645840e-003
4.000000e+004,3.072976e+002,1.723307e-003,6.131832e-003
4.000000e+004,3.152672e+002,1.704819e-003,2.931676e-003
4.000000e+004,3.232610e+002,1.690701e-003,-3.858262e-004
4.000000e+004,3.313045e+002,1.679581e-003,-3.843692e-003
4.000000e+004,3.392520e+002,1.673135e-003,-7.758666e-003
4.000000e+004,3.472214e+002,1.671248e-003,-1.191297e-002
4.000000e+004,3.552986e+002,1.676888e-003,-1.649327e-002
4.000000e+004,3.633070e+002,1.694250e-003,-2.204588e-002
4.000000e+004,3.712687e+002,2.713633e-003,-7.859507e-002
4.000000e+004,3.792110e+002,5.344004e-003,-1.264691e-001
4.000000e+004,3.872121e+002,5.333589e-003,-1.300196e-001
4.000000e+004,3.952174e+002,5.264395e-003,-1.320002e-001
3.500000e+004,3.977980e+002,4.587551e-003,-1.271777e-001
3.500000e+004,3.892578e+002,4.664059e-003,-1.213326e-001
3.500000e+004,3.817108e+002,4.729889e-003,-1.172060e-001
3.500000e+004,3.727886e+002,4.804758e-003,-1.147055e-001
3.500000e+004,3.644886e+002,4.828468e-003,-1.091626e-001
3.500000e+004,3.574971e+002,4.777167e-003,-1.072658e-001
3.500000e+004,3.484491e+002,2.520849e-003,-5.080387e-002
3.500000e+004,3.418201e+002,1.493798e-003,-5.872301e-004
3.500000e+004,3.328687e+002,1.478320e-003,3.085956e-003
3.500000e+004,3.256880e+002,1.482324e-003,7.143586e-003
3.500000e+004,3.173381e+002,1.493467e-003,7.898586e-003
3.500000e+004,3.096852e+002,1.505872e-003,1.121981e-002
3.500000e+004,3.008691e+002,1.523148e-003,1.170397e-002
3.500000e+004,3.052998e+002,1.511501e-003,8.973050e-003
3.500000e+004,3.133205e+002,1.494363e-003,5.194589e-003
3.500000e+004,3.214828e+002,1.481585e-003,2.054507e-003
3.500000e+004,3.293167e+002,1.471388e-003,-1.332554e-003
3.500000e+004,3.372531e+002,1.464140e-003,-5.286924e-003
3.500000e+004,3.452633e+002,1.461625e-003,-9.015978e-003
3.500000e+004,3.532312e+002,1.464659e-003,-1.400396e-002
3.500000e+004,3.615588e+002,1.477602e-003,-1.907113e-002
3.500000e+004,3.692909e+002,1.548194e-003,-2.945132e-002
3.500000e+004,3.772391e+002,4.657672e-003,-1.233629e-001
3.500000e+004,3.852429e+002,4.676103e-003,-1.274241e-001
3.500000e+004,3.932600e+002,4.619834e-003,-1.298240e-001
3.000000e+004,4.000035e+002,3.907469e-003,-1.271123e-001
3.000000e+004,3.911801e+002,3.982108e-003,-1.209618e-001
3.000000e+004,3.835265e+002,4.040183e-003,-1.165218e-001
3.000000e+004,3.753484e+002,4.103999e-003,-1.147291e-001
3.000000e+004,3.662911e+002,4.139574e-003,-1.088674e-001
3.000000e+004,3.597683e+002,4.111070e-003,-1.073800e-001
3.000000e+004,3.504950e+002,3.364392e-003,-8.456425e-002
3.000000e+004,3.436071e+002,1.289900e-003,-1.740422e-003
3.000000e+004,3.351337e+002,1.268111e-003,2.801051e-003
3.000000e+004,3.274138e+002,1.270022e-003,7.754950e-003
3.000000e+004,3.194295e+002,1.278289e-003,8.748300e-003
3.000000e+004,3.115664e+002,1.288934e-003,1.242393e-002
3.000000e+004,3.037182e+002,1.302134e-003,1.256021e-002
3.000000e+004,3.032934e+002,1.300195e-003,1.147800e-002
3.000000e+004,3.113189e+002,1.286151e-003,8.154433e-003
3.000000e+004,3.192755e+002,1.274226e-003,4.885491e-003
3.000000e+004,3.272751e+002,1.264335e-003,1.520539e-003
3.000000e+004,3.352476e+002,1.257531e-003,-2.441064e-003
3.000000e+004,3.432198e+002,1.254570e-003,-6.340198e-003
3.000000e+004,3.512607e+002,1.255880e-003,-1.068791e-002
3.000000e+004,3.592326e+002,1.263840e-003,-1.535492e-002
3.000000e+004,3.672345e+002,1.289773e-003,-2.295192e-002
3.000000e+004,3.752486e+002,3.954870e-003,-1.191007e-001
3.000000e+004,3.832558e+002,4.017952e-003,-1.243224e-001
3.000000e+004,3.912202e+002,3.975949e-003,-1.268536e-001
3.000000e+004,3.992122e+002,3.917125e-003,-1.288143e-001
2.500000e+004,3.935425e+002,3.305137e-003,-1.201620e-001
2.500000e+004,3.856309e+002,3.355977e-003,-1.150682e-001
2.500000e+004,3.776480e+002,3.408840e-003,-1.136845e-001
2.500000e+004,3.679894e+002,3.450218e-003,-1.077383e-001
2.500000e+004,3.617694e+002,3.443014e-003,-1.035034e-001
2.500000e+004,3.526987e+002,3.147839e-003,-9.267439e-002
2.500000e+004,3.449532e+002,1.085674e-003,-1.436722e-003
2.500000e+004,3.374785e+002,1.060783e-003,2.342816e-003
2.500000e+004,3.289757e+002,1.058783e-003,8.653862e-003
2.500000e+004,3.216288e+002,1.064908e-003,9.062916e-003
2.500000e+004,3.133538e+002,1.074268e-003,1.202554e-002
2.500000e+004,3.059299e+002,1.083104e-003,1.493059e-002
2.500000e+004,3.012472e+002,1.089357e-003,1.346928e-002
2.500000e+004,3.093613e+002,1.076599e-003,9.509979e-003
2.500000e+004,3.172498e+002,1.066094e-003,6.430510e-003
2.500000e+004,3.252560e+002,1.057412e-003,3.087840e-003
2.500000e+004,3.332715e+002,1.051138e-003,-3.707815e-004
2.500000e+004,3.414464e+002,1.047607e-003,-4.287525e-003
2.500000e+004,3.492790e+002,1.047809e-003,-8.784909e-003
2.500000e+004,3.572504e+002,1.052727e-003,-1.319217e-002
2.500000e+004,3.652584e+002,1.067774e-003,-1.954750e-002
2.500000e+004,3.732630e+002,2.939200e-003,-1.090802e-001
2.500000e+004,3.815193e+002,3.355572e-003,-1.222249e-001
2.500000e+004,3.893191e+002,3.327833e-003,-1.250517e-001
2.500000e+004,3.973275e+002,3.279606e-003,-1.266784e-001
2.000000e+004,3.955948e+002,2.636952e-003,-1.200887e-001
2.000000e+004,3.874644e+002,2.678802e-003,-1.147931e-001
2.000000e+004,3.796913e+002,2.719729e-003,-1.134005e-001
2.000000e+004,3.703340e+002,2.759281e-003,-1.077253e-001
2.000000e+004,3.635331e+002,2.765530e-003,-1.031292e-001
2.000000e+004,3.552583e+002,2.700408e-003,-9.902510e-002
2.000000e+004,3.467822e+002,9.476806e-004,-1.060347e-002
2.000000e+004,3.395333e+002,8.541081e-004,2.156183e-003
2.000000e+004,3.307541e+002,8.483331e-004,8.400592e-003
2.000000e+004,3.238709e+002,8.509461e-004,1.164576e-002
2.000000e+004,3.153877e+002,8.585104e-004,1.268668e-002
2.000000e+004,3.077737e+002,8.660216e-004,1.587388e-002
2.000000e+004,3.001190e+002,8.738242e-004,1.617735e-002
2.000000e+004,3.073535e+002,8.649557e-004,1.303235e-002
2.000000e+004,3.152770e+002,8.562976e-004,9.972319e-003
2.000000e+004,3.233192e+002,8.489987e-004,6.788252e-003
2.000000e+004,3.313045e+002,8.433355e-004,3.376880e-003
2.000000e+004,3.392129e+002,8.402226e-004,-4.471713e-004
2.000000e+004,3.472529e+002,8.393776e-004,-4.708041e-003
2.000000e+004,3.552682e+002,8.424316e-004,-8.637907e-003
2.000000e+004,3.632618e+002,8.517097e-004,-1.384763e-002
2.000000e+004,3.712715e+002,1.519633e-003,-7.490572e-002
2.000000e+004,3.792808e+002,2.684511e-003,-1.157482e-001
2.000000e+004,3.872394e+002,2.671427e-003,-1.190152e-001
2.000000e+004,3.952586e+002,2.635303e-003,-1.210093e-001
1.500000e+004,3.976955e+002,1.970300e-003,-1.162882e-001
1.500000e+004,3.891535e+002,2.004682e-003,-1.107053e-001
1.500000e+004,3.818198e+002,2.031929e-003,-1.064598e-001
1.500000e+004,3.730217e+002,2.064673e-003,-1.042159e-001
1.500000e+004,3.647753e+002,2.077312e-003,-9.870486e-002
1.500000e+004,3.574972e+002,2.058690e-003,-9.653476e-002
1.500000e+004,3.485466e+002,1.242741e-003,-5.303868e-002
1.500000e+004,3.419066e+002,6.466642e-004,6.192746e-003
1.500000e+004,3.329130e+002,6.383612e-004,1.032345e-002
1.500000e+004,3.257556e+002,6.403212e-004,1.512547e-002
1.500000e+004,3.174278e+002,6.451031e-004,1.588012e-002
1.500000e+004,3.097041e+002,6.503718e-004,1.911682e-002
1.500000e+004,3.015389e+002,6.574220e-004,1.909759e-002
1.500000e+004,3.052961e+002,6.528154e-004,1.617267e-002
1.500000e+004,3.132506e+002,6.461132e-004,1.284902e-002
1.500000e+004,3.214685e+002,6.403937e-004,9.431301e-003
1.500000e+004,3.293188e+002,6.358161e-004,6.439319e-003
1.500000e+004,3.372531e+002,6.327705e-004,2.748583e-003
1.500000e+004,3.452633e+002,6.316672e-004,-1.736918e-003
1.500000e+004,3.532362e+002,6.330272e-004,-5.957809e-003
1.500000e+004,3.614746e+002,6.383973e-004,-1.152959e-002
1.500000e+004,3.693212e+002,6.813463e-004,-2.288699e-002
1.500000e+004,3.773081e+002,2.008774e-003,-1.123056e-001
1.500000e+004,3.852248e+002,2.010416e-003,-1.161502e-001
1.500000e+004,3.932599e+002,1.985101e-003,-1.186338e-001
1.000000e+004,4.000035e+002,1.307472e-003,-1.157630e-001
1.000000e+004,3.913414e+002,1.332423e-003,-1.098358e-001
1.000000e+004,3.836634e+002,1.351916e-003,-1.051585e-001
1.000000e+004,3.752176e+002,1.373386e-003,-1.034969e-001
1.000000e+004,3.664643e+002,1.386363e-003,-9.775008e-002
1.000000e+004,3.597370e+002,1.379088e-003,-9.626538e-002
1.000000e+004,3.506011e+002,1.160004e-003,-7.407388e-002
1.000000e+004,3.435574e+002,4.371569e-004,5.799003e-003
1.000000e+004,3.349139e+002,4.286184e-004,1.035854e-002
1.000000e+004,3.273263e+002,4.289645e-004,1.502688e-002
1.000000e+004,3.194296e+002,4.317418e-004,1.511468e-002
1.000000e+004,3.114993e+002,4.350962e-004,1.886688e-002
1.000000e+004,3.037273e+002,4.396689e-004,1.891113e-002
1.000000e+004,3.033515e+002,4.391144e-004,1.784565e-002
1.000000e+004,3.112556e+002,4.345076e-004,1.418706e-002
1.000000e+004,3.192391e+002,4.303913e-004,1.097036e-002
1.000000e+004,3.272495e+002,4.271490e-004,7.658334e-003
1.000000e+004,3.352678e+002,4.247625e-004,3.599059e-003
1.000000e+004,3.432080e+002,4.234508e-004,-4.549350e-004
1.000000e+004,3.512508e+002,4.240393e-004,-4.224929e-003
1.000000e+004,3.592248e+002,4.266541e-004,-9.216009e-003
1.000000e+004,3.672264e+002,4.358007e-004,-1.604116e-002
1.000000e+004,3.752401e+002,1.328692e-003,-1.094065e-001
1.000000e+004,3.832617e+002,1.344281e-003,-1.142006e-001
1.000000e+004,3.912730e+002,1.329566e-003,-1.168092e-001
1.000000e+004,3.992509e+002,1.309559e-003,-1.185477e-001
9.000000e+003,3.934139e+002,1.194506e-003,-1.098009e-001
9.000000e+003,3.855828e+002,1.206442e-003,-1.023122e-001
9.000000e+003,3.774579e+002,1.232018e-003,-1.036777e-001
9.000000e+003,3.683612e+002,1.247368e-003,-9.794755e-002
9.000000e+003,3.618037e+002,1.246341e-003,-9.343222e-002
9.000000e+003,3.527561e+002,1.148035e-003,-8.273882e-002
9.000000e+003,3.449604e+002,3.974853e-004,4.275741e-003
9.000000e+003,3.374739e+002,3.879351e-004,9.071453e-003
9.000000e+003,3.290383e+002,3.866007e-004,1.453052e-002
9.000000e+003,3.216534e+002,3.882988e-004,1.540818e-002
9.000000e+003,3.133966e+002,3.918706e-004,1.834491e-002
9.000000e+003,3.059465e+002,3.951482e-004,2.028230e-002
9.000000e+003,3.012097e+002,3.937934e-004,9.931065e-005
9.000000e+003,3.092895e+002,3.928478e-004,1.579057e-002
9.000000e+003,3.172998e+002,3.889842e-004,1.242510e-002
9.000000e+003,3.252728e+002,3.858413e-004,8.975749e-003
9.000000e+003,3.332050e+002,3.832011e-004,5.354987e-003
9.000000e+003,3.414651e+002,3.820770e-004,1.464842e-003
9.000000e+003,3.492153e+002,3.821935e-004,-2.506374e-003
9.000000e+003,3.572632e+002,3.840326e-004,-7.111915e-003
9.000000e+003,3.652798e+002,3.893298e-004,-1.342077e-002
9.000000e+003,3.732799e+002,1.097389e-003,-1.010874e-001
9.000000e+003,3.814928e+002,1.212387e-003,-1.126445e-001
9.000000e+003,3.893344e+002,1.201398e-003,-1.151938e-001
9.000000e+003,3.972507e+002,1.184061e-003,-1.171072e-001
8.000000e+003,3.955599e+002,1.057750e-003,-1.106942e-001
8.000000e+003,3.874948e+002,1.074758e-003,-1.051503e-001
8.000000e+003,3.797729e+002,1.091060e-003,-1.037776e-001
8.000000e+003,3.701848e+002,1.107514e-003,-9.796377e-002
8.000000e+003,3.631848e+002,1.109315e-003,-9.287838e-002
8.000000e+003,3.553344e+002,1.087119e-003,-8.938615e-002
8.000000e+003,3.470332e+002,4.221913e-004,-1.254059e-002
8.000000e+003,3.395447e+002,3.471032e-004,7.486274e-003
8.000000e+003,3.307366e+002,3.439688e-004,1.451223e-002
8.000000e+003,3.238730e+002,3.452171e-004,1.761806e-002
8.000000e+003,3.155276e+002,3.482956e-004,1.840731e-002
8.000000e+003,3.077663e+002,3.512185e-004,2.143168e-002
8.000000e+003,3.001154e+002,3.548978e-004,2.153572e-002
8.000000e+003,3.074057e+002,3.508475e-004,1.758169e-002
8.000000e+003,3.152633e+002,3.473396e-004,1.426861e-002
8.000000e+003,3.232423e+002,3.444893e-004,1.065864e-002
8.000000e+003,3.312279e+002,3.420249e-004,7.162784e-003
8.000000e+003,3.392797e+002,3.406396e-004,3.560684e-003
8.000000e+003,3.473206e+002,3.404836e-004,-1.089663e-003
8.000000e+003,3.552454e+002,3.415055e-004,-5.730903e-003
8.000000e+003,3.632485e+002,3.450730e-004,-1.134181e-002
8.000000e+003,3.712882e+002,6.396803e-004,-7.193960e-002
8.000000e+003,3.792721e+002,1.078262e-003,-1.104231e-001
8.000000e+003,3.872698e+002,1.072021e-003,-1.136651e-001
8.000000e+003,3.952903e+002,1.057156e-003,-1.156981e-001
7.000000e+003,3.977916e+002,9.236429e-004,-1.111197e-001
7.000000e+003,3.893100e+002,9.397778e-004,-1.052415e-001
7.000000e+003,3.817314e+002,9.530816e-004,-1.009665e-001
7.000000e+003,3.726680e+002,9.687082e-004,-9.851177e-002
7.000000e+003,3.644298e+002,9.745858e-004,-9.307420e-002
7.000000e+003,3.573713e+002,9.670956e-004,-9.079349e-002
7.000000e+003,3.486416e+002,6.270519e-004,-5.301537e-002
7.000000e+003,3.419183e+002,3.071206e-004,9.177247e-003
7.000000e+003,3.327872e+002,3.026197e-004,1.354071e-002
7.000000e+003,3.256057e+002,3.032018e-004,1.725505e-002
7.000000e+003,3.173481e+002,3.053622e-004,1.819440e-002
7.000000e+003,3.096378e+002,3.080408e-004,2.113442e-002
7.000000e+003,3.015121e+002,3.109872e-004,2.223874e-002
7.000000e+003,3.053715e+002,3.091815e-004,1.876231e-002
7.000000e+003,3.132526e+002,3.060474e-004,1.501808e-002
7.000000e+003,3.214725e+002,3.032812e-004,1.155254e-002
7.000000e+003,3.292886e+002,3.012110e-004,8.017613e-003
7.000000e+003,3.372122e+002,2.993519e-004,4.695008e-003
7.000000e+003,3.452418e+002,2.992040e-004,3.410384e-004
7.000000e+003,3.532537e+002,2.995785e-004,-4.083415e-003
7.000000e+003,3.615009e+002,3.023195e-004,-9.271553e-003
7.000000e+003,3.692965e+002,3.269925e-004,-2.256062e-002
7.000000e+003,3.773196e+002,9.438908e-004,-1.082140e-001
7.000000e+003,3.852068e+002,9.433272e-004,-1.120629e-001
7.000000e+003,3.932537e+002,9.311017e-004,-1.143089e-001
6.000000e+003,4.000035e+002,7.881660e-004,-1.114321e-001
6.000000e+003,3.912578e+002,8.031462e-004,-1.052794e-001
6.000000e+003,3.836843e+002,8.145334e-004,-1.007404e-001
6.000000e+003,3.752888e+002,8.271137e-004,-9.953494e-002
6.000000e+003,3.665212e+002,8.357662e-004,-9.335615e-002
6.000000e+003,3.596927e+002,8.329817e-004,-9.189209e-002
6.000000e+003,3.504629e+002,6.993829e-004,-6.937794e-002
6.000000e+003,3.434346e+002,2.660751e-004,7.803500e-003
6.000000e+003,3.348334e+002,2.606819e-004,1.229560e-002
6.000000e+003,3.266940e+002,2.607768e-004,1.716281e-002
6.000000e+003,3.193891e+002,2.622646e-004,1.746330e-002
6.000000e+003,3.111944e+002,2.646491e-004,2.081106e-002
6.000000e+003,3.036711e+002,2.672214e-004,2.111290e-002
6.000000e+003,3.033442e+002,2.668491e-004,1.961951e-002
6.000000e+003,3.113208e+002,2.640098e-004,1.631519e-002
6.000000e+003,3.192775e+002,2.615283e-004,1.273937e-002
6.000000e+003,3.273220e+002,2.595622e-004,9.285685e-003
6.000000e+003,3.352947e+002,2.579893e-004,5.458140e-003
6.000000e+003,3.432410e+002,2.574952e-004,1.876401e-003
6.000000e+003,3.512557e+002,2.574440e-004,-2.628100e-003
6.000000e+003,3.592664e+002,2.592623e-004,-7.423622e-003
6.000000e+003,3.672563e+002,2.648832e-004,-1.465826e-002
6.000000e+003,3.752344e+002,8.030308e-004,-1.056888e-001
6.000000e+003,3.832587e+002,8.105758e-004,-1.105881e-001
6.000000e+003,3.912357e+002,8.018794e-004,-1.131648e-001
6.000000e+003,3.992799e+002,7.896634e-004,-1.149100e-001
5.000000e+003,3.934578e+002,6.673624e-004,-1.064011e-001
5.000000e+003,3.856339e+002,6.775907e-004,-1.013095e-001
5.000000e+003,3.776624e+002,6.880935e-004,-9.976765e-002
5.000000e+003,3.685938e+002,6.965477e-004,-9.416255e-002
5.000000e+003,3.617773e+002,6.967685e-004,-8.962220e-002
5.000000e+003,3.528186e+002,6.469688e-004,-7.939329e-002
5.000000e+003,3.451679e+002,2.256866e-004,5.242723e-003
5.000000e+003,3.373420e+002,2.192228e-004,1.022294e-002
5.000000e+003,3.294227e+002,2.180140e-004,1.580670e-002
5.000000e+003,3.215425e+002,2.193918e-004,1.638416e-002
5.000000e+003,3.135502e+002,2.209853e-004,2.030494e-002
5.000000e+003,3.058727e+002,2.231824e-004,2.082136e-002
5.000000e+003,3.012704e+002,2.243177e-004,2.097406e-002
5.000000e+003,3.092668e+002,2.217933e-004,1.737444e-002
5.000000e+003,3.172719e+002,2.196445e-004,1.381821e-002
5.000000e+003,3.252559e+002,2.178798e-004,1.028617e-002
5.000000e+003,3.332936e+002,2.165649e-004,6.275932e-003
5.000000e+003,3.414137e+002,2.158563e-004,2.255707e-003
5.000000e+003,3.493009e+002,2.157039e-004,-1.538449e-003
5.000000e+003,3.573146e+002,2.168091e-004,-6.405906e-003
5.000000e+003,3.653229e+002,2.199393e-004,-1.236645e-002
5.000000e+003,3.733587e+002,6.244010e-004,-9.912692e-002
5.000000e+003,3.815046e+002,6.778106e-004,-1.093258e-001
5.000000e+003,3.892177e+002,6.713979e-004,-1.119714e-001
5.000000e+003,3.972922e+002,6.614494e-004,-1.138644e-001
4.000000e+003,3.955694e+002,5.324852e-004,-1.071177e-001
4.000000e+003,3.874857e+002,5.411509e-004,-1.018001e-001
4.000000e+003,3.796797e+002,5.493261e-004,-1.004561e-001
4.000000e+003,3.705887e+002,5.575194e-004,-9.507773e-002
4.000000e+003,3.634054e+002,5.593728e-004,-9.021825e-002
4.000000e+003,3.551721e+002,5.475606e-004,-8.598318e-002
4.000000e+003,3.469897e+002,2.216339e-004,-1.332289e-002
4.000000e+003,3.395032e+002,1.776275e-004,8.492867e-003
4.000000e+003,3.310073e+002,1.757731e-004,1.446886e-002
4.000000e+003,3.239022e+002,1.762391e-004,1.732106e-002
4.000000e+003,3.151434e+002,1.778730e-004,1.839958e-002
4.000000e+003,3.077513e+002,1.792990e-004,2.125317e-002
4.000000e+003,3.001172e+002,1.811002e-004,2.142447e-002
4.000000e+003,3.074300e+002,1.791024e-004,1.766110e-002
4.000000e+003,3.152948e+002,1.773606e-004,1.391231e-002
4.000000e+003,3.232777e+002,1.758459e-004,1.027636e-002
4.000000e+003,3.312651e+002,1.747115e-004,6.353355e-003
4.000000e+003,3.392889e+002,1.739906e-004,2.525843e-003
4.000000e+003,3.473013e+002,1.736547e-004,-1.567254e-003
4.000000e+003,3.553138e+002,1.743143e-004,-5.784464e-003
4.000000e+003,3.633309e+002,1.759712e-004,-1.114870e-002
4.000000e+003,3.712853e+002,3.282240e-004,-7.111348e-002
4.000000e+003,3.792576e+002,5.435186e-004,-1.080887e-001
4.000000e+003,3.872607e+002,5.400472e-004,-1.115291e-001
4.000000e+003,3.952839e+002,5.323153e-004,-1.134887e-001
3.000000e+003,3.978140e+002,3.986094e-004,-1.086404e-001
3.000000e+003,3.891473e+002,4.055821e-004,-1.026583e-001
3.000000e+003,3.817226e+002,4.113951e-004,-9.866975e-002
3.000000e+003,3.728757e+002,4.180487e-004,-9.642451e-002
3.000000e+003,3.648879e+002,4.209587e-004,-9.100470e-002
3.000000e+003,3.574639e+002,4.176972e-004,-8.868805e-002
3.000000e+003,3.485320e+002,2.747799e-004,-5.186737e-002
3.000000e+003,3.419206e+002,1.354743e-004,7.775773e-003
3.000000e+003,3.323216e+002,1.331848e-004,1.229714e-002
3.000000e+003,3.256711e+002,1.335049e-004,1.615028e-002
3.000000e+003,3.173779e+002,1.345554e-004,1.662862e-002
3.000000e+003,3.095829e+002,1.356887e-004,2.010430e-002
3.000000e+003,3.014960e+002,1.371430e-004,2.012474e-002
3.000000e+003,3.052778e+002,1.360176e-004,1.717106e-002
3.000000e+003,3.132836e+002,1.347245e-004,1.440173e-002
3.000000e+003,3.214685e+002,1.335397e-004,1.024349e-002
3.000000e+003,3.293231e+002,1.326225e-004,7.094771e-003
3.000000e+003,3.372758e+002,1.318726e-004,3.160999e-003
3.000000e+003,3.452585e+002,1.316443e-004,-1.199681e-003
3.000000e+003,3.532588e+002,1.319568e-004,-5.160796e-003
3.000000e+003,3.615062e+002,1.330532e-004,-1.056817e-002
3.000000e+003,3.692690e+002,1.437222e-004,-2.338570e-002
3.000000e+003,3.772909e+002,4.075940e-004,-1.067823e-001
3.000000e+003,3.852729e+002,4.070501e-004,-1.105824e-001
3.000000e+003,3.933008e+002,4.016827e-004,-1.129373e-001
2.500000e+003,4.000035e+002,3.307856e-004,-1.101069e-001
2.500000e+003,3.911833e+002,3.372418e-004,-1.039886e-001
2.500000e+003,3.835771e+002,3.421272e-004,-9.947224e-002
2.500000e+003,3.751523e+002,3.477499e-004,-9.730243e-002
2.500000e+003,3.659750e+002,3.511126e-004,-9.170860e-002
2.500000e+003,3.596772e+002,3.501364e-004,-9.029822e-002
2.500000e+003,3.501035e+002,2.891760e-004,-6.668916e-002
2.500000e+003,3.434842e+002,1.146044e-004,5.630317e-003
2.500000e+003,3.348513e+002,1.120582e-004,1.043866e-002
2.500000e+003,3.271302e+002,1.120106e-004,1.513183e-002
2.500000e+003,3.193688e+002,1.127688e-004,1.568631e-002
2.500000e+003,3.116087e+002,1.136236e-004,1.918146e-002
2.500000e+003,3.036311e+002,1.147470e-004,1.918247e-002
2.500000e+003,3.033206e+002,1.146823e-004,1.849362e-002
2.500000e+003,3.112940e+002,1.134164e-004,1.462930e-002
2.500000e+003,3.192897e+002,1.123678e-004,1.097159e-002
2.500000e+003,3.272665e+002,1.115236e-004,7.288649e-003
2.500000e+003,3.352498e+002,1.108842e-004,3.127391e-003
2.500000e+003,3.432316e+002,1.106902e-004,-1.260757e-004
2.500000e+003,3.512879e+002,1.106062e-004,-4.715553e-003
2.500000e+003,3.592664e+002,1.113217e-004,-9.376254e-003
2.500000e+003,3.672943e+002,1.136953e-004,-1.654951e-002
2.500000e+003,3.752600e+002,3.375587e-004,-1.048629e-001
2.500000e+003,3.832943e+002,3.407567e-004,-1.094351e-001
2.500000e+003,3.912544e+002,3.367263e-004,-1.118738e-001
2.500000e+003,3.992993e+002,3.315514e-004,-1.136598e-001
2.000000e+003,3.933856e+002,2.692658e-004,-1.047324e-001
2.000000e+003,3.851888e+002,2.735060e-004,-9.974972e-002
2.000000e+003,3.773572e+002,2.778607e-004,-9.819292e-002
2.000000e+003,3.675258e+002,2.814927e-004,-9.208576e-002
2.000000e+003,3.617800e+002,2.810875e-004,-8.842325e-002
2.000000e+003,3.523742e+002,2.567298e-004,-7.587329e-002
2.000000e+003,3.448293e+002,9.345672e-005,2.844563e-003
2.000000e+003,3.372828e+002,9.089383e-005,8.485504e-003
2.000000e+003,3.287602e+002,9.051316e-005,1.359566e-002
2.000000e+003,3.216329e+002,9.098133e-005,1.408477e-002
2.000000e+003,3.133751e+002,9.170306e-005,1.756244e-002
2.000000e+003,3.058450e+002,9.248866e-005,1.839038e-002
2.000000e+003,3.012418e+002,9.289013e-005,1.851292e-002
2.000000e+003,3.093254e+002,9.191308e-005,1.448677e-002
2.000000e+003,3.173058e+002,9.103911e-005,1.121890e-002
2.000000e+003,3.252643e+002,9.028819e-005,7.061305e-003
2.000000e+003,3.333025e+002,8.963204e-005,3.434828e-003
2.000000e+003,3.415047e+002,8.950558e-005,-1.056914e-004
2.000000e+003,3.492912e+002,8.946951e-005,-4.516130e-003
2.000000e+003,3.572607e+002,8.978030e-005,-8.994279e-003
2.000000e+003,3.652342e+002,9.103838e-005,-1.459039e-002
2.000000e+003,3.733080e+002,2.513675e-004,-9.802842e-002
2.000000e+003,3.815959e+002,2.734339e-004,-1.083432e-001
2.000000e+003,3.892729e+002,2.710536e-004,-1.114087e-001
2.000000e+003,3.972731e+002,2.669832e-004,-1.130814e-001
1.500000e+003,3.955028e+002,2.016901e-004,-1.063541e-001
1.500000e+003,3.871030e+002,2.051235e-004,-1.008049e-001
1.500000e+003,3.797176e+002,2.081326e-004,-9.944465e-002
1.500000e+003,3.699058e+002,2.114221e-004,-9.346465e-002
1.500000e+003,3.626411e+002,2.118379e-004,-8.854073e-002
1.500000e+003,3.551316e+002,2.077175e-004,-8.488487e-002
1.500000e+003,3.461975e+002,7.541961e-005,-5.859697e-003
1.500000e+003,3.395379e+002,6.966611e-005,4.950237e-003
1.500000e+003,3.302403e+002,6.886572e-005,1.112914e-002
1.500000e+003,3.239418e+002,6.905955e-005,1.420051e-002
1.500000e+003,3.151081e+002,6.967093e-005,1.484390e-002
1.500000e+003,3.078317e+002,7.023170e-005,1.752520e-002
1.500000e+003,3.001066e+002,7.093497e-005,1.795926e-002
1.500000e+003,3.073610e+002,7.018200e-005,1.414829e-002
1.500000e+003,3.152377e+002,6.947792e-005,1.066309e-002
1.500000e+003,3.232922e+002,6.880554e-005,7.036249e-003
1.500000e+003,3.313001e+002,6.845900e-005,3.373969e-003
1.500000e+003,3.392682e+002,6.812383e-005,6.240836e-005
1.500000e+003,3.473133e+002,6.808591e-005,-4.557387e-003
1.500000e+003,3.552428e+002,6.830976e-005,-8.844880e-003
1.500000e+003,3.633016e+002,6.897683e-005,-1.435744e-002
1.500000e+003,3.711880e+002,1.223830e-004,-6.866467e-002
1.500000e+003,3.792896e+002,2.061139e-004,-1.071591e-001
1.500000e+003,3.873032e+002,2.047365e-004,-1.103522e-001
1.500000e+003,3.953062e+002,2.017949e-004,-1.124327e-001
1.000000e+003,3.977948e+002,1.344323e-004,-1.078637e-001
1.000000e+003,3.893377e+002,1.368230e-004,-1.010926e-001
1.000000e+003,3.817933e+002,1.387428e-004,-9.747765e-002
1.000000e+003,3.722620e+002,1.411932e-004,-9.483097e-002
1.000000e+003,3.639996e+002,1.420435e-004,-8.932683e-002
1.000000e+003,3.573096e+002,1.411659e-004,-8.721833e-002
1.000000e+003,3.479168e+002,8.000497e-005,-4.002981e-002
1.000000e+003,3.419042e+002,4.775124e-005,2.547095e-003
1.000000e+003,3.323128e+002,4.700297e-005,8.370445e-003
1.000000e+003,3.252686e+002,4.707512e-005,1.158197e-002
1.000000e+003,3.172461e+002,4.743967e-005,1.314140e-002
1.000000e+003,3.094124e+002,4.781639e-005,1.592834e-002
1.000000e+003,3.008620e+002,4.831539e-005,1.645833e-002
1.000000e+003,3.052980e+002,4.799121e-005,1.422060e-002
1.000000e+003,3.132895e+002,4.746376e-005,1.004531e-002
1.000000e+003,3.214541e+002,4.709325e-005,5.668906e-003
1.000000e+003,3.292907e+002,4.675378e-005,2.100415e-003
1.000000e+003,3.372872e+002,4.651791e-005,-7.867131e-004
1.000000e+003,3.452514e+002,4.643899e-005,-5.645702e-003
1.000000e+003,3.533014e+002,4.650027e-005,-1.006083e-002
1.000000e+003,3.615035e+002,4.685382e-005,-1.585180e-002
1.000000e+003,3.693542e+002,5.107027e-005,-2.706386e-002
1.000000e+003,3.772276e+002,1.377750e-004,-1.055529e-001
1.000000e+003,3.852700e+002,1.375404e-004,-1.089250e-001
1.000000e+003,3.932631e+002,1.357133e-004,-1.115382e-001
9.000000e+002,4.000035e+002,1.204588e-004,-1.091170e-001
9.000000e+002,3.911802e+002,1.227328e-004,-1.026661e-001
9.000000e+002,3.836455e+002,1.245863e-004,-9.807079e-002
9.000000e+002,3.750756e+002,1.266876e-004,-9.617071e-002
9.000000e+002,3.657054e+002,1.280058e-004,-8.979946e-002
9.000000e+002,3.596824e+002,1.277055e-004,-8.888221e-002
9.000000e+002,3.496148e+002,1.029660e-004,-6.350099e-002
9.000000e+002,3.429394e+002,4.347559e-005,2.921908e-003
9.000000e+002,3.347124e+002,4.265531e-005,5.309709e-003
9.000000e+002,3.265793e+002,4.263097e-005,9.881260e-003
9.000000e+002,3.193629e+002,4.289751e-005,1.167001e-002
9.000000e+002,3.109380e+002,4.324063e-005,1.391852e-002
9.000000e+002,3.036801e+002,4.362236e-005,1.440985e-002
9.000000e+002,3.033370e+002,4.358067e-005,1.389900e-002
9.000000e+002,3.112978e+002,4.312602e-005,1.012369e-002
9.000000e+002,3.192776e+002,4.271841e-005,7.485745e-003
9.000000e+002,3.272537e+002,4.242449e-005,2.582216e-003
9.000000e+002,3.352701e+002,4.218122e-005,-1.558632e-004
9.000000e+002,3.432575e+002,4.201022e-005,-3.518592e-003
9.000000e+002,3.513078e+002,4.207534e-005,-8.814737e-003
9.000000e+002,3.593209e+002,4.232642e-005,-1.392472e-002
9.000000e+002,3.672291e+002,4.313532e-005,-2.108647e-002
9.000000e+002,3.752799e+002,1.232007e-004,-1.033600e-001
9.000000e+002,3.833152e+002,1.242859e-004,-1.082966e-001
9.000000e+002,3.913226e+002,1.227575e-004,-1.102914e-001
9.000000e+002,3.992703e+002,1.209338e-004,-1.126590e-001
8.000000e+002,3.933261e+002,1.087975e-004,-1.037562e-001
8.000000e+002,3.853181e+002,1.104407e-004,-9.870358e-002
8.000000e+002,3.773515e+002,1.122939e-004,-9.720150e-002
8.000000e+002,3.674497e+002,1.137701e-004,-9.095827e-002
8.000000e+002,3.616378e+002,1.137151e-004,-8.696559e-002
8.000000e+002,3.522497e+002,1.037596e-004,-7.467225e-002
8.000000e+002,3.444391e+002,3.921166e-005,1.481200e-004
8.000000e+002,3.373238e+002,3.832486e-005,3.634983e-003
8.000000e+002,3.283817e+002,3.811181e-005,9.488193e-003
8.000000e+002,3.215590e+002,3.828265e-005,1.010028e-002
8.000000e+002,3.130431e+002,3.857168e-005,1.446215e-002
8.000000e+002,3.059207e+002,3.883689e-005,1.532759e-002
8.000000e+002,3.012222e+002,3.910657e-005,1.503138e-002
8.000000e+002,3.093084e+002,3.870262e-005,1.084763e-002
8.000000e+002,3.172958e+002,3.833929e-005,6.670816e-003
8.000000e+002,3.252749e+002,3.801621e-005,2.952751e-003
8.000000e+002,3.332626e+002,3.782210e-005,-4.136933e-004
8.000000e+002,3.415234e+002,3.765973e-005,-4.793349e-003
8.000000e+002,3.493108e+002,3.766365e-005,-8.146008e-003
8.000000e+002,3.573043e+002,3.772155e-005,-1.281345e-002
8.000000e+002,3.652584e+002,3.828933e-005,-1.864721e-002
8.000000e+002,3.732321e+002,1.011815e-004,-9.666817e-002
8.000000e+002,3.815223e+002,1.107548e-004,-1.074319e-001
8.000000e+002,3.892638e+002,1.096153e-004,-1.101417e-001
8.000000e+002,3.972476e+002,1.079676e-004,-1.115629e-001
7.000000e+002,3.955630e+002,9.481471e-005,-1.049423e-001
7.000000e+002,3.869180e+002,9.639973e-005,-9.901950e-002
7.000000e+002,3.796127e+002,9.780482e-005,-9.813927e-002
7.000000e+002,3.700217e+002,9.943703e-005,-9.248355e-002
7.000000e+002,3.629406e+002,9.974815e-005,-8.778324e-002
7.000000e+002,3.547242e+002,9.741547e-005,-8.312720e-002
7.000000e+002,3.460534e+002,3.666479e-005,-7.533494e-003
7.000000e+002,3.394066e+002,3.398141e-005,7.431905e-004
7.000000e+002,3.302228e+002,3.358159e-005,8.422696e-003
7.000000e+002,3.239335e+002,3.369047e-005,9.749194e-003
7.000000e+002,3.149154e+002,3.398160e-005,1.230223e-002
7.000000e+002,3.077494e+002,3.424265e-005,1.460695e-002
7.000000e+002,3.001243e+002,3.453418e-005,1.436069e-002
7.000000e+002,3.072752e+002,3.423619e-005,1.023493e-002
7.000000e+002,3.152849e+002,3.390496e-005,7.692889e-003
7.000000e+002,3.232486e+002,3.357172e-005,3.502357e-003
7.000000e+002,3.312520e+002,3.340508e-005,-6.254707e-004
7.000000e+002,3.392682e+002,3.326398e-005,-4.312015e-003
7.000000e+002,3.472916e+002,3.322442e-005,-7.857503e-003
7.000000e+002,3.553316e+002,3.327580e-005,-1.289885e-002
7.000000e+002,3.632618e+002,3.362015e-005,-1.776745e-002
7.000000e+002,3.712437e+002,5.989837e-005,-7.119687e-002
7.000000e+002,3.792750e+002,9.708823e-005,-1.058301e-001
7.000000e+002,3.873214e+002,9.639202e-005,-1.091018e-001
7.000000e+002,3.953030e+002,9.497348e-005,-1.110864e-001
6.000000e+002,3.977339e+002,8.103754e-005,-1.079855e-001
6.000000e+002,3.890738e+002,8.236734e-005,-1.004214e-001
6.000000e+002,3.818287e+002,8.353801e-005,-9.672806e-002
6.000000e+002,3.725754e+002,8.502805e-005,-9.362543e-002
6.000000e+002,3.643763e+002,8.563741e-005,-8.832853e-002
6.000000e+002,3.574176e+002,8.515030e-005,-8.656317e-002
6.000000e+002,3.480455e+002,5.228768e-005,-4.525568e-002
6.000000e+002,3.419487e+002,2.961176e-005,4.838011e-004
6.000000e+002,3.324759e+002,2.905723e-005,5.964498e-003
6.000000e+002,3.257430e+002,2.912225e-005,9.517752e-003
6.000000e+002,3.171465e+002,2.931056e-005,1.000982e-002
6.000000e+002,3.095829e+002,2.958963e-005,1.448127e-002
6.000000e+002,3.014423e+002,2.985401e-005,1.405796e-002
6.000000e+002,3.053348e+002,2.968456e-005,9.464767e-003
6.000000e+002,3.132370e+002,2.940194e-005,7.596356e-003
6.000000e+002,3.214932e+002,2.911037e-005,4.086555e-003
6.000000e+002,3.293037e+002,2.889302e-005,8.617065e-005
6.000000e+002,3.372281e+002,2.876568e-005,-4.305419e-003
6.000000e+002,3.452418e+002,2.873115e-005,-8.478311e-003
6.000000e+002,3.532638e+002,2.870983e-005,-1.118741e-002
6.000000e+002,3.615799e+002,2.896295e-005,-1.640805e-002
6.000000e+002,3.693074e+002,3.173745e-005,-3.001803e-002
6.000000e+002,3.772592e+002,8.311452e-005,-1.045376e-001
6.000000e+002,3.852699e+002,8.292451e-005,-1.079330e-001
6.000000e+002,3.933070e+002,8.181504e-005,-1.102908e-001
5.000000e+002,4.000035e+002,6.701828e-005,-1.080630e-001
5.000000e+002,3.913508e+002,6.839437e-005,-1.017154e-001
5.000000e+002,3.835950e+002,6.941717e-005,-9.722209e-002
5.000000e+002,3.749080e+002,7.067576e-005,-9.526865e-002
5.000000e+002,3.658887e+002,7.138222e-005,-8.939247e-002
5.000000e+002,3.595549e+002,7.122949e-005,-8.823292e-002
5.000000e+002,3.502709e+002,6.053690e-005,-6.652747e-002
5.000000e+002,3.437253e+002,2.514407e-005,-3.888780e-003
5.000000e+002,3.346834e+002,2.453255e-005,1.248248e-003
5.000000e+002,3.268959e+002,2.451225e-005,8.476587e-003
5.000000e+002,3.195026e+002,2.467719e-005,7.271791e-003
5.000000e+002,3.113246e+002,2.487115e-005,1.213620e-002
5.000000e+002,3.035402e+002,2.509278e-005,1.197213e-002
5.000000e+002,3.033497e+002,2.507114e-005,1.012422e-002
5.000000e+002,3.112805e+002,2.481175e-005,5.757213e-003
5.000000e+002,3.192452e+002,2.461104e-005,3.046227e-003
5.000000e+002,3.273412e+002,2.435115e-005,-5.407989e-004
5.000000e+002,3.353150e+002,2.427299e-005,-4.590884e-003
5.000000e+002,3.432316e+002,2.420387e-005,-8.396288e-003
5.000000e+002,3.512359e+002,2.419439e-005,-1.179095e-002
5.000000e+002,3.592742e+002,2.433932e-005,-1.669613e-002
5.000000e+002,3.673297e+002,2.481588e-005,-2.388952e-002
5.000000e+002,3.753311e+002,6.879140e-005,-1.024487e-001
5.000000e+002,3.832617e+002,6.937190e-005,-1.072716e-001
5.000000e+002,3.912793e+002,6.844898e-005,-1.101348e-001
5.000000e+002,3.993316e+002,6.749097e-005,-1.113279e-001
4.000000e+002,3.934359e+002,5.444564e-005,-1.027104e-001
4.000000e+002,3.851319e+002,5.533569e-005,-9.776568e-002
4.000000e+002,3.775328e+002,5.630180e-005,-9.570559e-002
4.000000e+002,3.679348e+002,5.703025e-005,-9.049788e-002
4.000000e+002,3.617720e+002,5.707577e-005,-8.579697e-002
4.000000e+002,3.524166e+002,5.259266e-005,-7.432862e-002
4.000000e+002,3.444771e+002,2.050721e-005,-4.610751e-003
4.000000e+002,3.371989e+002,1.999814e-005,3.117776e-004
4.000000e+002,3.283217e+002,1.987776e-005,5.545671e-003
4.000000e+002,3.216288e+002,1.999327e-005,5.527801e-003
4.000000e+002,3.132528e+002,2.012965e-005,8.631893e-003
4.000000e+002,3.058782e+002,2.033707e-005,1.087901e-002
4.000000e+002,3.012597e+002,2.039768e-005,1.028893e-002
4.000000e+002,3.093254e+002,2.016542e-005,3.862131e-003
4.000000e+002,3.173278e+002,2.000808e-005,1.175710e-003
4.000000e+002,3.252938e+002,1.988866e-005,-3.696599e-003
4.000000e+002,3.332737e+002,1.972491e-005,-6.343435e-003
4.000000e+002,3.415164e+002,1.965055e-005,-8.687153e-003
4.000000e+002,3.492912e+002,1.966707e-005,-1.327446e-002
4.000000e+002,3.573043e+002,1.968298e-005,-1.643933e-002
4.000000e+002,3.652288e+002,1.990138e-005,-2.204903e-002
4.000000e+002,3.732799e+002,5.131396e-005,-9.637573e-002
4.000000e+002,3.815812e+002,5.559425e-005,-1.063600e-001
4.000000e+002,3.893282e+002,5.505548e-005,-1.090372e-001
4.000000e+002,3.972731e+002,5.424464e-005,-1.118835e-001
3.000000e+002,3.956392e+002,4.059304e-005,-1.044500e-001
3.000000e+002,3.869907e+002,4.132149e-005,-9.982286e-002
3.000000e+002,3.797030e+002,4.198266e-005,-9.804435e-002
3.000000e+002,3.699691e+002,4.265837e-005,-9.181513e-002
3.000000e+002,3.628690e+002,4.286516e-005,-8.671641e-002
3.000000e+002,3.550126e+002,4.202467e-005,-8.310289e-002
3.000000e+002,3.463441e+002,1.728955e-005,-1.567544e-002
3.000000e+002,3.395540e+002,1.539525e-005,-5.415634e-003
3.000000e+002,3.303141e+002,1.519284e-005,2.321487e-003
3.000000e+002,3.239209e+002,1.521197e-005,3.557186e-003
3.000000e+002,3.151810e+002,1.537546e-005,4.659146e-003
3.000000e+002,3.077775e+002,1.551910e-005,9.064512e-003
3.000000e+002,3.001101e+002,1.565908e-005,1.054210e-002
3.000000e+002,3.073871e+002,1.550912e-005,2.782967e-003
3.000000e+002,3.152495e+002,1.534502e-005,5.246543e-004
3.000000e+002,3.233358e+002,1.521437e-005,-3.530665e-003
3.000000e+002,3.313307e+002,1.508342e-005,-6.790591e-003
3.000000e+002,3.392773e+002,1.502111e-005,-7.758677e-003
3.000000e+002,3.472722e+002,1.499122e-005,-1.487030e-002
3.000000e+002,3.553290e+002,1.500273e-005,-1.821342e-002
3.000000e+002,3.632565e+002,1.515871e-005,-2.329483e-002
3.000000e+002,3.713605e+002,2.678949e-005,-7.280318e-002
3.000000e+002,3.793303e+002,4.167336e-005,-1.056968e-001
3.000000e+002,3.023702e+002,1.500867e-005,1.481445e-002
3.000000e+002,3.102950e+002,1.486990e-005,8.317539e-003
3.000000e+002,3.182472e+002,1.474040e-005,5.409456e-003
3.000000e+002,3.262717e+002,1.460288e-005,1.404108e-005
3.000000e+002,3.342877e+002,1.452123e-005,-2.908597e-003
3.000000e+002,3.422885e+002,1.448173e-005,-7.793081e-003
3.000000e+002,3.502509e+002,1.441938e-005,-1.212219e-002
3.000000e+002,3.582258e+002,1.449178e-005,-1.915840e-002
3.000000e+002,3.662504e+002,1.467343e-005,-2.380606e-002
3.000000e+002,3.742588e+002,3.881851e-005,-9.932722e-002
3.000000e+002,3.822243e+002,4.074199e-005,-1.080978e-001
3.000000e+002,3.903135e+002,4.026244e-005,-1.113068e-001
3.000000e+002,3.983015e+002,3.972924e-005,-1.137327e-001
2.000000e+002,3.944460e+002,2.635103e-005,-1.055093e-001
2.000000e+002,3.862371e+002,2.675824e-005,-1.024864e-001
2.000000e+002,3.785901e+002,2.712744e-005,-1.013311e-001
2.000000e+002,3.686241e+002,2.750055e-005,-9.435037e-002
2.000000e+002,3.620120e+002,2.754789e-005,-9.122556e-002
2.000000e+002,3.536858e+002,2.645579e-005,-8.495472e-002
2.000000e+002,3.450057e+002,1.035105e-005,-1.511857e-002
2.000000e+002,3.385037e+002,1.007847e-005,-9.260181e-003
2.000000e+002,3.286505e+002,9.951746e-006,-3.440727e-003
2.000000e+002,3.228005e+002,1.005053e-005,-5.031519e-003
2.000000e+002,3.136710e+002,1.009503e-005,1.674394e-003
2.000000e+002,3.067987e+002,1.017199e-005,1.239361e-003
2.000000e+002,3.000481e+002,1.025421e-005,5.488157e-003
2.000000e+002,3.083530e+002,1.016868e-005,-3.363630e-003
2.000000e+002,3.163286e+002,1.005770e-005,-6.294594e-003
2.000000e+002,3.242971e+002,9.941865e-006,-8.189198e-003
2.000000e+002,3.323257e+002,9.914649e-006,-9.287992e-003
2.000000e+002,3.402377e+002,9.853116e-006,-1.363105e-002
2.000000e+002,3.482786e+002,9.829566e-006,-2.060468e-002
2.000000e+002,3.562807e+002,9.859124e-006,-2.642391e-002
2.000000e+002,3.642959e+002,9.934001e-006,-3.102677e-002
2.000000e+002,3.722645e+002,2.025554e-005,-8.552904e-002
2.000000e+002,3.802548e+002,2.682202e-005,-1.066879e-001
2.000000e+002,3.883023e+002,2.653529e-005,-1.079211e-001
2.000000e+002,3.962907e+002,2.619682e-005,-1.106753e-001
1.000000e+002,3.966539e+002,1.244294e-005,-1.052486e-001
1.000000e+002,3.882261e+002,1.260540e-005,-9.843855e-002
1.000000e+002,3.808639e+002,1.280105e-005,-9.486020e-002
1.000000e+002,3.713776e+002,1.296934e-005,-9.055819e-002
1.000000e+002,3.634320e+002,1.309132e-005,-8.310468e-002
1.000000e+002,3.561230e+002,1.300958e-005,-8.531503e-002
1.000000e+002,3.466113e+002,6.046019e-006,-3.051116e-002
1.000000e+002,3.405809e+002,5.257598e-006,-1.911892e-002
1.000000e+002,3.311035e+002,5.231556e-006,-1.625851e-002
1.000000e+002,3.247810e+002,5.231575e-006,-3.400969e-003
1.000000e+002,3.160376e+002,5.278617e-006,-3.331160e-003
1.000000e+002,3.087574e+002,5.324096e-006,-7.298142e-003
1.000000e+002,3.001190e+002,5.370059e-006,-4.724293e-004
1.000000e+002,3.063998e+002,5.337405e-006,-4.343456e-003
1.000000e+002,3.142897e+002,5.254840e-006,-7.636867e-003
1.000000e+002,3.222485e+002,5.194830e-006,-1.745402e-002
1.000000e+002,3.302313e+002,5.177564e-006,-1.596365e-002
1.000000e+002,3.382791e+002,5.111443e-006,-1.741207e-002
1.000000e+002,3.462888e+002,5.147592e-006,-2.512613e-002
1.000000e+002,3.542718e+002,5.122201e-006,-2.895181e-002
1.000000e+002,3.622364e+002,5.134873e-006,-2.795009e-002
1.000000e+002,3.703365e+002,6.320625e-006,-5.339234e-002
1.000000e+002,3.782773e+002,1.268404e-005,-1.012607e-001
1.000000e+002,3.863276e+002,1.263214e-005,-1.011129e-001
1.000000e+002,3.943165e+002,1.247276e-005,-1.053974e-001
0.000000e+000,3.988321e+002,-1.748286e-006,-1.112388e-001
0.000000e+000,3.901811e+002,-1.790816e-006,-9.714717e-002
0.000000e+000,3.827037e+002,-1.827094e-006,-1.153324e-001
0.000000e+000,3.739568e+002,-1.836980e-006,-8.649149e-002
0.000000e+000,3.650059e+002,-1.841043e-006,-9.112518e-002
0.000000e+000,3.585463e+002,-1.821295e-006,-8.396780e-002
0.000000e+000,3.489540e+002,-1.141020e-006,-6.672543e-002
0.000000e+000,3.428005e+002,-7.018487e-008,0.000000e+000
0.000000e+000,3.337134e+002,-5.957032e-008,0.000000e+000
0.000000e+000,3.262887e+002,-5.970905e-008,-3.981066e-002
0.000000e+000,3.183199e+002,-4.000111e-007,1.150233e+000
0.000000e+000,3.101124e+002,-2.412181e-007,5.698335e-001
0.000000e+000,3.026821e+002,-8.495816e-008,0.000000e+000
0.000000e+000,3.043561e+002,-2.274944e-007,5.857965e-001
0.000000e+000,3.122767e+002,-2.573041e-007,5.996975e-001
0.000000e+000,3.202784e+002,-8.154528e-008,0.000000e+000
0.000000e+000,3.283171e+002,-4.652674e-008,7.668972e-003
0.000000e+000,3.362720e+002,-2.027789e-007,5.487098e-001
0.000000e+000,3.442609e+002,-7.299711e-008,0.000000e+000
0.000000e+000,3.522617e+002,-3.670129e-007,1.118494e+000
0.000000e+000,3.602690e+002,-4.042414e-007,1.086805e+000
0.000000e+000,3.682625e+002,-7.488298e-008,9.316745e-001
0.000000e+000,3.762754e+002,-1.743520e-006,-1.030818e-001
0.000000e+000,3.843079e+002,-1.755716e-006,-9.299164e-002
0.000000e+000,3.923216e+002,-1.783435e-006,-1.152367e-001
0.000000e+000,3.999905e+002,-1.857432e-006,-1.255777e-001