File: dmuchawiec/STO-N11-12p5g-15a-600C-vac-old_MvH_T-300-K-full_231026_v2.rso.dat
[Header]
TITLE,MPMS RSO Measurement
BYAPP,MPMS Measurement,1.1,Summary
FILEOPENTIME, 1698355527.984000 10/26/2023, 11:25:27 PM

INFO, APPNAME, MPMS MultiVu Application, Revision 1.60,  Build 081

INFO, NAME, STO-N11-12p5g-15a-600C-vac-old
INFO, WEIGHT, 98.480
INFO, AREA, 0.000
INFO, LENGTH, 0.000
INFO, SHAPE, 0
INFO, COMMENT,
INFO, SEQUENCE FILE: MvsH-full_mod_MvT.seq


INFO, BACKGROUND DATA FILE:, None


STARTUPAXIS,X,4,LINEAR,AUTO,0.000000,0.000000
STARTUPAXIS,Y1,5,LINEAR,AUTO,0.000000,0.000000


STARTUPGROUP,Longitudinal
FIELDGROUP,Longitudinal,1,2,3,4,5,6,7,8,9,10,11,19,20,21,22,23,35
FIELDGROUP,Transverse,1,2,3,4,12,13,14,15,16,17,18,24,25,26,27,28,35

PLOT_APPEARANCE,ALL,HORZ_GRID_ON,VERT_GRID_ON,MARKERS_AND_LINES

[Data]
Time,Comment,Field (Oe),Temperature (K),Long Moment (emu),Long Scan Std Dev,Long Offset (cm),Long Offset Std Dev,Long Algorithm,Long Reg Fit,Long Reg Factor,Trans Moment (emu),Trans Scan Std Dev,Trans Offset (cm),Trans Offset Std Dev,Trans Algorithm,Trans Reg Fit,Trans Reg Factor,Long Moment [w/o ABS] (emu),Long Scan Std Dev [w/o ABS],Long Offset [w/o ABS] (cm),Long Offset Std Dev [w/o ABS],Long Reg Fit [w/o ABS],Trans Moment [w/o ABS] (emu),Trans Scan Std Dev [w/o ABS],Trans Offset [w/o ABS] (cm),Trans Offset Std Dev [w/o ABS],Trans Reg Fit [w/o ABS],RSO Position (deg),Amplitude (cm),Frequency,Cycles to Average,Scans per Measurement,Delta Temp (K),Error,EC Comp. Running,Using ABS,
1698355527.984,,0.000000e+000,3.000012e+002,9.010284e-007,3.389137e-008,6.223416e-002,2.849491e-002,3,7.250961e-001,1.825000e+000,,,,,,,,,,,,,,,,,,0,4.000000e+000,1.000000e+000,2,2,0.000000e+000,0,,0,
1698355551.421,,5.047331e+001,3.000012e+002,4.894460e-006,1.436045e-007,1.271647e-001,1.083556e-002,3,9.276184e-001,1.825000e+000,,,,,,,,,,,,,,,,,,0,4.000000e+000,1.000000e+000,2,2,0.000000e+000,0,,0,
1698355581.914,,1.006840e+002,2.999977e+002,8.457439e-006,3.854993e-008,1.520372e-001,2.774358e-003,3,9.581116e-001,1.825000e+000,,,,,,,,,,,,,,,,,,0,4.000000e+000,1.000000e+000,2,2,7.080078e-003,0,,0,
1698355655.693,,2.011638e+002,2.999977e+002,1.613293e-005,2.079522e-007,1.539582e-001,6.050433e-003,3,9.597143e-001,1.825000e+000,,,,,,,,,,,,,,,,,,0,4.000000e+000,1.000000e+000,2,2,7.080078e-003,0,,0,
1698355689.221,,3.014541e+002,3.000012e+002,2.343455e-005,2.430698e-007,1.619378e-001,3.766516e-003,3,9.663175e-001,1.825000e+000,,,,,,,,,,,,,,,,,,0,4.000000e+000,1.000000e+000,2,2,0.000000e+000,0,,0,
1698355717.930,,4.019338e+002,2.999994e+002,3.053385e-005,2.853787e-007,1.725641e-001,6.732643e-004,3,9.580959e-001,1.825000e+000,,,,,,,,,,,,,,,,,,0,4.000000e+000,1.000000e+000,2,2,7.080078e-003,0,,0,
1698355741.615,,5.023846e+002,2.999994e+002,3.731262e-005,3.623307e-007,1.733118e-001,8.557117e-003,3,9.643795e-001,1.825000e+000,,,,,,,,,,,,,,,,,,0,4.000000e+000,1.000000e+000,2,2,7.080078e-003,0,,0,
1698355781.297,,6.027621e+002,2.999994e+002,4.410690e-005,1.389323e-007,1.834643e-001,1.365347e-004,3,9.662400e-001,1.825000e+000,,,,,,,,,,,,,,,,,,0,4.000000e+000,1.000000e+000,2,2,7.080078e-003,0,,0,
1698355803.037,,7.030231e+002,2.999977e+002,5.039840e-005,1.020397e-006,1.924292e-001,3.007831e-003,3,9.614052e-001,1.825000e+000,,,,,,,,,,,,,,,,,,0,4.000000e+000,1.000000e+000,2,2,7.080078e-003,0,,0,
1698355825.222,,8.034592e+002,3.000012e+002,5.642252e-005,1.364970e-006,1.919440e-001,8.115407e-003,3,9.530586e-001,1.825000e+000,,,,,,,,,,,,,,,,,,0,4.000000e+000,1.000000e+000,2,2,0.000000e+000,0,,0,
1698355847.657,,9.038223e+002,2.999994e+002,5.965611e-005,5.926901e-009,2.167552e-001,1.579775e-002,3,9.366379e-001,1.825000e+000,,,,,,,,,,,,,,,,,,0,4.000000e+000,1.000000e+000,2,2,7.080078e-003,0,,0,
1698355880.935,,1.004331e+003,2.999977e+002,6.463411e-005,1.245575e-007,2.134681e-001,1.202439e-003,3,9.661373e-001,1.825000e+000,,,,,,,,,,,,,,,,,,0,4.000000e+000,1.000000e+000,2,2,7.080078e-003,0,,0,
1698355948.153,,1.255181e+003,2.999994e+002,7.499965e-005,2.755062e-006,2.239611e-001,3.226014e-002,3,8.940251e-001,1.825000e+000,,,,,,,,,,,,,,,,,,0,4.000000e+000,1.000000e+000,2,2,7.080078e-003,0,,0,
1698355970.625,,1.506118e+003,2.999959e+002,8.315381e-005,6.199322e-007,2.538203e-001,3.486851e-003,3,9.641619e-001,1.825000e+000,,,,,,,,,,,,,,,,,,0,4.000000e+000,1.000000e+000,2,2,7.080078e-003,0,,0,
1698355993.341,,1.757230e+003,2.999994e+002,8.789459e-005,3.385639e-007,2.687546e-001,2.353712e-003,3,9.562654e-001,1.825000e+000,,,,,,,,,,,,,,,,,,0,4.000000e+000,1.000000e+000,2,2,7.080078e-003,0,,0,
1698356035.889,,2.008283e+003,2.999994e+002,9.119559e-005,1.441904e-007,2.851999e-001,7.390450e-004,3,9.700326e-001,1.825000e+000,,,,,,,,,,,,,,,,,,0,4.000000e+000,1.000000e+000,2,2,7.080078e-003,0,,0,
1698356116.295,,3.011696e+003,2.999994e+002,9.381441e-005,5.152545e-007,3.504683e-001,1.232100e-003,3,9.764454e-001,1.825000e+000,,,,,,,,,,,,,,,,,,0,4.000000e+000,1.000000e+000,2,2,7.080078e-003,0,,0,
1698356142.480,,4.015326e+003,2.999977e+002,8.939427e-005,1.206073e-006,4.112726e-001,2.789487e-002,3,9.229814e-001,1.825000e+000,,,,,,,,,,,,,,,,,,0,4.000000e+000,1.000000e+000,2,2,7.080078e-003,0,,0,
1698356167.711,,5.019030e+003,2.999977e+002,7.880564e-005,4.309968e-007,5.459754e-001,1.968393e-002,3,9.122928e-001,1.825000e+000,,,,,,,,,,,,,,,,,,0,4.000000e+000,1.000000e+000,2,2,7.080078e-003,0,,0,
1698356192.647,,6.022225e+003,3.000012e+002,7.139872e-005,1.319337e-006,6.807488e-001,3.704286e-004,3,8.555697e-001,1.825000e+000,,,,,,,,,,,,,,,,,,0,4.000000e+000,1.000000e+000,2,2,0.000000e+000,0,,0,
1698356262.400,,7.013165e+003,3.000012e+002,3.592384e-005,4.591565e-005,4.480974e-001,6.337054e-001,3,3.616051e-001,1.825000e+000,,,,,,,,,,,,,,,,,,0,4.000000e+000,1.000000e+000,2,2,0.000000e+000,0,,0,
1698356288.356,,8.017086e+003,2.999994e+002,-6.542598e-005,6.184145e-008,-6.755055e-001,9.497624e-003,3,6.581494e-001,1.825000e+000,,,,,,,,,,,,,,,,,,0,4.000000e+000,1.000000e+000,2,2,7.080078e-003,0,,0,
1698356314.602,,9.021010e+003,3.000012e+002,-8.099309e-005,7.500719e-007,-5.440778e-001,4.347216e-002,3,6.718652e-001,1.825000e+000,,,,,,,,,,,,,,,,,,0,4.000000e+000,1.000000e+000,2,2,0.000000e+000,0,,0,
1698356340.788,,1.002552e+004,2.999977e+002,-9.824106e-005,4.361314e-007,-3.953174e-001,1.027180e-002,3,8.453656e-001,1.825000e+000,,,,,,,,,,,,,,,,,,0,4.000000e+000,1.000000e+000,2,2,7.080078e-003,0,,0,
1698356497.730,,1.500000e+004,2.999959e+002,-2.223057e-004,1.272123e-007,-1.769792e-001,4.320157e-004,3,9.542735e-001,1.825000e+000,,,,,,,,,,,,,,,,,,0,4.000000e+000,1.000000e+000,2,2,7.080078e-003,0,,0,
1698356637.172,,2.000000e+004,2.999959e+002,-3.571361e-004,1.516712e-008,-1.156552e-001,4.258412e-005,3,9.772482e-001,1.825000e+000,,,,,,,,,,,,,,,,,,0,4.000000e+000,1.000000e+000,2,2,7.080078e-003,0,,0,
1698356778.615,,2.500000e+004,2.999959e+002,-4.947231e-004,2.137389e-007,-8.653089e-002,6.152334e-004,3,9.836450e-001,1.825000e+000,,,,,,,,,,,,,,,,,,0,4.000000e+000,1.000000e+000,2,2,7.080078e-003,0,,0,
1698356920.379,,3.000000e+004,2.999994e+002,-6.329762e-004,1.194024e-007,-6.947833e-002,1.923529e-004,3,9.864041e-001,1.825000e+000,,,,,,,,,,,,,,,,,,0,4.000000e+000,1.000000e+000,2,2,7.080078e-003,0,,0,
1698357063.871,,3.500000e+004,2.999959e+002,-7.720437e-004,2.362528e-007,-5.790056e-002,1.355890e-004,3,9.867792e-001,1.825000e+000,,,,,,,,,,,,,,,,,,0,4.000000e+000,1.000000e+000,2,2,7.080078e-003,0,,0,
1698357207.314,,4.000000e+004,2.999994e+002,-9.111282e-004,3.975962e-008,-4.968225e-002,2.391307e-004,3,9.869360e-001,1.825000e+000,,,,,,,,,,,,,,,,,,0,4.000000e+000,1.000000e+000,2,2,7.080078e-003,0,,0,
1698357352.756,,4.500000e+004,2.999994e+002,-1.050224e-003,1.835711e-008,-4.308458e-002,1.212512e-004,3,9.866517e-001,1.825000e+000,,,,,,,,,,,,,,,,,,0,4.000000e+000,1.000000e+000,2,2,7.080078e-003,0,,0,
1698357500.449,,5.000000e+004,3.000012e+002,-1.189316e-003,7.104054e-008,-3.786533e-002,4.259729e-005,3,9.862269e-001,1.825000e+000,,,,,,,,,,,,,,,,,,0,4.000000e+000,1.000000e+000,2,2,0.000000e+000,0,,0,
1698357647.439,,5.500000e+004,2.999959e+002,-1.328656e-003,9.878168e-009,-3.361356e-002,6.458478e-005,3,9.858723e-001,1.825000e+000,,,,,,,,,,,,,,,,,,0,4.000000e+000,1.000000e+000,2,2,7.080078e-003,0,,0,
1698357784.131,,6.000000e+004,2.999959e+002,-1.468002e-003,6.429046e-008,-2.989919e-002,1.080395e-004,3,9.855373e-001,1.825000e+000,,,,,,,,,,,,,,,,,,0,4.000000e+000,1.000000e+000,2,2,7.080078e-003,0,,0,
1698357926.830,,6.500000e+004,2.999959e+002,-1.607054e-003,7.656022e-009,-2.677382e-002,3.016661e-005,3,9.851749e-001,1.825000e+000,,,,,,,,,,,,,,,,,,0,4.000000e+000,1.000000e+000,2,2,7.080078e-003,0,,0,
1698358071.795,,7.000000e+004,3.000012e+002,-1.746350e-003,1.446329e-007,-2.404424e-002,2.626275e-005,3,9.851019e-001,1.825000e+000,,,,,,,,,,,,,,,,,,0,4.000000e+000,1.000000e+000,2,2,0.000000e+000,0,,0,
1698358120.599,,7.000000e+004,2.999959e+002,-1.780625e-003,4.184770e-005,-2.446872e-002,1.489967e-003,3,9.663790e-001,1.825000e+000,,,,,,,,,,,,,,,,,,0,4.000000e+000,1.000000e+000,2,2,7.080078e-003,0,,0,
1698358165.543,,6.523894e+004,2.999994e+002,-1.611172e-003,1.388541e-006,-2.542889e-002,2.404623e-004,3,9.848691e-001,1.825000e+000,,,,,,,,,,,,,,,,,,0,4.000000e+000,1.000000e+000,2,2,7.080078e-003,0,,0,
1698358211.020,,6.022225e+004,3.000012e+002,-1.471365e-003,8.789922e-007,-2.892038e-002,3.567928e-004,3,9.860097e-001,1.825000e+000,,,,,,,,,,,,,,,,,,0,4.000000e+000,1.000000e+000,2,2,0.000000e+000,0,,0,
1698358257.207,,5.520555e+004,3.000012e+002,-1.331852e-003,9.404015e-007,-3.163131e-002,1.677207e-004,3,9.852440e-001,1.825000e+000,,,,,,,,,,,,,,,,,,0,4.000000e+000,1.000000e+000,2,2,0.000000e+000,0,,0,
1698358303.165,,5.018739e+004,2.999959e+002,-1.191721e-003,1.063220e-006,-3.538435e-002,1.614330e-004,3,9.856357e-001,1.825000e+000,,,,,,,,,,,,,,,,,,0,4.000000e+000,1.000000e+000,2,2,7.080078e-003,0,,0,
1698358348.601,,4.516778e+004,2.999994e+002,-1.051858e-003,9.329929e-007,-4.038855e-002,8.645794e-004,3,9.871169e-001,1.825000e+000,,,,,,,,,,,,,,,,,,0,4.000000e+000,1.000000e+000,2,2,7.080078e-003,0,,0,
1698358395.538,,4.015181e+004,2.999994e+002,-9.136260e-004,4.173526e-008,-4.607565e-002,7.515099e-004,3,9.868958e-001,1.825000e+000,,,,,,,,,,,,,,,,,,0,4.000000e+000,1.000000e+000,2,2,7.080078e-003,0,,0,
1698358446.257,,3.513438e+004,3.000012e+002,-7.735597e-004,1.995390e-007,-5.307142e-002,6.062482e-004,3,9.859257e-001,1.825000e+000,,,,,,,,,,,,,,,,,,0,4.000000e+000,1.000000e+000,2,2,0.000000e+000,0,,0,
1698358491.242,,3.011549e+004,2.999994e+002,-6.349353e-004,1.315443e-007,-6.438816e-002,1.563917e-003,3,9.848430e-001,1.825000e+000,,,,,,,,,,,,,,,,,,0,4.000000e+000,1.000000e+000,2,2,7.080078e-003,0,,0,
1698358537.179,,2.509880e+004,3.000012e+002,-4.974031e-004,2.659903e-006,-7.978389e-002,1.476604e-003,3,9.790897e-001,1.825000e+000,,,,,,,,,,,,,,,,,,0,4.000000e+000,1.000000e+000,2,2,0.000000e+000,0,,0,
1698358582.116,,2.008064e+004,2.999959e+002,-3.601774e-004,2.773151e-006,-1.101187e-001,2.470332e-004,3,9.711633e-001,1.825000e+000,,,,,,,,,,,,,,,,,,0,4.000000e+000,1.000000e+000,2,2,7.080078e-003,0,,0,
1698358627.303,,1.505855e+004,2.999941e+002,-2.229831e-004,1.893367e-006,-1.688236e-001,2.876649e-003,3,9.484794e-001,1.825000e+000,,,,,,,,,,,,,,,,,,0,4.000000e+000,1.000000e+000,2,2,0.000000e+000,0,,0,
1698358721.529,,1.002435e+004,3.000012e+002,-9.586388e-005,8.467956e-008,-4.048678e-001,2.577842e-002,3,8.226901e-001,1.825000e+000,,,,,,,,,,,,,,,,,,0,4.000000e+000,1.000000e+000,2,2,0.000000e+000,0,,0,
1698358766.662,,9.018384e+003,3.000012e+002,-7.755999e-005,1.011776e-006,-5.133874e-001,1.866810e-003,3,7.549520e-001,1.825000e+000,,,,,,,,,,,,,,,,,,0,4.000000e+000,1.000000e+000,2,2,0.000000e+000,0,,0,
1698358810.092,,8.014898e+003,2.999977e+002,-6.572992e-005,1.244274e-006,-6.755207e-001,6.319793e-003,3,6.626369e-001,1.825000e+000,,,,,,,,,,,,,,,,,,0,4.000000e+000,1.000000e+000,2,2,1.419067e-002,0,,0,
1698358846.365,,7.010830e+003,2.999977e+002,5.714437e-006,8.905546e-005,-4.680306e-003,1.275295e+000,3,6.208842e-001,1.825000e+000,,,,,,,,,,,,,,,,,,0,4.000000e+000,1.000000e+000,2,2,7.080078e-003,0,,0,
1698358927.771,,6.022078e+003,2.999977e+002,7.165628e-005,2.497221e-007,6.951717e-001,7.225656e-004,3,8.600967e-001,1.825000e+000,,,,,,,,,,,,,,,,,,0,4.000000e+000,1.000000e+000,2,2,7.080078e-003,0,,0,
1698358952.723,,5.018884e+003,2.999977e+002,7.998324e-005,5.527658e-007,5.367532e-001,3.412462e-003,3,9.455629e-001,1.825000e+000,,,,,,,,,,,,,,,,,,0,4.000000e+000,1.000000e+000,2,2,7.080078e-003,0,,0,
1698358979.158,,4.015327e+003,2.999994e+002,8.851389e-005,1.233948e-007,4.405913e-001,7.269762e-003,3,9.425206e-001,1.825000e+000,,,,,,,,,,,,,,,,,,0,4.000000e+000,1.000000e+000,2,2,1.419067e-002,0,,0,
1698359005.344,,3.011695e+003,2.999994e+002,9.198606e-005,9.813255e-006,3.916089e-001,7.808230e-003,3,8.623219e-001,1.825000e+000,,,,,,,,,,,,,,,,,,0,4.000000e+000,1.000000e+000,2,2,7.080078e-003,0,,0,
1698359163.754,,2.000000e+003,2.999941e+002,9.291178e-005,2.230614e-007,2.851105e-001,6.919248e-004,3,9.701266e-001,1.825000e+000,,,,,,,,,,,,,,,,,,0,4.000000e+000,1.000000e+000,2,2,0.000000e+000,0,,0,
1698359285.945,,1.750000e+003,2.999941e+002,9.031093e-005,5.645476e-008,2.695968e-001,1.831281e-004,3,9.695020e-001,1.825000e+000,,,,,,,,,,,,,,,,,,0,4.000000e+000,1.000000e+000,2,2,0.000000e+000,0,,0,
1698359414.886,,1.500000e+003,2.999994e+002,8.608779e-005,1.161971e-007,2.500275e-001,9.611484e-004,3,9.675800e-001,1.825000e+000,,,,,,,,,,,,,,,,,,0,4.000000e+000,1.000000e+000,2,2,7.080078e-003,0,,0,
1698359536.827,,1.250000e+003,2.999994e+002,7.962772e-005,1.704653e-007,2.318972e-001,1.029574e-003,3,9.666356e-001,1.825000e+000,,,,,,,,,,,,,,,,,,0,4.000000e+000,1.000000e+000,2,2,7.080078e-003,0,,0,
1698359659.277,,1.000000e+003,2.999959e+002,7.230803e-005,2.815638e-007,2.060236e-001,3.072084e-003,3,9.668057e-001,1.825000e+000,,,,,,,,,,,,,,,,,,0,4.000000e+000,1.000000e+000,2,2,7.080078e-003,0,,0,
1698359781.718,,9.000000e+002,2.999977e+002,6.872133e-005,1.857404e-007,1.935423e-001,5.785709e-005,3,9.680016e-001,1.825000e+000,,,,,,,,,,,,,,,,,,0,4.000000e+000,1.000000e+000,2,2,1.419067e-002,0,,0,
1698359896.257,,8.000000e+002,2.999994e+002,6.524568e-005,1.462998e-007,1.826562e-001,5.995178e-004,3,9.658989e-001,1.825000e+000,,,,,,,,,,,,,,,,,,0,4.000000e+000,1.000000e+000,2,2,7.080078e-003,0,,0,
1698360018.203,,7.000000e+002,3.000030e+002,6.104205e-005,5.581139e-007,1.731983e-001,1.793896e-003,3,9.649689e-001,1.825000e+000,,,,,,,,,,,,,,,,,,0,4.000000e+000,1.000000e+000,2,2,7.110596e-003,0,,0,
1698360140.644,,6.000000e+002,2.999994e+002,5.669201e-005,9.779643e-008,1.590832e-001,5.238853e-004,3,9.676569e-001,1.825000e+000,,,,,,,,,,,,,,,,,,0,4.000000e+000,1.000000e+000,2,2,7.080078e-003,0,,0,
1698360261.603,,5.000000e+002,3.000012e+002,5.206593e-005,6.837544e-008,1.465365e-001,1.160619e-003,3,9.664167e-001,1.825000e+000,,,,,,,,,,,,,,,,,,0,4.000000e+000,1.000000e+000,2,2,0.000000e+000,0,,0,
1698360384.044,,4.000000e+002,2.999977e+002,4.712405e-005,1.761658e-007,1.315704e-001,3.192835e-003,3,9.675948e-001,1.825000e+000,,,,,,,,,,,,,,,,,,0,4.000000e+000,1.000000e+000,2,2,7.080078e-003,0,,0,
1698360506.235,,3.000000e+002,3.000012e+002,4.138402e-005,6.375019e-008,1.139590e-001,3.658505e-004,3,9.682035e-001,1.825000e+000,,,,,,,,,,,,,,,,,,0,4.000000e+000,1.000000e+000,2,2,0.000000e+000,0,,0,
1698360628.176,,2.000000e+002,3.000012e+002,3.495463e-005,2.630319e-008,9.718236e-002,2.458642e-003,3,9.699183e-001,1.825000e+000,,,,,,,,,,,,,,,,,,0,4.000000e+000,1.000000e+000,2,2,0.000000e+000,0,,0,
1698360750.368,,1.000000e+002,3.000030e+002,2.694683e-005,6.558177e-008,7.020891e-002,8.774010e-003,3,9.705609e-001,1.825000e+000,,,,,,,,,,,,,,,,,,0,4.000000e+000,1.000000e+000,2,2,1.419067e-002,0,,0,
1698360859.362,,7.500000e+001,2.999994e+002,2.482579e-005,2.414337e-007,6.692129e-002,2.727960e-003,3,9.794583e-001,1.825000e+000,,,,,,,,,,,,,,,,,,0,4.000000e+000,1.000000e+000,2,2,7.080078e-003,0,,0,
1698360975.172,,5.000000e+001,3.000012e+002,2.228206e-005,8.200551e-008,5.774176e-002,6.688339e-003,3,9.797688e-001,1.825000e+000,,,,,,,,,,,,,,,,,,0,4.000000e+000,1.000000e+000,2,2,0.000000e+000,0,,0,
1698361090.362,,2.500000e+001,2.999977e+002,1.993724e-005,1.919207e-007,5.510664e-002,2.907877e-003,3,9.711635e-001,1.825000e+000,,,,,,,,,,,,,,,,,,0,4.000000e+000,1.000000e+000,2,2,7.080078e-003,0,,0,
1698361205.803,,0.000000e+000,2.999994e+002,1.747289e-005,2.568066e-007,3.957189e-002,6.718495e-003,3,9.584151e-001,1.825000e+000,,,,,,,,,,,,,,,,,,0,4.000000e+000,1.000000e+000,2,2,7.080078e-003,0,,0,
1698361314.548,,-2.500000e+001,2.999959e+002,1.498839e-005,1.879681e-008,2.268151e-002,2.964240e-003,3,9.742281e-001,1.825000e+000,,,,,,,,,,,,,,,,,,0,4.000000e+000,1.000000e+000,2,2,7.080078e-003,0,,0,
1698361430.489,,-5.000000e+001,3.000012e+002,1.255042e-005,1.903329e-007,-3.745508e-003,8.125127e-004,3,9.460772e-001,1.825000e+000,,,,,,,,,,,,,,,,,,0,4.000000e+000,1.000000e+000,2,2,0.000000e+000,0,,0,
1698361545.429,,-7.500000e+001,3.000012e+002,9.715996e-006,3.908295e-007,-2.896667e-002,2.874163e-003,3,9.421794e-001,1.825000e+000,,,,,,,,,,,,,,,,,,0,4.000000e+000,1.000000e+000,2,2,0.000000e+000,0,,0,
1698361653.928,,-1.000000e+002,3.000012e+002,7.441930e-006,7.806518e-008,-1.014334e-001,1.335617e-002,3,9.023939e-001,1.825000e+000,,,,,,,,,,,,,,,,,,0,4.000000e+000,1.000000e+000,2,2,0.000000e+000,0,,0,
1698361775.869,,-2.000000e+002,2.999994e+002,-4.660184e-006,1.269274e-008,6.004310e-001,2.519897e-002,3,9.033030e-001,1.825000e+000,,,,,,,,,,,,,,,,,,0,4.000000e+000,1.000000e+000,2,2,7.080078e-003,0,,0,
1698361890.867,,-3.000000e+002,3.000012e+002,-1.327028e-005,1.012577e-008,2.990042e-001,4.271794e-003,3,9.535573e-001,1.825000e+000,,,,,,,,,,,,,,,,,,0,4.000000e+000,1.000000e+000,2,2,0.000000e+000,0,,0,
1698362012.118,,-4.000000e+002,3.000012e+002,-2.211728e-005,2.581675e-007,2.411248e-001,5.990911e-003,3,9.563491e-001,1.825000e+000,,,,,,,,,,,,,,,,,,0,4.000000e+000,1.000000e+000,2,2,1.419067e-002,0,,0,
1698362132.809,,-5.000000e+002,2.999994e+002,-3.064081e-005,9.094088e-008,2.313534e-001,1.605795e-004,3,9.628248e-001,1.825000e+000,,,,,,,,,,,,,,,,,,0,4.000000e+000,1.000000e+000,2,2,7.080078e-003,0,,0,
1698362248.073,,-6.000000e+002,2.999977e+002,-3.933599e-005,1.356962e-006,2.347371e-001,2.271346e-002,3,9.077458e-001,1.825000e+000,,,,,,,,,,,,,,,,,,0,4.000000e+000,1.000000e+000,2,2,7.080078e-003,0,,0,
1698362363.516,,-7.000000e+002,2.999959e+002,-4.519077e-005,4.351564e-007,2.224560e-001,3.272661e-003,3,9.642581e-001,1.825000e+000,,,,,,,,,,,,,,,,,,0,4.000000e+000,1.000000e+000,2,2,7.080078e-003,0,,0,
1698362484.517,,-8.000000e+002,3.000012e+002,-5.128567e-005,2.613701e-007,2.269659e-001,8.360670e-004,3,9.661301e-001,1.825000e+000,,,,,,,,,,,,,,,,,,0,4.000000e+000,1.000000e+000,2,2,0.000000e+000,0,,0,
1698362605.501,,-9.000000e+002,2.999994e+002,-5.730801e-005,2.647349e-007,2.307871e-001,2.705975e-003,3,9.587667e-001,1.825000e+000,,,,,,,,,,,,,,,,,,0,4.000000e+000,1.000000e+000,2,2,7.080078e-003,0,,0,
1698362727.255,,-1.000000e+003,3.000012e+002,-6.189286e-005,3.916796e-008,2.374561e-001,1.933908e-004,3,9.675918e-001,1.825000e+000,,,,,,,,,,,,,,,,,,0,4.000000e+000,1.000000e+000,2,2,0.000000e+000,0,,0,
1698362855.196,,-1.250000e+003,3.000012e+002,-7.233961e-005,2.555307e-007,2.530717e-001,1.566008e-003,3,9.664134e-001,1.825000e+000,,,,,,,,,,,,,,,,,,0,4.000000e+000,1.000000e+000,2,2,0.000000e+000,0,,0,
1698362977.388,,-1.500000e+003,2.999959e+002,-8.053624e-005,4.377777e-008,2.710302e-001,1.540678e-004,3,9.696136e-001,1.825000e+000,,,,,,,,,,,,,,,,,,0,4.000000e+000,1.000000e+000,2,2,7.080078e-003,0,,0,
1698363098.149,,-1.750000e+003,2.999994e+002,-8.622008e-005,4.272822e-008,2.874317e-001,2.582337e-004,3,9.711785e-001,1.825000e+000,,,,,,,,,,,,,,,,,,0,4.000000e+000,1.000000e+000,2,2,7.080078e-003,0,,0,
1698363226.342,,-2.000000e+003,3.000012e+002,-8.977597e-005,5.660396e-008,3.011262e-001,5.607427e-004,3,9.725875e-001,1.825000e+000,,,,,,,,,,,,,,,,,,0,4.000000e+000,1.000000e+000,2,2,0.000000e+000,0,,0,
1698363295.776,,-3.011769e+003,2.999977e+002,-9.287342e-005,1.410880e-007,3.617371e-001,1.906176e-003,3,9.784809e-001,1.825000e+000,,,,,,,,,,,,,,,,,,0,4.000000e+000,1.000000e+000,2,2,7.080078e-003,0,,0,
1698363335.246,,-4.015399e+003,2.999959e+002,-8.771529e-005,1.573613e-007,4.377263e-001,3.855952e-003,3,9.791066e-001,1.825000e+000,,,,,,,,,,,,,,,,,,0,4.000000e+000,1.000000e+000,2,2,7.080078e-003,0,,0,
1698363362.438,,-5.019031e+003,2.999977e+002,-7.710898e-005,4.181768e-006,5.511580e-001,3.039673e-003,3,8.616403e-001,1.825000e+000,,,,,,,,,,,,,,,,,,0,4.000000e+000,1.000000e+000,2,2,7.080078e-003,0,,0,
1698363388.625,,-6.022371e+003,2.999959e+002,-7.347611e-005,8.897296e-007,7.109756e-001,1.458058e-002,3,8.140696e-001,1.825000e+000,,,,,,,,,,,,,,,,,,0,4.000000e+000,1.000000e+000,2,2,7.080078e-003,0,,0,
1698363460.063,,-7.013456e+003,3.000012e+002,-6.957974e-005,4.499454e-007,9.078845e-001,1.777918e-002,3,7.496691e-001,1.825000e+000,,,,,,,,,,,,,,,,,,0,4.000000e+000,1.000000e+000,2,2,0.000000e+000,0,,0,
1698363485.498,,-8.017232e+003,2.999959e+002,6.449567e-005,1.563426e-007,-6.709622e-001,1.700857e-002,3,6.535018e-001,1.825000e+000,,,,,,,,,,,,,,,,,,0,4.000000e+000,1.000000e+000,2,2,7.080078e-003,0,,0,
1698363511.684,,-9.021302e+003,3.000012e+002,7.911175e-005,2.756354e-006,-4.922952e-001,8.573428e-003,3,7.802487e-001,1.825000e+000,,,,,,,,,,,,,,,,,,0,4.000000e+000,1.000000e+000,2,2,0.000000e+000,0,,0,
1698363538.120,,-1.002610e+004,3.000012e+002,9.984017e-005,6.728730e-007,-3.759458e-001,6.161890e-003,3,8.464121e-001,1.825000e+000,,,,,,,,,,,,,,,,,,0,4.000000e+000,1.000000e+000,2,2,0.000000e+000,0,,0,
1698363695.313,,-1.500000e+004,2.999994e+002,2.220591e-004,7.645290e-008,-1.632968e-001,4.386328e-004,3,9.548869e-001,1.825000e+000,,,,,,,,,,,,,,,,,,0,4.000000e+000,1.000000e+000,2,2,7.080078e-003,0,,0,
1698363835.849,,-2.000000e+004,2.999959e+002,3.568170e-004,6.499011e-008,-1.024498e-001,2.160500e-004,3,9.768264e-001,1.825000e+000,,,,,,,,,,,,,,,,,,0,4.000000e+000,1.000000e+000,2,2,7.080078e-003,0,,0,
1698363984.014,,-2.500000e+004,2.999995e+002,4.944875e-004,9.651794e-008,-7.388441e-002,2.807349e-004,3,9.840679e-001,1.825000e+000,,,,,,,,,,,,,,,,,,0,4.000000e+000,1.000000e+000,2,2,1.419067e-002,0,,0,
1698364125.456,,-3.000000e+004,2.999959e+002,6.329954e-004,1.666946e-008,-5.746914e-002,1.174317e-005,3,9.862533e-001,1.825000e+000,,,,,,,,,,,,,,,,,,0,4.000000e+000,1.000000e+000,2,2,7.080078e-003,0,,0,
1698364268.636,,-3.500000e+004,2.999977e+002,7.716119e-004,2.091702e-007,-4.684274e-002,7.716825e-005,3,9.869173e-001,1.825000e+000,,,,,,,,,,,,,,,,,,0,4.000000e+000,1.000000e+000,2,2,7.080078e-003,0,,0,
1698364412.634,,-4.000000e+004,3.000012e+002,9.108130e-004,1.099358e-007,-3.894733e-002,1.168074e-004,3,9.867560e-001,1.825000e+000,,,,,,,,,,,,,,,,,,0,4.000000e+000,1.000000e+000,2,2,0.000000e+000,0,,0,
1698364552.179,,-4.500000e+004,2.999994e+002,1.049759e-003,2.880309e-007,-3.323390e-002,5.231214e-005,3,9.864061e-001,1.825000e+000,,,,,,,,,,,,,,,,,,0,4.000000e+000,1.000000e+000,2,2,7.080078e-003,0,,0,
1698364693.171,,-5.000000e+004,2.999994e+002,1.189081e-003,1.179618e-007,-2.871000e-002,9.072109e-005,3,9.861205e-001,1.825000e+000,,,,,,,,,,,,,,,,,,0,4.000000e+000,1.000000e+000,2,2,7.080078e-003,0,,0,
1698364841.671,,-5.500000e+004,2.999994e+002,1.328242e-003,1.251235e-008,-2.514280e-002,1.066236e-004,3,9.858258e-001,1.825000e+000,,,,,,,,,,,,,,,,,,0,4.000000e+000,1.000000e+000,2,2,7.080078e-003,0,,0,
1698364977.428,,-6.000000e+004,3.000012e+002,1.467644e-003,6.420809e-008,-2.224134e-002,9.547315e-005,3,9.856567e-001,1.825000e+000,,,,,,,,,,,,,,,,,,0,4.000000e+000,1.000000e+000,2,2,0.000000e+000,0,,0,
1698365127.397,,-6.500000e+004,3.000030e+002,1.606810e-003,4.124143e-008,-1.970135e-002,6.368521e-005,3,9.852604e-001,1.825000e+000,,,,,,,,,,,,,,,,,,0,4.000000e+000,1.000000e+000,2,2,7.110596e-003,0,,0,
1698365271.685,,-7.000000e+004,2.999977e+002,1.746155e-003,1.639776e-007,-1.765718e-002,4.578201e-005,3,9.850378e-001,1.825000e+000,,,,,,,,,,,,,,,,,,0,4.000000e+000,1.000000e+000,2,2,7.080078e-003,0,,0,
1698365284.890,,-7.000000e+004,2.999994e+002,1.746097e-003,6.659536e-008,-1.788952e-002,2.026658e-004,3,9.850607e-001,1.825000e+000,,,,,,,,,,,,,,,,,,0,4.000000e+000,1.000000e+000,2,2,7.080078e-003,0,,0,
1698365435.083,,-6.500000e+004,2.999977e+002,1.606407e-003,1.224070e-007,-2.029515e-002,8.573196e-005,3,9.852227e-001,1.825000e+000,,,,,,,,,,,,,,,,,,0,4.000000e+000,1.000000e+000,2,2,7.080078e-003,0,,0,
1698365583.025,,-6.000000e+004,3.000012e+002,1.466599e-003,6.881790e-008,-2.315760e-002,1.870108e-004,3,9.854770e-001,1.825000e+000,,,,,,,,,,,,,,,,,,0,4.000000e+000,1.000000e+000,2,2,0.000000e+000,0,,0,
1698365729.468,,-5.500000e+004,2.999959e+002,1.326992e-003,4.144715e-007,-2.636299e-002,1.345723e-004,3,9.857875e-001,1.825000e+000,,,,,,,,,,,,,,,,,,0,4.000000e+000,1.000000e+000,2,2,7.080078e-003,0,,0,
1698365874.707,,-5.000000e+004,2.999977e+002,1.187972e-003,5.655257e-008,-3.030207e-002,5.218175e-005,3,9.861823e-001,1.825000e+000,,,,,,,,,,,,,,,,,,0,4.000000e+000,1.000000e+000,2,2,7.080078e-003,0,,0,
1698366026.901,,-4.500000e+004,2.999977e+002,1.048877e-003,1.926243e-008,-3.507439e-002,1.942706e-004,3,9.866116e-001,1.825000e+000,,,,,,,,,,,,,,,,,,0,4.000000e+000,1.000000e+000,2,2,7.080078e-003,0,,0,
1698366169.379,,-4.000000e+004,2.999994e+002,9.097307e-004,3.271732e-007,-4.085365e-002,6.053605e-005,3,9.867751e-001,1.825000e+000,,,,,,,,,,,,,,,,,,0,4.000000e+000,1.000000e+000,2,2,7.080078e-003,0,,0,
1698366318.910,,-3.500000e+004,2.999994e+002,7.711247e-004,3.770167e-007,-4.816772e-002,1.713823e-004,3,9.865825e-001,1.825000e+000,,,,,,,,,,,,,,,,,,0,4.000000e+000,1.000000e+000,2,2,7.080078e-003,0,,0,
1698366460.602,,-3.000000e+004,3.000012e+002,6.320636e-004,1.710981e-007,-5.907328e-002,3.124319e-004,3,9.863780e-001,1.825000e+000,,,,,,,,,,,,,,,,,,0,4.000000e+000,1.000000e+000,2,2,0.000000e+000,0,,0,
1698366600.044,,-2.500000e+004,2.999994e+002,4.934638e-004,5.412414e-008,-7.525942e-002,4.581889e-005,3,9.846808e-001,1.825000e+000,,,,,,,,,,,,,,,,,,0,4.000000e+000,1.000000e+000,2,2,7.080078e-003,0,,0,
1698366739.736,,-2.000000e+004,2.999977e+002,3.561754e-004,1.251235e-007,-1.039288e-001,4.098412e-004,3,9.771047e-001,1.825000e+000,,,,,,,,,,,,,,,,,,0,4.000000e+000,1.000000e+000,2,2,7.080078e-003,0,,0,
1698366884.646,,-1.500000e+004,2.999994e+002,2.213310e-004,9.514939e-008,-1.645712e-001,1.745933e-004,3,9.548899e-001,1.825000e+000,,,,,,,,,,,,,,,,,,0,4.000000e+000,1.000000e+000,2,2,7.080078e-003,0,,0,
1698366953.870,,-1.002610e+004,2.999994e+002,9.734925e-005,7.789141e-007,-3.830355e-001,1.033167e-003,3,8.409417e-001,1.825000e+000,,,,,,,,,,,,,,,,,,0,4.000000e+000,1.000000e+000,2,2,7.080078e-003,0,,0,
1698366981.363,,-9.020134e+003,3.000012e+002,7.798173e-005,1.116902e-006,-5.033333e-001,1.935173e-003,3,7.751255e-001,1.825000e+000,,,,,,,,,,,,,,,,,,0,4.000000e+000,1.000000e+000,2,2,0.000000e+000,0,,0,
1698367007.804,,-8.016211e+003,2.999977e+002,6.451537e-005,1.226025e-006,-6.884813e-001,3.534898e-003,3,6.531330e-001,1.825000e+000,,,,,,,,,,,,,,,,,,0,4.000000e+000,1.000000e+000,2,2,7.080078e-003,0,,0,
1698367033.739,,-7.012143e+003,2.999994e+002,2.752854e-005,4.432542e-005,-4.555074e-001,6.441848e-001,3,2.741089e-001,1.825000e+000,,,,,,,,,,,,,,,,,,0,4.000000e+000,1.000000e+000,2,2,7.080078e-003,0,,0,
1698367104.931,,-6.022370e+003,3.000012e+002,-7.110033e-005,1.161642e-006,7.011462e-001,1.577746e-002,3,8.301746e-001,1.825000e+000,,,,,,,,,,,,,,,,,,0,4.000000e+000,1.000000e+000,2,2,0.000000e+000,0,,0,
1698367132.617,,-5.019176e+003,2.999959e+002,-8.043199e-005,5.359266e-007,5.432844e-001,9.536947e-003,3,9.212048e-001,1.825000e+000,,,,,,,,,,,,,,,,,,0,4.000000e+000,1.000000e+000,2,2,7.080078e-003,0,,0,
1698367158.802,,-4.015399e+003,2.999994e+002,-8.748796e-005,2.231113e-006,4.299915e-001,5.479933e-003,3,9.440657e-001,1.825000e+000,,,,,,,,,,,,,,,,,,0,4.000000e+000,1.000000e+000,2,2,7.080078e-003,0,,0,
1698367191.456,,-3.011769e+003,2.999977e+002,-9.544865e-005,9.776556e-007,3.574716e-001,1.637616e-004,3,9.643549e-001,1.825000e+000,,,,,,,,,,,,,,,,,,0,4.000000e+000,1.000000e+000,2,2,7.080078e-003,0,,0,
1698367341.658,,-2.000000e+003,2.999977e+002,-9.316715e-005,1.602836e-007,2.890589e-001,1.567462e-003,3,9.695333e-001,1.825000e+000,,,,,,,,,,,,,,,,,,0,4.000000e+000,1.000000e+000,2,2,7.080078e-003,0,,0,
1698367468.162,,-1.750000e+003,2.999994e+002,-9.038735e-005,1.713245e-007,2.740663e-001,3.937991e-004,3,9.693991e-001,1.825000e+000,,,,,,,,,,,,,,,,,,0,4.000000e+000,1.000000e+000,2,2,7.080078e-003,0,,0,
1698367588.389,,-1.500000e+003,3.000012e+002,-8.591554e-005,7.714746e-008,2.552294e-001,9.839814e-004,3,9.690952e-001,1.825000e+000,,,,,,,,,,,,,,,,,,0,4.000000e+000,1.000000e+000,2,2,0.000000e+000,0,,0,
1698367715.081,,-1.250000e+003,3.000012e+002,-7.994122e-005,7.512038e-008,2.345161e-001,5.921948e-004,3,9.662769e-001,1.825000e+000,,,,,,,,,,,,,,,,,,0,4.000000e+000,1.000000e+000,2,2,0.000000e+000,0,,0,
1698367841.272,,-1.000000e+003,3.000012e+002,-7.226029e-005,7.866522e-009,2.071830e-001,5.799828e-004,3,9.667504e-001,1.825000e+000,,,,,,,,,,,,,,,,,,0,4.000000e+000,1.000000e+000,2,2,1.419067e-002,0,,0,
1698367955.480,,-9.000000e+002,3.000012e+002,-6.885818e-005,9.715589e-008,2.001010e-001,4.834665e-004,3,9.664817e-001,1.825000e+000,,,,,,,,,,,,,,,,,,0,4.000000e+000,1.000000e+000,2,2,0.000000e+000,0,,0,
1698368075.671,,-8.000000e+002,2.999959e+002,-6.516826e-005,1.986592e-007,1.869969e-001,6.693762e-004,3,9.640015e-001,1.825000e+000,,,,,,,,,,,,,,,,,,0,4.000000e+000,1.000000e+000,2,2,7.080078e-003,0,,0,
1698368196.416,,-7.000000e+002,2.999977e+002,-6.125226e-005,4.101240e-007,1.775419e-001,1.045126e-003,3,9.669404e-001,1.825000e+000,,,,,,,,,,,,,,,,,,0,4.000000e+000,1.000000e+000,2,2,7.080078e-003,0,,0,
1698368318.397,,-6.000000e+002,3.000012e+002,-5.689345e-005,6.056423e-007,1.623013e-001,5.202080e-004,3,9.639207e-001,1.825000e+000,,,,,,,,,,,,,,,,,,0,4.000000e+000,1.000000e+000,2,2,0.000000e+000,0,,0,
1698368439.589,,-5.000000e+002,3.000012e+002,-5.231069e-005,3.952553e-008,1.479150e-001,1.160313e-003,3,9.694993e-001,1.825000e+000,,,,,,,,,,,,,,,,,,0,4.000000e+000,1.000000e+000,2,2,0.000000e+000,0,,0,
1698368553.548,,-4.000000e+002,2.999977e+002,-4.715274e-005,2.227192e-007,1.359213e-001,3.956578e-003,3,9.666041e-001,1.825000e+000,,,,,,,,,,,,,,,,,,0,4.000000e+000,1.000000e+000,2,2,7.080078e-003,0,,0,
1698368675.753,,-3.000000e+002,3.000012e+002,-4.148344e-005,2.298861e-007,1.196659e-001,9.395586e-004,3,9.696829e-001,1.825000e+000,,,,,,,,,,,,,,,,,,0,4.000000e+000,1.000000e+000,2,2,0.000000e+000,0,,0,
1698368797.444,,-2.000000e+002,3.000012e+002,-3.514966e-005,1.555168e-007,1.014856e-001,4.832436e-003,3,9.634237e-001,1.825000e+000,,,,,,,,,,,,,,,,,,0,4.000000e+000,1.000000e+000,2,2,0.000000e+000,0,,0,
1698368918.966,,-1.000000e+002,2.999959e+002,-2.678864e-005,3.902262e-008,7.880694e-002,2.014066e-003,3,9.729471e-001,1.825000e+000,,,,,,,,,,,,,,,,,,0,4.000000e+000,1.000000e+000,2,2,7.080078e-003,0,,0,
1698369028.407,,-7.500000e+001,3.000012e+002,-2.469489e-005,1.917535e-007,7.290015e-002,2.399589e-003,3,9.589826e-001,1.825000e+000,,,,,,,,,,,,,,,,,,0,4.000000e+000,1.000000e+000,2,2,0.000000e+000,0,,0,
1698369143.415,,-5.000000e+001,3.000012e+002,-2.246218e-005,8.759156e-009,6.249412e-002,1.731082e-003,3,9.722570e-001,1.825000e+000,,,,,,,,,,,,,,,,,,0,4.000000e+000,1.000000e+000,2,2,0.000000e+000,0,,0,
1698369252.662,,-2.500000e+001,3.000012e+002,-1.995723e-005,1.724422e-007,5.430119e-002,8.004477e-005,3,9.757684e-001,1.825000e+000,,,,,,,,,,,,,,,,,,0,4.000000e+000,1.000000e+000,2,2,0.000000e+000,0,,0,
1698369361.602,,0.000000e+000,2.999995e+002,-1.755881e-005,8.221388e-008,3.876384e-002,7.037309e-003,3,9.728889e-001,1.825000e+000,,,,,,,,,,,,,,,,,,0,4.000000e+000,1.000000e+000,2,2,1.419067e-002,0,,0,
1698369477.382,,2.500000e+001,2.999977e+002,-1.476894e-005,4.538105e-008,2.509763e-002,6.727182e-003,3,9.740844e-001,1.825000e+000,,,,,,,,,,,,,,,,,,0,4.000000e+000,1.000000e+000,2,2,1.419067e-002,0,,0,
1698369586.322,,5.000000e+001,2.999941e+002,-1.264643e-005,3.370346e-008,3.249240e-004,5.616973e-003,3,9.546680e-001,1.825000e+000,,,,,,,,,,,,,,,,,,0,4.000000e+000,1.000000e+000,2,2,0.000000e+000,0,,0,
1698369700.763,,7.500000e+001,3.000012e+002,-9.682495e-006,8.753175e-008,-2.861389e-002,6.070355e-003,3,9.144202e-001,1.825000e+000,,,,,,,,,,,,,,,,,,0,4.000000e+000,1.000000e+000,2,2,1.419067e-002,0,,0,
1698369815.204,,1.000000e+002,2.999959e+002,-7.374992e-006,3.697226e-007,-7.334155e-002,1.740836e-002,3,8.874617e-001,1.825000e+000,,,,,,,,,,,,,,,,,,0,4.000000e+000,1.000000e+000,2,2,7.080078e-003,0,,0,
1698369937.712,,2.000000e+002,3.000030e+002,5.503199e-006,1.091424e-006,5.907402e-001,4.337749e-002,3,7.835929e-001,1.825000e+000,,,,,,,,,,,,,,,,,,0,4.000000e+000,1.000000e+000,2,2,7.110596e-003,0,,0,
1698370058.903,,3.000000e+002,3.000012e+002,1.352765e-005,1.668651e-007,2.863863e-001,2.620733e-003,3,9.447559e-001,1.825000e+000,,,,,,,,,,,,,,,,,,0,4.000000e+000,1.000000e+000,2,2,0.000000e+000,0,,0,
1698370174.361,,4.000000e+002,3.000012e+002,2.218798e-005,8.316954e-008,2.489022e-001,3.691537e-003,3,9.522976e-001,1.825000e+000,,,,,,,,,,,,,,,,,,0,4.000000e+000,1.000000e+000,2,2,1.419067e-002,0,,0,
1698370290.051,,5.000000e+002,2.999994e+002,3.079022e-005,1.517148e-007,2.294253e-001,3.191465e-004,3,9.561665e-001,1.825000e+000,,,,,,,,,,,,,,,,,,0,4.000000e+000,1.000000e+000,2,2,7.080078e-003,0,,0,
1698370404.742,,6.000000e+002,3.000012e+002,3.836520e-005,8.469500e-008,2.201715e-001,3.775905e-003,3,9.577920e-001,1.825000e+000,,,,,,,,,,,,,,,,,,0,4.000000e+000,1.000000e+000,2,2,0.000000e+000,0,,0,
1698370525.232,,7.000000e+002,3.000012e+002,4.551288e-005,3.231241e-008,2.267426e-001,1.293381e-003,3,9.639019e-001,1.825000e+000,,,,,,,,,,,,,,,,,,0,4.000000e+000,1.000000e+000,2,2,0.000000e+000,0,,0,
1698370646.174,,8.000000e+002,2.999977e+002,5.175724e-005,4.807890e-009,2.273778e-001,1.970787e-004,3,9.646658e-001,1.825000e+000,,,,,,,,,,,,,,,,,,0,4.000000e+000,1.000000e+000,2,2,7.080078e-003,0,,0,
1698370761.864,,9.000000e+002,3.000012e+002,5.662424e-005,1.458702e-007,2.344617e-001,3.381442e-004,3,9.667709e-001,1.825000e+000,,,,,,,,,,,,,,,,,,0,4.000000e+000,1.000000e+000,2,2,0.000000e+000,0,,0,
1698370882.915,,1.000000e+003,2.999959e+002,6.191769e-005,6.525250e-008,2.382519e-001,8.333802e-004,3,9.682109e-001,1.825000e+000,,,,,,,,,,,,,,,,,,0,4.000000e+000,1.000000e+000,2,2,7.080078e-003,0,,0,
1698371005.607,,1.250000e+003,3.000012e+002,7.253654e-005,3.062232e-008,2.553083e-001,3.913967e-004,3,9.686778e-001,1.825000e+000,,,,,,,,,,,,,,,,,,0,4.000000e+000,1.000000e+000,2,2,0.000000e+000,0,,0,
1698371134.549,,1.500000e+003,3.000012e+002,8.063435e-005,4.410705e-008,2.716708e-001,1.264974e-003,3,9.692670e-001,1.825000e+000,,,,,,,,,,,,,,,,,,0,4.000000e+000,1.000000e+000,2,2,0.000000e+000,0,,0,
1698371256.026,,1.750000e+003,3.000012e+002,8.620009e-005,4.752839e-008,2.876420e-001,8.593321e-004,3,9.709891e-001,1.825000e+000,,,,,,,,,,,,,,,,,,0,4.000000e+000,1.000000e+000,2,2,0.000000e+000,0,,0,
1698371378.252,,2.000000e+003,2.999994e+002,8.979635e-005,7.937519e-008,3.021523e-001,1.821165e-004,3,9.727819e-001,1.825000e+000,,,,,,,,,,,,,,,,,,0,4.000000e+000,1.000000e+000,2,2,7.080078e-003,0,,0,
1698371440.907,,3.011842e+003,2.999977e+002,9.371752e-005,1.512749e-007,3.659229e-001,1.654265e-005,3,9.737816e-001,1.825000e+000,,,,,,,,,,,,,,,,,,0,4.000000e+000,1.000000e+000,2,2,7.080078e-003,0,,0,
1698371468.099,,4.015544e+003,2.999977e+002,8.819292e-005,1.653024e-006,4.416554e-001,1.421280e-002,3,9.513161e-001,1.825000e+000,,,,,,,,,,,,,,,,,,0,4.000000e+000,1.000000e+000,2,2,7.080078e-003,0,,0,
1698371494.284,,5.019177e+003,2.999994e+002,7.956281e-005,1.181161e-007,5.548586e-001,2.383193e-003,3,8.996458e-001,1.825000e+000,,,,,,,,,,,,,,,,,,0,4.000000e+000,1.000000e+000,2,2,7.080078e-003,0,,0,
1698371522.221,,6.022516e+003,2.999977e+002,7.208095e-005,5.653193e-008,7.019818e-001,3.874433e-003,3,8.485385e-001,1.825000e+000,,,,,,,,,,,,,,,,,,0,4.000000e+000,1.000000e+000,2,2,7.080078e-003,0,,0,
1698371592.160,,7.013310e+003,2.999994e+002,6.772175e-005,2.827523e-007,8.995850e-001,1.509279e-003,3,7.221740e-001,1.825000e+000,,,,,,,,,,,,,,,,,,0,4.000000e+000,1.000000e+000,2,2,7.080078e-003,0,,0,
1698371625.151,,8.017086e+003,2.999994e+002,-6.486888e-005,1.944456e-007,-6.768913e-001,8.387939e-003,3,6.871760e-001,1.825000e+000,,,,,,,,,,,,,,,,,,0,4.000000e+000,1.000000e+000,2,2,7.080078e-003,0,,0,