File: dmuchawiec/STO-N11_12p5g-15a-600C-vac_old_MvH_T-300-K-full_231026.rso.dat
[Header]
TITLE,MPMS RSO Measurement
BYAPP,MPMS Measurement,1.1,Summary
FILEOPENTIME, 1698323315.732000 10/26/2023, 2:28:35 PM

INFO, APPNAME, MPMS MultiVu Application, Revision 1.60,  Build 081

INFO, NAME, STO-N11-12p5g-15a-600C-vac-old
INFO, WEIGHT, 98.480
INFO, AREA, 0.000
INFO, LENGTH, 0.000
INFO, SHAPE, 0
INFO, COMMENT,
INFO, SEQUENCE FILE: MvsH-new-full_only_NO.seq


INFO, BACKGROUND DATA FILE:, None


STARTUPAXIS,X,4,LINEAR,AUTO,0.000000,0.000000
STARTUPAXIS,Y1,5,LINEAR,AUTO,0.000000,0.000000


STARTUPGROUP,Longitudinal
FIELDGROUP,Longitudinal,1,2,3,4,5,6,7,8,9,10,11,19,20,21,22,23,35
FIELDGROUP,Transverse,1,2,3,4,12,13,14,15,16,17,18,24,25,26,27,28,35

PLOT_APPEARANCE,ALL,HORZ_GRID_ON,VERT_GRID_ON,MARKERS_AND_LINES

[Data]
Time,Comment,Field (Oe),Temperature (K),Long Moment (emu),Long Scan Std Dev,Long Offset (cm),Long Offset Std Dev,Long Algorithm,Long Reg Fit,Long Reg Factor,Trans Moment (emu),Trans Scan Std Dev,Trans Offset (cm),Trans Offset Std Dev,Trans Algorithm,Trans Reg Fit,Trans Reg Factor,Long Moment [w/o ABS] (emu),Long Scan Std Dev [w/o ABS],Long Offset [w/o ABS] (cm),Long Offset Std Dev [w/o ABS],Long Reg Fit [w/o ABS],Trans Moment [w/o ABS] (emu),Trans Scan Std Dev [w/o ABS],Trans Offset [w/o ABS] (cm),Trans Offset Std Dev [w/o ABS],Trans Reg Fit [w/o ABS],RSO Position (deg),Amplitude (cm),Frequency,Cycles to Average,Scans per Measurement,Delta Temp (K),Error,EC Comp. Running,Using ABS,
1698323315.732,,0.000000e+000,2.999906e+002,1.419984e-006,3.551735e-009,6.831392e-003,1.117052e-003,3,9.087372e-001,1.825000e+000,,,,,,,,,,,,,,,,,,0,4.000000e+000,1.000000e+000,2,2,7.019043e-003,0,,0,
1698323423.944,,5.000000e+001,3.000012e+002,3.491720e-006,7.462486e-009,5.655059e-003,3.718473e-003,3,9.592898e-001,1.825000e+000,,,,,,,,,,,,,,,,,,0,4.000000e+000,1.000000e+000,2,2,0.000000e+000,0,,0,
1698323539.384,,1.000000e+002,2.999994e+002,5.710787e-006,5.226875e-009,-1.893821e-003,3.407455e-003,3,9.679669e-001,1.825000e+000,,,,,,,,,,,,,,,,,,0,4.000000e+000,1.000000e+000,2,2,7.080078e-003,0,,0,
1698323661.369,,2.000000e+002,3.000012e+002,1.073553e-005,2.011905e-008,-2.781074e-003,9.367135e-004,3,9.785004e-001,1.825000e+000,,,,,,,,,,,,,,,,,,0,4.000000e+000,1.000000e+000,2,2,0.000000e+000,0,,0,
1698323782.560,,3.000000e+002,2.999959e+002,1.562723e-005,3.338641e-008,3.469156e-003,6.629270e-004,3,9.808353e-001,1.825000e+000,,,,,,,,,,,,,,,,,,0,4.000000e+000,1.000000e+000,2,2,7.080078e-003,0,,0,
1698323905.251,,4.000000e+002,2.999994e+002,1.989621e-005,3.273172e-008,4.483621e-003,6.210931e-004,3,9.822398e-001,1.825000e+000,,,,,,,,,,,,,,,,,,0,4.000000e+000,1.000000e+000,2,2,7.080078e-003,0,,0,
1698324027.192,,5.000000e+002,2.999959e+002,2.414871e-005,8.045304e-009,7.686894e-003,1.451475e-003,3,9.813502e-001,1.825000e+000,,,,,,,,,,,,,,,,,,0,4.000000e+000,1.000000e+000,2,2,7.080078e-003,0,,0,
1698324148.160,,6.000000e+002,2.999994e+002,2.823411e-005,4.212627e-008,1.105742e-002,5.367224e-004,3,9.819154e-001,1.825000e+000,,,,,,,,,,,,,,,,,,0,4.000000e+000,1.000000e+000,2,2,7.080078e-003,0,,0,
1698324264.351,,7.000000e+002,2.999977e+002,3.150823e-005,2.839716e-008,1.286510e-002,1.855681e-003,3,9.819822e-001,1.825000e+000,,,,,,,,,,,,,,,,,,0,4.000000e+000,1.000000e+000,2,2,1.409912e-002,0,,0,
1698324379.357,,8.000000e+002,2.999959e+002,3.400833e-005,7.434395e-010,1.460738e-002,8.362554e-004,3,9.798132e-001,1.825000e+000,,,,,,,,,,,,,,,,,,0,4.000000e+000,1.000000e+000,2,2,7.080078e-003,0,,0,
1698324501.608,,9.000000e+002,2.999959e+002,3.612726e-005,6.595735e-009,1.524113e-002,2.783990e-004,3,9.809166e-001,1.825000e+000,,,,,,,,,,,,,,,,,,0,4.000000e+000,1.000000e+000,2,2,7.080078e-003,0,,0,
1698324623.299,,1.000000e+003,2.999994e+002,3.796937e-005,1.917471e-007,1.650769e-002,3.119170e-004,3,9.822363e-001,1.825000e+000,,,,,,,,,,,,,,,,,,0,4.000000e+000,1.000000e+000,2,2,7.080078e-003,0,,0,
1698324751.492,,1.250000e+003,2.999959e+002,4.129986e-005,1.212133e-007,1.938993e-002,5.778886e-004,3,9.815466e-001,1.825000e+000,,,,,,,,,,,,,,,,,,0,4.000000e+000,1.000000e+000,2,2,7.080078e-003,0,,0,
1698324872.227,,1.500000e+003,2.999994e+002,4.246536e-005,4.918762e-008,2.348077e-002,5.270569e-004,3,9.814715e-001,1.825000e+000,,,,,,,,,,,,,,,,,,0,4.000000e+000,1.000000e+000,2,2,7.080078e-003,0,,0,
1698325012.644,,1.750000e+003,3.000012e+002,4.203853e-005,6.623517e-008,2.845128e-002,3.720155e-003,3,9.816285e-001,1.825000e+000,,,,,,,,,,,,,,,,,,0,4.000000e+000,1.000000e+000,2,2,0.000000e+000,0,,0,
1698325140.835,,2.000000e+003,3.000012e+002,4.057826e-005,1.055420e-007,3.179036e-002,7.290641e-004,3,9.788610e-001,1.825000e+000,,,,,,,,,,,,,,,,,,0,4.000000e+000,1.000000e+000,2,2,0.000000e+000,0,,0,
1698325263.099,,2.250000e+003,2.999994e+002,3.854974e-005,7.247591e-008,3.856404e-002,1.774282e-003,3,9.791701e-001,1.825000e+000,,,,,,,,,,,,,,,,,,0,4.000000e+000,1.000000e+000,2,2,7.080078e-003,0,,0,
1698325384.790,,2.500000e+003,2.999977e+002,3.585014e-005,2.873903e-007,4.923275e-002,2.816200e-005,3,9.724658e-001,1.825000e+000,,,,,,,,,,,,,,,,,,0,4.000000e+000,1.000000e+000,2,2,7.080078e-003,0,,0,
1698325506.481,,2.750000e+003,2.999994e+002,3.290086e-005,1.117391e-007,5.224414e-002,4.257640e-003,3,9.756246e-001,1.825000e+000,,,,,,,,,,,,,,,,,,0,4.000000e+000,1.000000e+000,2,2,7.080078e-003,0,,0,
1698325629.193,,3.000000e+003,3.000012e+002,2.940237e-005,6.157006e-008,6.550306e-002,8.609916e-004,3,9.695011e-001,1.825000e+000,,,,,,,,,,,,,,,,,,0,4.000000e+000,1.000000e+000,2,2,0.000000e+000,0,,0,
1698325762.135,,4.000000e+003,2.999994e+002,1.285757e-005,2.200362e-007,1.938099e-001,1.016421e-002,3,8.853070e-001,1.825000e+000,,,,,,,,,,,,,,,,,,0,4.000000e+000,1.000000e+000,2,2,7.080078e-003,0,,0,
1698325895.327,,5.000000e+003,3.000012e+002,-9.859221e-006,1.851635e-007,-3.185832e-001,8.177754e-003,3,9.159861e-001,1.825000e+000,,,,,,,,,,,,,,,,,,0,4.000000e+000,1.000000e+000,2,2,0.000000e+000,0,,0,
1698326036.487,,6.000000e+003,2.999977e+002,-3.220686e-005,8.634650e-008,-1.119743e-001,1.171693e-002,3,9.630084e-001,1.825000e+000,,,,,,,,,,,,,,,,,,0,4.000000e+000,1.000000e+000,2,2,7.080078e-003,0,,0,
1698326170.458,,7.000000e+003,2.999977e+002,-5.695202e-005,2.130108e-007,-6.614728e-002,3.565897e-003,3,9.644536e-001,1.825000e+000,,,,,,,,,,,,,,,,,,0,4.000000e+000,1.000000e+000,2,2,7.080078e-003,0,,0,
1698326290.900,,8.000000e+003,2.999959e+002,-8.254459e-005,9.738741e-008,-5.050734e-002,6.641553e-005,3,9.731916e-001,1.825000e+000,,,,,,,,,,,,,,,,,,0,4.000000e+000,1.000000e+000,2,2,7.080078e-003,0,,0,
1698326411.591,,9.000000e+003,2.999994e+002,-1.090080e-004,1.240996e-007,-3.953182e-002,2.119986e-005,3,9.784298e-001,1.825000e+000,,,,,,,,,,,,,,,,,,0,4.000000e+000,1.000000e+000,2,2,7.080078e-003,0,,0,
1698326533.282,,1.000000e+004,2.999994e+002,-1.357634e-004,1.067357e-007,-3.398030e-002,6.718734e-005,3,9.780186e-001,1.825000e+000,,,,,,,,,,,,,,,,,,0,4.000000e+000,1.000000e+000,2,2,7.080078e-003,0,,0,
1698326682.369,,1.500000e+004,2.999977e+002,-2.730037e-004,1.121584e-007,-2.212154e-002,2.462402e-003,3,9.813603e-001,1.825000e+000,,,,,,,,,,,,,,,,,,0,4.000000e+000,1.000000e+000,2,2,7.080078e-003,0,,0,
1698326822.562,,2.000000e+004,2.999994e+002,-4.115826e-004,2.998230e-007,-1.589471e-002,1.114072e-003,3,9.803762e-001,1.825000e+000,,,,,,,,,,,,,,,,,,0,4.000000e+000,1.000000e+000,2,2,7.080078e-003,0,,0,
1698326962.809,,2.500000e+004,2.999977e+002,-5.511235e-004,6.235594e-008,-1.292886e-002,3.971873e-004,3,9.815134e-001,1.825000e+000,,,,,,,,,,,,,,,,,,0,4.000000e+000,1.000000e+000,2,2,7.080078e-003,0,,0,
1698327098.094,,3.000000e+004,2.999977e+002,-6.907568e-004,6.783009e-008,-1.250490e-002,1.143071e-003,3,9.819658e-001,1.825000e+000,,,,,,,,,,,,,,,,,,0,4.000000e+000,1.000000e+000,2,2,7.080078e-003,0,,0,
1698327241.793,,3.500000e+004,2.999977e+002,-8.449127e-004,1.583799e-007,9.502793e-003,7.380716e-004,3,9.606144e-001,1.825000e+000,,,,,,,,,,,,,,,,,,0,4.000000e+000,1.000000e+000,2,2,7.080078e-003,0,,0,
1698327385.985,,4.000000e+004,2.999977e+002,-9.844967e-004,3.882943e-007,8.987633e-003,1.391030e-004,3,9.633460e-001,1.825000e+000,,,,,,,,,,,,,,,,,,0,4.000000e+000,1.000000e+000,2,2,7.080078e-003,0,,0,
1698327525.677,,4.500000e+004,3.000012e+002,-1.124532e-003,3.301778e-007,8.331043e-003,1.055398e-003,3,9.662945e-001,1.825000e+000,,,,,,,,,,,,,,,,,,0,4.000000e+000,1.000000e+000,2,2,0.000000e+000,0,,0,
1698327671.370,,5.000000e+004,2.999994e+002,-1.263978e-003,8.561079e-008,7.719313e-003,4.932004e-005,3,9.679937e-001,1.825000e+000,,,,,,,,,,,,,,,,,,0,4.000000e+000,1.000000e+000,2,2,1.419067e-002,0,,0,
1698327819.088,,5.500000e+004,2.999959e+002,-1.403803e-003,6.486663e-008,7.652082e-003,5.511194e-005,3,9.696143e-001,1.825000e+000,,,,,,,,,,,,,,,,,,0,4.000000e+000,1.000000e+000,2,2,7.080078e-003,0,,0,
1698327955.834,,6.000000e+004,3.000012e+002,-1.543541e-003,2.607013e-007,7.340251e-003,6.809680e-006,3,9.708873e-001,1.825000e+000,,,,,,,,,,,,,,,,,,0,4.000000e+000,1.000000e+000,2,2,1.419067e-002,0,,0,
1698328100.089,,6.500000e+004,2.999994e+002,-1.683065e-003,1.226567e-008,7.198884e-003,9.775106e-005,3,9.718757e-001,1.825000e+000,,,,,,,,,,,,,,,,,,0,4.000000e+000,1.000000e+000,2,2,7.080078e-003,0,,0,
1698328251.583,,7.000000e+004,3.000012e+002,-1.750493e-003,1.316266e-007,-2.149072e-002,5.342903e-005,3,9.849521e-001,1.825000e+000,,,,,,,,,,,,,,,,,,0,4.000000e+000,1.000000e+000,2,2,1.419067e-002,0,,0,
1698328400.025,,6.500000e+004,2.999994e+002,-1.610387e-003,3.284501e-008,-2.367138e-002,7.728547e-005,3,9.852390e-001,1.825000e+000,,,,,,,,,,,,,,,,,,0,4.000000e+000,1.000000e+000,2,2,7.080078e-003,0,,0,
1698328567.090,,5.500000e+004,2.999994e+002,-1.330637e-003,5.605866e-008,-2.952514e-002,1.215173e-004,3,9.858234e-001,1.825000e+000,,,,,,,,,,,,,,,,,,0,4.000000e+000,1.000000e+000,2,2,7.080078e-003,0,,0,
1698328738.793,,4.500000e+004,2.999977e+002,-1.051431e-003,1.515476e-007,-3.758652e-002,5.167994e-005,3,9.862784e-001,1.825000e+000,,,,,,,,,,,,,,,,,,0,4.000000e+000,1.000000e+000,2,2,7.080078e-003,0,,0,
1698328901.487,,3.500000e+004,2.999994e+002,-7.731017e-004,8.890351e-008,-5.045912e-002,1.050940e-003,3,9.867786e-001,1.825000e+000,,,,,,,,,,,,,,,,,,0,4.000000e+000,1.000000e+000,2,2,7.080078e-003,0,,0,
1698329063.430,,2.500000e+004,3.000012e+002,-4.951515e-004,3.209170e-007,-7.719842e-002,3.994994e-005,3,9.838803e-001,1.825000e+000,,,,,,,,,,,,,,,,,,0,4.000000e+000,1.000000e+000,2,2,0.000000e+000,0,,0,
1698329229.624,,1.500000e+004,2.999994e+002,-2.221726e-004,1.261010e-007,-1.656588e-001,1.235956e-003,3,9.557865e-001,1.825000e+000,,,,,,,,,,,,,,,,,,0,4.000000e+000,1.000000e+000,2,2,7.080078e-003,0,,0,
1698329374.584,,1.000000e+004,2.999994e+002,-9.792115e-005,6.099769e-008,-3.808408e-001,4.618241e-004,3,8.434880e-001,1.825000e+000,,,,,,,,,,,,,,,,,,0,4.000000e+000,1.000000e+000,2,2,7.080078e-003,0,,0,
1698329489.525,,9.000000e+003,2.999977e+002,-7.880673e-005,2.383314e-007,-4.989506e-001,2.285834e-003,3,7.738400e-001,1.825000e+000,,,,,,,,,,,,,,,,,,0,4.000000e+000,1.000000e+000,2,2,7.080078e-003,0,,0,
1698329610.732,,8.000000e+003,3.000012e+002,-6.449669e-005,9.495388e-008,-6.795200e-001,1.971630e-004,3,6.698763e-001,1.825000e+000,,,,,,,,,,,,,,,,,,0,4.000000e+000,1.000000e+000,2,2,0.000000e+000,0,,0,
1698329732.423,,7.000000e+003,3.000030e+002,6.882871e-005,2.601611e-007,8.958552e-001,1.854461e-004,3,7.388667e-001,1.825000e+000,,,,,,,,,,,,,,,,,,0,4.000000e+000,1.000000e+000,2,2,7.110596e-003,0,,0,
1698329859.663,,6.000000e+003,2.999994e+002,7.183598e-005,9.446512e-008,6.985283e-001,1.060330e-003,3,8.561249e-001,1.825000e+000,,,,,,,,,,,,,,,,,,0,4.000000e+000,1.000000e+000,2,2,7.080078e-003,0,,0,
1698329993.105,,5.000000e+003,2.999977e+002,7.969167e-005,2.138366e-007,5.432453e-001,3.681949e-004,3,9.323335e-001,1.825000e+000,,,,,,,,,,,,,,,,,,0,4.000000e+000,1.000000e+000,2,2,7.080078e-003,0,,0,
1698330118.546,,4.000000e+003,2.999994e+002,8.885353e-005,1.477661e-007,4.343638e-001,2.237365e-004,3,9.699238e-001,1.825000e+000,,,,,,,,,,,,,,,,,,0,4.000000e+000,1.000000e+000,2,2,7.080078e-003,0,,0,
1698330251.737,,3.000000e+003,3.000012e+002,9.456450e-005,1.096271e-007,3.545992e-001,2.226281e-003,3,9.773624e-001,1.825000e+000,,,,,,,,,,,,,,,,,,0,4.000000e+000,1.000000e+000,2,2,0.000000e+000,0,,0,
1698330373.488,,2.750000e+003,3.000012e+002,9.525041e-005,1.806213e-007,3.390325e-001,1.361175e-003,3,9.765296e-001,1.825000e+000,,,,,,,,,,,,,,,,,,0,4.000000e+000,1.000000e+000,2,2,0.000000e+000,0,,0,
1698330495.501,,2.500000e+003,2.999959e+002,9.526537e-005,1.538319e-008,3.231923e-001,2.584866e-004,3,9.741579e-001,1.825000e+000,,,,,,,,,,,,,,,,,,0,4.000000e+000,1.000000e+000,2,2,7.080078e-003,0,,0,
1698330617.442,,2.250000e+003,3.000012e+002,9.429672e-005,1.078367e-008,3.075742e-001,4.145142e-004,3,9.722843e-001,1.825000e+000,,,,,,,,,,,,,,,,,,0,4.000000e+000,1.000000e+000,2,2,0.000000e+000,0,,0,
1698330739.884,,2.000000e+003,2.999994e+002,9.274471e-005,2.832719e-007,2.915667e-001,8.261414e-004,3,9.718463e-001,1.825000e+000,,,,,,,,,,,,,,,,,,0,4.000000e+000,1.000000e+000,2,2,7.080078e-003,0,,0,
1698330862.076,,1.750000e+003,2.999941e+002,9.028499e-005,1.570886e-007,2.722599e-001,6.489982e-004,3,9.694553e-001,1.825000e+000,,,,,,,,,,,,,,,,,,0,4.000000e+000,1.000000e+000,2,2,0.000000e+000,0,,0,
1698330983.090,,1.500000e+003,2.999959e+002,8.591088e-005,5.862590e-008,2.547263e-001,5.027487e-004,3,9.677788e-001,1.825000e+000,,,,,,,,,,,,,,,,,,0,4.000000e+000,1.000000e+000,2,2,7.080078e-003,0,,0,
1698331105.282,,1.250000e+003,2.999994e+002,7.966071e-005,1.051099e-007,2.349804e-001,8.201777e-004,3,9.674883e-001,1.825000e+000,,,,,,,,,,,,,,,,,,0,4.000000e+000,1.000000e+000,2,2,1.419067e-002,0,,0,
1698331227.723,,1.000000e+003,3.000012e+002,7.168598e-005,1.214963e-007,2.105032e-001,8.593848e-004,3,9.686892e-001,1.825000e+000,,,,,,,,,,,,,,,,,,0,4.000000e+000,1.000000e+000,2,2,0.000000e+000,0,,0,
1698331343.418,,9.000000e+002,2.999941e+002,6.865853e-005,3.621275e-007,2.002167e-001,1.686654e-003,3,9.663118e-001,1.825000e+000,,,,,,,,,,,,,,,,,,0,4.000000e+000,1.000000e+000,2,2,0.000000e+000,0,,0,
1698331465.152,,8.000000e+002,2.999977e+002,6.499901e-005,2.867601e-007,1.858417e-001,6.274612e-004,3,9.669278e-001,1.825000e+000,,,,,,,,,,,,,,,,,,0,4.000000e+000,1.000000e+000,2,2,7.080078e-003,0,,0,
1698331586.594,,7.000000e+002,3.000012e+002,6.091379e-005,1.410520e-007,1.761452e-001,5.948501e-004,3,9.688553e-001,1.825000e+000,,,,,,,,,,,,,,,,,,0,4.000000e+000,1.000000e+000,2,2,0.000000e+000,0,,0,
1698331707.785,,6.000000e+002,2.999977e+002,5.673723e-005,2.171936e-007,1.623644e-001,1.088443e-005,3,9.698876e-001,1.825000e+000,,,,,,,,,,,,,,,,,,0,4.000000e+000,1.000000e+000,2,2,7.080078e-003,0,,0,
1698331823.798,,5.000000e+002,3.000012e+002,5.205344e-005,9.026691e-009,1.494513e-001,2.704173e-003,3,9.702164e-001,1.825000e+000,,,,,,,,,,,,,,,,,,0,4.000000e+000,1.000000e+000,2,2,0.000000e+000,0,,0,
1698331939.990,,4.000000e+002,3.000012e+002,4.692919e-005,2.178007e-007,1.358800e-001,8.860637e-004,3,9.613670e-001,1.825000e+000,,,,,,,,,,,,,,,,,,0,4.000000e+000,1.000000e+000,2,2,0.000000e+000,0,,0,
1698332061.225,,3.000000e+002,2.999977e+002,4.211944e-005,7.231616e-007,1.084789e-001,1.237455e-002,3,9.483656e-001,1.825000e+000,,,,,,,,,,,,,,,,,,0,4.000000e+000,1.000000e+000,2,2,7.080078e-003,0,,0,
1698332176.425,,2.000000e+002,2.999977e+002,3.519825e-005,4.277812e-007,9.984671e-002,4.608389e-004,3,9.635788e-001,1.825000e+000,,,,,,,,,,,,,,,,,,0,4.000000e+000,1.000000e+000,2,2,7.080078e-003,0,,0,
1698332299.117,,1.000000e+002,3.000012e+002,2.700384e-005,4.656115e-008,7.830712e-002,1.872021e-003,3,9.701182e-001,1.825000e+000,,,,,,,,,,,,,,,,,,0,4.000000e+000,1.000000e+000,2,2,0.000000e+000,0,,0,
1698332407.333,,7.500000e+001,3.000012e+002,2.458271e-005,3.376198e-008,6.939042e-002,2.550411e-005,3,9.639016e-001,1.825000e+000,,,,,,,,,,,,,,,,,,0,4.000000e+000,1.000000e+000,2,2,0.000000e+000,0,,0,
1698332515.524,,5.000000e+001,3.000012e+002,2.235231e-005,7.508437e-008,6.692921e-002,2.208042e-003,3,9.733254e-001,1.825000e+000,,,,,,,,,,,,,,,,,,0,4.000000e+000,1.000000e+000,2,2,0.000000e+000,0,,0,
1698332630.554,,2.500000e+001,2.999977e+002,1.989141e-005,2.140270e-008,5.382662e-002,4.257883e-003,3,9.722697e-001,1.825000e+000,,,,,,,,,,,,,,,,,,0,4.000000e+000,1.000000e+000,2,2,7.080078e-003,0,,0,
1698332738.794,,0.000000e+000,2.999977e+002,1.728831e-005,3.228386e-007,3.716085e-002,1.553169e-003,3,9.569378e-001,1.825000e+000,,,,,,,,,,,,,,,,,,0,4.000000e+000,1.000000e+000,2,2,7.080078e-003,0,,0,
1698332853.485,,-2.500000e+001,2.999959e+002,1.481234e-005,3.448728e-007,2.267303e-002,5.750313e-003,3,9.727826e-001,1.825000e+000,,,,,,,,,,,,,,,,,,0,4.000000e+000,1.000000e+000,2,2,7.080078e-003,0,,0,
1698332969.248,,-5.000000e+001,2.999977e+002,1.242069e-005,2.610338e-007,5.138972e-003,6.055104e-003,3,9.643871e-001,1.825000e+000,,,,,,,,,,,,,,,,,,0,4.000000e+000,1.000000e+000,2,2,7.080078e-003,0,,0,
1698333084.188,,-7.500000e+001,2.999977e+002,9.605219e-006,1.247215e-007,-3.634770e-002,7.405084e-003,3,9.521456e-001,1.825000e+000,,,,,,,,,,,,,,,,,,0,4.000000e+000,1.000000e+000,2,2,7.080078e-003,0,,0,
1698333193.452,,-1.000000e+002,2.999994e+002,7.220880e-006,1.960781e-007,-8.688833e-002,2.908559e-003,3,9.018265e-001,1.825000e+000,,,,,,,,,,,,,,,,,,0,4.000000e+000,1.000000e+000,2,2,7.080078e-003,0,,0,
1698333315.393,,-2.000000e+002,3.000012e+002,-4.991255e-006,3.619062e-007,6.137129e-001,3.687900e-002,3,8.589209e-001,1.825000e+000,,,,,,,,,,,,,,,,,,0,4.000000e+000,1.000000e+000,2,2,0.000000e+000,0,,0,
1698333437.084,,-3.000000e+002,2.999959e+002,-1.334852e-005,1.392346e-007,2.840061e-001,2.262042e-003,3,9.412274e-001,1.825000e+000,,,,,,,,,,,,,,,,,,0,4.000000e+000,1.000000e+000,2,2,7.080078e-003,0,,0,
1698333558.537,,-4.000000e+002,2.999995e+002,-2.236082e-005,4.095581e-008,2.450429e-001,1.236166e-002,3,9.513405e-001,1.825000e+000,,,,,,,,,,,,,,,,,,0,4.000000e+000,1.000000e+000,2,2,1.419067e-002,0,,0,
1698333680.514,,-5.000000e+002,3.000012e+002,-3.067020e-005,2.233057e-007,2.285718e-001,5.836285e-004,3,9.660158e-001,1.825000e+000,,,,,,,,,,,,,,,,,,0,4.000000e+000,1.000000e+000,2,2,0.000000e+000,0,,0,
1698333803.279,,-6.000000e+002,3.000012e+002,-3.812053e-005,2.011673e-007,2.268950e-001,2.925012e-003,3,9.679656e-001,1.825000e+000,,,,,,,,,,,,,,,,,,0,4.000000e+000,1.000000e+000,2,2,0.000000e+000,0,,0,
1698333924.720,,-7.000000e+002,3.000012e+002,-4.491868e-005,7.223924e-007,2.288552e-001,6.495419e-003,3,9.053993e-001,1.825000e+000,,,,,,,,,,,,,,,,,,0,4.000000e+000,1.000000e+000,2,2,0.000000e+000,0,,0,
1698334046.412,,-8.000000e+002,3.000012e+002,-5.131622e-005,8.444290e-008,2.302719e-001,1.749916e-003,3,9.648173e-001,1.825000e+000,,,,,,,,,,,,,,,,,,0,4.000000e+000,1.000000e+000,2,2,0.000000e+000,0,,0,
1698334168.652,,-9.000000e+002,3.000012e+002,-5.685367e-005,4.722484e-008,2.327597e-001,9.438787e-004,3,9.671760e-001,1.825000e+000,,,,,,,,,,,,,,,,,,0,4.000000e+000,1.000000e+000,2,2,1.419067e-002,0,,0,
1698334284.124,,-1.000000e+003,3.000012e+002,-6.196411e-005,1.329848e-007,2.387702e-001,2.147277e-004,3,9.686791e-001,1.825000e+000,,,,,,,,,,,,,,,,,,0,4.000000e+000,1.000000e+000,2,2,0.000000e+000,0,,0,
1698334407.315,,-1.250000e+003,2.999994e+002,-7.239672e-005,3.441924e-008,2.553064e-001,3.928297e-004,3,9.692891e-001,1.825000e+000,,,,,,,,,,,,,,,,,,0,4.000000e+000,1.000000e+000,2,2,7.080078e-003,0,,0,
1698334528.756,,-1.500000e+003,2.999977e+002,-8.053488e-005,7.959129e-009,2.722279e-001,1.702311e-004,3,9.696961e-001,1.825000e+000,,,,,,,,,,,,,,,,,,0,4.000000e+000,1.000000e+000,2,2,7.080078e-003,0,,0,
1698334657.197,,-1.750000e+003,3.000012e+002,-8.624786e-005,7.148810e-008,2.874672e-001,7.509304e-004,3,9.715465e-001,1.825000e+000,,,,,,,,,,,,,,,,,,0,4.000000e+000,1.000000e+000,2,2,0.000000e+000,0,,0,
1698334785.444,,-2.000000e+003,3.000012e+002,-8.971505e-005,3.175934e-008,3.019240e-001,1.584300e-004,3,9.726293e-001,1.825000e+000,,,,,,,,,,,,,,,,,,0,4.000000e+000,1.000000e+000,2,2,0.000000e+000,0,,0,
1698334906.945,,-2.250000e+003,2.999959e+002,-9.176502e-005,1.576442e-007,3.162949e-001,6.833058e-004,3,9.740209e-001,1.825000e+000,,,,,,,,,,,,,,,,,,0,4.000000e+000,1.000000e+000,2,2,7.080078e-003,0,,0,
1698335035.887,,-2.500000e+003,2.999994e+002,-9.296089e-005,6.189289e-008,3.310222e-001,3.514626e-004,3,9.758812e-001,1.825000e+000,,,,,,,,,,,,,,,,,,0,4.000000e+000,1.000000e+000,2,2,7.080078e-003,0,,0,
1698335165.828,,-2.750000e+003,2.999994e+002,-9.310304e-005,3.643089e-008,3.465473e-001,6.301586e-004,3,9.765886e-001,1.825000e+000,,,,,,,,,,,,,,,,,,0,4.000000e+000,1.000000e+000,2,2,7.080078e-003,0,,0,
1698335287.769,,-3.000000e+003,2.999959e+002,-9.312366e-005,2.516360e-008,3.628364e-001,3.423799e-004,3,9.788457e-001,1.825000e+000,,,,,,,,,,,,,,,,,,0,4.000000e+000,1.000000e+000,2,2,7.080078e-003,0,,0,
1698335420.961,,-4.000000e+003,2.999994e+002,-8.822915e-005,5.668730e-007,4.414001e-001,4.298916e-003,3,9.670308e-001,1.825000e+000,,,,,,,,,,,,,,,,,,0,4.000000e+000,1.000000e+000,2,2,7.080078e-003,0,,0,
1698335553.904,,-5.000000e+003,2.999977e+002,-7.925396e-005,9.485922e-007,5.505826e-001,2.884868e-003,3,9.255291e-001,1.825000e+000,,,,,,,,,,,,,,,,,,0,4.000000e+000,1.000000e+000,2,2,1.419067e-002,0,,0,
1698335687.095,,-6.000000e+003,2.999994e+002,-7.121491e-005,3.442644e-007,7.050290e-001,6.179992e-004,3,8.510668e-001,1.825000e+000,,,,,,,,,,,,,,,,,,0,4.000000e+000,1.000000e+000,2,2,7.080078e-003,0,,0,
1698335821.038,,-7.000000e+003,2.999994e+002,-6.871317e-005,1.501430e-007,8.995301e-001,5.314719e-005,3,7.386423e-001,1.825000e+000,,,,,,,,,,,,,,,,,,0,4.000000e+000,1.000000e+000,2,2,7.080078e-003,0,,0,
1698335941.229,,-8.000000e+003,2.999994e+002,6.466089e-005,2.402144e-007,-6.707227e-001,1.552016e-003,3,6.712028e-001,1.825000e+000,,,,,,,,,,,,,,,,,,0,4.000000e+000,1.000000e+000,2,2,7.080078e-003,0,,0,
1698336062.680,,-9.000000e+003,3.000012e+002,7.888250e-005,1.040037e-007,-4.920630e-001,1.293592e-003,3,7.788161e-001,1.825000e+000,,,,,,,,,,,,,,,,,,0,4.000000e+000,1.000000e+000,2,2,0.000000e+000,0,,0,
1698336184.910,,-1.000000e+004,3.000012e+002,9.849588e-005,1.697193e-007,-3.766684e-001,1.171472e-003,3,8.460451e-001,1.825000e+000,,,,,,,,,,,,,,,,,,0,4.000000e+000,1.000000e+000,2,2,0.000000e+000,0,,0,
1698336356.240,,-2.000000e+004,2.999977e+002,3.578499e-004,1.983454e-007,-1.000619e-001,1.954560e-005,3,9.775903e-001,1.825000e+000,,,,,,,,,,,,,,,,,,0,4.000000e+000,1.000000e+000,2,2,7.080078e-003,0,,0,
1698336518.706,,-3.000000e+004,2.999994e+002,6.341118e-004,2.694270e-007,-5.662666e-002,2.991162e-004,3,9.862809e-001,1.825000e+000,,,,,,,,,,,,,,,,,,0,4.000000e+000,1.000000e+000,2,2,7.080078e-003,0,,0,
1698336690.867,,-4.000000e+004,2.999994e+002,9.123094e-004,1.144633e-007,-3.846800e-002,2.436720e-004,3,9.866889e-001,1.825000e+000,,,,,,,,,,,,,,,,,,0,4.000000e+000,1.000000e+000,2,2,7.080078e-003,0,,0,
1698336850.562,,-5.000000e+004,2.999959e+002,1.191516e-003,7.672044e-007,-2.751694e-002,2.987158e-004,3,9.853092e-001,1.825000e+000,,,,,,,,,,,,,,,,,,0,4.000000e+000,1.000000e+000,2,2,7.080078e-003,0,,0,
1698337019.505,,-6.000000e+004,2.999959e+002,1.469957e-003,3.144550e-008,-2.091663e-002,6.948040e-005,3,9.854615e-001,1.825000e+000,,,,,,,,,,,,,,,,,,0,4.000000e+000,1.000000e+000,2,2,7.080078e-003,0,,0,
1698337184.449,,-7.000000e+004,2.999977e+002,1.748698e-003,4.667442e-008,-1.629616e-002,5.834309e-005,3,9.848974e-001,1.825000e+000,,,,,,,,,,,,,,,,,,0,4.000000e+000,1.000000e+000,2,2,7.080078e-003,0,,0,
1698337332.891,,-6.500000e+004,2.999959e+002,1.608688e-003,3.021084e-008,-1.902909e-002,2.402318e-004,3,9.852710e-001,1.825000e+000,,,,,,,,,,,,,,,,,,0,4.000000e+000,1.000000e+000,2,2,7.080078e-003,0,,0,
1698337500.624,,-5.500000e+004,2.999959e+002,1.329266e-003,5.976291e-008,-2.512163e-002,1.730378e-004,3,9.859273e-001,1.825000e+000,,,,,,,,,,,,,,,,,,0,4.000000e+000,1.000000e+000,2,2,7.080078e-003,0,,0,
1698337672.570,,-4.500000e+004,2.999959e+002,1.050186e-003,8.062231e-007,-3.304074e-002,2.707461e-004,3,9.863682e-001,1.825000e+000,,,,,,,,,,,,,,,,,,0,4.000000e+000,1.000000e+000,2,2,7.080078e-003,0,,0,
1698337842.513,,-3.500000e+004,3.000012e+002,7.720982e-004,1.954231e-007,-4.702350e-002,1.750648e-004,3,9.868796e-001,1.825000e+000,,,,,,,,,,,,,,,,,,0,4.000000e+000,1.000000e+000,2,2,0.000000e+000,0,,0,
1698338010.457,,-2.500000e+004,2.999977e+002,4.945252e-004,9.569476e-008,-7.371111e-002,2.896806e-004,3,9.837517e-001,1.825000e+000,,,,,,,,,,,,,,,,,,0,4.000000e+000,1.000000e+000,2,2,1.419067e-002,0,,0,
1698338170.225,,-1.500000e+004,2.999977e+002,2.219555e-004,4.042846e-008,-1.640756e-001,7.836996e-004,3,9.555525e-001,1.825000e+000,,,,,,,,,,,,,,,,,,0,4.000000e+000,1.000000e+000,2,2,7.080078e-003,0,,0,
1698338314.192,,-1.000000e+004,3.000012e+002,9.774460e-005,2.558188e-007,-3.795080e-001,2.534374e-003,3,8.454227e-001,1.825000e+000,,,,,,,,,,,,,,,,,,0,4.000000e+000,1.000000e+000,2,2,0.000000e+000,0,,0,
1698338429.134,,-9.000000e+003,2.999977e+002,7.843856e-005,1.336537e-007,-4.973711e-001,6.957422e-007,3,7.750609e-001,1.825000e+000,,,,,,,,,,,,,,,,,,0,4.000000e+000,1.000000e+000,2,2,7.080078e-003,0,,0,
1698338549.576,,-8.000000e+003,2.999994e+002,6.457006e-005,1.387985e-007,-6.785872e-001,4.258096e-004,3,6.651950e-001,1.825000e+000,,,,,,,,,,,,,,,,,,0,4.000000e+000,1.000000e+000,2,2,7.080078e-003,0,,0,
1698338676.524,,-7.000000e+003,2.999994e+002,-6.930390e-005,2.017564e-007,8.962146e-001,1.099611e-004,3,7.419449e-001,1.825000e+000,,,,,,,,,,,,,,,,,,0,4.000000e+000,1.000000e+000,2,2,7.080078e-003,0,,0,
1698338810.784,,-6.000000e+003,2.999959e+002,-7.195634e-005,1.990862e-007,6.990397e-001,1.068549e-003,3,8.586318e-001,1.825000e+000,,,,,,,,,,,,,,,,,,0,4.000000e+000,1.000000e+000,2,2,7.080078e-003,0,,0,
1698338944.477,,-5.000000e+003,3.000012e+002,-7.997212e-005,4.720941e-008,5.441576e-001,1.556483e-004,3,9.337926e-001,1.825000e+000,,,,,,,,,,,,,,,,,,0,4.000000e+000,1.000000e+000,2,2,0.000000e+000,0,,0,
1698339077.450,,-4.000000e+003,2.999994e+002,-8.876392e-005,1.525199e-007,4.337226e-001,1.187256e-003,3,9.702938e-001,1.825000e+000,,,,,,,,,,,,,,,,,,0,4.000000e+000,1.000000e+000,2,2,7.080078e-003,0,,0,
1698339211.143,,-3.000000e+003,2.999994e+002,-9.465012e-005,1.562551e-007,3.558923e-001,5.979163e-004,3,9.763761e-001,1.825000e+000,,,,,,,,,,,,,,,,,,0,4.000000e+000,1.000000e+000,2,2,7.080078e-003,0,,0,
1698339333.334,,-2.750000e+003,2.999977e+002,-9.516841e-005,1.687057e-007,3.384503e-001,2.676620e-003,3,9.741593e-001,1.825000e+000,,,,,,,,,,,,,,,,,,0,4.000000e+000,1.000000e+000,2,2,7.080078e-003,0,,0,
1698339455.277,,-2.500000e+003,2.999959e+002,-9.490541e-005,7.582008e-008,3.230920e-001,2.678854e-004,3,9.725761e-001,1.825000e+000,,,,,,,,,,,,,,,,,,0,4.000000e+000,1.000000e+000,2,2,7.080078e-003,0,,0,
1698339584.468,,-2.250000e+003,3.000012e+002,-9.440504e-005,6.275209e-008,3.083118e-001,9.396640e-005,3,9.715288e-001,1.825000e+000,,,,,,,,,,,,,,,,,,0,4.000000e+000,1.000000e+000,2,2,0.000000e+000,0,,0,
1698339706.171,,-2.000000e+003,2.999959e+002,-9.286733e-005,1.008705e-007,2.928526e-001,2.299110e-004,3,9.719000e-001,1.825000e+000,,,,,,,,,,,,,,,,,,0,4.000000e+000,1.000000e+000,2,2,7.080078e-003,0,,0,
1698339828.898,,-1.750000e+003,2.999941e+002,-9.021271e-005,1.393388e-007,2.760347e-001,4.816542e-004,3,9.692729e-001,1.825000e+000,,,,,,,,,,,,,,,,,,0,4.000000e+000,1.000000e+000,2,2,0.000000e+000,0,,0,
1698339949.839,,-1.500000e+003,2.999959e+002,-8.593296e-005,9.569475e-009,2.557552e-001,5.038234e-004,3,9.689296e-001,1.825000e+000,,,,,,,,,,,,,,,,,,0,4.000000e+000,1.000000e+000,2,2,7.080078e-003,0,,0,
1698340072.781,,-1.250000e+003,2.999994e+002,-7.967818e-005,3.874608e-007,2.356093e-001,7.247256e-004,3,9.673021e-001,1.825000e+000,,,,,,,,,,,,,,,,,,0,4.000000e+000,1.000000e+000,2,2,7.080078e-003,0,,0,
1698340194.472,,-1.000000e+003,2.999977e+002,-7.185261e-005,8.444804e-008,2.104650e-001,1.677445e-005,3,9.658378e-001,1.825000e+000,,,,,,,,,,,,,,,,,,0,4.000000e+000,1.000000e+000,2,2,7.080078e-003,0,,0,
1698340315.663,,-9.000000e+002,2.999994e+002,-6.848839e-005,5.455115e-008,1.997222e-001,2.509845e-004,3,9.675583e-001,1.825000e+000,,,,,,,,,,,,,,,,,,0,4.000000e+000,1.000000e+000,2,2,7.080078e-003,0,,0,
1698340431.854,,-8.000000e+002,2.999977e+002,-6.509872e-005,4.934556e-007,1.894394e-001,4.334119e-003,3,9.652480e-001,1.825000e+000,,,,,,,,,,,,,,,,,,0,4.000000e+000,1.000000e+000,2,2,7.080078e-003,0,,0,
1698340553.295,,-7.000000e+002,3.000012e+002,-6.083570e-005,1.900930e-007,1.795168e-001,1.003063e-003,3,9.681112e-001,1.825000e+000,,,,,,,,,,,,,,,,,,0,4.000000e+000,1.000000e+000,2,2,0.000000e+000,0,,0,
1698340675.025,,-6.000000e+002,3.000012e+002,-5.687461e-005,1.240996e-007,1.650905e-001,1.205063e-003,3,9.649869e-001,1.825000e+000,,,,,,,,,,,,,,,,,,0,4.000000e+000,1.000000e+000,2,2,0.000000e+000,0,,0,
1698340797.260,,-5.000000e+002,2.999994e+002,-5.247899e-005,1.019046e-007,1.512072e-001,1.626900e-003,3,9.660535e-001,1.825000e+000,,,,,,,,,,,,,,,,,,0,4.000000e+000,1.000000e+000,2,2,7.080078e-003,0,,0,
1698340918.952,,-4.000000e+002,2.999977e+002,-4.720212e-005,1.528749e-007,1.356825e-001,1.527476e-003,3,9.678067e-001,1.825000e+000,,,,,,,,,,,,,,,,,,0,4.000000e+000,1.000000e+000,2,2,7.080078e-003,0,,0,
1698341039.394,,-3.000000e+002,2.999977e+002,-4.135626e-005,1.145044e-007,1.167584e-001,1.908973e-003,3,9.721262e-001,1.825000e+000,,,,,,,,,,,,,,,,,,0,4.000000e+000,1.000000e+000,2,2,7.080078e-003,0,,0,
1698341161.835,,-2.000000e+002,2.999994e+002,-3.489505e-005,1.279017e-007,9.638394e-002,2.522073e-003,3,9.706678e-001,1.825000e+000,,,,,,,,,,,,,,,,,,0,4.000000e+000,1.000000e+000,2,2,7.080078e-003,0,,0,
1698341284.028,,-1.000000e+002,2.999994e+002,-2.696916e-005,1.917458e-007,7.794998e-002,3.569659e-003,3,9.737409e-001,1.825000e+000,,,,,,,,,,,,,,,,,,0,4.000000e+000,1.000000e+000,2,2,7.080078e-003,0,,0,
1698341392.782,,-7.500000e+001,3.000012e+002,-2.462720e-005,1.241884e-007,7.298213e-002,2.399889e-003,3,9.693022e-001,1.825000e+000,,,,,,,,,,,,,,,,,,0,4.000000e+000,1.000000e+000,2,2,0.000000e+000,0,,0,
1698341500.790,,-5.000000e+001,3.000030e+002,-2.253688e-005,4.714767e-008,6.181080e-002,3.050046e-003,3,9.697414e-001,1.825000e+000,,,,,,,,,,,,,,,,,,0,4.000000e+000,1.000000e+000,2,2,7.110596e-003,0,,0,
1698341615.231,,-2.500000e+001,2.999994e+002,-1.987991e-005,2.712599e-007,5.136720e-002,4.719504e-003,3,9.725623e-001,1.825000e+000,,,,,,,,,,,,,,,,,,0,4.000000e+000,1.000000e+000,2,2,7.080078e-003,0,,0,
1698341723.939,,0.000000e+000,2.999994e+002,-1.754502e-005,7.623296e-008,5.163001e-002,6.304810e-003,3,9.688254e-001,1.825000e+000,,,,,,,,,,,,,,,,,,0,4.000000e+000,1.000000e+000,2,2,7.080078e-003,0,,0,
1698341833.388,,2.500000e+001,3.000012e+002,-1.497083e-005,1.320067e-007,2.656442e-002,9.232231e-003,3,9.630004e-001,1.825000e+000,,,,,,,,,,,,,,,,,,0,4.000000e+000,1.000000e+000,2,2,1.419067e-002,0,,0,
1698341949.578,,5.000000e+001,2.999977e+002,-1.249323e-005,7.187589e-008,-5.992191e-003,7.437115e-003,3,9.740394e-001,1.825000e+000,,,,,,,,,,,,,,,,,,0,4.000000e+000,1.000000e+000,2,2,7.080078e-003,0,,0,
1698342065.330,,7.500000e+001,2.999994e+002,-9.708559e-006,1.143739e-007,-1.995036e-002,4.595745e-004,3,9.359664e-001,1.825000e+000,,,,,,,,,,,,,,,,,,0,4.000000e+000,1.000000e+000,2,2,1.419067e-002,0,,0,
1698342173.291,,1.000000e+002,3.000012e+002,-7.366646e-006,9.383198e-008,-8.228717e-002,8.182063e-003,3,9.392433e-001,1.825000e+000,,,,,,,,,,,,,,,,,,0,4.000000e+000,1.000000e+000,2,2,1.419067e-002,0,,0,
1698342295.015,,2.000000e+002,2.999959e+002,4.609154e-006,5.845097e-008,6.485467e-001,8.272664e-002,3,7.789281e-001,1.825000e+000,,,,,,,,,,,,,,,,,,0,4.000000e+000,1.000000e+000,2,2,7.080078e-003,0,,0,
1698342417.707,,3.000000e+002,2.999977e+002,1.332922e-005,3.752855e-007,3.021063e-001,2.044459e-003,3,9.259483e-001,1.825000e+000,,,,,,,,,,,,,,,,,,0,4.000000e+000,1.000000e+000,2,2,7.080078e-003,0,,0,
1698342540.177,,4.000000e+002,2.999977e+002,2.247574e-005,1.814419e-007,2.412390e-001,2.651542e-003,3,9.489904e-001,1.825000e+000,,,,,,,,,,,,,,,,,,0,4.000000e+000,1.000000e+000,2,2,7.080078e-003,0,,0,
1698342661.904,,5.000000e+002,2.999977e+002,3.068031e-005,1.502227e-007,2.353950e-001,1.432424e-003,3,9.625114e-001,1.825000e+000,,,,,,,,,,,,,,,,,,0,4.000000e+000,1.000000e+000,2,2,7.080078e-003,0,,0,
1698342783.668,,6.000000e+002,2.999994e+002,3.836053e-005,8.028584e-008,2.239368e-001,2.368126e-003,3,9.656093e-001,1.825000e+000,,,,,,,,,,,,,,,,,,0,4.000000e+000,1.000000e+000,2,2,7.080078e-003,0,,0,
1698342899.359,,7.000000e+002,2.999977e+002,4.521889e-005,1.702492e-007,2.222525e-001,1.116712e-003,3,9.615390e-001,1.825000e+000,,,,,,,,,,,,,,,,,,0,4.000000e+000,1.000000e+000,2,2,7.080078e-003,0,,0,
1698343014.800,,8.000000e+002,3.000012e+002,5.156128e-005,2.081875e-008,2.250223e-001,2.189371e-003,3,9.626970e-001,1.825000e+000,,,,,,,,,,,,,,,,,,0,4.000000e+000,1.000000e+000,2,2,0.000000e+000,0,,0,
1698343129.742,,9.000000e+002,2.999977e+002,5.748680e-005,1.204915e-006,2.289396e-001,4.924532e-003,3,9.497041e-001,1.825000e+000,,,,,,,,,,,,,,,,,,0,4.000000e+000,1.000000e+000,2,2,7.080078e-003,0,,0,
1698343251.229,,1.000000e+003,2.999977e+002,6.195474e-005,1.227208e-007,2.390877e-001,4.236391e-004,3,9.682287e-001,1.825000e+000,,,,,,,,,,,,,,,,,,0,4.000000e+000,1.000000e+000,2,2,7.080078e-003,0,,0,
1698343379.921,,1.250000e+003,3.000012e+002,7.247101e-005,7.135949e-009,2.560249e-001,4.096674e-005,3,9.691315e-001,1.825000e+000,,,,,,,,,,,,,,,,,,0,4.000000e+000,1.000000e+000,2,2,0.000000e+000,0,,0,
1698343501.112,,1.500000e+003,2.999959e+002,8.060345e-005,1.450187e-007,2.728547e-001,1.405155e-003,3,9.699720e-001,1.825000e+000,,,,,,,,,,,,,,,,,,0,4.000000e+000,1.000000e+000,2,2,7.080078e-003,0,,0,
1698343623.303,,1.750000e+003,2.999994e+002,8.629238e-005,3.682190e-008,2.886338e-001,8.340651e-004,3,9.711570e-001,1.825000e+000,,,,,,,,,,,,,,,,,,0,4.000000e+000,1.000000e+000,2,2,7.080078e-003,0,,0,
1698343751.244,,2.000000e+003,2.999994e+002,8.976120e-005,5.768438e-008,3.022297e-001,2.280987e-004,3,9.727531e-001,1.825000e+000,,,,,,,,,,,,,,,,,,0,4.000000e+000,1.000000e+000,2,2,7.080078e-003,0,,0,
1698343884.936,,3.000000e+003,3.000012e+002,9.290095e-005,2.754414e-007,3.634298e-001,1.411919e-003,3,9.782435e-001,1.825000e+000,,,,,,,,,,,,,,,,,,0,4.000000e+000,1.000000e+000,2,2,0.000000e+000,0,,0,
1698344018.178,,4.000000e+003,3.000012e+002,8.820498e-005,2.959900e-007,4.458023e-001,4.427632e-003,3,9.605241e-001,1.825000e+000,,,,,,,,,,,,,,,,,,0,4.000000e+000,1.000000e+000,2,2,0.000000e+000,0,,0,
1698344151.619,,5.000000e+003,3.000012e+002,7.913233e-005,7.805965e-007,5.501201e-001,3.230387e-003,3,9.261603e-001,1.825000e+000,,,,,,,,,,,,,,,,,,0,4.000000e+000,1.000000e+000,2,2,0.000000e+000,0,,0,