File: spin_crossover/dane/AOT — kopia/Big AOT/FeTrz_XTvT_MCE_final.rso.csv
Field (Oe),Temperature (K),Long Moment (emu),Long Offset (cm)
0.000000e+000,4.000043e+002,-1.351779e-006,-1.627299e-001
0.000000e+000,3.912113e+002,-1.385659e-006,-1.503208e-001
0.000000e+000,3.836063e+002,-1.359524e-006,-1.386173e-001
0.000000e+000,3.754981e+002,-1.413546e-006,-1.451405e-001
0.000000e+000,3.668011e+002,-1.407319e-006,-1.388944e-001
0.000000e+000,3.597372e+002,-1.418303e-006,-1.449545e-001
0.000000e+000,3.509884e+002,-2.382132e-007,-1.966443e-001
0.000000e+000,3.437551e+002,-8.743270e-008,-8.455911e-002
0.000000e+000,3.354444e+002,-9.083564e-008,-4.822742e-001
0.000000e+000,3.276722e+002,-9.951295e-008,-6.673495e-001
0.000000e+000,3.196050e+002,-3.343912e-008,-5.024137e-001
0.000000e+000,3.116689e+002,-1.174493e-007,-1.893785e-001
0.000000e+000,3.037182e+002,-1.169115e-007,-5.563334e-001
0.000000e+000,3.033259e+002,-6.136595e-008,-8.328723e-001
0.000000e+000,3.112523e+002,-7.755398e-008,-3.901222e-001
0.000000e+000,3.192404e+002,-3.365818e-008,4.115373e-003
0.000000e+000,3.272963e+002,-4.297945e-008,-5.221202e-001
0.000000e+000,3.352504e+002,-1.512065e-007,-2.056281e-001
0.000000e+000,3.432824e+002,-4.164428e-008,-6.618557e-001
0.000000e+000,3.512231e+002,-5.397058e-008,-5.294019e-001
0.000000e+000,3.592874e+002,-1.782328e-007,-2.088363e-001
0.000000e+000,3.672354e+002,-8.196131e-008,-9.866285e-002
0.000000e+000,3.753157e+002,-7.789325e-008,-4.985466e-001
0.000000e+000,3.832343e+002,-5.260917e-007,-1.517377e-001
0.000000e+000,3.912359e+002,-1.384866e-006,-1.471870e-001
0.000000e+000,3.992324e+002,-1.357871e-006,-1.741114e-001
1.000000e+002,3.934769e+002,1.121880e-005,-1.020416e-001
1.000000e+002,3.856546e+002,1.136387e-005,-9.623811e-002
1.000000e+002,3.775030e+002,1.148436e-005,-9.272698e-002
1.000000e+002,3.689130e+002,1.160844e-005,-9.190509e-002
1.000000e+002,3.618358e+002,1.166861e-005,-8.523166e-002
1.000000e+002,3.532211e+002,7.432390e-006,-5.159352e-002
1.000000e+002,3.456451e+002,5.431827e-006,-1.479556e-002
1.000000e+002,3.375590e+002,5.392792e-006,-1.413701e-002
1.000000e+002,3.296024e+002,5.410033e-006,-1.426601e-002
1.000000e+002,3.216858e+002,5.407927e-006,-5.285311e-003
1.000000e+002,3.136347e+002,5.449273e-006,-9.327324e-003
1.000000e+002,3.057972e+002,5.508836e-006,-9.880527e-003
1.000000e+002,3.012237e+002,5.523552e-006,-8.796619e-003
1.000000e+002,3.092218e+002,5.478619e-006,-9.943872e-003
1.000000e+002,3.172390e+002,5.407743e-006,-1.378691e-002
1.000000e+002,3.252515e+002,5.386859e-006,-1.429629e-002
1.000000e+002,3.332475e+002,5.351255e-006,-2.539647e-002
1.000000e+002,3.414335e+002,5.308750e-006,-2.371054e-002
1.000000e+002,3.492710e+002,5.313576e-006,-2.418358e-002
1.000000e+002,3.573223e+002,5.352742e-006,-3.349735e-002
1.000000e+002,3.652968e+002,5.333760e-006,-3.312486e-002
1.000000e+002,3.732448e+002,5.377955e-006,-4.181366e-002
1.000000e+002,3.814980e+002,6.449891e-006,-5.992244e-002
1.000000e+002,3.892975e+002,1.128382e-005,-1.053142e-001
1.000000e+002,3.973217e+002,1.117112e-005,-1.074835e-001
2.000000e+002,3.956905e+002,2.389648e-005,-1.003524e-001
2.000000e+002,3.874581e+002,2.422189e-005,-9.615964e-002
2.000000e+002,3.798188e+002,2.450143e-005,-9.444658e-002
2.000000e+002,3.708729e+002,2.478328e-005,-9.006514e-002
2.000000e+002,3.636829e+002,2.497326e-005,-8.619702e-002
2.000000e+002,3.553849e+002,2.217345e-005,-7.753606e-002
2.000000e+002,3.476322e+002,1.139924e-005,-1.465010e-002
2.000000e+002,3.396518e+002,1.106101e-005,-1.114544e-002
2.000000e+002,3.315086e+002,1.111137e-005,-6.452844e-003
2.000000e+002,3.238413e+002,1.113811e-005,-5.125329e-003
2.000000e+002,3.156371e+002,1.122651e-005,-2.030917e-003
2.000000e+002,3.079050e+002,1.131722e-005,-5.779585e-004
2.000000e+002,3.000672e+002,1.137624e-005,2.826602e-003
2.000000e+002,3.073183e+002,1.125890e-005,-3.387952e-003
2.000000e+002,3.152485e+002,1.119634e-005,-7.246365e-003
2.000000e+002,3.232627e+002,1.112759e-005,-1.198585e-002
2.000000e+002,3.312478e+002,1.108959e-005,-1.710358e-002
2.000000e+002,3.392760e+002,1.103679e-005,-1.740129e-002
2.000000e+002,3.472811e+002,1.102563e-005,-2.231627e-002
2.000000e+002,3.552554e+002,1.098763e-005,-2.158340e-002
2.000000e+002,3.632199e+002,1.100092e-005,-2.642295e-002
2.000000e+002,3.712282e+002,1.107253e-005,-3.024892e-002
2.000000e+002,3.792887e+002,1.169251e-005,-3.978866e-002
2.000000e+002,3.872453e+002,2.415586e-005,-1.064267e-001
2.000000e+002,3.953034e+002,2.392186e-005,-1.083872e-001
3.000000e+002,3.977954e+002,3.639676e-005,-1.025705e-001
3.000000e+002,3.893744e+002,3.687766e-005,-9.781753e-002
3.000000e+002,3.817691e+002,3.731664e-005,-9.321973e-002
3.000000e+002,3.731382e+002,3.776508e-005,-9.161341e-002
3.000000e+002,3.653103e+002,3.815588e-005,-8.775400e-002
3.000000e+002,3.575023e+002,3.815478e-005,-8.733967e-002
3.000000e+002,3.493568e+002,1.778602e-005,-1.821174e-002
3.000000e+002,3.417698e+002,1.670084e-005,-9.945381e-003
3.000000e+002,3.334517e+002,1.668139e-005,-5.076115e-003
3.000000e+002,3.258546e+002,1.677854e-005,-1.152913e-003
3.000000e+002,3.175949e+002,1.685666e-005,-2.350276e-003
3.000000e+002,3.097899e+002,1.692737e-005,2.178688e-003
3.000000e+002,3.016084e+002,1.709849e-005,1.718509e-003
3.000000e+002,3.052870e+002,1.695529e-005,-8.346051e-004
3.000000e+002,3.132591e+002,1.688829e-005,-4.342085e-003
3.000000e+002,3.214309e+002,1.680468e-005,-8.111121e-003
3.000000e+002,3.292303e+002,1.666707e-005,-9.061811e-003
3.000000e+002,3.372288e+002,1.664990e-005,-1.352144e-002
3.000000e+002,3.452600e+002,1.660659e-005,-1.678642e-002
3.000000e+002,3.532459e+002,1.653364e-005,-2.016887e-002
3.000000e+002,3.614672e+002,1.661970e-005,-2.477853e-002
3.000000e+002,3.692811e+002,1.658456e-005,-2.766909e-002
3.000000e+002,3.772841e+002,1.698238e-005,-3.406250e-002
3.000000e+002,3.852245e+002,3.626239e-005,-1.048940e-001
3.000000e+002,3.932665e+002,3.663317e-005,-1.077413e-001
4.000000e+002,4.000043e+002,4.858224e-005,-1.057180e-001
4.000000e+002,3.914192e+002,4.927121e-005,-1.000643e-001
4.000000e+002,3.837166e+002,4.986561e-005,-9.561044e-002
4.000000e+002,3.754583e+002,5.046616e-005,-9.409961e-002
4.000000e+002,3.670943e+002,5.103572e-005,-8.940808e-002
4.000000e+002,3.596748e+002,5.122136e-005,-8.877328e-002
4.000000e+002,3.512951e+002,2.600328e-005,-3.092416e-002
4.000000e+002,3.437929e+002,2.222002e-005,-7.642635e-003
4.000000e+002,3.354443e+002,2.211226e-005,-6.411800e-003
4.000000e+002,3.276915e+002,2.218190e-005,-3.686366e-003
4.000000e+002,3.195706e+002,2.228050e-005,-1.753485e-003
4.000000e+002,3.117034e+002,2.240270e-005,1.990764e-004
4.000000e+002,3.037091e+002,2.257458e-005,2.731802e-003
4.000000e+002,3.032734e+002,2.257077e-005,-7.315181e-004
4.000000e+002,3.112830e+002,2.235317e-005,-3.158943e-003
4.000000e+002,3.192444e+002,2.224605e-005,-7.688234e-003
4.000000e+002,3.272622e+002,2.214384e-005,-1.036823e-002
4.000000e+002,3.352303e+002,2.204185e-005,-1.410391e-002
4.000000e+002,3.432635e+002,2.195874e-005,-1.909917e-002
4.000000e+002,3.512430e+002,2.194101e-005,-2.249925e-002
4.000000e+002,3.592433e+002,2.196600e-005,-2.498596e-002
4.000000e+002,3.672736e+002,2.205277e-005,-2.762077e-002
4.000000e+002,3.752218e+002,2.227805e-005,-3.379186e-002
4.000000e+002,3.832790e+002,4.360784e-005,-9.663364e-002
4.000000e+002,3.913041e+002,4.919565e-005,-1.081503e-001
4.000000e+002,3.992420e+002,4.865739e-005,-1.095418e-001
5.000000e+002,3.935586e+002,6.125259e-005,-1.037014e-001
5.000000e+002,3.855794e+002,6.204337e-005,-9.819193e-002
5.000000e+002,3.775289e+002,6.271191e-005,-9.718452e-002
5.000000e+002,3.689844e+002,6.355313e-005,-9.320280e-002
5.000000e+002,3.618094e+002,6.397519e-005,-8.924618e-002
5.000000e+002,3.532989e+002,4.543681e-005,-6.448594e-002
5.000000e+002,3.456834e+002,2.771557e-005,-1.460917e-002
5.000000e+002,3.374497e+002,2.720957e-005,-1.005387e-002
5.000000e+002,3.297128e+002,2.727310e-005,-6.250925e-003
5.000000e+002,3.216693e+002,2.740071e-005,-6.178071e-003
5.000000e+002,3.136697e+002,2.757436e-005,-3.257954e-003
5.000000e+002,3.057657e+002,2.773170e-005,-2.880076e-003
5.000000e+002,3.012291e+002,2.783804e-005,-2.334695e-003
5.000000e+002,3.092275e+002,2.766014e-005,-5.602548e-003
5.000000e+002,3.172570e+002,2.742882e-005,-9.682244e-003
5.000000e+002,3.252641e+002,2.728264e-005,-1.374396e-002
5.000000e+002,3.333051e+002,2.710118e-005,-1.637327e-002
5.000000e+002,3.413962e+002,2.703303e-005,-1.972516e-002
5.000000e+002,3.492270e+002,2.701838e-005,-2.241134e-002
5.000000e+002,3.572145e+002,2.701950e-005,-2.709623e-002
5.000000e+002,3.652833e+002,2.707899e-005,-3.099583e-002
5.000000e+002,3.732448e+002,2.732198e-005,-3.560617e-002
5.000000e+002,3.814803e+002,4.563014e-005,-8.381654e-002
5.000000e+002,3.892422e+002,6.152606e-005,-1.098530e-001
5.000000e+002,3.972610e+002,6.087455e-005,-1.122665e-001
6.000000e+002,3.955921e+002,7.295609e-005,-1.071837e-001
6.000000e+002,3.874247e+002,7.395858e-005,-1.026282e-001
6.000000e+002,3.798304e+002,7.472243e-005,-1.009989e-001
6.000000e+002,3.709561e+002,7.570829e-005,-9.565231e-002
6.000000e+002,3.636402e+002,7.637106e-005,-9.236611e-002
6.000000e+002,3.554688e+002,7.225673e-005,-8.768321e-002
6.000000e+002,3.476056e+002,3.343831e-005,-2.247078e-002
6.000000e+002,3.396357e+002,3.205421e-005,-1.601322e-002
6.000000e+002,3.316270e+002,3.210895e-005,-1.254703e-002
6.000000e+002,3.237975e+002,3.222827e-005,-1.119883e-002
6.000000e+002,3.155936e+002,3.243550e-005,-8.265345e-003
6.000000e+002,3.079050e+002,3.262826e-005,-5.580114e-003
6.000000e+002,3.000796e+002,3.287028e-005,-2.994959e-003
6.000000e+002,3.072568e+002,3.261755e-005,-9.192280e-003
6.000000e+002,3.152091e+002,3.238465e-005,-1.250222e-002
6.000000e+002,3.232772e+002,3.217361e-005,-1.600235e-002
6.000000e+002,3.312610e+002,3.204873e-005,-1.962385e-002
6.000000e+002,3.392507e+002,3.192658e-005,-2.355903e-002
6.000000e+002,3.472303e+002,3.179940e-005,-2.753610e-002
6.000000e+002,3.552249e+002,3.184019e-005,-3.141682e-002
6.000000e+002,3.632517e+002,3.189371e-005,-3.546899e-002
6.000000e+002,3.712978e+002,3.213854e-005,-3.713445e-002
6.000000e+002,3.792480e+002,3.978096e-005,-5.952819e-002
6.000000e+002,3.872392e+002,7.370363e-005,-1.119859e-001
6.000000e+002,3.952780e+002,7.287214e-005,-1.135337e-001
7.000000e+002,3.977346e+002,8.428354e-005,-1.117808e-001
7.000000e+002,3.890644e+002,8.550967e-005,-1.056700e-001
7.000000e+002,3.817868e+002,8.649280e-005,-1.016723e-001
7.000000e+002,3.731973e+002,8.764582e-005,-1.001263e-001
7.000000e+002,3.655471e+002,8.857320e-005,-9.598959e-002
7.000000e+002,3.575846e+002,8.895636e-005,-9.471993e-002
7.000000e+002,3.494843e+002,4.032475e-005,-3.334386e-002
7.000000e+002,3.417838e+002,3.680703e-005,-2.146554e-002
7.000000e+002,3.335205e+002,3.679455e-005,-1.775548e-002
7.000000e+002,3.258715e+002,3.692645e-005,-1.380481e-002
7.000000e+002,3.175809e+002,3.708366e-005,-1.365269e-002
7.000000e+002,3.097955e+002,3.736187e-005,-1.107639e-002
7.000000e+002,3.016102e+002,3.760137e-005,-8.746063e-003
7.000000e+002,3.053128e+002,3.743341e-005,-1.233513e-002
7.000000e+002,3.131989e+002,3.717010e-005,-1.680146e-002
7.000000e+002,3.214207e+002,3.689617e-005,-2.028655e-002
7.000000e+002,3.292282e+002,3.672975e-005,-2.367534e-002
7.000000e+002,3.372357e+002,3.657352e-005,-2.681527e-002
7.000000e+002,3.452600e+002,3.646079e-005,-3.067830e-002
7.000000e+002,3.532510e+002,3.640652e-005,-3.443713e-002
7.000000e+002,3.614278e+002,3.652698e-005,-3.810442e-002
7.000000e+002,3.692426e+002,3.673076e-005,-4.149268e-002
7.000000e+002,3.772553e+002,3.845763e-005,-4.763657e-002
7.000000e+002,3.852605e+002,8.563572e-005,-1.138997e-001
7.000000e+002,3.932258e+002,8.481121e-005,-1.160312e-001
8.000000e+002,4.000043e+002,9.536629e-005,-1.153341e-001
8.000000e+002,3.913695e+002,9.683880e-005,-1.096307e-001
8.000000e+002,3.836331e+002,9.804730e-005,-1.049769e-001
8.000000e+002,3.753928e+002,9.924792e-005,-1.035982e-001
8.000000e+002,3.669965e+002,1.004628e-004,-9.893227e-002
8.000000e+002,3.596176e+002,1.010147e-004,-9.855144e-002
8.000000e+002,3.513547e+002,5.145666e-005,-5.095063e-002
8.000000e+002,3.437976e+002,4.162834e-005,-2.509869e-002
8.000000e+002,3.355567e+002,4.124297e-005,-2.310297e-002
8.000000e+002,3.277363e+002,4.139074e-005,-1.909349e-002
8.000000e+002,3.196111e+002,4.160194e-005,-1.813821e-002
8.000000e+002,3.117515e+002,4.188994e-005,-1.568265e-002
8.000000e+002,3.036110e+002,4.217189e-005,-1.464617e-002
8.000000e+002,3.032915e+002,4.214817e-005,-1.511317e-002
8.000000e+002,3.112466e+002,4.186672e-005,-1.966924e-002
8.000000e+002,3.192565e+002,4.153104e-005,-2.344358e-002
8.000000e+002,3.272451e+002,4.130643e-005,-2.717396e-002
8.000000e+002,3.351876e+002,4.108483e-005,-3.093416e-002
8.000000e+002,3.432377e+002,4.097676e-005,-3.403946e-002
8.000000e+002,3.512429e+002,4.090050e-005,-3.769248e-002
8.000000e+002,3.592874e+002,4.097550e-005,-4.073624e-002
8.000000e+002,3.672355e+002,4.117545e-005,-4.594662e-002
8.000000e+002,3.752559e+002,4.189950e-005,-5.074838e-002
8.000000e+002,3.832284e+002,9.448756e-005,-1.143751e-001
8.000000e+002,3.913103e+002,9.664076e-005,-1.184967e-001
8.000000e+002,3.992065e+002,9.548203e-005,-1.201650e-001
9.000000e+002,3.935586e+002,1.078667e-004,-1.131417e-001
9.000000e+002,3.855704e+002,1.093144e-004,-1.082096e-001
9.000000e+002,3.776124e+002,1.106020e-004,-1.066575e-001
9.000000e+002,3.690228e+002,1.121061e-004,-1.020602e-001
9.000000e+002,3.618516e+002,1.129811e-004,-9.880242e-002
9.000000e+002,3.533364e+002,8.469528e-005,-7.978539e-002
9.000000e+002,3.457121e+002,4.679427e-005,-3.150611e-002
9.000000e+002,3.375567e+002,4.558409e-005,-2.802055e-002
9.000000e+002,3.296717e+002,4.574259e-005,-2.331962e-002
9.000000e+002,3.215748e+002,4.597380e-005,-2.270494e-002
9.000000e+002,3.136833e+002,4.624841e-005,-1.956267e-002
9.000000e+002,3.057530e+002,4.656335e-005,-1.823377e-002
9.000000e+002,3.012094e+002,4.674291e-005,-1.838149e-002
9.000000e+002,3.092861e+002,4.639324e-005,-2.322546e-002
9.000000e+002,3.172210e+002,4.604900e-005,-2.616225e-002
9.000000e+002,3.252283e+002,4.574002e-005,-2.967203e-002
9.000000e+002,3.332253e+002,4.550138e-005,-3.409828e-002
9.000000e+002,3.414055e+002,4.533309e-005,-3.733923e-002
9.000000e+002,3.492711e+002,4.524465e-005,-4.094002e-002
9.000000e+002,3.572094e+002,4.525671e-005,-4.429179e-002
9.000000e+002,3.652215e+002,4.547725e-005,-4.842015e-002
9.000000e+002,3.732982e+002,4.601355e-005,-5.302291e-002
9.000000e+002,3.814333e+002,9.145153e-005,-1.066804e-001
9.000000e+002,3.892729e+002,1.083778e-004,-1.193921e-001
9.000000e+002,3.972834e+002,1.071431e-004,-1.219157e-001
1.500000e+003,3.956365e+002,1.739935e-004,-1.235651e-001
1.500000e+003,3.874125e+002,1.765643e-004,-1.179267e-001
1.500000e+003,3.798188e+002,1.785982e-004,-1.166467e-001
1.500000e+003,3.708979e+002,1.812047e-004,-1.115763e-001
1.500000e+003,3.637094e+002,1.829388e-004,-1.078440e-001
1.500000e+003,3.554841e+002,1.774986e-004,-1.049623e-001
1.500000e+003,3.476322e+002,7.421081e-005,-5.219931e-002
1.500000e+003,3.396171e+002,6.996742e-005,-4.535233e-002
1.500000e+003,3.316160e+002,7.007463e-005,-4.128888e-002
1.500000e+003,3.237767e+002,7.040742e-005,-4.025856e-002
1.500000e+003,3.155502e+002,7.086800e-005,-3.678790e-002
1.500000e+003,3.078862e+002,7.136128e-005,-3.498887e-002
1.500000e+003,3.000583e+002,7.203271e-005,-3.383550e-002
1.500000e+003,3.073593e+002,7.134034e-005,-3.807677e-002
1.500000e+003,3.152446e+002,7.077320e-005,-4.198960e-002
1.500000e+003,3.232232e+002,7.024387e-005,-4.561573e-002
1.500000e+003,3.312873e+002,6.983498e-005,-4.885399e-002
1.500000e+003,3.392967e+002,6.954328e-005,-5.320775e-002
1.500000e+003,3.472667e+002,6.938739e-005,-5.671938e-002
1.500000e+003,3.552503e+002,6.939552e-005,-6.076136e-002
1.500000e+003,3.632650e+002,6.962418e-005,-6.380837e-002
1.500000e+003,3.712616e+002,7.033584e-005,-6.847973e-002
1.500000e+003,3.792567e+002,1.048680e-004,-9.487569e-002
1.500000e+003,3.872301e+002,1.760763e-004,-1.280706e-001
1.500000e+003,3.952336e+002,1.739413e-004,-1.300619e-001
2.000000e+003,3.978115e+002,2.271393e-004,-1.295364e-001
2.000000e+003,3.893898e+002,2.307028e-004,-1.240248e-001
2.000000e+003,3.817396e+002,2.337021e-004,-1.194284e-001
2.000000e+003,3.731832e+002,2.368650e-004,-1.173026e-001
2.000000e+003,3.652941e+002,2.396001e-004,-1.128166e-001
2.000000e+003,3.574508e+002,2.409457e-004,-1.117230e-001
2.000000e+003,3.494401e+002,1.006201e-004,-6.657906e-002
2.000000e+003,3.418353e+002,8.917613e-005,-5.596420e-002
2.000000e+003,3.335094e+002,8.893626e-005,-5.152595e-002
2.000000e+003,3.258672e+002,8.932293e-005,-4.883693e-002
2.000000e+003,3.175569e+002,8.993607e-005,-4.649772e-002
2.000000e+003,3.098240e+002,9.059999e-005,-4.404528e-002
2.000000e+003,3.015905e+002,9.140674e-005,-4.227890e-002
2.000000e+003,3.053514e+002,9.094157e-005,-4.603423e-002
2.000000e+003,3.132183e+002,9.011394e-005,-5.014607e-002
2.000000e+003,3.214084e+002,8.941307e-005,-5.447416e-002
2.000000e+003,3.292325e+002,8.889420e-005,-5.745243e-002
2.000000e+003,3.372379e+002,8.843135e-005,-6.110897e-002
2.000000e+003,3.453102e+002,8.812851e-005,-6.507466e-002
2.000000e+003,3.532735e+002,9.570758e-005,-1.268429e-001
2.000000e+003,3.615066e+002,8.838619e-005,-7.271348e-002
2.000000e+003,3.692481e+002,8.917435e-005,-7.708672e-002
2.000000e+003,3.772524e+002,9.942512e-005,-8.420148e-002
2.000000e+003,3.852515e+002,2.314771e-004,-1.321811e-001
2.000000e+003,3.932696e+002,2.286936e-004,-1.344680e-001
2.500000e+003,4.000076e+002,2.793012e-004,-1.352174e-001
2.500000e+003,3.913850e+002,2.837043e-004,-1.286910e-001
2.500000e+003,3.835617e+002,2.876110e-004,-1.237787e-001
2.500000e+003,3.753899e+002,2.913260e-004,-1.220908e-001
2.500000e+003,3.670182e+002,2.952170e-004,-1.171721e-001
2.500000e+003,3.597191e+002,2.971037e-004,-1.164606e-001
2.500000e+003,3.512457e+002,1.429709e-004,-8.559953e-002
2.500000e+003,3.438237e+002,1.088449e-004,-6.240859e-002
2.500000e+003,3.354757e+002,1.072440e-004,-5.979069e-002
2.500000e+003,3.277578e+002,1.076735e-004,-5.602238e-002
2.500000e+003,3.195645e+002,1.082960e-004,-5.508003e-002
2.500000e+003,3.117246e+002,1.091567e-004,-5.161710e-002
2.500000e+003,3.036127e+002,1.100742e-004,-5.042977e-002
2.500000e+003,3.033422e+002,1.100393e-004,-5.237110e-002
2.500000e+003,3.112217e+002,1.090330e-004,-5.665447e-002
2.500000e+003,3.192606e+002,1.080929e-004,-6.012790e-002
2.500000e+003,3.272792e+002,1.073615e-004,-6.417517e-002
2.500000e+003,3.352100e+002,1.067998e-004,-6.785150e-002
2.500000e+003,3.432376e+002,1.063972e-004,-7.185787e-002
2.500000e+003,3.512677e+002,1.062499e-004,-7.527541e-002
2.500000e+003,3.592406e+002,1.065427e-004,-7.916804e-002
2.500000e+003,3.672599e+002,1.072889e-004,-8.349898e-002
2.500000e+003,3.752531e+002,1.102994e-004,-8.837999e-002
2.500000e+003,3.832819e+002,2.840438e-004,-1.347471e-001
2.500000e+003,3.912947e+002,2.831699e-004,-1.371395e-001
2.500000e+003,3.992937e+002,2.794837e-004,-1.391385e-001
3.000000e+003,3.935210e+002,3.359439e-004,-1.326362e-001
3.000000e+003,3.855915e+002,3.407608e-004,-1.271988e-001
3.000000e+003,3.776355e+002,3.452401e-004,-1.257076e-001
3.000000e+003,3.689597e+002,3.503941e-004,-1.207309e-001
3.000000e+003,3.618489e+002,3.533105e-004,-1.171507e-001
3.000000e+003,3.531961e+002,2.640667e-004,-1.039177e-001
3.000000e+003,3.457121e+002,1.301424e-004,-7.030453e-002
3.000000e+003,3.374588e+002,1.255104e-004,-6.636295e-002
3.000000e+003,3.296803e+002,1.259131e-004,-6.264699e-002
3.000000e+003,3.216364e+002,1.266057e-004,-6.135788e-002
3.000000e+003,3.136697e+002,1.275805e-004,-5.783443e-002
3.000000e+003,3.057861e+002,1.286181e-004,-5.633501e-002
3.000000e+003,3.012344e+002,1.292646e-004,-5.656377e-002
3.000000e+003,3.092521e+002,1.280013e-004,-6.046983e-002
3.000000e+003,3.172111e+002,1.268609e-004,-6.468575e-002
3.000000e+003,3.252430e+002,1.259313e-004,-6.858793e-002
3.000000e+003,3.333007e+002,1.251475e-004,-7.210405e-002
3.000000e+003,3.414429e+002,1.246239e-004,-7.619240e-002
3.000000e+003,3.492392e+002,1.244141e-004,-7.969499e-002
3.000000e+003,3.572684e+002,1.246014e-004,-8.378439e-002
3.000000e+003,3.652188e+002,1.253082e-004,-8.712386e-002
3.000000e+003,3.733066e+002,1.275536e-004,-9.238298e-002
3.000000e+003,3.814480e+002,3.082934e-004,-1.332853e-001
3.000000e+003,3.892300e+002,3.379873e-004,-1.391969e-001
3.000000e+003,3.972513e+002,3.335662e-004,-1.414602e-001
4.000000e+003,3.955223e+002,4.405913e-004,-1.373539e-001
4.000000e+003,3.874247e+002,4.473833e-004,-1.318314e-001
4.000000e+003,3.797983e+002,4.527840e-004,-1.300740e-001
4.000000e+003,3.712313e+002,4.595844e-004,-1.253495e-001
4.000000e+003,3.636748e+002,4.645548e-004,-1.211075e-001
4.000000e+003,3.555170e+002,4.571319e-004,-1.189616e-001
4.000000e+003,3.476516e+002,1.745142e-004,-8.198857e-002
4.000000e+003,3.395964e+002,1.610861e-004,-7.565559e-002
4.000000e+003,3.314977e+002,1.613336e-004,-7.134989e-002
4.000000e+003,3.238059e+002,1.620109e-004,-6.988956e-002
4.000000e+003,3.156450e+002,1.632993e-004,-6.683962e-002
4.000000e+003,3.079069e+002,1.646181e-004,-6.393175e-002
4.000000e+003,3.000708e+002,1.661721e-004,-6.277230e-002
4.000000e+003,3.073220e+002,1.645341e-004,-6.744559e-002
4.000000e+003,3.152682e+002,1.630169e-004,-7.154761e-002
4.000000e+003,3.232814e+002,1.616992e-004,-7.517658e-002
4.000000e+003,3.312260e+002,1.606528e-004,-7.905801e-002
4.000000e+003,3.392714e+002,1.599212e-004,-8.306439e-002
4.000000e+003,3.472328e+002,1.595409e-004,-8.725435e-002
4.000000e+003,3.552351e+002,1.596733e-004,-9.095926e-002
4.000000e+003,3.632517e+002,1.604842e-004,-9.508553e-002
4.000000e+003,3.712449e+002,1.627059e-004,-9.934838e-002
4.000000e+003,3.792683e+002,2.887946e-004,-1.216917e-001
4.000000e+003,3.872665e+002,4.461079e-004,-1.421324e-001
4.000000e+003,3.952495e+002,4.403790e-004,-1.440470e-001
5.000000e+003,3.977602e+002,5.437345e-004,-1.412173e-001
5.000000e+003,3.894451e+002,5.523095e-004,-1.353825e-001
5.000000e+003,3.817986e+002,5.598369e-004,-1.308291e-001
5.000000e+003,3.733070e+002,5.676341e-004,-1.286641e-001
5.000000e+003,3.656522e+002,5.745639e-004,-1.243278e-001
5.000000e+003,3.575871e+002,5.783209e-004,-1.231927e-001
5.000000e+003,3.495749e+002,2.303374e-004,-9.135188e-002
5.000000e+003,3.417418e+002,1.970391e-004,-8.161891e-002
5.000000e+003,3.334539e+002,1.964633e-004,-7.773854e-002
5.000000e+003,3.258525e+002,1.972611e-004,-7.397605e-002
5.000000e+003,3.176309e+002,1.985866e-004,-7.291783e-002
5.000000e+003,3.097690e+002,2.002883e-004,-6.980259e-002
5.000000e+003,3.016854e+002,2.022892e-004,-6.835979e-002
5.000000e+003,3.053165e+002,2.011200e-004,-7.233018e-002
5.000000e+003,3.132786e+002,1.991333e-004,-7.592496e-002
5.000000e+003,3.214453e+002,1.973550e-004,-8.012633e-002
5.000000e+003,3.292281e+002,1.960775e-004,-8.423470e-002
5.000000e+003,3.372266e+002,1.951150e-004,-8.792880e-002
5.000000e+003,3.452552e+002,1.944936e-004,-9.185020e-002
5.000000e+003,3.532459e+002,1.945145e-004,-9.561406e-002
5.000000e+003,3.614409e+002,1.953443e-004,-1.001326e-001
5.000000e+003,3.692371e+002,1.974738e-004,-1.037167e-001
5.000000e+003,3.772697e+002,2.379084e-004,-1.096201e-001
5.000000e+003,3.852604e+002,5.545792e-004,-1.442102e-001
5.000000e+003,3.932227e+002,5.476099e-004,-1.462798e-001
6.000000e+003,4.000173e+002,6.460517e-004,-1.455341e-001
6.000000e+003,3.915372e+002,6.563956e-004,-1.387914e-001
6.000000e+003,3.836897e+002,6.658018e-004,-1.338162e-001
6.000000e+003,3.754411e+002,6.747185e-004,-1.320362e-001
6.000000e+003,3.675295e+002,6.837212e-004,-1.275465e-001
6.000000e+003,3.597425e+002,6.889027e-004,-1.261561e-001
6.000000e+003,3.513769e+002,3.374861e-004,-1.065331e-001
6.000000e+003,3.438307e+002,2.360139e-004,-8.599347e-002
6.000000e+003,3.355904e+002,2.314820e-004,-8.280282e-002
6.000000e+003,3.277599e+002,2.324523e-004,-7.923039e-002
6.000000e+003,3.196578e+002,2.337872e-004,-7.778677e-002
6.000000e+003,3.117649e+002,2.358321e-004,-7.503917e-002
6.000000e+003,3.036964e+002,2.379743e-004,-7.303990e-002
6.000000e+003,3.032607e+002,2.380068e-004,-7.556629e-002
6.000000e+003,3.112217e+002,2.354945e-004,-7.927230e-002
6.000000e+003,3.192343e+002,2.333802e-004,-8.356559e-002
6.000000e+003,3.272195e+002,2.316638e-004,-8.778369e-002
6.000000e+003,3.352796e+002,2.303638e-004,-9.138785e-002
6.000000e+003,3.432117e+002,2.295163e-004,-9.498499e-002
6.000000e+003,3.512578e+002,2.293442e-004,-9.954436e-002
6.000000e+003,3.592614e+002,2.301242e-004,-1.031412e-001
6.000000e+003,3.672627e+002,2.321517e-004,-1.069656e-001
6.000000e+003,3.752388e+002,2.410056e-004,-1.109594e-001
6.000000e+003,3.832284e+002,6.610165e-004,-1.455066e-001
6.000000e+003,3.912048e+002,6.554713e-004,-1.479945e-001
6.000000e+003,3.992098e+002,6.466412e-004,-1.501875e-001
7.000000e+003,3.935900e+002,7.592708e-004,-1.418177e-001
7.000000e+003,3.854081e+002,7.711751e-004,-1.365970e-001
7.000000e+003,3.776182e+002,7.808623e-004,-1.347661e-001
7.000000e+003,3.694437e+002,7.922407e-004,-1.300103e-001
7.000000e+003,3.618990e+002,7.997504e-004,-1.262964e-001
7.000000e+003,3.534318e+002,6.382974e-004,-1.169824e-001
7.000000e+003,3.457217e+002,2.783039e-004,-9.093679e-002
7.000000e+003,3.375544e+002,2.664246e-004,-8.729187e-002
7.000000e+003,3.296046e+002,2.673175e-004,-8.289623e-002
7.000000e+003,3.216653e+002,2.687018e-004,-8.170174e-002
7.000000e+003,3.137184e+002,2.709577e-004,-7.847495e-002
7.000000e+003,3.057400e+002,2.733851e-004,-7.710440e-002
7.000000e+003,3.012183e+002,2.747905e-004,-7.749175e-002
7.000000e+003,3.092388e+002,2.719366e-004,-8.169927e-002
7.000000e+003,3.172610e+002,2.693275e-004,-8.544508e-002
7.000000e+003,3.252704e+002,2.671935e-004,-8.989774e-002
7.000000e+003,3.332674e+002,2.655166e-004,-9.364355e-002
7.000000e+003,3.415035e+002,2.644978e-004,-9.743682e-002
7.000000e+003,3.492882e+002,2.640099e-004,-1.010344e-001
7.000000e+003,3.572581e+002,2.646410e-004,-1.049600e-001
7.000000e+003,3.652565e+002,2.665569e-004,-1.089592e-001
7.000000e+003,3.732926e+002,2.723176e-004,-1.132310e-001
7.000000e+003,3.815628e+002,7.308506e-004,-1.448778e-001
7.000000e+003,3.892576e+002,7.638166e-004,-1.484542e-001
7.000000e+003,3.972098e+002,7.537699e-004,-1.507096e-001
8.000000e+003,3.956492e+002,8.596546e-004,-1.441787e-001
8.000000e+003,3.875554e+002,8.729382e-004,-1.385933e-001
8.000000e+003,3.798246e+002,8.841144e-004,-1.368726e-001
8.000000e+003,3.711590e+002,8.977792e-004,-1.319413e-001
8.000000e+003,3.637761e+002,9.076750e-004,-1.277947e-001
8.000000e+003,3.555297e+002,9.001795e-004,-1.259450e-001
8.000000e+003,3.473319e+002,3.267285e-004,-9.572504e-002
8.000000e+003,3.396057e+002,3.015257e-004,-9.051789e-002
8.000000e+003,3.316423e+002,3.017642e-004,-8.672025e-002
8.000000e+003,3.238017e+002,3.031270e-004,-8.484150e-002
8.000000e+003,3.155798e+002,3.056822e-004,-8.174874e-002
8.000000e+003,3.078956e+002,3.082409e-004,-7.935122e-002
8.000000e+003,3.000637e+002,3.113905e-004,-7.793450e-002
8.000000e+003,3.072903e+002,3.080761e-004,-8.287255e-002
8.000000e+003,3.152189e+002,3.049765e-004,-8.667012e-002
8.000000e+003,3.232378e+002,3.024981e-004,-9.046625e-002
8.000000e+003,3.312632e+002,3.004895e-004,-9.502321e-002
8.000000e+003,3.392599e+002,2.990901e-004,-9.823839e-002
8.000000e+003,3.472932e+002,2.984362e-004,-1.023635e-001
8.000000e+003,3.552630e+002,2.988496e-004,-1.059477e-001
8.000000e+003,3.632146e+002,3.007238e-004,-1.100139e-001
8.000000e+003,3.712421e+002,3.054191e-004,-1.140489e-001
8.000000e+003,3.792829e+002,6.085648e-004,-1.339192e-001
8.000000e+003,3.872150e+002,8.711555e-004,-1.487719e-001
8.000000e+003,3.952875e+002,8.594415e-004,-1.511124e-001
9.000000e+003,3.977313e+002,9.611768e-004,-1.448797e-001
9.000000e+003,3.890982e+002,9.774677e-004,-1.388029e-001
9.000000e+003,3.817278e+002,9.904359e-004,-1.342908e-001
9.000000e+003,3.732282e+002,1.004540e-003,-1.327155e-001
9.000000e+003,3.653588e+002,1.017272e-003,-1.280470e-001
9.000000e+003,3.576127e+002,1.024057e-003,-1.272636e-001
9.000000e+003,3.494966e+002,4.076503e-004,-1.018394e-001
9.000000e+003,3.418914e+002,3.397723e-004,-9.072988e-002
9.000000e+003,3.334517e+002,3.371038e-004,-8.895501e-002
9.000000e+003,3.257807e+002,3.387093e-004,-8.506380e-002
9.000000e+003,3.176808e+002,3.408270e-004,-8.340254e-002
9.000000e+003,3.097747e+002,3.440300e-004,-8.035210e-002
9.000000e+003,3.017195e+002,3.473939e-004,-7.923466e-002
9.000000e+003,3.053495e+002,3.452836e-004,-8.287229e-002
9.000000e+003,3.132183e+002,3.418371e-004,-8.760097e-002
9.000000e+003,3.213407e+002,3.388711e-004,-9.181830e-002
9.000000e+003,3.292476e+002,3.365273e-004,-9.549826e-002
9.000000e+003,3.372629e+002,3.347546e-004,-9.941712e-002
9.000000e+003,3.452218e+002,3.337429e-004,-1.034357e-001
9.000000e+003,3.532710e+002,3.338832e-004,-1.067912e-001
9.000000e+003,3.614146e+002,3.355602e-004,-1.111715e-001
9.000000e+003,3.692151e+002,3.397405e-004,-1.145805e-001
9.000000e+003,3.772180e+002,4.477475e-004,-1.213621e-001
9.000000e+003,3.852425e+002,9.810363e-004,-1.487935e-001
9.000000e+003,3.932884e+002,9.681615e-004,-1.511518e-001
1.000000e+004,4.000173e+002,1.061377e-003,-1.494648e-001
1.000000e+004,3.914689e+002,1.078519e-003,-1.426703e-001
1.000000e+004,3.836927e+002,1.094334e-003,-1.375970e-001
1.000000e+004,3.754412e+002,1.109252e-003,-1.357080e-001
1.000000e+004,3.675568e+002,1.124362e-003,-1.309849e-001
1.000000e+004,3.597399e+002,1.133484e-003,-1.296422e-001
1.000000e+004,3.515381e+002,5.860908e-004,-1.144620e-001
1.000000e+004,3.438189e+002,3.806630e-004,-9.442185e-002
1.000000e+004,3.355971e+002,3.719822e-004,-9.189782e-002
1.000000e+004,3.277556e+002,3.734325e-004,-8.822278e-002
1.000000e+004,3.195685e+002,3.757597e-004,-8.664565e-002
1.000000e+004,3.117438e+002,3.790196e-004,-8.337575e-002
1.000000e+004,3.036528e+002,3.826751e-004,-8.208326e-002
1.000000e+004,3.033223e+002,3.824289e-004,-8.406639e-002
1.000000e+004,3.112562e+002,3.784709e-004,-8.846501e-002
1.000000e+004,3.192282e+002,3.750202e-004,-9.242567e-002
1.000000e+004,3.272173e+002,3.722028e-004,-9.587356e-002
1.000000e+004,3.352706e+002,3.699417e-004,-9.993026e-002
1.000000e+004,3.432541e+002,3.687089e-004,-1.039477e-001
1.000000e+004,3.512256e+002,3.686565e-004,-1.082594e-001
1.000000e+004,3.592224e+002,3.699887e-004,-1.119353e-001
1.000000e+004,3.672436e+002,3.736895e-004,-1.157849e-001
1.000000e+004,3.752332e+002,3.934644e-004,-1.190816e-001
1.000000e+004,3.832076e+002,1.090123e-003,-1.490136e-001
1.000000e+004,3.912545e+002,1.077123e-003,-1.515372e-001
1.000000e+004,3.992872e+002,1.062507e-003,-1.535679e-001
1.500000e+004,3.935492e+002,1.600897e-003,-1.458047e-001
1.500000e+004,3.856275e+002,1.625375e-003,-1.404370e-001
1.500000e+004,3.776182e+002,1.647238e-003,-1.386556e-001
1.500000e+004,3.694160e+002,1.671172e-003,-1.337585e-001
1.500000e+004,3.619070e+002,1.687661e-003,-1.300268e-001
1.500000e+004,3.533666e+002,1.374823e-003,-1.220059e-001
1.500000e+004,3.457433e+002,5.756328e-004,-1.011274e-001
1.500000e+004,3.374792e+002,5.465664e-004,-9.762543e-002
1.500000e+004,3.297280e+002,5.481638e-004,-9.338340e-002
1.500000e+004,3.217022e+002,5.511752e-004,-9.253693e-002
1.500000e+004,3.136268e+002,5.559616e-004,-8.901598e-002
1.500000e+004,3.057787e+002,5.608650e-004,-8.722256e-002
1.500000e+004,3.011951e+002,5.641216e-004,-8.747964e-002
1.500000e+004,3.092294e+002,5.577957e-004,-9.166599e-002
1.500000e+004,3.172051e+002,5.522991e-004,-9.598157e-002
1.500000e+004,3.252493e+002,5.480199e-004,-1.001266e-001
1.500000e+004,3.332497e+002,5.444589e-004,-1.037794e-001
1.500000e+004,3.414078e+002,5.422306e-004,-1.075880e-001
1.500000e+004,3.492588e+002,5.417399e-004,-1.113366e-001
1.500000e+004,3.572376e+002,5.430888e-004,-1.154604e-001
1.500000e+004,3.652000e+002,5.477095e-004,-1.192083e-001
1.500000e+004,3.732476e+002,5.611554e-004,-1.231965e-001
1.500000e+004,3.814715e+002,1.583246e-003,-1.494689e-001
1.500000e+004,3.892698e+002,1.611163e-003,-1.525086e-001
1.500000e+004,3.972066e+002,1.589584e-003,-1.546310e-001
2.000000e+004,3.955826e+002,2.120351e-003,-1.480772e-001
2.000000e+004,3.875464e+002,2.153301e-003,-1.425463e-001
2.000000e+004,3.798159e+002,2.181286e-003,-1.406830e-001
2.000000e+004,3.709200e+002,2.216093e-003,-1.354091e-001
2.000000e+004,3.636695e+002,2.240219e-003,-1.312811e-001
2.000000e+004,3.555044e+002,2.232866e-003,-1.297325e-001
2.000000e+004,3.476831e+002,8.018495e-004,-1.067276e-001
2.000000e+004,3.396194e+002,7.228327e-004,-1.008415e-001
2.000000e+004,3.316314e+002,7.228499e-004,-9.655860e-002
2.000000e+004,3.238476e+002,7.262987e-004,-9.559053e-002
2.000000e+004,3.156212e+002,7.322655e-004,-9.179027e-002
2.000000e+004,3.079031e+002,7.383229e-004,-8.942129e-002
2.000000e+004,4.000432e+002,2.103123e-003,-1.562207e-001
2.000000e+004,3.915062e+002,2.137935e-003,-1.484185e-001
2.000000e+004,3.837106e+002,2.169203e-003,-1.436457e-001
2.000000e+004,3.754241e+002,2.199112e-003,-1.429078e-001
2.000000e+004,3.675948e+002,2.229208e-003,-1.388106e-001
2.000000e+004,3.597347e+002,2.247098e-003,-1.379348e-001
2.000000e+004,3.514340e+002,1.115315e-003,-1.256681e-001
2.000000e+004,3.438213e+002,7.388239e-004,-1.082790e-001
2.000000e+004,3.354914e+002,7.214557e-004,-1.055663e-001
2.000000e+004,3.277684e+002,7.241863e-004,-1.021381e-001
2.000000e+004,3.196416e+002,7.289792e-004,-1.010384e-001
2.000000e+004,3.117303e+002,7.352868e-004,-9.754349e-002
2.000000e+004,3.037364e+002,7.425242e-004,-9.526643e-002
2.000000e+004,3.032426e+002,7.421294e-004,-9.805927e-002
2.000000e+004,3.112217e+002,7.342890e-004,-1.022960e-001
2.000000e+004,3.192080e+002,7.273965e-004,-1.061139e-001
2.000000e+004,3.272536e+002,7.220304e-004,-1.100510e-001
2.000000e+004,3.352415e+002,7.175714e-004,-1.129476e-001
2.000000e+004,3.432234e+002,7.155864e-004,-1.189307e-001
2.000000e+004,3.512157e+002,7.145932e-004,-1.204931e-001
2.000000e+004,3.592381e+002,7.177378e-004,-1.245826e-001
2.000000e+004,3.672735e+002,7.250816e-004,-1.274655e-001
2.000000e+004,3.752133e+002,7.633828e-004,-1.300042e-001
2.000000e+004,3.832284e+002,2.161625e-003,-1.565311e-001
2.000000e+004,3.912296e+002,2.135595e-003,-1.591596e-001
2.000000e+004,3.992872e+002,2.105589e-003,-1.609515e-001
2.500000e+004,3.935020e+002,2.657422e-003,-1.522899e-001
2.500000e+004,3.856848e+002,2.697696e-003,-1.471145e-001
2.500000e+004,3.776239e+002,2.733932e-003,-1.452978e-001
2.500000e+004,3.693336e+002,2.774455e-003,-1.398718e-001
2.500000e+004,3.618621e+002,2.802035e-003,-1.361803e-001
2.500000e+004,3.534418e+002,2.343785e-003,-1.288701e-001
2.500000e+004,3.457457e+002,9.472903e-004,-1.094812e-001
2.500000e+004,3.375680e+002,8.968493e-004,-1.045594e-001
2.500000e+004,3.297084e+002,8.996628e-004,-1.009940e-001
2.500000e+004,3.217063e+002,9.046696e-004,-9.933931e-002
2.500000e+004,3.136171e+002,9.128430e-004,-9.540371e-002
2.500000e+004,3.057916e+002,9.208041e-004,-9.335546e-002
2.500000e+004,3.012040e+002,9.260705e-004,-9.250136e-002
2.500000e+004,3.092766e+002,9.154825e-004,-9.705730e-002
2.500000e+004,3.172810e+002,9.072021e-004,-1.008719e-001
2.500000e+004,3.252115e+002,8.993236e-004,-1.068929e-001
2.500000e+004,3.332807e+002,8.935707e-004,-1.089298e-001
2.500000e+004,3.414405e+002,8.897985e-004,-1.126510e-001
2.500000e+004,3.492025e+002,8.889332e-004,-1.157304e-001
2.500000e+004,3.572402e+002,8.912356e-004,-1.194760e-001
2.500000e+004,3.652350e+002,8.992536e-004,-1.241391e-001
2.500000e+004,3.732589e+002,9.224289e-004,-1.270773e-001
2.500000e+004,3.815186e+002,2.649012e-003,-1.511055e-001
2.500000e+004,3.891870e+002,2.674357e-003,-1.540856e-001
2.500000e+004,3.972961e+002,2.638157e-003,-1.569170e-001
3.000000e+004,3.956174e+002,3.174008e-003,-1.488301e-001
3.000000e+004,3.876315e+002,3.222694e-003,-1.432384e-001
3.000000e+004,3.798538e+002,3.264904e-003,-1.409468e-001
3.000000e+004,3.712507e+002,3.315600e-003,-1.359942e-001
3.000000e+004,3.637548e+002,3.353386e-003,-1.318155e-001
3.000000e+004,3.554307e+002,3.347652e-003,-1.299943e-001
3.000000e+004,3.475596e+002,1.195748e-003,-1.082941e-001
3.000000e+004,3.396586e+002,1.075564e-003,-1.027687e-001
3.000000e+004,3.316665e+002,1.075164e-003,-9.878458e-002
3.000000e+004,3.238664e+002,1.080879e-003,-9.694926e-002
3.000000e+004,3.156903e+002,1.089368e-003,-9.338682e-002
3.000000e+004,3.079125e+002,1.099430e-003,-9.074771e-002
3.000000e+004,3.000690e+002,1.110566e-003,-9.033574e-002
3.000000e+004,3.072530e+002,1.098700e-003,-9.451880e-002
3.000000e+004,3.152346e+002,1.087609e-003,-9.862137e-002
3.000000e+004,3.232336e+002,1.077583e-003,-1.015873e-001
3.000000e+004,3.312478e+002,1.070636e-003,-1.063121e-001
3.000000e+004,3.392139e+002,1.065726e-003,-1.102448e-001
3.000000e+004,3.472715e+002,1.063667e-003,-1.138655e-001
3.000000e+004,3.553010e+002,1.065834e-003,-1.180331e-001
3.000000e+004,3.632279e+002,1.073176e-003,-1.212787e-001
3.000000e+004,3.712366e+002,1.093030e-003,-1.256858e-001
3.000000e+004,3.792771e+002,2.503108e-003,-1.426730e-001
3.000000e+004,3.872422e+002,3.217055e-003,-1.521150e-001
3.000000e+004,3.952242e+002,3.173189e-003,-1.545573e-001
3.500000e+004,3.977794e+002,3.685590e-003,-1.497593e-001
3.500000e+004,3.895097e+002,3.744129e-003,-1.436280e-001
3.500000e+004,3.817661e+002,3.797248e-003,-1.391535e-001
3.500000e+004,3.732816e+002,3.853125e-003,-1.367576e-001
3.500000e+004,3.656090e+002,3.901749e-003,-1.322799e-001
3.500000e+004,3.576000e+002,3.933472e-003,-1.307376e-001
3.500000e+004,3.494867e+002,1.530295e-003,-1.119676e-001
3.500000e+004,3.418633e+002,1.260696e-003,-1.034052e-001
3.500000e+004,3.336382e+002,1.251597e-003,-9.993939e-002
3.500000e+004,3.258250e+002,1.257019e-003,-9.602693e-002
3.500000e+004,3.176449e+002,1.266310e-003,-9.437636e-002
3.500000e+004,3.097860e+002,1.277736e-003,-9.113690e-002
3.500000e+004,3.016979e+002,1.291044e-003,-8.920003e-002
3.500000e+004,3.052650e+002,1.283471e-003,-9.353574e-002
3.500000e+004,3.132164e+002,1.269701e-003,-9.768498e-002
3.500000e+004,3.213755e+002,1.258295e-003,-1.010148e-001
3.500000e+004,3.292562e+002,1.249125e-003,-1.052203e-001
3.500000e+004,3.372697e+002,1.242658e-003,-1.093962e-001
3.500000e+004,3.452601e+002,1.239140e-003,-1.129685e-001
3.500000e+004,3.532409e+002,1.240145e-003,-1.167509e-001
3.500000e+004,3.614041e+002,1.247546e-003,-1.210881e-001
3.500000e+004,3.692178e+002,1.265055e-003,-1.248457e-001
3.500000e+004,3.772582e+002,1.861749e-003,-1.310185e-001
3.500000e+004,3.852155e+002,3.763502e-003,-1.512351e-001
3.500000e+004,3.932884e+002,3.712643e-003,-1.534536e-001
4.000000e+004,4.000011e+002,4.192652e-003,-1.506497e-001
4.000000e+004,3.915279e+002,4.258263e-003,-1.440953e-001
4.000000e+004,3.836182e+002,4.320782e-003,-1.393826e-001
4.000000e+004,3.755152e+002,4.381597e-003,-1.375180e-001
4.000000e+004,3.675786e+002,4.441101e-003,-1.327406e-001
4.000000e+004,3.597296e+002,4.481580e-003,-1.315380e-001
4.000000e+004,3.514389e+002,2.267271e-003,-1.201785e-001
4.000000e+004,3.438829e+002,1.465671e-003,-1.034700e-001
4.000000e+004,3.356624e+002,1.426913e-003,-1.011504e-001
4.000000e+004,3.277150e+002,1.432495e-003,-9.716107e-002
4.000000e+004,3.196517e+002,1.441640e-003,-9.585173e-002
4.000000e+004,3.117169e+002,1.454378e-003,-9.210840e-002
4.000000e+004,3.037181e+002,1.468478e-003,-9.057590e-002
4.000000e+004,3.032661e+002,1.467627e-003,-9.253849e-002
4.000000e+004,3.112504e+002,1.451806e-003,-9.701951e-002
4.000000e+004,3.192484e+002,1.438255e-003,-1.010583e-001
4.000000e+004,3.272707e+002,1.426864e-003,-1.049021e-001
4.000000e+004,3.352998e+002,1.418824e-003,-1.087773e-001
4.000000e+004,3.432117e+002,1.414568e-003,-1.128099e-001
4.000000e+004,3.512306e+002,1.413879e-003,-1.166481e-001
4.000000e+004,3.592095e+002,1.420248e-003,-1.205205e-001
4.000000e+004,3.672192e+002,1.436130e-003,-1.244211e-001
4.000000e+004,3.752019e+002,1.549257e-003,-1.262698e-001
4.000000e+004,3.832522e+002,4.308382e-003,-1.505598e-001
4.000000e+004,3.912792e+002,4.252234e-003,-1.530145e-001
4.000000e+004,3.991775e+002,4.194115e-003,-1.552240e-001
4.500000e+004,3.935429e+002,4.772570e-003,-1.455896e-001
4.500000e+004,3.856396e+002,4.845377e-003,-1.403682e-001
4.500000e+004,3.776066e+002,4.912163e-003,-1.386690e-001
4.500000e+004,3.694023e+002,4.983659e-003,-1.336491e-001
4.500000e+004,3.618911e+002,5.034444e-003,-1.299824e-001
4.500000e+004,3.534519e+002,4.241262e-003,-1.237293e-001
4.500000e+004,3.457121e+002,1.698361e-003,-1.055055e-001
4.500000e+004,3.375930e+002,1.605474e-003,-1.021936e-001
4.500000e+004,3.297258e+002,1.609968e-003,-9.839550e-002
4.500000e+004,3.216898e+002,1.618599e-003,-9.677717e-002
4.500000e+004,3.136735e+002,1.632874e-003,-9.335180e-002
4.500000e+004,3.058138e+002,1.646908e-003,-9.134349e-002
4.500000e+004,3.011951e+002,1.656558e-003,-9.140958e-002
4.500000e+004,3.092464e+002,1.637652e-003,-9.614067e-002
4.500000e+004,3.172769e+002,1.622330e-003,-1.003004e-001
4.500000e+004,3.252241e+002,1.608767e-003,-1.040579e-001
4.500000e+004,3.332630e+002,1.598659e-003,-1.082666e-001
4.500000e+004,3.413845e+002,1.592167e-003,-1.121986e-001
4.500000e+004,3.492368e+002,1.590486e-003,-1.159116e-001
4.500000e+004,3.572838e+002,1.595152e-003,-1.197678e-001
4.500000e+004,3.651946e+002,1.610213e-003,-1.235829e-001
4.500000e+004,3.732476e+002,1.656346e-003,-1.274555e-001
4.500000e+004,3.813951e+002,4.797466e-003,-1.494882e-001
4.500000e+004,3.892023e+002,4.801884e-003,-1.522622e-001
4.500000e+004,3.972705e+002,4.735347e-003,-1.545105e-001
5.000000e+004,3.957000e+002,5.283937e-003,-1.470047e-001
5.000000e+004,3.875950e+002,5.364577e-003,-1.413101e-001
5.000000e+004,3.797371e+002,5.439699e-003,-1.396824e-001
5.000000e+004,3.713119e+002,5.522189e-003,-1.346814e-001
5.000000e+004,3.637228e+002,5.584367e-003,-1.305172e-001
5.000000e+004,3.555246e+002,5.590326e-003,-1.289341e-001
5.000000e+004,3.476225e+002,1.999476e-003,-1.086721e-001
5.000000e+004,3.396102e+002,1.789341e-003,-1.035216e-001
5.000000e+004,3.316160e+002,1.787268e-003,-9.931425e-002
5.000000e+004,3.238059e+002,1.796894e-003,-9.780160e-002
5.000000e+004,3.156863e+002,1.810919e-003,-9.432749e-002
5.000000e+004,3.078619e+002,1.826570e-003,-9.210706e-002
5.000000e+004,3.000583e+002,1.845387e-003,-9.033418e-002
5.000000e+004,3.072624e+002,1.825028e-003,-9.529829e-002
5.000000e+004,3.152189e+002,1.807202e-003,-9.953506e-002
5.000000e+004,3.232648e+002,1.791633e-003,-1.034745e-001
5.000000e+004,3.312085e+002,1.779931e-003,-1.074391e-001
5.000000e+004,3.392322e+002,1.771409e-003,-1.112098e-001
5.000000e+004,3.473053e+002,1.767602e-003,-1.151815e-001
5.000000e+004,3.552807e+002,1.770683e-003,-1.188909e-001
5.000000e+004,3.632331e+002,1.784311e-003,-1.227993e-001
5.000000e+004,3.712283e+002,1.818981e-003,-1.266191e-001
5.000000e+004,3.792276e+002,4.401051e-003,-1.440201e-001
5.000000e+004,3.872453e+002,5.355636e-003,-1.514780e-001
5.000000e+004,3.952432e+002,5.282218e-003,-1.538970e-001
5.500000e+004,3.977730e+002,5.788375e-003,-1.480757e-001
5.500000e+004,3.895311e+002,5.879474e-003,-1.420916e-001
5.500000e+004,3.817867e+002,5.961525e-003,-1.375911e-001
5.500000e+004,3.733829e+002,6.051138e-003,-1.354045e-001
5.500000e+004,3.655740e+002,6.127356e-003,-1.309796e-001
5.500000e+004,3.574509e+002,6.182837e-003,-1.296331e-001
5.500000e+004,3.495553e+002,2.429105e-003,-1.118969e-001
5.500000e+004,3.418002e+002,1.980902e-003,-1.042485e-001
5.500000e+004,3.336026e+002,1.964139e-003,-1.001652e-001
5.500000e+004,3.258757e+002,1.972364e-003,-9.704413e-002
5.500000e+004,3.175728e+002,1.987810e-003,-9.509486e-002
5.500000e+004,3.098297e+002,2.004822e-003,-9.208249e-002
5.500000e+004,3.016424e+002,2.025839e-003,-9.017027e-002
5.500000e+004,3.052944e+002,2.012936e-003,-9.397581e-002
5.500000e+004,3.132028e+002,1.991330e-003,-9.815924e-002
5.500000e+004,3.214166e+002,1.974753e-003,-1.025614e-001
5.500000e+004,3.292822e+002,1.959668e-003,-1.065001e-001
5.500000e+004,3.372493e+002,1.950064e-003,-1.103787e-001
5.500000e+004,3.452457e+002,1.944599e-003,-1.142681e-001
5.500000e+004,3.532735e+002,1.947039e-003,-1.180897e-001
5.500000e+004,3.613646e+002,1.957132e-003,-1.221222e-001
5.500000e+004,3.692838e+002,1.987123e-003,-1.258419e-001
5.500000e+004,3.772783e+002,3.151766e-003,-1.328444e-001
5.500000e+004,3.852815e+002,5.909196e-003,-1.508899e-001
5.500000e+004,3.932916e+002,5.828897e-003,-1.531618e-001
6.000000e+004,4.000108e+002,6.283354e-003,-1.494464e-001
6.000000e+004,3.914968e+002,6.388608e-003,-1.431118e-001
6.000000e+004,3.837165e+002,6.481535e-003,-1.382381e-001
6.000000e+004,3.754839e+002,6.576670e-003,-1.363858e-001
6.000000e+004,3.675730e+002,6.665381e-003,-1.317311e-001
6.000000e+004,3.597242e+002,6.728511e-003,-1.304992e-001
6.000000e+004,3.516000e+002,3.568684e-003,-1.202956e-001
6.000000e+004,3.438734e+002,2.202778e-003,-1.036764e-001
6.000000e+004,3.355005e+002,2.141167e-003,-1.010705e-001
6.000000e+004,3.277577e+002,2.149189e-003,-9.741352e-002
6.000000e+004,3.196537e+002,2.163146e-003,-9.575444e-002
6.000000e+004,3.117284e+002,2.182286e-003,-9.237415e-002
6.000000e+004,3.037018e+002,2.203478e-003,-9.059867e-002
6.000000e+004,3.032842e+002,2.201648e-003,-9.281661e-002
6.000000e+004,3.112792e+002,2.177817e-003,-9.708130e-002
6.000000e+004,3.192080e+002,2.157986e-003,-1.012669e-001
6.000000e+004,3.272067e+002,2.141727e-003,-1.054828e-001
6.000000e+004,3.352886e+002,2.128844e-003,-1.090198e-001
6.000000e+004,3.432611e+002,2.122209e-003,-1.130919e-001
6.000000e+004,3.512133e+002,2.121435e-003,-1.170041e-001
6.000000e+004,3.592173e+002,2.130916e-003,-1.206154e-001
6.000000e+004,3.672599e+002,2.156756e-003,-1.244273e-001
6.000000e+004,3.752076e+002,2.371749e-003,-1.262703e-001
6.000000e+004,3.832135e+002,6.465894e-003,-1.496472e-001
6.000000e+004,3.912483e+002,6.380428e-003,-1.521948e-001
6.000000e+004,3.992581e+002,6.290519e-003,-1.544093e-001
6.500000e+004,3.934330e+002,6.893700e-003,-1.443109e-001
6.500000e+004,3.855583e+002,6.996970e-003,-1.391069e-001
6.500000e+004,3.776326e+002,7.096056e-003,-1.375817e-001
6.500000e+004,3.694877e+002,7.198518e-003,-1.327209e-001
6.500000e+004,3.618990e+002,7.273018e-003,-1.291194e-001
6.500000e+004,3.534970e+002,6.270747e-003,-1.233564e-001
6.500000e+004,3.457648e+002,2.462899e-003,-1.055968e-001
6.500000e+004,3.375565e+002,2.319623e-003,-1.023222e-001
6.500000e+004,3.297128e+002,2.326975e-003,-9.841862e-002
6.500000e+004,3.216918e+002,2.339439e-003,-9.696960e-002
6.500000e+004,3.136463e+002,2.359928e-003,-9.336272e-002
6.500000e+004,3.057861e+002,2.380566e-003,-9.174557e-002
6.500000e+004,3.012397e+002,2.393311e-003,-9.158981e-002
6.500000e+004,3.092426e+002,2.365271e-003,-9.642449e-002
6.500000e+004,3.172290e+002,2.343465e-003,-1.003792e-001
6.500000e+004,3.252451e+002,2.323942e-003,-1.044865e-001
6.500000e+004,3.332607e+002,2.310242e-003,-1.082698e-001
6.500000e+004,3.413473e+002,2.300756e-003,-1.125094e-001
6.500000e+004,3.492098e+002,2.298088e-003,-1.160760e-001
6.500000e+004,3.572941e+002,2.305391e-003,-1.199262e-001
6.500000e+004,3.652081e+002,2.326938e-003,-1.238703e-001
6.500000e+004,3.732195e+002,2.400186e-003,-1.273296e-001
6.500000e+004,3.813980e+002,6.969186e-003,-1.489910e-001
6.500000e+004,3.892637e+002,6.935226e-003,-1.515181e-001
6.500000e+004,3.971842e+002,6.838635e-003,-1.538004e-001
7.000000e+004,3.955667e+002,7.395728e-003,-1.457408e-001
7.000000e+004,3.875524e+002,7.507192e-003,-1.402623e-001
7.000000e+004,3.798100e+002,7.611281e-003,-1.386631e-001
7.000000e+004,3.713759e+002,7.728015e-003,-1.337985e-001
7.000000e+004,3.636775e+002,7.817117e-003,-1.295343e-001
7.000000e+004,3.555678e+002,7.841915e-003,-1.281837e-001
7.000000e+004,3.476540e+002,2.817558e-003,-1.085912e-001
7.000000e+004,3.395825e+002,2.505223e-003,-1.036065e-001
7.000000e+004,3.316006e+002,2.502105e-003,-9.947537e-002
7.000000e+004,3.237892e+002,2.514779e-003,-9.771231e-002
7.000000e+004,3.156034e+002,2.536830e-003,-9.459335e-002
7.000000e+004,3.078676e+002,2.556972e-003,-9.193808e-002
7.000000e+004,3.000601e+002,2.583832e-003,-9.041500e-002
7.000000e+004,3.073183e+002,2.555066e-003,-9.514001e-002
7.000000e+004,3.152445e+002,2.529352e-003,-9.986927e-002
7.000000e+004,3.232087e+002,2.508168e-003,-1.037761e-001
7.000000e+004,3.312785e+002,2.491675e-003,-1.076592e-001
7.000000e+004,3.392093e+002,2.480212e-003,-1.115727e-001
7.000000e+004,3.472183e+002,2.475316e-003,-1.155607e-001
7.000000e+004,3.552782e+002,2.480401e-003,-1.193775e-001
7.000000e+004,3.632066e+002,2.498252e-003,-1.231875e-001
7.000000e+004,3.712171e+002,2.549503e-003,-1.272257e-001
7.000000e+004,3.792334e+002,6.385675e-003,-1.449696e-001
7.000000e+004,3.872817e+002,7.492138e-003,-1.513982e-001
7.000000e+004,3.952971e+002,7.388774e-003,-1.537353e-001
7.000000e+004,3.999914e+002,7.326997e-003,-1.528697e-001