File: spin_crossover/dane/AOT — kopia/Big AOT/FeTrz_AOT_120nm_FC_FH.rso.csv
Field (Oe),Temperature (K),Long Moment (emu),Long Offset (cm)
1.000000e+003,2.999946e+002,4.678228e-005,-2.417562e-002
1.000000e+003,3.011040e+002,4.670864e-005,-2.311823e-002
1.000000e+003,3.021143e+002,4.668240e-005,-2.487972e-002
1.000000e+003,3.031428e+002,4.665743e-005,-2.559357e-002
1.000000e+003,3.041278e+002,4.659759e-005,-2.560181e-002
1.000000e+003,3.051160e+002,4.651779e-005,-2.540967e-002
1.000000e+003,3.061555e+002,4.648811e-005,-2.688852e-002
1.000000e+003,3.071319e+002,4.647645e-005,-2.671637e-002
1.000000e+003,3.081149e+002,4.637693e-005,-2.687442e-002
1.000000e+003,3.091840e+002,4.638059e-005,-2.721771e-002
1.000000e+003,3.101469e+002,4.635743e-005,-2.663973e-002
1.000000e+003,3.111431e+002,4.626761e-005,-2.799465e-002
1.000000e+003,3.121307e+002,4.623957e-005,-2.776279e-002
1.000000e+003,3.131212e+002,4.625190e-005,-3.068606e-002
1.000000e+003,3.141497e+002,4.620639e-005,-2.850885e-002
1.000000e+003,3.151539e+002,4.616688e-005,-2.872138e-002
1.000000e+003,3.160976e+002,4.606068e-005,-2.962886e-002
1.000000e+003,3.171312e+002,4.606231e-005,-2.989715e-002
1.000000e+003,3.181279e+002,4.604295e-005,-3.012513e-002
1.000000e+003,3.191433e+002,4.600673e-005,-2.981529e-002
1.000000e+003,3.201371e+002,4.597869e-005,-3.086953e-002
1.000000e+003,3.211377e+002,4.592746e-005,-3.068709e-002
1.000000e+003,3.221325e+002,4.588937e-005,-3.142001e-002
1.000000e+003,3.231048e+002,4.590020e-005,-3.077646e-002
1.000000e+003,3.241503e+002,4.581858e-005,-3.159927e-002
1.000000e+003,3.251104e+002,4.582753e-005,-3.356450e-002
1.000000e+003,3.261063e+002,4.581160e-005,-3.450010e-002
1.000000e+003,3.271342e+002,4.575474e-005,-3.511503e-002
1.000000e+003,3.281025e+002,4.575633e-005,-3.505942e-002
1.000000e+003,3.291028e+002,4.569926e-005,-3.514631e-002
1.000000e+003,3.301292e+002,4.567785e-005,-3.533528e-002
1.000000e+003,3.311144e+002,4.564744e-005,-3.570967e-002
1.000000e+003,3.320926e+002,4.567624e-005,-3.565697e-002
1.000000e+003,3.331610e+002,4.561970e-005,-3.695447e-002
1.000000e+003,3.341476e+002,4.560760e-005,-3.610682e-002
1.000000e+003,3.351068e+002,4.556443e-005,-3.707651e-002
1.000000e+003,3.361416e+002,4.555091e-005,-3.692614e-002
1.000000e+003,3.370993e+002,4.551606e-005,-3.794514e-002
1.000000e+003,3.381085e+002,4.548870e-005,-3.818588e-002
1.000000e+003,3.391517e+002,4.545130e-005,-3.741353e-002
1.000000e+003,3.401207e+002,4.545465e-005,-3.861481e-002
1.000000e+003,3.411398e+002,4.545445e-005,-3.969255e-002
1.000000e+003,3.421489e+002,4.543253e-005,-3.928735e-002
1.000000e+003,3.431196e+002,4.541376e-005,-4.032572e-002
1.000000e+003,3.441294e+002,4.540205e-005,-3.976735e-002
1.000000e+003,3.451501e+002,4.541808e-005,-3.938702e-002
1.000000e+003,3.461269e+002,4.534464e-005,-4.079977e-002
1.000000e+003,3.471457e+002,4.533206e-005,-4.021553e-002
1.000000e+003,3.481101e+002,4.539229e-005,-4.141638e-002
1.000000e+003,3.491217e+002,4.534350e-005,-4.118650e-002
1.000000e+003,3.501248e+002,4.533349e-005,-4.288492e-002
1.000000e+003,3.510944e+002,4.528845e-005,-4.338142e-002
1.000000e+003,3.521543e+002,4.530079e-005,-4.322013e-002
1.000000e+003,3.531307e+002,4.530177e-005,-4.397247e-002
1.000000e+003,3.541632e+002,4.528690e-005,-4.358926e-002
1.000000e+003,3.551337e+002,4.528603e-005,-4.423274e-002
1.000000e+003,3.561097e+002,4.530959e-005,-4.464807e-002
1.000000e+003,3.571093e+002,4.533357e-005,-4.422803e-002
1.000000e+003,3.580994e+002,4.532871e-005,-4.483494e-002
1.000000e+003,3.591549e+002,4.533720e-005,-4.479701e-002
1.000000e+003,3.601256e+002,4.534805e-005,-4.524974e-002
1.000000e+003,3.611282e+002,4.537289e-005,-4.596968e-002
1.000000e+003,3.621313e+002,4.538358e-005,-4.683439e-002
1.000000e+003,3.631189e+002,4.536698e-005,-4.635542e-002
1.000000e+003,3.641122e+002,4.538835e-005,-4.635343e-002
1.000000e+003,3.651381e+002,4.536555e-005,-4.574726e-002
1.000000e+003,3.661242e+002,4.544309e-005,-4.709705e-002
1.000000e+003,3.671403e+002,4.547303e-005,-4.769950e-002
1.000000e+003,3.681158e+002,4.545555e-005,-4.653989e-002
1.000000e+003,3.691271e+002,4.548241e-005,-4.849874e-002
1.000000e+003,3.701524e+002,4.549853e-005,-4.765188e-002
1.000000e+003,3.711115e+002,4.552780e-005,-4.983887e-002
1.000000e+003,3.721595e+002,4.557519e-005,-4.876599e-002
1.000000e+003,3.731183e+002,4.565698e-005,-4.982456e-002
1.000000e+003,3.741160e+002,4.564322e-005,-5.051846e-002
1.000000e+003,3.751422e+002,4.569730e-005,-5.041422e-002
1.000000e+003,3.761285e+002,4.576585e-005,-5.038652e-002
1.000000e+003,3.771604e+002,4.580553e-005,-5.149042e-002
1.000000e+003,3.781288e+002,4.583473e-005,-5.181167e-002
1.000000e+003,3.791055e+002,4.593212e-005,-5.217936e-002
1.000000e+003,3.801194e+002,4.599011e-005,-5.223749e-002
1.000000e+003,3.811157e+002,4.603965e-005,-5.134996e-002
1.000000e+003,3.821409e+002,4.612484e-005,-5.416709e-002
1.000000e+003,3.831333e+002,4.623170e-005,-5.334525e-002
1.000000e+003,3.841610e+002,4.630497e-005,-5.387941e-002
1.000000e+003,3.851403e+002,4.642433e-005,-5.410990e-002
1.000000e+003,3.861218e+002,4.644583e-005,-5.475460e-002
1.000000e+003,3.871268e+002,4.659846e-005,-5.542612e-002
1.000000e+003,3.881342e+002,4.673215e-005,-5.585047e-002
1.000000e+003,3.843881e+002,4.680767e-005,-5.159894e-002
1.000000e+003,3.862185e+002,4.689448e-005,-5.166567e-002
1.000000e+003,3.872332e+002,4.694618e-005,-5.296973e-002
1.000000e+003,3.881555e+002,4.702978e-005,-5.276292e-002
1.000000e+003,3.891685e+002,4.712100e-005,-5.418532e-002
1.000000e+003,3.901315e+002,4.723327e-005,-5.417303e-002
1.000000e+003,3.911117e+002,4.740176e-005,-5.480686e-002
1.000000e+003,3.921159e+002,4.762467e-005,-5.599217e-002
1.000000e+003,3.931066e+002,4.790799e-005,-5.636448e-002
1.000000e+003,3.940931e+002,4.838259e-005,-5.724007e-002
1.000000e+003,3.951260e+002,4.994862e-005,-6.058597e-002
1.000000e+003,3.961321e+002,5.790445e-005,-7.271333e-002
1.000000e+003,3.971171e+002,8.068031e-005,-9.785937e-002
1.000000e+003,3.982188e+002,1.078799e-004,-1.168418e-001
1.000000e+003,3.991195e+002,1.129912e-004,-1.196222e-001
1.000000e+003,4.000626e+002,1.153910e-004,-1.195435e-001
1.000000e+003,4.000076e+002,1.160009e-004,-1.187829e-001
1.000000e+003,3.988264e+002,1.162428e-004,-1.180762e-001
1.000000e+003,3.977729e+002,1.164688e-004,-1.169373e-001
1.000000e+003,3.967724e+002,1.166614e-004,-1.166491e-001
1.000000e+003,3.957539e+002,1.168761e-004,-1.155101e-001
1.000000e+003,3.946483e+002,1.170923e-004,-1.146545e-001
1.000000e+003,3.937155e+002,1.172363e-004,-1.145490e-001
1.000000e+003,3.926841e+002,1.174479e-004,-1.133033e-001
1.000000e+003,3.917827e+002,1.175700e-004,-1.130301e-001
1.000000e+003,3.908175e+002,1.177847e-004,-1.125381e-001
1.000000e+003,3.898849e+002,1.178851e-004,-1.119923e-001
1.000000e+003,3.889324e+002,1.180013e-004,-1.125174e-001
1.000000e+003,3.878841e+002,1.182051e-004,-1.118423e-001
1.000000e+003,3.868599e+002,1.184125e-004,-1.113054e-001
1.000000e+003,3.857721e+002,1.186086e-004,-1.106695e-001
1.000000e+003,3.848402e+002,1.188185e-004,-1.102487e-001
1.000000e+003,3.838356e+002,1.189690e-004,-1.093463e-001
1.000000e+003,3.828602e+002,1.191300e-004,-1.091900e-001
1.000000e+003,3.818958e+002,1.192964e-004,-1.089803e-001
1.000000e+003,3.809131e+002,1.194389e-004,-1.085423e-001
1.000000e+003,3.798771e+002,1.195885e-004,-1.083812e-001
1.000000e+003,3.788557e+002,1.197860e-004,-1.080524e-001
1.000000e+003,3.778603e+002,1.199253e-004,-1.075068e-001
1.000000e+003,3.768674e+002,1.200542e-004,-1.073361e-001
1.000000e+003,3.758799e+002,1.201537e-004,-1.066723e-001
1.000000e+003,3.748666e+002,1.203188e-004,-1.063788e-001
1.000000e+003,3.738844e+002,1.204653e-004,-1.063426e-001
1.000000e+003,3.728907e+002,1.205685e-004,-1.059374e-001
1.000000e+003,3.718719e+002,1.206936e-004,-1.052990e-001
1.000000e+003,3.708726e+002,1.208203e-004,-1.052888e-001
1.000000e+003,3.698569e+002,1.209097e-004,-1.046598e-001
1.000000e+003,3.688771e+002,1.209982e-004,-1.043207e-001
1.000000e+003,3.678919e+002,1.210349e-004,-1.040742e-001
1.000000e+003,3.668768e+002,1.211498e-004,-1.031890e-001
1.000000e+003,3.659028e+002,1.211199e-004,-1.028841e-001
1.000000e+003,3.648858e+002,1.211022e-004,-1.025267e-001
1.000000e+003,3.638640e+002,1.210938e-004,-1.024674e-001
1.000000e+003,3.628801e+002,1.209415e-004,-1.020970e-001
1.000000e+003,3.618674e+002,1.207094e-004,-1.015170e-001
1.000000e+003,3.608999e+002,1.203751e-004,-1.012009e-001
1.000000e+003,3.598727e+002,1.190038e-004,-9.958057e-002
1.000000e+003,3.588878e+002,1.098991e-004,-9.431884e-002
1.000000e+003,3.578520e+002,9.422391e-005,-8.594094e-002
1.000000e+003,3.568659e+002,7.923759e-005,-7.659937e-002
1.000000e+003,3.558651e+002,6.680307e-005,-6.262733e-002
1.000000e+003,3.548804e+002,5.903460e-005,-4.977476e-002
1.000000e+003,3.538912e+002,5.435268e-005,-4.297445e-002
1.000000e+003,3.528829e+002,5.154783e-005,-3.856093e-002
1.000000e+003,3.518433e+002,4.975562e-005,-3.551317e-002
1.000000e+003,3.508645e+002,4.873136e-005,-3.345505e-002
1.000000e+003,3.498741e+002,4.817716e-005,-3.200365e-002
1.000000e+003,3.488726e+002,4.784923e-005,-3.128021e-002
1.000000e+003,3.478770e+002,4.763301e-005,-3.020803e-002
1.000000e+003,3.468609e+002,4.748834e-005,-2.934707e-002
1.000000e+003,3.458750e+002,4.740002e-005,-2.896444e-002
1.000000e+003,3.448878e+002,4.734249e-005,-2.849437e-002
1.000000e+003,3.438616e+002,4.734112e-005,-2.741371e-002
1.000000e+003,3.428723e+002,4.730850e-005,-2.732624e-002
1.000000e+003,3.418726e+002,4.733515e-005,-2.673717e-002
1.000000e+003,3.408838e+002,4.730664e-005,-2.740799e-002
1.000000e+003,3.398825e+002,4.734422e-005,-2.626446e-002
1.000000e+003,3.388736e+002,4.732041e-005,-2.626724e-002
1.000000e+003,3.378893e+002,4.734450e-005,-2.569395e-002
1.000000e+003,3.368678e+002,4.737320e-005,-2.639982e-002
1.000000e+003,3.358958e+002,4.739291e-005,-2.563550e-002
1.000000e+003,3.348692e+002,4.741637e-005,-2.519252e-002
1.000000e+003,3.338737e+002,4.741500e-005,-2.477641e-002
1.000000e+003,3.328644e+002,4.743863e-005,-2.413830e-002
1.000000e+003,3.318771e+002,4.749096e-005,-2.512628e-002
1.000000e+003,3.308610e+002,4.750858e-005,-2.391418e-002
1.000000e+003,3.298384e+002,4.752997e-005,-2.397498e-002
1.000000e+003,3.288635e+002,4.756219e-005,-2.320075e-002
1.000000e+003,3.278754e+002,4.757126e-005,-2.294226e-002
1.000000e+003,3.268681e+002,4.762871e-005,-2.331221e-002
1.000000e+003,3.258672e+002,4.763345e-005,-2.274629e-002
1.000000e+003,3.248751e+002,4.766263e-005,-2.171056e-002
1.000000e+003,3.238685e+002,4.766733e-005,-2.262997e-002
1.000000e+003,3.228953e+002,4.771904e-005,-2.202513e-002
1.000000e+003,3.218729e+002,4.778659e-005,-2.148884e-002
1.000000e+003,3.208675e+002,4.782285e-005,-2.208755e-002
1.000000e+003,3.198871e+002,4.780548e-005,-2.100803e-002
1.000000e+003,3.188767e+002,4.781551e-005,-2.197963e-002
1.000000e+003,3.178530e+002,4.790751e-005,-2.005154e-002
1.000000e+003,3.168542e+002,4.792793e-005,-2.040525e-002
1.000000e+003,3.158660e+002,4.795815e-005,-2.028451e-002
1.000000e+003,3.148767e+002,4.803283e-005,-1.987097e-002
1.000000e+003,3.138567e+002,4.808217e-005,-2.077736e-002
1.000000e+003,3.128535e+002,4.809886e-005,-1.978043e-002
1.000000e+003,3.118630e+002,4.812267e-005,-1.912864e-002
1.000000e+003,3.108714e+002,4.817214e-005,-1.972941e-002
1.000000e+003,3.098904e+002,4.822451e-005,-1.953625e-002
1.000000e+003,3.088764e+002,4.829367e-005,-1.861600e-002
1.000000e+003,3.078807e+002,4.832075e-005,-1.790757e-002
1.000000e+003,3.068825e+002,4.832853e-005,-1.802503e-002
1.000000e+003,3.058598e+002,4.840477e-005,-1.839251e-002
1.000000e+003,3.048903e+002,4.838871e-005,-1.720283e-002
1.000000e+003,3.038691e+002,4.848260e-005,-1.682341e-002
1.000000e+003,3.028805e+002,4.852958e-005,-1.817808e-002
1.000000e+003,3.018683e+002,4.857012e-005,-1.705655e-002
1.000000e+003,3.008615e+002,4.865345e-005,-1.712049e-002
1.000000e+003,3.000070e+002,4.868566e-005,-1.741220e-002
1.000000e+003,3.000087e+002,4.863651e-005,-1.750396e-002
1.000000e+003,3.011308e+002,4.858584e-005,-1.816665e-002
1.000000e+003,3.021485e+002,4.851982e-005,-1.949562e-002
1.000000e+003,3.031718e+002,4.849574e-005,-1.991369e-002
1.000000e+003,3.041114e+002,4.844174e-005,-2.020546e-002
1.000000e+003,3.051031e+002,4.840899e-005,-2.099301e-002
1.000000e+003,3.061315e+002,4.833852e-005,-2.162603e-002
1.000000e+003,3.071188e+002,4.826917e-005,-2.123052e-002
1.000000e+003,3.081299e+002,4.824760e-005,-2.156744e-002
1.000000e+003,3.091179e+002,4.819768e-005,-2.288493e-002
1.000000e+003,3.101241e+002,4.816651e-005,-2.257311e-002
1.000000e+003,3.111335e+002,4.810538e-005,-2.298703e-002
1.000000e+003,3.121442e+002,4.804266e-005,-2.370853e-002
1.000000e+003,3.131096e+002,4.803232e-005,-2.461140e-002
1.000000e+003,3.140988e+002,4.795764e-005,-2.486346e-002
1.000000e+003,3.151263e+002,4.794457e-005,-2.486435e-002
1.000000e+003,3.161215e+002,4.790485e-005,-2.554743e-002
1.000000e+003,3.171531e+002,4.781601e-005,-2.518897e-002
1.000000e+003,3.181339e+002,4.781546e-005,-2.567345e-002
1.000000e+003,3.191615e+002,4.777026e-005,-2.548078e-002
1.000000e+003,3.201147e+002,4.773911e-005,-2.654087e-002
1.000000e+003,3.211213e+002,4.770045e-005,-2.733007e-002
1.000000e+003,3.221469e+002,4.761951e-005,-2.734803e-002
1.000000e+003,3.231318e+002,4.761531e-005,-2.839955e-002
1.000000e+003,3.241482e+002,4.760998e-005,-2.879369e-002
1.000000e+003,3.251336e+002,4.751120e-005,-2.857775e-002
1.000000e+003,3.261253e+002,4.747864e-005,-2.932823e-002
1.000000e+003,3.271256e+002,4.743564e-005,-2.973103e-002
1.000000e+003,3.281175e+002,4.742711e-005,-2.971190e-002
1.000000e+003,3.291374e+002,4.736911e-005,-2.950929e-002
1.000000e+003,3.301271e+002,4.736487e-005,-3.065629e-002
1.000000e+003,3.311384e+002,4.732580e-005,-3.158534e-002
1.000000e+003,3.321255e+002,4.725824e-005,-3.192164e-002
1.000000e+003,3.331676e+002,4.724388e-005,-3.263985e-002
1.000000e+003,3.341097e+002,4.724854e-005,-3.233815e-002
1.000000e+003,3.351337e+002,4.722825e-005,-3.291816e-002
1.000000e+003,3.361461e+002,4.718226e-005,-3.326172e-002
1.000000e+003,3.371334e+002,4.714290e-005,-3.375549e-002
1.000000e+003,3.381496e+002,4.715116e-005,-3.369612e-002
1.000000e+003,3.391310e+002,4.713621e-005,-3.449730e-002
1.000000e+003,3.401254e+002,4.706944e-005,-3.532072e-002
1.000000e+003,3.411328e+002,4.705931e-005,-3.471963e-002
1.000000e+003,3.421302e+002,4.705481e-005,-3.644753e-002
1.000000e+003,3.431526e+002,4.699649e-005,-3.555457e-002
1.000000e+003,3.441389e+002,4.697574e-005,-3.621370e-002
1.000000e+003,3.451168e+002,4.697838e-005,-3.653806e-002
1.000000e+003,3.461437e+002,4.695579e-005,-3.672463e-002
1.000000e+003,3.471143e+002,4.697337e-005,-3.813953e-002
1.000000e+003,3.481028e+002,4.695333e-005,-3.890822e-002
1.000000e+003,3.491218e+002,4.691225e-005,-3.879209e-002
1.000000e+003,3.501346e+002,4.694997e-005,-3.944740e-002
1.000000e+003,3.511142e+002,4.693268e-005,-3.928230e-002
1.000000e+003,3.521293e+002,4.691087e-005,-3.922576e-002
1.000000e+003,3.531181e+002,4.689382e-005,-4.013326e-002
1.000000e+003,3.541305e+002,4.689627e-005,-4.070482e-002
1.000000e+003,3.551336e+002,4.693797e-005,-4.130947e-002
1.000000e+003,3.561505e+002,4.692918e-005,-4.149597e-002
1.000000e+003,3.571196e+002,4.689433e-005,-4.112441e-002
1.000000e+003,3.581252e+002,4.692910e-005,-4.238874e-002
1.000000e+003,3.591264e+002,4.694336e-005,-4.234266e-002
1.000000e+003,3.601178e+002,4.691507e-005,-4.257745e-002
1.000000e+003,3.611045e+002,4.690023e-005,-4.428766e-002
1.000000e+003,3.621470e+002,4.690909e-005,-4.352523e-002
1.000000e+003,3.631401e+002,4.694582e-005,-4.345038e-002
1.000000e+003,3.641336e+002,4.696963e-005,-4.504646e-002
1.000000e+003,3.651354e+002,4.695918e-005,-4.560484e-002
1.000000e+003,3.661647e+002,4.698016e-005,-4.598570e-002
1.000000e+003,3.671104e+002,4.705013e-005,-4.542083e-002
1.000000e+003,3.681240e+002,4.706495e-005,-4.633397e-002
1.000000e+003,3.691133e+002,4.705193e-005,-4.656900e-002
1.000000e+003,3.701192e+002,4.712668e-005,-4.725622e-002
1.000000e+003,3.711309e+002,4.712956e-005,-4.852257e-002
1.000000e+003,3.721568e+002,4.719396e-005,-4.787958e-002
1.000000e+003,3.731126e+002,4.722657e-005,-4.813932e-002
1.000000e+003,3.741330e+002,4.725531e-005,-4.923188e-002
1.000000e+003,3.751194e+002,4.736474e-005,-4.915108e-002
1.000000e+003,3.761456e+002,4.735707e-005,-4.935294e-002
1.000000e+003,3.771374e+002,4.747895e-005,-4.977399e-002
1.000000e+003,3.781028e+002,4.755401e-005,-5.070325e-002
1.000000e+003,3.791258e+002,4.762576e-005,-5.156589e-002
1.000000e+003,3.801136e+002,4.772222e-005,-5.168386e-002
1.000000e+003,3.811127e+002,4.784539e-005,-5.214463e-002
1.000000e+003,3.821439e+002,4.796216e-005,-5.306799e-002
1.000000e+003,3.831303e+002,4.816141e-005,-5.314821e-002
1.000000e+003,3.841520e+002,4.849558e-005,-5.448824e-002
1.000000e+003,3.851103e+002,4.942380e-005,-5.434230e-002
1.000000e+003,3.861128e+002,5.196829e-005,-5.901572e-002
1.000000e+003,3.871328e+002,5.782489e-005,-6.706879e-002
1.000000e+003,3.881220e+002,6.879908e-005,-8.185523e-002
1.000000e+003,3.891194e+002,8.627374e-005,-9.851612e-002
1.000000e+003,3.901500e+002,1.068560e-004,-1.132174e-001
1.000000e+003,3.911241e+002,1.162705e-004,-1.188135e-001
1.000000e+003,3.921284e+002,1.168643e-004,-1.191614e-001
1.000000e+003,3.931097e+002,1.169358e-004,-1.196638e-001
1.000000e+003,3.941183e+002,1.168111e-004,-1.196768e-001
1.000000e+003,3.951450e+002,1.167377e-004,-1.197725e-001
1.000000e+003,3.960907e+002,1.166739e-004,-1.200767e-001
1.000000e+003,3.971522e+002,1.165843e-004,-1.199581e-001
1.000000e+003,3.981321e+002,1.164714e-004,-1.205297e-001
1.000000e+003,3.991582e+002,1.163505e-004,-1.201389e-001
1.000000e+003,3.999816e+002,1.164868e-004,-1.192510e-001
1.000000e+003,4.000011e+002,1.166539e-004,-1.181281e-001
1.000000e+003,3.988329e+002,1.168269e-004,-1.170645e-001
1.000000e+003,3.978211e+002,1.170542e-004,-1.159141e-001
1.000000e+003,3.967181e+002,1.172604e-004,-1.150578e-001
1.000000e+003,3.957063e+002,1.174653e-004,-1.147155e-001
1.000000e+003,3.947178e+002,1.176558e-004,-1.140771e-001
1.000000e+003,3.937438e+002,1.178706e-004,-1.131709e-001
1.000000e+003,3.927685e+002,1.180285e-004,-1.126746e-001
1.000000e+003,3.917827e+002,1.182176e-004,-1.123475e-001
1.000000e+003,3.908051e+002,1.183748e-004,-1.116719e-001
1.000000e+003,3.898541e+002,1.185302e-004,-1.110615e-001
1.000000e+003,3.889538e+002,1.186308e-004,-1.115467e-001
1.000000e+003,3.878933e+002,1.188827e-004,-1.114402e-001
1.000000e+003,3.868478e+002,1.190420e-004,-1.107030e-001
1.000000e+003,3.857841e+002,1.192528e-004,-1.104059e-001
1.000000e+003,3.848312e+002,1.194435e-004,-1.102134e-001
1.000000e+003,3.838446e+002,1.196111e-004,-1.092658e-001
1.000000e+003,3.828721e+002,1.197373e-004,-1.092906e-001
1.000000e+003,3.818988e+002,1.199324e-004,-1.088068e-001
1.000000e+003,3.808837e+002,1.201078e-004,-1.081590e-001
1.000000e+003,3.798917e+002,1.202762e-004,-1.082856e-001
1.000000e+003,3.788673e+002,1.204304e-004,-1.076898e-001
1.000000e+003,3.778631e+002,1.206270e-004,-1.073875e-001
1.000000e+003,3.768760e+002,1.207613e-004,-1.065135e-001
1.000000e+003,3.758885e+002,1.209594e-004,-1.065391e-001
1.000000e+003,3.748922e+002,1.211022e-004,-1.058070e-001
1.000000e+003,3.738957e+002,1.212880e-004,-1.060259e-001
1.000000e+003,3.728851e+002,1.214182e-004,-1.054611e-001
1.000000e+003,3.718802e+002,1.215710e-004,-1.050182e-001
1.000000e+003,3.708587e+002,1.216784e-004,-1.046513e-001
1.000000e+003,3.698652e+002,1.218136e-004,-1.043125e-001
1.000000e+003,3.688936e+002,1.219270e-004,-1.037165e-001
1.000000e+003,3.678947e+002,1.220367e-004,-1.035646e-001
1.000000e+003,3.668606e+002,1.221603e-004,-1.031098e-001
1.000000e+003,3.659055e+002,1.222276e-004,-1.026522e-001
1.000000e+003,3.648858e+002,1.223046e-004,-1.022717e-001
1.000000e+003,3.638640e+002,1.223378e-004,-1.020107e-001
1.000000e+003,3.628721e+002,1.223538e-004,-1.018436e-001
1.000000e+003,3.618885e+002,1.223558e-004,-1.013936e-001
1.000000e+003,3.608710e+002,1.222842e-004,-1.008979e-001
1.000000e+003,3.598571e+002,1.221301e-004,-1.001390e-001
1.000000e+003,3.588619e+002,1.216367e-004,-9.954385e-002
1.000000e+003,3.578726e+002,1.158244e-004,-9.567782e-002
1.000000e+003,3.568531e+002,1.001999e-004,-8.844243e-002
1.000000e+003,3.558855e+002,8.520311e-005,-7.904729e-002
1.000000e+003,3.548702e+002,7.290530e-005,-6.824267e-002
1.000000e+003,3.538636e+002,6.387410e-005,-5.622424e-002
1.000000e+003,3.528879e+002,5.739681e-005,-4.624230e-002
1.000000e+003,3.518483e+002,5.362528e-005,-4.169812e-002
1.000000e+003,3.508669e+002,5.177401e-005,-3.787519e-002
1.000000e+003,3.498765e+002,5.032308e-005,-3.629447e-002
1.000000e+003,3.488482e+002,4.939326e-005,-3.282066e-002
1.000000e+003,3.478915e+002,4.886599e-005,-3.232318e-002
1.000000e+003,3.468826e+002,4.854417e-005,-3.136530e-002
1.000000e+003,3.458486e+002,4.831002e-005,-2.997263e-002
1.000000e+003,3.448854e+002,4.814707e-005,-2.944785e-002
1.000000e+003,3.438686e+002,4.804014e-005,-2.835158e-002
1.000000e+003,3.428582e+002,4.795409e-005,-2.814855e-002
1.000000e+003,3.418961e+002,4.795445e-005,-2.769960e-002
1.000000e+003,3.408513e+002,4.795982e-005,-2.749000e-002
1.000000e+003,3.398894e+002,4.792154e-005,-2.756893e-002
1.000000e+003,3.388782e+002,4.793063e-005,-2.693585e-002
1.000000e+003,3.378665e+002,4.796004e-005,-2.646547e-002
1.000000e+003,3.369019e+002,4.797910e-005,-2.597990e-002
1.000000e+003,3.358636e+002,4.797544e-005,-2.572981e-002
1.000000e+003,3.348715e+002,4.801712e-005,-2.679687e-002
1.000000e+003,3.338581e+002,4.801149e-005,-2.502036e-002
1.000000e+003,3.328755e+002,4.799858e-005,-2.498286e-002
1.000000e+003,3.318419e+002,4.802510e-005,-2.449324e-002
1.000000e+003,3.308632e+002,4.808894e-005,-2.511398e-002
1.000000e+003,3.298796e+002,4.808506e-005,-2.496775e-002
1.000000e+003,3.288527e+002,4.817416e-005,-2.433049e-002
1.000000e+003,3.278840e+002,4.814819e-005,-2.360152e-002
1.000000e+003,3.268872e+002,4.812672e-005,-2.362141e-002
1.000000e+003,3.258757e+002,4.825975e-005,-2.337352e-002
1.000000e+003,3.248709e+002,4.827118e-005,-2.263581e-002
1.000000e+003,3.238664e+002,4.828939e-005,-2.320891e-002
1.000000e+003,3.228601e+002,4.834554e-005,-2.331596e-002
1.000000e+003,3.218502e+002,4.835454e-005,-2.249557e-002
1.000000e+003,3.208777e+002,4.840736e-005,-2.179091e-002
1.000000e+003,3.198850e+002,4.845065e-005,-2.215125e-002
1.000000e+003,3.188585e+002,4.851108e-005,-2.128890e-002
1.000000e+003,3.178890e+002,4.847969e-005,-2.108449e-002
1.000000e+003,3.168503e+002,4.852084e-005,-2.110644e-002
1.000000e+003,3.158760e+002,4.859673e-005,-2.110672e-002
1.000000e+003,3.148354e+002,4.862305e-005,-2.082043e-002
1.000000e+003,3.138802e+002,4.867095e-005,-2.107052e-002
1.000000e+003,3.128555e+002,4.874082e-005,-1.994715e-002
1.000000e+003,3.118668e+002,4.874056e-005,-1.960995e-002
1.000000e+003,3.108771e+002,4.879592e-005,-1.977985e-002
1.000000e+003,3.098809e+002,4.884013e-005,-2.012870e-002
1.000000e+003,3.088669e+002,4.884999e-005,-1.959079e-002
1.000000e+003,3.078844e+002,4.889561e-005,-1.921090e-002
1.000000e+003,3.068509e+002,4.896649e-005,-1.860909e-002
1.000000e+003,3.058783e+002,4.898381e-005,-1.884696e-002
1.000000e+003,3.048463e+002,4.901462e-005,-1.837765e-002
1.000000e+003,3.038691e+002,4.910899e-005,-1.817232e-002
1.000000e+003,3.028841e+002,4.912627e-005,-1.812398e-002
1.000000e+003,3.018790e+002,4.922682e-005,-1.805849e-002
1.000000e+003,3.008918e+002,4.922465e-005,-1.747648e-002
1.000000e+003,3.000105e+002,4.925628e-005,-1.809049e-002