File: spin_crossover/dane/AOT — kopia/Big AOT/FeTrz_XTvT_MCE_final.rso.dat
[Header]
TITLE,MPMS RSO Measurement
BYAPP,MPMS Measurement,1.1,Summary
FILEOPENTIME, 1654297054.543000 6/4/2022, 12:57:34 AM

INFO, APPNAME, MPMS MultiVu Application, Revision 1.60,  Build 081

INFO, NAME, AP_FeTrz_AOT_120nm
INFO, WEIGHT, 4.610
INFO, AREA, 0.000
INFO, LENGTH, 0.000
INFO, SHAPE, 0
INFO, COMMENT, Cu drut, w foli Al
INFO, SEQUENCE FILE: FeTrz_HTvT_MCE.seq


INFO, BACKGROUND DATA FILE:, None


STARTUPAXIS,X,4,LINEAR,AUTO,0.000000,0.000000
STARTUPAXIS,Y1,5,LINEAR,AUTO,0.000000,0.000000


STARTUPGROUP,Longitudinal
FIELDGROUP,Longitudinal,1,2,3,4,5,6,7,8,9,10,11,19,20,21,22,23,35
FIELDGROUP,Transverse,1,2,3,4,12,13,14,15,16,17,18,24,25,26,27,28,35

PLOT_APPEARANCE,ALL,HORZ_GRID_ON,VERT_GRID_ON,MARKERS_AND_LINES

[Data]
Time,Comment,Field (Oe),Temperature (K),Long Moment (emu),Long Scan Std Dev,Long Offset (cm),Long Offset Std Dev,Long Algorithm,Long Reg Fit,Long Reg Factor,Trans Moment (emu),Trans Scan Std Dev,Trans Offset (cm),Trans Offset Std Dev,Trans Algorithm,Trans Reg Fit,Trans Reg Factor,Long Moment [w/o ABS] (emu),Long Scan Std Dev [w/o ABS],Long Offset [w/o ABS] (cm),Long Offset Std Dev [w/o ABS],Long Reg Fit [w/o ABS],Trans Moment [w/o ABS] (emu),Trans Scan Std Dev [w/o ABS],Trans Offset [w/o ABS] (cm),Trans Offset Std Dev [w/o ABS],Trans Reg Fit [w/o ABS],RSO Position (deg),Amplitude (cm),Frequency,Cycles to Average,Scans per Measurement,Delta Temp (K),Error,EC Comp. Running,Using ABS,
1654297054.542,,0.000000e+000,4.000043e+002,-1.351779e-006,2.938088e-008,-1.627299e-001,4.995333e-002,3,8.883740e-001,1.825000e+000,,,,,,,,,,,,,,,,,,0,4.000000e+000,1.000000e+000,2,2,2.590942e-002,0,,0,
1654297913.632,,0.000000e+000,3.708896e+002,-1.419518e-006,1.601665e-009,-1.374671e-001,1.601390e-002,3,8.897507e-001,1.825000e+000,,,,,,,,,,,,,,,,,,0,4.000000e+000,1.000000e+000,2,2,1.043518e+000,0,,0,
1654298647.946,,0.000000e+000,3.437551e+002,-8.743270e-008,6.496114e-008,-8.455911e-002,1.145021e+000,3,0.000000e+000,1.825000e+000,,,,,,,,,,,,,,,,,,0,4.000000e+000,1.000000e+000,2,2,4.353943e-001,0,,0,
1654299595.284,,0.000000e+000,3.155325e+002,-1.829302e-008,1.201273e-007,-7.996621e-001,4.473924e-001,3,0.000000e+000,1.825000e+000,,,,,,,,,,,,,,,,,,0,4.000000e+000,1.000000e+000,2,2,7.261047e-001,0,,0,
1654300925.950,,0.000000e+000,3.112523e+002,-7.755398e-008,6.861599e-008,-3.901222e-001,6.750727e-001,3,0.000000e+000,1.825000e+000,,,,,,,,,,,,,,,,,,0,4.000000e+000,1.000000e+000,2,2,4.215088e-001,0,,0,
1654301769.126,,0.000000e+000,3.392300e+002,-1.338523e-007,2.049390e-008,-5.018098e-001,4.670301e-002,3,3.038971e-002,1.825000e+000,,,,,,,,,,,,,,,,,,0,4.000000e+000,1.000000e+000,2,2,4.511108e-001,0,,0,
1654302609.160,,0.000000e+000,3.672354e+002,-8.196131e-008,6.419064e-008,-9.866285e-002,1.065934e+000,3,0.000000e+000,1.825000e+000,,,,,,,,,,,,,,,,,,0,4.000000e+000,1.000000e+000,2,2,4.132080e-001,0,,0,
1654303449.325,,0.000000e+000,3.952464e+002,-1.407718e-006,5.490157e-008,-1.670432e-001,6.991098e-003,3,8.918675e-001,1.825000e+000,,,,,,,,,,,,,,,,,,0,4.000000e+000,1.000000e+000,2,2,3.800964e-001,0,,0,
1654304962.695,,1.000000e+002,3.775030e+002,1.148436e-005,1.088463e-008,-9.272698e-002,9.121579e-004,3,9.667706e-001,1.825000e+000,,,,,,,,,,,,,,,,,,0,4.000000e+000,1.000000e+000,2,2,7.717896e-001,0,,0,
1654305671.236,,1.000000e+002,3.494108e+002,5.623170e-006,3.966059e-009,-2.113514e-002,6.627255e-003,3,9.422559e-001,1.825000e+000,,,,,,,,,,,,,,,,,,0,4.000000e+000,1.000000e+000,2,2,8.132935e-001,0,,0,
1654306621.605,,1.000000e+002,3.216858e+002,5.407927e-006,2.676945e-009,-5.285311e-003,1.238445e-003,3,9.387083e-001,1.825000e+000,,,,,,,,,,,,,,,,,,0,4.000000e+000,1.000000e+000,2,2,5.839233e-001,0,,0,
1654307908.984,,1.000000e+002,3.052870e+002,5.519538e-006,1.770482e-008,-5.939921e-003,4.080835e-003,3,9.368608e-001,1.825000e+000,,,,,,,,,,,,,,,,,,0,4.000000e+000,1.000000e+000,2,2,4.927979e-001,0,,0,
1654308733.045,,1.000000e+002,3.332475e+002,5.351255e-006,1.419183e-008,-2.539647e-002,4.296395e-003,3,9.310840e-001,1.825000e+000,,,,,,,,,,,,,,,,,,0,4.000000e+000,1.000000e+000,2,2,4.521179e-001,0,,0,
1654309577.753,,1.000000e+002,3.614357e+002,5.333916e-006,1.213966e-008,-3.083456e-002,3.577818e-003,3,9.359958e-001,1.825000e+000,,,,,,,,,,,,,,,,,,0,4.000000e+000,1.000000e+000,2,2,4.312134e-001,0,,0,
1654310413.431,,1.000000e+002,3.892975e+002,1.128382e-005,1.993576e-008,-1.053142e-001,4.209048e-004,3,9.613855e-001,1.825000e+000,,,,,,,,,,,,,,,,,,0,4.000000e+000,1.000000e+000,2,2,4.300842e-001,0,,0,
1654311712.572,,2.000000e+002,3.836897e+002,2.434337e-005,2.010361e-008,-9.471601e-002,1.682555e-003,3,9.650536e-001,1.825000e+000,,,,,,,,,,,,,,,,,,0,4.000000e+000,1.000000e+000,2,2,5.601196e-001,0,,0,
1654312735.228,,2.000000e+002,3.553849e+002,2.217345e-005,7.007184e-007,-7.753606e-002,2.899282e-003,3,9.638100e-001,1.825000e+000,,,,,,,,,,,,,,,,,,0,4.000000e+000,1.000000e+000,2,2,7.919922e-001,0,,0,
1654313458.963,,2.000000e+002,3.277556e+002,1.113803e-005,1.676588e-009,-5.217266e-003,4.037662e-003,3,9.402524e-001,1.825000e+000,,,,,,,,,,,,,,,,,,0,4.000000e+000,1.000000e+000,2,2,4.364014e-001,0,,0,
1654314625.166,,2.000000e+002,3.000672e+002,1.137624e-005,5.196135e-008,2.826602e-003,1.921832e-003,3,9.416380e-001,1.825000e+000,,,,,,,,,,,,,,,,,,0,4.000000e+000,1.000000e+000,2,2,7.110596e-003,0,,0,
1654315703.432,,2.000000e+002,3.272302e+002,1.110655e-005,1.586423e-008,-1.169707e-002,1.541138e-003,3,9.378569e-001,1.825000e+000,,,,,,,,,,,,,,,,,,0,4.000000e+000,1.000000e+000,2,2,4.519958e-001,0,,0,
1654316542.872,,2.000000e+002,3.552554e+002,1.098763e-005,2.202651e-008,-2.158340e-002,2.706973e-004,3,9.393676e-001,1.825000e+000,,,,,,,,,,,,,,,,,,0,4.000000e+000,1.000000e+000,2,2,3.855286e-001,0,,0,
1654317382.582,,2.000000e+002,3.832552e+002,1.892898e-005,4.217669e-007,-8.575954e-002,3.504294e-003,3,9.582254e-001,1.825000e+000,,,,,,,,,,,,,,,,,,0,4.000000e+000,1.000000e+000,2,2,4.399109e-001,0,,0,
1654318760.467,,3.000000e+002,3.893744e+002,3.687766e-005,9.734111e-009,-9.781753e-002,3.140836e-004,3,9.656125e-001,1.825000e+000,,,,,,,,,,,,,,,,,,0,4.000000e+000,1.000000e+000,2,2,7.863770e-001,0,,0,
1654319544.543,,3.000000e+002,3.618779e+002,3.825186e-005,3.706628e-008,-8.574778e-002,2.816990e-004,3,9.669436e-001,1.825000e+000,,,,,,,,,,,,,,,,,,0,4.000000e+000,1.000000e+000,2,2,2.214050e-001,0,,0,
1654320488.180,,3.000000e+002,3.334517e+002,1.668139e-005,4.931881e-008,-5.076115e-003,3.842436e-004,3,9.410982e-001,1.825000e+000,,,,,,,,,,,,,,,,,,0,4.000000e+000,1.000000e+000,2,2,8.076172e-001,0,,0,
1654321389.442,,3.000000e+002,3.057289e+002,1.697928e-005,2.776305e-008,2.799704e-003,1.625950e-003,3,9.415964e-001,1.825000e+000,,,,,,,,,,,,,,,,,,0,4.000000e+000,1.000000e+000,2,2,4.205017e-001,0,,0,
1654322680.338,,3.000000e+002,3.214309e+002,1.680468e-005,4.427811e-008,-8.111121e-003,1.340566e-004,3,9.404534e-001,1.825000e+000,,,,,,,,,,,,,,,,,,0,4.000000e+000,1.000000e+000,2,2,4.515991e-001,0,,0,
1654323513.795,,3.000000e+002,3.492270e+002,1.657294e-005,7.856230e-009,-1.911350e-002,2.264033e-003,3,9.410599e-001,1.825000e+000,,,,,,,,,,,,,,,,,,0,4.000000e+000,1.000000e+000,2,2,4.110107e-001,0,,0,
1654324354.685,,3.000000e+002,3.772841e+002,1.698238e-005,3.515367e-008,-3.406250e-002,8.045544e-004,3,9.407486e-001,1.825000e+000,,,,,,,,,,,,,,,,,,0,4.000000e+000,1.000000e+000,2,2,4.257202e-001,0,,0,
1654325820.974,,4.000000e+002,3.957190e+002,4.890750e-005,7.106878e-008,-1.026998e-001,5.172472e-004,3,9.658433e-001,1.825000e+000,,,,,,,,,,,,,,,,,,0,4.000000e+000,1.000000e+000,2,2,5.715027e-001,0,,0,
1654326569.418,,4.000000e+002,3.670943e+002,5.103572e-005,1.012255e-008,-8.940808e-002,1.659637e-004,3,9.662567e-001,1.825000e+000,,,,,,,,,,,,,,,,,,0,4.000000e+000,1.000000e+000,2,2,7.825012e-001,0,,0,
1654327550.317,,4.000000e+002,3.396148e+002,2.210078e-005,2.058852e-008,-8.188666e-003,2.734382e-004,3,9.421778e-001,1.825000e+000,,,,,,,,,,,,,,,,,,0,4.000000e+000,1.000000e+000,2,2,7.196045e-001,0,,0,
1654328276.647,,4.000000e+002,3.117034e+002,2.240270e-005,3.505978e-008,1.990764e-004,1.234358e-003,3,9.433716e-001,1.825000e+000,,,,,,,,,,,,,,,,,,0,4.000000e+000,1.000000e+000,2,2,4.768066e-001,0,,0,
1654329649.530,,4.000000e+002,3.152484e+002,2.234594e-005,2.311208e-008,-5.856506e-003,3.218159e-004,3,9.418417e-001,1.825000e+000,,,,,,,,,,,,,,,,,,0,4.000000e+000,1.000000e+000,2,2,4.096069e-001,0,,0,
1654330491.299,,4.000000e+002,3.432635e+002,2.195874e-005,5.173047e-008,-1.909917e-002,9.339017e-004,3,9.425318e-001,1.825000e+000,,,,,,,,,,,,,,,,,,0,4.000000e+000,1.000000e+000,2,2,4.153137e-001,0,,0,
1654331332.177,,4.000000e+002,3.712978e+002,2.212670e-005,5.243918e-009,-3.191088e-002,3.348040e-004,3,9.413096e-001,1.825000e+000,,,,,,,,,,,,,,,,,,0,4.000000e+000,1.000000e+000,2,2,3.894958e-001,0,,0,
1654332170.178,,4.000000e+002,3.992420e+002,4.865739e-005,2.679710e-008,-1.095418e-001,1.871847e-005,3,9.654301e-001,1.825000e+000,,,,,,,,,,,,,,,,,,0,4.000000e+000,1.000000e+000,2,2,4.385071e-001,0,,0,
1654333633.717,,5.000000e+002,3.732001e+002,6.318754e-005,4.369031e-008,-9.486138e-002,2.965874e-004,3,9.678826e-001,1.825000e+000,,,,,,,,,,,,,,,,,,0,4.000000e+000,1.000000e+000,2,2,9.561157e-001,0,,0,
1654334354.888,,5.000000e+002,3.456834e+002,2.771557e-005,7.031764e-009,-1.460917e-002,1.167256e-003,3,9.431249e-001,1.825000e+000,,,,,,,,,,,,,,,,,,0,4.000000e+000,1.000000e+000,2,2,4.980774e-001,0,,0,
1654335306.393,,5.000000e+002,3.175249e+002,2.747760e-005,1.134703e-008,-5.159135e-003,1.337044e-003,3,9.428989e-001,1.825000e+000,,,,,,,,,,,,,,,,,,0,4.000000e+000,1.000000e+000,2,2,7.279968e-001,0,,0,
1654336618.806,,5.000000e+002,3.092275e+002,2.766014e-005,1.112194e-008,-5.602548e-003,5.452600e-004,3,9.429469e-001,1.825000e+000,,,,,,,,,,,,,,,,,,0,4.000000e+000,1.000000e+000,2,2,4.460144e-001,0,,0,
1654337459.726,,5.000000e+002,3.372493e+002,2.710445e-005,4.339705e-008,-1.775402e-002,4.894434e-004,3,9.411487e-001,1.825000e+000,,,,,,,,,,,,,,,,,,0,4.000000e+000,1.000000e+000,2,2,4.092102e-001,0,,0,
1654338300.996,,5.000000e+002,3.652833e+002,2.707899e-005,3.850685e-008,-3.099583e-002,1.713915e-004,3,9.414654e-001,1.825000e+000,,,,,,,,,,,,,,,,,,0,4.000000e+000,1.000000e+000,2,2,4.194031e-001,0,,0,
1654339140.223,,5.000000e+002,3.932696e+002,6.118018e-005,1.193612e-009,-1.103568e-001,2.426341e-004,3,9.662226e-001,1.825000e+000,,,,,,,,,,,,,,,,,,0,4.000000e+000,1.000000e+000,2,2,4.139099e-001,0,,0,
1654340665.552,,6.000000e+002,3.798304e+002,7.472243e-005,1.938076e-008,-1.009989e-001,5.668751e-004,3,9.678498e-001,1.825000e+000,,,,,,,,,,,,,,,,,,0,4.000000e+000,1.000000e+000,2,2,3.033752e-001,0,,0,
1654341399.928,,6.000000e+002,3.512630e+002,3.882512e-005,1.292988e-006,-4.098437e-002,3.731982e-003,3,9.498160e-001,1.825000e+000,,,,,,,,,,,,,,,,,,0,4.000000e+000,1.000000e+000,2,2,8.220825e-001,0,,0,
1654342316.998,,6.000000e+002,3.237975e+002,3.222827e-005,4.469614e-008,-1.119883e-002,1.068652e-003,3,9.438033e-001,1.825000e+000,,,,,,,,,,,,,,,,,,0,4.000000e+000,1.000000e+000,2,2,3.086243e-001,0,,0,
1654343617.312,,6.000000e+002,3.033187e+002,3.275550e-005,2.988146e-008,-7.482486e-003,2.737626e-004,3,9.445311e-001,1.825000e+000,,,,,,,,,,,,,,,,,,0,4.000000e+000,1.000000e+000,2,2,5.438843e-001,0,,0,
1654344429.612,,6.000000e+002,3.312610e+002,3.204873e-005,4.428197e-008,-1.962385e-002,5.408494e-005,3,9.430555e-001,1.825000e+000,,,,,,,,,,,,,,,,,,0,4.000000e+000,1.000000e+000,2,2,4.638977e-001,0,,0,
1654345268.560,,6.000000e+002,3.592588e+002,3.185109e-005,2.114545e-009,-3.290866e-002,7.593993e-004,3,9.427346e-001,1.825000e+000,,,,,,,,,,,,,,,,,,0,4.000000e+000,1.000000e+000,2,2,4.154968e-001,0,,0,
1654346109.017,,6.000000e+002,3.872392e+002,7.370363e-005,5.077998e-009,-1.119859e-001,2.475390e-004,3,9.672334e-001,1.825000e+000,,,,,,,,,,,,,,,,,,0,4.000000e+000,1.000000e+000,2,2,4.494934e-001,0,,0,
1654347431.117,,7.000000e+002,3.855944e+002,8.607918e-005,5.111437e-008,-1.038216e-001,2.395785e-004,3,9.685614e-001,1.825000e+000,,,,,,,,,,,,,,,,,,0,4.000000e+000,1.000000e+000,2,2,6.744995e-001,0,,0,
1654348455.694,,7.000000e+002,3.575846e+002,8.895636e-005,4.558363e-009,-9.471993e-002,2.455633e-004,3,9.692682e-001,1.825000e+000,,,,,,,,,,,,,,,,,,0,4.000000e+000,1.000000e+000,2,2,8.638000e-001,0,,0,
1654349168.305,,7.000000e+002,3.296349e+002,3.678239e-005,3.647462e-008,-1.568093e-002,1.020737e-004,3,9.439929e-001,1.825000e+000,,,,,,,,,,,,,,,,,,0,4.000000e+000,1.000000e+000,2,2,5.892029e-001,0,,0,
1654350096.279,,7.000000e+002,3.016102e+002,3.760137e-005,8.098040e-009,-8.746063e-003,1.830174e-004,3,9.439585e-001,1.825000e+000,,,,,,,,,,,,,,,,,,0,4.000000e+000,1.000000e+000,2,2,5.661926e-001,0,,0,
1654351401.231,,7.000000e+002,3.252662e+002,3.686681e-005,2.846919e-008,-2.128329e-002,5.541072e-004,3,9.435633e-001,1.825000e+000,,,,,,,,,,,,,,,,,,0,4.000000e+000,1.000000e+000,2,2,4.042053e-001,0,,0,
1654352240.362,,7.000000e+002,3.532510e+002,3.640652e-005,4.267420e-008,-3.443713e-002,1.298307e-004,3,9.433582e-001,1.825000e+000,,,,,,,,,,,,,,,,,,0,4.000000e+000,1.000000e+000,2,2,4.111023e-001,0,,0,
1654353086.997,,7.000000e+002,3.814480e+002,6.810623e-005,1.490935e-006,-9.617741e-002,1.320271e-003,3,9.629284e-001,1.825000e+000,,,,,,,,,,,,,,,,,,0,4.000000e+000,1.000000e+000,2,2,4.473877e-001,0,,0,
1654354488.631,,8.000000e+002,3.913695e+002,9.683880e-005,3.628683e-008,-1.096307e-001,3.474375e-004,3,9.690279e-001,1.825000e+000,,,,,,,,,,,,,,,,,,0,4.000000e+000,1.000000e+000,2,2,8.692932e-001,0,,0,
1654355239.699,,8.000000e+002,3.637495e+002,1.007834e-004,3.202173e-008,-9.705767e-002,1.161883e-004,3,9.696729e-001,1.825000e+000,,,,,,,,,,,,,,,,,,0,4.000000e+000,1.000000e+000,2,2,4.797058e-001,0,,0,
1654356214.786,,8.000000e+002,3.355567e+002,4.124297e-005,4.481190e-009,-2.310297e-002,3.963424e-004,3,9.447323e-001,1.825000e+000,,,,,,,,,,,,,,,,,,0,4.000000e+000,1.000000e+000,2,2,8.567200e-001,0,,0,
1654357044.365,,8.000000e+002,3.078900e+002,4.201974e-005,9.209333e-010,-1.426580e-002,7.716298e-005,3,9.457394e-001,1.825000e+000,,,,,,,,,,,,,,,,,,0,4.000000e+000,1.000000e+000,2,2,1.797180e-001,0,,0,
1654358372.424,,8.000000e+002,3.192565e+002,4.153104e-005,1.926759e-009,-2.344358e-002,3.821692e-004,3,9.449304e-001,1.825000e+000,,,,,,,,,,,,,,,,,,0,4.000000e+000,1.000000e+000,2,2,3.966064e-001,0,,0,
1654359212.382,,8.000000e+002,3.472763e+002,4.092125e-005,9.847298e-009,-3.570500e-002,2.216924e-005,3,9.445021e-001,1.825000e+000,,,,,,,,,,,,,,,,,,0,4.000000e+000,1.000000e+000,2,2,4.447937e-001,0,,0,
1654360051.199,,8.000000e+002,3.752559e+002,4.189950e-005,7.520013e-008,-5.074838e-002,4.985445e-005,3,9.454795e-001,1.825000e+000,,,,,,,,,,,,,,,,,,0,4.000000e+000,1.000000e+000,2,2,4.096069e-001,0,,0,
1654361515.740,,9.000000e+002,3.977441e+002,1.070153e-004,3.508807e-009,-1.159424e-001,2.056187e-004,3,9.695508e-001,1.825000e+000,,,,,,,,,,,,,,,,,,0,4.000000e+000,1.000000e+000,2,2,4.100037e-001,0,,0,
1654362281.862,,9.000000e+002,3.690228e+002,1.121061e-004,4.268706e-008,-1.020602e-001,5.984009e-004,3,9.703050e-001,1.825000e+000,,,,,,,,,,,,,,,,,,0,4.000000e+000,1.000000e+000,2,2,8.129883e-001,0,,0,
1654363242.056,,9.000000e+002,3.417394e+002,4.572952e-005,6.331031e-008,-2.994352e-002,7.772999e-004,3,9.456005e-001,1.825000e+000,,,,,,,,,,,,,,,,,,0,4.000000e+000,1.000000e+000,2,2,4.207153e-001,0,,0,
1654363975.092,,9.000000e+002,3.136833e+002,4.624841e-005,1.929072e-008,-1.956267e-002,1.125532e-004,3,9.451299e-001,1.825000e+000,,,,,,,,,,,,,,,,,,0,4.000000e+000,1.000000e+000,2,2,5.378723e-001,0,,0,
1654365331.986,,9.000000e+002,3.132028e+002,4.620800e-005,7.283862e-008,-2.419860e-002,5.203542e-004,3,9.467429e-001,1.825000e+000,,,,,,,,,,,,,,,,,,0,4.000000e+000,1.000000e+000,2,2,4.039001e-001,0,,0,
1654366180.356,,9.000000e+002,3.414055e+002,4.533309e-005,6.166138e-009,-3.733923e-002,3.934435e-004,3,9.446249e-001,1.825000e+000,,,,,,,,,,,,,,,,,,0,4.000000e+000,1.000000e+000,2,2,4.664917e-001,0,,0,
1654367015.595,,9.000000e+002,3.692398e+002,4.563716e-005,2.788267e-008,-4.999371e-002,1.172947e-004,3,9.456657e-001,1.825000e+000,,,,,,,,,,,,,,,,,,0,4.000000e+000,1.000000e+000,2,2,4.510193e-001,0,,0,
1654367856.599,,9.000000e+002,3.972834e+002,1.071431e-004,6.353928e-009,-1.219157e-001,1.254922e-004,3,9.692414e-001,1.825000e+000,,,,,,,,,,,,,,,,,,0,4.000000e+000,1.000000e+000,2,2,4.476013e-001,0,,0,
1654369348.994,,1.500000e+003,3.754526e+002,1.798937e-004,1.359586e-007,-1.142703e-001,9.969837e-005,3,9.724951e-001,1.825000e+000,,,,,,,,,,,,,,,,,,0,4.000000e+000,1.000000e+000,2,2,9.682007e-001,0,,0,
1654370059.271,,1.500000e+003,3.476322e+002,7.421081e-005,4.197810e-007,-5.219931e-002,5.694856e-004,3,9.508615e-001,1.825000e+000,,,,,,,,,,,,,,,,,,0,4.000000e+000,1.000000e+000,2,2,6.299744e-001,0,,0,
1654371013.490,,1.500000e+003,3.196153e+002,7.063580e-005,2.099111e-009,-3.763773e-002,3.246256e-004,3,9.493190e-001,1.825000e+000,,,,,,,,,,,,,,,,,,0,4.000000e+000,1.000000e+000,2,2,7.218018e-001,0,,0,
1654372316.195,,1.500000e+003,3.073593e+002,7.134034e-005,2.592505e-008,-3.807677e-002,4.750240e-004,3,9.495998e-001,1.825000e+000,,,,,,,,,,,,,,,,,,0,4.000000e+000,1.000000e+000,2,2,5.223083e-001,0,,0,
1654373147.732,,1.500000e+003,3.352212e+002,6.966066e-005,6.746480e-008,-5.059683e-002,7.907803e-006,3,9.485664e-001,1.825000e+000,,,,,,,,,,,,,,,,,,0,4.000000e+000,1.000000e+000,2,2,4.488831e-001,0,,0,
1654373988.809,,1.500000e+003,3.632650e+002,6.962418e-005,3.485655e-008,-6.380837e-002,7.845899e-004,3,9.488132e-001,1.825000e+000,,,,,,,,,,,,,,,,,,0,4.000000e+000,1.000000e+000,2,2,5.103149e-001,0,,0,
1654374828.643,,1.500000e+003,3.912917e+002,1.750237e-004,4.550131e-008,-1.291165e-001,3.617254e-005,3,9.719372e-001,1.825000e+000,,,,,,,,,,,,,,,,,,0,4.000000e+000,1.000000e+000,2,2,4.096985e-001,0,,0,
1654376131.381,,2.000000e+003,3.817396e+002,2.337021e-004,7.793463e-008,-1.194284e-001,1.003938e-004,3,9.738536e-001,1.825000e+000,,,,,,,,,,,,,,,,,,0,4.000000e+000,1.000000e+000,2,2,3.892212e-001,0,,0,
1654377132.504,,2.000000e+003,3.533214e+002,1.810321e-004,1.211204e-005,-9.675513e-002,2.432210e-003,3,9.699491e-001,1.825000e+000,,,,,,,,,,,,,,,,,,0,4.000000e+000,1.000000e+000,2,2,9.527283e-001,0,,0,
1654377905.725,,2.000000e+003,3.258672e+002,8.932293e-005,3.585466e-008,-4.883693e-002,2.510819e-004,3,9.514511e-001,1.825000e+000,,,,,,,,,,,,,,,,,,0,4.000000e+000,1.000000e+000,2,2,2.113953e-001,0,,0,
1654379324.114,,2.000000e+003,3.012416e+002,9.141662e-005,1.517225e-008,-4.388112e-002,5.330312e-004,3,9.517341e-001,1.825000e+000,,,,,,,,,,,,,,,,,,0,4.000000e+000,1.000000e+000,2,2,3.788147e-001,0,,0,
1654380133.577,,2.000000e+003,3.292325e+002,8.889420e-005,1.541920e-008,-5.745243e-002,2.586499e-005,3,9.508153e-001,1.825000e+000,,,,,,,,,,,,,,,,,,0,4.000000e+000,1.000000e+000,2,2,4.493103e-001,0,,0,
1654380973.681,,2.000000e+003,3.572556e+002,8.821390e-005,4.771361e-008,-7.081199e-002,3.956904e-004,3,9.509055e-001,1.825000e+000,,,,,,,,,,,,,,,,,,0,4.000000e+000,1.000000e+000,2,2,4.107056e-001,0,,0,
1654381813.690,,2.000000e+003,3.852515e+002,2.314771e-004,2.179371e-008,-1.321811e-001,1.285479e-006,3,9.735215e-001,1.825000e+000,,,,,,,,,,,,,,,,,,0,4.000000e+000,1.000000e+000,2,2,4.567871e-001,0,,0,
1654383170.661,,2.500000e+003,3.874886e+002,2.856615e-004,9.958428e-008,-1.262758e-001,3.796483e-004,3,9.745233e-001,1.825000e+000,,,,,,,,,,,,,,,,,,0,4.000000e+000,1.000000e+000,2,2,8.882141e-001,0,,0,
1654384191.153,,2.500000e+003,3.597191e+002,2.971037e-004,8.357342e-008,-1.164606e-001,1.284109e-004,3,9.750013e-001,1.825000e+000,,,,,,,,,,,,,,,,,,0,4.000000e+000,1.000000e+000,2,2,5.728149e-001,0,,0,
1654384905.917,,2.500000e+003,3.314779e+002,1.073966e-004,3.150724e-008,-5.763267e-002,2.386039e-004,3,9.531438e-001,1.825000e+000,,,,,,,,,,,,,,,,,,0,4.000000e+000,1.000000e+000,2,2,6.486816e-001,0,,0,
1654385824.378,,2.500000e+003,3.036127e+002,1.100742e-004,6.688343e-010,-5.042977e-002,1.408732e-004,3,9.537611e-001,1.825000e+000,,,,,,,,,,,,,,,,,,0,4.000000e+000,1.000000e+000,2,2,4.797058e-001,0,,0,
1654387113.676,,2.500000e+003,3.232648e+002,1.077174e-004,4.405045e-008,-6.234676e-002,7.914125e-005,3,9.529341e-001,1.825000e+000,,,,,,,,,,,,,,,,,,0,4.000000e+000,1.000000e+000,2,2,4.488220e-001,0,,0,
1654387952.731,,2.500000e+003,3.512677e+002,1.062499e-004,6.281899e-009,-7.527541e-002,3.353730e-004,3,9.527937e-001,1.825000e+000,,,,,,,,,,,,,,,,,,0,4.000000e+000,1.000000e+000,2,2,4.062195e-001,0,,0,
1654388792.151,,2.500000e+003,3.792567e+002,1.764353e-004,5.882212e-006,-1.102345e-001,1.762028e-003,3,9.651176e-001,1.825000e+000,,,,,,,,,,,,,,,,,,0,4.000000e+000,1.000000e+000,2,2,3.954163e-001,0,,0,
1654390240.689,,3.000000e+003,3.935210e+002,3.359439e-004,2.228144e-007,-1.326362e-001,3.441712e-004,3,9.750961e-001,1.825000e+000,,,,,,,,,,,,,,,,,,0,4.000000e+000,1.000000e+000,2,2,8.917236e-001,0,,0,
1654390981.608,,3.000000e+003,3.655633e+002,3.520655e-004,6.056552e-008,-1.188082e-001,5.648204e-005,3,9.757031e-001,1.825000e+000,,,,,,,,,,,,,,,,,,0,4.000000e+000,1.000000e+000,2,2,6.893921e-001,0,,0,
1654391967.516,,3.000000e+003,3.374588e+002,1.255104e-004,5.100633e-008,-6.636295e-002,5.440420e-004,3,9.546028e-001,1.825000e+000,,,,,,,,,,,,,,,,,,0,4.000000e+000,1.000000e+000,2,2,8.282776e-001,0,,0,
1654392720.794,,3.000000e+003,3.098032e+002,1.280918e-004,9.158463e-010,-5.647618e-002,3.742904e-005,3,9.553069e-001,1.825000e+000,,,,,,,,,,,,,,,,,,0,4.000000e+000,1.000000e+000,2,2,3.263855e-001,0,,0,
1654394093.591,,3.000000e+003,3.172111e+002,1.268609e-004,3.575691e-008,-6.468575e-002,2.197115e-004,3,9.546393e-001,1.825000e+000,,,,,,,,,,,,,,,,,,0,4.000000e+000,1.000000e+000,2,2,3.991089e-001,0,,0,
1654394936.341,,3.000000e+003,3.452863e+002,1.244926e-004,3.672415e-008,-7.775404e-002,2.520540e-004,3,9.541306e-001,1.825000e+000,,,,,,,,,,,,,,,,,,0,4.000000e+000,1.000000e+000,2,2,4.013062e-001,0,,0,
1654395775.700,,3.000000e+003,3.733066e+002,1.275536e-004,1.505495e-007,-9.238298e-002,1.475403e-004,3,9.549965e-001,1.825000e+000,,,,,,,,,,,,,,,,,,0,4.000000e+000,1.000000e+000,2,2,4.162903e-001,0,,0,
1654397213.798,,4.000000e+003,4.000108e+002,4.371152e-004,1.226951e-007,-1.408615e-001,7.141783e-005,3,9.762257e-001,1.825000e+000,,,,,,,,,,,,,,,,,,0,4.000000e+000,1.000000e+000,2,2,1.300049e-002,0,,0,
1654398058.205,,4.000000e+003,3.712313e+002,4.595844e-004,1.901547e-007,-1.253495e-001,1.923161e-004,3,9.766230e-001,1.825000e+000,,,,,,,,,,,,,,,,,,0,4.000000e+000,1.000000e+000,2,2,9.012146e-001,0,,0,
1654398813.834,,4.000000e+003,3.437977e+002,1.638906e-004,1.819023e-007,-7.608591e-002,5.512281e-005,3,9.574422e-001,1.825000e+000,,,,,,,,,,,,,,,,,,0,4.000000e+000,1.000000e+000,2,2,3.031006e-001,0,,0,
1654399742.749,,4.000000e+003,3.156450e+002,1.632993e-004,7.723492e-008,-6.683962e-002,4.902995e-004,3,9.565985e-001,1.825000e+000,,,,,,,,,,,,,,,,,,0,4.000000e+000,1.000000e+000,2,2,7.029724e-001,0,,0,
1654401078.431,,4.000000e+003,3.112811e+002,1.637156e-004,6.698640e-009,-6.931828e-002,1.053829e-004,3,9.567088e-001,1.825000e+000,,,,,,,,,,,,,,,,,,0,4.000000e+000,1.000000e+000,2,2,4.140930e-001,0,,0,
1654401921.499,,4.000000e+003,3.392714e+002,1.599212e-004,1.646361e-009,-8.306439e-002,2.709094e-004,3,9.561821e-001,1.825000e+000,,,,,,,,,,,,,,,,,,0,4.000000e+000,1.000000e+000,2,2,3.591003e-001,0,,0,
1654402760.961,,4.000000e+003,3.672572e+002,1.613215e-004,6.389940e-008,-9.677286e-002,1.984590e-005,3,9.567425e-001,1.825000e+000,,,,,,,,,,,,,,,,,,0,4.000000e+000,1.000000e+000,2,2,4.133911e-001,0,,0,
1654403600.507,,4.000000e+003,3.952495e+002,4.403790e-004,1.130227e-007,-1.440470e-001,1.467448e-004,3,9.760249e-001,1.825000e+000,,,,,,,,,,,,,,,,,,0,4.000000e+000,1.000000e+000,2,2,3.421021e-001,0,,0,
1654405128.490,,5.000000e+003,3.776240e+002,5.633637e-004,2.457606e-007,-1.311750e-001,3.078195e-004,3,9.770682e-001,1.825000e+000,,,,,,,,,,,,,,,,,,0,4.000000e+000,1.000000e+000,2,2,7.260132e-001,0,,0,
1654405837.404,,5.000000e+003,3.495749e+002,2.303374e-004,3.354307e-006,-9.135188e-002,8.647901e-004,3,9.624728e-001,1.825000e+000,,,,,,,,,,,,,,,,,,0,4.000000e+000,1.000000e+000,2,2,6.667786e-001,0,,0,
1654406791.442,,5.000000e+003,3.215871e+002,1.978826e-004,5.829148e-008,-7.463175e-002,2.609838e-004,3,9.583120e-001,1.825000e+000,,,,,,,,,,,,,,,,,,0,4.000000e+000,1.000000e+000,2,2,6.164856e-001,0,,0,
1654408078.498,,5.000000e+003,3.053165e+002,2.011200e-004,8.980901e-008,-7.233018e-002,3.366479e-005,3,9.586636e-001,1.825000e+000,,,,,,,,,,,,,,,,,,0,4.000000e+000,1.000000e+000,2,2,5.662842e-001,0,,0,
1654408902.933,,5.000000e+003,3.333007e+002,1.955542e-004,1.630927e-008,-8.613198e-002,4.565030e-004,3,9.579654e-001,1.825000e+000,,,,,,,,,,,,,,,,,,0,4.000000e+000,1.000000e+000,2,2,3.724060e-001,0,,0,
1654409747.073,,5.000000e+003,3.614409e+002,1.953443e-004,4.802230e-008,-1.001326e-001,2.700612e-004,3,9.577458e-001,1.825000e+000,,,,,,,,,,,,,,,,,,0,4.000000e+000,1.000000e+000,2,2,4.313049e-001,0,,0,
1654410580.452,,5.000000e+003,3.892238e+002,5.512292e-004,7.289265e-008,-1.451805e-001,3.329390e-004,3,9.767444e-001,1.825000e+000,,,,,,,,,,,,,,,,,,0,4.000000e+000,1.000000e+000,2,2,4.176025e-001,0,,0,
1654411889.465,,6.000000e+003,3.836897e+002,6.658018e-004,2.442377e-007,-1.338162e-001,5.405333e-005,3,9.775319e-001,1.825000e+000,,,,,,,,,,,,,,,,,,0,4.000000e+000,1.000000e+000,2,2,5.125122e-001,0,,0,
1654412906.189,,6.000000e+003,3.555221e+002,6.794488e-004,6.612363e-006,-1.235972e-001,3.049693e-004,3,9.778818e-001,1.825000e+000,,,,,,,,,,,,,,,,,,0,4.000000e+000,1.000000e+000,2,2,8.636780e-001,0,,0,
1654413640.551,,6.000000e+003,3.277599e+002,2.324523e-004,1.304741e-008,-7.923039e-002,7.117549e-005,3,9.593752e-001,1.825000e+000,,,,,,,,,,,,,,,,,,0,4.000000e+000,1.000000e+000,2,2,3.851013e-001,0,,0,
1654414803.344,,6.000000e+003,3.000672e+002,2.391410e-004,2.262718e-008,-7.285476e-002,3.953374e-005,3,9.600731e-001,1.825000e+000,,,,,,,,,,,,,,,,,,0,4.000000e+000,1.000000e+000,2,2,2.130127e-002,0,,0,
1654415877.520,,6.000000e+003,3.272195e+002,2.316638e-004,1.854214e-008,-8.778369e-002,2.611735e-004,3,9.591476e-001,1.825000e+000,,,,,,,,,,,,,,,,,,0,4.000000e+000,1.000000e+000,2,2,4.264221e-001,0,,0,
1654416717.642,,6.000000e+003,3.552351e+002,2.295724e-004,9.941964e-008,-1.008943e-001,4.537108e-004,3,9.589941e-001,1.825000e+000,,,,,,,,,,,,,,,,,,0,4.000000e+000,1.000000e+000,2,2,3.652039e-001,0,,0,
1654417557.263,,6.000000e+003,3.832284e+002,6.610165e-004,6.354954e-007,-1.455066e-001,1.975423e-004,3,9.773468e-001,1.825000e+000,,,,,,,,,,,,,,,,,,0,4.000000e+000,1.000000e+000,2,2,4.042053e-001,0,,0,
1654418948.609,,7.000000e+003,3.893959e+002,7.653518e-004,4.840302e-007,-1.390468e-001,1.361765e-004,3,9.776898e-001,1.825000e+000,,,,,,,,,,,,,,,,,,0,4.000000e+000,1.000000e+000,2,2,7.252197e-001,0,,0,
1654419736.758,,7.000000e+003,3.618990e+002,7.997504e-004,1.364010e-007,-1.262964e-001,1.118683e-004,3,9.781130e-001,1.825000e+000,,,,,,,,,,,,,,,,,,0,4.000000e+000,1.000000e+000,2,2,2.004089e-001,0,,0,
1654420674.467,,7.000000e+003,3.335227e+002,2.667994e-004,1.596970e-008,-8.528531e-002,2.387145e-004,3,9.600502e-001,1.825000e+000,,,,,,,,,,,,,,,,,,0,4.000000e+000,1.000000e+000,2,2,7.904968e-001,0,,0,
1654421577.662,,7.000000e+003,3.057400e+002,2.733851e-004,5.083182e-009,-7.710440e-002,4.199407e-005,3,9.603847e-001,1.825000e+000,,,,,,,,,,,,,,,,,,0,4.000000e+000,1.000000e+000,2,2,4.205017e-001,0,,0,
1654422869.194,,7.000000e+003,3.214166e+002,2.682367e-004,5.844583e-009,-8.751439e-002,3.531484e-004,3,9.599837e-001,1.825000e+000,,,,,,,,,,,,,,,,,,0,4.000000e+000,1.000000e+000,2,2,4.104919e-001,0,,0,
1654423704.064,,7.000000e+003,3.492882e+002,2.640099e-004,2.628005e-008,-1.010344e-001,1.731761e-004,3,9.591304e-001,1.825000e+000,,,,,,,,,,,,,,,,,,0,4.000000e+000,1.000000e+000,2,2,4.015198e-001,0,,0,
1654424542.249,,7.000000e+003,3.772122e+002,3.318948e-004,8.787124e-006,-1.164701e-001,1.074792e-003,3,9.639919e-001,1.825000e+000,,,,,,,,,,,,,,,,,,0,4.000000e+000,1.000000e+000,2,2,4.141235e-001,0,,0,
1654426010.693,,8.000000e+003,3.956492e+002,8.596546e-004,3.703901e-007,-1.441787e-001,1.293171e-004,3,9.777023e-001,1.825000e+000,,,,,,,,,,,,,,,,,,0,4.000000e+000,1.000000e+000,2,2,6.473999e-001,0,,0,
1654426751.632,,8.000000e+003,3.674940e+002,9.031257e-004,4.134425e-007,-1.295614e-001,1.827066e-005,3,9.783968e-001,1.825000e+000,,,,,,,,,,,,,,,,,,0,4.000000e+000,1.000000e+000,2,2,6.861877e-001,0,,0,
1654427735.480,,8.000000e+003,3.396057e+002,3.015257e-004,6.488722e-008,-9.051789e-002,4.496489e-004,3,9.606155e-001,1.825000e+000,,,,,,,,,,,,,,,,,,0,4.000000e+000,1.000000e+000,2,2,6.457825e-001,0,,0,
1654428467.476,,8.000000e+003,3.117592e+002,3.069669e-004,1.369567e-007,-7.994384e-002,6.860980e-005,3,9.607942e-001,1.825000e+000,,,,,,,,,,,,,,,,,,0,4.000000e+000,1.000000e+000,2,2,4.076843e-001,0,,0,
1654429833.969,,8.000000e+003,3.152189e+002,3.049765e-004,4.214685e-008,-8.667012e-002,3.412683e-004,3,9.607415e-001,1.825000e+000,,,,,,,,,,,,,,,,,,0,4.000000e+000,1.000000e+000,2,2,3.544006e-001,0,,0,
1654430675.957,,8.000000e+003,3.432258e+002,2.986036e-004,1.221394e-007,-1.008437e-001,3.971340e-004,3,9.601721e-001,1.825000e+000,,,,,,,,,,,,,,,,,,0,4.000000e+000,1.000000e+000,2,2,3.774109e-001,0,,0,
1654431515.653,,8.000000e+003,3.712421e+002,3.054191e-004,1.049350e-007,-1.140489e-001,8.038984e-005,3,9.611683e-001,1.825000e+000,,,,,,,,,,,,,,,,,,0,4.000000e+000,1.000000e+000,2,2,4.114990e-001,0,,0,
1654432357.480,,8.000000e+003,3.992679e+002,8.535890e-004,1.447152e-007,-1.520068e-001,2.687388e-004,3,9.776353e-001,1.825000e+000,,,,,,,,,,,,,,,,,,0,4.000000e+000,1.000000e+000,2,2,4.130249e-001,0,,0,
1654434403.774,,9.000000e+003,3.732282e+002,1.004540e-003,8.999834e-007,-1.327155e-001,1.197392e-004,3,9.782592e-001,1.825000e+000,,,,,,,,,,,,,,,,,,0,4.000000e+000,1.000000e+000,2,2,9.674072e-001,0,,0,
1654435117.568,,9.000000e+003,3.456427e+002,3.539954e-004,1.288236e-006,-9.465341e-002,5.991069e-004,3,9.623011e-001,1.825000e+000,,,,,,,,,,,,,,,,,,0,4.000000e+000,1.000000e+000,2,2,5.936890e-001,0,,0,
1654436073.014,,9.000000e+003,3.176808e+002,3.408270e-004,7.167846e-008,-8.340254e-002,2.471438e-004,3,9.614407e-001,1.825000e+000,,,,,,,,,,,,,,,,,,0,4.000000e+000,1.000000e+000,2,2,5.846252e-001,0,,0,
1654437377.398,,9.000000e+003,3.092332e+002,3.434996e-004,1.311121e-007,-8.542271e-002,9.965096e-005,3,9.613774e-001,1.825000e+000,,,,,,,,,,,,,,,,,,0,4.000000e+000,1.000000e+000,2,2,4.385071e-001,0,,0,
1654438218.643,,9.000000e+003,3.372629e+002,3.347546e-004,3.766107e-009,-9.941712e-002,1.379256e-004,3,9.609656e-001,1.825000e+000,,,,,,,,,,,,,,,,,,0,4.000000e+000,1.000000e+000,2,2,3.727722e-001,0,,0,
1654439058.438,,9.000000e+003,3.652537e+002,3.372091e-004,8.440111e-010,-1.125889e-001,1.686875e-004,3,9.612962e-001,1.825000e+000,,,,,,,,,,,,,,,,,,0,4.000000e+000,1.000000e+000,2,2,3.979797e-001,0,,0,
1654439898.525,,9.000000e+003,3.932884e+002,9.681615e-004,1.384590e-007,-1.511518e-001,1.080856e-004,3,9.779977e-001,1.825000e+000,,,,,,,,,,,,,,,,,,0,4.000000e+000,1.000000e+000,2,2,3.889160e-001,0,,0,
1654441420.203,,1.000000e+004,3.798217e+002,1.100540e-003,2.392986e-007,-1.381767e-001,8.214421e-005,3,9.783388e-001,1.825000e+000,,,,,,,,,,,,,,,,,,0,4.000000e+000,1.000000e+000,2,2,3.616943e-001,0,,0,
1654442146.400,,1.000000e+004,3.515381e+002,5.860908e-004,4.445097e-005,-1.144620e-001,1.248758e-003,3,9.715185e-001,1.825000e+000,,,,,,,,,,,,,,,,,,0,4.000000e+000,1.000000e+000,2,2,8.137817e-001,0,,0,
1654443068.701,,1.000000e+004,3.238205e+002,3.742057e-004,1.440566e-008,-8.866112e-002,5.137596e-004,3,9.615854e-001,1.825000e+000,,,,,,,,,,,,,,,,,,0,4.000000e+000,1.000000e+000,2,2,2.835999e-001,0,,0,
1654444366.532,,1.000000e+004,3.033223e+002,3.824289e-004,6.536055e-008,-8.406639e-002,4.260730e-004,3,9.617420e-001,1.825000e+000,,,,,,,,,,,,,,,,,,0,4.000000e+000,1.000000e+000,2,2,4.424133e-001,0,,0,
1654445177.889,,1.000000e+004,3.312150e+002,3.710182e-004,1.181264e-008,-9.835438e-002,1.720908e-004,3,9.612387e-001,1.825000e+000,,,,,,,,,,,,,,,,,,0,4.000000e+000,1.000000e+000,2,2,4.024963e-001,0,,0,
1654446017.797,,1.000000e+004,3.592224e+002,3.699887e-004,3.632285e-008,-1.119353e-001,1.619440e-004,3,9.611768e-001,1.825000e+000,,,,,,,,,,,,,,,,,,0,4.000000e+000,1.000000e+000,2,2,3.737793e-001,0,,0,
1654446856.564,,1.000000e+004,3.872119e+002,1.084419e-003,3.459828e-007,-1.504780e-001,2.674217e-005,3,9.781430e-001,1.825000e+000,,,,,,,,,,,,,,,,,,0,4.000000e+000,1.000000e+000,2,2,3.887024e-001,0,,0,
1654448198.331,,1.500000e+004,3.856275e+002,1.625375e-003,7.895949e-007,-1.404370e-001,1.377043e-004,3,9.786135e-001,1.825000e+000,,,,,,,,,,,,,,,,,,0,4.000000e+000,1.000000e+000,2,2,5.780945e-001,0,,0,
1654449219.437,,1.500000e+004,3.574972e+002,1.693705e-003,3.901876e-007,-1.303331e-001,2.578334e-004,3,9.787320e-001,1.825000e+000,,,,,,,,,,,,,,,,,,0,4.000000e+000,1.000000e+000,2,2,7.811890e-001,0,,0,
1654449930.477,,1.500000e+004,3.297280e+002,5.481638e-004,7.478597e-008,-9.338340e-002,5.193440e-004,3,9.625491e-001,1.825000e+000,,,,,,,,,,,,,,,,,,0,4.000000e+000,1.000000e+000,2,2,4.941101e-001,0,,0,
1654450859.101,,1.500000e+004,3.017051e+002,5.640060e-004,2.524695e-007,-8.594669e-002,3.705235e-005,3,9.629418e-001,1.825000e+000,,,,,,,,,,,,,,,,,,0,4.000000e+000,1.000000e+000,2,2,5.162964e-001,0,,0,
1654452163.863,,1.500000e+004,3.252493e+002,5.480199e-004,1.258232e-007,-1.001266e-001,1.277366e-004,3,9.625014e-001,1.825000e+000,,,,,,,,,,,,,,,,,,0,4.000000e+000,1.000000e+000,2,2,4.546204e-001,0,,0,
1654453002.610,,1.500000e+004,3.532310e+002,5.419849e-004,9.894631e-008,-1.136123e-001,2.998222e-004,3,9.624497e-001,1.825000e+000,,,,,,,,,,,,,,,,,,0,4.000000e+000,1.000000e+000,2,2,4.111023e-001,0,,0,
1654453849.557,,1.500000e+004,3.814715e+002,1.583246e-003,1.053128e-005,-1.494689e-001,3.464471e-005,3,9.780819e-001,1.825000e+000,,,,,,,,,,,,,,,,,,0,4.000000e+000,1.000000e+000,2,2,4.004211e-001,0,,0,
1654455268.090,,2.000000e+004,3.915745e+002,2.136588e-003,9.026999e-007,-1.450032e-001,4.913796e-004,3,9.785424e-001,1.825000e+000,,,,,,,,,,,,,,,,,,0,4.000000e+000,1.000000e+000,2,2,8.577881e-001,0,,0,
1654456022.147,,2.000000e+004,3.636695e+002,2.240219e-003,8.185708e-007,-1.312811e-001,1.680922e-004,3,9.788806e-001,1.825000e+000,,,,,,,,,,,,,,,,,,0,4.000000e+000,1.000000e+000,2,2,4.689026e-001,0,,0,
1654456997.367,,2.000000e+004,3.354443e+002,7.217843e-004,1.078367e-007,-9.875764e-002,1.365242e-004,3,9.631499e-001,1.825000e+000,,,,,,,,,,,,,,,,,,0,4.000000e+000,1.000000e+000,2,2,7.304077e-001,0,,0,
1654457831.983,,2.000000e+004,3.079031e+002,7.383229e-004,2.470777e-007,-8.942129e-002,5.694461e-004,3,9.633574e-001,1.825000e+000,,,,,,,,,,,,,,,,,,0,4.000000e+000,1.000000e+000,2,2,1.573181e-001,0,,0,
1654504629.474,,2.000000e+004,3.798771e+002,2.181521e-003,2.515640e-007,-1.455846e-001,3.472373e-004,3,9.787933e-001,1.825000e+000,,,,,,,,,,,,,,,,,,0,4.000000e+000,1.000000e+000,2,2,2.333984e-001,0,,0,
1654505366.229,,2.000000e+004,3.514340e+002,1.115315e-003,7.510577e-005,-1.256681e-001,1.317853e-003,3,9.725412e-001,1.825000e+000,,,,,,,,,,,,,,,,,,0,4.000000e+000,1.000000e+000,2,2,8.926086e-001,0,,0,
1654506293.581,,2.000000e+004,3.238059e+002,7.258751e-004,1.786302e-008,-1.028786e-001,1.431518e-004,3,9.630668e-001,1.825000e+000,,,,,,,,,,,,,,,,,,0,4.000000e+000,1.000000e+000,2,2,3.419189e-001,0,,0,
1654507596.548,,2.000000e+004,3.032426e+002,7.421294e-004,5.632614e-007,-9.805927e-002,2.592505e-004,3,9.630092e-001,1.825000e+000,,,,,,,,,,,,,,,,,,0,4.000000e+000,1.000000e+000,2,2,4.421997e-001,0,,0,
1654508412.073,,2.000000e+004,3.312872e+002,7.192621e-004,1.623312e-007,-1.109097e-001,5.661745e-004,3,9.628218e-001,1.825000e+000,,,,,,,,,,,,,,,,,,0,4.000000e+000,1.000000e+000,2,2,4.114075e-001,0,,0,
1654509250.401,,2.000000e+004,3.592381e+002,7.177378e-004,3.447481e-007,-1.245826e-001,2.528547e-004,3,9.626981e-001,1.825000e+000,,,,,,,,,,,,,,,,,,0,4.000000e+000,1.000000e+000,2,2,3.739929e-001,0,,0,
1654510091.249,,2.000000e+004,3.872999e+002,2.149495e-003,6.111293e-007,-1.578362e-001,1.543102e-004,3,9.784997e-001,1.825000e+000,,,,,,,,,,,,,,,,,,0,4.000000e+000,1.000000e+000,2,2,3.766785e-001,0,,0,
1654511423.294,,2.500000e+004,3.856848e+002,2.697696e-003,6.131049e-007,-1.471145e-001,4.121646e-004,3,9.786575e-001,1.825000e+000,,,,,,,,,,,,,,,,,,0,4.000000e+000,1.000000e+000,2,2,6.865234e-001,0,,0,
1654512459.656,,2.500000e+004,3.575100e+002,2.811772e-003,3.885413e-007,-1.363409e-001,1.088864e-004,3,9.790995e-001,1.825000e+000,,,,,,,,,,,,,,,,,,0,4.000000e+000,1.000000e+000,2,2,7.605896e-001,0,,0,
1654513169.134,,2.500000e+004,3.297084e+002,8.996628e-004,6.182086e-008,-1.009940e-001,5.918155e-004,3,9.636537e-001,1.825000e+000,,,,,,,,,,,,,,,,,,0,4.000000e+000,1.000000e+000,2,2,5.719910e-001,0,,0,
1654514096.553,,2.500000e+004,3.017034e+002,9.262036e-004,3.357754e-007,-9.233965e-002,1.949661e-004,3,9.642272e-001,1.825000e+000,,,,,,,,,,,,,,,,,,0,4.000000e+000,1.000000e+000,2,2,5.520935e-001,0,,0,
1654515396.346,,2.500000e+004,3.252115e+002,8.993236e-004,1.402700e-007,-1.068929e-001,2.363991e-003,3,9.621235e-001,1.825000e+000,,,,,,,,,,,,,,,,,,0,4.000000e+000,1.000000e+000,2,2,4.208984e-001,0,,0,
1654516236.446,,2.500000e+004,3.532610e+002,8.894957e-004,3.364339e-007,-1.177775e-001,2.797603e-004,3,9.633340e-001,1.825000e+000,,,,,,,,,,,,,,,,,,0,4.000000e+000,1.000000e+000,2,2,3.508911e-001,0,,0,
1654517084.174,,2.500000e+004,3.815186e+002,2.649012e-003,1.430276e-005,-1.511055e-001,3.375014e-004,3,9.781695e-001,1.825000e+000,,,,,,,,,,,,,,,,,,0,4.000000e+000,1.000000e+000,2,2,3.533020e-001,0,,0,
1654518504.122,,3.000000e+004,3.914658e+002,3.199271e-003,2.157557e-006,-1.458896e-001,2.043279e-004,3,9.787189e-001,1.825000e+000,,,,,,,,,,,,,,,,,,0,4.000000e+000,1.000000e+000,2,2,8.572998e-001,0,,0,
1654519255.846,,3.000000e+004,3.637548e+002,3.353386e-003,1.268192e-006,-1.318155e-001,7.240829e-005,3,9.789940e-001,1.825000e+000,,,,,,,,,,,,,,,,,,0,4.000000e+000,1.000000e+000,2,2,4.371948e-001,0,,0,
1654520234.703,,3.000000e+004,3.355184e+002,1.073518e-003,1.597794e-007,-1.007034e-001,3.690062e-004,3,9.644561e-001,1.825000e+000,,,,,,,,,,,,,,,,,,0,4.000000e+000,1.000000e+000,2,2,6.856995e-001,0,,0,
1654521048.013,,3.000000e+004,3.079125e+002,1.099430e-003,3.363516e-007,-9.074771e-002,1.089754e-003,3,9.644366e-001,1.825000e+000,,,,,,,,,,,,,,,,,,0,4.000000e+000,1.000000e+000,2,2,1.947021e-001,0,,0,
1654522386.650,,3.000000e+004,3.192444e+002,1.082289e-003,2.966743e-007,-1.004574e-001,1.486256e-004,3,9.642304e-001,1.825000e+000,,,,,,,,,,,,,,,,,,0,4.000000e+000,1.000000e+000,2,2,4.612122e-001,0,,0,
1654523226.293,,3.000000e+004,3.472715e+002,1.063667e-003,3.868949e-008,-1.138655e-001,1.336582e-005,3,9.635216e-001,1.825000e+000,,,,,,,,,,,,,,,,,,0,4.000000e+000,1.000000e+000,2,2,3.869019e-001,0,,0,
1654524066.544,,3.000000e+004,3.752645e+002,1.156189e-003,8.959087e-006,-1.260792e-001,2.112822e-004,3,9.653025e-001,1.825000e+000,,,,,,,,,,,,,,,,,,0,4.000000e+000,1.000000e+000,2,2,3.981934e-001,0,,0,
1654525549.536,,3.500000e+004,3.977794e+002,3.685590e-003,1.997365e-006,-1.497593e-001,4.314784e-005,3,9.786835e-001,1.825000e+000,,,,,,,,,,,,,,,,,,0,4.000000e+000,1.000000e+000,2,2,3.460999e-001,0,,0,
1654526318.325,,3.500000e+004,3.692015e+002,3.880143e-003,2.544781e-006,-1.342174e-001,4.749950e-005,3,9.791179e-001,1.825000e+000,,,,,,,,,,,,,,,,,,0,4.000000e+000,1.000000e+000,2,2,8.358154e-001,0,,0,
1654527265.860,,3.500000e+004,3.418633e+002,1.260696e-003,4.082976e-007,-1.034052e-001,1.474929e-004,3,9.645716e-001,1.825000e+000,,,,,,,,,,,,,,,,,,0,4.000000e+000,1.000000e+000,2,2,2.619934e-001,0,,0,
1654528018.288,,3.500000e+004,3.136580e+002,1.272044e-003,6.130226e-007,-9.272502e-002,1.828172e-004,3,9.647753e-001,1.825000e+000,,,,,,,,,,,,,,,,,,0,4.000000e+000,1.000000e+000,2,2,4.988098e-001,0,,0,
1654529363.556,,3.500000e+004,3.132164e+002,1.269701e-003,6.168916e-007,-9.768498e-002,1.731761e-004,3,9.641408e-001,1.825000e+000,,,,,,,,,,,,,,,,,,0,4.000000e+000,1.000000e+000,2,2,3.962097e-001,0,,0,
1654530211.139,,3.500000e+004,3.413682e+002,1.240456e-003,3.540500e-007,-1.113013e-001,2.980730e-004,3,9.641632e-001,1.825000e+000,,,,,,,,,,,,,,,,,,0,4.000000e+000,1.000000e+000,2,2,4.104004e-001,0,,0,
1654531046.412,,3.500000e+004,3.692178e+002,1.265055e-003,4.629568e-007,-1.248457e-001,5.536516e-005,3,9.640211e-001,1.825000e+000,,,,,,,,,,,,,,,,,,0,4.000000e+000,1.000000e+000,2,2,3.630066e-001,0,,0,
1654531886.887,,3.500000e+004,3.972386e+002,3.687410e-003,7.069475e-007,-1.546862e-001,4.722555e-005,3,9.785854e-001,1.825000e+000,,,,,,,,,,,,,,,,,,0,4.000000e+000,1.000000e+000,2,2,4.348145e-001,0,,0,
1654533398.763,,4.000000e+004,3.755152e+002,4.381597e-003,2.362858e-006,-1.375180e-001,1.220046e-004,3,9.790388e-001,1.825000e+000,,,,,,,,,,,,,,,,,,0,4.000000e+000,1.000000e+000,2,2,8.776245e-001,0,,0,
1654534111.976,,4.000000e+004,3.476056e+002,1.593706e-003,1.513450e-005,-1.083565e-001,3.380388e-004,3,9.670051e-001,1.825000e+000,,,,,,,,,,,,,,,,,,0,4.000000e+000,1.000000e+000,2,2,6.202087e-001,0,,0,
1654535066.001,,4.000000e+004,3.196517e+002,1.441640e-003,3.461475e-007,-9.585173e-002,6.666050e-005,3,9.645514e-001,1.825000e+000,,,,,,,,,,,,,,,,,,0,4.000000e+000,1.000000e+000,2,2,5.599060e-001,0,,0,
1654536362.764,,4.000000e+004,3.072698e+002,1.459807e-003,3.416210e-008,-9.495828e-002,2.979255e-005,3,9.649252e-001,1.825000e+000,,,,,,,,,,,,,,,,,,0,4.000000e+000,1.000000e+000,2,2,4.772034e-001,0,,0,
1654537197.896,,4.000000e+004,3.352998e+002,1.418824e-003,1.201021e-007,-1.087773e-001,8.911951e-005,3,9.642986e-001,1.825000e+000,,,,,,,,,,,,,,,,,,0,4.000000e+000,1.000000e+000,2,2,4.041138e-001,0,,0,
1654538035.693,,4.000000e+004,3.632358e+002,1.426158e-003,3.451597e-007,-1.226104e-001,1.927112e-004,3,9.641626e-001,1.825000e+000,,,,,,,,,,,,,,,,,,0,4.000000e+000,1.000000e+000,2,2,4.039001e-001,0,,0,
1654538877.345,,4.000000e+004,3.912792e+002,4.252234e-003,4.767862e-007,-1.530145e-001,1.880171e-004,3,9.787412e-001,1.825000e+000,,,,,,,,,,,,,,,,,,0,4.000000e+000,1.000000e+000,2,2,4.096069e-001,0,,0,
1654540186.693,,4.500000e+004,3.817838e+002,4.877253e-003,2.535726e-006,-1.383176e-001,5.058676e-005,3,9.790350e-001,1.825000e+000,,,,,,,,,,,,,,,,,,0,4.000000e+000,1.000000e+000,2,2,3.538208e-001,0,,0,
1654541181.302,,4.500000e+004,3.534519e+002,4.241262e-003,2.233082e-004,-1.237293e-001,1.341255e-003,3,9.791943e-001,1.825000e+000,,,,,,,,,,,,,,,,,,0,4.000000e+000,1.000000e+000,2,2,9.135132e-001,0,,0,
1654541971.816,,4.500000e+004,3.259011e+002,1.613103e-003,4.096147e-007,-9.687139e-002,1.682186e-005,3,9.653562e-001,1.825000e+000,,,,,,,,,,,,,,,,,,0,4.000000e+000,1.000000e+000,2,2,1.944885e-001,0,,0,
1654543371.768,,4.500000e+004,3.011951e+002,1.656558e-003,7.797167e-007,-9.140958e-002,8.570561e-005,3,9.655398e-001,1.825000e+000,,,,,,,,,,,,,,,,,,0,4.000000e+000,1.000000e+000,2,2,3.786011e-001,0,,0,
1654544181.621,,4.500000e+004,3.292022e+002,1.603216e-003,2.705795e-007,-1.060379e-001,4.550753e-004,3,9.650897e-001,1.825000e+000,,,,,,,,,,,,,,,,,,0,4.000000e+000,1.000000e+000,2,2,3.800964e-001,0,,0,
1654545023.145,,4.500000e+004,3.572838e+002,1.595152e-003,2.062891e-007,-1.197678e-001,3.311530e-004,3,9.647809e-001,1.825000e+000,,,,,,,,,,,,,,,,,,0,4.000000e+000,1.000000e+000,2,2,4.003906e-001,0,,0,
1654545863.072,,4.500000e+004,3.852635e+002,4.833653e-003,1.288442e-006,-1.510705e-001,6.268290e-005,3,9.788946e-001,1.825000e+000,,,,,,,,,,,,,,,,,,0,4.000000e+000,1.000000e+000,2,2,3.726807e-001,0,,0,
1654547229.632,,5.000000e+004,3.875950e+002,5.364577e-003,2.889693e-006,-1.413101e-001,1.708739e-004,3,9.791061e-001,1.825000e+000,,,,,,,,,,,,,,,,,,0,4.000000e+000,1.000000e+000,2,2,6.572876e-001,0,,0,
1654548240.998,,5.000000e+004,3.597296e+002,5.608751e-003,2.168258e-006,-1.311750e-001,7.708659e-005,3,9.796702e-001,1.825000e+000,,,,,,,,,,,,,,,,,,0,4.000000e+000,1.000000e+000,2,2,5.415039e-001,0,,0,
1654548961.642,,5.000000e+004,3.316160e+002,1.787268e-003,3.108330e-007,-9.931425e-002,4.092354e-004,3,9.655656e-001,1.825000e+000,,,,,,,,,,,,,,,,,,0,4.000000e+000,1.000000e+000,2,2,6.054993e-001,0,,0,
1654549877.194,,5.000000e+004,3.037145e+002,1.836916e-003,7.239050e-007,-9.091377e-002,1.147026e-004,3,9.657688e-001,1.825000e+000,,,,,,,,,,,,,,,,,,0,4.000000e+000,1.000000e+000,2,2,4.874268e-001,0,,0,
1654551170.047,,5.000000e+004,3.232648e+002,1.791633e-003,4.245966e-007,-1.034745e-001,1.432519e-004,3,9.656047e-001,1.825000e+000,,,,,,,,,,,,,,,,,,0,4.000000e+000,1.000000e+000,2,2,4.571228e-001,0,,0,
1654552008.508,,5.000000e+004,3.512232e+002,1.768892e-003,1.755021e-007,-1.169581e-001,2.329088e-004,3,9.650072e-001,1.825000e+000,,,,,,,,,,,,,,,,,,0,4.000000e+000,1.000000e+000,2,2,4.259033e-001,0,,0,
1654552848.349,,5.000000e+004,3.792276e+002,4.401051e-003,1.156835e-004,-1.440201e-001,8.159946e-004,3,9.765462e-001,1.825000e+000,,,,,,,,,,,,,,,,,,0,4.000000e+000,1.000000e+000,2,2,4.302979e-001,0,,0,
1654554314.680,,5.500000e+004,3.934487e+002,5.834186e-003,4.712545e-006,-1.447343e-001,2.279934e-004,3,9.791108e-001,1.825000e+000,,,,,,,,,,,,,,,,,,0,4.000000e+000,1.000000e+000,2,2,8.288879e-001,0,,0,
1654555056.494,,5.500000e+004,3.655740e+002,6.127356e-003,2.631215e-006,-1.309796e-001,1.503062e-004,3,9.794478e-001,1.825000e+000,,,,,,,,,,,,,,,,,,0,4.000000e+000,1.000000e+000,2,2,5.601196e-001,0,,0,
1654556034.313,,5.500000e+004,3.376568e+002,1.963488e-003,3.057293e-007,-1.024203e-001,2.880210e-005,3,9.657518e-001,1.825000e+000,,,,,,,,,,,,,,,,,,0,4.000000e+000,1.000000e+000,2,2,6.380920e-001,0,,0,
1654556803.150,,5.500000e+004,3.098297e+002,2.004822e-003,5.325979e-007,-9.208249e-002,1.252710e-004,3,9.659880e-001,1.825000e+000,,,,,,,,,,,,,,,,,,0,4.000000e+000,1.000000e+000,2,2,3.263855e-001,0,,0,
1654558163.922,,5.500000e+004,3.172550e+002,1.982704e-003,6.690812e-007,-1.003326e-001,9.731181e-005,3,9.655815e-001,1.825000e+000,,,,,,,,,,,,,,,,,,0,4.000000e+000,1.000000e+000,2,2,3.992004e-001,0,,0,
1654559003.773,,5.500000e+004,3.452457e+002,1.944599e-003,2.971693e-008,-1.142681e-001,1.620283e-004,3,9.653105e-001,1.825000e+000,,,,,,,,,,,,,,,,,,0,4.000000e+000,1.000000e+000,2,2,3.725281e-001,0,,0,
1654559843.592,,5.500000e+004,3.732589e+002,2.028076e-003,3.091043e-006,-1.274755e-001,2.009772e-004,3,9.659858e-001,1.825000e+000,,,,,,,,,,,,,,,,,,0,4.000000e+000,1.000000e+000,2,2,3.712769e-001,0,,0,
1654561286.295,,6.000000e+004,4.000108e+002,6.283354e-003,1.264405e-007,-1.494464e-001,2.834395e-006,3,9.788973e-001,1.825000e+000,,,,,,,,,,,,,,,,,,0,4.000000e+000,1.000000e+000,2,2,2.590942e-002,0,,0,
1654562132.051,,6.000000e+004,3.713314e+002,6.626210e-003,5.020414e-006,-1.339038e-001,1.115627e-004,3,9.795132e-001,1.825000e+000,,,,,,,,,,,,,,,,,,0,4.000000e+000,1.000000e+000,2,2,9.682007e-001,0,,0,
1654562900.723,,6.000000e+004,3.438734e+002,2.202778e-003,3.120349e-006,-1.036764e-001,1.127112e-004,3,9.661146e-001,1.825000e+000,,,,,,,,,,,,,,,,,,0,4.000000e+000,1.000000e+000,2,2,2.462769e-001,0,,0,
1654563819.079,,6.000000e+004,3.156212e+002,2.173288e-003,7.978267e-007,-9.401125e-002,1.161567e-004,3,9.659709e-001,1.825000e+000,,,,,,,,,,,,,,,,,,0,4.000000e+000,1.000000e+000,2,2,5.292053e-001,0,,0,
1654565152.236,,6.000000e+004,3.112792e+002,2.177817e-003,6.815936e-007,-9.708130e-002,8.289758e-005,3,9.654951e-001,1.825000e+000,,,,,,,,,,,,,,,,,,0,4.000000e+000,1.000000e+000,2,2,4.216919e-001,0,,0,
1654565993.010,,6.000000e+004,3.392231e+002,2.124687e-003,2.242344e-007,-1.114650e-001,1.732288e-004,3,9.653677e-001,1.825000e+000,,,,,,,,,,,,,,,,,,0,4.000000e+000,1.000000e+000,2,2,4.049988e-001,0,,0,
1654566834.301,,6.000000e+004,3.672599e+002,2.156756e-003,2.486005e-007,-1.244273e-001,2.327770e-004,3,9.654024e-001,1.825000e+000,,,,,,,,,,,,,,,,,,0,4.000000e+000,1.000000e+000,2,2,3.587952e-001,0,,0,
1654567672.338,,6.000000e+004,3.952210e+002,6.335981e-003,1.009549e-006,-1.533773e-001,8.505234e-005,3,9.789969e-001,1.825000e+000,,,,,,,,,,,,,,,,,,0,4.000000e+000,1.000000e+000,2,2,4.309998e-001,0,,0,
1654569211.108,,6.500000e+004,3.776326e+002,7.096056e-003,5.351662e-006,-1.375817e-001,1.310556e-004,3,9.793366e-001,1.825000e+000,,,,,,,,,,,,,,,,,,0,4.000000e+000,1.000000e+000,2,2,7.148132e-001,0,,0,
1654569922.375,,6.500000e+004,3.495700e+002,2.884980e-003,5.992030e-005,-1.120881e-001,2.949437e-004,3,9.701255e-001,1.825000e+000,,,,,,,,,,,,,,,,,,0,4.000000e+000,1.000000e+000,2,2,6.866150e-001,0,,0,
1654570865.493,,6.500000e+004,3.216918e+002,2.339439e-003,4.275601e-007,-9.696960e-002,3.677839e-004,3,9.661273e-001,1.825000e+000,,,,,,,,,,,,,,,,,,0,4.000000e+000,1.000000e+000,2,2,4.769897e-001,0,,0,
1654572161.153,,6.500000e+004,3.052723e+002,2.378887e-003,7.706617e-007,-9.417350e-002,4.315205e-004,3,9.656080e-001,1.825000e+000,,,,,,,,,,,,,,,,,,0,4.000000e+000,1.000000e+000,2,2,5.073853e-001,0,,0,
1654572985.439,,6.500000e+004,3.332607e+002,2.310242e-003,8.564371e-007,-1.082698e-001,2.064195e-004,3,9.652115e-001,1.825000e+000,,,,,,,,,,,,,,,,,,0,4.000000e+000,1.000000e+000,2,2,3.635864e-001,0,,0,
1654573830.480,,6.500000e+004,3.614461e+002,2.314501e-003,5.418175e-007,-1.220664e-001,1.434889e-004,3,9.654778e-001,1.825000e+000,,,,,,,,,,,,,,,,,,0,4.000000e+000,1.000000e+000,2,2,4.100952e-001,0,,0,
1654574665.214,,6.500000e+004,3.892637e+002,6.935226e-003,1.946987e-006,-1.515181e-001,5.932178e-006,3,9.790660e-001,1.825000e+000,,,,,,,,,,,,,,,,,,0,4.000000e+000,1.000000e+000,2,2,3.684998e-001,0,,0,
1654575993.132,,7.000000e+004,3.837433e+002,7.559951e-003,3.720447e-006,-1.380119e-001,1.943813e-004,3,9.791223e-001,1.825000e+000,,,,,,,,,,,,,,,,,,0,4.000000e+000,1.000000e+000,2,2,5.364075e-001,0,,0,
1654577002.454,,7.000000e+004,3.555678e+002,7.841915e-003,2.569707e-005,-1.281837e-001,3.134672e-005,3,9.796996e-001,1.825000e+000,,,,,,,,,,,,,,,,,,0,4.000000e+000,1.000000e+000,2,2,7.421265e-001,0,,0,
1654577748.251,,7.000000e+004,3.277599e+002,2.507227e-003,2.275271e-007,-9.785059e-002,2.257859e-004,3,9.659451e-001,1.825000e+000,,,,,,,,,,,,,,,,,,0,4.000000e+000,1.000000e+000,2,2,3.338013e-001,0,,0,
1654578902.023,,7.000000e+004,3.000601e+002,2.583832e-003,3.490286e-007,-9.041500e-002,1.641409e-004,3,9.664350e-001,1.825000e+000,,,,,,,,,,,,,,,,,,0,4.000000e+000,1.000000e+000,2,2,2.130127e-002,0,,0,
1654579978.689,,7.000000e+004,3.272536e+002,2.499562e-003,7.242343e-007,-1.058327e-001,1.039973e-004,3,9.659809e-001,1.825000e+000,,,,,,,,,,,,,,,,,,0,4.000000e+000,1.000000e+000,2,2,4.093933e-001,0,,0,
1654580818.471,,7.000000e+004,3.552782e+002,2.480401e-003,8.133025e-008,-1.193775e-001,1.072795e-004,3,9.652333e-001,1.825000e+000,,,,,,,,,,,,,,,,,,0,4.000000e+000,1.000000e+000,2,2,4.161072e-001,0,,0,
1654581657.766,,7.000000e+004,3.832908e+002,7.542296e-003,1.928218e-006,-1.501483e-001,3.604609e-005,3,9.792709e-001,1.825000e+000,,,,,,,,,,,,,,,,,,0,4.000000e+000,1.000000e+000,2,2,3.923950e-001,0,,0,
1654582413.140,,7.000000e+004,3.999914e+002,7.326997e-003,8.956205e-008,-1.528697e-001,6.324134e-005,3,9.789528e-001,1.825000e+000,,,,,,,,,,,,,,,,,,0,4.000000e+000,1.000000e+000,2,2,2.590942e-002,0,,0,