File: spin_crossover/dane/AOT — kopia/Big AOT/FeTrz_AOT_120nm_FC_FH.rso.dat
[Header]
TITLE,MPMS RSO Measurement
BYAPP,MPMS Measurement,1.1,Summary
FILEOPENTIME, 1654265175.331000 6/3/2022, 4:06:15 PM

INFO, APPNAME, MPMS MultiVu Application, Revision 1.60,  Build 081

INFO, NAME, AP_FeTrz_AOT_120nm
INFO, WEIGHT, 4.610
INFO, AREA, 0.000
INFO, LENGTH, 0.000
INFO, SHAPE, 0
INFO, COMMENT, Cu drut, w foli Al
INFO, SEQUENCE FILE: FC_FH_300-390.seq


INFO, BACKGROUND DATA FILE:, None


STARTUPAXIS,X,4,LINEAR,AUTO,0.000000,0.000000
STARTUPAXIS,Y1,5,LINEAR,AUTO,0.000000,0.000000


STARTUPGROUP,Longitudinal
FIELDGROUP,Longitudinal,1,2,3,4,5,6,7,8,9,10,11,19,20,21,22,23,35
FIELDGROUP,Transverse,1,2,3,4,12,13,14,15,16,17,18,24,25,26,27,28,35

PLOT_APPEARANCE,ALL,HORZ_GRID_ON,VERT_GRID_ON,MARKERS_AND_LINES

[Data]
Time,Comment,Field (Oe),Temperature (K),Long Moment (emu),Long Scan Std Dev,Long Offset (cm),Long Offset Std Dev,Long Algorithm,Long Reg Fit,Long Reg Factor,Trans Moment (emu),Trans Scan Std Dev,Trans Offset (cm),Trans Offset Std Dev,Trans Algorithm,Trans Reg Fit,Trans Reg Factor,Long Moment [w/o ABS] (emu),Long Scan Std Dev [w/o ABS],Long Offset [w/o ABS] (cm),Long Offset Std Dev [w/o ABS],Long Reg Fit [w/o ABS],Trans Moment [w/o ABS] (emu),Trans Scan Std Dev [w/o ABS],Trans Offset [w/o ABS] (cm),Trans Offset Std Dev [w/o ABS],Trans Reg Fit [w/o ABS],RSO Position (deg),Amplitude (cm),Frequency,Cycles to Average,Scans per Measurement,Delta Temp (K),Error,EC Comp. Running,Using ABS,
1654265175.330,,1.000000e+003,2.999946e+002,4.678228e-005,1.520312e-008,-2.417562e-002,1.053690e-003,3,9.431939e-001,1.825000e+000,,,,,,,,,,,,,,,,,,0,4.000000e+000,1.000000e+000,2,2,1.409912e-002,0,,0,
1654265340.209,,1.000000e+003,3.021143e+002,4.668240e-005,1.139594e-009,-2.487972e-002,1.075653e-004,3,9.431186e-001,1.825000e+000,,,,,,,,,,,,,,,,,,0,4.000000e+000,1.000000e+000,2,2,2.445068e-001,0,,0,
1654265447.413,,1.000000e+003,3.041278e+002,4.659759e-005,2.193262e-008,-2.560181e-002,9.156930e-004,3,9.435433e-001,1.825000e+000,,,,,,,,,,,,,,,,,,0,4.000000e+000,1.000000e+000,2,2,1.896057e-001,0,,0,
1654265561.037,,1.000000e+003,3.061555e+002,4.648811e-005,1.278245e-008,-2.688852e-002,1.922975e-003,3,9.431334e-001,1.825000e+000,,,,,,,,,,,,,,,,,,0,4.000000e+000,1.000000e+000,2,2,2.218933e-001,0,,0,
1654265673.413,,1.000000e+003,3.081149e+002,4.637693e-005,1.737426e-008,-2.687442e-002,2.093184e-004,3,9.429531e-001,1.825000e+000,,,,,,,,,,,,,,,,,,0,4.000000e+000,1.000000e+000,2,2,2.250977e-001,0,,0,
1654265793.289,,1.000000e+003,3.101469e+002,4.635743e-005,5.641360e-008,-2.663973e-002,1.124965e-004,3,9.432639e-001,1.825000e+000,,,,,,,,,,,,,,,,,,0,4.000000e+000,1.000000e+000,2,2,2.128906e-001,0,,0,
1654265912.217,,1.000000e+003,3.121307e+002,4.623957e-005,1.103577e-008,-2.776279e-002,6.828185e-004,3,9.433877e-001,1.825000e+000,,,,,,,,,,,,,,,,,,0,4.000000e+000,1.000000e+000,2,2,2.005920e-001,0,,0,
1654266033.367,,1.000000e+003,3.141497e+002,4.620639e-005,2.682025e-008,-2.850885e-002,1.635206e-004,3,9.434569e-001,1.825000e+000,,,,,,,,,,,,,,,,,,0,4.000000e+000,1.000000e+000,2,2,2.031860e-001,0,,0,
1654266150.035,,1.000000e+003,3.160976e+002,4.606068e-005,2.422466e-008,-2.962886e-002,1.217194e-003,3,9.427039e-001,1.825000e+000,,,,,,,,,,,,,,,,,,0,4.000000e+000,1.000000e+000,2,2,1.900940e-001,0,,0,
1654266271.223,,1.000000e+003,3.181279e+002,4.604295e-005,1.181264e-008,-3.012513e-002,7.079327e-004,3,9.428116e-001,1.825000e+000,,,,,,,,,,,,,,,,,,0,4.000000e+000,1.000000e+000,2,2,2.088013e-001,0,,0,
1654266391.856,,1.000000e+003,3.201371e+002,4.597869e-005,2.179113e-008,-3.086953e-002,1.036942e-003,3,9.429252e-001,1.825000e+000,,,,,,,,,,,,,,,,,,0,4.000000e+000,1.000000e+000,2,2,2.117004e-001,0,,0,
1654266511.255,,1.000000e+003,3.221325e+002,4.588937e-005,4.517204e-009,-3.142001e-002,1.111544e-004,3,9.427211e-001,1.825000e+000,,,,,,,,,,,,,,,,,,0,4.000000e+000,1.000000e+000,2,2,1.979980e-001,0,,0,
1654266632.137,,1.000000e+003,3.241503e+002,4.581858e-005,1.099203e-008,-3.159927e-002,6.006176e-004,3,9.424175e-001,1.825000e+000,,,,,,,,,,,,,,,,,,0,4.000000e+000,1.000000e+000,2,2,1.838989e-001,0,,0,
1654266750.285,,1.000000e+003,3.261063e+002,4.581160e-005,3.124742e-008,-3.450010e-002,6.908922e-005,3,9.426437e-001,1.825000e+000,,,,,,,,,,,,,,,,,,0,4.000000e+000,1.000000e+000,2,2,2.031860e-001,0,,0,
1654266869.699,,1.000000e+003,3.281025e+002,4.575633e-005,1.664883e-008,-3.505942e-002,3.419769e-004,3,9.427426e-001,1.825000e+000,,,,,,,,,,,,,,,,,,0,4.000000e+000,1.000000e+000,2,2,1.972046e-001,0,,0,
1654266991.080,,1.000000e+003,3.301292e+002,4.567785e-005,1.933703e-008,-3.533528e-002,1.687373e-003,3,9.437067e-001,1.825000e+000,,,,,,,,,,,,,,,,,,0,4.000000e+000,1.000000e+000,2,2,2.086182e-001,0,,0,
1654267108.956,,1.000000e+003,3.320926e+002,4.567624e-005,3.663154e-008,-3.565697e-002,7.767480e-004,3,9.426096e-001,1.825000e+000,,,,,,,,,,,,,,,,,,0,4.000000e+000,1.000000e+000,2,2,1.759949e-001,0,,0,
1654267231.099,,1.000000e+003,3.341476e+002,4.560760e-005,1.797621e-008,-3.610682e-002,2.711170e-003,3,9.429941e-001,1.825000e+000,,,,,,,,,,,,,,,,,,0,4.000000e+000,1.000000e+000,2,2,1.961060e-001,0,,0,
1654267351.027,,1.000000e+003,3.361416e+002,4.555091e-005,1.316832e-008,-3.692614e-002,7.433308e-004,3,9.420353e-001,1.825000e+000,,,,,,,,,,,,,,,,,,0,4.000000e+000,1.000000e+000,2,2,1.987000e-001,0,,0,
1654267469.200,,1.000000e+003,3.381085e+002,4.548870e-005,1.456515e-008,-3.818588e-002,1.479512e-004,3,9.424075e-001,1.825000e+000,,,,,,,,,,,,,,,,,,0,4.000000e+000,1.000000e+000,2,2,2.102966e-001,0,,0,
1654267589.357,,1.000000e+003,3.401207e+002,4.545465e-005,3.009754e-009,-3.861481e-002,4.421837e-004,3,9.417845e-001,1.825000e+000,,,,,,,,,,,,,,,,,,0,4.000000e+000,1.000000e+000,2,2,2.221069e-001,0,,0,
1654267711.483,,1.000000e+003,3.421489e+002,4.543253e-005,1.059331e-008,-3.928735e-002,1.282318e-005,3,9.428570e-001,1.825000e+000,,,,,,,,,,,,,,,,,,0,4.000000e+000,1.000000e+000,2,2,1.875000e-001,0,,0,
1654267830.377,,1.000000e+003,3.441294e+002,4.540205e-005,4.028440e-009,-3.976735e-002,1.902746e-004,3,9.423917e-001,1.825000e+000,,,,,,,,,,,,,,,,,,0,4.000000e+000,1.000000e+000,2,2,2.276917e-001,0,,0,
1654267949.341,,1.000000e+003,3.461269e+002,4.534464e-005,5.706957e-008,-4.079977e-002,1.530795e-003,3,9.421395e-001,1.825000e+000,,,,,,,,,,,,,,,,,,0,4.000000e+000,1.000000e+000,2,2,2.209778e-001,0,,0,
1654268068.717,,1.000000e+003,3.481101e+002,4.539229e-005,2.232620e-008,-4.141638e-002,5.091656e-004,3,9.429018e-001,1.825000e+000,,,,,,,,,,,,,,,,,,0,4.000000e+000,1.000000e+000,2,2,1.943970e-001,0,,0,
1654268188.892,,1.000000e+003,3.501248e+002,4.533349e-005,4.546530e-008,-4.288492e-002,2.139137e-004,3,9.420754e-001,1.825000e+000,,,,,,,,,,,,,,,,,,0,4.000000e+000,1.000000e+000,2,2,1.968079e-001,0,,0,
1654268310.778,,1.000000e+003,3.521543e+002,4.530079e-005,2.871357e-008,-4.322013e-002,1.195311e-004,3,9.415867e-001,1.825000e+000,,,,,,,,,,,,,,,,,,0,4.000000e+000,1.000000e+000,2,2,2.191772e-001,0,,0,
1654268431.262,,1.000000e+003,3.541632e+002,4.528690e-005,2.103741e-008,-4.358926e-002,1.050097e-003,3,9.426201e-001,1.825000e+000,,,,,,,,,,,,,,,,,,0,4.000000e+000,1.000000e+000,2,2,2.419128e-001,0,,0,
1654268548.148,,1.000000e+003,3.561097e+002,4.530959e-005,1.293937e-008,-4.464807e-002,7.765820e-005,3,9.418058e-001,1.825000e+000,,,,,,,,,,,,,,,,,,0,4.000000e+000,1.000000e+000,2,2,2.039185e-001,0,,0,
1654268667.865,,1.000000e+003,3.580994e+002,4.532871e-005,3.602187e-008,-4.483494e-002,1.283659e-003,3,9.420121e-001,1.825000e+000,,,,,,,,,,,,,,,,,,0,4.000000e+000,1.000000e+000,2,2,2.062988e-001,0,,0,
1654268788.502,,1.000000e+003,3.601256e+002,4.534805e-005,5.088800e-008,-4.524974e-002,7.057490e-005,3,9.429295e-001,1.825000e+000,,,,,,,,,,,,,,,,,,0,4.000000e+000,1.000000e+000,2,2,1.983032e-001,0,,0,
1654268909.180,,1.000000e+003,3.621313e+002,4.538358e-005,2.870842e-009,-4.683439e-002,9.067552e-004,3,9.419348e-001,1.825000e+000,,,,,,,,,,,,,,,,,,0,4.000000e+000,1.000000e+000,2,2,2.218018e-001,0,,0,
1654269028.321,,1.000000e+003,3.641122e+002,4.538835e-005,3.684762e-008,-4.635343e-002,9.852168e-004,3,9.425236e-001,1.825000e+000,,,,,,,,,,,,,,,,,,0,4.000000e+000,1.000000e+000,2,2,2.030029e-001,0,,0,
1654269148.450,,1.000000e+003,3.661242e+002,4.544309e-005,3.700712e-008,-4.709705e-002,1.415739e-004,3,9.418128e-001,1.825000e+000,,,,,,,,,,,,,,,,,,0,4.000000e+000,1.000000e+000,2,2,2.161865e-001,0,,0,
1654269267.383,,1.000000e+003,3.681158e+002,4.545555e-005,7.923114e-010,-4.653989e-002,1.436662e-003,3,9.424008e-001,1.825000e+000,,,,,,,,,,,,,,,,,,0,4.000000e+000,1.000000e+000,2,2,2.185974e-001,0,,0,
1654269389.834,,1.000000e+003,3.701524e+002,4.549853e-005,4.944229e-009,-4.765188e-002,3.623602e-004,3,9.427898e-001,1.825000e+000,,,,,,,,,,,,,,,,,,0,4.000000e+000,1.000000e+000,2,2,2.210999e-001,0,,0,
1654269509.750,,1.000000e+003,3.721595e+002,4.557519e-005,1.207246e-008,-4.876599e-002,5.174896e-004,3,9.424073e-001,1.825000e+000,,,,,,,,,,,,,,,,,,0,4.000000e+000,1.000000e+000,2,2,1.789856e-001,0,,0,
1654269627.380,,1.000000e+003,3.741160e+002,4.564322e-005,1.005827e-009,-5.051846e-002,4.320210e-004,3,9.428986e-001,1.825000e+000,,,,,,,,,,,,,,,,,,0,4.000000e+000,1.000000e+000,2,2,2.034912e-001,0,,0,
1654269747.813,,1.000000e+003,3.761285e+002,4.576585e-005,5.827862e-008,-5.038652e-002,6.977174e-004,3,9.432788e-001,1.825000e+000,,,,,,,,,,,,,,,,,,0,4.000000e+000,1.000000e+000,2,2,2.057800e-001,0,,0,
1654269867.562,,1.000000e+003,3.781288e+002,4.583473e-005,1.540893e-009,-5.181167e-002,1.200450e-003,3,9.428625e-001,1.825000e+000,,,,,,,,,,,,,,,,,,0,4.000000e+000,1.000000e+000,2,2,2.080078e-001,0,,0,
1654269986.724,,1.000000e+003,3.801194e+002,4.599011e-005,5.813713e-010,-5.223749e-002,1.259664e-004,3,9.421089e-001,1.825000e+000,,,,,,,,,,,,,,,,,,0,4.000000e+000,1.000000e+000,2,2,1.869202e-001,0,,0,
1654270108.387,,1.000000e+003,3.821409e+002,4.612484e-005,6.263891e-009,-5.416709e-002,4.633098e-004,3,9.429888e-001,1.825000e+000,,,,,,,,,,,,,,,,,,0,4.000000e+000,1.000000e+000,2,2,1.773071e-001,0,,0,
1654270229.344,,1.000000e+003,3.841610e+002,4.630497e-005,3.863804e-009,-5.387941e-002,4.382140e-004,3,9.434557e-001,1.825000e+000,,,,,,,,,,,,,,,,,,0,4.000000e+000,1.000000e+000,2,2,2.270203e-001,0,,0,
1654270346.512,,1.000000e+003,3.861218e+002,4.644583e-005,2.801901e-008,-5.475460e-002,6.311965e-004,3,9.438543e-001,1.825000e+000,,,,,,,,,,,,,,,,,,0,4.000000e+000,1.000000e+000,2,2,2.172852e-001,0,,0,
1654270467.518,,1.000000e+003,3.881342e+002,4.673215e-005,2.957019e-008,-5.585047e-002,1.363443e-003,3,9.423398e-001,1.825000e+000,,,,,,,,,,,,,,,,,,0,4.000000e+000,1.000000e+000,2,2,1.830750e-001,0,,0,
1654270909.243,,1.000000e+003,3.862185e+002,4.689448e-005,3.136318e-008,-5.166567e-002,9.635296e-004,3,9.437462e-001,1.825000e+000,,,,,,,,,,,,,,,,,,0,4.000000e+000,1.000000e+000,2,2,2.900085e-001,0,,0,
1654270986.446,,1.000000e+003,3.881555e+002,4.702978e-005,2.354811e-008,-5.276292e-002,3.522186e-004,3,9.441387e-001,1.825000e+000,,,,,,,,,,,,,,,,,,0,4.000000e+000,1.000000e+000,2,2,3.174133e-001,0,,0,
1654271085.648,,1.000000e+003,3.901315e+002,4.723327e-005,5.262954e-008,-5.417303e-002,3.280368e-004,3,9.442693e-001,1.825000e+000,,,,,,,,,,,,,,,,,,0,4.000000e+000,1.000000e+000,2,2,2.466736e-001,0,,0,
1654271216.827,,1.000000e+003,3.921159e+002,4.762467e-005,2.446647e-008,-5.599217e-002,1.001330e-004,3,9.440964e-001,1.825000e+000,,,,,,,,,,,,,,,,,,0,4.000000e+000,1.000000e+000,2,2,1.744995e-001,0,,0,
1654271344.207,,1.000000e+003,3.940931e+002,4.838259e-005,2.238170e-010,-5.724007e-002,1.149827e-003,3,9.451910e-001,1.825000e+000,,,,,,,,,,,,,,,,,,0,4.000000e+000,1.000000e+000,2,2,1.889038e-001,0,,0,
1654271467.628,,1.000000e+003,3.961321e+002,5.790445e-005,1.096757e-006,-7.271333e-002,1.703043e-003,3,9.513773e-001,1.825000e+000,,,,,,,,,,,,,,,,,,0,4.000000e+000,1.000000e+000,2,2,2.163086e-001,0,,0,
1654271592.025,,1.000000e+003,3.982188e+002,1.078799e-004,9.929926e-007,-1.168418e-001,9.413077e-004,3,9.677564e-001,1.825000e+000,,,,,,,,,,,,,,,,,,0,4.000000e+000,1.000000e+000,2,2,2.310791e-001,0,,0,
1654271825.723,,1.000000e+003,4.000626e+002,1.153910e-004,1.698839e-008,-1.195435e-001,2.842805e-005,3,9.693993e-001,1.825000e+000,,,,,,,,,,,,,,,,,,0,4.000000e+000,1.000000e+000,2,2,2.587891e-002,0,,0,
1654272144.138,,1.000000e+003,3.988264e+002,1.162428e-004,3.467648e-009,-1.180762e-001,6.453736e-005,3,9.697179e-001,1.825000e+000,,,,,,,,,,,,,,,,,,0,4.000000e+000,1.000000e+000,2,2,2.962036e-001,0,,0,
1654272227.017,,1.000000e+003,3.967724e+002,1.166614e-004,2.574497e-008,-1.166491e-001,3.611458e-005,3,9.699433e-001,1.825000e+000,,,,,,,,,,,,,,,,,,0,4.000000e+000,1.000000e+000,2,2,4.083252e-001,0,,0,
1654272285.941,,1.000000e+003,3.946483e+002,1.170923e-004,1.841867e-009,-1.146545e-001,1.329786e-004,3,9.696498e-001,1.825000e+000,,,,,,,,,,,,,,,,,,0,4.000000e+000,1.000000e+000,2,2,4.675293e-001,0,,0,
1654272339.605,,1.000000e+003,3.926841e+002,1.174479e-004,3.863289e-008,-1.133033e-001,3.722041e-004,3,9.698420e-001,1.825000e+000,,,,,,,,,,,,,,,,,,0,4.000000e+000,1.000000e+000,2,2,4.251099e-001,0,,0,
1654272401.732,,1.000000e+003,3.908175e+002,1.177847e-004,2.313652e-008,-1.125381e-001,1.157247e-004,3,9.697605e-001,1.825000e+000,,,,,,,,,,,,,,,,,,0,4.000000e+000,1.000000e+000,2,2,3.342896e-001,0,,0,
1654272706.893,,1.000000e+003,3.889324e+002,1.180013e-004,6.595735e-008,-1.125174e-001,4.773658e-005,3,9.698356e-001,1.825000e+000,,,,,,,,,,,,,,,,,,0,4.000000e+000,1.000000e+000,2,2,1.226196e-001,0,,0,
1654272852.143,,1.000000e+003,3.868599e+002,1.184125e-004,2.490636e-008,-1.113054e-001,2.228989e-004,3,9.693321e-001,1.825000e+000,,,,,,,,,,,,,,,,,,0,4.000000e+000,1.000000e+000,2,2,2.666016e-001,0,,0,
1654272934.560,,1.000000e+003,3.848402e+002,1.188185e-004,2.277123e-008,-1.102487e-001,2.157445e-004,3,9.699126e-001,1.825000e+000,,,,,,,,,,,,,,,,,,0,4.000000e+000,1.000000e+000,2,2,2.879028e-001,0,,0,
1654273023.253,,1.000000e+003,3.828602e+002,1.191300e-004,4.542928e-008,-1.091900e-001,7.588013e-005,3,9.698188e-001,1.825000e+000,,,,,,,,,,,,,,,,,,0,4.000000e+000,1.000000e+000,2,2,2.373047e-001,0,,0,
1654273161.268,,1.000000e+003,3.809131e+002,1.194389e-004,3.452218e-009,-1.085423e-001,5.209983e-004,3,9.697179e-001,1.825000e+000,,,,,,,,,,,,,,,,,,0,4.000000e+000,1.000000e+000,2,2,1.410217e-001,0,,0,
1654273305.735,,1.000000e+003,3.788557e+002,1.197860e-004,7.929287e-008,-1.080524e-001,1.813368e-004,3,9.698269e-001,1.825000e+000,,,,,,,,,,,,,,,,,,0,4.000000e+000,1.000000e+000,2,2,2.204895e-001,0,,0,
1654273418.381,,1.000000e+003,3.768674e+002,1.200542e-004,5.083141e-009,-1.073361e-001,6.442673e-005,3,9.700480e-001,1.825000e+000,,,,,,,,,,,,,,,,,,0,4.000000e+000,1.000000e+000,2,2,1.723022e-001,0,,0,
1654273533.293,,1.000000e+003,3.748666e+002,1.203188e-004,2.293587e-008,-1.063788e-001,1.547738e-004,3,9.701480e-001,1.825000e+000,,,,,,,,,,,,,,,,,,0,4.000000e+000,1.000000e+000,2,2,2.384033e-001,0,,0,
1654273656.674,,1.000000e+003,3.728907e+002,1.205685e-004,5.247777e-010,-1.059374e-001,1.631873e-004,3,9.702834e-001,1.825000e+000,,,,,,,,,,,,,,,,,,0,4.000000e+000,1.000000e+000,2,2,1.571960e-001,0,,0,
1654273781.854,,1.000000e+003,3.708726e+002,1.208203e-004,5.463347e-008,-1.052888e-001,3.233138e-004,3,9.701360e-001,1.825000e+000,,,,,,,,,,,,,,,,,,0,4.000000e+000,1.000000e+000,2,2,2.332153e-001,0,,0,
1654273899.796,,1.000000e+003,3.688771e+002,1.209982e-004,1.892287e-008,-1.043207e-001,1.743668e-004,3,9.705155e-001,1.825000e+000,,,,,,,,,,,,,,,,,,0,4.000000e+000,1.000000e+000,2,2,1.866150e-001,0,,0,
1654274019.975,,1.000000e+003,3.668768e+002,1.211498e-004,7.013499e-008,-1.031890e-001,2.069832e-004,3,9.697863e-001,1.825000e+000,,,,,,,,,,,,,,,,,,0,4.000000e+000,1.000000e+000,2,2,2.170105e-001,0,,0,
1654274141.406,,1.000000e+003,3.648858e+002,1.211022e-004,2.333717e-008,-1.025267e-001,2.675429e-004,3,9.702910e-001,1.825000e+000,,,,,,,,,,,,,,,,,,0,4.000000e+000,1.000000e+000,2,2,2.145996e-001,0,,0,
1654274262.536,,1.000000e+003,3.628801e+002,1.209415e-004,1.359792e-008,-1.020970e-001,4.730457e-005,3,9.700688e-001,1.825000e+000,,,,,,,,,,,,,,,,,,0,4.000000e+000,1.000000e+000,2,2,2.333984e-001,0,,0,
1654274381.545,,1.000000e+003,3.608999e+002,1.203751e-004,6.172311e-008,-1.012009e-001,9.339742e-005,3,9.700001e-001,1.825000e+000,,,,,,,,,,,,,,,,,,0,4.000000e+000,1.000000e+000,2,2,1.781921e-001,0,,0,
1654274502.762,,1.000000e+003,3.588878e+002,1.098991e-004,1.287640e-006,-9.431884e-002,5.594678e-004,3,9.684411e-001,1.825000e+000,,,,,,,,,,,,,,,,,,0,4.000000e+000,1.000000e+000,2,2,2.177124e-001,0,,0,
1654274624.720,,1.000000e+003,3.568659e+002,7.923759e-005,1.288514e-006,-7.659937e-002,8.592320e-004,3,9.604049e-001,1.825000e+000,,,,,,,,,,,,,,,,,,0,4.000000e+000,1.000000e+000,2,2,2.251892e-001,0,,0,
1654274744.370,,1.000000e+003,3.548804e+002,5.903460e-005,5.266581e-007,-4.977476e-002,7.536884e-004,3,9.517503e-001,1.825000e+000,,,,,,,,,,,,,,,,,,0,4.000000e+000,1.000000e+000,2,2,2.225952e-001,0,,0,
1654274864.373,,1.000000e+003,3.528829e+002,5.154783e-005,1.789672e-007,-3.856093e-002,4.494435e-005,3,9.470160e-001,1.825000e+000,,,,,,,,,,,,,,,,,,0,4.000000e+000,1.000000e+000,2,2,2.201233e-001,0,,0,
1654274985.791,,1.000000e+003,3.508645e+002,4.873136e-005,1.172672e-007,-3.345505e-002,7.251549e-004,3,9.453703e-001,1.825000e+000,,,,,,,,,,,,,,,,,,0,4.000000e+000,1.000000e+000,2,2,2.174072e-001,0,,0,
1654275105.529,,1.000000e+003,3.488726e+002,4.784923e-005,4.575855e-008,-3.128021e-002,5.706420e-005,3,9.446840e-001,1.825000e+000,,,,,,,,,,,,,,,,,,0,4.000000e+000,1.000000e+000,2,2,1.856079e-001,0,,0,
1654275226.908,,1.000000e+003,3.468609e+002,4.748834e-005,5.273501e-009,-2.934707e-002,2.882963e-004,3,9.445323e-001,1.825000e+000,,,,,,,,,,,,,,,,,,0,4.000000e+000,1.000000e+000,2,2,2.315063e-001,0,,0,
1654275346.063,,1.000000e+003,3.448878e+002,4.734249e-005,1.129815e-008,-2.849437e-002,1.861653e-004,3,9.443176e-001,1.825000e+000,,,,,,,,,,,,,,,,,,0,4.000000e+000,1.000000e+000,2,2,2.191772e-001,0,,0,
1654275467.439,,1.000000e+003,3.428723e+002,4.730850e-005,1.881225e-008,-2.732624e-002,3.153348e-004,3,9.439721e-001,1.825000e+000,,,,,,,,,,,,,,,,,,0,4.000000e+000,1.000000e+000,2,2,2.259827e-001,0,,0,
1654275586.878,,1.000000e+003,3.408838e+002,4.730664e-005,2.733474e-008,-2.740799e-002,5.926585e-004,3,9.439391e-001,1.825000e+000,,,,,,,,,,,,,,,,,,0,4.000000e+000,1.000000e+000,2,2,2.045288e-001,0,,0,
1654275708.267,,1.000000e+003,3.388736e+002,4.732041e-005,3.573118e-008,-2.626724e-002,1.336753e-004,3,9.441398e-001,1.825000e+000,,,,,,,,,,,,,,,,,,0,4.000000e+000,1.000000e+000,2,2,2.203979e-001,0,,0,
1654275829.213,,1.000000e+003,3.368678e+002,4.737320e-005,4.919790e-008,-2.639982e-002,4.595153e-004,3,9.442305e-001,1.825000e+000,,,,,,,,,,,,,,,,,,0,4.000000e+000,1.000000e+000,2,2,2.086182e-001,0,,0,
1654275949.156,,1.000000e+003,3.348692e+002,4.741637e-005,1.947338e-009,-2.519252e-002,2.659163e-004,3,9.431349e-001,1.825000e+000,,,,,,,,,,,,,,,,,,0,4.000000e+000,1.000000e+000,2,2,2.149963e-001,0,,0,
1654276070.045,,1.000000e+003,3.328644e+002,4.743863e-005,1.268727e-008,-2.413830e-002,5.143759e-004,3,9.438061e-001,1.825000e+000,,,,,,,,,,,,,,,,,,0,4.000000e+000,1.000000e+000,2,2,2.122192e-001,0,,0,
1654276190.188,,1.000000e+003,3.308610e+002,4.750858e-005,1.339726e-008,-2.391418e-002,2.106420e-004,3,9.445459e-001,1.825000e+000,,,,,,,,,,,,,,,,,,0,4.000000e+000,1.000000e+000,2,2,2.095032e-001,0,,0,
1654276309.852,,1.000000e+003,3.288635e+002,4.756219e-005,2.284326e-008,-2.320075e-002,4.679973e-004,3,9.443281e-001,1.825000e+000,,,,,,,,,,,,,,,,,,0,4.000000e+000,1.000000e+000,2,2,1.811218e-001,0,,0,
1654276430.229,,1.000000e+003,3.268681e+002,4.762871e-005,6.088965e-009,-2.331221e-002,7.394190e-004,3,9.443292e-001,1.825000e+000,,,,,,,,,,,,,,,,,,0,4.000000e+000,1.000000e+000,2,2,1.786804e-001,0,,0,
1654276551.156,,1.000000e+003,3.248751e+002,4.766263e-005,2.045091e-009,-2.171056e-002,6.533288e-005,3,9.442899e-001,1.825000e+000,,,,,,,,,,,,,,,,,,0,4.000000e+000,1.000000e+000,2,2,2.183838e-001,0,,0,
1654276669.650,,1.000000e+003,3.228953e+002,4.771904e-005,3.220437e-008,-2.202513e-002,6.041171e-004,3,9.439642e-001,1.825000e+000,,,,,,,,,,,,,,,,,,0,4.000000e+000,1.000000e+000,2,2,2.072754e-001,0,,0,
1654276791.292,,1.000000e+003,3.208675e+002,4.782285e-005,4.106900e-008,-2.208755e-002,9.693801e-004,3,9.443207e-001,1.825000e+000,,,,,,,,,,,,,,,,,,0,4.000000e+000,1.000000e+000,2,2,2.127075e-001,0,,0,
1654276911.554,,1.000000e+003,3.188767e+002,4.781551e-005,4.329416e-009,-2.197963e-002,2.098207e-003,3,9.435151e-001,1.825000e+000,,,,,,,,,,,,,,,,,,0,4.000000e+000,1.000000e+000,2,2,2.098999e-001,0,,0,
1654277032.203,,1.000000e+003,3.168542e+002,4.792793e-005,1.031034e-008,-2.040525e-002,3.930022e-004,3,9.446689e-001,1.825000e+000,,,,,,,,,,,,,,,,,,0,4.000000e+000,1.000000e+000,2,2,1.991272e-001,0,,0,
1654277151.115,,1.000000e+003,3.148767e+002,4.803283e-005,1.556328e-009,-1.987097e-002,8.855870e-004,3,9.444849e-001,1.825000e+000,,,,,,,,,,,,,,,,,,0,4.000000e+000,1.000000e+000,2,2,2.120972e-001,0,,0,
1654277272.242,,1.000000e+003,3.128535e+002,4.809886e-005,6.790211e-008,-1.978043e-002,1.135726e-004,3,9.444121e-001,1.825000e+000,,,,,,,,,,,,,,,,,,0,4.000000e+000,1.000000e+000,2,2,2.015076e-001,0,,0,
1654277391.368,,1.000000e+003,3.108714e+002,4.817214e-005,3.266998e-009,-1.972941e-002,2.490484e-004,3,9.451963e-001,1.825000e+000,,,,,,,,,,,,,,,,,,0,4.000000e+000,1.000000e+000,2,2,2.141113e-001,0,,0,
1654277511.760,,1.000000e+003,3.088764e+002,4.829367e-005,1.369567e-008,-1.861600e-002,2.345367e-004,3,9.451526e-001,1.825000e+000,,,,,,,,,,,,,,,,,,0,4.000000e+000,1.000000e+000,2,2,2.185974e-001,0,,0,
1654277631.431,,1.000000e+003,3.068825e+002,4.832853e-005,5.944908e-009,-1.802503e-002,6.822745e-004,3,9.451818e-001,1.825000e+000,,,,,,,,,,,,,,,,,,0,4.000000e+000,1.000000e+000,2,2,2.231140e-001,0,,0,
1654277751.056,,1.000000e+003,3.048903e+002,4.838871e-005,3.713316e-008,-1.720283e-002,4.392782e-004,3,9.441626e-001,1.825000e+000,,,,,,,,,,,,,,,,,,0,4.000000e+000,1.000000e+000,2,2,2.127075e-001,0,,0,
1654277871.697,,1.000000e+003,3.028805e+002,4.852958e-005,2.288699e-008,-1.817808e-002,7.294249e-004,3,9.447715e-001,1.825000e+000,,,,,,,,,,,,,,,,,,0,4.000000e+000,1.000000e+000,2,2,1.951904e-001,0,,0,
1654277992.072,,1.000000e+003,3.008615e+002,4.865345e-005,4.847762e-008,-1.712049e-002,7.668408e-004,3,9.450972e-001,1.825000e+000,,,,,,,,,,,,,,,,,,0,4.000000e+000,1.000000e+000,2,2,2.138977e-001,0,,0,
1654278597.498,,1.000000e+003,3.000087e+002,4.863651e-005,3.371697e-008,-1.750396e-002,1.402278e-004,3,9.441901e-001,1.825000e+000,,,,,,,,,,,,,,,,,,0,4.000000e+000,1.000000e+000,2,2,1.422119e-002,0,,0,
1654278756.920,,1.000000e+003,3.021485e+002,4.851982e-005,2.269663e-008,-1.949562e-002,2.250536e-004,3,9.451606e-001,1.825000e+000,,,,,,,,,,,,,,,,,,0,4.000000e+000,1.000000e+000,2,2,2.517090e-001,0,,0,
1654278857.342,,1.000000e+003,3.041114e+002,4.844174e-005,5.543608e-009,-2.020546e-002,2.355890e-004,3,9.453145e-001,1.825000e+000,,,,,,,,,,,,,,,,,,0,4.000000e+000,1.000000e+000,2,2,2.260742e-001,0,,0,
1654278973.506,,1.000000e+003,3.061315e+002,4.833852e-005,1.125957e-008,-2.162603e-002,7.678273e-004,3,9.450852e-001,1.825000e+000,,,,,,,,,,,,,,,,,,0,4.000000e+000,1.000000e+000,2,2,2.145081e-001,0,,0,
1654279094.483,,1.000000e+003,3.081299e+002,4.824760e-005,8.419595e-009,-2.156744e-002,2.666499e-004,3,9.441651e-001,1.825000e+000,,,,,,,,,,,,,,,,,,0,4.000000e+000,1.000000e+000,2,2,2.250977e-001,0,,0,
1654279214.893,,1.000000e+003,3.101241e+002,4.816651e-005,2.140784e-008,-2.257311e-002,3.426381e-004,3,9.443252e-001,1.825000e+000,,,,,,,,,,,,,,,,,,0,4.000000e+000,1.000000e+000,2,2,2.128906e-001,0,,0,
1654279335.547,,1.000000e+003,3.121442e+002,4.804266e-005,1.493558e-008,-2.370853e-002,7.880012e-004,3,9.441695e-001,1.825000e+000,,,,,,,,,,,,,,,,,,0,4.000000e+000,1.000000e+000,2,2,1.927795e-001,0,,0,
1654279453.212,,1.000000e+003,3.140988e+002,4.795764e-005,8.049163e-009,-2.486346e-002,2.828304e-004,3,9.442959e-001,1.825000e+000,,,,,,,,,,,,,,,,,,0,4.000000e+000,1.000000e+000,2,2,1.875916e-001,0,,0,
1654279573.587,,1.000000e+003,3.161215e+002,4.790485e-005,4.671293e-008,-2.554743e-002,1.472901e-004,3,9.445747e-001,1.825000e+000,,,,,,,,,,,,,,,,,,0,4.000000e+000,1.000000e+000,2,2,2.061157e-001,0,,0,
1654279693.713,,1.000000e+003,3.181339e+002,4.781546e-005,8.234379e-009,-2.567345e-002,3.035679e-004,3,9.445806e-001,1.825000e+000,,,,,,,,,,,,,,,,,,0,4.000000e+000,1.000000e+000,2,2,2.008057e-001,0,,0,
1654279812.838,,1.000000e+003,3.201147e+002,4.773911e-005,2.613856e-008,-2.654087e-002,7.045214e-004,3,9.447231e-001,1.825000e+000,,,,,,,,,,,,,,,,,,0,4.000000e+000,1.000000e+000,2,2,1.871948e-001,0,,0,
1654279934.483,,1.000000e+003,3.221469e+002,4.761951e-005,9.710959e-009,-2.734803e-002,5.435679e-004,3,9.439240e-001,1.825000e+000,,,,,,,,,,,,,,,,,,0,4.000000e+000,1.000000e+000,2,2,2.062073e-001,0,,0,
1654280054.421,,1.000000e+003,3.241482e+002,4.760998e-005,3.035479e-009,-2.879369e-002,1.413546e-003,3,9.443079e-001,1.825000e+000,,,,,,,,,,,,,,,,,,0,4.000000e+000,1.000000e+000,2,2,2.005920e-001,0,,0,
1654280173.166,,1.000000e+003,3.261253e+002,4.747864e-005,3.827790e-009,-2.932823e-002,4.516061e-004,3,9.432460e-001,1.825000e+000,,,,,,,,,,,,,,,,,,0,4.000000e+000,1.000000e+000,2,2,1.777954e-001,0,,0,
1654280292.378,,1.000000e+003,3.281175e+002,4.742711e-005,2.804988e-008,-2.971190e-002,1.130692e-003,3,9.441733e-001,1.825000e+000,,,,,,,,,,,,,,,,,,0,4.000000e+000,1.000000e+000,2,2,1.716003e-001,0,,0,
1654280413.553,,1.000000e+003,3.301271e+002,4.736487e-005,2.304649e-008,-3.065629e-002,7.103035e-004,3,9.435532e-001,1.825000e+000,,,,,,,,,,,,,,,,,,0,4.000000e+000,1.000000e+000,2,2,2.345886e-001,0,,0,
1654280532.984,,1.000000e+003,3.321255e+002,4.725824e-005,3.416457e-008,-3.192164e-002,2.332696e-004,3,9.438868e-001,1.825000e+000,,,,,,,,,,,,,,,,,,0,4.000000e+000,1.000000e+000,2,2,2.376099e-001,0,,0,
1654280651.962,,1.000000e+003,3.341097e+002,4.724854e-005,1.570989e-008,-3.233815e-002,5.580243e-005,3,9.441543e-001,1.825000e+000,,,,,,,,,,,,,,,,,,0,4.000000e+000,1.000000e+000,2,2,2.051086e-001,0,,0,
1654280773.599,,1.000000e+003,3.361461e+002,4.718226e-005,1.698325e-008,-3.326172e-002,3.895001e-004,3,9.436762e-001,1.825000e+000,,,,,,,,,,,,,,,,,,0,4.000000e+000,1.000000e+000,2,2,1.987000e-001,0,,0,
1654280893.783,,1.000000e+003,3.381496e+002,4.715116e-005,5.332668e-009,-3.369612e-002,4.952518e-005,3,9.433329e-001,1.825000e+000,,,,,,,,,,,,,,,,,,0,4.000000e+000,1.000000e+000,2,2,2.012024e-001,0,,0,
1654281012.718,,1.000000e+003,3.401254e+002,4.706944e-005,3.076638e-008,-3.532072e-002,4.373657e-004,3,9.436734e-001,1.825000e+000,,,,,,,,,,,,,,,,,,0,4.000000e+000,1.000000e+000,2,2,2.313843e-001,0,,0,
1654281132.369,,1.000000e+003,3.421302e+002,4.705481e-005,3.441924e-009,-3.644753e-002,9.332629e-005,3,9.437324e-001,1.825000e+000,,,,,,,,,,,,,,,,,,0,4.000000e+000,1.000000e+000,2,2,2.249146e-001,0,,0,
1654281252.746,,1.000000e+003,3.441389e+002,4.697574e-005,4.121562e-008,-3.621370e-002,4.523463e-004,3,9.431281e-001,1.825000e+000,,,,,,,,,,,,,,,,,,0,4.000000e+000,1.000000e+000,2,2,2.087097e-001,0,,0,
1654281373.121,,1.000000e+003,3.461437e+002,4.695579e-005,1.273872e-008,-3.672463e-002,7.690562e-004,3,9.436278e-001,1.825000e+000,,,,,,,,,,,,,,,,,,0,4.000000e+000,1.000000e+000,2,2,1.921997e-001,0,,0,
1654281490.010,,1.000000e+003,3.481028e+002,4.695333e-005,3.918597e-008,-3.890822e-002,1.059493e-004,3,9.440509e-001,1.825000e+000,,,,,,,,,,,,,,,,,,0,4.000000e+000,1.000000e+000,2,2,1.943970e-001,0,,0,
1654281611.460,,1.000000e+003,3.501346e+002,4.694997e-005,2.206896e-008,-3.944740e-002,1.520500e-004,3,9.437609e-001,1.825000e+000,,,,,,,,,,,,,,,,,,0,4.000000e+000,1.000000e+000,2,2,2.164917e-001,0,,0,
1654281731.150,,1.000000e+003,3.521293e+002,4.691087e-005,7.508952e-009,-3.922576e-002,5.727467e-004,3,9.435445e-001,1.825000e+000,,,,,,,,,,,,,,,,,,0,4.000000e+000,1.000000e+000,2,2,1.991882e-001,0,,0,
1654281852.031,,1.000000e+003,3.541305e+002,4.689627e-005,2.617714e-008,-4.070482e-002,1.387948e-004,3,9.432892e-001,1.825000e+000,,,,,,,,,,,,,,,,,,0,4.000000e+000,1.000000e+000,2,2,2.318115e-001,0,,0,
1654281972.675,,1.000000e+003,3.561505e+002,4.692918e-005,2.393398e-008,-4.149597e-002,6.053499e-004,3,9.431965e-001,1.825000e+000,,,,,,,,,,,,,,,,,,0,4.000000e+000,1.000000e+000,2,2,2.040100e-001,0,,0,
1654282090.875,,1.000000e+003,3.581252e+002,4.692910e-005,5.265012e-008,-4.238874e-002,4.512452e-004,3,9.435403e-001,1.825000e+000,,,,,,,,,,,,,,,,,,0,4.000000e+000,1.000000e+000,2,2,1.856995e-001,0,,0,
1654282210.392,,1.000000e+003,3.601178e+002,4.691507e-005,3.670872e-009,-4.257745e-002,7.025195e-004,3,9.438676e-001,1.825000e+000,,,,,,,,,,,,,,,,,,0,4.000000e+000,1.000000e+000,2,2,2.087097e-001,0,,0,
1654282331.571,,1.000000e+003,3.621470e+002,4.690909e-005,4.643254e-009,-4.352523e-002,7.954190e-004,3,9.427101e-001,1.825000e+000,,,,,,,,,,,,,,,,,,0,4.000000e+000,1.000000e+000,2,2,2.217102e-001,0,,0,
1654282450.247,,1.000000e+003,3.641336e+002,4.696963e-005,4.461896e-008,-4.504646e-002,6.945985e-004,3,9.438449e-001,1.825000e+000,,,,,,,,,,,,,,,,,,0,4.000000e+000,1.000000e+000,2,2,1.816101e-001,0,,0,
1654282572.630,,1.000000e+003,3.661647e+002,4.698016e-005,2.960106e-008,-4.598570e-002,5.979399e-004,3,9.445360e-001,1.825000e+000,,,,,,,,,,,,,,,,,,0,4.000000e+000,1.000000e+000,2,2,2.054138e-001,0,,0,
1654282690.162,,1.000000e+003,3.681240e+002,4.706495e-005,4.252243e-009,-4.633397e-002,2.756088e-004,3,9.434530e-001,1.825000e+000,,,,,,,,,,,,,,,,,,0,4.000000e+000,1.000000e+000,2,2,1.966858e-001,0,,0,
1654282809.854,,1.000000e+003,3.701192e+002,4.712668e-005,2.326771e-008,-4.725622e-002,1.484104e-003,3,9.443846e-001,1.825000e+000,,,,,,,,,,,,,,,,,,0,4.000000e+000,1.000000e+000,2,2,1.990051e-001,0,,0,
1654282931.352,,1.000000e+003,3.721568e+002,4.719396e-005,3.023903e-008,-4.787958e-002,4.909397e-004,3,9.444230e-001,1.825000e+000,,,,,,,,,,,,,,,,,,0,4.000000e+000,1.000000e+000,2,2,2.236938e-001,0,,0,
1654283051.322,,1.000000e+003,3.741330e+002,4.725531e-005,2.037115e-008,-4.923188e-002,1.083024e-003,3,9.432840e-001,1.825000e+000,,,,,,,,,,,,,,,,,,0,4.000000e+000,1.000000e+000,2,2,2.033997e-001,0,,0,
1654283170.981,,1.000000e+003,3.761456e+002,4.735707e-005,3.567975e-009,-4.935294e-002,8.057687e-005,3,9.437065e-001,1.825000e+000,,,,,,,,,,,,,,,,,,0,4.000000e+000,1.000000e+000,2,2,2.058105e-001,0,,0,
1654283288.171,,1.000000e+003,3.781028e+002,4.755401e-005,2.720097e-008,-5.070325e-002,3.483437e-005,3,9.442009e-001,1.825000e+000,,,,,,,,,,,,,,,,,,0,4.000000e+000,1.000000e+000,2,2,1.965027e-001,0,,0,
1654283409.137,,1.000000e+003,3.801136e+002,4.772222e-005,2.788267e-008,-5.168386e-002,7.719985e-005,3,9.441934e-001,1.825000e+000,,,,,,,,,,,,,,,,,,0,4.000000e+000,1.000000e+000,2,2,2.218933e-001,0,,0,
1654283530.767,,1.000000e+003,3.821439e+002,4.796216e-005,2.779264e-008,-5.306799e-002,1.523298e-003,3,9.447199e-001,1.825000e+000,,,,,,,,,,,,,,,,,,0,4.000000e+000,1.000000e+000,2,2,1.654053e-001,0,,0,
1654283650.952,,1.000000e+003,3.841520e+002,4.849558e-005,4.659460e-008,-5.448824e-002,1.474955e-004,3,9.451396e-001,1.825000e+000,,,,,,,,,,,,,,,,,,0,4.000000e+000,1.000000e+000,2,2,1.672058e-001,0,,0,
1654283768.332,,1.000000e+003,3.861128e+002,5.196829e-005,2.553018e-007,-5.901572e-002,8.972011e-004,3,9.469594e-001,1.825000e+000,,,,,,,,,,,,,,,,,,0,4.000000e+000,1.000000e+000,2,2,1.931763e-001,0,,0,
1654283889.212,,1.000000e+003,3.881220e+002,6.879908e-005,1.098000e-006,-8.185523e-002,2.181047e-003,3,9.560288e-001,1.825000e+000,,,,,,,,,,,,,,,,,,0,4.000000e+000,1.000000e+000,2,2,2.074890e-001,0,,0,
1654284009.873,,1.000000e+003,3.901500e+002,1.068560e-004,1.370261e-006,-1.132174e-001,7.901691e-004,3,9.675753e-001,1.825000e+000,,,,,,,,,,,,,,,,,,0,4.000000e+000,1.000000e+000,2,2,2.220764e-001,0,,0,
1654284129.327,,1.000000e+003,3.921284e+002,1.168643e-004,1.900518e-008,-1.191614e-001,6.618899e-004,3,9.697712e-001,1.825000e+000,,,,,,,,,,,,,,,,,,0,4.000000e+000,1.000000e+000,2,2,1.994934e-001,0,,0,
1654284248.958,,1.000000e+003,3.941183e+002,1.168111e-004,4.360285e-008,-1.196768e-001,1.575554e-004,3,9.695801e-001,1.825000e+000,,,,,,,,,,,,,,,,,,0,4.000000e+000,1.000000e+000,2,2,2.141724e-001,0,,0,
1654284367.173,,1.000000e+003,3.960907e+002,1.166739e-004,4.512059e-008,-1.200767e-001,1.143286e-004,3,9.697091e-001,1.825000e+000,,,,,,,,,,,,,,,,,,0,4.000000e+000,1.000000e+000,2,2,1.781006e-001,0,,0,
1654284489.054,,1.000000e+003,3.981321e+002,1.164714e-004,6.070957e-010,-1.205297e-001,9.966676e-005,3,9.692674e-001,1.825000e+000,,,,,,,,,,,,,,,,,,0,4.000000e+000,1.000000e+000,2,2,2.310791e-001,0,,0,
1654284854.273,,1.000000e+003,3.999816e+002,1.164868e-004,4.226003e-008,-1.192510e-001,4.719288e-004,3,9.691808e-001,1.825000e+000,,,,,,,,,,,,,,,,,,0,4.000000e+000,1.000000e+000,2,2,1.300049e-002,0,,0,
1654285174.415,,1.000000e+003,3.988329e+002,1.168269e-004,1.943735e-008,-1.170645e-001,2.174145e-004,3,9.695182e-001,1.825000e+000,,,,,,,,,,,,,,,,,,0,4.000000e+000,1.000000e+000,2,2,2.962036e-001,0,,0,
1654285260.543,,1.000000e+003,3.967181e+002,1.172604e-004,1.129815e-008,-1.150578e-001,1.191913e-004,3,9.696475e-001,1.825000e+000,,,,,,,,,,,,,,,,,,0,4.000000e+000,1.000000e+000,2,2,3.571167e-001,0,,0,
1654285314.028,,1.000000e+003,3.947178e+002,1.176558e-004,2.572954e-008,-1.140771e-001,2.082054e-005,3,9.696264e-001,1.825000e+000,,,,,,,,,,,,,,,,,,0,4.000000e+000,1.000000e+000,2,2,4.677124e-001,0,,0,
1654285367.404,,1.000000e+003,3.927685e+002,1.180285e-004,2.567300e-009,-1.126746e-001,1.114521e-004,3,9.697517e-001,1.825000e+000,,,,,,,,,,,,,,,,,,0,4.000000e+000,1.000000e+000,2,2,4.628906e-001,0,,0,
1654285430.606,,1.000000e+003,3.908051e+002,1.183748e-004,3.889014e-008,-1.116719e-001,4.600065e-004,3,9.700239e-001,1.825000e+000,,,,,,,,,,,,,,,,,,0,4.000000e+000,1.000000e+000,2,2,3.218994e-001,0,,0,
1654285732.276,,1.000000e+003,3.889538e+002,1.186308e-004,5.988639e-009,-1.115467e-001,1.294540e-004,3,9.696285e-001,1.825000e+000,,,,,,,,,,,,,,,,,,0,4.000000e+000,1.000000e+000,2,2,1.104126e-001,0,,0,
1654285879.186,,1.000000e+003,3.868478e+002,1.190420e-004,4.208511e-009,-1.107030e-001,1.923582e-004,3,9.697642e-001,1.825000e+000,,,,,,,,,,,,,,,,,,0,4.000000e+000,1.000000e+000,2,2,2.666016e-001,0,,0,
1654285961.813,,1.000000e+003,3.848312e+002,1.194435e-004,1.993641e-008,-1.102134e-001,2.153388e-004,3,9.699568e-001,1.825000e+000,,,,,,,,,,,,,,,,,,0,4.000000e+000,1.000000e+000,2,2,3.237915e-001,0,,0,
1654286050.015,,1.000000e+003,3.828721e+002,1.197373e-004,1.530087e-008,-1.092906e-001,1.163253e-005,3,9.699545e-001,1.825000e+000,,,,,,,,,,,,,,,,,,0,4.000000e+000,1.000000e+000,2,2,2.373047e-001,0,,0,
1654286193.173,,1.000000e+003,3.808837e+002,1.201078e-004,2.124841e-009,-1.081590e-001,4.435113e-004,3,9.699731e-001,1.825000e+000,,,,,,,,,,,,,,,,,,0,4.000000e+000,1.000000e+000,2,2,1.643982e-001,0,,0,
1654286334.819,,1.000000e+003,3.788673e+002,1.204304e-004,9.049844e-009,-1.076898e-001,2.832374e-004,3,9.701652e-001,1.825000e+000,,,,,,,,,,,,,,,,,,0,4.000000e+000,1.000000e+000,2,2,2.204895e-001,0,,0,
1654286447.005,,1.000000e+003,3.768760e+002,1.207613e-004,4.819723e-008,-1.065135e-001,1.213250e-004,3,9.699858e-001,1.825000e+000,,,,,,,,,,,,,,,,,,0,4.000000e+000,1.000000e+000,2,2,2.066040e-001,0,,0,
1654286560.692,,1.000000e+003,3.748922e+002,1.211022e-004,2.135131e-009,-1.058070e-001,1.735397e-004,3,9.700588e-001,1.825000e+000,,,,,,,,,,,,,,,,,,0,4.000000e+000,1.000000e+000,2,2,2.043762e-001,0,,0,
1654286685.822,,1.000000e+003,3.728851e+002,1.214182e-004,2.473143e-008,-1.054611e-001,1.883227e-004,3,9.699939e-001,1.825000e+000,,,,,,,,,,,,,,,,,,0,4.000000e+000,1.000000e+000,2,2,1.907959e-001,0,,0,
1654286811.245,,1.000000e+003,3.708587e+002,1.216784e-004,2.922806e-008,-1.046513e-001,1.133329e-004,3,9.703638e-001,1.825000e+000,,,,,,,,,,,,,,,,,,0,4.000000e+000,1.000000e+000,2,2,2.109985e-001,0,,0,
1654286928.652,,1.000000e+003,3.688936e+002,1.219270e-004,7.845942e-009,-1.037165e-001,2.264076e-004,3,9.700589e-001,1.825000e+000,,,,,,,,,,,,,,,,,,0,4.000000e+000,1.000000e+000,2,2,2.086182e-001,0,,0,
1654287050.531,,1.000000e+003,3.668606e+002,1.221603e-004,1.315031e-008,-1.031098e-001,7.852485e-005,3,9.702723e-001,1.825000e+000,,,,,,,,,,,,,,,,,,0,4.000000e+000,1.000000e+000,2,2,1.953125e-001,0,,0,
1654287170.909,,1.000000e+003,3.648858e+002,1.223046e-004,2.809104e-008,-1.022717e-001,1.633190e-006,3,9.703313e-001,1.825000e+000,,,,,,,,,,,,,,,,,,0,4.000000e+000,1.000000e+000,2,2,2.145996e-001,0,,0,
1654287292.245,,1.000000e+003,3.628721e+002,1.223538e-004,9.981065e-009,-1.018436e-001,3.640961e-005,3,9.701698e-001,1.825000e+000,,,,,,,,,,,,,,,,,,0,4.000000e+000,1.000000e+000,2,2,1.910095e-001,0,,0,
1654287412.143,,1.000000e+003,3.608710e+002,1.222842e-004,1.880968e-008,-1.008979e-001,7.041685e-005,3,9.702994e-001,1.825000e+000,,,,,,,,,,,,,,,,,,0,4.000000e+000,1.000000e+000,2,2,1.991882e-001,0,,0,
1654287533.285,,1.000000e+003,3.588619e+002,1.216367e-004,9.855530e-008,-9.954385e-002,3.900480e-004,3,9.703834e-001,1.825000e+000,,,,,,,,,,,,,,,,,,0,4.000000e+000,1.000000e+000,2,2,1.762085e-001,0,,0,
1654287654.964,,1.000000e+003,3.568531e+002,1.001999e-004,1.147344e-006,-8.844243e-002,5.990700e-004,3,9.662281e-001,1.825000e+000,,,,,,,,,,,,,,,,,,0,4.000000e+000,1.000000e+000,2,2,2.354736e-001,0,,0,
1654287774.633,,1.000000e+003,3.548702e+002,7.290530e-005,9.147235e-007,-6.824267e-002,9.485938e-004,3,9.576053e-001,1.825000e+000,,,,,,,,,,,,,,,,,,0,4.000000e+000,1.000000e+000,2,2,2.327881e-001,0,,0,
1654287893.764,,1.000000e+003,3.528879e+002,5.739681e-005,4.514631e-007,-4.624230e-002,9.243015e-004,3,9.512646e-001,1.825000e+000,,,,,,,,,,,,,,,,,,0,4.000000e+000,1.000000e+000,2,2,2.201233e-001,0,,0,
1654288015.186,,1.000000e+003,3.508669e+002,5.177401e-005,1.962437e-007,-3.787519e-002,3.518551e-004,3,9.473987e-001,1.825000e+000,,,,,,,,,,,,,,,,,,0,4.000000e+000,1.000000e+000,2,2,2.273254e-001,0,,0,
1654288137.067,,1.000000e+003,3.488482e+002,4.939326e-005,2.248569e-008,-3.282066e-002,2.687362e-004,3,9.456436e-001,1.825000e+000,,,,,,,,,,,,,,,,,,0,4.000000e+000,1.000000e+000,2,2,2.245178e-001,0,,0,
1654288255.445,,1.000000e+003,3.468826e+002,4.854417e-005,6.927065e-008,-3.136530e-002,1.149081e-004,3,9.448665e-001,1.825000e+000,,,,,,,,,,,,,,,,,,0,4.000000e+000,1.000000e+000,2,2,2.218933e-001,0,,0,
1654288375.820,,1.000000e+003,3.448854e+002,4.814707e-005,1.137018e-009,-2.944785e-002,1.350385e-004,3,9.451032e-001,1.825000e+000,,,,,,,,,,,,,,,,,,0,4.000000e+000,1.000000e+000,2,2,2.286987e-001,0,,0,
1654288497.465,,1.000000e+003,3.428582e+002,4.795409e-005,2.197378e-008,-2.814855e-002,1.597326e-004,3,9.445124e-001,1.825000e+000,,,,,,,,,,,,,,,,,,0,4.000000e+000,1.000000e+000,2,2,2.071838e-001,0,,0,
1654288618.629,,1.000000e+003,3.408513e+002,4.795982e-005,3.269571e-008,-2.749000e-002,1.909226e-004,3,9.450803e-001,1.825000e+000,,,,,,,,,,,,,,,,,,0,4.000000e+000,1.000000e+000,2,2,2.232056e-001,0,,0,
1654288737.845,,1.000000e+003,3.388782e+002,4.793063e-005,1.112323e-008,-2.693585e-002,3.567046e-004,3,9.451458e-001,1.825000e+000,,,,,,,,,,,,,,,,,,0,4.000000e+000,1.000000e+000,2,2,2.019958e-001,0,,0,
1654288856.263,,1.000000e+003,3.369019e+002,4.797910e-005,1.957369e-008,-2.597990e-002,4.650918e-004,3,9.446936e-001,1.825000e+000,,,,,,,,,,,,,,,,,,0,4.000000e+000,1.000000e+000,2,2,1.996155e-001,0,,0,
1654288978.388,,1.000000e+003,3.348715e+002,4.801712e-005,2.310565e-008,-2.679687e-002,2.634310e-005,3,9.439371e-001,1.825000e+000,,,,,,,,,,,,,,,,,,0,4.000000e+000,1.000000e+000,2,2,2.330017e-001,0,,0,
1654289098.764,,1.000000e+003,3.328755e+002,4.799858e-005,1.056501e-008,-2.498286e-002,1.917576e-004,3,9.445771e-001,1.825000e+000,,,,,,,,,,,,,,,,,,0,4.000000e+000,1.000000e+000,2,2,2.210999e-001,0,,0,
1654289219.689,,1.000000e+003,3.308632e+002,4.808894e-005,4.023553e-008,-2.511398e-002,1.187725e-004,3,9.449207e-001,1.825000e+000,,,,,,,,,,,,,,,,,,0,4.000000e+000,1.000000e+000,2,2,2.007141e-001,0,,0,
1654289340.374,,1.000000e+003,3.288527e+002,4.817416e-005,2.078788e-008,-2.433049e-002,1.966862e-004,3,9.444671e-001,1.825000e+000,,,,,,,,,,,,,,,,,,0,4.000000e+000,1.000000e+000,2,2,2.154846e-001,0,,0,
1654289458.592,,1.000000e+003,3.268872e+002,4.812672e-005,5.746058e-008,-2.362141e-002,4.003937e-004,3,9.421729e-001,1.825000e+000,,,,,,,,,,,,,,,,,,0,4.000000e+000,1.000000e+000,2,2,2.211914e-001,0,,0,
1654289578.766,,1.000000e+003,3.248709e+002,4.827118e-005,1.064218e-008,-2.263581e-002,3.849114e-004,3,9.452046e-001,1.825000e+000,,,,,,,,,,,,,,,,,,0,4.000000e+000,1.000000e+000,2,2,2.268066e-001,0,,0,
1654289699.662,,1.000000e+003,3.228601e+002,4.834554e-005,4.460610e-009,-2.331596e-002,5.270160e-004,3,9.443717e-001,1.825000e+000,,,,,,,,,,,,,,,,,,0,4.000000e+000,1.000000e+000,2,2,1.989136e-001,0,,0,
1654289819.344,,1.000000e+003,3.208777e+002,4.840736e-005,3.228926e-008,-2.179091e-002,2.303720e-005,3,9.445400e-001,1.825000e+000,,,,,,,,,,,,,,,,,,0,4.000000e+000,1.000000e+000,2,2,2.209167e-001,0,,0,
1654289940.798,,1.000000e+003,3.188585e+002,4.851108e-005,1.703727e-008,-2.128890e-002,3.134672e-005,3,9.469054e-001,1.825000e+000,,,,,,,,,,,,,,,,,,0,4.000000e+000,1.000000e+000,2,2,2.179260e-001,0,,0,
1654290062.016,,1.000000e+003,3.168503e+002,4.852084e-005,1.418700e-008,-2.110644e-002,2.626381e-004,3,9.448395e-001,1.825000e+000,,,,,,,,,,,,,,,,,,0,4.000000e+000,1.000000e+000,2,2,1.989746e-001,0,,0,
1654290182.700,,1.000000e+003,3.148354e+002,4.862305e-005,4.688271e-008,-2.082043e-002,4.471702e-004,3,9.447170e-001,1.825000e+000,,,,,,,,,,,,,,,,,,0,4.000000e+000,1.000000e+000,2,2,2.198792e-001,0,,0,
1654290301.850,,1.000000e+003,3.128555e+002,4.874082e-005,2.331916e-008,-1.994715e-002,5.269831e-004,3,9.452412e-001,1.825000e+000,,,,,,,,,,,,,,,,,,0,4.000000e+000,1.000000e+000,2,2,2.092285e-001,0,,0,
1654290420.474,,1.000000e+003,3.108771e+002,4.879592e-005,3.265198e-008,-1.977985e-002,1.444847e-004,3,9.446841e-001,1.825000e+000,,,,,,,,,,,,,,,,,,0,4.000000e+000,1.000000e+000,2,2,2.293091e-001,0,,0,
1654290542.136,,1.000000e+003,3.088669e+002,4.884999e-005,4.067028e-009,-1.959079e-002,7.265274e-004,3,9.454762e-001,1.825000e+000,,,,,,,,,,,,,,,,,,0,4.000000e+000,1.000000e+000,2,2,2.112122e-001,0,,0,
1654290662.571,,1.000000e+003,3.068509e+002,4.896649e-005,1.652792e-008,-1.860909e-002,7.113176e-004,3,9.449472e-001,1.825000e+000,,,,,,,,,,,,,,,,,,0,4.000000e+000,1.000000e+000,2,2,2.304993e-001,0,,0,
1654290782.990,,1.000000e+003,3.048463e+002,4.901462e-005,2.456681e-009,-1.837765e-002,1.832071e-006,3,9.454826e-001,1.825000e+000,,,,,,,,,,,,,,,,,,0,4.000000e+000,1.000000e+000,2,2,2.346191e-001,0,,0,
1654290900.149,,1.000000e+003,3.028841e+002,4.912627e-005,2.272493e-008,-1.812398e-002,3.496555e-004,3,9.445084e-001,1.825000e+000,,,,,,,,,,,,,,,,,,0,4.000000e+000,1.000000e+000,2,2,2.097168e-001,0,,0,
1654291020.325,,1.000000e+003,3.008918e+002,4.922465e-005,4.362343e-008,-1.747648e-002,1.103393e-003,3,9.454741e-001,1.825000e+000,,,,,,,,,,,,,,,,,,0,4.000000e+000,1.000000e+000,2,2,2.068176e-001,0,,0,
1654291374.043,,1.000000e+003,3.000105e+002,4.925628e-005,2.588389e-008,-1.809049e-002,1.421705e-004,3,9.458630e-001,1.825000e+000,,,,,,,,,,,,,,,,,,0,4.000000e+000,1.000000e+000,2,2,1.422119e-002,0,,0,