File: dane/Trt_TEOS — kopia/Medium TEOS/FeTrz_Trt_medium_XTvT_MCE,powtorka.rso.dat
[Header]
TITLE,MPMS RSO Measurement
BYAPP,MPMS Measurement,1.1,Summary
FILEOPENTIME, 1660911491.180000 8/19/2022, 2:18:11 PM

INFO, APPNAME, MPMS MultiVu Application, Revision 1.60,  Build 081

INFO, NAME, FeTrz_Trt_medium
INFO, WEIGHT, 4.600
INFO, AREA, 0.000
INFO, LENGTH, 0.000
INFO, SHAPE, 0
INFO, COMMENT, 55 nm
INFO, SEQUENCE FILE: FeTrz_HTvT_MCE_reverse.seq


INFO, BACKGROUND DATA FILE:, None


STARTUPAXIS,X,4,LINEAR,AUTO,0.000000,0.000000
STARTUPAXIS,Y1,5,LINEAR,AUTO,0.000000,0.000000


STARTUPGROUP,Longitudinal
FIELDGROUP,Longitudinal,1,2,3,4,5,6,7,8,9,10,11,19,20,21,22,23,35
FIELDGROUP,Transverse,1,2,3,4,12,13,14,15,16,17,18,24,25,26,27,28,35

PLOT_APPEARANCE,ALL,HORZ_GRID_ON,VERT_GRID_ON,MARKERS_AND_LINES

[Data]
Time,Comment,Field (Oe),Temperature (K),Long Moment (emu),Long Scan Std Dev,Long Offset (cm),Long Offset Std Dev,Long Algorithm,Long Reg Fit,Long Reg Factor,Trans Moment (emu),Trans Scan Std Dev,Trans Offset (cm),Trans Offset Std Dev,Trans Algorithm,Trans Reg Fit,Trans Reg Factor,Long Moment [w/o ABS] (emu),Long Scan Std Dev [w/o ABS],Long Offset [w/o ABS] (cm),Long Offset Std Dev [w/o ABS],Long Reg Fit [w/o ABS],Trans Moment [w/o ABS] (emu),Trans Scan Std Dev [w/o ABS],Trans Offset [w/o ABS] (cm),Trans Offset Std Dev [w/o ABS],Trans Reg Fit [w/o ABS],RSO Position (deg),Amplitude (cm),Frequency,Cycles to Average,Scans per Measurement,Delta Temp (K),Error,EC Comp. Running,Using ABS,
1660911491.179,,7.000000e+004,3.999935e+002,6.393907e-003,4.116035e-008,-1.093909e-001,7.247151e-005,3,9.830674e-001,1.825000e+000,,,,,,,,,,,,,,,,,,0,4.000000e+000,1.000000e+000,2,2,2.590942e-002,0,,0,
1660912324.528,,7.000000e+004,3.713188e+002,6.719062e-003,3.362199e-006,-9.407771e-002,2.189634e-004,3,9.867438e-001,1.825000e+000,,,,,,,,,,,,,,,,,,0,4.000000e+000,1.000000e+000,2,2,8.571167e-001,0,,0,
1660913089.307,,7.000000e+004,3.438458e+002,2.122805e-003,1.947646e-007,-6.236163e-003,3.100111e-004,3,9.581234e-001,1.825000e+000,,,,,,,,,,,,,,,,,,0,4.000000e+000,1.000000e+000,2,2,2.178040e-001,0,,0,
1660914011.113,,7.000000e+004,3.156254e+002,2.077310e-003,5.844582e-007,8.788873e-003,1.630306e-004,3,9.565519e-001,1.825000e+000,,,,,,,,,,,,,,,,,,0,4.000000e+000,1.000000e+000,2,2,6.632996e-001,0,,0,
1660915352.268,,7.000000e+004,3.112142e+002,2.058524e-003,1.395126e-006,8.532784e-003,1.250326e-004,3,9.549727e-001,1.825000e+000,,,,,,,,,,,,,,,,,,0,4.000000e+000,1.000000e+000,2,2,4.138184e-001,0,,0,
1660916196.526,,7.000000e+004,3.392353e+002,2.038657e-003,5.795192e-007,-7.198611e-003,8.046657e-005,3,9.560731e-001,1.825000e+000,,,,,,,,,,,,,,,,,,0,4.000000e+000,1.000000e+000,2,2,4.049988e-001,0,,0,
1660917036.348,,7.000000e+004,3.672095e+002,2.187565e-003,2.450279e-006,-2.976183e-002,3.557721e-005,3,9.592960e-001,1.825000e+000,,,,,,,,,,,,,,,,,,0,4.000000e+000,1.000000e+000,2,2,4.023132e-001,0,,0,
1660917876.520,,7.000000e+004,3.952262e+002,6.414940e-003,1.537043e-006,-1.082871e-001,2.273296e-005,3,9.829183e-001,1.825000e+000,,,,,,,,,,,,,,,,,,0,4.000000e+000,1.000000e+000,2,2,4.057007e-001,0,,0,
1660919427.169,,6.500000e+004,3.775563e+002,6.220492e-003,3.761277e-006,-9.350063e-002,1.390477e-004,3,9.862800e-001,1.825000e+000,,,,,,,,,,,,,,,,,,0,4.000000e+000,1.000000e+000,2,2,7.373962e-001,0,,0,
1660920133.255,,6.500000e+004,3.495659e+002,2.088628e-003,8.178629e-006,-1.160351e-002,2.010648e-004,3,9.604498e-001,1.825000e+000,,,,,,,,,,,,,,,,,,0,4.000000e+000,1.000000e+000,2,2,6.864929e-001,0,,0,
1660921090.849,,6.500000e+004,3.216429e+002,1.944050e-003,1.200527e-006,7.140405e-003,1.554741e-004,3,9.572592e-001,1.825000e+000,,,,,,,,,,,,,,,,,,0,4.000000e+000,1.000000e+000,2,2,5.838013e-001,0,,0,
1660922368.347,,6.500000e+004,3.052355e+002,1.943107e-003,6.179617e-007,1.271260e-002,1.802206e-004,3,9.556768e-001,1.825000e+000,,,,,,,,,,,,,,,,,,0,4.000000e+000,1.000000e+000,2,2,4.559021e-001,0,,0,
1660923193.007,,6.500000e+004,3.332303e+002,1.912550e-003,4.428712e-007,-3.185640e-003,2.141010e-004,3,9.564841e-001,1.825000e+000,,,,,,,,,,,,,,,,,,0,4.000000e+000,1.000000e+000,2,2,4.078064e-001,0,,0,
1660924038.242,,6.500000e+004,3.614210e+002,1.995031e-003,1.389529e-006,-2.347529e-002,1.938162e-004,3,9.596341e-001,1.825000e+000,,,,,,,,,,,,,,,,,,0,4.000000e+000,1.000000e+000,2,2,4.205933e-001,0,,0,
1660924874.167,,6.500000e+004,3.892809e+002,6.032119e-003,8.472176e-007,-1.057258e-001,6.968981e-005,3,9.840715e-001,1.825000e+000,,,,,,,,,,,,,,,,,,0,4.000000e+000,1.000000e+000,2,2,3.683777e-001,0,,0,
1660926197.062,,6.000000e+004,3.836914e+002,5.649575e-003,3.874217e-006,-9.276880e-002,1.556483e-004,3,9.832747e-001,1.825000e+000,,,,,,,,,,,,,,,,,,0,4.000000e+000,1.000000e+000,2,2,5.720215e-001,0,,0,
1660927225.552,,6.000000e+004,3.553607e+002,5.679457e-003,2.432169e-005,-8.347968e-002,3.980664e-004,3,9.873635e-001,1.825000e+000,,,,,,,,,,,,,,,,,,0,4.000000e+000,1.000000e+000,2,2,8.833008e-001,0,,0,
1660927945.705,,6.000000e+004,3.277218e+002,1.807770e-003,5.707111e-007,5.225871e-003,3.650971e-006,3,9.576921e-001,1.825000e+000,,,,,,,,,,,,,,,,,,0,4.000000e+000,1.000000e+000,2,2,4.792175e-001,0,,0,
1660929113.250,,6.000000e+004,3.000848e+002,1.822620e-003,1.026836e-006,1.509677e-002,2.389614e-004,3,9.562075e-001,1.825000e+000,,,,,,,,,,,,,,,,,,0,4.000000e+000,1.000000e+000,2,2,1.409912e-002,0,,0,
1660930188.750,,6.000000e+004,3.272327e+002,1.780675e-003,8.597299e-007,-1.048263e-003,1.197845e-004,3,9.567859e-001,1.825000e+000,,,,,,,,,,,,,,,,,,0,4.000000e+000,1.000000e+000,2,2,4.179993e-001,0,,0,
1660931027.742,,6.000000e+004,3.552209e+002,1.818932e-003,3.735594e-007,-1.881894e-002,2.012696e-004,3,9.585572e-001,1.825000e+000,,,,,,,,,,,,,,,,,,0,4.000000e+000,1.000000e+000,2,2,4.158936e-001,0,,0,
1660931867.476,,6.000000e+004,3.832034e+002,5.629018e-003,5.739216e-007,-1.040310e-001,2.778531e-005,3,9.854127e-001,1.825000e+000,,,,,,,,,,,,,,,,,,0,4.000000e+000,1.000000e+000,2,2,3.804016e-001,0,,0,
1660933267.751,,5.500000e+004,3.895422e+002,5.146453e-003,1.384590e-006,-9.638274e-002,9.041552e-005,3,9.834976e-001,1.825000e+000,,,,,,,,,,,,,,,,,,0,4.000000e+000,1.000000e+000,2,2,8.243103e-001,0,,0,
1660934057.138,,5.500000e+004,3.618554e+002,5.345312e-003,9.459993e-007,-8.468657e-002,5.984853e-006,3,9.871515e-001,1.825000e+000,,,,,,,,,,,,,,,,,,0,4.000000e+000,1.000000e+000,2,2,2.214966e-001,0,,0,
1660934995.588,,5.500000e+004,3.336054e+002,1.671111e-003,3.317428e-008,1.754138e-003,3.316801e-004,3,9.586620e-001,1.825000e+000,,,,,,,,,,,,,,,,,,0,4.000000e+000,1.000000e+000,2,2,7.553101e-001,0,,0,
1660935903.949,,5.500000e+004,3.057493e+002,1.672268e-003,1.755844e-006,1.365918e-002,2.108403e-004,3,9.569860e-001,1.825000e+000,,,,,,,,,,,,,,,,,,0,4.000000e+000,1.000000e+000,2,2,4.057922e-001,0,,0,
1660937184.211,,5.500000e+004,3.213246e+002,1.645701e-003,6.164800e-007,2.775521e-003,3.614514e-004,3,9.572985e-001,1.825000e+000,,,,,,,,,,,,,,,,,,0,4.000000e+000,1.000000e+000,2,2,4.184265e-001,0,,0,
1660938020.186,,5.500000e+004,3.492327e+002,1.657072e-003,6.151629e-007,-1.415842e-002,1.650016e-004,3,9.585673e-001,1.825000e+000,,,,,,,,,,,,,,,,,,0,4.000000e+000,1.000000e+000,2,2,4.012146e-001,0,,0,
1660938860.324,,5.500000e+004,3.772511e+002,5.169319e-003,4.958840e-007,-1.011501e-001,5.942179e-005,3,9.863132e-001,1.825000e+000,,,,,,,,,,,,,,,,,,0,4.000000e+000,1.000000e+000,2,2,4.142151e-001,0,,0,
1660940347.793,,5.000000e+004,3.955401e+002,4.642840e-003,1.745801e-006,-9.975463e-002,1.162990e-004,3,9.839757e-001,1.825000e+000,,,,,,,,,,,,,,,,,,0,4.000000e+000,1.000000e+000,2,2,6.979065e-001,0,,0,
1660941092.758,,5.000000e+004,3.670521e+002,4.872264e-003,3.358577e-007,-8.628435e-002,1.527560e-004,3,9.868243e-001,1.825000e+000,,,,,,,,,,,,,,,,,,0,4.000000e+000,1.000000e+000,2,2,6.192017e-001,0,,0,
1660942069.517,,5.000000e+004,3.395740e+002,1.536877e-003,7.071945e-007,-2.503649e-003,2.015569e-004,3,9.594812e-001,1.825000e+000,,,,,,,,,,,,,,,,,,0,4.000000e+000,1.000000e+000,2,2,6.181030e-001,0,,0,
1660942795.792,,5.000000e+004,3.117670e+002,1.746660e-003,3.145913e-004,-9.520515e-002,1.521085e-001,3,6.668748e-001,1.825000e+000,,,,,,,,,,,,,,,,,,0,4.000000e+000,1.000000e+000,2,2,4.461975e-001,0,,0,
1660944170.760,,5.000000e+004,3.152664e+002,1.505033e-003,5.967236e-007,6.927087e-003,6.379123e-005,3,9.568666e-001,1.825000e+000,,,,,,,,,,,,,,,,,,0,4.000000e+000,1.000000e+000,2,2,3.703003e-001,0,,0,
1660945011.815,,5.000000e+004,3.432430e+002,1.501638e-003,8.705958e-007,-9.374345e-003,3.477490e-004,3,9.580560e-001,1.825000e+000,,,,,,,,,,,,,,,,,,0,4.000000e+000,1.000000e+000,2,2,4.152222e-001,0,,0,
1660945851.128,,5.000000e+004,3.712241e+002,3.201735e-003,1.916104e-004,-8.016402e-002,3.013347e-003,3,9.809965e-001,1.825000e+000,,,,,,,,,,,,,,,,,,0,4.000000e+000,1.000000e+000,2,2,4.115906e-001,0,,0,
1660946692.708,,5.000000e+004,3.992861e+002,4.595528e-003,2.815280e-007,-1.063379e-001,1.095555e-004,3,9.830895e-001,1.825000e+000,,,,,,,,,,,,,,,,,,0,4.000000e+000,1.000000e+000,2,2,3.999023e-001,0,,0,
1660948173.301,,4.500000e+004,3.733984e+002,4.358236e-003,1.875535e-006,-8.867849e-002,2.143009e-004,3,9.862721e-001,1.825000e+000,,,,,,,,,,,,,,,,,,0,4.000000e+000,1.000000e+000,2,2,8.334045e-001,0,,0,
1660948900.659,,4.500000e+004,3.457656e+002,1.424073e-003,1.498930e-006,-5.233848e-003,1.853306e-004,3,9.601731e-001,1.825000e+000,,,,,,,,,,,,,,,,,,0,4.000000e+000,1.000000e+000,2,2,4.505005e-001,0,,0,
1660949846.803,,4.500000e+004,3.175630e+002,1.370963e-003,1.214850e-006,1.076248e-002,3.989759e-004,3,9.586325e-001,1.825000e+000,,,,,,,,,,,,,,,,,,0,4.000000e+000,1.000000e+000,2,2,6.961060e-001,0,,0,
1660951169.588,,4.500000e+004,3.092956e+002,1.365579e-003,2.541735e-006,1.211805e-002,1.406691e-004,3,9.557472e-001,1.825000e+000,,,,,,,,,,,,,,,,,,0,4.000000e+000,1.000000e+000,2,2,3.933105e-001,0,,0,
1660952007.772,,4.500000e+004,3.372158e+002,1.350331e-003,5.739215e-007,-4.105825e-003,2.059637e-004,3,9.579554e-001,1.825000e+000,,,,,,,,,,,,,,,,,,0,4.000000e+000,1.000000e+000,2,2,4.091187e-001,0,,0,
1660952848.596,,4.500000e+004,3.652415e+002,1.474188e-003,3.295604e-006,-2.840883e-002,3.891221e-004,3,9.612674e-001,1.825000e+000,,,,,,,,,,,,,,,,,,0,4.000000e+000,1.000000e+000,2,2,3.979187e-001,0,,0,
1660953687.794,,4.500000e+004,3.932089e+002,4.173587e-003,1.135660e-006,-1.025045e-001,2.683174e-005,3,9.830928e-001,1.825000e+000,,,,,,,,,,,,,,,,,,0,4.000000e+000,1.000000e+000,2,2,3.764038e-001,0,,0,
1660955239.734,,4.000000e+004,3.797941e+002,3.827533e-003,1.290912e-006,-9.007896e-002,1.108357e-004,3,9.852904e-001,1.825000e+000,,,,,,,,,,,,,,,,,,0,4.000000e+000,1.000000e+000,2,2,3.732910e-001,0,,0,
1660955966.214,,4.000000e+004,3.513829e+002,3.350960e-003,1.731928e-004,-7.391860e-002,2.174377e-003,3,9.854965e-001,1.825000e+000,,,,,,,,,,,,,,,,,,0,4.000000e+000,1.000000e+000,2,2,8.327942e-001,0,,0,
1660956894.751,,4.000000e+004,3.237979e+002,1.218042e-003,9.960485e-008,9.115765e-003,7.147710e-005,3,9.583613e-001,1.825000e+000,,,,,,,,,,,,,,,,,,0,4.000000e+000,1.000000e+000,2,2,3.170166e-001,0,,0,
1660958187.229,,4.000000e+004,3.033024e+002,1.223583e-003,6.268521e-007,1.705477e-002,1.528363e-004,3,9.555414e-001,1.825000e+000,,,,,,,,,,,,,,,,,,0,4.000000e+000,1.000000e+000,2,2,4.277954e-001,0,,0,
1660958998.781,,4.000000e+004,3.312002e+002,1.202245e-003,3.469706e-007,9.061032e-004,8.953283e-006,3,9.573321e-001,1.825000e+000,,,,,,,,,,,,,,,,,,0,4.000000e+000,1.000000e+000,2,2,3.850098e-001,0,,0,
1660959841.092,,4.000000e+004,3.592781e+002,1.253232e-003,8.793215e-007,-1.894920e-002,3.133091e-004,3,9.594176e-001,1.825000e+000,,,,,,,,,,,,,,,,,,0,4.000000e+000,1.000000e+000,2,2,4.154968e-001,0,,0,
1660960680.664,,4.000000e+004,3.872744e+002,3.752026e-003,1.095324e-006,-9.952077e-002,1.170629e-005,3,9.838064e-001,1.825000e+000,,,,,,,,,,,,,,,,,,0,4.000000e+000,1.000000e+000,2,2,3.403015e-001,0,,0,
1660962026.081,,3.500000e+004,3.856143e+002,3.295157e-003,9.832070e-007,-8.779749e-002,1.866420e-004,3,9.822341e-001,1.825000e+000,,,,,,,,,,,,,,,,,,0,4.000000e+000,1.000000e+000,2,2,6.743164e-001,0,,0,
1660963055.873,,3.500000e+004,3.575985e+002,3.406772e-003,2.973658e-006,-7.904406e-002,4.090984e-004,3,9.876317e-001,1.825000e+000,,,,,,,,,,,,,,,,,,0,4.000000e+000,1.000000e+000,2,2,7.716064e-001,0,,0,
1660963765.478,,3.500000e+004,3.296505e+002,1.069956e-003,2.200362e-007,9.424414e-003,4.907079e-005,3,9.581159e-001,1.825000e+000,,,,,,,,,,,,,,,,,,0,4.000000e+000,1.000000e+000,2,2,6.152039e-001,0,,0,
1660964695.050,,3.500000e+004,3.015922e+002,1.081625e-003,5.421468e-007,2.125163e-002,2.092762e-004,3,9.562948e-001,1.825000e+000,,,,,,,,,,,,,,,,,,0,4.000000e+000,1.000000e+000,2,2,6.018982e-001,0,,0,
1660966000.782,,3.500000e+004,3.253383e+002,1.057820e-003,6.149165e-008,7.337458e-003,3.242795e-004,3,9.572881e-001,1.825000e+000,,,,,,,,,,,,,,,,,,0,4.000000e+000,1.000000e+000,2,2,6.149902e-001,0,,0,
1660966835.513,,3.500000e+004,3.532845e+002,1.079144e-003,8.307539e-007,-1.039375e-002,8.175238e-005,3,9.592576e-001,1.825000e+000,,,,,,,,,,,,,,,,,,0,4.000000e+000,1.000000e+000,2,2,3.710938e-001,0,,0,
1660967680.400,,3.500000e+004,3.814496e+002,3.320832e-003,9.127427e-007,-9.421387e-002,1.084807e-004,3,9.851589e-001,1.825000e+000,,,,,,,,,,,,,,,,,,0,4.000000e+000,1.000000e+000,2,2,4.122009e-001,0,,0,
1660969100.218,,3.000000e+004,3.915826e+002,2.807364e-003,6.266051e-007,-8.844565e-002,2.885900e-004,3,9.828413e-001,1.825000e+000,,,,,,,,,,,,,,,,,,0,4.000000e+000,1.000000e+000,2,2,8.329773e-001,0,,0,
1660969852.779,,3.000000e+004,3.637747e+002,2.935437e-003,6.145867e-007,-7.548465e-002,4.166743e-005,3,9.864036e-001,1.825000e+000,,,,,,,,,,,,,,,,,,0,4.000000e+000,1.000000e+000,2,2,4.158020e-001,0,,0,
1660970828.691,,3.000000e+004,3.354629e+002,9.256090e-004,3.732713e-007,8.266343e-003,1.046724e-004,3,9.586953e-001,1.825000e+000,,,,,,,,,,,,,,,,,,0,4.000000e+000,1.000000e+000,2,2,7.933044e-001,0,,0,
1660971676.025,,3.000000e+004,3.078864e+002,9.251314e-004,2.875782e-007,2.439386e-002,1.076101e-004,3,9.575626e-001,1.825000e+000,,,,,,,,,,,,,,,,,,0,4.000000e+000,1.000000e+000,2,2,1.722107e-001,0,,0,
1660972984.517,,3.000000e+004,3.192022e+002,9.126771e-004,2.962627e-007,1.552832e-002,7.382040e-004,3,9.582185e-001,1.825000e+000,,,,,,,,,,,,,,,,,,0,4.000000e+000,1.000000e+000,2,2,3.722229e-001,0,,0,
1660973825.425,,3.000000e+004,3.472674e+002,9.185008e-004,4.333635e-007,-1.639617e-003,3.567558e-005,3,9.586722e-001,1.825000e+000,,,,,,,,,,,,,,,,,,0,4.000000e+000,1.000000e+000,2,2,4.158936e-001,0,,0,
1660974663.755,,3.000000e+004,3.752205e+002,2.853157e-003,1.961640e-006,-8.641055e-002,4.915379e-006,3,9.864293e-001,1.825000e+000,,,,,,,,,,,,,,,,,,0,4.000000e+000,1.000000e+000,2,2,4.094849e-001,0,,0,
1660976153.761,,2.500000e+004,3.978071e+002,2.319971e-003,7.453078e-007,-8.795358e-002,1.704313e-005,3,9.832252e-001,1.825000e+000,,,,,,,,,,,,,,,,,,0,4.000000e+000,1.000000e+000,2,2,3.589172e-001,0,,0,
1660976916.422,,2.500000e+004,3.693239e+002,2.444168e-003,7.001975e-007,-7.322408e-002,8.334540e-005,3,9.859054e-001,1.825000e+000,,,,,,,,,,,,,,,,,,0,4.000000e+000,1.000000e+000,2,2,8.143921e-001,0,,0,
1660977880.420,,2.500000e+004,3.417823e+002,7.856023e-004,1.892492e-007,1.069287e-002,2.283319e-004,3,9.607459e-001,1.825000e+000,,,,,,,,,,,,,,,,,,0,4.000000e+000,1.000000e+000,2,2,4.302063e-001,0,,0,
1660978608.747,,2.500000e+004,3.137614e+002,7.759291e-004,2.111047e-007,2.654382e-002,3.608613e-004,3,9.595312e-001,1.825000e+000,,,,,,,,,,,,,,,,,,0,4.000000e+000,1.000000e+000,2,2,4.835205e-001,0,,0,
1660979970.205,,2.500000e+004,3.132651e+002,7.689017e-004,6.175501e-007,2.412121e-002,2.215778e-004,3,9.576973e-001,1.825000e+000,,,,,,,,,,,,,,,,,,0,4.000000e+000,1.000000e+000,2,2,3.497009e-001,0,,0,
1660980816.474,,2.500000e+004,3.413922e+002,7.658743e-004,2.053840e-008,7.387860e-003,1.333128e-004,3,9.591526e-001,1.825000e+000,,,,,,,,,,,,,,,,,,0,4.000000e+000,1.000000e+000,2,2,4.011230e-001,0,,0,
1660981652.619,,2.500000e+004,3.692604e+002,1.119987e-003,5.162791e-005,-4.156708e-002,3.553406e-003,3,9.722715e-001,1.825000e+000,,,,,,,,,,,,,,,,,,0,4.000000e+000,1.000000e+000,2,2,3.630981e-001,0,,0,
1660982490.314,,2.500000e+004,3.971799e+002,2.319182e-003,1.190320e-007,-8.541852e-002,4.841622e-006,3,9.830687e-001,1.825000e+000,,,,,,,,,,,,,,,,,,0,4.000000e+000,1.000000e+000,2,2,3.580017e-001,0,,0,
1660984002.542,,2.000000e+004,3.754227e+002,1.946701e-003,9.031115e-007,-6.911501e-002,2.049443e-004,3,9.863501e-001,1.825000e+000,,,,,,,,,,,,,,,,,,0,4.000000e+000,1.000000e+000,2,2,8.314819e-001,0,,0,
1660984711.450,,2.000000e+004,3.476331e+002,6.579999e-004,1.929165e-006,9.802969e-003,4.047395e-004,3,9.621280e-001,1.825000e+000,,,,,,,,,,,,,,,,,,0,4.000000e+000,1.000000e+000,2,2,5.814819e-001,0,,0,
1660985671.666,,2.000000e+004,3.196277e+002,6.242592e-004,7.807869e-008,2.688168e-002,5.206453e-006,3,9.609252e-001,1.825000e+000,,,,,,,,,,,,,,,,,,0,4.000000e+000,1.000000e+000,2,2,6.166992e-001,0,,0,
1660986963.254,,2.000000e+004,3.072494e+002,6.232541e-004,3.609649e-008,3.116502e-002,2.676588e-005,3,9.580901e-001,1.825000e+000,,,,,,,,,,,,,,,,,,0,4.000000e+000,1.000000e+000,2,2,4.772034e-001,0,,0,
1660987800.118,,2.000000e+004,3.352802e+002,6.161517e-004,1.197316e-007,1.448217e-002,4.535975e-004,3,9.595430e-001,1.825000e+000,,,,,,,,,,,,,,,,,,0,4.000000e+000,1.000000e+000,2,2,4.040222e-001,0,,0,
1660988638.334,,2.000000e+004,3.632503e+002,6.621053e-004,1.263911e-006,-7.645337e-003,4.744441e-004,3,9.622594e-001,1.825000e+000,,,,,,,,,,,,,,,,,,0,4.000000e+000,1.000000e+000,2,2,3.614197e-001,0,,0,
1660989478.826,,2.000000e+004,3.912625e+002,1.881357e-003,6.542639e-007,-7.930696e-002,2.704774e-005,3,9.841328e-001,1.825000e+000,,,,,,,,,,,,,,,,,,0,4.000000e+000,1.000000e+000,2,2,3.724060e-001,0,,0,
1660990783.984,,1.500000e+004,3.817618e+002,1.440466e-003,5.865162e-007,-6.518703e-002,2.997800e-004,3,9.841760e-001,1.825000e+000,,,,,,,,,,,,,,,,,,0,4.000000e+000,1.000000e+000,2,2,3.893127e-001,0,,0,
1660991783.213,,1.500000e+004,3.534352e+002,1.448521e-003,5.420151e-006,-5.482766e-002,2.394204e-004,3,9.880155e-001,1.825000e+000,,,,,,,,,,,,,,,,,,0,4.000000e+000,1.000000e+000,2,2,7.727966e-001,0,,0,
1660992544.754,,1.500000e+004,3.258655e+002,4.719594e-004,8.178299e-008,2.680342e-002,1.018465e-004,3,9.604957e-001,1.825000e+000,,,,,,,,,,,,,,,,,,0,4.000000e+000,1.000000e+000,2,2,2.619934e-001,0,,0,
1660993971.861,,1.500000e+004,3.012129e+002,4.759799e-004,6.379650e-009,3.422472e-002,8.857423e-005,3,9.587865e-001,1.825000e+000,,,,,,,,,,,,,,,,,,0,4.000000e+000,1.000000e+000,2,2,3.715210e-001,0,,0,
1660994782.985,,1.500000e+004,3.292329e+002,4.668234e-004,2.663812e-007,1.799560e-002,2.725505e-004,3,9.598237e-001,1.825000e+000,,,,,,,,,,,,,,,,,,0,4.000000e+000,1.000000e+000,2,2,3.543091e-001,0,,0,
1660995624.290,,1.500000e+004,3.572874e+002,4.830524e-004,3.746501e-007,-1.099322e-003,5.389405e-005,3,9.617739e-001,1.825000e+000,,,,,,,,,,,,,,,,,,0,4.000000e+000,1.000000e+000,2,2,4.004822e-001,0,,0,
1660996462.567,,1.500000e+004,3.852502e+002,1.433063e-003,6.156568e-007,-7.639636e-002,1.691564e-004,3,9.857987e-001,1.825000e+000,,,,,,,,,,,,,,,,,,0,4.000000e+000,1.000000e+000,2,2,4.086914e-001,0,,0,
1660997824.618,,1.000000e+004,3.875268e+002,9.551612e-004,4.906568e-007,-6.717758e-002,3.587118e-004,3,9.837604e-001,1.825000e+000,,,,,,,,,,,,,,,,,,0,4.000000e+000,1.000000e+000,2,2,7.543945e-001,0,,0,
1660998850.402,,1.000000e+004,3.597254e+002,9.967536e-004,3.235923e-007,-5.786879e-002,1.277234e-004,3,9.881901e-001,1.825000e+000,,,,,,,,,,,,,,,,,,0,4.000000e+000,1.000000e+000,2,2,5.415955e-001,0,,0,
1660999562.875,,1.000000e+004,3.315903e+002,3.211723e-004,9.950196e-008,2.195679e-002,2.662956e-004,3,9.609439e-001,1.825000e+000,,,,,,,,,,,,,,,,,,0,4.000000e+000,1.000000e+000,2,2,7.718811e-001,0,,0,
1661000488.005,,1.000000e+004,3.037200e+002,3.231778e-004,2.476127e-007,3.276145e-002,1.985907e-004,3,9.593468e-001,1.825000e+000,,,,,,,,,,,,,,,,,,0,4.000000e+000,1.000000e+000,2,2,5.527039e-001,0,,0,
1661001773.963,,1.000000e+004,3.232547e+002,3.173756e-004,3.009548e-007,1.997579e-002,4.958261e-004,3,9.602228e-001,1.825000e+000,,,,,,,,,,,,,,,,,,0,4.000000e+000,1.000000e+000,2,2,3.573914e-001,0,,0,
1661002612.162,,1.000000e+004,3.512463e+002,3.220771e-004,1.428630e-007,2.707135e-003,1.468564e-004,3,9.611661e-001,1.825000e+000,,,,,,,,,,,,,,,,,,0,4.000000e+000,1.000000e+000,2,2,4.061890e-001,0,,0,
1661003451.700,,1.000000e+004,3.792321e+002,9.690184e-004,1.047086e-007,-7.301355e-002,2.896542e-005,3,9.866672e-001,1.825000e+000,,,,,,,,,,,,,,,,,,0,4.000000e+000,1.000000e+000,2,2,3.605957e-001,0,,0,
1661004888.701,,9.000000e+003,3.934193e+002,8.533841e-004,5.165870e-007,-6.966716e-002,5.068158e-005,3,9.841604e-001,1.825000e+000,,,,,,,,,,,,,,,,,,0,4.000000e+000,1.000000e+000,2,2,7.408142e-001,0,,0,
1661005633.334,,9.000000e+003,3.653088e+002,8.974451e-004,1.524119e-007,-5.595470e-002,3.002647e-004,3,9.875679e-001,1.825000e+000,,,,,,,,,,,,,,,,,,0,4.000000e+000,1.000000e+000,2,2,6.130066e-001,0,,0,
1661006616.718,,9.000000e+003,3.375163e+002,2.926836e-004,5.332153e-008,1.781542e-002,5.422824e-004,3,9.617975e-001,1.825000e+000,,,,,,,,,,,,,,,,,,0,4.000000e+000,1.000000e+000,2,2,7.195129e-001,0,,0,
1661007361.436,,9.000000e+003,3.097596e+002,2.916048e-004,3.599358e-008,3.157331e-002,2.314073e-004,3,9.609972e-001,1.825000e+000,,,,,,,,,,,,,,,,,,0,4.000000e+000,1.000000e+000,2,2,3.111267e-001,0,,0,
1661008738.140,,9.000000e+003,3.172053e+002,2.880316e-004,1.329025e-007,2.425607e-002,4.105208e-004,3,9.590583e-001,1.825000e+000,,,,,,,,,,,,,,,,,,0,4.000000e+000,1.000000e+000,2,2,3.991089e-001,0,,0,
1661009578.957,,9.000000e+003,3.452321e+002,2.888735e-004,1.364834e-007,7.380458e-003,8.974470e-004,3,9.609107e-001,1.825000e+000,,,,,,,,,,,,,,,,,,0,4.000000e+000,1.000000e+000,2,2,4.010925e-001,0,,0,
1661010418.465,,9.000000e+003,3.732237e+002,8.714269e-004,3.211639e-007,-6.931335e-002,6.859399e-006,3,9.872917e-001,1.825000e+000,,,,,,,,,,,,,,,,,,0,4.000000e+000,1.000000e+000,2,2,4.049072e-001,0,,0,
1661011839.407,,8.000000e+003,4.000162e+002,7.500979e-004,6.655416e-008,-7.358581e-002,8.836613e-005,3,9.837757e-001,1.825000e+000,,,,,,,,,,,,,,,,,,0,4.000000e+000,1.000000e+000,2,2,1.290894e-002,0,,0,
1661012684.630,,8.000000e+003,3.711047e+002,7.951795e-004,3.669328e-007,-5.816998e-002,3.571339e-004,3,9.872568e-001,1.825000e+000,,,,,,,,,,,,,,,,,,0,4.000000e+000,1.000000e+000,2,2,8.894043e-001,0,,0,
1661013449.004,,8.000000e+003,3.436990e+002,2.661172e-004,4.541900e-008,1.443966e-002,2.925979e-004,3,9.626147e-001,1.825000e+000,,,,,,,,,,,,,,,,,,0,4.000000e+000,1.000000e+000,2,2,2.177124e-001,0,,0,
1661014366.466,,8.000000e+003,3.154774e+002,2.606237e-004,1.461763e-007,2.853758e-002,6.415264e-004,3,9.611909e-001,1.825000e+000,,,,,,,,,,,,,,,,,,0,4.000000e+000,1.000000e+000,2,2,7.019958e-001,0,,0,
1661015703.934,,8.000000e+003,3.112813e+002,2.586594e-004,1.783421e-007,2.793432e-002,4.209114e-004,3,9.588330e-001,1.825000e+000,,,,,,,,,,,,,,,,,,0,4.000000e+000,1.000000e+000,2,2,4.063110e-001,0,,0,
1661016545.896,,8.000000e+003,3.392168e+002,2.571916e-004,6.054493e-008,1.056642e-002,5.235936e-004,3,9.610527e-001,1.825000e+000,,,,,,,,,,,,,,,,,,0,4.000000e+000,1.000000e+000,2,2,4.602966e-001,0,,0,
1661017386.681,,8.000000e+003,3.672612e+002,3.026485e-004,2.112837e-006,-1.953685e-002,9.342139e-004,3,9.663773e-001,1.825000e+000,,,,,,,,,,,,,,,,,,0,4.000000e+000,1.000000e+000,2,2,4.133911e-001,0,,0,
1661018225.244,,8.000000e+003,3.952357e+002,7.553304e-004,1.997448e-007,-7.571964e-002,3.735268e-006,3,9.837400e-001,1.825000e+000,,,,,,,,,,,,,,,,,,0,4.000000e+000,1.000000e+000,2,2,3.927917e-001,0,,0,
1661019753.151,,7.000000e+003,3.775564e+002,6.913248e-004,3.625287e-007,-6.168346e-002,2.761672e-005,3,9.866528e-001,1.825000e+000,,,,,,,,,,,,,,,,,,0,4.000000e+000,1.000000e+000,2,2,8.295898e-001,0,,0,
1661020458.819,,7.000000e+003,3.495414e+002,4.256442e-004,4.470517e-005,-2.651318e-002,5.503206e-003,3,9.792339e-001,1.825000e+000,,,,,,,,,,,,,,,,,,0,4.000000e+000,1.000000e+000,2,2,6.571045e-001,0,,0,
1661021411.582,,7.000000e+003,3.216162e+002,2.299551e-004,6.145044e-008,2.466861e-002,5.304708e-005,3,9.615626e-001,1.825000e+000,,,,,,,,,,,,,,,,,,0,4.000000e+000,1.000000e+000,2,2,6.248169e-001,0,,0,
1661022704.737,,7.000000e+003,3.052962e+002,2.304166e-004,1.995493e-007,2.973143e-002,1.203714e-004,3,9.595307e-001,1.825000e+000,,,,,,,,,,,,,,,,,,0,4.000000e+000,1.000000e+000,2,2,5.589905e-001,0,,0,
1661023529.466,,7.000000e+003,3.332857e+002,2.273012e-004,8.963408e-008,1.357126e-002,2.363233e-004,3,9.610276e-001,1.825000e+000,,,,,,,,,,,,,,,,,,0,4.000000e+000,1.000000e+000,2,2,4.168091e-001,0,,0,
1661024372.371,,7.000000e+003,3.614104e+002,2.404631e-004,2.337833e-007,-6.529732e-003,1.432170e-004,3,9.632614e-001,1.825000e+000,,,,,,,,,,,,,,,,,,0,4.000000e+000,1.000000e+000,2,2,4.416809e-001,0,,0,
1661025207.398,,7.000000e+003,3.892656e+002,6.726487e-004,2.607836e-007,-7.307932e-002,1.086440e-004,3,9.850873e-001,1.825000e+000,,,,,,,,,,,,,,,,,,0,4.000000e+000,1.000000e+000,2,2,3.561096e-001,0,,0,
1661026513.063,,6.000000e+003,3.836914e+002,5.839796e-004,2.455548e-007,-6.030817e-002,2.207573e-004,3,9.841563e-001,1.825000e+000,,,,,,,,,,,,,,,,,,0,4.000000e+000,1.000000e+000,2,2,5.244141e-001,0,,0,
1661027537.717,,6.000000e+003,3.554495e+002,6.014880e-004,1.162866e-006,-5.085159e-002,3.689272e-004,3,9.884015e-001,1.825000e+000,,,,,,,,,,,,,,,,,,0,4.000000e+000,1.000000e+000,2,2,8.835144e-001,0,,0,
1661028262.986,,6.000000e+003,3.277560e+002,1.992884e-004,6.554584e-009,2.275732e-002,3.149687e-004,3,9.613793e-001,1.825000e+000,,,,,,,,,,,,,,,,,,0,4.000000e+000,1.000000e+000,2,2,3.764954e-001,0,,0,
1661029429.813,,6.000000e+003,3.000707e+002,2.015209e-004,7.135947e-008,3.280932e-002,3.358972e-004,3,9.603783e-001,1.825000e+000,,,,,,,,,,,,,,,,,,0,4.000000e+000,1.000000e+000,2,2,0.000000e+000,0,,0,
1661030508.712,,6.000000e+003,3.272796e+002,1.972185e-004,7.069064e-008,1.662341e-002,2.941837e-004,3,9.607024e-001,1.825000e+000,,,,,,,,,,,,,,,,,,0,4.000000e+000,1.000000e+000,2,2,3.839111e-001,0,,0,
1661031346.694,,6.000000e+003,3.552361e+002,2.023322e-004,2.157763e-008,-9.623347e-004,4.833504e-004,3,9.625359e-001,1.825000e+000,,,,,,,,,,,,,,,,,,0,4.000000e+000,1.000000e+000,2,2,3.955994e-001,0,,0,
1661032187.143,,6.000000e+003,3.832747e+002,5.859003e-004,7.301612e-008,-7.100326e-002,2.301587e-004,3,9.862121e-001,1.825000e+000,,,,,,,,,,,,,,,,,,0,4.000000e+000,1.000000e+000,2,2,4.042969e-001,0,,0,
1661033574.819,,5.000000e+003,3.894684e+002,4.838914e-004,3.519715e-007,-6.382541e-002,1.102772e-004,3,9.839972e-001,1.825000e+000,,,,,,,,,,,,,,,,,,0,4.000000e+000,1.000000e+000,2,2,7.255249e-001,0,,0,
1661034366.697,,5.000000e+003,3.618791e+002,5.065006e-004,5.350674e-009,-5.136168e-002,1.561831e-004,3,9.878230e-001,1.825000e+000,,,,,,,,,,,,,,,,,,0,4.000000e+000,1.000000e+000,2,2,1.899109e-001,0,,0,
1661035300.310,,5.000000e+003,3.335610e+002,1.690324e-004,8.794656e-008,1.791443e-002,3.332736e-004,3,9.617847e-001,1.825000e+000,,,,,,,,,,,,,,,,,,0,4.000000e+000,1.000000e+000,2,2,7.371826e-001,0,,0,
1661036208.952,,5.000000e+003,3.057899e+002,1.697707e-004,1.444682e-008,2.904141e-002,1.130853e-004,3,9.601351e-001,1.825000e+000,,,,,,,,,,,,,,,,,,0,4.000000e+000,1.000000e+000,2,2,4.649048e-001,0,,0,
1661037493.191,,5.000000e+003,3.214600e+002,1.671715e-004,7.850056e-008,1.782701e-002,1.670490e-004,3,9.609770e-001,1.825000e+000,,,,,,,,,,,,,,,,,,0,4.000000e+000,1.000000e+000,2,2,4.105835e-001,0,,0,
1661038327.305,,5.000000e+003,3.492499e+002,1.686256e-004,1.115307e-007,1.699435e-003,5.609268e-005,3,9.616731e-001,1.825000e+000,,,,,,,,,,,,,,,,,,0,4.000000e+000,1.000000e+000,2,2,4.503174e-001,0,,0,
1661039164.999,,5.000000e+003,3.772195e+002,4.938905e-004,5.391833e-008,-6.859848e-002,1.142180e-005,3,9.871280e-001,1.825000e+000,,,,,,,,,,,,,,,,,,0,4.000000e+000,1.000000e+000,2,2,4.255981e-001,0,,0,
1661040641.774,,4.000000e+003,3.955085e+002,3.856411e-004,2.033050e-007,-6.793115e-002,6.426340e-005,3,9.839358e-001,1.825000e+000,,,,,,,,,,,,,,,,,,0,4.000000e+000,1.000000e+000,2,2,7.485962e-001,0,,0,
1661041388.286,,4.000000e+003,3.670548e+002,4.071342e-004,1.240945e-007,-5.333550e-002,9.754362e-006,3,9.876211e-001,1.825000e+000,,,,,,,,,,,,,,,,,,0,4.000000e+000,1.000000e+000,2,2,6.518860e-001,0,,0,
1661042366.663,,4.000000e+003,3.395325e+002,1.389967e-004,5.127387e-008,1.144096e-002,1.836911e-004,3,9.626067e-001,1.825000e+000,,,,,,,,,,,,,,,,,,0,4.000000e+000,1.000000e+000,2,2,6.916809e-001,0,,0,
1661043090.416,,4.000000e+003,3.117573e+002,1.383164e-004,1.034121e-008,2.518566e-002,1.360948e-004,3,9.614934e-001,1.825000e+000,,,,,,,,,,,,,,,,,,0,4.000000e+000,1.000000e+000,2,2,4.537964e-001,0,,0,
1661044465.528,,4.000000e+003,3.152545e+002,1.368515e-004,4.049020e-008,1.907416e-002,8.061244e-005,3,9.607961e-001,1.825000e+000,,,,,,,,,,,,,,,,,,0,4.000000e+000,1.000000e+000,2,2,3.940125e-001,0,,0,
1661045307.433,,4.000000e+003,3.432502e+002,1.365522e-004,1.359277e-008,3.455640e-003,1.482800e-004,3,9.612360e-001,1.825000e+000,,,,,,,,,,,,,,,,,,0,4.000000e+000,1.000000e+000,2,2,4.057922e-001,0,,0,
1661046147.265,,4.000000e+003,3.712491e+002,3.940449e-004,4.259342e-007,-6.576441e-002,8.852945e-005,3,9.873071e-001,1.825000e+000,,,,,,,,,,,,,,,,,,0,4.000000e+000,1.000000e+000,2,2,4.673157e-001,0,,0,
1661046985.911,,4.000000e+003,3.992054e+002,3.820863e-004,1.349810e-007,-7.460606e-002,9.035232e-006,3,9.835198e-001,1.825000e+000,,,,,,,,,,,,,,,,,,0,4.000000e+000,1.000000e+000,2,2,3.999023e-001,0,,0,
1661048453.715,,3.000000e+003,3.733956e+002,3.057935e-004,2.320752e-007,-5.728112e-002,2.699216e-004,3,9.871224e-001,1.825000e+000,,,,,,,,,,,,,,,,,,0,4.000000e+000,1.000000e+000,2,2,9.343872e-001,0,,0,
1661049179.473,,3.000000e+003,3.457345e+002,1.097549e-004,1.008756e-007,4.947010e-003,3.130951e-005,3,9.630109e-001,1.825000e+000,,,,,,,,,,,,,,,,,,0,4.000000e+000,1.000000e+000,2,2,4.791260e-001,0,,0,
1661050128.712,,3.000000e+003,3.175630e+002,1.065586e-004,3.748044e-008,1.831440e-002,1.411919e-005,3,9.623064e-001,1.825000e+000,,,,,,,,,,,,,,,,,,0,4.000000e+000,1.000000e+000,2,2,6.801147e-001,0,,0,
1661051451.098,,3.000000e+003,3.092900e+002,1.061594e-004,8.200423e-008,1.961689e-002,2.501745e-004,3,9.602929e-001,1.825000e+000,,,,,,,,,,,,,,,,,,0,4.000000e+000,1.000000e+000,2,2,4.463196e-001,0,,0,
1661052290.525,,3.000000e+003,3.372249e+002,1.053323e-004,6.683200e-009,3.123229e-003,3.222382e-004,3,9.617771e-001,1.825000e+000,,,,,,,,,,,,,,,,,,0,4.000000e+000,1.000000e+000,2,2,4.001160e-001,0,,0,
1661053131.566,,3.000000e+003,3.652523e+002,1.160074e-004,2.623991e-007,-1.926602e-002,3.037155e-004,3,9.654994e-001,1.825000e+000,,,,,,,,,,,,,,,,,,0,4.000000e+000,1.000000e+000,2,2,4.515991e-001,0,,0,
1661053972.535,,3.000000e+003,3.932967e+002,2.925140e-004,1.687520e-007,-7.297367e-002,3.116233e-005,3,9.837658e-001,1.825000e+000,,,,,,,,,,,,,,,,,,0,4.000000e+000,1.000000e+000,2,2,3.763123e-001,0,,0,
1661055505.885,,2.500000e+003,3.798058e+002,2.533603e-004,1.041323e-007,-6.111062e-002,6.286993e-005,3,9.862727e-001,1.825000e+000,,,,,,,,,,,,,,,,,,0,4.000000e+000,1.000000e+000,2,2,3.733826e-001,0,,0,
1661056229.025,,2.500000e+003,3.514027e+002,2.413810e-004,5.273573e-006,-4.659991e-002,6.655066e-004,3,9.874036e-001,1.825000e+000,,,,,,,,,,,,,,,,,,0,4.000000e+000,1.000000e+000,2,2,8.725891e-001,0,,0,
1661057165.069,,2.500000e+003,3.237042e+002,9.044046e-005,4.643253e-008,1.215536e-002,3.549680e-004,3,9.625244e-001,1.825000e+000,,,,,,,,,,,,,,,,,,0,4.000000e+000,1.000000e+000,2,2,5.083923e-001,0,,0,
1661058457.553,,2.500000e+003,3.033840e+002,9.102890e-005,9.223739e-008,1.981455e-002,3.239552e-004,3,9.601541e-001,1.825000e+000,,,,,,,,,,,,,,,,,,0,4.000000e+000,1.000000e+000,2,2,4.862061e-001,0,,0,
1661059268.746,,2.500000e+003,3.312527e+002,8.965714e-005,9.456287e-009,3.549805e-003,4.194993e-004,3,9.610342e-001,1.825000e+000,,,,,,,,,,,,,,,,,,0,4.000000e+000,1.000000e+000,2,2,4.026184e-001,0,,0,
1661060108.674,,2.500000e+003,3.592728e+002,9.319843e-005,3.874608e-008,-1.507867e-002,1.680217e-004,3,9.631234e-001,1.825000e+000,,,,,,,,,,,,,,,,,,0,4.000000e+000,1.000000e+000,2,2,3.948059e-001,0,,0,
1661060947.551,,2.500000e+003,3.872471e+002,2.488911e-004,9.127015e-008,-7.184397e-002,2.905393e-004,3,9.851024e-001,1.825000e+000,,,,,,,,,,,,,,,,,,0,4.000000e+000,1.000000e+000,2,2,4.131165e-001,0,,0,
1661062271.313,,2.000000e+003,3.855992e+002,2.011678e-004,8.597092e-008,-6.151491e-002,2.843780e-004,3,9.834129e-001,1.825000e+000,,,,,,,,,,,,,,,,,,0,4.000000e+000,1.000000e+000,2,2,7.347107e-001,0,,0,
1661063291.864,,2.000000e+003,3.575188e+002,2.095725e-004,1.870061e-007,-5.183481e-002,2.011274e-004,3,9.881650e-001,1.825000e+000,,,,,,,,,,,,,,,,,,0,4.000000e+000,1.000000e+000,2,2,8.121948e-001,0,,0,
1661064004.999,,2.000000e+003,3.296353e+002,7.453369e-005,4.974069e-008,7.610054e-003,3.638458e-006,3,9.618984e-001,1.825000e+000,,,,,,,,,,,,,,,,,,0,4.000000e+000,1.000000e+000,2,2,5.284119e-001,0,,0,
1661064929.454,,2.000000e+003,3.016514e+002,7.531975e-005,7.151567e-010,1.931483e-002,7.884359e-005,3,9.608907e-001,1.825000e+000,,,,,,,,,,,,,,,,,,0,4.000000e+000,1.000000e+000,2,2,5.804749e-001,0,,0,
1661066243.870,,2.000000e+003,3.252918e+002,7.399594e-005,2.237508e-008,2.830870e-003,2.916776e-004,3,9.611577e-001,1.825000e+000,,,,,,,,,,,,,,,,,,0,4.000000e+000,1.000000e+000,2,2,4.127197e-001,0,,0,
1661067083.765,,2.000000e+003,3.532971e+002,7.515922e-005,5.032206e-008,-1.355077e-002,1.875324e-004,3,9.630014e-001,1.825000e+000,,,,,,,,,,,,,,,,,,0,4.000000e+000,1.000000e+000,2,2,4.412231e-001,0,,0,
1661067926.646,,2.000000e+003,3.813937e+002,2.034452e-004,6.886935e-008,-7.094846e-002,6.778267e-005,3,9.863330e-001,1.825000e+000,,,,,,,,,,,,,,,,,,0,4.000000e+000,1.000000e+000,2,2,4.473267e-001,0,,0,
1661069335.717,,1.500000e+003,3.914212e+002,1.516707e-004,6.851950e-008,-6.649183e-002,6.524490e-004,3,9.834986e-001,1.825000e+000,,,,,,,,,,,,,,,,,,0,4.000000e+000,1.000000e+000,2,2,9.566956e-001,0,,0,
1661070087.079,,1.500000e+003,3.637267e+002,1.590811e-004,5.458717e-008,-5.334285e-002,1.440000e-004,3,9.868072e-001,1.825000e+000,,,,,,,,,,,,,,,,,,0,4.000000e+000,1.000000e+000,2,2,5.010071e-001,0,,0,
1661071067.543,,1.500000e+003,3.354539e+002,5.850031e-005,2.201751e-008,-2.398069e-004,6.170119e-004,3,9.622587e-001,1.825000e+000,,,,,,,,,,,,,,,,,,0,4.000000e+000,1.000000e+000,2,2,9.010010e-001,0,,0,
1661071884.141,,1.500000e+003,3.078807e+002,5.860920e-005,1.176891e-008,1.075847e-002,2.518083e-004,3,9.614611e-001,1.825000e+000,,,,,,,,,,,,,,,,,,0,4.000000e+000,1.000000e+000,2,2,1.347961e-001,0,,0,
1661073219.754,,1.500000e+003,3.192467e+002,5.800350e-005,1.247633e-008,1.293853e-003,5.606886e-004,3,9.610567e-001,1.825000e+000,,,,,,,,,,,,,,,,,,0,4.000000e+000,1.000000e+000,2,2,3.722229e-001,0,,0,
1661074058.941,,1.500000e+003,3.472626e+002,5.812355e-005,7.758477e-009,-1.519992e-002,1.712426e-004,3,9.621870e-001,1.825000e+000,,,,,,,,,,,,,,,,,,0,4.000000e+000,1.000000e+000,2,2,4.352112e-001,0,,0,
1661074899.247,,1.500000e+003,3.752659e+002,1.553989e-004,2.120719e-008,-6.974316e-002,1.963464e-004,3,9.864194e-001,1.825000e+000,,,,,,,,,,,,,,,,,,0,4.000000e+000,1.000000e+000,2,2,3.526917e-001,0,,0,
1661076375.822,,1.000000e+003,3.978232e+002,1.021148e-004,1.189702e-007,-7.354505e-002,3.225446e-004,3,9.828138e-001,1.825000e+000,,,,,,,,,,,,,,,,,,0,4.000000e+000,1.000000e+000,2,2,3.590088e-001,0,,0,
1661077157.410,,1.000000e+003,3.681556e+002,1.080106e-004,3.421859e-008,-5.788887e-002,6.500888e-005,3,9.862196e-001,1.825000e+000,,,,,,,,,,,,,,,,,,0,4.000000e+000,1.000000e+000,2,2,8.309021e-001,0,,0,
1661078107.460,,1.000000e+003,3.417682e+002,4.183011e-005,1.923928e-008,-1.337298e-002,1.063989e-003,3,9.623814e-001,1.825000e+000,,,,,,,,,,,,,,,,,,0,4.000000e+000,1.000000e+000,2,2,3.927917e-001,0,,0,
1661078832.694,,1.000000e+003,3.136894e+002,4.156125e-005,1.092258e-008,1.223947e-004,1.891303e-004,3,9.621158e-001,1.825000e+000,,,,,,,,,,,,,,,,,,0,4.000000e+000,1.000000e+000,2,2,5.769043e-001,0,,0,
1661080195.322,,1.000000e+003,3.132826e+002,4.124935e-005,7.382644e-008,-4.184925e-003,8.341966e-004,3,9.601548e-001,1.825000e+000,,,,,,,,,,,,,,,,,,0,4.000000e+000,1.000000e+000,2,2,3.574829e-001,0,,0,
1661081041.642,,1.000000e+003,3.414039e+002,4.106842e-005,3.910108e-009,-1.926209e-002,1.602733e-003,3,9.612211e-001,1.825000e+000,,,,,,,,,,,,,,,,,,0,4.000000e+000,1.000000e+000,2,2,4.291077e-001,0,,0,
1661081876.977,,1.000000e+003,3.692466e+002,7.631408e-005,3.919019e-006,-6.560756e-002,1.792432e-003,3,9.807478e-001,1.825000e+000,,,,,,,,,,,,,,,,,,0,4.000000e+000,1.000000e+000,2,2,4.179993e-001,0,,0,
1661082716.522,,1.000000e+003,3.972214e+002,1.021210e-004,3.280375e-008,-7.785425e-002,1.517550e-004,3,9.819683e-001,1.825000e+000,,,,,,,,,,,,,,,,,,0,4.000000e+000,1.000000e+000,2,2,3.963013e-001,0,,0,
1661084208.220,,9.000000e+002,3.752776e+002,9.672773e-005,1.048681e-007,-6.210165e-002,6.371260e-004,3,9.855213e-001,1.825000e+000,,,,,,,,,,,,,,,,,,0,4.000000e+000,1.000000e+000,2,2,9.104004e-001,0,,0,
1661084917.999,,9.000000e+002,3.475580e+002,3.952695e-005,3.518814e-007,-1.792858e-002,1.314205e-003,3,9.630445e-001,1.825000e+000,,,,,,,,,,,,,,,,,,0,4.000000e+000,1.000000e+000,2,2,6.879272e-001,0,,0,
1661085874.093,,9.000000e+002,3.196013e+002,3.792100e-005,3.268799e-008,-4.413063e-003,1.062650e-003,3,9.618856e-001,1.825000e+000,,,,,,,,,,,,,,,,,,0,4.000000e+000,1.000000e+000,2,2,7.543030e-001,0,,0,
1661087171.987,,9.000000e+002,3.072792e+002,3.796933e-005,3.609647e-008,-1.102787e-003,1.805131e-004,3,9.592364e-001,1.825000e+000,,,,,,,,,,,,,,,,,,0,4.000000e+000,1.000000e+000,2,2,4.772949e-001,0,,0,
1661088006.658,,9.000000e+002,3.352622e+002,3.752959e-005,6.689115e-008,-1.845287e-002,7.909660e-004,3,9.601381e-001,1.825000e+000,,,,,,,,,,,,,,,,,,0,4.000000e+000,1.000000e+000,2,2,4.130249e-001,0,,0,
1661088845.448,,9.000000e+002,3.632371e+002,3.980071e-005,6.596250e-008,-3.551057e-002,6.997694e-005,3,9.640485e-001,1.825000e+000,,,,,,,,,,,,,,,,,,0,4.000000e+000,1.000000e+000,2,2,4.146118e-001,0,,0,
1661089685.503,,9.000000e+002,3.912719e+002,9.350962e-005,3.659038e-008,-7.641423e-002,1.022114e-004,3,9.831057e-001,1.825000e+000,,,,,,,,,,,,,,,,,,0,4.000000e+000,1.000000e+000,2,2,3.848877e-001,0,,0,
1661090977.310,,8.000000e+002,3.817501e+002,8.504343e-005,4.005803e-008,-6.268441e-002,7.079116e-004,3,9.831651e-001,1.825000e+000,,,,,,,,,,,,,,,,,,0,4.000000e+000,1.000000e+000,2,2,3.656006e-001,0,,0,
1661091972.039,,8.000000e+002,3.534052e+002,8.665497e-005,1.917805e-007,-5.293968e-002,3.106934e-004,3,9.872153e-001,1.825000e+000,,,,,,,,,,,,,,,,,,0,4.000000e+000,1.000000e+000,2,2,8.930969e-001,0,,0,
1661092738.021,,8.000000e+002,3.258634e+002,3.431083e-005,1.910036e-008,-8.994688e-003,2.131985e-004,3,9.609997e-001,1.825000e+000,,,,,,,,,,,,,,,,,,0,4.000000e+000,1.000000e+000,2,2,2.196960e-001,0,,0,
1661094164.989,,8.000000e+002,3.012415e+002,3.459995e-005,2.632120e-008,-1.504999e-003,1.131180e-003,3,9.600098e-001,1.825000e+000,,,,,,,,,,,,,,,,,,0,4.000000e+000,1.000000e+000,2,2,4.288025e-001,0,,0,
1661094974.977,,8.000000e+002,3.292264e+002,3.411826e-005,1.031548e-008,-1.779835e-002,6.273045e-004,3,9.607272e-001,1.825000e+000,,,,,,,,,,,,,,,,,,0,4.000000e+000,1.000000e+000,2,2,4.146118e-001,0,,0,
1661095814.268,,8.000000e+002,3.572104e+002,3.486982e-005,3.845798e-009,-3.394084e-002,3.712321e-004,3,9.631286e-001,1.825000e+000,,,,,,,,,,,,,,,,,,0,4.000000e+000,1.000000e+000,2,2,4.002075e-001,0,,0,
1661096654.560,,8.000000e+002,3.852412e+002,8.479226e-005,2.605881e-008,-7.510567e-002,5.487994e-004,3,9.843141e-001,1.825000e+000,,,,,,,,,,,,,,,,,,0,4.000000e+000,1.000000e+000,2,2,4.086914e-001,0,,0,
1661098003.558,,7.000000e+002,3.875269e+002,7.411484e-005,6.596250e-008,-6.639050e-002,1.869213e-004,3,9.818717e-001,1.825000e+000,,,,,,,,,,,,,,,,,,0,4.000000e+000,1.000000e+000,2,2,8.760986e-001,0,,0,
1661099022.851,,7.000000e+002,3.596161e+002,7.764285e-005,3.929144e-008,-5.742786e-002,1.618202e-004,3,9.873142e-001,1.825000e+000,,,,,,,,,,,,,,,,,,0,4.000000e+000,1.000000e+000,2,2,7.077026e-001,0,,0,
1661099731.669,,7.000000e+002,3.315376e+002,3.072834e-005,3.744700e-008,-1.418179e-002,1.545196e-004,3,9.608812e-001,1.825000e+000,,,,,,,,,,,,,,,,,,0,4.000000e+000,1.000000e+000,2,2,7.190857e-001,0,,0,
1661100654.657,,7.000000e+002,3.036928e+002,3.096570e-005,1.750545e-008,-4.225423e-003,1.833665e-004,3,9.610969e-001,1.825000e+000,,,,,,,,,,,,,,,,,,0,4.000000e+000,1.000000e+000,2,2,6.399231e-001,0,,0,
1661101949.608,,7.000000e+002,3.232672e+002,3.057302e-005,5.654222e-009,-1.809453e-002,2.610023e-004,3,9.619623e-001,1.825000e+000,,,,,,,,,,,,,,,,,,0,4.000000e+000,1.000000e+000,2,2,4.072876e-001,0,,0,
1661102788.669,,7.000000e+002,3.512736e+002,3.078030e-005,2.537969e-008,-3.288147e-002,3.460651e-004,3,9.626573e-001,1.825000e+000,,,,,,,,,,,,,,,,,,0,4.000000e+000,1.000000e+000,2,2,4.358826e-001,0,,0,
1661103628.861,,7.000000e+002,3.792845e+002,7.548658e-005,2.480861e-008,-7.383141e-002,4.245768e-005,3,9.857382e-001,1.825000e+000,,,,,,,,,,,,,,,,,,0,4.000000e+000,1.000000e+000,2,2,4.071960e-001,0,,0,
1661105064.567,,6.000000e+002,3.934852e+002,6.346217e-005,7.468821e-008,-7.168515e-002,2.226144e-004,3,9.820597e-001,1.825000e+000,,,,,,,,,,,,,,,,,,0,4.000000e+000,1.000000e+000,2,2,8.038025e-001,0,,0,
1661105803.423,,6.000000e+002,3.655995e+002,6.676207e-005,4.943200e-008,-5.816077e-002,7.797746e-004,3,9.859805e-001,1.825000e+000,,,,,,,,,,,,,,,,,,0,4.000000e+000,1.000000e+000,2,2,6.250000e-001,0,,0,
1661106787.776,,6.000000e+002,3.374662e+002,2.712735e-005,3.562186e-008,-2.039210e-002,9.083647e-004,3,9.617040e-001,1.825000e+000,,,,,,,,,,,,,,,,,,0,4.000000e+000,1.000000e+000,2,2,8.648987e-001,0,,0,
1661107548.437,,6.000000e+002,3.098222e+002,2.711128e-005,5.601616e-008,-8.320193e-003,1.131883e-003,3,9.627448e-001,1.825000e+000,,,,,,,,,,,,,,,,,,0,4.000000e+000,1.000000e+000,2,2,3.112183e-001,0,,0,
1661108918.615,,6.000000e+002,3.172432e+002,2.684363e-005,3.931716e-008,-1.665899e-002,1.681989e-004,3,9.615190e-001,1.825000e+000,,,,,,,,,,,,,,,,,,0,4.000000e+000,1.000000e+000,2,2,4.071045e-001,0,,0,
1661109759.400,,6.000000e+002,3.452728e+002,2.687643e-005,1.451370e-008,-3.394417e-002,1.093526e-004,3,9.610716e-001,1.825000e+000,,,,,,,,,,,,,,,,,,0,4.000000e+000,1.000000e+000,2,2,3.726807e-001,0,,0,
1661110599.032,,6.000000e+002,3.732491e+002,6.538873e-005,1.950938e-008,-7.306372e-002,1.449746e-004,3,9.857441e-001,1.825000e+000,,,,,,,,,,,,,,,,,,0,4.000000e+000,1.000000e+000,2,2,4.387207e-001,0,,0,
1661112015.393,,5.000000e+002,4.000097e+002,5.273749e-005,1.505134e-008,-7.851908e-002,2.713572e-004,3,9.804274e-001,1.825000e+000,,,,,,,,,,,,,,,,,,0,4.000000e+000,1.000000e+000,2,2,0.000000e+000,0,,0,
1661112860.769,,5.000000e+002,3.710214e+002,5.582021e-005,3.984709e-008,-6.219748e-002,3.964939e-004,3,9.854624e-001,1.825000e+000,,,,,,,,,,,,,,,,,,0,4.000000e+000,1.000000e+000,2,2,8.890076e-001,0,,0,
1661113629.079,,5.000000e+002,3.438623e+002,2.355517e-005,3.964515e-008,-2.683588e-002,5.307843e-004,3,9.634943e-001,1.825000e+000,,,,,,,,,,,,,,,,,,0,4.000000e+000,1.000000e+000,2,2,2.084045e-001,0,,0,
1661114538.311,,5.000000e+002,3.155603e+002,2.332239e-005,6.405374e-009,-1.434399e-002,2.165460e-003,3,9.615448e-001,1.825000e+000,,,,,,,,,,,,,,,,,,0,4.000000e+000,1.000000e+000,2,2,6.710815e-001,0,,0,
1661115881.030,,5.000000e+002,3.112295e+002,2.322435e-005,1.252392e-008,-1.765221e-002,7.502903e-004,3,9.605871e-001,1.825000e+000,,,,,,,,,,,,,,,,,,0,4.000000e+000,1.000000e+000,2,2,4.138794e-001,0,,0,
1661116725.616,,5.000000e+002,3.392720e+002,2.302878e-005,1.587195e-009,-3.248557e-002,7.532195e-004,3,9.612911e-001,1.825000e+000,,,,,,,,,,,,,,,,,,0,4.000000e+000,1.000000e+000,2,2,4.420166e-001,0,,0,
1661117563.410,,5.000000e+002,3.672177e+002,2.634356e-005,2.720869e-007,-5.291190e-002,2.985314e-004,3,9.668713e-001,1.825000e+000,,,,,,,,,,,,,,,,,,0,4.000000e+000,1.000000e+000,2,2,4.132996e-001,0,,0,
1661118405.108,,5.000000e+002,3.952484e+002,5.332653e-005,2.182200e-008,-8.016193e-002,1.258979e-004,3,9.819056e-001,1.825000e+000,,,,,,,,,,,,,,,,,,0,4.000000e+000,1.000000e+000,2,2,4.436035e-001,0,,0,
1661119913.991,,4.000000e+002,3.774929e+002,4.472925e-005,6.464026e-008,-6.641995e-002,3.702601e-004,3,9.848324e-001,1.825000e+000,,,,,,,,,,,,,,,,,,0,4.000000e+000,1.000000e+000,2,2,6.795959e-001,0,,0,
1661120624.165,,4.000000e+002,3.492990e+002,3.104287e-005,2.368350e-006,-4.613737e-002,1.341913e-003,3,9.781578e-001,1.825000e+000,,,,,,,,,,,,,,,,,,0,4.000000e+000,1.000000e+000,2,2,7.831726e-001,0,,0,
1661121572.219,,4.000000e+002,3.216656e+002,1.932279e-005,1.128015e-009,-2.429764e-002,1.171846e-003,3,9.638786e-001,1.825000e+000,,,,,,,,,,,,,,,,,,0,4.000000e+000,1.000000e+000,2,2,6.907043e-001,0,,0,
1661122875.074,,4.000000e+002,3.052906e+002,1.928928e-005,3.461089e-008,-1.760265e-002,1.748523e-003,3,9.616099e-001,1.825000e+000,,,,,,,,,,,,,,,,,,0,4.000000e+000,1.000000e+000,2,2,4.412842e-001,0,,0,
1661123700.442,,4.000000e+002,3.332901e+002,1.909923e-005,1.794920e-008,-3.483105e-002,1.710899e-005,3,9.608051e-001,1.825000e+000,,,,,,,,,,,,,,,,,,0,4.000000e+000,1.000000e+000,2,2,4.166870e-001,0,,0,
1661124545.790,,4.000000e+002,3.614893e+002,1.977114e-005,2.631606e-009,-5.024949e-002,5.732683e-004,3,9.648225e-001,1.825000e+000,,,,,,,,,,,,,,,,,,0,4.000000e+000,1.000000e+000,2,2,4.419861e-001,0,,0,
1661125377.971,,4.000000e+002,3.892502e+002,4.366906e-005,1.862703e-008,-7.945261e-002,8.708171e-004,3,9.832790e-001,1.825000e+000,,,,,,,,,,,,,,,,,,0,4.000000e+000,1.000000e+000,2,2,4.052124e-001,0,,0,
1661126682.587,,3.000000e+002,3.835901e+002,3.336646e-005,7.331195e-008,-6.933311e-002,4.559762e-005,3,9.828126e-001,1.825000e+000,,,,,,,,,,,,,,,,,,0,4.000000e+000,1.000000e+000,2,2,5.718079e-001,0,,0,
1661127697.678,,3.000000e+002,3.551299e+002,3.457810e-005,5.798021e-008,-6.037471e-002,7.574447e-004,3,9.877133e-001,1.825000e+000,,,,,,,,,,,,,,,,,,0,4.000000e+000,1.000000e+000,2,2,9.021912e-001,0,,0,
1661128426.865,,3.000000e+002,3.277090e+002,1.515517e-005,3.655501e-008,-3.064488e-002,1.970154e-004,3,9.639758e-001,1.825000e+000,,,,,,,,,,,,,,,,,,0,4.000000e+000,1.000000e+000,2,2,3.936157e-001,0,,0,
1661129592.887,,3.000000e+002,3.000654e+002,1.529803e-005,2.942871e-008,-2.060318e-002,5.237549e-004,3,9.593629e-001,1.825000e+000,,,,,,,,,,,,,,,,,,0,4.000000e+000,1.000000e+000,2,2,1.422119e-002,0,,0,
1661130671.645,,3.000000e+002,3.272412e+002,1.502167e-005,1.281396e-008,-3.866191e-002,1.323437e-004,3,9.602247e-001,1.825000e+000,,,,,,,,,,,,,,,,,,0,4.000000e+000,1.000000e+000,2,2,4.009094e-001,0,,0,
1661131511.708,,3.000000e+002,3.552412e+002,1.518997e-005,1.200750e-008,-5.218465e-002,2.197737e-003,3,9.644264e-001,1.825000e+000,,,,,,,,,,,,,,,,,,0,4.000000e+000,1.000000e+000,2,2,4.565125e-001,0,,0,
1661132352.995,,3.000000e+002,3.833044e+002,3.363015e-005,2.568838e-008,-8.006725e-002,1.076452e-003,3,9.834284e-001,1.825000e+000,,,,,,,,,,,,,,,,,,0,4.000000e+000,1.000000e+000,2,2,4.282227e-001,0,,0,
1661133730.844,,2.000000e+002,3.894624e+002,2.238491e-005,3.462761e-008,-7.661861e-002,2.502996e-004,3,9.796133e-001,1.825000e+000,,,,,,,,,,,,,,,,,,0,4.000000e+000,1.000000e+000,2,2,8.727112e-001,0,,0,
1661134525.148,,2.000000e+002,3.618685e+002,2.345351e-005,6.891823e-008,-6.543669e-002,2.452051e-004,3,9.843941e-001,1.825000e+000,,,,,,,,,,,,,,,,,,0,4.000000e+000,1.000000e+000,2,2,2.214966e-001,0,,0,
1661135459.089,,2.000000e+002,3.333568e+002,1.079371e-005,4.696181e-008,-4.306119e-002,1.258505e-003,3,9.609653e-001,1.825000e+000,,,,,,,,,,,,,,,,,,0,4.000000e+000,1.000000e+000,2,2,8.072205e-001,0,,0,
1661136368.983,,2.000000e+002,3.056921e+002,1.089465e-005,2.229276e-008,-3.133778e-002,6.848889e-004,3,9.613196e-001,1.825000e+000,,,,,,,,,,,,,,,,,,0,4.000000e+000,1.000000e+000,2,2,4.719849e-001,0,,0,
1661137651.034,,2.000000e+002,3.214128e+002,1.078893e-005,2.014799e-008,-4.541466e-002,1.236565e-003,3,9.646676e-001,1.825000e+000,,,,,,,,,,,,,,,,,,0,4.000000e+000,1.000000e+000,2,2,4.598083e-001,0,,0,
1661138485.718,,2.000000e+002,3.492915e+002,1.075334e-005,5.508493e-008,-5.776998e-002,8.545063e-004,3,9.620757e-001,1.825000e+000,,,,,,,,,,,,,,,,,,0,4.000000e+000,1.000000e+000,2,2,4.013977e-001,0,,0,
1661139323.791,,2.000000e+002,3.772425e+002,2.298284e-005,7.519498e-008,-8.162426e-002,1.059256e-004,3,9.841635e-001,1.825000e+000,,,,,,,,,,,,,,,,,,0,4.000000e+000,1.000000e+000,2,2,4.602051e-001,0,,0,
1661140788.676,,1.000000e+002,3.956005e+002,1.115510e-005,2.940298e-008,-9.039848e-002,4.941244e-003,3,9.695454e-001,1.825000e+000,,,,,,,,,,,,,,,,,,0,4.000000e+000,1.000000e+000,2,2,7.869263e-001,0,,0,
1661141528.279,,1.000000e+002,3.672723e+002,1.191871e-005,6.580943e-008,-7.225566e-002,2.705617e-004,3,9.805588e-001,1.825000e+000,,,,,,,,,,,,,,,,,,0,4.000000e+000,1.000000e+000,2,2,7.614136e-001,0,,0,
1661142509.156,,1.000000e+002,3.395233e+002,6.163048e-006,8.184281e-008,-6.274543e-002,7.216939e-003,3,9.563545e-001,1.825000e+000,,,,,,,,,,,,,,,,,,0,4.000000e+000,1.000000e+000,2,2,8.022766e-001,0,,0,
1661143237.639,,1.000000e+002,3.117131e+002,6.152722e-006,2.624081e-008,-5.736975e-002,9.292616e-004,3,9.627943e-001,1.825000e+000,,,,,,,,,,,,,,,,,,0,4.000000e+000,1.000000e+000,2,2,4.613953e-001,0,,0,
1661144614.392,,1.000000e+002,3.152368e+002,6.160886e-006,9.617708e-009,-6.266003e-002,8.112188e-004,3,9.602491e-001,1.825000e+000,,,,,,,,,,,,,,,,,,0,4.000000e+000,1.000000e+000,2,2,4.018250e-001,0,,0,
1661145455.407,,1.000000e+002,3.432195e+002,6.066115e-006,2.851067e-008,-7.137069e-002,7.891802e-003,3,9.594315e-001,1.825000e+000,,,,,,,,,,,,,,,,,,0,4.000000e+000,1.000000e+000,2,2,4.151917e-001,0,,0,
1661146295.320,,1.000000e+002,3.712463e+002,1.170572e-005,5.657630e-008,-8.626692e-002,2.736858e-003,3,9.773053e-001,1.825000e+000,,,,,,,,,,,,,,,,,,0,4.000000e+000,1.000000e+000,2,2,4.226990e-001,0,,0,
1661147136.327,,1.000000e+002,3.992635e+002,1.132720e-005,8.280618e-008,-9.727545e-002,4.784458e-004,3,9.777764e-001,1.825000e+000,,,,,,,,,,,,,,,,,,0,4.000000e+000,1.000000e+000,2,2,4.515076e-001,0,,0,
1661148595.040,,0.000000e+000,3.730862e+002,-2.389659e-007,7.315267e-008,6.583385e-001,3.677877e-002,3,2.129924e-001,1.825000e+000,,,,,,,,,,,,,,,,,,0,4.000000e+000,1.000000e+000,2,2,9.332275e-001,0,,0,
1661149317.041,,0.000000e+000,3.456913e+002,8.175753e-007,3.293792e-008,-2.438227e-001,2.216210e-002,3,7.820555e-001,1.825000e+000,,,,,,,,,,,,,,,,,,0,4.000000e+000,1.000000e+000,2,2,5.268860e-001,0,,0,
1661150264.473,,0.000000e+000,3.175891e+002,8.346880e-007,4.879688e-008,-2.211036e-001,2.705800e-002,3,8.076985e-001,1.825000e+000,,,,,,,,,,,,,,,,,,0,4.000000e+000,1.000000e+000,2,2,7.684021e-001,0,,0,
1661151589.987,,0.000000e+000,3.093164e+002,8.127141e-007,9.344788e-010,-1.796036e-001,1.089129e-002,3,7.749586e-001,1.825000e+000,,,,,,,,,,,,,,,,,,0,4.000000e+000,1.000000e+000,2,2,4.916992e-001,0,,0,
1661152428.756,,0.000000e+000,3.372590e+002,8.001987e-007,9.577514e-009,-2.334795e-001,1.232938e-002,3,7.687596e-001,1.825000e+000,,,,,,,,,,,,,,,,,,0,4.000000e+000,1.000000e+000,2,2,4.183044e-001,0,,0,
1661153268.890,,0.000000e+000,3.652388e+002,7.287732e-007,9.089915e-009,-2.226450e-001,1.587519e-002,3,7.507541e-001,1.825000e+000,,,,,,,,,,,,,,,,,,0,4.000000e+000,1.000000e+000,2,2,4.515991e-001,0,,0,
1661154108.873,,0.000000e+000,3.932402e+002,-2.801613e-007,8.918338e-008,8.676533e-001,7.267486e-002,3,3.161782e-001,1.825000e+000,,,,,,,,,,,,,,,,,,0,4.000000e+000,1.000000e+000,2,2,4.013977e-001,0,,0,
1661154564.119,,0.000000e+000,3.999838e+002,-2.162012e-007,2.261689e-008,9.704041e-001,1.227692e-001,3,9.057768e-003,1.825000e+000,,,,,,,,,,,,,,,,,,0,4.000000e+000,1.000000e+000,2,2,0.000000e+000,0,,0,