File: dane/Trt_TEOS — kopia/Small TEOS/FeTrz_Trt_small_XTvT_MCE.rso.dat
[Header]
TITLE,MPMS RSO Measurement
BYAPP,MPMS Measurement,1.1,Summary
FILEOPENTIME, 1656962375.570000 7/4/2022, 9:19:35 PM

INFO, APPNAME, MPMS MultiVu Application, Revision 1.60,  Build 081

INFO, NAME, FeTrz_Trt_small
INFO, WEIGHT, 7.710
INFO, AREA, 0.000
INFO, LENGTH, 0.000
INFO, SHAPE, 0
INFO, COMMENT, w torebce papierowej, na drucie Cu
INFO, SEQUENCE FILE: FeTrz_HTvT_MCE_reverse.seq


INFO, BACKGROUND DATA FILE:, None


STARTUPAXIS,X,4,LINEAR,AUTO,0.000000,0.000000
STARTUPAXIS,Y1,5,LINEAR,AUTO,0.000000,0.000000


STARTUPGROUP,Longitudinal
FIELDGROUP,Longitudinal,1,2,3,4,5,6,7,8,9,10,11,19,20,21,22,23,35
FIELDGROUP,Transverse,1,2,3,4,12,13,14,15,16,17,18,24,25,26,27,28,35

PLOT_APPEARANCE,ALL,HORZ_GRID_ON,VERT_GRID_ON,MARKERS_AND_LINES

[Data]
Time,Comment,Field (Oe),Temperature (K),Long Moment (emu),Long Scan Std Dev,Long Offset (cm),Long Offset Std Dev,Long Algorithm,Long Reg Fit,Long Reg Factor,Trans Moment (emu),Trans Scan Std Dev,Trans Offset (cm),Trans Offset Std Dev,Trans Algorithm,Trans Reg Fit,Trans Reg Factor,Long Moment [w/o ABS] (emu),Long Scan Std Dev [w/o ABS],Long Offset [w/o ABS] (cm),Long Offset Std Dev [w/o ABS],Long Reg Fit [w/o ABS],Trans Moment [w/o ABS] (emu),Trans Scan Std Dev [w/o ABS],Trans Offset [w/o ABS] (cm),Trans Offset Std Dev [w/o ABS],Trans Reg Fit [w/o ABS],RSO Position (deg),Amplitude (cm),Frequency,Cycles to Average,Scans per Measurement,Delta Temp (K),Error,EC Comp. Running,Using ABS,
1656962375.570,,7.000000e+004,3.999970e+002,1.345480e-002,1.000329e-006,-8.862163e-002,9.662165e-006,3,9.871591e-001,1.825000e+000,,,,,,,,,,,,,,,,,,0,4.000000e+000,1.000000e+000,2,2,1.300049e-002,0,,0,
1656963247.579,,7.000000e+004,3.705610e+002,1.423142e-002,1.132433e-005,-7.227645e-002,1.313296e-004,3,9.869568e-001,1.825000e+000,,,,,,,,,,,,,,,,,,0,4.000000e+000,1.000000e+000,2,2,8.533936e-001,0,,0,
1656963978.320,,7.000000e+004,3.433826e+002,3.966706e-003,5.624299e-006,-1.993469e-002,2.633230e-004,3,9.794405e-001,1.825000e+000,,,,,,,,,,,,,,,,,,0,4.000000e+000,1.000000e+000,2,2,4.911194e-001,0,,0,
1656964941.313,,7.000000e+004,3.154330e+002,3.835729e-003,2.138624e-007,-8.278840e-003,3.937859e-004,3,9.778299e-001,1.825000e+000,,,,,,,,,,,,,,,,,,0,4.000000e+000,1.000000e+000,2,2,7.810059e-001,0,,0,
1656966282.275,,7.000000e+004,3.112671e+002,3.812521e-003,7.762594e-007,-1.011757e-002,4.369904e-005,3,9.774444e-001,1.825000e+000,,,,,,,,,,,,,,,,,,0,4.000000e+000,1.000000e+000,2,2,4.523010e-001,0,,0,
1656967125.575,,7.000000e+004,3.392359e+002,3.833083e-003,8.236746e-007,-2.555354e-002,9.185379e-005,3,9.784814e-001,1.825000e+000,,,,,,,,,,,,,,,,,,0,4.000000e+000,1.000000e+000,2,2,4.142151e-001,0,,0,
1656967965.920,,7.000000e+004,3.672563e+002,4.246341e-003,7.957523e-006,-4.445489e-002,1.060072e-004,3,9.796813e-001,1.825000e+000,,,,,,,,,,,,,,,,,,0,4.000000e+000,1.000000e+000,2,2,4.024048e-001,0,,0,
1656968805.304,,7.000000e+004,3.952491e+002,1.361392e-002,3.643068e-006,-9.058483e-002,1.069792e-004,3,9.875818e-001,1.825000e+000,,,,,,,,,,,,,,,,,,0,4.000000e+000,1.000000e+000,2,2,4.182129e-001,0,,0,
1656970364.031,,6.500000e+004,3.775904e+002,1.312879e-002,9.909119e-006,-7.594818e-002,2.221718e-004,3,9.872580e-001,1.825000e+000,,,,,,,,,,,,,,,,,,0,4.000000e+000,1.000000e+000,2,2,8.411865e-001,0,,0,
1656971091.045,,6.500000e+004,3.481183e+002,9.794232e-003,6.365248e-004,-6.739264e-002,7.644912e-004,3,9.884526e-001,1.825000e+000,,,,,,,,,,,,,,,,,,0,4.000000e+000,1.000000e+000,2,2,8.163147e-001,0,,0,
1656972050.934,,6.500000e+004,3.216329e+002,3.545503e-003,2.214357e-007,-1.153496e-002,5.213104e-005,3,9.783370e-001,1.825000e+000,,,,,,,,,,,,,,,,,,0,4.000000e+000,1.000000e+000,2,2,6.163940e-001,0,,0,
1656973336.999,,6.500000e+004,3.052740e+002,3.539316e-003,1.272637e-006,-7.098378e-003,1.751636e-004,3,9.771074e-001,1.825000e+000,,,,,,,,,,,,,,,,,,0,4.000000e+000,1.000000e+000,2,2,4.559021e-001,0,,0,
1656974162.197,,6.500000e+004,3.332581e+002,3.532297e-003,4.237734e-007,-2.237971e-002,1.063023e-004,3,9.785994e-001,1.825000e+000,,,,,,,,,,,,,,,,,,0,4.000000e+000,1.000000e+000,2,2,4.078064e-001,0,,0,
1656975007.912,,6.500000e+004,3.614720e+002,3.773705e-003,2.740533e-006,-4.025068e-002,1.144471e-004,3,9.798505e-001,1.825000e+000,,,,,,,,,,,,,,,,,,0,4.000000e+000,1.000000e+000,2,2,4.208069e-001,0,,0,
1656975842.623,,6.500000e+004,3.892607e+002,1.284353e-002,3.065525e-006,-8.948752e-002,1.209140e-004,3,9.876439e-001,1.825000e+000,,,,,,,,,,,,,,,,,,0,4.000000e+000,1.000000e+000,2,2,4.051819e-001,0,,0,
1656977198.618,,6.000000e+004,3.837230e+002,1.201965e-002,5.714191e-006,-7.672679e-002,2.936582e-005,3,9.878588e-001,1.825000e+000,,,,,,,,,,,,,,,,,,0,4.000000e+000,1.000000e+000,2,2,5.243835e-001,0,,0,
1656978225.068,,6.000000e+004,3.550809e+002,1.280172e-002,1.924267e-006,-6.822709e-002,2.432400e-004,3,9.875054e-001,1.825000e+000,,,,,,,,,,,,,,,,,,0,4.000000e+000,1.000000e+000,2,2,9.521790e-001,0,,0,
1656978928.658,,6.000000e+004,3.276509e+002,3.292747e-003,4.316759e-007,-1.244111e-002,2.177372e-004,3,9.794219e-001,1.825000e+000,,,,,,,,,,,,,,,,,,0,4.000000e+000,1.000000e+000,2,2,6.157227e-001,0,,0,
1656980121.333,,6.000000e+004,3.001066e+002,3.282916e-003,8.053999e-007,-3.407186e-003,6.854329e-005,3,9.772156e-001,1.825000e+000,,,,,,,,,,,,,,,,,,0,4.000000e+000,1.000000e+000,2,2,7.019043e-003,0,,0,
1656981210.881,,6.000000e+004,3.273668e+002,3.241552e-003,2.239051e-008,-1.911680e-002,4.155284e-005,3,9.779609e-001,1.825000e+000,,,,,,,,,,,,,,,,,,0,4.000000e+000,1.000000e+000,2,2,4.184265e-001,0,,0,
1656982046.780,,6.000000e+004,3.552859e+002,3.384798e-003,2.476621e-006,-3.586239e-002,1.825248e-004,3,9.795865e-001,1.825000e+000,,,,,,,,,,,,,,,,,,0,4.000000e+000,1.000000e+000,2,2,3.652954e-001,0,,0,
1656982886.647,,6.000000e+004,3.832736e+002,1.202752e-002,6.039512e-006,-8.787839e-002,5.587618e-005,3,9.878746e-001,1.825000e+000,,,,,,,,,,,,,,,,,,0,4.000000e+000,1.000000e+000,2,2,4.161987e-001,0,,0,
1656984306.939,,5.500000e+004,3.893499e+002,1.092396e-002,7.981559e-006,-8.023685e-002,1.497109e-004,3,9.881228e-001,1.825000e+000,,,,,,,,,,,,,,,,,,0,4.000000e+000,1.000000e+000,2,2,8.110046e-001,0,,0,
1656985076.727,,5.500000e+004,3.618406e+002,1.161743e-002,3.236088e-006,-6.854525e-002,7.386762e-005,3,9.880904e-001,1.825000e+000,,,,,,,,,,,,,,,,,,0,4.000000e+000,1.000000e+000,2,2,2.740784e-001,0,,0,
1656986052.511,,5.500000e+004,3.329197e+002,3.026654e-003,6.272637e-007,-1.551658e-002,4.016667e-004,3,9.796194e-001,1.825000e+000,,,,,,,,,,,,,,,,,,0,4.000000e+000,1.000000e+000,2,2,9.287109e-001,0,,0,
1656986948.731,,5.500000e+004,3.058210e+002,2.997010e-003,3.258149e-007,-5.301600e-003,5.260750e-005,3,9.774001e-001,1.825000e+000,,,,,,,,,,,,,,,,,,0,4.000000e+000,1.000000e+000,2,2,3.099976e-001,0,,0,
1656988246.169,,5.500000e+004,3.214069e+002,2.966136e-003,6.378004e-007,-1.622700e-002,1.311939e-004,3,9.776871e-001,1.825000e+000,,,,,,,,,,,,,,,,,,0,4.000000e+000,1.000000e+000,2,2,4.021912e-001,0,,0,
1656989081.017,,5.500000e+004,3.492643e+002,3.047843e-003,6.904839e-007,-3.215742e-002,3.558300e-004,3,9.789733e-001,1.825000e+000,,,,,,,,,,,,,,,,,,0,4.000000e+000,1.000000e+000,2,2,4.109802e-001,0,,0,
1656989919.438,,5.500000e+004,3.772362e+002,1.123546e-002,3.702996e-006,-8.631681e-002,1.721172e-004,3,9.880130e-001,1.825000e+000,,,,,,,,,,,,,,,,,,0,4.000000e+000,1.000000e+000,2,2,4.140930e-001,0,,0,
1656991427.862,,5.000000e+004,3.954933e+002,9.816801e-003,6.394467e-006,-8.465928e-002,1.852933e-004,3,9.882342e-001,1.825000e+000,,,,,,,,,,,,,,,,,,0,4.000000e+000,1.000000e+000,2,2,7.613220e-001,0,,0,
1656992175.417,,5.000000e+004,3.664994e+002,1.047916e-002,4.885742e-006,-7.085538e-002,2.432505e-004,3,9.881513e-001,1.825000e+000,,,,,,,,,,,,,,,,,,0,4.000000e+000,1.000000e+000,2,2,6.498108e-001,0,,0,
1656993169.678,,5.000000e+004,3.395978e+002,2.772748e-003,1.741356e-006,-2.004712e-002,2.448100e-004,3,9.798025e-001,1.825000e+000,,,,,,,,,,,,,,,,,,0,4.000000e+000,1.000000e+000,2,2,7.841187e-001,0,,0,
1656993872.518,,5.000000e+004,3.115818e+002,2.722807e-003,9.120841e-008,-6.553832e-003,2.931445e-005,3,9.778327e-001,1.825000e+000,,,,,,,,,,,,,,,,,,0,4.000000e+000,1.000000e+000,2,2,6.300964e-001,0,,0,
1656995276.267,,5.000000e+004,3.153105e+002,2.699997e-003,2.798814e-007,-1.292395e-002,4.856173e-005,3,9.774441e-001,1.825000e+000,,,,,,,,,,,,,,,,,,0,4.000000e+000,1.000000e+000,2,2,3.940735e-001,0,,0,
1656996114.658,,5.000000e+004,3.432151e+002,2.741723e-003,4.585116e-007,-2.858255e-002,7.390318e-005,3,9.794196e-001,1.825000e+000,,,,,,,,,,,,,,,,,,0,4.000000e+000,1.000000e+000,2,2,4.527893e-001,0,,0,
1656996957.813,,5.000000e+004,3.713188e+002,6.772277e-003,2.470441e-004,-6.261040e-002,1.403113e-003,3,9.877801e-001,1.825000e+000,,,,,,,,,,,,,,,,,,0,4.000000e+000,1.000000e+000,2,2,4.229126e-001,0,,0,
1656997796.340,,5.000000e+004,3.992928e+002,9.749964e-003,3.031280e-006,-9.256642e-002,9.072109e-005,3,9.883437e-001,1.825000e+000,,,,,,,,,,,,,,,,,,0,4.000000e+000,1.000000e+000,2,2,4.128113e-001,0,,0,
1656999310.835,,4.500000e+004,3.728925e+002,9.309247e-003,8.662494e-006,-7.455425e-002,1.015212e-004,3,9.881957e-001,1.825000e+000,,,,,,,,,,,,,,,,,,0,4.000000e+000,1.000000e+000,2,2,1.089203e+000,0,,0,
1657000029.608,,4.500000e+004,3.452490e+002,5.942248e-003,2.524771e-004,-6.322072e-002,1.022996e-003,3,9.881443e-001,1.825000e+000,,,,,,,,,,,,,,,,,,0,4.000000e+000,1.000000e+000,2,2,5.826721e-001,0,,0,
1657001001.410,,4.500000e+004,3.174219e+002,2.448833e-003,4.117550e-007,-9.480272e-003,2.218531e-004,3,9.783688e-001,1.825000e+000,,,,,,,,,,,,,,,,,,0,4.000000e+000,1.000000e+000,2,2,8.872986e-001,0,,0,
1657002320.076,,4.500000e+004,3.092611e+002,2.439655e-003,3.259795e-008,-9.589940e-003,2.063161e-004,3,9.776739e-001,1.825000e+000,,,,,,,,,,,,,,,,,,0,4.000000e+000,1.000000e+000,2,2,4.536133e-001,0,,0,
1657003162.513,,4.500000e+004,3.372781e+002,2.451022e-003,2.100757e-007,-2.557421e-002,1.667461e-004,3,9.794097e-001,1.825000e+000,,,,,,,,,,,,,,,,,,0,4.000000e+000,1.000000e+000,2,2,4.638062e-001,0,,0,
1657004001.887,,4.500000e+004,3.652691e+002,2.723774e-003,5.597135e-006,-4.446337e-002,2.725162e-004,3,9.812971e-001,1.825000e+000,,,,,,,,,,,,,,,,,,0,4.000000e+000,1.000000e+000,2,2,4.085999e-001,0,,0,
1657004841.236,,4.500000e+004,3.932568e+002,8.900693e-003,3.905827e-006,-9.173188e-002,6.263021e-005,3,9.884548e-001,1.825000e+000,,,,,,,,,,,,,,,,,,0,4.000000e+000,1.000000e+000,2,2,4.138794e-001,0,,0,
1657006410.729,,4.000000e+004,3.797176e+002,8.149723e-003,3.868949e-006,-7.919505e-002,3.275337e-005,3,9.882506e-001,1.825000e+000,,,,,,,,,,,,,,,,,,0,4.000000e+000,1.000000e+000,2,2,4.082031e-001,0,,0,
1657007147.544,,4.000000e+004,3.504875e+002,8.659003e-003,5.960486e-006,-6.656502e-002,5.868580e-004,3,9.867142e-001,1.825000e+000,,,,,,,,,,,,,,,,,,0,4.000000e+000,1.000000e+000,2,2,8.477173e-001,0,,0,
1657007929.953,,4.000000e+004,3.239105e+002,2.189665e-003,1.346723e-007,-1.072111e-002,1.383602e-005,3,9.798340e-001,1.825000e+000,,,,,,,,,,,,,,,,,,0,4.000000e+000,1.000000e+000,2,2,1.251831e-001,0,,0,
1657009375.239,,4.000000e+004,3.033388e+002,2.180941e-003,4.082976e-008,-5.855255e-003,2.106644e-004,3,9.776144e-001,1.825000e+000,,,,,,,,,,,,,,,,,,0,4.000000e+000,1.000000e+000,2,2,5.440063e-001,0,,0,
1657010188.377,,4.000000e+004,3.312585e+002,2.172491e-003,4.402370e-007,-2.178328e-002,7.811655e-005,3,9.796201e-001,1.825000e+000,,,,,,,,,,,,,,,,,,0,4.000000e+000,1.000000e+000,2,2,4.201965e-001,0,,0,
1657011026.710,,4.000000e+004,3.592196e+002,2.303089e-003,1.405169e-006,-3.910822e-002,1.007968e-004,3,9.810393e-001,1.825000e+000,,,,,,,,,,,,,,,,,,0,4.000000e+000,1.000000e+000,2,2,4.153748e-001,0,,0,
1657011868.591,,4.000000e+004,3.872910e+002,8.009944e-003,3.257820e-006,-8.976718e-002,1.339111e-004,3,9.882575e-001,1.825000e+000,,,,,,,,,,,,,,,,,,0,4.000000e+000,1.000000e+000,2,2,4.495850e-001,0,,0,
1657013226.629,,3.500000e+004,3.856129e+002,7.060710e-003,4.595653e-006,-7.895345e-002,1.852459e-004,3,9.885761e-001,1.825000e+000,,,,,,,,,,,,,,,,,,0,4.000000e+000,1.000000e+000,2,2,6.623230e-001,0,,0,
1657014264.558,,3.500000e+004,3.575203e+002,7.540872e-003,5.237075e-006,-7.028157e-002,1.946710e-004,3,9.868099e-001,1.825000e+000,,,,,,,,,,,,,,,,,,0,4.000000e+000,1.000000e+000,2,2,8.943787e-001,0,,0,
1657014969.200,,3.500000e+004,3.292801e+002,1.924906e-003,7.112281e-007,-1.311057e-002,6.732959e-005,3,9.802631e-001,1.825000e+000,,,,,,,,,,,,,,,,,,0,4.000000e+000,1.000000e+000,2,2,7.608032e-001,0,,0,
1657015910.717,,3.500000e+004,3.015908e+002,1.918829e-003,1.689167e-007,-3.881150e-003,3.366260e-004,3,9.780902e-001,1.825000e+000,,,,,,,,,,,,,,,,,,0,4.000000e+000,1.000000e+000,2,2,7.021179e-001,0,,0,
1657017218.298,,3.500000e+004,3.252454e+002,1.896687e-003,4.571122e-007,-1.800615e-002,7.922923e-004,3,9.792458e-001,1.825000e+000,,,,,,,,,,,,,,,,,,0,4.000000e+000,1.000000e+000,2,2,4.125977e-001,0,,0,
1657018057.902,,3.500000e+004,3.532688e+002,1.967886e-003,3.179288e-006,-3.483603e-002,1.222285e-004,3,9.803058e-001,1.825000e+000,,,,,,,,,,,,,,,,,,0,4.000000e+000,1.000000e+000,2,2,4.110107e-001,0,,0,
1657018903.473,,3.500000e+004,3.814575e+002,7.138037e-003,3.355284e-006,-8.811588e-002,1.019532e-004,3,9.881780e-001,1.825000e+000,,,,,,,,,,,,,,,,,,0,4.000000e+000,1.000000e+000,2,2,4.472046e-001,0,,0,
1657020349.922,,3.000000e+004,3.914657e+002,5.987226e-003,5.459992e-006,-8.247077e-002,6.395784e-005,3,9.885429e-001,1.825000e+000,,,,,,,,,,,,,,,,,,0,4.000000e+000,1.000000e+000,2,2,8.326111e-001,0,,0,
1657021094.804,,3.000000e+004,3.635278e+002,6.387101e-003,3.867632e-006,-6.983303e-002,2.073941e-004,3,9.876751e-001,1.825000e+000,,,,,,,,,,,,,,,,,,0,4.000000e+000,1.000000e+000,2,2,5.429993e-001,0,,0,
1657022095.377,,3.000000e+004,3.353967e+002,1.659123e-003,9.420479e-007,-1.708432e-002,6.861771e-004,3,9.799664e-001,1.825000e+000,,,,,,,,,,,,,,,,,,0,4.000000e+000,1.000000e+000,2,2,1.008484e+000,0,,0,
1657022843.677,,3.000000e+004,3.078055e+002,1.642661e-003,9.896278e-007,-4.811249e-003,2.134837e-005,3,9.788991e-001,1.825000e+000,,,,,,,,,,,,,,,,,,0,4.000000e+000,1.000000e+000,2,2,2.844238e-001,0,,0,
1657024263.046,,3.000000e+004,3.193464e+002,1.626826e-003,1.023214e-007,-1.495555e-002,3.421890e-004,3,9.788163e-001,1.825000e+000,,,,,,,,,,,,,,,,,,0,4.000000e+000,1.000000e+000,2,2,4.048767e-001,0,,0,
1657025100.185,,3.000000e+004,3.472915e+002,1.663274e-003,3.424678e-006,-3.095068e-002,5.948764e-005,3,9.799036e-001,1.825000e+000,,,,,,,,,,,,,,,,,,0,4.000000e+000,1.000000e+000,2,2,3.578186e-001,0,,0,
1657025939.382,,3.000000e+004,3.752798e+002,6.227576e-003,3.253210e-006,-8.666055e-002,1.130642e-004,3,9.876525e-001,1.825000e+000,,,,,,,,,,,,,,,,,,0,4.000000e+000,1.000000e+000,2,2,4.096069e-001,0,,0,
1657027457.276,,2.500000e+004,3.978044e+002,4.927940e-003,2.027329e-006,-8.748531e-002,5.827329e-005,3,9.885536e-001,1.825000e+000,,,,,,,,,,,,,,,,,,0,4.000000e+000,1.000000e+000,2,2,3.460083e-001,0,,0,
1657028230.596,,2.500000e+004,3.686021e+002,5.278887e-003,1.376621e-005,-7.319147e-002,7.857648e-004,3,9.876494e-001,1.825000e+000,,,,,,,,,,,,,,,,,,0,4.000000e+000,1.000000e+000,2,2,7.344055e-001,0,,0,
1657029194.286,,2.500000e+004,3.418785e+002,1.401583e-003,7.338655e-007,-2.090422e-002,2.373934e-004,3,9.811320e-001,1.825000e+000,,,,,,,,,,,,,,,,,,0,4.000000e+000,1.000000e+000,2,2,2.152100e-001,0,,0,
1657029921.011,,2.500000e+004,3.136047e+002,1.369681e-003,3.810503e-007,-6.819293e-003,5.504829e-004,3,9.795480e-001,1.825000e+000,,,,,,,,,,,,,,,,,,0,4.000000e+000,1.000000e+000,2,2,6.230774e-001,0,,0,
1657031297.619,,2.500000e+004,3.132700e+002,1.359693e-003,5.832235e-007,-1.123668e-002,1.293414e-004,3,9.786638e-001,1.825000e+000,,,,,,,,,,,,,,,,,,0,4.000000e+000,1.000000e+000,2,2,3.652954e-001,0,,0,
1657032147.485,,2.500000e+004,3.414767e+002,1.373140e-003,6.921303e-007,-2.622461e-002,2.326769e-004,3,9.796476e-001,1.825000e+000,,,,,,,,,,,,,,,,,,0,4.000000e+000,1.000000e+000,2,2,4.012756e-001,0,,0,
1657032979.854,,2.500000e+004,3.692305e+002,2.524232e-003,1.011714e-004,-5.363257e-002,1.216753e-003,3,9.880152e-001,1.825000e+000,,,,,,,,,,,,,,,,,,0,4.000000e+000,1.000000e+000,2,2,3.850098e-001,0,,0,
1657033821.658,,2.500000e+004,3.972795e+002,4.948159e-003,1.682911e-006,-9.217274e-002,3.701020e-005,3,9.883105e-001,1.825000e+000,,,,,,,,,,,,,,,,,,0,4.000000e+000,1.000000e+000,2,2,4.219971e-001,0,,0,
1657035357.204,,2.000000e+004,3.753370e+002,4.153218e-003,2.940730e-006,-7.544604e-002,2.986736e-004,3,9.879728e-001,1.825000e+000,,,,,,,,,,,,,,,,,,0,4.000000e+000,1.000000e+000,2,2,9.106140e-001,0,,0,
1657036073.274,,2.000000e+004,3.470620e+002,4.030294e-003,8.237305e-005,-6.460319e-002,3.208956e-005,3,9.858852e-001,1.825000e+000,,,,,,,,,,,,,,,,,,0,4.000000e+000,1.000000e+000,2,2,5.794983e-001,0,,0,
1657037037.801,,2.000000e+004,3.195045e+002,1.096524e-003,1.193200e-006,-9.562548e-003,8.404937e-005,3,9.792089e-001,1.825000e+000,,,,,,,,,,,,,,,,,,0,4.000000e+000,1.000000e+000,2,2,7.376099e-001,0,,0,
1657038345.482,,2.000000e+004,3.073218e+002,1.095450e-003,4.944846e-007,-7.836873e-003,3.829146e-004,3,9.786885e-001,1.825000e+000,,,,,,,,,,,,,,,,,,0,4.000000e+000,1.000000e+000,2,2,4.848022e-001,0,,0,
1657039180.224,,2.000000e+004,3.352633e+002,1.098290e-003,2.006091e-007,-2.312101e-002,3.501218e-005,3,9.810717e-001,1.825000e+000,,,,,,,,,,,,,,,,,,0,4.000000e+000,1.000000e+000,2,2,4.489136e-001,0,,0,
1657040017.595,,2.000000e+004,3.632060e+002,1.194542e-003,2.320628e-006,-4.185342e-002,1.811156e-004,3,9.822317e-001,1.825000e+000,,,,,,,,,,,,,,,,,,0,4.000000e+000,1.000000e+000,2,2,4.037781e-001,0,,0,
1657040859.730,,2.000000e+004,3.912917e+002,4.011036e-003,5.897267e-007,-9.026796e-002,1.738768e-004,3,9.882509e-001,1.825000e+000,,,,,,,,,,,,,,,,,,0,4.000000e+000,1.000000e+000,2,2,4.096069e-001,0,,0,
1657042189.567,,1.500000e+004,3.817638e+002,3.071736e-003,2.785643e-007,-7.627025e-002,3.456042e-005,3,9.883643e-001,1.825000e+000,,,,,,,,,,,,,,,,,,0,4.000000e+000,1.000000e+000,2,2,3.537903e-001,0,,0,
1657043191.481,,1.500000e+004,3.529936e+002,3.273700e-003,2.062561e-006,-6.657757e-002,1.905196e-004,3,9.859716e-001,1.825000e+000,,,,,,,,,,,,,,,,,,0,4.000000e+000,1.000000e+000,2,2,9.306946e-001,0,,0,
1657043923.785,,1.500000e+004,3.257239e+002,8.296968e-004,5.901382e-007,-1.039197e-002,2.341949e-004,3,9.802524e-001,1.825000e+000,,,,,,,,,,,,,,,,,,0,4.000000e+000,1.000000e+000,2,2,3.293762e-001,0,,0,
1657045392.893,,1.500000e+004,3.012311e+002,8.285207e-004,2.083059e-007,-4.911262e-003,3.282996e-004,3,9.789240e-001,1.825000e+000,,,,,,,,,,,,,,,,,,0,4.000000e+000,1.000000e+000,2,2,4.073181e-001,0,,0,
1657046204.082,,1.500000e+004,3.292670e+002,8.222261e-004,5.149818e-007,-1.970119e-002,2.178070e-005,3,9.797836e-001,1.825000e+000,,,,,,,,,,,,,,,,,,0,4.000000e+000,1.000000e+000,2,2,4.147949e-001,0,,0,
1657047043.761,,1.500000e+004,3.572709e+002,8.640226e-004,1.031692e-006,-3.678866e-002,5.584194e-004,3,9.817780e-001,1.825000e+000,,,,,,,,,,,,,,,,,,0,4.000000e+000,1.000000e+000,2,2,4.208984e-001,0,,0,
1657047883.596,,1.500000e+004,3.852669e+002,3.056064e-003,1.226539e-006,-8.877286e-002,9.307078e-005,3,9.879924e-001,1.825000e+000,,,,,,,,,,,,,,,,,,0,4.000000e+000,1.000000e+000,2,2,4.085999e-001,0,,0,
1657049267.193,,1.000000e+004,3.873277e+002,2.034744e-003,1.570464e-006,-7.943627e-002,2.597194e-004,3,9.881517e-001,1.825000e+000,,,,,,,,,,,,,,,,,,0,4.000000e+000,1.000000e+000,2,2,7.899170e-001,0,,0,
1657050291.966,,1.000000e+004,3.596589e+002,2.163032e-003,1.133520e-006,-7.030334e-002,1.260191e-005,3,9.864734e-001,1.825000e+000,,,,,,,,,,,,,,,,,,0,4.000000e+000,1.000000e+000,2,2,6.141968e-001,0,,0,
1657050997.769,,1.000000e+004,3.312566e+002,5.573824e-004,1.738558e-007,-1.383974e-002,3.858735e-004,3,9.799336e-001,1.825000e+000,,,,,,,,,,,,,,,,,,0,4.000000e+000,1.000000e+000,2,2,8.840942e-001,0,,0,
1657051926.802,,1.000000e+004,3.036747e+002,5.556779e-004,1.174267e-007,-4.087124e-003,3.255767e-004,3,9.787024e-001,1.825000e+000,,,,,,,,,,,,,,,,,,0,4.000000e+000,1.000000e+000,2,2,6.252136e-001,0,,0,
1657053217.783,,1.000000e+004,3.232756e+002,5.501456e-004,3.674678e-007,-1.675360e-002,1.198814e-004,3,9.796584e-001,1.825000e+000,,,,,,,,,,,,,,,,,,0,4.000000e+000,1.000000e+000,2,2,4.154968e-001,0,,0,
1657054055.713,,1.000000e+004,3.512533e+002,5.677335e-004,4.695834e-007,-3.251943e-002,1.045953e-004,3,9.814475e-001,1.825000e+000,,,,,,,,,,,,,,,,,,0,4.000000e+000,1.000000e+000,2,2,4.161072e-001,0,,0,
1657054895.099,,1.000000e+004,3.792459e+002,2.072626e-003,1.426737e-006,-8.690526e-002,2.250747e-004,3,9.877499e-001,1.825000e+000,,,,,,,,,,,,,,,,,,0,4.000000e+000,1.000000e+000,2,2,4.534912e-001,0,,0,
1657056351.190,,9.000000e+003,3.933103e+002,1.809772e-003,1.258479e-006,-8.368763e-002,1.363819e-004,3,9.878168e-001,1.825000e+000,,,,,,,,,,,,,,,,,,0,4.000000e+000,1.000000e+000,2,2,8.782959e-001,0,,0,
1657057085.923,,9.000000e+003,3.653579e+002,1.926695e-003,5.625616e-007,-7.021099e-002,2.732591e-004,3,9.869790e-001,1.825000e+000,,,,,,,,,,,,,,,,,,0,4.000000e+000,1.000000e+000,2,2,6.132813e-001,0,,0,
1657058081.534,,9.000000e+003,3.373421e+002,5.064431e-004,9.000657e-007,-1.758050e-002,2.182035e-004,3,9.810447e-001,1.825000e+000,,,,,,,,,,,,,,,,,,0,4.000000e+000,1.000000e+000,2,2,9.465027e-001,0,,0,
1657058810.763,,9.000000e+003,3.097477e+002,4.998874e-004,1.200197e-007,-5.139505e-003,1.625854e-004,3,9.791132e-001,1.825000e+000,,,,,,,,,,,,,,,,,,0,4.000000e+000,1.000000e+000,2,2,4.097290e-001,0,,0,
1657060214.727,,9.000000e+003,3.172538e+002,4.957287e-004,1.061492e-007,-1.361925e-002,1.734178e-004,3,9.790213e-001,1.825000e+000,,,,,,,,,,,,,,,,,,0,4.000000e+000,1.000000e+000,2,2,4.071960e-001,0,,0,
1657061054.971,,9.000000e+003,3.452728e+002,5.045043e-004,1.015517e-006,-2.898826e-002,3.417411e-004,3,9.806125e-001,1.825000e+000,,,,,,,,,,,,,,,,,,0,4.000000e+000,1.000000e+000,2,2,4.108276e-001,0,,0,
1657061894.604,,9.000000e+003,3.732771e+002,1.805977e-003,1.398230e-005,-8.252433e-002,2.686124e-004,3,9.873785e-001,1.825000e+000,,,,,,,,,,,,,,,,,,0,4.000000e+000,1.000000e+000,2,2,4.051208e-001,0,,0,
1657063327.252,,8.000000e+003,4.000035e+002,1.593785e-003,3.172538e-007,-8.973201e-002,9.674282e-005,3,9.868219e-001,1.825000e+000,,,,,,,,,,,,,,,,,,0,4.000000e+000,1.000000e+000,2,2,0.000000e+000,0,,0,
1657064179.782,,8.000000e+003,3.706496e+002,1.702014e-003,2.003210e-006,-7.369485e-002,1.615436e-004,3,9.857101e-001,1.825000e+000,,,,,,,,,,,,,,,,,,0,4.000000e+000,1.000000e+000,2,2,8.093872e-001,0,,0,
1657064917.337,,8.000000e+003,3.437797e+002,9.646188e-004,3.297727e-005,-5.847887e-002,6.348395e-004,3,9.881181e-001,1.825000e+000,,,,,,,,,,,,,,,,,,0,4.000000e+000,1.000000e+000,2,2,3.597107e-001,0,,0,
1657065863.355,,8.000000e+003,3.155118e+002,4.448212e-004,1.419163e-007,-8.148761e-003,2.372202e-004,3,9.800006e-001,1.825000e+000,,,,,,,,,,,,,,,,,,0,4.000000e+000,1.000000e+000,2,2,7.971191e-001,0,,0,
1657067216.568,,8.000000e+003,3.113035e+002,4.426482e-004,1.885289e-007,-1.033826e-002,8.538095e-005,3,9.787488e-001,1.825000e+000,,,,,,,,,,,,,,,,,,0,4.000000e+000,1.000000e+000,2,2,4.600220e-001,0,,0,
1657068059.114,,8.000000e+003,3.392543e+002,4.460656e-004,2.165788e-007,-2.586867e-002,1.109608e-004,3,9.811727e-001,1.825000e+000,,,,,,,,,,,,,,,,,,0,4.000000e+000,1.000000e+000,2,2,3.866882e-001,0,,0,
1657068899.214,,8.000000e+003,3.672889e+002,5.729831e-004,1.343180e-005,-4.611939e-002,3.004807e-005,3,9.855262e-001,1.825000e+000,,,,,,,,,,,,,,,,,,0,4.000000e+000,1.000000e+000,2,2,4.024963e-001,0,,0,
1657069739.337,,8.000000e+003,3.952903e+002,1.614390e-003,2.795522e-007,-9.316057e-002,1.757998e-004,3,9.860679e-001,1.825000e+000,,,,,,,,,,,,,,,,,,0,4.000000e+000,1.000000e+000,2,2,4.057007e-001,0,,0,
1657071279.428,,7.000000e+003,3.774349e+002,1.471010e-003,2.710734e-007,-7.805666e-002,4.399080e-006,3,9.858629e-001,1.825000e+000,,,,,,,,,,,,,,,,,,0,4.000000e+000,1.000000e+000,2,2,7.946167e-001,0,,0,
1657071999.087,,7.000000e+003,3.484564e+002,1.526220e-003,4.633272e-006,-6.382671e-002,1.750938e-004,3,9.867267e-001,1.825000e+000,,,,,,,,,,,,,,,,,,0,4.000000e+000,1.000000e+000,2,2,6.524963e-001,0,,0,
1657072951.644,,7.000000e+003,3.215856e+002,3.909110e-004,1.996419e-007,-1.094584e-002,2.345676e-004,3,9.798961e-001,1.825000e+000,,,,,,,,,,,,,,,,,,0,4.000000e+000,1.000000e+000,2,2,6.245117e-001,0,,0,
1657074245.077,,7.000000e+003,3.054378e+002,3.907485e-004,1.365657e-007,-6.991782e-003,7.503028e-005,3,9.783770e-001,1.825000e+000,,,,,,,,,,,,,,,,,,0,4.000000e+000,1.000000e+000,2,2,5.595093e-001,0,,0,
1657075065.610,,7.000000e+003,3.332470e+002,3.899270e-004,9.857610e-009,-2.260622e-002,2.315877e-004,3,9.808839e-001,1.825000e+000,,,,,,,,,,,,,,,,,,0,4.000000e+000,1.000000e+000,2,2,4.165955e-001,0,,0,
1657075911.307,,7.000000e+003,3.614588e+002,4.164636e-004,1.332112e-006,-4.046170e-002,4.531049e-005,3,9.812165e-001,1.825000e+000,,,,,,,,,,,,,,,,,,0,4.000000e+000,1.000000e+000,2,2,4.103088e-001,0,,0,
1657076744.604,,7.000000e+003,3.892515e+002,1.437739e-003,4.661672e-007,-9.139031e-002,6.708725e-005,3,9.853438e-001,1.825000e+000,,,,,,,,,,,,,,,,,,0,4.000000e+000,1.000000e+000,2,2,3.928833e-001,0,,0,
1657078074.906,,6.000000e+003,3.836366e+002,1.242965e-003,1.447975e-007,-7.844813e-002,4.716232e-005,3,9.867132e-001,1.825000e+000,,,,,,,,,,,,,,,,,,0,4.000000e+000,1.000000e+000,2,2,4.884033e-001,0,,0,
1657079098.315,,6.000000e+003,3.550505e+002,1.315428e-003,2.479502e-006,-6.807466e-002,1.821956e-004,3,9.853572e-001,1.825000e+000,,,,,,,,,,,,,,,,,,0,4.000000e+000,1.000000e+000,2,2,1.023010e+000,0,,0,
1657079807.529,,6.000000e+003,3.276423e+002,3.375105e-004,1.176531e-007,-1.196910e-002,1.740013e-004,3,9.805128e-001,1.825000e+000,,,,,,,,,,,,,,,,,,0,4.000000e+000,1.000000e+000,2,2,4.960938e-001,0,,0,
1657080997.037,,6.000000e+003,3.000906e+002,3.381717e-004,1.021773e-007,-3.009535e-003,2.844881e-004,3,9.787931e-001,1.825000e+000,,,,,,,,,,,,,,,,,,0,4.000000e+000,1.000000e+000,2,2,7.080078e-003,0,,0,
1657082083.450,,6.000000e+003,3.273689e+002,3.341281e-004,1.910602e-007,-1.887152e-002,1.150108e-004,3,9.794800e-001,1.825000e+000,,,,,,,,,,,,,,,,,,0,4.000000e+000,1.000000e+000,2,2,4.096985e-001,0,,0,
1657082922.081,,6.000000e+003,3.553164e+002,3.474096e-004,4.914388e-007,-3.625423e-002,4.033453e-005,3,9.808004e-001,1.825000e+000,,,,,,,,,,,,,,,,,,0,4.000000e+000,1.000000e+000,2,2,4.161072e-001,0,,0,
1657083760.688,,6.000000e+003,3.832646e+002,1.249519e-003,8.676324e-007,-8.987312e-002,1.006994e-004,3,9.854391e-001,1.825000e+000,,,,,,,,,,,,,,,,,,0,4.000000e+000,1.000000e+000,2,2,4.042969e-001,0,,0,
1657085167.344,,5.000000e+003,3.893438e+002,1.022352e-003,6.656239e-007,-8.164877e-002,1.907619e-004,3,9.870581e-001,1.825000e+000,,,,,,,,,,,,,,,,,,0,4.000000e+000,1.000000e+000,2,2,8.846130e-001,0,,0,
1657085941.865,,5.000000e+003,3.619038e+002,1.090165e-003,1.864586e-006,-6.900943e-002,1.945077e-005,3,9.847095e-001,1.825000e+000,,,,,,,,,,,,,,,,,,0,4.000000e+000,1.000000e+000,2,2,2.108765e-001,0,,0,
1657086901.872,,5.000000e+003,3.330258e+002,2.831542e-004,1.246296e-007,-1.563020e-002,5.601053e-005,3,9.803326e-001,1.825000e+000,,,,,,,,,,,,,,,,,,0,4.000000e+000,1.000000e+000,2,2,8.053284e-001,0,,0,
1657087805.495,,5.000000e+003,3.057565e+002,2.818492e-004,1.049761e-007,-4.840949e-003,1.626671e-005,3,9.783300e-001,1.825000e+000,,,,,,,,,,,,,,,,,,0,4.000000e+000,1.000000e+000,2,2,4.353027e-001,0,,0,
1657089100.642,,5.000000e+003,3.214315e+002,2.789980e-004,2.086763e-008,-1.698095e-002,4.990358e-004,3,9.786634e-001,1.825000e+000,,,,,,,,,,,,,,,,,,0,4.000000e+000,1.000000e+000,2,2,4.023132e-001,0,,0,
1657089934.191,,5.000000e+003,3.492202e+002,2.854113e-004,1.773954e-008,-3.183618e-002,8.063324e-004,3,9.800934e-001,1.825000e+000,,,,,,,,,,,,,,,,,,0,4.000000e+000,1.000000e+000,2,2,4.207153e-001,0,,0,
1657090777.260,,5.000000e+003,3.772937e+002,1.055847e-003,2.057952e-008,-8.758590e-002,1.326256e-004,3,9.850669e-001,1.825000e+000,,,,,,,,,,,,,,,,,,0,4.000000e+000,1.000000e+000,2,2,4.141846e-001,0,,0,
1657092268.930,,4.000000e+003,3.955440e+002,8.062673e-004,5.250658e-007,-8.599627e-002,3.638853e-005,3,9.876084e-001,1.825000e+000,,,,,,,,,,,,,,,,,,0,4.000000e+000,1.000000e+000,2,2,7.614746e-001,0,,0,
1657093025.771,,4.000000e+003,3.666431e+002,8.654116e-004,2.670810e-007,-7.129225e-002,3.127086e-004,3,9.847938e-001,1.825000e+000,,,,,,,,,,,,,,,,,,0,4.000000e+000,1.000000e+000,2,2,7.910156e-001,0,,0,
1657094018.459,,4.000000e+003,3.396162e+002,2.296440e-004,5.044039e-008,-1.966103e-002,2.970865e-004,3,9.800915e-001,1.825000e+000,,,,,,,,,,,,,,,,,,0,4.000000e+000,1.000000e+000,2,2,7.473145e-001,0,,0,
1657094726.201,,4.000000e+003,3.116433e+002,2.263453e-004,2.061759e-007,-6.926081e-003,8.361079e-005,3,9.784993e-001,1.825000e+000,,,,,,,,,,,,,,,,,,0,4.000000e+000,1.000000e+000,2,2,5.688171e-001,0,,0,
1657096131.378,,4.000000e+003,3.152475e+002,2.247455e-004,1.023419e-007,-1.305197e-002,6.276535e-004,3,9.779528e-001,1.825000e+000,,,,,,,,,,,,,,,,,,0,4.000000e+000,1.000000e+000,2,2,4.330750e-001,0,,0,
1657096974.689,,4.000000e+003,3.432741e+002,2.274227e-004,3.985532e-007,-2.888155e-002,2.266154e-003,3,9.800947e-001,1.825000e+000,,,,,,,,,,,,,,,,,,0,4.000000e+000,1.000000e+000,2,2,4.059143e-001,0,,0,
1657097818.781,,4.000000e+003,3.712742e+002,6.903263e-004,1.243916e-005,-7.301530e-002,5.702627e-004,3,9.859666e-001,1.825000e+000,,,,,,,,,,,,,,,,,,0,4.000000e+000,1.000000e+000,2,2,4.227905e-001,0,,0,
1657098658.708,,4.000000e+003,3.992671e+002,8.014537e-004,3.583305e-007,-9.337559e-002,1.256977e-004,3,9.873804e-001,1.825000e+000,,,,,,,,,,,,,,,,,,0,4.000000e+000,1.000000e+000,2,2,4.128113e-001,0,,0,
1657100141.113,,3.000000e+003,3.728755e+002,6.416163e-004,3.399736e-008,-7.521181e-002,3.632374e-004,3,9.852216e-001,1.825000e+000,,,,,,,,,,,,,,,,,,0,4.000000e+000,1.000000e+000,2,2,9.318237e-001,0,,0,
1657100855.212,,3.000000e+003,3.457369e+002,5.595714e-004,1.581017e-005,-6.460081e-002,2.470865e-006,3,9.859322e-001,1.825000e+000,,,,,,,,,,,,,,,,,,0,4.000000e+000,1.000000e+000,2,2,5.652161e-001,0,,0,
1657101825.764,,3.000000e+003,3.174898e+002,1.715482e-004,1.794534e-008,-9.547500e-003,1.648993e-003,3,9.790543e-001,1.825000e+000,,,,,,,,,,,,,,,,,,0,4.000000e+000,1.000000e+000,2,2,8.395996e-001,0,,0,
1657103156.373,,3.000000e+003,3.093935e+002,1.708437e-004,1.048423e-007,-9.443523e-003,2.541487e-003,3,9.764075e-001,1.825000e+000,,,,,,,,,,,,,,,,,,0,4.000000e+000,1.000000e+000,2,2,4.390259e-001,0,,0,
1657104008.680,,3.000000e+003,3.373008e+002,1.713793e-004,8.537412e-008,-2.552213e-002,2.655054e-004,3,9.800706e-001,1.825000e+000,,,,,,,,,,,,,,,,,,0,4.000000e+000,1.000000e+000,2,2,4.000854e-001,0,,0,
1657104849.650,,3.000000e+003,3.652933e+002,1.918263e-004,5.348513e-007,-4.532684e-002,2.329325e-004,3,9.824603e-001,1.825000e+000,,,,,,,,,,,,,,,,,,0,4.000000e+000,1.000000e+000,2,2,4.839783e-001,0,,0,
1657105694.883,,3.000000e+003,3.932694e+002,6.119361e-004,2.271979e-008,-9.193625e-002,3.515574e-005,3,9.866453e-001,1.825000e+000,,,,,,,,,,,,,,,,,,0,4.000000e+000,1.000000e+000,2,2,4.140015e-001,0,,0,
1657107262.343,,2.500000e+003,3.797583e+002,5.262047e-004,9.625862e-007,-7.877685e-002,4.967006e-005,3,9.858728e-001,1.825000e+000,,,,,,,,,,,,,,,,,,0,4.000000e+000,1.000000e+000,2,2,4.314880e-001,0,,0,
1657108004.617,,2.500000e+003,3.504727e+002,5.544347e-004,5.141175e-007,-6.555997e-002,2.360487e-004,3,9.857064e-001,1.825000e+000,,,,,,,,,,,,,,,,,,0,4.000000e+000,1.000000e+000,2,2,7.689209e-001,0,,0,
1657108845.461,,2.500000e+003,3.239982e+002,1.439638e-004,6.524736e-008,-1.153029e-002,3.499617e-004,3,9.790428e-001,1.825000e+000,,,,,,,,,,,,,,,,,,0,4.000000e+000,1.000000e+000,2,2,8.392334e-003,0,,0,
1657110246.844,,2.500000e+003,3.033733e+002,1.440160e-004,5.349645e-008,-6.933198e-003,8.633858e-004,3,9.773550e-001,1.825000e+000,,,,,,,,,,,,,,,,,,0,4.000000e+000,1.000000e+000,2,2,5.804138e-001,0,,0,
1657111072.250,,2.500000e+003,3.312870e+002,1.432858e-004,1.111603e-007,-2.299239e-002,2.504906e-004,3,9.796439e-001,1.825000e+000,,,,,,,,,,,,,,,,,,0,4.000000e+000,1.000000e+000,2,2,4.465027e-001,0,,0,
1657111914.857,,2.500000e+003,3.593157e+002,1.515372e-004,6.452707e-008,-4.057455e-002,6.246953e-004,3,9.811162e-001,1.825000e+000,,,,,,,,,,,,,,,,,,0,4.000000e+000,1.000000e+000,2,2,4.051208e-001,0,,0,
1657112751.903,,2.500000e+003,3.872334e+002,5.191081e-004,2.843266e-007,-9.066541e-002,1.360816e-005,3,9.854927e-001,1.825000e+000,,,,,,,,,,,,,,,,,,0,4.000000e+000,1.000000e+000,2,2,3.765869e-001,0,,0,
1657114098.320,,2.000000e+003,3.855887e+002,4.151357e-004,1.861211e-007,-7.891676e-002,4.852159e-006,3,9.870923e-001,1.825000e+000,,,,,,,,,,,,,,,,,,0,4.000000e+000,1.000000e+000,2,2,6.020203e-001,0,,0,
1657115134.082,,2.000000e+003,3.574586e+002,4.411063e-004,1.810997e-007,-6.943575e-002,1.418241e-004,3,9.852308e-001,1.825000e+000,,,,,,,,,,,,,,,,,,0,4.000000e+000,1.000000e+000,2,2,8.428955e-001,0,,0,
1657115838.657,,2.000000e+003,3.293189e+002,1.166352e-004,1.835693e-008,-1.489127e-002,1.496332e-004,3,9.798841e-001,1.825000e+000,,,,,,,,,,,,,,,,,,0,4.000000e+000,1.000000e+000,2,2,6.050720e-001,0,,0,
1657116783.603,,2.000000e+003,3.014924e+002,1.164568e-004,1.291107e-007,2.070120e-003,1.859468e-003,3,9.754161e-001,1.825000e+000,,,,,,,,,,,,,,,,,,0,4.000000e+000,1.000000e+000,2,2,7.874146e-001,0,,0,
1657118096.983,,2.000000e+003,3.252664e+002,1.153706e-004,1.487899e-008,-1.933338e-002,7.061309e-004,3,9.787457e-001,1.825000e+000,,,,,,,,,,,,,,,,,,0,4.000000e+000,1.000000e+000,2,2,3.198853e-001,0,,0,
1657118940.263,,2.000000e+003,3.533390e+002,1.193347e-004,6.263375e-008,-3.614579e-002,4.889825e-005,3,9.800761e-001,1.825000e+000,,,,,,,,,,,,,,,,,,0,4.000000e+000,1.000000e+000,2,2,4.514160e-001,0,,0,
1657119785.014,,2.000000e+003,3.814752e+002,4.209414e-004,4.095735e-007,-8.817282e-002,1.095502e-004,3,9.852108e-001,1.825000e+000,,,,,,,,,,,,,,,,,,0,4.000000e+000,1.000000e+000,2,2,5.415039e-001,0,,0,
1657121207.290,,1.500000e+003,3.914812e+002,3.071521e-004,4.013623e-007,-8.230607e-002,8.054262e-005,3,9.876885e-001,1.825000e+000,,,,,,,,,,,,,,,,,,0,4.000000e+000,1.000000e+000,2,2,8.946838e-001,0,,0,
1657121949.334,,1.500000e+003,3.636024e+002,3.279408e-004,2.362528e-008,-6.917126e-002,3.713190e-004,3,9.855731e-001,1.825000e+000,,,,,,,,,,,,,,,,,,0,4.000000e+000,1.000000e+000,2,2,5.644836e-001,0,,0,
1657122949.637,,1.500000e+003,3.351850e+002,8.881486e-005,5.249320e-008,-1.747047e-002,8.150885e-004,3,9.787785e-001,1.825000e+000,,,,,,,,,,,,,,,,,,0,4.000000e+000,1.000000e+000,2,2,9.153137e-001,0,,0,
1657123709.345,,1.500000e+003,3.078542e+002,8.811490e-005,7.062890e-008,-6.721114e-003,3.298867e-004,3,9.773498e-001,1.825000e+000,,,,,,,,,,,,,,,,,,0,4.000000e+000,1.000000e+000,2,2,2.544861e-001,0,,0,
1657125120.967,,1.500000e+003,3.192836e+002,8.736534e-005,5.842525e-008,-1.640695e-002,4.809693e-004,3,9.766881e-001,1.825000e+000,,,,,,,,,,,,,,,,,,0,4.000000e+000,1.000000e+000,2,2,4.531860e-001,0,,0,
1657125960.528,,1.500000e+003,3.473013e+002,8.906957e-005,1.039780e-008,-3.131355e-002,1.238709e-004,3,9.786381e-001,1.825000e+000,,,,,,,,,,,,,,,,,,0,4.000000e+000,1.000000e+000,2,2,4.545898e-001,0,,0,
1657126799.194,,1.500000e+003,3.752713e+002,3.200652e-004,5.060915e-007,-8.615412e-002,9.151134e-005,3,9.854597e-001,1.825000e+000,,,,,,,,,,,,,,,,,,0,4.000000e+000,1.000000e+000,2,2,4.437256e-001,0,,0,
1657128293.356,,1.000000e+003,3.977659e+002,2.019238e-004,1.875000e-007,-8.658927e-002,1.119104e-004,3,9.882029e-001,1.825000e+000,,,,,,,,,,,,,,,,,,0,4.000000e+000,1.000000e+000,2,2,4.229126e-001,0,,0,
1657129078.058,,1.000000e+003,3.678694e+002,2.174499e-004,3.708943e-007,-7.138979e-002,3.793374e-004,3,9.853488e-001,1.825000e+000,,,,,,,,,,,,,,,,,,0,4.000000e+000,1.000000e+000,2,2,9.387207e-001,0,,0,
1657130023.167,,1.000000e+003,3.419253e+002,6.101496e-005,2.746336e-008,-2.191565e-002,2.096226e-004,3,9.782978e-001,1.825000e+000,,,,,,,,,,,,,,,,,,0,4.000000e+000,1.000000e+000,2,2,1.590881e-001,0,,0,
1657130760.369,,1.000000e+003,3.135327e+002,5.973448e-005,4.170696e-008,-8.589349e-003,4.293776e-004,3,9.768754e-001,1.825000e+000,,,,,,,,,,,,,,,,,,0,4.000000e+000,1.000000e+000,2,2,7.940063e-001,0,,0,
1657132137.806,,1.000000e+003,3.132856e+002,5.932722e-005,4.763129e-008,-1.288424e-002,3.831017e-005,3,9.742610e-001,1.825000e+000,,,,,,,,,,,,,,,,,,0,4.000000e+000,1.000000e+000,2,2,4.351807e-001,0,,0,
1657132988.576,,1.000000e+003,3.415000e+002,5.990713e-005,4.395013e-008,-2.747424e-002,2.096384e-004,3,9.773083e-001,1.825000e+000,,,,,,,,,,,,,,,,,,0,4.000000e+000,1.000000e+000,2,2,4.201050e-001,0,,0,
1657133821.867,,1.000000e+003,3.692827e+002,1.286179e-004,4.518315e-006,-6.077555e-002,1.273999e-003,3,9.877059e-001,1.825000e+000,,,,,,,,,,,,,,,,,,0,4.000000e+000,1.000000e+000,2,2,4.620056e-001,0,,0,
1657134660.281,,1.000000e+003,3.972284e+002,2.030936e-004,9.423360e-008,-9.200154e-002,2.361909e-004,3,9.875173e-001,1.825000e+000,,,,,,,,,,,,,,,,,,0,4.000000e+000,1.000000e+000,2,2,4.473877e-001,0,,0,
1657136169.734,,9.000000e+002,3.750272e+002,1.927037e-004,1.884260e-007,-7.533491e-002,2.061086e-004,3,9.854927e-001,1.825000e+000,,,,,,,,,,,,,,,,,,0,4.000000e+000,1.000000e+000,2,2,1.033997e+000,0,,0,
1657136890.257,,9.000000e+002,3.466497e+002,1.882253e-004,3.327625e-006,-6.347052e-002,1.584722e-005,3,9.859827e-001,1.825000e+000,,,,,,,,,,,,,,,,,,0,4.000000e+000,1.000000e+000,2,2,6.647034e-001,0,,0,
1657137844.337,,9.000000e+002,3.194235e+002,5.400991e-005,2.807303e-008,-1.125012e-002,1.116101e-005,3,9.777850e-001,1.825000e+000,,,,,,,,,,,,,,,,,,0,4.000000e+000,1.000000e+000,2,2,7.453003e-001,0,,0,
1657139153.392,,9.000000e+002,3.073610e+002,5.388854e-005,1.279017e-008,-9.826657e-003,3.443068e-004,3,9.754210e-001,1.825000e+000,,,,,,,,,,,,,,,,,,0,4.000000e+000,1.000000e+000,2,2,4.774780e-001,0,,0,
1657139987.829,,9.000000e+002,3.353284e+002,5.389314e-005,2.833799e-008,-2.465506e-002,1.288300e-003,3,9.775630e-001,1.825000e+000,,,,,,,,,,,,,,,,,,0,4.000000e+000,1.000000e+000,2,2,4.131165e-001,0,,0,
1657140827.874,,9.000000e+002,3.633150e+002,5.842661e-005,4.326843e-009,-4.346839e-002,5.538596e-004,3,9.800687e-001,1.825000e+000,,,,,,,,,,,,,,,,,,0,4.000000e+000,1.000000e+000,2,2,4.571838e-001,0,,0,
1657141667.537,,9.000000e+002,3.913165e+002,1.858639e-004,9.610634e-009,-9.079777e-002,1.209404e-004,3,9.864269e-001,1.825000e+000,,,,,,,,,,,,,,,,,,0,4.000000e+000,1.000000e+000,2,2,4.344177e-001,0,,0,
1657142982.421,,8.000000e+002,3.817049e+002,1.679494e-004,1.817583e-007,-7.594484e-002,1.481462e-005,3,9.868588e-001,1.825000e+000,,,,,,,,,,,,,,,,,,0,4.000000e+000,1.000000e+000,2,2,3.890076e-001,0,,0,
1657143983.740,,8.000000e+002,3.522870e+002,1.782717e-004,8.018808e-008,-6.542675e-002,4.001211e-004,3,9.853853e-001,1.825000e+000,,,,,,,,,,,,,,,,,,0,4.000000e+000,1.000000e+000,2,2,1.096313e+000,0,,0,
1657144710.420,,8.000000e+002,3.258147e+002,4.831734e-005,1.073659e-007,-1.188660e-002,5.361935e-005,3,9.768367e-001,1.825000e+000,,,,,,,,,,,,,,,,,,0,4.000000e+000,1.000000e+000,2,2,2.872009e-001,0,,0,
1657146180.608,,8.000000e+002,3.012651e+002,4.842088e-005,1.004023e-008,-5.956410e-003,2.022479e-004,3,9.757367e-001,1.825000e+000,,,,,,,,,,,,,,,,,,0,4.000000e+000,1.000000e+000,2,2,4.217834e-001,0,,0,
1657146991.464,,8.000000e+002,3.292778e+002,4.805973e-005,1.054906e-007,-2.110833e-002,6.708198e-005,3,9.772487e-001,1.825000e+000,,,,,,,,,,,,,,,,,,0,4.000000e+000,1.000000e+000,2,2,4.234924e-001,0,,0,
1657147832.563,,8.000000e+002,3.573351e+002,5.018355e-005,7.011955e-008,-3.802064e-002,1.032013e-003,3,9.785114e-001,1.825000e+000,,,,,,,,,,,,,,,,,,0,4.000000e+000,1.000000e+000,2,2,4.519043e-001,0,,0,
1657148671.806,,8.000000e+002,3.853090e+002,1.677775e-004,1.955671e-007,-8.864760e-002,2.285623e-004,3,9.854207e-001,1.825000e+000,,,,,,,,,,,,,,,,,,0,4.000000e+000,1.000000e+000,2,2,4.447937e-001,0,,0,
1657150042.959,,7.000000e+002,3.870180e+002,1.450388e-004,8.626933e-008,-7.839400e-002,1.990596e-004,3,9.876450e-001,1.825000e+000,,,,,,,,,,,,,,,,,,0,4.000000e+000,1.000000e+000,2,2,7.765198e-001,0,,0,
1657151061.472,,7.000000e+002,3.596408e+002,1.540904e-004,2.937932e-007,-6.949332e-002,8.497860e-006,3,9.860414e-001,1.825000e+000,,,,,,,,,,,,,,,,,,0,4.000000e+000,1.000000e+000,2,2,6.661987e-001,0,,0,
1657151779.915,,7.000000e+002,3.305165e+002,4.259879e-005,4.320412e-008,-1.413757e-002,4.878511e-004,3,9.766809e-001,1.825000e+000,,,,,,,,,,,,,,,,,,0,4.000000e+000,1.000000e+000,2,2,7.665100e-001,0,,0,
1657152698.058,,7.000000e+002,3.035276e+002,4.251400e-005,1.133417e-008,-5.522633e-003,6.331942e-004,3,9.752085e-001,1.825000e+000,,,,,,,,,,,,,,,,,,0,4.000000e+000,1.000000e+000,2,2,7.043762e-001,0,,0,
1657153992.181,,7.000000e+002,3.233587e+002,4.219799e-005,3.602444e-008,-1.796454e-002,5.291642e-004,3,9.765562e-001,1.825000e+000,,,,,,,,,,,,,,,,,,0,4.000000e+000,1.000000e+000,2,2,4.490051e-001,0,,0,
1657154829.418,,7.000000e+002,3.512855e+002,4.332216e-005,6.443961e-009,-3.530791e-002,9.233690e-004,3,9.781160e-001,1.825000e+000,,,,,,,,,,,,,,,,,,0,4.000000e+000,1.000000e+000,2,2,4.061890e-001,0,,0,
1657155669.162,,7.000000e+002,3.792866e+002,1.488389e-004,1.163772e-008,-8.650532e-002,2.852551e-004,3,9.853984e-001,1.825000e+000,,,,,,,,,,,,,,,,,,0,4.000000e+000,1.000000e+000,2,2,4.073181e-001,0,,0,
1657157122.678,,6.000000e+002,3.934642e+002,1.221291e-004,1.019561e-007,-8.245651e-002,3.100954e-004,3,9.881583e-001,1.825000e+000,,,,,,,,,,,,,,,,,,0,4.000000e+000,1.000000e+000,2,2,9.669189e-001,0,,0,
1657157879.158,,6.000000e+002,3.644458e+002,1.312481e-004,4.583058e-008,-6.855749e-002,9.660584e-005,3,9.855121e-001,1.825000e+000,,,,,,,,,,,,,,,,,,0,4.000000e+000,1.000000e+000,2,2,6.099854e-001,0,,0,
1657158854.971,,6.000000e+002,3.372034e+002,3.699597e-005,8.677610e-008,-1.866119e-002,7.343588e-004,3,9.766172e-001,1.825000e+000,,,,,,,,,,,,,,,,,,0,4.000000e+000,1.000000e+000,2,2,9.543762e-001,0,,0,
1657159590.574,,6.000000e+002,3.097648e+002,3.662859e-005,3.736211e-008,-7.204746e-003,4.256209e-004,3,9.750423e-001,1.825000e+000,,,,,,,,,,,,,,,,,,0,4.000000e+000,1.000000e+000,2,2,3.337708e-001,0,,0,
1657160987.887,,6.000000e+002,3.172239e+002,3.639099e-005,3.890300e-008,-1.469451e-002,1.112835e-004,3,9.740547e-001,1.825000e+000,,,,,,,,,,,,,,,,,,0,4.000000e+000,1.000000e+000,2,2,4.470215e-001,0,,0,
1657161830.372,,6.000000e+002,3.453279e+002,3.689151e-005,2.646783e-008,-3.036791e-002,1.438885e-003,3,9.767878e-001,1.825000e+000,,,,,,,,,,,,,,,,,,0,4.000000e+000,1.000000e+000,2,2,4.588013e-001,0,,0,
1657162668.519,,6.000000e+002,3.732518e+002,1.219476e-004,1.029084e-006,-8.118139e-002,2.586710e-004,3,9.862052e-001,1.825000e+000,,,,,,,,,,,,,,,,,,0,4.000000e+000,1.000000e+000,2,2,4.613037e-001,0,,0,
1657164102.729,,5.000000e+002,4.000099e+002,1.003304e-004,8.363001e-008,-8.673605e-002,1.056664e-003,3,9.869133e-001,1.825000e+000,,,,,,,,,,,,,,,,,,0,4.000000e+000,1.000000e+000,2,2,1.287842e-002,0,,0,
1657164965.108,,5.000000e+002,3.701239e+002,1.079803e-004,1.780128e-009,-7.221273e-002,1.726598e-004,3,9.857645e-001,1.825000e+000,,,,,,,,,,,,,,,,,,0,4.000000e+000,1.000000e+000,2,2,9.617920e-001,0,,0,
1657165698.035,,5.000000e+002,3.437750e+002,6.914067e-005,2.034712e-006,-6.041990e-002,8.715942e-004,3,9.869972e-001,1.825000e+000,,,,,,,,,,,,,,,,,,0,4.000000e+000,1.000000e+000,2,2,3.503113e-001,0,,0,
1657166636.729,,5.000000e+002,3.156006e+002,3.074362e-005,3.408740e-008,-9.380357e-003,9.809547e-005,3,9.754295e-001,1.825000e+000,,,,,,,,,,,,,,,,,,0,4.000000e+000,1.000000e+000,2,2,7.738037e-001,0,,0,
1657167991.408,,5.000000e+002,3.113054e+002,3.059270e-005,2.683056e-009,-1.170458e-002,5.638860e-004,3,9.738157e-001,1.825000e+000,,,,,,,,,,,,,,,,,,0,4.000000e+000,1.000000e+000,2,2,4.140930e-001,0,,0,
1657168834.994,,5.000000e+002,3.392912e+002,3.082259e-005,2.722413e-008,-2.558414e-002,2.394376e-004,3,9.763635e-001,1.825000e+000,,,,,,,,,,,,,,,,,,0,4.000000e+000,1.000000e+000,2,2,4.511108e-001,0,,0,
1657169675.199,,5.000000e+002,3.673215e+002,4.274444e-005,1.580322e-006,-4.886517e-002,9.775488e-004,3,9.843830e-001,1.825000e+000,,,,,,,,,,,,,,,,,,0,4.000000e+000,1.000000e+000,2,2,4.895935e-001,0,,0,
1657170514.509,,5.000000e+002,3.952681e+002,1.020175e-004,5.445340e-008,-9.088944e-002,1.468976e-004,3,9.870381e-001,1.825000e+000,,,,,,,,,,,,,,,,,,0,4.000000e+000,1.000000e+000,2,2,4.182129e-001,0,,0,
1657172056.577,,4.000000e+002,3.775414e+002,8.478602e-005,5.515825e-008,-7.600226e-002,3.287191e-004,3,9.858857e-001,1.825000e+000,,,,,,,,,,,,,,,,,,0,4.000000e+000,1.000000e+000,2,2,7.832947e-001,0,,0,
1657172786.028,,4.000000e+002,3.480601e+002,8.844856e-005,2.776588e-007,-6.286711e-002,1.878169e-005,3,9.858670e-001,1.825000e+000,,,,,,,,,,,,,,,,,,0,4.000000e+000,1.000000e+000,2,2,8.353882e-001,0,,0,
1657173729.657,,4.000000e+002,3.215384e+002,2.484733e-005,7.870250e-008,-1.204496e-002,1.235716e-003,3,9.750093e-001,1.825000e+000,,,,,,,,,,,,,,,,,,0,4.000000e+000,1.000000e+000,2,2,6.817932e-001,0,,0,
1657175023.164,,4.000000e+002,3.052851e+002,2.481329e-005,9.339241e-009,-1.073817e-002,6.982547e-004,3,9.744163e-001,1.825000e+000,,,,,,,,,,,,,,,,,,0,4.000000e+000,1.000000e+000,2,2,5.074768e-001,0,,0,
1657175848.631,,4.000000e+002,3.333091e+002,2.476895e-005,3.224295e-008,-2.343977e-002,1.246110e-003,3,9.754314e-001,1.825000e+000,,,,,,,,,,,,,,,,,,0,4.000000e+000,1.000000e+000,2,2,4.610901e-001,0,,0,
1657176697.521,,4.000000e+002,3.615693e+002,2.636304e-005,5.336526e-009,-4.151141e-002,1.255394e-003,3,9.769778e-001,1.825000e+000,,,,,,,,,,,,,,,,,,0,4.000000e+000,1.000000e+000,2,2,4.947815e-001,0,,0,
1657177532.308,,4.000000e+002,3.892791e+002,8.289650e-005,8.739606e-008,-9.056886e-002,1.144708e-004,3,9.858985e-001,1.825000e+000,,,,,,,,,,,,,,,,,,0,4.000000e+000,1.000000e+000,2,2,4.053040e-001,0,,0,
1657178847.081,,3.000000e+002,3.835741e+002,6.191431e-005,2.233186e-007,-7.533866e-002,2.038390e-003,3,9.844198e-001,1.825000e+000,,,,,,,,,,,,,,,,,,0,4.000000e+000,1.000000e+000,2,2,5.835876e-001,0,,0,
1657179879.457,,3.000000e+002,3.550783e+002,6.612265e-005,1.693180e-008,-6.808311e-002,3.507092e-004,3,9.857980e-001,1.825000e+000,,,,,,,,,,,,,,,,,,0,4.000000e+000,1.000000e+000,2,2,1.033417e+000,0,,0,
1657180596.788,,3.000000e+002,3.273306e+002,1.887996e-005,5.671457e-008,-1.519184e-002,2.654626e-004,3,9.741817e-001,1.825000e+000,,,,,,,,,,,,,,,,,,0,4.000000e+000,1.000000e+000,2,2,4.777832e-001,0,,0,
1657181782.482,,3.000000e+002,3.000959e+002,1.895974e-005,4.651099e-008,-8.191245e-003,1.212774e-003,3,9.732823e-001,1.825000e+000,,,,,,,,,,,,,,,,,,0,4.000000e+000,1.000000e+000,2,2,0.000000e+000,0,,0,
1657182883.156,,3.000000e+002,3.272729e+002,1.878555e-005,1.452271e-008,-2.227535e-002,2.484575e-003,3,9.746341e-001,1.825000e+000,,,,,,,,,,,,,,,,,,0,4.000000e+000,1.000000e+000,2,2,4.863281e-001,0,,0,
1657183736.148,,3.000000e+002,3.553138e+002,1.940825e-005,3.027247e-008,-3.750803e-002,5.269331e-004,3,9.757934e-001,1.825000e+000,,,,,,,,,,,,,,,,,,0,4.000000e+000,1.000000e+000,2,2,4.869995e-001,0,,0,
1657184584.362,,3.000000e+002,3.832736e+002,6.283717e-005,7.885041e-008,-8.843367e-002,3.469897e-004,3,9.853107e-001,1.825000e+000,,,,,,,,,,,,,,,,,,0,4.000000e+000,1.000000e+000,2,2,4.874878e-001,0,,0,
1657185985.401,,2.000000e+002,3.890339e+002,4.025142e-005,1.510434e-007,-8.164510e-002,7.405675e-004,3,9.862421e-001,1.825000e+000,,,,,,,,,,,,,,,,,,0,4.000000e+000,1.000000e+000,2,2,8.706970e-001,0,,0,
1657186761.509,,2.000000e+002,3.618010e+002,4.308436e-005,5.758920e-008,-6.892848e-002,8.754585e-004,3,9.846673e-001,1.825000e+000,,,,,,,,,,,,,,,,,,0,4.000000e+000,1.000000e+000,2,2,2.424011e-001,0,,0,
1657187726.532,,2.000000e+002,3.328512e+002,1.279462e-005,6.019508e-009,-2.208278e-002,8.861546e-004,3,9.738195e-001,1.825000e+000,,,,,,,,,,,,,,,,,,0,4.000000e+000,1.000000e+000,2,2,9.725037e-001,0,,0,
1657188630.839,,2.000000e+002,3.057639e+002,1.273982e-005,2.117761e-009,-1.276363e-002,6.017187e-004,3,9.729856e-001,1.825000e+000,,,,,,,,,,,,,,,,,,0,4.000000e+000,1.000000e+000,2,2,3.984070e-001,0,,0,
1657189934.426,,2.000000e+002,3.214952e+002,1.266020e-005,8.489050e-011,-2.509606e-002,1.084805e-003,3,9.734625e-001,1.825000e+000,,,,,,,,,,,,,,,,,,0,4.000000e+000,1.000000e+000,2,2,4.435120e-001,0,,0,
1657190771.791,,2.000000e+002,3.492888e+002,1.295557e-005,4.637465e-008,-3.800077e-002,1.410552e-003,3,9.741385e-001,1.825000e+000,,,,,,,,,,,,,,,,,,0,4.000000e+000,1.000000e+000,2,2,4.502869e-001,0,,0,
1657191623.558,,2.000000e+002,3.772592e+002,4.188944e-005,6.795356e-008,-8.679350e-002,1.188610e-003,3,9.848734e-001,1.825000e+000,,,,,,,,,,,,,,,,,,0,4.000000e+000,1.000000e+000,2,2,3.681030e-001,0,,0,
1657193103.799,,1.000000e+002,3.954489e+002,1.884292e-005,5.039409e-009,-8.629386e-002,1.501634e-003,3,9.825264e-001,1.825000e+000,,,,,,,,,,,,,,,,,,0,4.000000e+000,1.000000e+000,2,2,8.627014e-001,0,,0,
1657193864.199,,1.000000e+002,3.662722e+002,2.046625e-005,1.047111e-008,-7.345511e-002,3.816134e-004,3,9.833546e-001,1.825000e+000,,,,,,,,,,,,,,,,,,0,4.000000e+000,1.000000e+000,2,2,7.788086e-001,0,,0,
1657194848.653,,1.000000e+002,3.393858e+002,6.646409e-006,7.311516e-009,-3.542800e-002,3.032353e-003,3,9.665475e-001,1.825000e+000,,,,,,,,,,,,,,,,,,0,4.000000e+000,1.000000e+000,2,2,9.305115e-001,0,,0,
1657195563.685,,1.000000e+002,3.115857e+002,6.617584e-006,3.111044e-009,-2.291436e-002,5.582827e-003,3,9.699757e-001,1.825000e+000,,,,,,,,,,,,,,,,,,0,4.000000e+000,1.000000e+000,2,2,4.916077e-001,0,,0,
1657196969.520,,1.000000e+002,3.152849e+002,6.541792e-006,2.419701e-008,-2.931592e-002,2.306025e-003,3,9.676591e-001,1.825000e+000,,,,,,,,,,,,,,,,,,0,4.000000e+000,1.000000e+000,2,2,3.464966e-001,0,,0,
1657197814.442,,1.000000e+002,3.433024e+002,6.564999e-006,2.259342e-008,-4.351852e-002,1.127059e-003,3,9.706042e-001,1.825000e+000,,,,,,,,,,,,,,,,,,0,4.000000e+000,1.000000e+000,2,2,4.532166e-001,0,,0,
1657198661.400,,1.000000e+002,3.713132e+002,1.705607e-005,2.120668e-007,-7.690863e-002,5.847549e-003,3,9.806820e-001,1.825000e+000,,,,,,,,,,,,,,,,,,0,4.000000e+000,1.000000e+000,2,2,4.451904e-001,0,,0,
1657199503.910,,1.000000e+002,3.992671e+002,1.910054e-005,1.576520e-008,-9.318406e-002,1.947785e-003,3,9.848956e-001,1.825000e+000,,,,,,,,,,,,,,,,,,0,4.000000e+000,1.000000e+000,2,2,4.128113e-001,0,,0,
1657200992.527,,0.000000e+000,3.725447e+002,-2.058543e-006,1.664947e-008,-5.257951e-002,5.111469e-003,3,9.137785e-001,1.825000e+000,,,,,,,,,,,,,,,,,,0,4.000000e+000,1.000000e+000,2,2,1.031219e+000,0,,0,
1657201720.964,,0.000000e+000,3.448936e+002,-1.415970e-006,1.671322e-008,-4.909658e-002,6.559006e-003,3,8.867414e-001,1.825000e+000,,,,,,,,,,,,,,,,,,0,4.000000e+000,1.000000e+000,2,2,5.147095e-001,0,,0,
1657202675.360,,0.000000e+000,3.173819e+002,1.634494e-007,3.881681e-008,-8.279985e-001,1.294078e-001,3,1.585206e-001,1.825000e+000,,,,,,,,,,,,,,,,,,0,4.000000e+000,1.000000e+000,2,2,7.749939e-001,0,,0,
1657204006.427,,0.000000e+000,3.093424e+002,1.002751e-007,5.903684e-008,-3.883053e-001,5.491466e-001,3,0.000000e+000,1.825000e+000,,,,,,,,,,,,,,,,,,0,4.000000e+000,1.000000e+000,2,2,4.463196e-001,0,,0,
1657204847.200,,0.000000e+000,3.373008e+002,1.024211e-007,7.636329e-008,-4.180791e-001,5.912531e-001,3,1.472203e-002,1.825000e+000,,,,,,,,,,,,,,,,,,0,4.000000e+000,1.000000e+000,2,2,4.183960e-001,0,,0,
1657205699.194,,0.000000e+000,3.652798e+002,-1.264412e-007,3.551709e-008,9.497970e-001,8.835290e-002,3,4.793303e-002,1.825000e+000,,,,,,,,,,,,,,,,,,0,4.000000e+000,1.000000e+000,2,2,4.087219e-001,0,,0,
1657206540.137,,0.000000e+000,3.933039e+002,-1.801121e-006,1.854005e-008,-7.802770e-002,6.156869e-003,3,8.977522e-001,1.825000e+000,,,,,,,,,,,,,,,,,,0,4.000000e+000,1.000000e+000,2,2,4.516907e-001,0,,0,
1657207000.756,,0.000000e+000,3.999841e+002,-1.741987e-006,2.992069e-008,-6.337081e-002,4.000953e-003,3,8.999329e-001,1.825000e+000,,,,,,,,,,,,,,,,,,0,4.000000e+000,1.000000e+000,2,2,1.290894e-002,0,,0,