File: dane/Trt_TEOS — kopia/Small TEOS/FeTrz_Trt_small_FC_FH.rso.dat
[Header]
TITLE,MPMS RSO Measurement
BYAPP,MPMS Measurement,1.1,Summary
FILEOPENTIME, 1654850335.798000 6/10/2022, 10:38:55 AM

INFO, APPNAME, MPMS MultiVu Application, Revision 1.60,  Build 081

INFO, NAME, AP_FeTrz_trt_small
INFO, WEIGHT, 4.000
INFO, AREA, 0.000
INFO, LENGTH, 0.000
INFO, SHAPE, 0
INFO, COMMENT, na Cu drutu, w foli Al
INFO, SEQUENCE FILE: FC_FH_300-390.seq


INFO, BACKGROUND DATA FILE:, None


STARTUPAXIS,X,4,LINEAR,AUTO,0.000000,0.000000
STARTUPAXIS,Y1,5,LINEAR,AUTO,0.000000,0.000000


STARTUPGROUP,Longitudinal
FIELDGROUP,Longitudinal,1,2,3,4,5,6,7,8,9,10,11,19,20,21,22,23,35
FIELDGROUP,Transverse,1,2,3,4,12,13,14,15,16,17,18,24,25,26,27,28,35

PLOT_APPEARANCE,ALL,HORZ_GRID_ON,VERT_GRID_ON,MARKERS_AND_LINES

[Data]
Time,Comment,Field (Oe),Temperature (K),Long Moment (emu),Long Scan Std Dev,Long Offset (cm),Long Offset Std Dev,Long Algorithm,Long Reg Fit,Long Reg Factor,Trans Moment (emu),Trans Scan Std Dev,Trans Offset (cm),Trans Offset Std Dev,Trans Algorithm,Trans Reg Fit,Trans Reg Factor,Long Moment [w/o ABS] (emu),Long Scan Std Dev [w/o ABS],Long Offset [w/o ABS] (cm),Long Offset Std Dev [w/o ABS],Long Reg Fit [w/o ABS],Trans Moment [w/o ABS] (emu),Trans Scan Std Dev [w/o ABS],Trans Offset [w/o ABS] (cm),Trans Offset Std Dev [w/o ABS],Trans Reg Fit [w/o ABS],RSO Position (deg),Amplitude (cm),Frequency,Cycles to Average,Scans per Measurement,Delta Temp (K),Error,EC Comp. Running,Using ABS,
1654850335.798,,1.000000e+003,3.000016e+002,3.688359e-005,2.904285e-009,-5.736395e-003,7.152274e-004,3,9.390391e-001,1.825000e+000,,,,,,,,,,,,,,,,,,0,4.000000e+000,1.000000e+000,2,2,1.409912e-002,0,,0,
1654850502.676,,1.000000e+003,3.021215e+002,3.683095e-005,3.959499e-008,-6.035130e-003,1.163078e-004,3,9.389184e-001,1.825000e+000,,,,,,,,,,,,,,,,,,0,4.000000e+000,1.000000e+000,2,2,2.156982e-001,0,,0,
1654850612.335,,1.000000e+003,3.041424e+002,3.674224e-005,2.766401e-008,-7.236742e-003,3.917767e-004,3,9.385765e-001,1.825000e+000,,,,,,,,,,,,,,,,,,0,4.000000e+000,1.000000e+000,2,2,2.479858e-001,0,,0,
1654850724.529,,1.000000e+003,3.061444e+002,3.670334e-005,2.976314e-009,-8.726929e-003,1.364495e-003,3,9.389763e-001,1.825000e+000,,,,,,,,,,,,,,,,,,0,4.000000e+000,1.000000e+000,2,2,2.366943e-001,0,,0,
1654850839.154,,1.000000e+003,3.081336e+002,3.667887e-005,2.711351e-009,-9.571889e-003,2.392202e-004,3,9.386461e-001,1.825000e+000,,,,,,,,,,,,,,,,,,0,4.000000e+000,1.000000e+000,2,2,2.401123e-001,0,,0,
1654850957.311,,1.000000e+003,3.101127e+002,3.663152e-005,2.647040e-008,-1.023212e-002,1.373100e-003,3,9.391779e-001,1.825000e+000,,,,,,,,,,,,,,,,,,0,4.000000e+000,1.000000e+000,2,2,2.130127e-001,0,,0,
1654851079.949,,1.000000e+003,3.120999e+002,3.662329e-005,1.408411e-008,-1.077427e-002,1.628002e-003,3,9.392956e-001,1.825000e+000,,,,,,,,,,,,,,,,,,0,4.000000e+000,1.000000e+000,2,2,2.003784e-001,0,,0,
1654851202.366,,1.000000e+003,3.141184e+002,3.655172e-005,1.988238e-008,-1.179199e-002,2.977372e-004,3,9.387865e-001,1.825000e+000,,,,,,,,,,,,,,,,,,0,4.000000e+000,1.000000e+000,2,2,2.344971e-001,0,,0,
1654851324.085,,1.000000e+003,3.161135e+002,3.658251e-005,5.039410e-009,-1.229710e-002,4.755864e-004,3,9.394960e-001,1.825000e+000,,,,,,,,,,,,,,,,,,0,4.000000e+000,1.000000e+000,2,2,1.901855e-001,0,,0,
1654851446.759,,1.000000e+003,3.181439e+002,3.653846e-005,2.284326e-008,-1.416206e-002,2.764656e-004,3,9.384377e-001,1.825000e+000,,,,,,,,,,,,,,,,,,0,4.000000e+000,1.000000e+000,2,2,2.088013e-001,0,,0,
1654851568.178,,1.000000e+003,3.201331e+002,3.652453e-005,8.031156e-009,-1.445521e-002,7.676542e-004,3,9.393522e-001,1.825000e+000,,,,,,,,,,,,,,,,,,0,4.000000e+000,1.000000e+000,2,2,2.117004e-001,0,,0,
1654851689.570,,1.000000e+003,3.221448e+002,3.652109e-005,9.096146e-009,-1.387267e-002,3.887869e-004,3,9.390115e-001,1.825000e+000,,,,,,,,,,,,,,,,,,0,4.000000e+000,1.000000e+000,2,2,1.651001e-001,0,,0,
1654851810.060,,1.000000e+003,3.241252e+002,3.653290e-005,1.083000e-009,-1.565216e-002,2.514850e-004,3,9.406247e-001,1.825000e+000,,,,,,,,,,,,,,,,,,0,4.000000e+000,1.000000e+000,2,2,2.005005e-001,0,,0,
1654851930.733,,1.000000e+003,3.260978e+002,3.656725e-005,4.596692e-008,-1.576661e-002,1.292788e-003,3,9.387412e-001,1.825000e+000,,,,,,,,,,,,,,,,,,0,4.000000e+000,1.000000e+000,2,2,2.031860e-001,0,,0,
1654852057.485,,1.000000e+003,3.281432e+002,3.662554e-005,2.134353e-008,-1.814409e-002,1.511051e-003,3,9.402554e-001,1.825000e+000,,,,,,,,,,,,,,,,,,0,4.000000e+000,1.000000e+000,2,2,2.144775e-001,0,,0,
1654852179.364,,1.000000e+003,3.301466e+002,3.661075e-005,4.954776e-008,-1.886239e-002,5.572077e-005,3,9.390665e-001,1.825000e+000,,,,,,,,,,,,,,,,,,0,4.000000e+000,1.000000e+000,2,2,2.259216e-001,0,,0,
1654852303.528,,1.000000e+003,3.321321e+002,3.660806e-005,2.940298e-008,-2.014382e-002,1.645887e-004,3,9.392064e-001,1.825000e+000,,,,,,,,,,,,,,,,,,0,4.000000e+000,1.000000e+000,2,2,1.761169e-001,0,,0,
1654852423.652,,1.000000e+003,3.341008e+002,3.667528e-005,7.135947e-009,-2.038283e-002,5.336766e-004,3,9.397480e-001,1.825000e+000,,,,,,,,,,,,,,,,,,0,4.000000e+000,1.000000e+000,2,2,2.050171e-001,0,,0,
1654852545.334,,1.000000e+003,3.361100e+002,3.670113e-005,2.987374e-008,-2.312957e-002,7.041289e-004,3,9.398422e-001,1.825000e+000,,,,,,,,,,,,,,,,,,0,4.000000e+000,1.000000e+000,2,2,1.805725e-001,0,,0,
1654852668.033,,1.000000e+003,3.381245e+002,3.679062e-005,2.155190e-008,-2.386761e-002,1.852163e-003,3,9.407457e-001,1.825000e+000,,,,,,,,,,,,,,,,,,0,4.000000e+000,1.000000e+000,2,2,1.919861e-001,0,,0,
1654852790.447,,1.000000e+003,3.401438e+002,3.682920e-005,3.352918e-008,-2.272879e-002,3.787105e-004,3,9.399799e-001,1.825000e+000,,,,,,,,,,,,,,,,,,0,4.000000e+000,1.000000e+000,2,2,2.221985e-001,0,,0,
1654852913.193,,1.000000e+003,3.421068e+002,3.687035e-005,2.093966e-009,-2.461152e-002,2.504445e-004,3,9.389273e-001,1.825000e+000,,,,,,,,,,,,,,,,,,0,4.000000e+000,1.000000e+000,2,2,2.061157e-001,0,,0,
1654853034.612,,1.000000e+003,3.441080e+002,3.698133e-005,2.985831e-008,-2.521392e-002,1.951593e-003,3,9.397064e-001,1.825000e+000,,,,,,,,,,,,,,,,,,0,4.000000e+000,1.000000e+000,2,2,1.802063e-001,0,,0,
1654853158.239,,1.000000e+003,3.461389e+002,3.700824e-005,8.576513e-009,-2.567482e-002,1.683599e-003,3,9.404967e-001,1.825000e+000,,,,,,,,,,,,,,,,,,0,4.000000e+000,1.000000e+000,2,2,1.921997e-001,0,,0,
1654853279.169,,1.000000e+003,3.481272e+002,3.714878e-005,1.618322e-008,-2.747000e-002,6.458715e-004,3,9.403172e-001,1.825000e+000,,,,,,,,,,,,,,,,,,0,4.000000e+000,1.000000e+000,2,2,2.333984e-001,0,,0,
1654853398.889,,1.000000e+003,3.501174e+002,3.723476e-005,6.091537e-008,-2.939494e-002,1.726513e-003,3,9.407126e-001,1.825000e+000,,,,,,,,,,,,,,,,,,0,4.000000e+000,1.000000e+000,2,2,2.066040e-001,0,,0,
1654853519.296,,1.000000e+003,3.521094e+002,3.733396e-005,2.874701e-008,-2.972546e-002,6.643568e-004,3,9.403862e-001,1.825000e+000,,,,,,,,,,,,,,,,,,0,4.000000e+000,1.000000e+000,2,2,2.189941e-001,0,,0,
1654853643.494,,1.000000e+003,3.541430e+002,3.750359e-005,3.764765e-008,-3.054025e-002,1.067150e-003,3,9.402361e-001,1.825000e+000,,,,,,,,,,,,,,,,,,0,4.000000e+000,1.000000e+000,2,2,2.218018e-001,0,,0,
1654853765.373,,1.000000e+003,3.561097e+002,3.764419e-005,5.939763e-008,-3.152624e-002,1.924220e-003,3,9.429055e-001,1.825000e+000,,,,,,,,,,,,,,,,,,0,4.000000e+000,1.000000e+000,2,2,2.243958e-001,0,,0,
1654853888.817,,1.000000e+003,3.581278e+002,3.777973e-005,1.828490e-008,-3.463773e-002,4.454073e-003,3,9.407682e-001,1.825000e+000,,,,,,,,,,,,,,,,,,0,4.000000e+000,1.000000e+000,2,2,2.271118e-001,0,,0,
1654854010.559,,1.000000e+003,3.601204e+002,3.786432e-005,8.913503e-009,-3.555874e-002,1.536332e-004,3,9.415593e-001,1.825000e+000,,,,,,,,,,,,,,,,,,0,4.000000e+000,1.000000e+000,2,2,2.192078e-001,0,,0,
1654854132.688,,1.000000e+003,3.621233e+002,3.806023e-005,4.627304e-008,-3.531815e-002,8.244819e-004,3,9.417543e-001,1.825000e+000,,,,,,,,,,,,,,,,,,0,4.000000e+000,1.000000e+000,2,2,2.111816e-001,0,,0,
1654854251.587,,1.000000e+003,3.641149e+002,3.822237e-005,5.834293e-009,-3.614996e-002,1.123177e-003,3,9.417807e-001,1.825000e+000,,,,,,,,,,,,,,,,,,0,4.000000e+000,1.000000e+000,2,2,2.135925e-001,0,,0,
1654854374.217,,1.000000e+003,3.661404e+002,3.841478e-005,1.501533e-008,-3.711299e-002,2.068093e-003,3,9.423454e-001,1.825000e+000,,,,,,,,,,,,,,,,,,0,4.000000e+000,1.000000e+000,2,2,1.729126e-001,0,,0,
1654854496.959,,1.000000e+003,3.681049e+002,3.869717e-005,3.487199e-008,-4.053887e-002,1.024827e-003,3,9.426403e-001,1.825000e+000,,,,,,,,,,,,,,,,,,0,4.000000e+000,1.000000e+000,2,2,1.857910e-001,0,,0,
1654854620.901,,1.000000e+003,3.701082e+002,3.897326e-005,2.088564e-008,-3.973104e-002,6.052182e-004,3,9.429848e-001,1.825000e+000,,,,,,,,,,,,,,,,,,0,4.000000e+000,1.000000e+000,2,2,1.990051e-001,0,,0,
1654854745.662,,1.000000e+003,3.721455e+002,3.930025e-005,5.940792e-008,-4.240946e-002,1.307927e-003,3,9.443008e-001,1.825000e+000,,,,,,,,,,,,,,,,,,0,4.000000e+000,1.000000e+000,2,2,1.900940e-001,0,,0,
1654854869.842,,1.000000e+003,3.741500e+002,3.965693e-005,2.675337e-008,-4.528804e-002,8.857160e-005,3,9.419910e-001,1.825000e+000,,,,,,,,,,,,,,,,,,0,4.000000e+000,1.000000e+000,2,2,2.035828e-001,0,,0,
1654854989.780,,1.000000e+003,3.761399e+002,4.037016e-005,4.590518e-008,-4.614089e-002,7.794269e-005,3,9.437135e-001,1.825000e+000,,,,,,,,,,,,,,,,,,0,4.000000e+000,1.000000e+000,2,2,2.058105e-001,0,,0,
1654855115.712,,1.000000e+003,3.781838e+002,4.141692e-005,4.659717e-008,-5.100540e-002,1.100673e-003,3,9.456873e-001,1.825000e+000,,,,,,,,,,,,,,,,,,0,4.000000e+000,1.000000e+000,2,2,3.353882e-001,0,,0,
1654855227.642,,1.000000e+003,3.801049e+002,4.306439e-005,9.427733e-008,-5.308192e-002,3.411208e-004,3,9.469800e-001,1.825000e+000,,,,,,,,,,,,,,,,,,0,4.000000e+000,1.000000e+000,2,2,1.869812e-001,0,,0,
1654855349.317,,1.000000e+003,3.821292e+002,4.617029e-005,1.707174e-007,-6.248483e-002,3.261033e-004,3,9.487727e-001,1.825000e+000,,,,,,,,,,,,,,,,,,0,4.000000e+000,1.000000e+000,2,2,2.008972e-001,0,,0,
1654855472.502,,1.000000e+003,3.841341e+002,5.318556e-005,4.613104e-007,-7.628375e-002,8.748474e-004,3,9.530144e-001,1.825000e+000,,,,,,,,,,,,,,,,,,0,4.000000e+000,1.000000e+000,2,2,2.269897e-001,0,,0,
1654855592.452,,1.000000e+003,3.861188e+002,7.613190e-005,1.308986e-006,-9.983988e-002,1.478617e-004,3,9.612005e-001,1.825000e+000,,,,,,,,,,,,,,,,,,0,4.000000e+000,1.000000e+000,2,2,2.052917e-001,0,,0,
1654855714.549,,1.000000e+003,3.881464e+002,1.055120e-004,2.932324e-007,-1.028150e-001,1.379993e-004,3,9.684649e-001,1.825000e+000,,,,,,,,,,,,,,,,,,0,4.000000e+000,1.000000e+000,2,2,2.196960e-001,0,,0,
1654855836.723,,1.000000e+003,3.901438e+002,1.065712e-004,7.467791e-008,-1.034693e-001,2.931577e-004,3,9.689463e-001,1.825000e+000,,,,,,,,,,,,,,,,,,0,4.000000e+000,1.000000e+000,2,2,1.973877e-001,0,,0,
1654855957.169,,1.000000e+003,3.921346e+002,1.068361e-004,2.839973e-009,-1.043637e-001,7.070134e-006,3,9.692467e-001,1.825000e+000,,,,,,,,,,,,,,,,,,0,4.000000e+000,1.000000e+000,2,2,1.994934e-001,0,,0,
1654856075.343,,1.000000e+003,3.941120e+002,1.069730e-004,3.665212e-008,-1.042520e-001,8.757589e-005,3,9.689654e-001,1.825000e+000,,,,,,,,,,,,,,,,,,0,4.000000e+000,1.000000e+000,2,2,2.141113e-001,0,,0,
1654856196.722,,1.000000e+003,3.961066e+002,1.069733e-004,3.014384e-008,-1.042941e-001,1.766427e-004,3,9.696712e-001,1.825000e+000,,,,,,,,,,,,,,,,,,0,4.000000e+000,1.000000e+000,2,2,2.162781e-001,0,,0,
1654856320.350,,1.000000e+003,3.981674e+002,1.069351e-004,4.877345e-009,-1.050908e-001,6.698188e-005,3,9.693043e-001,1.825000e+000,,,,,,,,,,,,,,,,,,0,4.000000e+000,1.000000e+000,2,2,1.925964e-001,0,,0,
1654856688.632,,1.000000e+003,3.999816e+002,1.071498e-004,4.236808e-008,-1.038061e-001,1.775699e-004,3,9.695929e-001,1.825000e+000,,,,,,,,,,,,,,,,,,0,4.000000e+000,1.000000e+000,2,2,1.300049e-002,0,,0,
1654857010.602,,1.000000e+003,3.988457e+002,1.074287e-004,3.764508e-008,-1.009338e-001,4.774132e-004,3,9.693130e-001,1.825000e+000,,,,,,,,,,,,,,,,,,0,4.000000e+000,1.000000e+000,2,2,2.447205e-001,0,,0,
1654857098.531,,1.000000e+003,3.967723e+002,1.078237e-004,1.033092e-008,-9.989245e-002,1.468765e-004,3,9.692619e-001,1.825000e+000,,,,,,,,,,,,,,,,,,0,4.000000e+000,1.000000e+000,2,2,4.465027e-001,0,,0,
1654857158.197,,1.000000e+003,3.947052e+002,1.082802e-004,1.962771e-008,-9.830941e-002,6.023048e-004,3,9.691899e-001,1.825000e+000,,,,,,,,,,,,,,,,,,0,4.000000e+000,1.000000e+000,2,2,5.434265e-001,0,,0,
1654857214.073,,1.000000e+003,3.927310e+002,1.087227e-004,9.139363e-008,-9.710819e-002,2.607467e-004,3,9.692857e-001,1.825000e+000,,,,,,,,,,,,,,,,,,0,4.000000e+000,1.000000e+000,2,2,4.378967e-001,0,,0,
1654857284.489,,1.000000e+003,3.908051e+002,1.090945e-004,3.655436e-008,-9.588714e-002,1.917524e-004,3,9.697412e-001,1.825000e+000,,,,,,,,,,,,,,,,,,0,4.000000e+000,1.000000e+000,2,2,2.723999e-001,0,,0,
1654857600.228,,1.000000e+003,3.888986e+002,1.093960e-004,4.860367e-008,-9.573802e-002,2.090853e-004,3,9.697106e-001,1.825000e+000,,,,,,,,,,,,,,,,,,0,4.000000e+000,1.000000e+000,2,2,1.346741e-001,0,,0,
1654857714.720,,1.000000e+003,3.868356e+002,1.098292e-004,5.124300e-009,-9.459913e-002,2.969509e-004,3,9.697369e-001,1.825000e+000,,,,,,,,,,,,,,,,,,0,4.000000e+000,1.000000e+000,2,2,2.909241e-001,0,,0,
1654857796.476,,1.000000e+003,3.848313e+002,1.102516e-004,7.424062e-009,-9.420761e-002,7.927190e-004,3,9.699243e-001,1.825000e+000,,,,,,,,,,,,,,,,,,0,4.000000e+000,1.000000e+000,2,2,3.237915e-001,0,,0,
1654857898.105,,1.000000e+003,3.828780e+002,1.106055e-004,2.406774e-008,-9.261945e-002,2.299479e-004,3,9.696125e-001,1.825000e+000,,,,,,,,,,,,,,,,,,0,4.000000e+000,1.000000e+000,2,2,2.136841e-001,0,,0,
1654858046.735,,1.000000e+003,3.808719e+002,1.110172e-004,2.119176e-008,-9.230405e-002,8.310147e-004,3,9.699357e-001,1.825000e+000,,,,,,,,,,,,,,,,,,0,4.000000e+000,1.000000e+000,2,2,1.407776e-001,0,,0,
1654858176.869,,1.000000e+003,3.788818e+002,1.114107e-004,6.584416e-008,-9.083574e-002,2.050918e-004,3,9.700509e-001,1.825000e+000,,,,,,,,,,,,,,,,,,0,4.000000e+000,1.000000e+000,2,2,2.088928e-001,0,,0,
1654858292.825,,1.000000e+003,3.768616e+002,1.118067e-004,2.222588e-008,-9.016432e-002,2.172828e-004,3,9.698323e-001,1.825000e+000,,,,,,,,,,,,,,,,,,0,4.000000e+000,1.000000e+000,2,2,2.296143e-001,0,,0,
1654858412.979,,1.000000e+003,3.748723e+002,1.121443e-004,5.591454e-008,-8.935207e-002,3.642383e-004,3,9.701668e-001,1.825000e+000,,,,,,,,,,,,,,,,,,0,4.000000e+000,1.000000e+000,2,2,2.156982e-001,0,,0,
1654858541.153,,1.000000e+003,3.728571e+002,1.125383e-004,1.195156e-008,-8.870465e-002,8.454131e-005,3,9.701483e-001,1.825000e+000,,,,,,,,,,,,,,,,,,0,4.000000e+000,1.000000e+000,2,2,1.794739e-001,0,,0,
1654858665.547,,1.000000e+003,3.708448e+002,1.128367e-004,4.424596e-010,-8.777213e-002,3.095159e-005,3,9.700739e-001,1.825000e+000,,,,,,,,,,,,,,,,,,0,4.000000e+000,1.000000e+000,2,2,2.219849e-001,0,,0,
1654858782.778,,1.000000e+003,3.688771e+002,1.132027e-004,5.592483e-008,-8.688574e-002,1.790187e-005,3,9.704245e-001,1.825000e+000,,,,,,,,,,,,,,,,,,0,4.000000e+000,1.000000e+000,2,2,1.866150e-001,0,,0,
1654858903.407,,1.000000e+003,3.668796e+002,1.134077e-004,3.950753e-008,-8.614602e-002,7.318800e-005,3,9.698173e-001,1.825000e+000,,,,,,,,,,,,,,,,,,0,4.000000e+000,1.000000e+000,2,2,2.279053e-001,0,,0,
1654859027.536,,1.000000e+003,3.648643e+002,1.136786e-004,1.927272e-008,-8.579786e-002,2.585077e-004,3,9.702029e-001,1.825000e+000,,,,,,,,,,,,,,,,,,0,4.000000e+000,1.000000e+000,2,2,1.930847e-001,0,,0,
1654859151.427,,1.000000e+003,3.628801e+002,1.139386e-004,1.433878e-008,-8.467052e-002,4.725716e-004,3,9.700864e-001,1.825000e+000,,,,,,,,,,,,,,,,,,0,4.000000e+000,1.000000e+000,2,2,2.121887e-001,0,,0,
1654859273.306,,1.000000e+003,3.609078e+002,1.140474e-004,1.273358e-008,-8.400267e-002,8.186077e-004,3,9.703355e-001,1.825000e+000,,,,,,,,,,,,,,,,,,0,4.000000e+000,1.000000e+000,2,2,1.991882e-001,0,,0,
1654859396.438,,1.000000e+003,3.588878e+002,1.141579e-004,1.641216e-008,-8.336913e-002,8.738095e-005,3,9.702748e-001,1.825000e+000,,,,,,,,,,,,,,,,,,0,4.000000e+000,1.000000e+000,2,2,2.177124e-001,0,,0,
1654859519.379,,1.000000e+003,3.568813e+002,1.140252e-004,2.995349e-008,-8.264864e-002,3.237615e-004,3,9.703714e-001,1.825000e+000,,,,,,,,,,,,,,,,,,0,4.000000e+000,1.000000e+000,2,2,2.048950e-001,0,,0,
1654859643.264,,1.000000e+003,3.548779e+002,1.137862e-004,4.806346e-008,-8.160633e-002,7.196048e-005,3,9.703102e-001,1.825000e+000,,,,,,,,,,,,,,,,,,0,4.000000e+000,1.000000e+000,2,2,2.225952e-001,0,,0,
1654859766.143,,1.000000e+003,3.528629e+002,1.132312e-004,4.443632e-008,-8.041538e-002,4.797681e-004,3,9.701287e-001,1.825000e+000,,,,,,,,,,,,,,,,,,0,4.000000e+000,1.000000e+000,2,2,2.001038e-001,0,,0,
1654859885.932,,1.000000e+003,3.508940e+002,1.088227e-004,7.782401e-007,-7.887973e-002,1.071426e-004,3,9.692671e-001,1.825000e+000,,,,,,,,,,,,,,,,,,0,4.000000e+000,1.000000e+000,2,2,1.976929e-001,0,,0,
1654860008.609,,1.000000e+003,3.488676e+002,6.597912e-005,2.194672e-006,-5.832124e-002,2.868936e-003,3,9.606073e-001,1.825000e+000,,,,,,,,,,,,,,,,,,0,4.000000e+000,1.000000e+000,2,2,2.051086e-001,0,,0,
1654860130.783,,1.000000e+003,3.468753e+002,3.925793e-005,4.325300e-008,-2.067866e-002,1.464930e-003,3,9.426474e-001,1.825000e+000,,,,,,,,,,,,,,,,,,0,4.000000e+000,1.000000e+000,2,2,2.218933e-001,0,,0,
1654860251.908,,1.000000e+003,3.449045e+002,3.884845e-005,1.133931e-008,-1.864731e-002,1.076648e-003,3,9.421971e-001,1.825000e+000,,,,,,,,,,,,,,,,,,0,4.000000e+000,1.000000e+000,2,2,2.096863e-001,0,,0,
1654860376.340,,1.000000e+003,3.428817e+002,3.862366e-005,2.629548e-008,-1.683857e-002,7.983772e-004,3,9.422466e-001,1.825000e+000,,,,,,,,,,,,,,,,,,0,4.000000e+000,1.000000e+000,2,2,2.164917e-001,0,,0,
1654860499.531,,1.000000e+003,3.408931e+002,3.849369e-005,4.817922e-008,-1.600018e-002,1.202423e-004,3,9.421618e-001,1.825000e+000,,,,,,,,,,,,,,,,,,0,4.000000e+000,1.000000e+000,2,2,2.047119e-001,0,,0,
1654860623.467,,1.000000e+003,3.388690e+002,3.838287e-005,4.883005e-008,-1.483901e-002,6.538873e-004,3,9.418914e-001,1.825000e+000,,,,,,,,,,,,,,,,,,0,4.000000e+000,1.000000e+000,2,2,1.928101e-001,0,,0,
1654860745.344,,1.000000e+003,3.368679e+002,3.826147e-005,2.799329e-008,-1.262599e-002,2.116345e-004,3,9.416503e-001,1.825000e+000,,,,,,,,,,,,,,,,,,0,4.000000e+000,1.000000e+000,2,2,2.357178e-001,0,,0,
1654860865.032,,1.000000e+003,3.348894e+002,3.817989e-005,2.031198e-008,-1.246255e-002,1.479541e-003,3,9.401429e-001,1.825000e+000,,,,,,,,,,,,,,,,,,0,4.000000e+000,1.000000e+000,2,2,1.971130e-001,0,,0,
1654860985.468,,1.000000e+003,3.328999e+002,3.815346e-005,6.865842e-009,-1.168397e-002,5.074059e-004,3,9.419301e-001,1.825000e+000,,,,,,,,,,,,,,,,,,0,4.000000e+000,1.000000e+000,2,2,1.945801e-001,0,,0,
1654861109.646,,1.000000e+003,3.308719e+002,3.809216e-005,5.381543e-008,-1.189112e-002,7.607388e-004,3,9.411798e-001,1.825000e+000,,,,,,,,,,,,,,,,,,0,4.000000e+000,1.000000e+000,2,2,2.182922e-001,0,,0,
1654861233.030,,1.000000e+003,3.288721e+002,3.806736e-005,1.666941e-008,-9.609655e-003,2.069768e-003,3,9.420485e-001,1.825000e+000,,,,,,,,,,,,,,,,,,0,4.000000e+000,1.000000e+000,2,2,1.984253e-001,0,,0,
1654861355.956,,1.000000e+003,3.268872e+002,3.802683e-005,3.358320e-008,-9.598294e-003,8.064174e-004,3,9.429293e-001,1.825000e+000,,,,,,,,,,,,,,,,,,0,4.000000e+000,1.000000e+000,2,2,2.211914e-001,0,,0,
1654861477.649,,1.000000e+003,3.248730e+002,3.799112e-005,1.669770e-008,-8.886019e-003,1.745610e-004,3,9.413561e-001,1.825000e+000,,,,,,,,,,,,,,,,,,0,4.000000e+000,1.000000e+000,2,2,2.268066e-001,0,,0,
1654861600.292,,1.000000e+003,3.228622e+002,3.801263e-005,7.439495e-008,-7.784365e-003,5.116065e-004,3,9.402748e-001,1.825000e+000,,,,,,,,,,,,,,,,,,0,4.000000e+000,1.000000e+000,2,2,2.154846e-001,0,,0,
1654861726.235,,1.000000e+003,3.208593e+002,3.802739e-005,4.926222e-008,-7.351334e-003,4.878488e-004,3,9.413317e-001,1.825000e+000,,,,,,,,,,,,,,,,,,0,4.000000e+000,1.000000e+000,2,2,2.125854e-001,0,,0,
1654861850.180,,1.000000e+003,3.188787e+002,3.806595e-005,2.940041e-008,-7.221922e-003,8.461622e-004,3,9.411306e-001,1.825000e+000,,,,,,,,,,,,,,,,,,0,4.000000e+000,1.000000e+000,2,2,2.018738e-001,0,,0,
1654861972.354,,1.000000e+003,3.168900e+002,3.803892e-005,2.443560e-008,-5.404169e-003,7.484246e-004,3,9.406106e-001,1.825000e+000,,,,,,,,,,,,,,,,,,0,4.000000e+000,1.000000e+000,2,2,2.149963e-001,0,,0,
1654862095.787,,1.000000e+003,3.148747e+002,3.805571e-005,3.483083e-008,-5.006805e-003,7.923301e-004,3,9.404584e-001,1.825000e+000,,,,,,,,,,,,,,,,,,0,4.000000e+000,1.000000e+000,2,2,1.885986e-001,0,,0,
1654862219.411,,1.000000e+003,3.128748e+002,3.807455e-005,2.479060e-008,-4.247611e-003,1.314940e-003,3,9.409505e-001,1.825000e+000,,,,,,,,,,,,,,,,,,0,4.000000e+000,1.000000e+000,2,2,2.247925e-001,0,,0,
1654862341.579,,1.000000e+003,3.108905e+002,3.811662e-005,2.304134e-008,-4.315546e-003,1.002972e-003,3,9.417700e-001,1.825000e+000,,,,,,,,,,,,,,,,,,0,4.000000e+000,1.000000e+000,2,2,2.140808e-001,0,,0,
1654862465.453,,1.000000e+003,3.088538e+002,3.813107e-005,1.253807e-008,-4.505755e-003,1.393169e-003,3,9.397024e-001,1.825000e+000,,,,,,,,,,,,,,,,,,0,4.000000e+000,1.000000e+000,2,2,2.187195e-001,0,,0,
1654862586.899,,1.000000e+003,3.068751e+002,3.824092e-005,2.704920e-008,-1.817932e-003,9.998360e-004,3,9.402087e-001,1.825000e+000,,,,,,,,,,,,,,,,,,0,4.000000e+000,1.000000e+000,2,2,1.933899e-001,0,,0,
1654862710.578,,1.000000e+003,3.048701e+002,3.821083e-005,4.656373e-008,-1.118082e-003,8.926989e-004,3,9.405540e-001,1.825000e+000,,,,,,,,,,,,,,,,,,0,4.000000e+000,1.000000e+000,2,2,1.906128e-001,0,,0,
1654862831.027,,1.000000e+003,3.028805e+002,3.831043e-005,4.784737e-009,-6.682714e-004,5.269354e-004,3,9.411557e-001,1.825000e+000,,,,,,,,,,,,,,,,,,0,4.000000e+000,1.000000e+000,2,2,2.241211e-001,0,,0,
1654862954.479,,1.000000e+003,3.008419e+002,3.834630e-005,4.304206e-008,-1.245227e-003,2.550136e-004,3,9.403546e-001,1.825000e+000,,,,,,,,,,,,,,,,,,0,4.000000e+000,1.000000e+000,2,2,2.067261e-001,0,,0,
1654863565.381,,1.000000e+003,3.000123e+002,3.833627e-005,7.147523e-008,-1.454274e-003,6.694886e-004,3,9.407446e-001,1.825000e+000,,,,,,,,,,,,,,,,,,0,4.000000e+000,1.000000e+000,2,2,0.000000e+000,0,,0,
1654863726.509,,1.000000e+003,3.021485e+002,3.823652e-005,3.348030e-008,-3.081249e-003,1.402275e-003,3,9.401035e-001,1.825000e+000,,,,,,,,,,,,,,,,,,0,4.000000e+000,1.000000e+000,2,2,2.660828e-001,0,,0,
1654863831.883,,1.000000e+003,3.041498e+002,3.817029e-005,4.090693e-008,-2.774377e-003,1.261743e-003,3,9.408879e-001,1.825000e+000,,,,,,,,,,,,,,,,,,0,4.000000e+000,1.000000e+000,2,2,2.480164e-001,0,,0,
1654863949.258,,1.000000e+003,3.061463e+002,3.808318e-005,5.034265e-009,-4.737385e-003,3.993707e-004,3,9.412920e-001,1.825000e+000,,,,,,,,,,,,,,,,,,0,4.000000e+000,1.000000e+000,2,2,2.293091e-001,0,,0,
1654864071.388,,1.000000e+003,3.081580e+002,3.804482e-005,2.854636e-008,-5.531400e-003,1.014418e-003,3,9.401927e-001,1.825000e+000,,,,,,,,,,,,,,,,,,0,4.000000e+000,1.000000e+000,2,2,2.026062e-001,0,,0,
1654864193.588,,1.000000e+003,3.101355e+002,3.795750e-005,8.368146e-009,-7.210106e-003,2.551185e-004,3,9.412694e-001,1.825000e+000,,,,,,,,,,,,,,,,,,0,4.000000e+000,1.000000e+000,2,2,2.130127e-001,0,,0,
1654864312.253,,1.000000e+003,3.121076e+002,3.791240e-005,3.192140e-008,-7.898282e-003,1.742564e-003,3,9.401830e-001,1.825000e+000,,,,,,,,,,,,,,,,,,0,4.000000e+000,1.000000e+000,2,2,2.158813e-001,0,,0,
1654864433.167,,1.000000e+003,3.141223e+002,3.783725e-005,2.665047e-008,-9.243790e-003,1.360768e-003,3,9.400634e-001,1.825000e+000,,,,,,,,,,,,,,,,,,0,4.000000e+000,1.000000e+000,2,2,1.954041e-001,0,,0,
1654864553.877,,1.000000e+003,3.161096e+002,3.783697e-005,5.524057e-008,-9.605434e-003,4.932597e-004,3,9.403331e-001,1.825000e+000,,,,,,,,,,,,,,,,,,0,4.000000e+000,1.000000e+000,2,2,2.218933e-001,0,,0,
1654864680.284,,1.000000e+003,3.181540e+002,3.779911e-005,2.149788e-008,-1.045182e-002,5.415613e-004,3,9.403672e-001,1.825000e+000,,,,,,,,,,,,,,,,,,0,4.000000e+000,1.000000e+000,2,2,2.008057e-001,0,,0,
1654864797.481,,1.000000e+003,3.201229e+002,3.779043e-005,1.028976e-010,-1.168193e-002,4.917971e-004,3,9.409326e-001,1.825000e+000,,,,,,,,,,,,,,,,,,0,4.000000e+000,1.000000e+000,2,2,2.035828e-001,0,,0,
1654864919.654,,1.000000e+003,3.221428e+002,3.774981e-005,2.174998e-008,-1.271232e-002,2.880783e-004,3,9.408606e-001,1.825000e+000,,,,,,,,,,,,,,,,,,0,4.000000e+000,1.000000e+000,2,2,1.896973e-001,0,,0,
1654865040.818,,1.000000e+003,3.241169e+002,3.775878e-005,4.995678e-009,-1.405812e-002,1.167763e-003,3,9.402033e-001,1.825000e+000,,,,,,,,,,,,,,,,,,0,4.000000e+000,1.000000e+000,2,2,2.173157e-001,0,,0,
1654865162.562,,1.000000e+003,3.261232e+002,3.774392e-005,3.022617e-009,-1.424508e-002,1.199725e-003,3,9.412903e-001,1.825000e+000,,,,,,,,,,,,,,,,,,0,4.000000e+000,1.000000e+000,2,2,1.862183e-001,0,,0,
1654865288.223,,1.000000e+003,3.281454e+002,3.771024e-005,2.439702e-008,-1.524335e-002,1.311311e-003,3,9.407500e-001,1.825000e+000,,,,,,,,,,,,,,,,,,0,4.000000e+000,1.000000e+000,2,2,1.887207e-001,0,,0,
1654865407.660,,1.000000e+003,3.301206e+002,3.772217e-005,2.134353e-008,-1.638361e-002,1.647207e-003,3,9.419061e-001,1.825000e+000,,,,,,,,,,,,,,,,,,0,4.000000e+000,1.000000e+000,2,2,2.086182e-001,0,,0,
1654865530.129,,1.000000e+003,3.321123e+002,3.772140e-005,8.306407e-009,-1.662594e-002,8.274151e-004,3,9.406155e-001,1.825000e+000,,,,,,,,,,,,,,,,,,0,4.000000e+000,1.000000e+000,2,2,1.849060e-001,0,,0,
1654865652.280,,1.000000e+003,3.341187e+002,3.774376e-005,9.577192e-009,-1.805667e-002,9.579004e-004,3,9.410657e-001,1.825000e+000,,,,,,,,,,,,,,,,,,0,4.000000e+000,1.000000e+000,2,2,2.051086e-001,0,,0,
1654865772.514,,1.000000e+003,3.361393e+002,3.775852e-005,3.228412e-008,-1.955257e-002,1.168116e-003,3,9.408407e-001,1.825000e+000,,,,,,,,,,,,,,,,,,0,4.000000e+000,1.000000e+000,2,2,1.895752e-001,0,,0,
1654865890.953,,1.000000e+003,3.381085e+002,3.780544e-005,5.192983e-008,-2.084205e-002,3.569219e-004,3,9.412177e-001,1.825000e+000,,,,,,,,,,,,,,,,,,0,4.000000e+000,1.000000e+000,2,2,2.011108e-001,0,,0,
1654866013.118,,1.000000e+003,3.401045e+002,3.783352e-005,4.476816e-008,-2.188471e-002,3.383812e-004,3,9.405632e-001,1.825000e+000,,,,,,,,,,,,,,,,,,0,4.000000e+000,1.000000e+000,2,2,1.851196e-001,0,,0,
1654866138.493,,1.000000e+003,3.421325e+002,3.790954e-005,1.875310e-009,-2.304570e-002,8.122475e-004,3,9.411284e-001,1.825000e+000,,,,,,,,,,,,,,,,,,0,4.000000e+000,1.000000e+000,2,2,2.156067e-001,0,,0,
1654866260.251,,1.000000e+003,3.441460e+002,3.795268e-005,2.460795e-008,-2.429909e-002,9.383443e-004,3,9.415191e-001,1.825000e+000,,,,,,,,,,,,,,,,,,0,4.000000e+000,1.000000e+000,2,2,1.992798e-001,0,,0,
1654866379.876,,1.000000e+003,3.461076e+002,3.803272e-005,7.763623e-009,-2.475450e-002,1.320204e-003,3,9.417818e-001,1.825000e+000,,,,,,,,,,,,,,,,,,0,4.000000e+000,1.000000e+000,2,2,2.015991e-001,0,,0,
1654866500.798,,1.000000e+003,3.481271e+002,3.810168e-005,2.005474e-008,-2.648376e-002,8.626775e-004,3,9.398607e-001,1.825000e+000,,,,,,,,,,,,,,,,,,0,4.000000e+000,1.000000e+000,2,2,1.653137e-001,0,,0,
1654866619.676,,1.000000e+003,3.501101e+002,3.818781e-005,8.507058e-009,-2.819905e-002,5.787803e-004,3,9.424329e-001,1.825000e+000,,,,,,,,,,,,,,,,,,0,4.000000e+000,1.000000e+000,2,2,1.870117e-001,0,,0,
1654866743.556,,1.000000e+003,3.521368e+002,3.837547e-005,4.727372e-008,-2.895631e-002,2.706370e-003,3,9.420283e-001,1.825000e+000,,,,,,,,,,,,,,,,,,0,4.000000e+000,1.000000e+000,2,2,1.891785e-001,0,,0,
1654866864.183,,1.000000e+003,3.541204e+002,3.851145e-005,1.303712e-008,-3.051246e-002,2.417236e-003,3,9.433491e-001,1.825000e+000,,,,,,,,,,,,,,,,,,0,4.000000e+000,1.000000e+000,2,2,2.217102e-001,0,,0,
1654866986.814,,1.000000e+003,3.561147e+002,3.865887e-005,5.433764e-008,-3.113539e-002,1.087178e-003,3,9.419428e-001,1.825000e+000,,,,,,,,,,,,,,,,,,0,4.000000e+000,1.000000e+000,2,2,2.039185e-001,0,,0,
1654867113.463,,1.000000e+003,3.581458e+002,3.885138e-005,1.436707e-008,-3.188657e-002,1.034417e-003,3,9.426069e-001,1.825000e+000,,,,,,,,,,,,,,,,,,0,4.000000e+000,1.000000e+000,2,2,2.062988e-001,0,,0,
1654867237.111,,1.000000e+003,3.601256e+002,3.908997e-005,3.006410e-008,-3.373574e-002,9.986643e-004,3,9.435639e-001,1.825000e+000,,,,,,,,,,,,,,,,,,0,4.000000e+000,1.000000e+000,2,2,2.192993e-001,0,,0,
1654867359.521,,1.000000e+003,3.621259e+002,3.934437e-005,3.495431e-008,-3.485409e-002,1.102130e-003,3,9.434489e-001,1.825000e+000,,,,,,,,,,,,,,,,,,0,4.000000e+000,1.000000e+000,2,2,2.006226e-001,0,,0,
1654867482.457,,1.000000e+003,3.641255e+002,3.971007e-005,2.445876e-008,-3.648608e-002,1.235772e-004,3,9.431089e-001,1.825000e+000,,,,,,,,,,,,,,,,,,0,4.000000e+000,1.000000e+000,2,2,1.708984e-001,0,,0,
1654867606.647,,1.000000e+003,3.661323e+002,4.036512e-005,1.595684e-008,-4.371034e-002,1.520679e-003,3,9.492155e-001,1.825000e+000,,,,,,,,,,,,,,,,,,0,4.000000e+000,1.000000e+000,2,2,1.836853e-001,0,,0,
1654867728.277,,1.000000e+003,3.681186e+002,4.122633e-005,6.894652e-008,-4.208643e-002,3.864444e-004,3,9.454077e-001,1.825000e+000,,,,,,,,,,,,,,,,,,0,4.000000e+000,1.000000e+000,2,2,2.185974e-001,0,,0,
1654867851.737,,1.000000e+003,3.701192e+002,4.470461e-005,2.858443e-007,-5.541955e-002,8.924542e-004,3,9.463989e-001,1.825000e+000,,,,,,,,,,,,,,,,,,0,4.000000e+000,1.000000e+000,2,2,1.990967e-001,0,,0,
1654867975.192,,1.000000e+003,3.721428e+002,5.707783e-005,9.080788e-007,-7.588471e-002,1.511339e-003,3,9.531378e-001,1.825000e+000,,,,,,,,,,,,,,,,,,0,4.000000e+000,1.000000e+000,2,2,2.124939e-001,0,,0,
1654868096.330,,1.000000e+003,3.741161e+002,9.648429e-005,1.643665e-006,-9.746608e-002,4.277168e-004,3,9.666070e-001,1.825000e+000,,,,,,,,,,,,,,,,,,0,4.000000e+000,1.000000e+000,2,2,2.260132e-001,0,,0,
1654868216.777,,1.000000e+003,3.761170e+002,1.107871e-004,1.337669e-009,-9.661955e-002,1.604373e-004,3,9.699135e-001,1.825000e+000,,,,,,,,,,,,,,,,,,0,4.000000e+000,1.000000e+000,2,2,2.057800e-001,0,,0,
1654868340.304,,1.000000e+003,3.781230e+002,1.105994e-004,5.022431e-008,-9.672844e-002,3.113124e-004,3,9.696045e-001,1.825000e+000,,,,,,,,,,,,,,,,,,0,4.000000e+000,1.000000e+000,2,2,2.080078e-001,0,,0,
1654868462.505,,1.000000e+003,3.801487e+002,1.104251e-004,1.004126e-007,-9.745605e-002,8.989923e-005,3,9.698533e-001,1.825000e+000,,,,,,,,,,,,,,,,,,0,4.000000e+000,1.000000e+000,2,2,2.221069e-001,0,,0,
1654868580.736,,1.000000e+003,3.821084e+002,1.102410e-004,6.693487e-008,-9.808369e-002,2.406164e-004,3,9.695874e-001,1.825000e+000,,,,,,,,,,,,,,,,,,0,4.000000e+000,1.000000e+000,2,2,2.125854e-001,0,,0,
1654868705.424,,1.000000e+003,3.840952e+002,1.099491e-004,2.984544e-008,-9.767132e-002,6.522489e-004,3,9.697334e-001,1.825000e+000,,,,,,,,,,,,,,,,,,0,4.000000e+000,1.000000e+000,2,2,1.791992e-001,0,,0,
1654868828.126,,1.000000e+003,3.861128e+002,1.096105e-004,1.894859e-008,-9.900810e-002,3.244201e-004,3,9.696868e-001,1.825000e+000,,,,,,,,,,,,,,,,,,0,4.000000e+000,1.000000e+000,2,2,1.931763e-001,0,,0,
1654868954.015,,1.000000e+003,3.881555e+002,1.092763e-004,2.581186e-008,-9.922710e-002,4.068066e-004,3,9.699304e-001,1.825000e+000,,,,,,,,,,,,,,,,,,0,4.000000e+000,1.000000e+000,2,2,1.708984e-001,0,,0,
1654869075.178,,1.000000e+003,3.901161e+002,1.089607e-004,3.606564e-009,-9.975518e-002,2.476233e-004,3,9.698855e-001,1.825000e+000,,,,,,,,,,,,,,,,,,0,4.000000e+000,1.000000e+000,2,2,2.219849e-001,0,,0,
1654869199.322,,1.000000e+003,3.921346e+002,1.086158e-004,6.930152e-008,-9.972987e-002,1.717589e-004,3,9.695781e-001,1.825000e+000,,,,,,,,,,,,,,,,,,0,4.000000e+000,1.000000e+000,2,2,1.745911e-001,0,,0,
1654869318.957,,1.000000e+003,3.941057e+002,1.082295e-004,4.719912e-008,-1.001788e-001,1.368824e-004,3,9.693958e-001,1.825000e+000,,,,,,,,,,,,,,,,,,0,4.000000e+000,1.000000e+000,2,2,2.141113e-001,0,,0,
1654869440.585,,1.000000e+003,3.960971e+002,1.079103e-004,2.800358e-008,-1.005549e-001,1.727547e-004,3,9.695508e-001,1.825000e+000,,,,,,,,,,,,,,,,,,0,4.000000e+000,1.000000e+000,2,2,2.034912e-001,0,,0,
1654869567.215,,1.000000e+003,3.981449e+002,1.074916e-004,4.909758e-008,-1.004260e-001,5.638722e-005,3,9.694837e-001,1.825000e+000,,,,,,,,,,,,,,,,,,0,4.000000e+000,1.000000e+000,2,2,2.438965e-001,0,,0,
1654869935.108,,1.000000e+003,3.999849e+002,1.073005e-004,3.005638e-008,-9.889288e-002,3.790477e-004,3,9.697973e-001,1.825000e+000,,,,,,,,,,,,,,,,,,0,4.000000e+000,1.000000e+000,2,2,1.300049e-002,0,,0,
1654870256.498,,1.000000e+003,3.988585e+002,1.075400e-004,1.845983e-008,-9.725716e-002,1.175581e-004,3,9.698105e-001,1.825000e+000,,,,,,,,,,,,,,,,,,0,4.000000e+000,1.000000e+000,2,2,2.446899e-001,0,,0,
1654870343.625,,1.000000e+003,3.967851e+002,1.079162e-004,6.259774e-008,-9.549513e-002,2.914981e-004,3,9.694397e-001,1.825000e+000,,,,,,,,,,,,,,,,,,0,4.000000e+000,1.000000e+000,2,2,3.828125e-001,0,,0,
1654870402.772,,1.000000e+003,3.947273e+002,1.084190e-004,4.557848e-008,-9.417430e-002,3.067184e-004,3,9.693618e-001,1.825000e+000,,,,,,,,,,,,,,,,,,0,4.000000e+000,1.000000e+000,2,2,4.550171e-001,0,,0,
1654870459.427,,1.000000e+003,3.927592e+002,1.088444e-004,2.560092e-008,-9.281884e-002,4.502179e-004,3,9.696578e-001,1.825000e+000,,,,,,,,,,,,,,,,,,0,4.000000e+000,1.000000e+000,2,2,4.002075e-001,0,,0,
1654870529.053,,1.000000e+003,3.908515e+002,1.093120e-004,5.204560e-008,-9.198780e-002,3.215278e-004,3,9.700009e-001,1.825000e+000,,,,,,,,,,,,,,,,,,0,4.000000e+000,1.000000e+000,2,2,2.600098e-001,0,,0,
1654870850.061,,1.000000e+003,3.889171e+002,1.095471e-004,2.620801e-008,-9.209676e-002,2.705880e-004,3,9.694537e-001,1.825000e+000,,,,,,,,,,,,,,,,,,0,4.000000e+000,1.000000e+000,2,2,1.471252e-001,0,,0,
1654870967.190,,1.000000e+003,3.868054e+002,1.100242e-004,2.601765e-008,-9.137836e-002,2.401949e-004,3,9.699048e-001,1.825000e+000,,,,,,,,,,,,,,,,,,0,4.000000e+000,1.000000e+000,2,2,2.666016e-001,0,,0,
1654871048.366,,1.000000e+003,3.848403e+002,1.104369e-004,6.461453e-008,-9.003215e-002,9.864470e-004,3,9.702927e-001,1.825000e+000,,,,,,,,,,,,,,,,,,0,4.000000e+000,1.000000e+000,2,2,3.117065e-001,0,,0,
1654871151.529,,1.000000e+003,3.828958e+002,1.108151e-004,3.971846e-009,-8.917867e-002,4.433638e-004,3,9.698360e-001,1.825000e+000,,,,,,,,,,,,,,,,,,0,4.000000e+000,1.000000e+000,2,2,1.899109e-001,0,,0,
1654871296.703,,1.000000e+003,3.808984e+002,1.112332e-004,1.462175e-008,-8.894663e-002,3.396035e-004,3,9.697479e-001,1.825000e+000,,,,,,,,,,,,,,,,,,0,4.000000e+000,1.000000e+000,2,2,1.878967e-001,0,,0,
1654871428.331,,1.000000e+003,3.788760e+002,1.116577e-004,2.173711e-008,-8.764395e-002,2.593243e-004,3,9.697965e-001,1.825000e+000,,,,,,,,,,,,,,,,,,0,4.000000e+000,1.000000e+000,2,2,2.088928e-001,0,,0,
1654871548.002,,1.000000e+003,3.768617e+002,1.120675e-004,1.919040e-008,-8.710419e-002,3.394981e-004,3,9.697482e-001,1.825000e+000,,,,,,,,,,,,,,,,,,0,4.000000e+000,1.000000e+000,2,2,2.296143e-001,0,,0,
1654871670.945,,1.000000e+003,3.748893e+002,1.124487e-004,3.206289e-008,-8.621584e-002,3.224919e-004,3,9.701990e-001,1.825000e+000,,,,,,,,,,,,,,,,,,0,4.000000e+000,1.000000e+000,2,2,1.704102e-001,0,,0,
1654871798.575,,1.000000e+003,3.728851e+002,1.128124e-004,6.492837e-009,-8.523782e-002,1.837550e-004,3,9.701784e-001,1.825000e+000,,,,,,,,,,,,,,,,,,0,4.000000e+000,1.000000e+000,2,2,2.131958e-001,0,,0,
1654871919.272,,1.000000e+003,3.708921e+002,1.132259e-004,2.192233e-008,-8.485991e-002,9.659531e-005,3,9.703537e-001,1.825000e+000,,,,,,,,,,,,,,,,,,0,4.000000e+000,1.000000e+000,2,2,2.109985e-001,0,,0,
1654872040.517,,1.000000e+003,3.688908e+002,1.135607e-004,1.337669e-010,-8.463085e-002,2.251274e-004,3,9.702346e-001,1.825000e+000,,,,,,,,,,,,,,,,,,0,4.000000e+000,1.000000e+000,2,2,2.196045e-001,0,,0,
1654872165.292,,1.000000e+003,3.668497e+002,1.139287e-004,1.764693e-008,-8.370613e-002,2.633283e-004,3,9.699696e-001,1.825000e+000,,,,,,,,,,,,,,,,,,0,4.000000e+000,1.000000e+000,2,2,2.169800e-001,0,,0,
1654872287.421,,1.000000e+003,3.648831e+002,1.142098e-004,8.391299e-009,-8.313422e-002,5.745247e-004,3,9.706541e-001,1.825000e+000,,,,,,,,,,,,,,,,,,0,4.000000e+000,1.000000e+000,2,2,2.254028e-001,0,,0,
1654872412.064,,1.000000e+003,3.628641e+002,1.144725e-004,1.843925e-008,-8.153077e-002,3.742219e-004,3,9.697921e-001,1.825000e+000,,,,,,,,,,,,,,,,,,0,4.000000e+000,1.000000e+000,2,2,2.015991e-001,0,,0,
1654872532.984,,1.000000e+003,3.608658e+002,1.147665e-004,6.688343e-010,-8.121797e-002,1.166836e-004,3,9.705862e-001,1.825000e+000,,,,,,,,,,,,,,,,,,0,4.000000e+000,1.000000e+000,2,2,2.411804e-001,0,,0,
1654872652.937,,1.000000e+003,3.588827e+002,1.149640e-004,4.304206e-008,-8.106607e-002,2.009140e-004,3,9.703273e-001,1.825000e+000,,,,,,,,,,,,,,,,,,0,4.000000e+000,1.000000e+000,2,2,2.177124e-001,0,,0,
1654872775.816,,1.000000e+003,3.568915e+002,1.150266e-004,4.019179e-008,-8.024935e-002,2.436931e-004,3,9.698690e-001,1.825000e+000,,,,,,,,,,,,,,,,,,0,4.000000e+000,1.000000e+000,2,2,2.048035e-001,0,,0,
1654872900.517,,1.000000e+003,3.548880e+002,1.150139e-004,1.110265e-008,-7.941018e-002,1.039289e-004,3,9.703962e-001,1.825000e+000,,,,,,,,,,,,,,,,,,0,4.000000e+000,1.000000e+000,2,2,2.124939e-001,0,,0,
1654873026.214,,1.000000e+003,3.528379e+002,1.148483e-004,1.008962e-007,-7.877857e-002,5.647678e-005,3,9.702347e-001,1.825000e+000,,,,,,,,,,,,,,,,,,0,4.000000e+000,1.000000e+000,2,2,1.999817e-001,0,,0,
1654873146.161,,1.000000e+003,3.508694e+002,1.140424e-004,2.156476e-007,-7.781347e-002,3.065656e-004,3,9.702597e-001,1.825000e+000,,,,,,,,,,,,,,,,,,0,4.000000e+000,1.000000e+000,2,2,1.976929e-001,0,,0,
1654873268.822,,1.000000e+003,3.488969e+002,6.478080e-005,3.003328e-006,-6.434673e-002,2.232229e-003,3,9.581227e-001,1.825000e+000,,,,,,,,,,,,,,,,,,0,4.000000e+000,1.000000e+000,2,2,1.954041e-001,0,,0,
1654873392.228,,1.000000e+003,3.468753e+002,3.982852e-005,4.561192e-008,-2.401417e-002,2.711083e-004,3,9.423804e-001,1.825000e+000,,,,,,,,,,,,,,,,,,0,4.000000e+000,1.000000e+000,2,2,2.123108e-001,0,,0,
1654873515.378,,1.000000e+003,3.448687e+002,3.887745e-005,3.689650e-008,-1.792131e-002,9.730654e-006,3,9.420825e-001,1.825000e+000,,,,,,,,,,,,,,,,,,0,4.000000e+000,1.000000e+000,2,2,1.716003e-001,0,,0,
1654873638.060,,1.000000e+003,3.428723e+002,3.859655e-005,6.899282e-009,-1.610879e-002,2.218413e-004,3,9.415969e-001,1.825000e+000,,,,,,,,,,,,,,,,,,0,4.000000e+000,1.000000e+000,2,2,2.072144e-001,0,,0,
1654873761.185,,1.000000e+003,3.408629e+002,3.842917e-005,2.558034e-008,-1.512691e-002,4.199492e-004,3,9.411252e-001,1.825000e+000,,,,,,,,,,,,,,,,,,0,4.000000e+000,1.000000e+000,2,2,2.045898e-001,0,,0,
1654873881.902,,1.000000e+003,3.388805e+002,3.829762e-005,2.628519e-008,-1.172425e-002,5.126572e-004,3,9.412874e-001,1.825000e+000,,,,,,,,,,,,,,,,,,0,4.000000e+000,1.000000e+000,2,2,1.927795e-001,0,,0,
1654874006.527,,1.000000e+003,3.368610e+002,3.821174e-005,4.105356e-008,-1.243183e-002,1.069455e-003,3,9.421551e-001,1.825000e+000,,,,,,,,,,,,,,,,,,0,4.000000e+000,1.000000e+000,2,2,1.994934e-001,0,,0,
1654874127.961,,1.000000e+003,3.348871e+002,3.813166e-005,3.458388e-008,-1.160627e-002,1.791261e-004,3,9.416342e-001,1.825000e+000,,,,,,,,,,,,,,,,,,0,4.000000e+000,1.000000e+000,2,2,1.882019e-001,0,,0,
1654874251.601,,1.000000e+003,3.328622e+002,3.805420e-005,1.075280e-009,-1.038533e-002,8.261039e-004,3,9.415830e-001,1.825000e+000,,,,,,,,,,,,,,,,,,0,4.000000e+000,1.000000e+000,2,2,1.857910e-001,0,,0,
1654874372.237,,1.000000e+003,3.308741e+002,3.802014e-005,2.154418e-008,-9.890087e-003,7.151405e-004,3,9.411020e-001,1.825000e+000,,,,,,,,,,,,,,,,,,0,4.000000e+000,1.000000e+000,2,2,2.095947e-001,0,,0,
1654874493.420,,1.000000e+003,3.288850e+002,3.800463e-005,4.962236e-008,-9.537295e-003,4.504148e-004,3,9.410467e-001,1.825000e+000,,,,,,,,,,,,,,,,,,0,4.000000e+000,1.000000e+000,2,2,1.984253e-001,0,,0,
1654874616.117,,1.000000e+003,3.268829e+002,3.797601e-005,4.259960e-009,-8.425088e-003,1.392402e-003,3,9.417316e-001,1.825000e+000,,,,,,,,,,,,,,,,,,0,4.000000e+000,1.000000e+000,2,2,2.041931e-001,0,,0,
1654874738.308,,1.000000e+003,3.248751e+002,3.794899e-005,1.034121e-008,-7.777308e-003,1.718962e-003,3,9.410913e-001,1.825000e+000,,,,,,,,,,,,,,,,,,0,4.000000e+000,1.000000e+000,2,2,2.015991e-001,0,,0,
1654874862.207,,1.000000e+003,3.228663e+002,3.793346e-005,2.615914e-008,-7.071374e-003,3.790088e-004,3,9.411376e-001,1.825000e+000,,,,,,,,,,,,,,,,,,0,4.000000e+000,1.000000e+000,2,2,1.988831e-001,0,,0,
1654874985.332,,1.000000e+003,3.208695e+002,3.793903e-005,3.823931e-008,-7.101931e-003,4.090954e-004,3,9.411017e-001,1.825000e+000,,,,,,,,,,,,,,,,,,0,4.000000e+000,1.000000e+000,2,2,1.962891e-001,0,,0,
1654875106.208,,1.000000e+003,3.188969e+002,3.794896e-005,1.758520e-008,-4.307976e-003,5.848073e-005,3,9.412016e-001,1.825000e+000,,,,,,,,,,,,,,,,,,0,4.000000e+000,1.000000e+000,2,2,1.856995e-001,0,,0,
1654875228.636,,1.000000e+003,3.168900e+002,3.797986e-005,1.561214e-008,-4.160648e-003,9.756687e-004,3,9.417314e-001,1.825000e+000,,,,,,,,,,,,,,,,,,0,4.000000e+000,1.000000e+000,2,2,1.990967e-001,0,,0,
1654875352.084,,1.000000e+003,3.148845e+002,3.798740e-005,2.819394e-009,-2.893481e-003,6.991308e-004,3,9.406649e-001,1.825000e+000,,,,,,,,,,,,,,,,,,0,4.000000e+000,1.000000e+000,2,2,1.965027e-001,0,,0,
1654875475.809,,1.000000e+003,3.128904e+002,3.805198e-005,1.344871e-008,-2.551094e-003,8.751313e-004,3,9.413154e-001,1.825000e+000,,,,,,,,,,,,,,,,,,0,4.000000e+000,1.000000e+000,2,2,1.937866e-001,0,,0,
1654875598.589,,1.000000e+003,3.108810e+002,3.804864e-005,1.967144e-008,-2.662238e-003,4.852503e-004,3,9.406016e-001,1.825000e+000,,,,,,,,,,,,,,,,,,0,4.000000e+000,1.000000e+000,2,2,2.216797e-001,0,,0,
1654875719.481,,1.000000e+003,3.088896e+002,3.809545e-005,6.675481e-009,-2.519096e-003,1.259388e-003,3,9.402972e-001,1.825000e+000,,,,,,,,,,,,,,,,,,0,4.000000e+000,1.000000e+000,2,2,2.186890e-001,0,,0,
1654875844.106,,1.000000e+003,3.068583e+002,3.814523e-005,1.727136e-008,-1.426643e-003,4.905565e-004,3,9.401135e-001,1.825000e+000,,,,,,,,,,,,,,,,,,0,4.000000e+000,1.000000e+000,2,2,2.008057e-001,0,,0,
1654875965.100,,1.000000e+003,3.048958e+002,3.814770e-005,9.561758e-009,-2.371999e-004,3.881552e-005,3,9.399104e-001,1.825000e+000,,,,,,,,,,,,,,,,,,0,4.000000e+000,1.000000e+000,2,2,2.054138e-001,0,,0,
1654876087.042,,1.000000e+003,3.028751e+002,3.823042e-005,5.661940e-009,-4.626290e-004,5.497354e-004,3,9.416320e-001,1.825000e+000,,,,,,,,,,,,,,,,,,0,4.000000e+000,1.000000e+000,2,2,2.025146e-001,0,,0,
1654876209.263,,1.000000e+003,3.008419e+002,3.830343e-005,5.836094e-008,8.585300e-004,7.555161e-004,3,9.410187e-001,1.825000e+000,,,,,,,,,,,,,,,,,,0,4.000000e+000,1.000000e+000,2,2,2.067261e-001,0,,0,
1654876567.467,,1.000000e+003,3.000105e+002,3.831282e-005,1.750288e-008,4.919771e-004,6.879570e-004,3,9.404601e-001,1.825000e+000,,,,,,,,,,,,,,,,,,0,4.000000e+000,1.000000e+000,2,2,1.422119e-002,0,,0,