File: spin_crossover/dane/Trt_TEOS — kopia/Medium TEOS/FeTrz_Trt_medium_XTvT_MCE,powtorka.rso.csv
Field (Oe),Temperature (K),Long Moment (emu),Long Offset (cm)
7.000000e+004,3.999935e+002,6.393907e-003,-1.093909e-001
7.000000e+004,3.914677e+002,6.494666e-003,-1.028775e-001
7.000000e+004,3.836974e+002,6.555712e-003,-9.748176e-002
7.000000e+004,3.754426e+002,6.689776e-003,-9.638175e-002
7.000000e+004,3.675662e+002,6.729687e-003,-9.175062e-002
7.000000e+004,3.596864e+002,6.635378e-003,-8.968978e-002
7.000000e+004,3.514894e+002,2.658779e-003,-3.140390e-002
7.000000e+004,3.438458e+002,2.122805e-003,-6.236163e-003
7.000000e+004,3.354696e+002,2.086186e-003,-1.603075e-003
7.000000e+004,3.278010e+002,2.076490e-003,3.876518e-003
7.000000e+004,3.196196e+002,2.072240e-003,6.354782e-003
7.000000e+004,3.117554e+002,2.078832e-003,1.134976e-002
7.000000e+004,3.036783e+002,2.088603e-003,1.327692e-002
7.000000e+004,3.033350e+002,2.079131e-003,1.288613e-002
7.000000e+004,3.112142e+002,2.058524e-003,8.532784e-003
7.000000e+004,3.192184e+002,2.042557e-003,4.872281e-003
7.000000e+004,3.272754e+002,2.040026e-003,-3.538083e-004
7.000000e+004,3.352734e+002,2.037233e-003,-4.820875e-003
7.000000e+004,3.432218e+002,2.043618e-003,-9.824025e-003
7.000000e+004,3.512315e+002,2.063299e-003,-1.486750e-002
7.000000e+004,3.592677e+002,2.097004e-003,-2.147868e-002
7.000000e+004,3.672095e+002,2.187565e-003,-2.976183e-002
7.000000e+004,3.752176e+002,5.328012e-003,-9.135075e-002
7.000000e+004,3.832658e+002,6.471213e-003,-1.052352e-001
7.000000e+004,3.912626e+002,6.444423e-003,-1.071640e-001
7.000000e+004,3.992151e+002,6.392636e-003,-1.095637e-001
6.500000e+004,3.935291e+002,6.031119e-003,-9.971741e-002
6.500000e+004,3.856684e+002,6.092151e-003,-9.412415e-002
6.500000e+004,3.775563e+002,6.220492e-003,-9.350063e-002
6.500000e+004,3.691259e+002,6.282347e-003,-8.859851e-002
6.500000e+004,3.618317e+002,6.265025e-003,-8.452386e-002
6.500000e+004,3.533073e+002,5.728058e-003,-8.061608e-002
6.500000e+004,3.456435e+002,2.016979e-003,-5.947723e-003
6.500000e+004,3.375071e+002,1.960772e-003,-9.882244e-004
6.500000e+004,3.296765e+002,1.947435e-003,4.773541e-003
6.500000e+004,3.216429e+002,1.944050e-003,7.140405e-003
6.500000e+004,3.136894e+002,1.951639e-003,1.137147e-002
6.500000e+004,3.057824e+002,1.953106e-003,1.407234e-002
6.500000e+004,3.012094e+002,1.955225e-003,1.497956e-002
6.500000e+004,3.092201e+002,1.933668e-003,1.049451e-002
6.500000e+004,3.172492e+002,1.918176e-003,6.794249e-003
6.500000e+004,3.252076e+002,1.916160e-003,1.043998e-003
6.500000e+004,3.332303e+002,1.912550e-003,-3.185640e-003
6.500000e+004,3.413689e+002,1.915467e-003,-8.083975e-003
6.500000e+004,3.492449e+002,1.932460e-003,-1.360286e-002
6.500000e+004,3.572720e+002,1.963738e-003,-1.959308e-002
6.500000e+004,3.652389e+002,2.040607e-003,-2.772742e-002
6.500000e+004,3.732659e+002,4.433501e-003,-8.376333e-002
6.500000e+004,3.813996e+002,6.065533e-003,-1.036654e-001
6.500000e+004,3.892809e+002,6.032119e-003,-1.057258e-001
6.500000e+004,3.972885e+002,5.963762e-003,-1.077795e-001
6.000000e+004,3.956068e+002,5.558489e-003,-1.008846e-001
6.000000e+004,3.875816e+002,5.617487e-003,-9.519804e-002
6.000000e+004,3.798029e+002,5.729006e-003,-9.469587e-002
6.000000e+004,3.712076e+002,5.806355e-003,-9.000109e-002
6.000000e+004,3.637533e+002,5.822749e-003,-8.570612e-002
6.000000e+004,3.553607e+002,5.679457e-003,-8.347968e-002
6.000000e+004,3.476597e+002,1.905183e-003,-9.728863e-003
6.000000e+004,3.396132e+002,1.827607e-003,-3.207998e-003
6.000000e+004,3.315661e+002,1.811597e-003,2.678559e-003
6.000000e+004,3.238146e+002,1.805802e-003,5.364207e-003
6.000000e+004,3.155780e+002,1.812470e-003,9.244500e-003
6.000000e+004,3.079163e+002,1.811245e-003,1.346349e-002
6.000000e+004,3.000848e+002,1.822620e-003,1.509677e-002
6.000000e+004,3.072624e+002,1.801105e-003,1.077451e-002
6.000000e+004,3.152782e+002,1.788370e-003,6.730374e-003
6.000000e+004,3.232485e+002,1.784240e-003,1.607663e-003
6.000000e+004,3.312746e+002,1.778671e-003,-3.061876e-003
6.000000e+004,3.391915e+002,1.780351e-003,-7.781944e-003
6.000000e+004,3.472119e+002,1.790577e-003,-1.278279e-002
6.000000e+004,3.552209e+002,1.818932e-003,-1.881894e-002
6.000000e+004,3.632370e+002,1.878803e-003,-2.638547e-002
6.000000e+004,3.712825e+002,2.773966e-003,-6.243003e-002
6.000000e+004,3.792176e+002,5.626445e-003,-1.029381e-001
6.000000e+004,3.872592e+002,5.602943e-003,-1.051283e-001
6.000000e+004,3.952230e+002,5.527902e-003,-1.069034e-001
5.500000e+004,3.978071e+002,5.082835e-003,-1.023552e-001
5.500000e+004,3.895422e+002,5.146453e-003,-9.638274e-002
5.500000e+004,3.817884e+002,5.204993e-003,-9.185873e-002
5.500000e+004,3.733224e+002,5.318876e-003,-9.099590e-002
5.500000e+004,3.655860e+002,5.352088e-003,-8.651960e-002
5.500000e+004,3.574752e+002,5.312704e-003,-8.497357e-002
5.500000e+004,3.495317e+002,1.969079e-003,-2.120048e-002
5.500000e+004,3.417658e+002,1.692056e-003,-4.860448e-003
5.500000e+004,3.336054e+002,1.671111e-003,1.754138e-003
5.500000e+004,3.258994e+002,1.662983e-003,6.401512e-003
5.500000e+004,3.175411e+002,1.666997e-003,8.601317e-003
5.500000e+004,3.098203e+002,1.668377e-003,1.367880e-002
5.500000e+004,3.017015e+002,1.678495e-003,1.531625e-002
5.500000e+004,3.052833e+002,1.664414e-003,1.195050e-002
5.500000e+004,3.132088e+002,1.648534e-003,8.014986e-003
5.500000e+004,3.213246e+002,1.645701e-003,2.775521e-003
5.500000e+004,3.292178e+002,1.640349e-003,-1.593707e-003
5.500000e+004,3.372681e+002,1.639876e-003,-6.414628e-003
5.500000e+004,3.451963e+002,1.648621e-003,-1.122148e-002
5.500000e+004,3.531993e+002,1.670400e-003,-1.725391e-002
5.500000e+004,3.613736e+002,1.718094e-003,-2.431451e-002
5.500000e+004,3.692686e+002,1.982965e-003,-4.273912e-002
5.500000e+004,3.772511e+002,5.169319e-003,-1.011501e-001
5.500000e+004,3.852382e+002,5.164879e-003,-1.037731e-001
5.500000e+004,3.932810e+002,5.091351e-003,-1.053962e-001
5.000000e+004,4.000097e+002,4.595660e-003,-1.028416e-001
5.000000e+004,3.914397e+002,4.673930e-003,-9.688267e-002
5.000000e+004,3.836318e+002,4.722517e-003,-9.160346e-002
5.000000e+004,3.755537e+002,4.825020e-003,-9.104630e-002
5.000000e+004,3.670521e+002,4.872264e-003,-8.628435e-002
5.000000e+004,3.596447e+002,4.875790e-003,-8.516771e-002
5.000000e+004,3.514398e+002,4.006831e-003,-7.502931e-002
5.000000e+004,3.438529e+002,1.560545e-003,-4.335115e-003
5.000000e+004,3.355370e+002,1.527846e-003,5.919570e-004
5.000000e+004,3.277303e+002,1.518778e-003,5.642151e-003
5.000000e+004,3.195283e+002,1.519853e-003,8.159519e-003
5.000000e+004,3.117670e+002,1.746660e-003,-9.520515e-002
5.000000e+004,3.036164e+002,1.526317e-003,1.507534e-002
5.000000e+004,3.033568e+002,1.520768e-003,1.390890e-002
5.000000e+004,3.112697e+002,1.505674e-003,1.012312e-002
5.000000e+004,3.192791e+002,1.503244e-003,4.218726e-003
5.000000e+004,3.272071e+002,1.497612e-003,-7.030651e-005
5.000000e+004,3.352331e+002,1.495622e-003,-4.286663e-003
5.000000e+004,3.432430e+002,1.501638e-003,-9.374345e-003
5.000000e+004,3.512339e+002,1.518673e-003,-1.508769e-002
5.000000e+004,3.592287e+002,1.555040e-003,-2.211418e-002
5.000000e+004,3.672530e+002,1.687445e-003,-3.463913e-002
5.000000e+004,3.753001e+002,4.699688e-003,-9.930824e-002
5.000000e+004,3.832479e+002,4.717827e-003,-1.024255e-001
5.000000e+004,3.912285e+002,4.652280e-003,-1.040968e-001
5.000000e+004,3.992861e+002,4.595528e-003,-1.063379e-001
4.500000e+004,3.935071e+002,4.192254e-003,-9.725808e-002
4.500000e+004,3.855601e+002,4.237769e-003,-9.162039e-002
4.500000e+004,3.775218e+002,4.328644e-003,-9.096558e-002
4.500000e+004,3.694010e+002,4.377774e-003,-8.636530e-002
4.500000e+004,3.618922e+002,4.388259e-003,-8.259189e-002
4.500000e+004,3.533399e+002,4.222393e-003,-7.922007e-002
4.500000e+004,3.457656e+002,1.424073e-003,-5.233848e-003
4.500000e+004,3.374958e+002,1.381673e-003,9.095830e-005
4.500000e+004,3.296764e+002,1.370994e-003,5.761802e-003
4.500000e+004,3.216491e+002,1.370117e-003,8.482231e-003
4.500000e+004,3.137225e+002,1.373692e-003,1.272238e-002
4.500000e+004,3.057013e+002,1.376000e-003,1.583242e-002
4.500000e+004,3.012040e+002,1.377028e-003,1.657679e-002
4.500000e+004,3.092956e+002,1.365579e-003,1.211805e-002
4.500000e+004,3.172193e+002,1.356211e-003,7.693356e-003
4.500000e+004,3.252350e+002,1.352758e-003,2.727421e-003
4.500000e+004,3.332524e+002,1.350489e-003,-2.064992e-003
4.500000e+004,3.414460e+002,1.354121e-003,-6.550901e-003
4.500000e+004,3.492450e+002,1.366389e-003,-1.197640e-002
4.500000e+004,3.572284e+002,1.393845e-003,-1.839260e-002
4.500000e+004,3.652415e+002,1.474188e-003,-2.840883e-002
4.500000e+004,3.732406e+002,4.204244e-003,-9.607362e-002
4.500000e+004,3.815203e+002,4.258095e-003,-9.987435e-002
4.500000e+004,3.892226e+002,4.205371e-003,-1.016599e-001
4.500000e+004,3.972726e+002,4.147139e-003,-1.036256e-001
4.000000e+004,3.955909e+002,3.711237e-003,-9.670521e-002
4.000000e+004,3.876120e+002,3.754395e-003,-9.087902e-002
4.000000e+004,3.797941e+002,3.827533e-003,-9.007896e-002
4.000000e+004,3.703836e+002,3.885974e-003,-8.478490e-002
4.000000e+004,3.637240e+002,3.902902e-003,-8.098418e-002
4.000000e+004,3.555638e+002,3.854579e-003,-7.922873e-002
4.000000e+004,3.476888e+002,1.287288e-003,-6.206079e-003
4.000000e+004,3.396040e+002,1.233414e-003,4.480587e-004
4.000000e+004,3.316363e+002,1.221999e-003,6.457340e-003
4.000000e+004,3.237979e+002,1.218042e-003,9.115765e-003
4.000000e+004,3.156550e+002,1.220587e-003,1.368811e-002
4.000000e+004,3.079106e+002,1.224319e-003,1.687746e-002
4.000000e+004,3.000742e+002,1.230167e-003,1.918089e-002
4.000000e+004,3.073015e+002,1.215800e-003,1.512267e-002
4.000000e+004,3.151935e+002,1.209232e-003,1.031362e-002
4.000000e+004,3.232505e+002,1.204858e-003,5.638687e-003
4.000000e+004,3.312002e+002,1.202245e-003,9.061032e-004
4.000000e+004,3.392697e+002,1.204536e-003,-3.705584e-003
4.000000e+004,3.472578e+002,1.213324e-003,-9.020126e-003
4.000000e+004,3.552539e+002,1.233706e-003,-1.519054e-002
4.000000e+004,3.632210e+002,1.286124e-003,-2.391726e-002
4.000000e+004,3.712352e+002,3.200007e-003,-8.688839e-002
4.000000e+004,3.792001e+002,3.791684e-003,-9.733766e-002
4.000000e+004,3.872744e+002,3.752026e-003,-9.952077e-002
4.000000e+004,3.952515e+002,3.695797e-003,-1.013335e-001
3.500000e+004,3.978167e+002,3.233861e-003,-9.674150e-002
3.500000e+004,3.894562e+002,3.275987e-003,-9.041655e-002
3.500000e+004,3.817531e+002,3.317253e-003,-8.588663e-002
3.500000e+004,3.734069e+002,3.387304e-003,-8.486387e-002
3.500000e+004,3.655887e+002,3.413510e-003,-8.026930e-002
3.500000e+004,3.575985e+002,3.406772e-003,-7.904406e-002
3.500000e+004,3.496101e+002,1.718212e-003,-3.979489e-002
3.500000e+004,3.417939e+002,1.086079e-003,4.241987e-004
3.500000e+004,3.335655e+002,1.073020e-003,7.041548e-003
3.500000e+004,3.258867e+002,1.067417e-003,1.172905e-002
3.500000e+004,3.176611e+002,1.072027e-003,1.482490e-002
3.500000e+004,3.098506e+002,1.076118e-003,1.890824e-002
3.500000e+004,3.015922e+002,1.081625e-003,2.125163e-002
3.500000e+004,3.052539e+002,1.071829e-003,1.843880e-002
3.500000e+004,3.131971e+002,1.063627e-003,1.447960e-002
3.500000e+004,3.213717e+002,1.059511e-003,1.002680e-002
3.500000e+004,3.292826e+002,1.057122e-003,4.927036e-003
3.500000e+004,3.372272e+002,1.057498e-003,5.921068e-004
3.500000e+004,3.452537e+002,1.063520e-003,-4.305702e-003
3.500000e+004,3.532845e+002,1.079144e-003,-1.039375e-002
3.500000e+004,3.614499e+002,1.116104e-003,-1.826556e-002
3.500000e+004,3.692081e+002,1.425296e-003,-4.528660e-002
3.500000e+004,3.772223e+002,3.326253e-003,-9.263255e-002
3.500000e+004,3.852893e+002,3.302442e-003,-9.529817e-002
3.500000e+004,3.931869e+002,3.251369e-003,-9.693763e-002
3.000000e+004,4.000065e+002,2.762130e-003,-9.467191e-002
3.000000e+004,3.915826e+002,2.807364e-003,-8.844565e-002
3.000000e+004,3.836825e+002,2.840584e-003,-8.307131e-002
3.000000e+004,3.753686e+002,2.899965e-003,-8.208332e-002
3.000000e+004,3.675334e+002,2.929884e-003,-7.759333e-002
3.000000e+004,3.596369e+002,2.936345e-003,-7.648960e-002
3.000000e+004,3.515539e+002,2.629635e-003,-6.958851e-002
3.000000e+004,3.438244e+002,9.456066e-004,3.338781e-003
3.000000e+004,3.354629e+002,9.256090e-004,8.266343e-003
3.000000e+004,3.277133e+002,9.203454e-004,1.389695e-002
3.000000e+004,3.196034e+002,9.220417e-004,1.673638e-002
3.000000e+004,3.117362e+002,9.250776e-004,2.129725e-002
3.000000e+004,3.037055e+002,9.285288e-004,2.541688e-002
3.000000e+004,3.032842e+002,9.262412e-004,2.404469e-002
3.000000e+004,3.112295e+002,9.162799e-004,2.093428e-002
3.000000e+004,3.192022e+002,9.126771e-004,1.552832e-002
3.000000e+004,3.272199e+002,9.107617e-004,1.062177e-002
3.000000e+004,3.352105e+002,9.102593e-004,5.618353e-003
3.000000e+004,3.432124e+002,9.136865e-004,1.043132e-003
3.000000e+004,3.512241e+002,9.256876e-004,-4.578186e-003
3.000000e+004,3.592806e+002,9.504741e-004,-1.181273e-002
3.000000e+004,3.671769e+002,1.051918e-003,-2.599929e-002
3.000000e+004,3.752205e+002,2.853157e-003,-8.641055e-002
3.000000e+004,3.832361e+002,2.847250e-003,-8.932643e-002
3.000000e+004,3.912719e+002,2.803373e-003,-9.119371e-002
3.000000e+004,3.992667e+002,2.766929e-003,-9.368265e-002
2.500000e+004,3.935354e+002,2.337245e-003,-8.488606e-002
2.500000e+004,3.856323e+002,2.364484e-003,-7.920256e-002
2.500000e+004,3.776197e+002,2.413413e-003,-7.810533e-002
2.500000e+004,3.693239e+002,2.444168e-003,-7.322408e-002
2.500000e+004,3.618896e+002,2.451544e-003,-6.958085e-002
2.500000e+004,3.534402e+002,2.384816e-003,-6.662939e-002
2.500000e+004,3.457488e+002,8.029443e-004,7.769190e-003
2.500000e+004,3.375004e+002,7.794671e-004,1.500513e-002
2.500000e+004,3.296959e+002,7.740836e-004,1.999046e-002
2.500000e+004,3.217190e+002,7.731793e-004,2.234192e-002
2.500000e+004,3.137614e+002,7.759291e-004,2.654382e-002
2.500000e+004,3.057050e+002,7.765860e-004,2.961161e-002
2.500000e+004,3.012022e+002,7.790635e-004,3.031083e-002
2.500000e+004,3.092692e+002,7.714264e-004,2.655035e-002
2.500000e+004,3.172791e+002,7.660812e-004,2.172213e-002
2.500000e+004,3.252139e+002,7.643835e-004,1.706625e-002
2.500000e+004,3.333322e+002,7.635679e-004,1.231675e-002
2.500000e+004,3.413922e+002,7.658743e-004,7.387860e-003
2.500000e+004,3.492523e+002,7.736988e-004,2.072960e-003
2.500000e+004,3.572438e+002,7.903638e-004,-4.056956e-003
2.500000e+004,3.652066e+002,8.414941e-004,-1.446998e-002
2.500000e+004,3.732322e+002,2.378031e-003,-7.774903e-002
2.500000e+004,3.813966e+002,2.386952e-003,-8.132421e-002
2.500000e+004,3.892841e+002,2.353640e-003,-8.331371e-002
2.500000e+004,3.971799e+002,2.319182e-003,-8.541852e-002
2.000000e+004,3.955401e+002,1.869493e-003,-7.860869e-002
2.000000e+004,3.875177e+002,1.892744e-003,-7.274511e-002
2.000000e+004,3.798058e+002,1.929640e-003,-7.150789e-002
2.000000e+004,3.712132e+002,1.959334e-003,-6.670640e-002
2.000000e+004,3.636601e+002,1.971292e-003,-6.245832e-002
2.000000e+004,3.554166e+002,1.951585e-003,-6.078803e-002
2.000000e+004,3.476331e+002,6.579999e-004,9.802969e-003
2.000000e+004,3.396848e+002,6.306292e-004,1.657810e-002
2.000000e+004,3.316187e+002,6.250860e-004,2.194836e-002
2.000000e+004,3.238542e+002,6.231583e-004,2.522316e-002
2.000000e+004,3.156096e+002,6.250923e-004,2.952319e-002
2.000000e+004,3.078901e+002,6.268036e-004,3.351532e-002
2.000000e+004,3.000849e+002,6.299682e-004,3.544050e-002
2.000000e+004,3.072494e+002,6.232541e-004,3.116502e-002
2.000000e+004,3.152231e+002,6.190373e-004,2.642529e-002
2.000000e+004,3.232298e+002,6.175232e-004,2.179240e-002
2.000000e+004,3.312133e+002,6.161352e-004,1.655272e-002
2.000000e+004,3.392306e+002,6.171920e-004,1.207361e-002
2.000000e+004,3.472578e+002,6.218600e-004,6.681962e-003
2.000000e+004,3.552361e+002,6.332493e-004,6.768800e-004
2.000000e+004,3.632503e+002,6.621053e-004,-7.645337e-003
2.000000e+004,3.712269e+002,1.853211e-003,-7.149138e-002
2.000000e+004,3.792756e+002,1.920736e-003,-7.609233e-002
2.000000e+004,3.872501e+002,1.897710e-003,-7.851011e-002
2.000000e+004,3.952230e+002,1.866806e-003,-8.033383e-002
1.500000e+004,3.978071e+002,1.402078e-003,-7.638788e-002
1.500000e+004,3.895975e+002,1.421213e-003,-6.986164e-002
1.500000e+004,3.817618e+002,1.440466e-003,-6.518703e-002
1.500000e+004,3.734238e+002,1.471146e-003,-6.369191e-002
1.500000e+004,3.656076e+002,1.484181e-003,-5.922550e-002
1.500000e+004,3.576139e+002,1.482862e-003,-5.809213e-002
1.500000e+004,3.495390e+002,8.349733e-004,-2.582863e-002
1.500000e+004,3.418243e+002,4.798501e-004,1.553448e-002
1.500000e+004,3.335832e+002,4.741918e-004,2.159293e-002
1.500000e+004,3.258655e+002,4.719594e-004,2.680342e-002
1.500000e+004,3.176011e+002,4.731361e-004,2.844079e-002
1.500000e+004,3.097710e+002,4.742036e-004,3.347284e-002
1.500000e+004,3.016334e+002,4.775107e-004,3.465514e-002
1.500000e+004,3.052797e+002,4.735628e-004,3.166502e-002
1.500000e+004,3.132107e+002,4.692222e-004,2.793387e-002
1.500000e+004,3.213799e+002,4.678988e-004,2.270442e-002
1.500000e+004,3.292329e+002,4.668234e-004,1.799560e-002
1.500000e+004,3.372227e+002,4.669036e-004,1.376685e-002
1.500000e+004,3.452059e+002,4.697226e-004,8.349048e-003
1.500000e+004,3.532219e+002,4.767377e-004,2.436623e-003
1.500000e+004,3.614210e+002,4.939180e-004,-5.368493e-003
1.500000e+004,3.692467e+002,7.452179e-004,-4.425856e-002
1.500000e+004,3.772310e+002,1.446352e-003,-7.384498e-002
1.500000e+004,3.852502e+002,1.433063e-003,-7.639636e-002
1.500000e+004,3.932496e+002,1.409020e-003,-7.835886e-002
1.000000e+004,4.000065e+002,9.341145e-004,-7.629885e-002
1.000000e+004,3.915080e+002,9.500160e-004,-7.011600e-002
1.000000e+004,3.836944e+002,9.615220e-004,-6.478286e-002
1.000000e+004,3.754483e+002,9.822985e-004,-6.383929e-002
1.000000e+004,3.673838e+002,9.929845e-004,-5.879858e-002
1.000000e+004,3.597254e+002,9.967536e-004,-5.786879e-002
1.000000e+004,3.514522e+002,9.092655e-004,-5.125704e-002
1.000000e+004,3.438315e+002,3.288741e-004,1.408764e-002
1.000000e+004,3.355416e+002,3.223156e-004,1.900831e-002
1.000000e+004,3.277089e+002,3.206213e-004,2.422769e-002
1.000000e+004,3.195789e+002,3.208422e-004,2.645451e-002
1.000000e+004,3.116689e+002,3.219002e-004,3.145479e-002
1.000000e+004,3.037200e+002,3.231778e-004,3.276145e-002
1.000000e+004,3.032407e+002,3.222246e-004,3.208312e-002
1.000000e+004,3.111854e+002,3.193093e-004,2.802678e-002
1.000000e+004,3.192508e+002,3.179233e-004,2.347677e-002
1.000000e+004,3.272818e+002,3.171880e-004,1.845519e-002
1.000000e+004,3.352218e+002,3.168807e-004,1.308301e-002
1.000000e+004,3.432313e+002,3.181924e-004,8.816030e-003
1.000000e+004,3.512463e+002,3.220771e-004,2.707135e-003
1.000000e+004,3.592287e+002,3.307816e-004,-4.381278e-003
1.000000e+004,3.672286e+002,3.710616e-004,-1.876536e-002
1.000000e+004,3.752432e+002,9.689416e-004,-7.128837e-002
1.000000e+004,3.832361e+002,9.733407e-004,-7.287627e-002
1.000000e+004,3.912160e+002,9.485291e-004,-7.601546e-002
1.000000e+004,3.992506e+002,9.347757e-004,-7.851042e-002
9.000000e+003,3.934193e+002,8.533841e-004,-6.966716e-002
9.000000e+003,3.855571e+002,8.641039e-004,-6.418081e-002
9.000000e+003,3.776169e+002,8.826779e-004,-6.304576e-002
9.000000e+003,3.685414e+002,8.950544e-004,-5.753651e-002
9.000000e+003,3.618633e+002,8.980482e-004,-5.421402e-002
9.000000e+003,3.534378e+002,8.779733e-004,-5.141413e-002
9.000000e+003,3.457345e+002,3.009812e-004,1.296976e-002
9.000000e+003,3.375163e+002,2.926836e-004,1.781542e-002
9.000000e+003,3.295941e+002,2.905065e-004,2.285180e-002
9.000000e+003,3.213226e+002,2.901952e-004,2.541438e-002
9.000000e+003,3.135959e+002,2.910983e-004,2.995713e-002
9.000000e+003,3.057898e+002,2.919862e-004,3.232213e-002
9.000000e+003,3.012112e+002,2.926511e-004,3.334019e-002
9.000000e+003,3.092673e+002,2.896708e-004,2.951877e-002
9.000000e+003,3.172053e+002,2.880316e-004,2.425607e-002
9.000000e+003,3.252455e+002,2.873147e-004,1.885204e-002
9.000000e+003,3.332768e+002,2.869403e-004,1.518944e-002
9.000000e+003,3.413899e+002,2.879055e-004,9.594465e-003
9.000000e+003,3.492205e+002,2.904340e-004,4.995486e-003
9.000000e+003,3.572027e+002,2.967648e-004,-1.090498e-003
9.000000e+003,3.652146e+002,3.170826e-004,-1.215524e-002
9.000000e+003,3.732237e+002,8.714269e-004,-6.931335e-002
9.000000e+003,3.814054e+002,8.719361e-004,-7.260894e-002
9.000000e+003,3.892840e+002,8.588576e-004,-7.444289e-002
9.000000e+003,3.971959e+002,8.450899e-004,-7.666179e-002
8.000000e+003,3.956703e+002,7.571805e-004,-7.022171e-002
8.000000e+003,3.875481e+002,7.671493e-004,-6.432778e-002
8.000000e+003,3.798145e+002,7.828115e-004,-6.325470e-002
8.000000e+003,3.711047e+002,7.951795e-004,-5.816998e-002
8.000000e+003,3.637453e+002,8.001772e-004,-5.409879e-002
8.000000e+003,3.555232e+002,7.946587e-004,-5.235755e-002
8.000000e+003,3.476428e+002,2.738248e-004,9.652838e-003
8.000000e+003,3.395948e+002,2.627599e-004,1.549047e-002
8.000000e+003,3.315157e+002,2.602084e-004,2.085069e-002
8.000000e+003,3.237375e+002,2.596514e-004,2.412105e-002
8.000000e+003,3.154774e+002,2.606237e-004,2.853758e-002
8.000000e+003,3.078938e+002,2.607293e-004,3.177430e-002
8.000000e+003,3.000636e+002,2.626177e-004,3.388924e-002
8.000000e+003,3.072568e+002,2.600594e-004,2.938122e-002
8.000000e+003,3.152349e+002,2.582408e-004,2.523487e-002
8.000000e+003,3.232672e+002,2.573684e-004,1.961630e-002
8.000000e+003,3.312527e+002,2.568659e-004,1.520823e-002
8.000000e+003,3.392168e+002,2.571916e-004,1.056642e-002
8.000000e+003,3.472650e+002,2.592569e-004,6.123933e-003
8.000000e+003,3.552438e+002,2.636694e-004,-2.818695e-004
8.000000e+003,3.633008e+002,2.764632e-004,-8.998959e-003
8.000000e+003,3.712074e+002,7.680951e-004,-6.768510e-002
8.000000e+003,3.793048e+002,7.785964e-004,-7.170072e-002
8.000000e+003,3.872714e+002,7.686228e-004,-7.384139e-002
8.000000e+003,3.952357e+002,7.553304e-004,-7.571964e-002
7.000000e+003,3.978488e+002,6.626262e-004,-7.172196e-002
7.000000e+003,3.895576e+002,6.722222e-004,-6.549298e-002
7.000000e+003,3.817825e+002,6.816078e-004,-6.057161e-002
7.000000e+003,3.733140e+002,6.965002e-004,-5.897989e-002
7.000000e+003,3.656049e+002,7.026036e-004,-5.478790e-002
7.000000e+003,3.575342e+002,7.036116e-004,-5.360696e-002
7.000000e+003,3.495414e+002,4.256442e-004,-2.651318e-002
7.000000e+003,3.418009e+002,2.333952e-004,1.325471e-002
7.000000e+003,3.335143e+002,2.307363e-004,1.994045e-002
7.000000e+003,3.258846e+002,2.296873e-004,2.436714e-002
7.000000e+003,3.176151e+002,2.301566e-004,2.706603e-002
7.000000e+003,3.097918e+002,2.306940e-004,3.074508e-002
7.000000e+003,3.015529e+002,2.324727e-004,3.271166e-002
7.000000e+003,3.052962e+002,2.304166e-004,2.973143e-002
7.000000e+003,3.132690e+002,2.285005e-004,2.572941e-002
7.000000e+003,3.213594e+002,2.278661e-004,2.098062e-002
7.000000e+003,3.292459e+002,2.272664e-004,1.583993e-002
7.000000e+003,3.372522e+002,2.275060e-004,1.124069e-002
7.000000e+003,3.452561e+002,2.286446e-004,7.110415e-003
7.000000e+003,3.531917e+002,2.320239e-004,1.025521e-003
7.000000e+003,3.614104e+002,2.404631e-004,-6.529732e-003
7.000000e+003,3.693458e+002,4.321118e-004,-5.300999e-002
7.000000e+003,3.772395e+002,6.853602e-004,-6.960888e-002
7.000000e+003,3.852472e+002,6.785715e-004,-7.224321e-002
7.000000e+003,3.932214e+002,6.666764e-004,-7.369939e-002
6.000000e+003,4.000194e+002,5.667973e-004,-7.222602e-002
6.000000e+003,3.914708e+002,5.766049e-004,-6.598963e-002
6.000000e+003,3.836914e+002,5.839796e-004,-6.030817e-002
6.000000e+003,3.754654e+002,5.971150e-004,-5.911727e-002
6.000000e+003,3.675307e+002,6.036740e-004,-5.468534e-002
6.000000e+003,3.597671e+002,6.063793e-004,-5.380012e-002
6.000000e+003,3.514323e+002,5.595462e-004,-4.717379e-002
6.000000e+003,3.438505e+002,2.041777e-004,1.379664e-002
6.000000e+003,3.356022e+002,2.003513e-004,1.777960e-002
6.000000e+003,3.277560e+002,1.992884e-004,2.275732e-002
6.000000e+003,3.196662e+002,1.996633e-004,2.463332e-002
6.000000e+003,3.116940e+002,2.000094e-004,2.903640e-002
6.000000e+003,3.036765e+002,2.009814e-004,3.144097e-002
6.000000e+003,3.032679e+002,2.004313e-004,2.998243e-002
6.000000e+003,3.112793e+002,1.986080e-004,2.629946e-002
6.000000e+003,3.192184e+002,1.978491e-004,2.059717e-002
6.000000e+003,3.272796e+002,1.972185e-004,1.662341e-002
6.000000e+003,3.352510e+002,1.970665e-004,1.204589e-002
6.000000e+003,3.432313e+002,1.977432e-004,7.430906e-003
6.000000e+003,3.513108e+002,2.001773e-004,1.415025e-003
6.000000e+003,3.592469e+002,2.055204e-004,-4.818092e-003
6.000000e+003,3.672449e+002,2.323366e-004,-1.997131e-002
6.000000e+003,3.752233e+002,5.898030e-004,-6.795631e-002
6.000000e+003,3.832747e+002,5.859003e-004,-7.100326e-002
6.000000e+003,3.912844e+002,5.758893e-004,-7.289134e-002
6.000000e+003,3.992086e+002,5.673746e-004,-7.510355e-002
5.000000e+003,3.935511e+002,4.807638e-004,-6.702942e-002
5.000000e+003,3.856414e+002,4.869972e-004,-6.110062e-002
5.000000e+003,3.775737e+002,4.978802e-004,-5.999250e-002
5.000000e+003,3.693046e+002,5.042282e-004,-5.495361e-002
5.000000e+003,3.618791e+002,5.065006e-004,-5.136168e-002
5.000000e+003,3.534352e+002,4.974776e-004,-4.864967e-002
5.000000e+003,3.457393e+002,1.742426e-004,1.064387e-002
5.000000e+003,3.374822e+002,1.696951e-004,1.485086e-002
5.000000e+003,3.296699e+002,1.685929e-004,2.027692e-002
5.000000e+003,3.216039e+002,1.685173e-004,2.327996e-002
5.000000e+003,3.136932e+002,1.692519e-004,2.658376e-002
5.000000e+003,3.057899e+002,1.697707e-004,2.904141e-002
5.000000e+003,3.012022e+002,1.700116e-004,2.963212e-002
5.000000e+003,3.092427e+002,1.683309e-004,2.569608e-002
5.000000e+003,3.171973e+002,1.672654e-004,2.145879e-002
5.000000e+003,3.252750e+002,1.669734e-004,1.586202e-002
5.000000e+003,3.332369e+002,1.666540e-004,1.206556e-002
5.000000e+003,3.414436e+002,1.670651e-004,6.577410e-003
5.000000e+003,3.492499e+002,1.686256e-004,1.699435e-003
5.000000e+003,3.572207e+002,1.721989e-004,-4.332879e-003
5.000000e+003,3.652657e+002,1.844469e-004,-1.475466e-002
5.000000e+003,3.732772e+002,4.927680e-004,-6.681146e-002
5.000000e+003,3.815026e+002,4.918766e-004,-6.991075e-002
5.000000e+003,3.892287e+002,4.843548e-004,-7.197908e-002
5.000000e+003,3.972151e+002,4.763874e-004,-7.400680e-002
4.000000e+003,3.955085e+002,3.856411e-004,-6.793115e-002
4.000000e+003,3.875877e+002,3.907894e-004,-6.212319e-002
4.000000e+003,3.797824e+002,3.989327e-004,-6.095545e-002
4.000000e+003,3.705470e+002,4.054358e-004,-5.545443e-002
4.000000e+003,3.637426e+002,4.080052e-004,-5.156681e-002
4.000000e+003,3.554140e+002,4.059271e-004,-4.997734e-002
4.000000e+003,3.476984e+002,1.453755e-004,5.203789e-003
4.000000e+003,3.395325e+002,1.389967e-004,1.144096e-002
4.000000e+003,3.315376e+002,1.378168e-004,1.699568e-002
4.000000e+003,3.238104e+002,1.375584e-004,1.908598e-002
4.000000e+003,3.155859e+002,1.380374e-004,2.302429e-002
4.000000e+003,3.078264e+002,1.381526e-004,2.654970e-002
4.000000e+003,3.000796e+002,1.390092e-004,2.843981e-002
4.000000e+003,3.072829e+002,1.375443e-004,2.402500e-002
4.000000e+003,3.152545e+002,1.368515e-004,1.907416e-002
4.000000e+003,3.232464e+002,1.363983e-004,1.426811e-002
4.000000e+003,3.312265e+002,1.360484e-004,1.027551e-002
4.000000e+003,3.392606e+002,1.362872e-004,5.421451e-003
4.000000e+003,3.472626e+002,1.371996e-004,6.743745e-004
4.000000e+003,3.552563e+002,1.396049e-004,-5.337537e-003
4.000000e+003,3.632424e+002,1.460036e-004,-1.313019e-002
4.000000e+003,3.712491e+002,3.940449e-004,-6.576441e-002
4.000000e+003,3.792932e+002,3.970522e-004,-6.934041e-002
4.000000e+003,3.872501e+002,3.916136e-004,-7.160483e-002
4.000000e+003,3.952547e+002,3.846689e-004,-7.330843e-002
3.000000e+003,3.977975e+002,2.905984e-004,-7.002362e-002
3.000000e+003,3.895331e+002,2.948857e-004,-6.385414e-002
3.000000e+003,3.817737e+002,2.992433e-004,-5.901710e-002
3.000000e+003,3.733956e+002,3.057935e-004,-5.728112e-002
3.000000e+003,3.655725e+002,3.085856e-004,-5.276530e-002
3.000000e+003,3.575111e+002,3.093592e-004,-5.161384e-002
3.000000e+003,3.494484e+002,1.938498e-004,-2.892699e-002
3.000000e+003,3.417542e+002,1.077755e-004,6.473702e-003
3.000000e+003,3.335076e+002,1.066367e-004,1.150849e-002
3.000000e+003,3.258930e+002,1.062700e-004,1.618005e-002
3.000000e+003,3.175630e+002,1.065586e-004,1.831440e-002
3.000000e+003,3.098468e+002,1.067889e-004,2.247677e-002
3.000000e+003,3.015887e+002,1.073656e-004,2.526759e-002
3.000000e+003,3.052484e+002,1.065577e-004,2.186443e-002
3.000000e+003,3.132107e+002,1.057854e-004,1.725295e-002
3.000000e+003,3.214251e+002,1.055092e-004,1.176612e-002
3.000000e+003,3.292869e+002,1.052467e-004,7.164674e-003
3.000000e+003,3.372249e+002,1.053323e-004,3.123229e-003
3.000000e+003,3.452274e+002,1.057488e-004,-1.846571e-003
3.000000e+003,3.532093e+002,1.072590e-004,-6.917849e-003
3.000000e+003,3.614078e+002,1.109062e-004,-1.395416e-002
3.000000e+003,3.693595e+002,2.107434e-004,-5.826182e-002
3.000000e+003,3.772223e+002,3.010357e-004,-6.849480e-002
3.000000e+003,3.852442e+002,2.978440e-004,-7.122789e-002
3.000000e+003,3.932967e+002,2.925140e-004,-7.297367e-002
2.500000e+003,4.000194e+002,2.426005e-004,-7.161225e-002
2.500000e+003,3.914149e+002,2.467179e-004,-6.524086e-002
2.500000e+003,3.836348e+002,2.499875e-004,-5.993992e-002
2.500000e+003,3.754854e+002,2.555065e-004,-5.861410e-002
2.500000e+003,3.665097e+002,2.587125e-004,-5.327363e-002
2.500000e+003,3.596734e+002,2.597786e-004,-5.303895e-002
2.500000e+003,3.514027e+002,2.413810e-004,-4.659991e-002
2.500000e+003,3.438576e+002,9.249119e-005,4.003750e-003
2.500000e+003,3.354022e+002,9.087717e-005,7.925625e-003
2.500000e+003,3.277410e+002,9.051176e-005,1.256046e-002
2.500000e+003,3.195628e+002,9.066274e-005,1.437374e-002
2.500000e+003,3.117420e+002,9.096366e-005,1.821241e-002
2.500000e+003,3.036982e+002,9.127219e-005,2.130080e-002
2.500000e+003,3.033840e+002,9.102890e-005,1.981455e-002
2.500000e+003,3.112276e+002,9.030408e-005,1.491917e-002
2.500000e+003,3.192184e+002,8.999746e-005,1.023595e-002
2.500000e+003,3.272242e+002,8.976094e-005,5.359111e-003
2.500000e+003,3.352824e+002,8.959473e-005,8.522437e-004
2.500000e+003,3.432384e+002,8.995860e-005,-3.292065e-003
2.500000e+003,3.512686e+002,9.092255e-005,-8.453541e-003
2.500000e+003,3.592728e+002,9.319843e-005,-1.507867e-002
2.500000e+003,3.672531e+002,1.053595e-004,-2.833301e-002
2.500000e+003,3.752460e+002,2.528140e-004,-6.798245e-002
2.500000e+003,3.832539e+002,2.509728e-004,-7.104479e-002
2.500000e+003,3.912657e+002,2.466626e-004,-7.288923e-002
2.500000e+003,3.992344e+002,2.428943e-004,-7.509798e-002
2.000000e+003,3.934538e+002,1.986361e-004,-6.703167e-002
2.000000e+003,3.855992e+002,2.011678e-004,-6.151491e-002
2.000000e+003,3.774930e+002,2.055640e-004,-6.041231e-002
2.000000e+003,3.689062e+002,2.083986e-004,-5.506440e-002
2.000000e+003,3.618896e+002,2.093011e-004,-5.175206e-002
2.000000e+003,3.530818e+002,2.054525e-004,-4.880099e-002
2.000000e+003,3.457249e+002,7.674519e-005,-3.302030e-004
2.000000e+003,3.375231e+002,7.499256e-005,2.846554e-003
2.000000e+003,3.296353e+002,7.453369e-005,7.610054e-003
2.000000e+003,3.215566e+002,7.455813e-005,1.025308e-002
2.000000e+003,3.136407e+002,7.490353e-005,1.360786e-002
2.000000e+003,3.057364e+002,7.510300e-005,1.617836e-002
2.000000e+003,3.011843e+002,7.514928e-005,1.704157e-002
2.000000e+003,3.093372e+002,7.448941e-005,1.243719e-002
2.000000e+003,3.172751e+002,7.412433e-005,7.906172e-003
2.000000e+003,3.252918e+002,7.399594e-005,2.830870e-003
2.000000e+003,3.332303e+002,7.383891e-005,-1.025014e-003
2.000000e+003,3.414342e+002,7.400056e-005,-5.356045e-003
2.000000e+003,3.492523e+002,7.461914e-005,-1.100826e-002
2.000000e+003,3.572387e+002,7.600062e-005,-1.622893e-002
2.000000e+003,3.652711e+002,8.099823e-005,-2.523305e-002
2.000000e+003,3.732434e+002,2.039678e-004,-6.748762e-002
2.000000e+003,3.813937e+002,2.034452e-004,-7.094846e-002
2.000000e+003,3.892471e+002,2.002190e-004,-7.293448e-002
2.000000e+003,3.972502e+002,1.969771e-004,-7.505467e-002
1.500000e+003,3.955909e+002,1.504391e-004,-6.950729e-002
1.500000e+003,3.874417e+002,1.525667e-004,-6.354414e-002
1.500000e+003,3.797708e+002,1.556341e-004,-6.254497e-002
1.500000e+003,3.708687e+002,1.580396e-004,-5.739385e-002
1.500000e+003,3.637267e+002,1.590811e-004,-5.334285e-002
1.500000e+003,3.553657e+002,1.586289e-004,-5.155011e-002
1.500000e+003,3.475725e+002,6.102640e-005,-8.217001e-003
1.500000e+003,3.395740e+002,5.876350e-005,-3.519987e-003
1.500000e+003,3.315332e+002,5.830829e-005,1.366287e-003
1.500000e+003,3.238250e+002,5.828918e-005,3.759145e-003
1.500000e+003,3.155997e+002,5.845668e-005,7.873073e-003
1.500000e+003,3.078807e+002,5.860920e-005,1.075847e-002
1.500000e+003,3.000831e+002,5.891225e-005,1.400107e-002
1.500000e+003,3.072736e+002,5.827582e-005,9.215558e-003
1.500000e+003,3.152545e+002,5.813409e-005,2.829205e-003
1.500000e+003,3.232505e+002,5.778606e-005,-1.054681e-003
1.500000e+003,3.312790e+002,5.771338e-005,-4.103323e-003
1.500000e+003,3.392191e+002,5.772982e-005,-1.001982e-002
1.500000e+003,3.472626e+002,5.812355e-005,-1.519992e-002
1.500000e+003,3.552437e+002,5.901993e-005,-1.918064e-002
1.500000e+003,3.632981e+002,6.144962e-005,-2.660618e-002
1.500000e+003,3.712130e+002,1.542793e-004,-6.743960e-002
1.500000e+003,3.792176e+002,1.551191e-004,-7.090271e-002
1.500000e+003,3.872774e+002,1.529353e-004,-7.352878e-002
1.500000e+003,3.952674e+002,1.503426e-004,-7.487640e-002
1.000000e+003,3.978232e+002,1.021148e-004,-7.354505e-002
1.000000e+003,3.886558e+002,1.036350e-004,-6.609170e-002
1.000000e+003,3.817825e+002,1.049999e-004,-6.224092e-002
1.000000e+003,3.731846e+002,1.072409e-004,-6.052354e-002
1.000000e+003,3.649811e+002,1.082895e-004,-5.576791e-002
1.000000e+003,3.575162e+002,1.085731e-004,-5.501121e-002
1.000000e+003,3.494043e+002,7.199404e-005,-3.714319e-002
1.000000e+003,3.417682e+002,4.183011e-005,-1.337298e-002
1.000000e+003,3.333923e+002,4.147665e-005,-8.296818e-003
1.000000e+003,3.258740e+002,4.137084e-005,-5.100228e-003
1.000000e+003,3.175191e+002,4.154754e-005,-1.531639e-003
1.000000e+003,3.098070e+002,4.162111e-005,2.591502e-003
1.000000e+003,3.016120e+002,4.181723e-005,4.633134e-003
1.000000e+003,3.052558e+002,4.157381e-005,5.048069e-004
1.000000e+003,3.132826e+002,4.124935e-005,-4.184925e-003
1.000000e+003,3.214272e+002,4.108297e-005,-8.102085e-003
1.000000e+003,3.292545e+002,4.108428e-005,-1.288783e-002
1.000000e+003,3.372567e+002,4.100626e-005,-1.709268e-002
1.000000e+003,3.452226e+002,4.121174e-005,-2.129655e-002
1.000000e+003,3.533046e+002,4.166266e-005,-2.582165e-002
1.000000e+003,3.614183e+002,4.285339e-005,-3.231562e-002
1.000000e+003,3.692466e+002,7.631408e-005,-6.560756e-002
1.000000e+003,3.772568e+002,1.058527e-004,-7.234527e-002
1.000000e+003,3.852622e+002,1.046553e-004,-7.485704e-002
1.000000e+003,3.932308e+002,1.028693e-004,-7.669129e-002
9.000000e+002,4.000097e+002,9.184814e-005,-7.534235e-002
9.000000e+002,3.914305e+002,9.346975e-005,-6.923696e-002
9.000000e+002,3.835812e+002,9.461290e-005,-6.320786e-002
9.000000e+002,3.752776e+002,9.672773e-005,-6.210165e-002
9.000000e+002,3.669815e+002,9.786202e-005,-5.736866e-002
9.000000e+002,3.596838e+002,9.837899e-005,-5.628063e-002
9.000000e+002,3.511995e+002,9.107073e-005,-5.063459e-002
9.000000e+002,3.438268e+002,3.854330e-005,-1.471176e-002
9.000000e+002,3.353589e+002,3.803408e-005,-1.055469e-002
9.000000e+002,3.277090e+002,3.787544e-005,-6.515883e-003
9.000000e+002,3.196013e+002,3.792100e-005,-4.413063e-003
9.000000e+002,3.117401e+002,3.807319e-005,6.108833e-005
9.000000e+002,3.036273e+002,3.818695e-005,2.022356e-003
9.000000e+002,3.032843e+002,3.813842e-005,2.963890e-004
9.000000e+002,3.113062e+002,3.780983e-005,-3.902390e-003
9.000000e+002,3.192710e+002,3.769159e-005,-8.698834e-003
9.000000e+002,3.272860e+002,3.765980e-005,-1.391575e-002
9.000000e+002,3.352622e+002,3.752959e-005,-1.845287e-002
9.000000e+002,3.432855e+002,3.764925e-005,-2.205145e-002
9.000000e+002,3.512859e+002,3.798640e-005,-2.691810e-002
9.000000e+002,3.592599e+002,3.883924e-005,-3.279268e-002
9.000000e+002,3.672340e+002,4.339203e-005,-4.189957e-002
9.000000e+002,3.752091e+002,9.589299e-005,-7.170206e-002
9.000000e+002,3.832450e+002,9.510234e-005,-7.439329e-002
9.000000e+002,3.912719e+002,9.350962e-005,-7.641423e-002
9.000000e+002,3.992828e+002,9.213923e-005,-7.868031e-002
8.000000e+002,3.933817e+002,8.346373e-005,-7.080095e-002
8.000000e+002,3.855752e+002,8.437029e-005,-6.479003e-002
8.000000e+002,3.775247e+002,8.623054e-005,-6.392300e-002
8.000000e+002,3.688486e+002,8.736789e-005,-5.870831e-002
8.000000e+002,3.618475e+002,8.777886e-005,-5.486694e-002
8.000000e+002,3.534052e+002,8.665497e-005,-5.293968e-002
8.000000e+002,3.457177e+002,3.523135e-005,-1.893401e-002
8.000000e+002,3.374548e+002,3.455580e-005,-1.480225e-002
8.000000e+002,3.296006e+002,3.434697e-005,-1.000244e-002
8.000000e+002,3.216080e+002,3.437063e-005,-8.900204e-003
8.000000e+002,3.136407e+002,3.452460e-005,-4.533193e-003
8.000000e+002,3.057566e+002,3.458132e-005,-2.350855e-003
8.000000e+002,3.012415e+002,3.459995e-005,-1.504999e-003
8.000000e+002,3.092919e+002,3.435212e-005,-5.706640e-003
8.000000e+002,3.172153e+002,3.423410e-005,-1.144729e-002
8.000000e+002,3.252708e+002,3.414288e-005,-1.631591e-002
8.000000e+002,3.332702e+002,3.402946e-005,-1.875100e-002
8.000000e+002,3.414319e+002,3.406600e-005,-2.356318e-002
8.000000e+002,3.492793e+002,3.433178e-005,-2.883296e-002
8.000000e+002,3.572104e+002,3.486982e-005,-3.394084e-002
8.000000e+002,3.652281e+002,3.688737e-005,-3.992516e-002
8.000000e+002,3.732406e+002,8.573696e-005,-7.095939e-002
8.000000e+002,3.814703e+002,8.536856e-005,-7.427886e-002
8.000000e+002,3.893086e+002,8.408591e-005,-7.633425e-002
8.000000e+002,3.972407e+002,8.269591e-005,-7.801247e-002
7.000000e+002,3.956290e+002,7.311954e-005,-7.241954e-002
7.000000e+002,3.875269e+002,7.411484e-005,-6.639050e-002
7.000000e+002,3.797913e+002,7.562028e-005,-6.545601e-002
7.000000e+002,3.710992e+002,7.679383e-005,-6.034161e-002
7.000000e+002,3.637027e+002,7.731421e-005,-5.646111e-002
7.000000e+002,3.554241e+002,7.722572e-005,-5.468027e-002
7.000000e+002,3.476185e+002,3.218150e-005,-2.358646e-002
7.000000e+002,3.394911e+002,3.096031e-005,-2.040979e-002
7.000000e+002,3.315376e+002,3.072834e-005,-1.418179e-002
7.000000e+002,3.237104e+002,3.076098e-005,-1.184196e-002
7.000000e+002,3.156195e+002,3.082569e-005,-7.774392e-003
7.000000e+002,3.078807e+002,3.094204e-005,-4.302217e-003
7.000000e+002,3.000583e+002,3.101886e-005,-1.709756e-003
7.000000e+002,3.072792e+002,3.076956e-005,-8.452314e-003
7.000000e+002,3.152172e+002,3.058903e-005,-1.175737e-002
7.000000e+002,3.232672e+002,3.057302e-005,-1.809453e-002
7.000000e+002,3.312221e+002,3.045458e-005,-2.166209e-002
7.000000e+002,3.392353e+002,3.046070e-005,-2.668720e-002
7.000000e+002,3.472239e+002,3.059816e-005,-2.929657e-002
7.000000e+002,3.552082e+002,3.101172e-005,-3.470299e-002
7.000000e+002,3.632238e+002,3.212468e-005,-3.974579e-002
7.000000e+002,3.712769e+002,7.527195e-005,-7.032652e-002
7.000000e+002,3.792845e+002,7.548658e-005,-7.383141e-002
7.000000e+002,3.872349e+002,7.444568e-005,-7.570109e-002
7.000000e+002,3.952293e+002,7.318056e-005,-7.824314e-002
6.000000e+002,3.977751e+002,6.291037e-005,-7.582144e-002
6.000000e+002,3.893609e+002,6.389523e-005,-6.891951e-002
6.000000e+002,3.817559e+002,6.474995e-005,-6.416292e-002
6.000000e+002,3.732128e+002,6.621843e-005,-6.216172e-002
6.000000e+002,3.655995e+002,6.676207e-005,-5.816077e-002
6.000000e+002,3.575265e+002,6.705077e-005,-5.656436e-002
6.000000e+002,3.490030e+002,4.023755e-005,-3.888936e-002
6.000000e+002,3.417355e+002,2.727555e-005,-2.306103e-002
6.000000e+002,3.335144e+002,2.706999e-005,-1.902683e-002
6.000000e+002,3.259099e+002,2.702566e-005,-1.524815e-002
6.000000e+002,3.174491e+002,2.711863e-005,-1.368297e-002
6.000000e+002,3.098222e+002,2.711128e-005,-8.320193e-003
6.000000e+002,3.016550e+002,2.726301e-005,-7.621801e-003
6.000000e+002,3.052962e+002,2.707992e-005,-1.059034e-002
6.000000e+002,3.132321e+002,2.698842e-005,-1.555310e-002
6.000000e+002,3.213963e+002,2.688259e-005,-1.943789e-002
6.000000e+002,3.292977e+002,2.683026e-005,-2.489993e-002
6.000000e+002,3.372522e+002,2.676857e-005,-2.847297e-002
6.000000e+002,3.452728e+002,2.687643e-005,-3.394417e-002
6.000000e+002,3.533146e+002,2.711339e-005,-3.627256e-002
6.000000e+002,3.614183e+002,2.787419e-005,-4.222126e-002
6.000000e+002,3.693154e+002,5.079241e-005,-7.045330e-002
6.000000e+002,3.773029e+002,6.535492e-005,-7.420151e-002
6.000000e+002,3.852082e+002,6.468565e-005,-7.697177e-002
6.000000e+002,3.932183e+002,6.353581e-005,-7.881422e-002
5.000000e+002,4.000097e+002,5.273749e-005,-7.851908e-002
5.000000e+002,3.913405e+002,5.358746e-005,-7.112575e-002
5.000000e+002,3.836735e+002,5.431553e-005,-6.600274e-002
5.000000e+002,3.753914e+002,5.551014e-005,-6.452172e-002
5.000000e+002,3.672016e+002,5.609768e-005,-5.960495e-002
5.000000e+002,3.596916e+002,5.651688e-005,-5.881959e-002
5.000000e+002,3.510584e+002,5.239413e-005,-5.248740e-002
5.000000e+002,3.438623e+002,2.355517e-005,-2.683588e-002
5.000000e+002,3.354718e+002,2.327354e-005,-2.385583e-002
5.000000e+002,3.277903e+002,2.316570e-005,-1.969210e-002
5.000000e+002,3.195629e+002,2.330509e-005,-1.650986e-002
5.000000e+002,3.117863e+002,2.332237e-005,-1.336856e-002
5.000000e+002,3.036946e+002,2.337740e-005,-1.151290e-002
5.000000e+002,3.033405e+002,2.332581e-005,-1.176134e-002
5.000000e+002,3.112295e+002,2.322435e-005,-1.765221e-002
5.000000e+002,3.192730e+002,2.309293e-005,-2.215493e-002
5.000000e+002,3.272519e+002,2.306802e-005,-2.560066e-002
5.000000e+002,3.352353e+002,2.301793e-005,-3.011800e-002
5.000000e+002,3.432549e+002,2.305547e-005,-3.602071e-002
5.000000e+002,3.512389e+002,2.320240e-005,-3.955810e-002
5.000000e+002,3.592314e+002,2.370046e-005,-4.417776e-002
5.000000e+002,3.672177e+002,2.634356e-005,-5.291190e-002
5.000000e+002,3.752603e+002,5.508286e-005,-7.407903e-002
5.000000e+002,3.832390e+002,5.464630e-005,-7.682718e-002
5.000000e+002,3.912378e+002,5.370006e-005,-7.952484e-002
5.000000e+002,3.992732e+002,5.298077e-005,-8.133203e-002
4.000000e+002,3.935888e+002,4.322426e-005,-7.439056e-002
4.000000e+002,3.855842e+002,4.376865e-005,-6.805546e-002
4.000000e+002,3.774929e+002,4.472925e-005,-6.641995e-002
4.000000e+002,3.689117e+002,4.531971e-005,-6.098522e-002
4.000000e+002,3.619028e+002,4.555592e-005,-5.822362e-002
4.000000e+002,3.531420e+002,4.500418e-005,-5.598661e-002
4.000000e+002,3.457105e+002,1.970257e-005,-3.150113e-002
4.000000e+002,3.375482e+002,1.932069e-005,-3.004850e-002
4.000000e+002,3.297198e+002,1.924945e-005,-2.754821e-002
4.000000e+002,3.216656e+002,1.932279e-005,-2.429764e-002
4.000000e+002,3.136114e+002,1.934631e-005,-1.976976e-002
4.000000e+002,3.057456e+002,1.938021e-005,-1.618457e-002
4.000000e+002,3.012058e+002,1.941292e-005,-1.626316e-002
4.000000e+002,3.092295e+002,1.925470e-005,-2.181305e-002
4.000000e+002,3.172033e+002,1.919744e-005,-2.597704e-002
4.000000e+002,3.252434e+002,1.910870e-005,-3.014486e-002
4.000000e+002,3.332901e+002,1.909923e-005,-3.483105e-002
4.000000e+002,3.414435e+002,1.913922e-005,-3.891211e-002
4.000000e+002,3.492450e+002,1.923477e-005,-4.424412e-002
4.000000e+002,3.572438e+002,1.954534e-005,-4.957596e-002
4.000000e+002,3.652120e+002,2.046506e-005,-5.332721e-002
4.000000e+002,3.732491e+002,4.454170e-005,-7.431470e-002
4.000000e+002,3.815203e+002,4.437904e-005,-7.808132e-002
4.000000e+002,3.892502e+002,4.366906e-005,-7.945261e-002
4.000000e+002,3.972054e+002,4.301579e-005,-8.210458e-002
3.000000e+002,3.955338e+002,3.273348e-005,-7.833108e-002
3.000000e+002,3.875542e+002,3.314397e-005,-7.273567e-002
3.000000e+002,3.797708e+002,3.381124e-005,-7.054965e-002
3.000000e+002,3.709326e+002,3.437559e-005,-6.490807e-002
3.000000e+002,3.637213e+002,3.456594e-005,-6.170606e-002
3.000000e+002,3.551299e+002,3.457810e-005,-6.037471e-002
3.000000e+002,3.474902e+002,1.564492e-005,-4.024776e-002
3.000000e+002,3.396064e+002,1.520182e-005,-3.965823e-002
3.000000e+002,3.315924e+002,1.514370e-005,-3.161545e-002
3.000000e+002,3.237875e+002,1.515075e-005,-2.923250e-002
3.000000e+002,3.156353e+002,1.519625e-005,-2.699219e-002
3.000000e+002,3.078620e+002,1.523801e-005,-2.430307e-002
3.000000e+002,3.000654e+002,1.529803e-005,-2.060318e-002
3.000000e+002,3.073035e+002,1.520971e-005,-2.754835e-002
3.000000e+002,3.152368e+002,1.510845e-005,-3.344280e-002
3.000000e+002,3.232547e+002,1.505210e-005,-3.776069e-002
3.000000e+002,3.312637e+002,1.501603e-005,-3.974260e-002
3.000000e+002,3.392905e+002,1.501176e-005,-4.454954e-002
3.000000e+002,3.472191e+002,1.508227e-005,-4.928891e-002
3.000000e+002,3.552412e+002,1.518997e-005,-5.218465e-002
3.000000e+002,3.632423e+002,1.574831e-005,-5.736132e-002
3.000000e+002,3.712992e+002,3.375526e-005,-7.643263e-002
3.000000e+002,3.792583e+002,3.380836e-005,-7.868694e-002
3.000000e+002,3.872258e+002,3.332362e-005,-8.092538e-002
3.000000e+002,3.952040e+002,3.282036e-005,-8.337127e-002
2.000000e+002,3.977815e+002,2.204436e-005,-8.206961e-002
2.000000e+002,3.894624e+002,2.238491e-005,-7.661861e-002
2.000000e+002,3.817825e+002,2.273730e-005,-7.200900e-002
2.000000e+002,3.732128e+002,2.319730e-005,-6.818078e-002
2.000000e+002,3.655726e+002,2.342635e-005,-6.683403e-002
2.000000e+002,3.575676e+002,2.350323e-005,-6.459726e-002
2.000000e+002,3.491106e+002,1.588398e-005,-5.465014e-002
2.000000e+002,3.417191e+002,1.091707e-005,-4.951832e-002
2.000000e+002,3.333568e+002,1.079371e-005,-4.306119e-002
2.000000e+002,3.258972e+002,1.082966e-005,-3.885816e-002
2.000000e+002,3.176431e+002,1.085163e-005,-3.690992e-002
2.000000e+002,3.098563e+002,1.087437e-005,-3.480686e-002
2.000000e+002,3.016245e+002,1.087002e-005,-3.084617e-002
2.000000e+002,3.053698e+002,1.084272e-005,-3.828687e-002
2.000000e+002,3.132457e+002,1.078702e-005,-3.990131e-002
2.000000e+002,3.214128e+002,1.078893e-005,-4.541466e-002
2.000000e+002,3.292654e+002,1.070216e-005,-4.568561e-002
2.000000e+002,3.372977e+002,1.070007e-005,-5.453824e-002
2.000000e+002,3.452608e+002,1.072163e-005,-5.659517e-002
2.000000e+002,3.532394e+002,1.077518e-005,-5.805062e-002
2.000000e+002,3.614998e+002,1.104232e-005,-6.237376e-002
2.000000e+002,3.693099e+002,1.895957e-005,-8.084594e-002
2.000000e+002,3.772425e+002,2.298284e-005,-8.162426e-002
2.000000e+002,3.852292e+002,2.267623e-005,-8.427155e-002
2.000000e+002,3.932873e+002,2.237016e-005,-8.595770e-002
1.000000e+002,4.000162e+002,1.115370e-005,-8.917063e-002
1.000000e+002,3.914243e+002,1.135767e-005,-8.161096e-002
1.000000e+002,3.836110e+002,1.157526e-005,-8.065416e-002
1.000000e+002,3.754114e+002,1.181217e-005,-7.984816e-002
1.000000e+002,3.672723e+002,1.191871e-005,-7.225566e-002
1.000000e+002,3.590032e+002,1.202059e-005,-7.479525e-002
1.000000e+002,3.510584e+002,1.130101e-005,-6.794161e-002
1.000000e+002,3.438860e+002,6.163787e-006,-6.611755e-002
1.000000e+002,3.354494e+002,6.122458e-006,-5.909348e-002
1.000000e+002,3.277753e+002,6.127627e-006,-4.950217e-002
1.000000e+002,3.195061e+002,6.166232e-006,-5.667568e-002
1.000000e+002,3.117131e+002,6.152722e-006,-5.736975e-002
1.000000e+002,3.035837e+002,6.163311e-006,-4.744294e-002
1.000000e+002,3.032697e+002,6.154215e-006,-5.489268e-002
1.000000e+002,3.112582e+002,6.143977e-006,-5.527364e-002
1.000000e+002,3.192184e+002,6.109387e-006,-6.028539e-002
1.000000e+002,3.272434e+002,6.110748e-006,-6.439152e-002
1.000000e+002,3.352914e+002,6.063808e-006,-7.030782e-002
1.000000e+002,3.432195e+002,6.066115e-006,-7.137069e-002
1.000000e+002,3.512786e+002,6.099471e-006,-7.527563e-002
1.000000e+002,3.592781e+002,6.175204e-006,-8.005144e-002
1.000000e+002,3.672966e+002,6.732938e-006,-8.477075e-002
1.000000e+002,3.752176e+002,1.175838e-005,-8.920968e-002
1.000000e+002,3.832628e+002,1.161386e-005,-9.032516e-002
1.000000e+002,3.912440e+002,1.146626e-005,-9.413057e-002
1.000000e+002,3.992635e+002,1.132720e-005,-9.727545e-002
0.000000e+000,3.934883e+002,-4.136517e-007,3.800466e-001
0.000000e+000,3.856052e+002,-3.341538e-007,5.579946e-001
0.000000e+000,3.775478e+002,-2.972677e-007,7.314119e-001
0.000000e+000,3.688293e+002,-2.550418e-007,7.293477e-001
0.000000e+000,3.618738e+002,-2.690284e-007,5.650617e-001
0.000000e+000,3.532297e+002,-3.210369e-007,8.294198e-001
0.000000e+000,3.456913e+002,8.175753e-007,-2.438227e-001
0.000000e+000,3.375026e+002,8.145698e-007,-2.783434e-001
0.000000e+000,3.296894e+002,8.209356e-007,-2.456354e-001
0.000000e+000,3.215691e+002,8.180374e-007,-2.348764e-001
0.000000e+000,3.136349e+002,7.930670e-007,-1.591889e-001
0.000000e+000,3.056995e+002,8.494632e-007,-1.990829e-001
0.000000e+000,3.012236e+002,8.325516e-007,-2.593354e-001
0.000000e+000,3.093164e+002,8.127141e-007,-1.796036e-001
0.000000e+000,3.172831e+002,7.512663e-007,-2.350304e-001
0.000000e+000,3.253213e+002,8.194568e-007,-2.573772e-001
0.000000e+000,3.332303e+002,8.217390e-007,-2.175407e-001
0.000000e+000,3.414646e+002,7.657732e-007,-2.258513e-001
0.000000e+000,3.492474e+002,7.811736e-007,-2.221006e-001
0.000000e+000,3.572181e+002,7.275901e-007,-1.880282e-001
0.000000e+000,3.652388e+002,7.287732e-007,-2.226450e-001
0.000000e+000,3.733138e+002,-2.800998e-007,7.145236e-001
0.000000e+000,3.814909e+002,-2.530028e-007,8.554262e-001
0.000000e+000,3.892932e+002,-2.784979e-007,8.372071e-001
0.000000e+000,3.972214e+002,-1.999432e-007,8.119043e-001
0.000000e+000,3.999838e+002,-2.162012e-007,9.704041e-001