File: spin_crossover/dane/Trt_TEOS — kopia/Medium TEOS/FeTrz_Trt_medium_FC_FH.rso.dat
[Header]
TITLE,MPMS RSO Measurement
BYAPP,MPMS Measurement,1.1,Summary
FILEOPENTIME, 1654705912.056000 6/8/2022, 6:31:52 PM

INFO, APPNAME, MPMS MultiVu Application, Revision 1.60,  Build 081

INFO, NAME, AP_FeTrz_trt_medium
INFO, WEIGHT, 5.440
INFO, AREA, 0.000
INFO, LENGTH, 0.000
INFO, SHAPE, 0
INFO, COMMENT, na Cu drutu, w foli Al, medium - 55 nm
INFO, SEQUENCE FILE: FC_FH_300-390.seq


INFO, BACKGROUND DATA FILE:, None


STARTUPAXIS,X,4,LINEAR,AUTO,0.000000,0.000000
STARTUPAXIS,Y1,5,LINEAR,AUTO,0.000000,0.000000


STARTUPGROUP,Longitudinal
FIELDGROUP,Longitudinal,1,2,3,4,5,6,7,8,9,10,11,19,20,21,22,23,35
FIELDGROUP,Transverse,1,2,3,4,12,13,14,15,16,17,18,24,25,26,27,28,35

PLOT_APPEARANCE,ALL,HORZ_GRID_ON,VERT_GRID_ON,MARKERS_AND_LINES

[Data]
Time,Comment,Field (Oe),Temperature (K),Long Moment (emu),Long Scan Std Dev,Long Offset (cm),Long Offset Std Dev,Long Algorithm,Long Reg Fit,Long Reg Factor,Trans Moment (emu),Trans Scan Std Dev,Trans Offset (cm),Trans Offset Std Dev,Trans Algorithm,Trans Reg Fit,Trans Reg Factor,Long Moment [w/o ABS] (emu),Long Scan Std Dev [w/o ABS],Long Offset [w/o ABS] (cm),Long Offset Std Dev [w/o ABS],Long Reg Fit [w/o ABS],Trans Moment [w/o ABS] (emu),Trans Scan Std Dev [w/o ABS],Trans Offset [w/o ABS] (cm),Trans Offset Std Dev [w/o ABS],Trans Reg Fit [w/o ABS],RSO Position (deg),Amplitude (cm),Frequency,Cycles to Average,Scans per Measurement,Delta Temp (K),Error,EC Comp. Running,Using ABS,
1654705912.055,,1.000000e+003,3.000034e+002,4.492341e-005,3.839366e-008,-2.028146e-002,8.758247e-005,3,9.468756e-001,1.825000e+000,,,,,,,,,,,,,,,,,,0,4.000000e+000,1.000000e+000,2,2,2.120972e-002,0,,0,
1654706070.684,,1.000000e+003,3.021485e+002,4.474737e-005,4.759013e-009,-2.146966e-002,6.436298e-004,3,9.459924e-001,1.825000e+000,,,,,,,,,,,,,,,,,,0,4.000000e+000,1.000000e+000,2,2,2.876892e-001,0,,0,
1654706170.563,,1.000000e+003,3.041388e+002,4.464341e-005,1.977434e-008,-2.378275e-002,1.539449e-003,3,9.467633e-001,1.825000e+000,,,,,,,,,,,,,,,,,,0,4.000000e+000,1.000000e+000,2,2,2.479858e-001,0,,0,
1654706285.947,,1.000000e+003,3.061222e+002,4.455642e-005,8.772056e-010,-2.374614e-002,4.189423e-004,3,9.466836e-001,1.825000e+000,,,,,,,,,,,,,,,,,,0,4.000000e+000,1.000000e+000,2,2,1.923218e-001,0,,0,
1654706409.122,,1.000000e+003,3.081093e+002,4.442814e-005,6.930152e-009,-2.572290e-002,3.678511e-004,3,9.460651e-001,1.825000e+000,,,,,,,,,,,,,,,,,,0,4.000000e+000,1.000000e+000,2,2,1.950073e-001,0,,0,
1654706531.497,,1.000000e+003,3.101279e+002,4.440554e-005,5.492158e-008,-2.611949e-002,2.686019e-004,3,9.461637e-001,1.825000e+000,,,,,,,,,,,,,,,,,,0,4.000000e+000,1.000000e+000,2,2,2.128906e-001,0,,0,
1654706652.188,,1.000000e+003,3.121249e+002,4.431162e-005,3.830363e-009,-2.697032e-002,1.504972e-004,3,9.473165e-001,1.825000e+000,,,,,,,,,,,,,,,,,,0,4.000000e+000,1.000000e+000,2,2,2.160034e-001,0,,0,
1654706774.313,,1.000000e+003,3.141516e+002,4.423402e-005,6.575413e-008,-2.776703e-002,6.977121e-004,3,9.456933e-001,1.825000e+000,,,,,,,,,,,,,,,,,,0,4.000000e+000,1.000000e+000,2,2,2.346191e-001,0,,0,
1654706891.993,,1.000000e+003,3.161293e+002,4.420477e-005,4.990532e-010,-2.965227e-002,1.507817e-004,3,9.460101e-001,1.825000e+000,,,,,,,,,,,,,,,,,,0,4.000000e+000,1.000000e+000,2,2,2.218933e-001,0,,0,
1654707011.867,,1.000000e+003,3.181259e+002,4.414320e-005,2.286900e-009,-2.945304e-002,6.223311e-004,3,9.462682e-001,1.825000e+000,,,,,,,,,,,,,,,,,,0,4.000000e+000,1.000000e+000,2,2,2.328796e-001,0,,0,
1654707132.133,,1.000000e+003,3.201392e+002,4.411222e-005,2.425810e-008,-3.103663e-002,2.075982e-004,3,9.463823e-001,1.825000e+000,,,,,,,,,,,,,,,,,,0,4.000000e+000,1.000000e+000,2,2,1.871948e-001,0,,0,
1654707251.259,,1.000000e+003,3.221284e+002,4.407466e-005,4.568653e-009,-3.245724e-002,8.570193e-004,3,9.465308e-001,1.825000e+000,,,,,,,,,,,,,,,,,,0,4.000000e+000,1.000000e+000,2,2,2.308960e-001,0,,0,
1654707369.953,,1.000000e+003,3.241190e+002,4.402740e-005,2.308507e-008,-3.379358e-002,1.489291e-003,3,9.466026e-001,1.825000e+000,,,,,,,,,,,,,,,,,,0,4.000000e+000,1.000000e+000,2,2,2.256165e-001,0,,0,
1654707490.340,,1.000000e+003,3.261232e+002,4.398010e-005,5.200958e-008,-3.437675e-002,8.657647e-004,3,9.456335e-001,1.825000e+000,,,,,,,,,,,,,,,,,,0,4.000000e+000,1.000000e+000,2,2,2.031860e-001,0,,0,
1654707611.725,,1.000000e+003,3.281540e+002,4.395701e-005,3.217607e-008,-3.629947e-002,1.387772e-003,3,9.458590e-001,1.825000e+000,,,,,,,,,,,,,,,,,,0,4.000000e+000,1.000000e+000,2,2,2.144775e-001,0,,0,
1654707730.899,,1.000000e+003,3.301379e+002,4.398461e-005,5.809855e-008,-3.740000e-002,5.853433e-004,3,9.466041e-001,1.825000e+000,,,,,,,,,,,,,,,,,,0,4.000000e+000,1.000000e+000,2,2,2.258911e-001,0,,0,
1654707849.816,,1.000000e+003,3.321079e+002,4.397430e-005,4.018150e-009,-3.816759e-002,1.190709e-003,3,9.458486e-001,1.825000e+000,,,,,,,,,,,,,,,,,,0,4.000000e+000,1.000000e+000,2,2,2.023010e-001,0,,0,
1654707968.768,,1.000000e+003,3.340985e+002,4.397917e-005,6.793813e-009,-4.002979e-002,1.310569e-003,3,9.458055e-001,1.825000e+000,,,,,,,,,,,,,,,,,,0,4.000000e+000,1.000000e+000,2,2,1.961060e-001,0,,0,
1654708090.698,,1.000000e+003,3.361371e+002,4.400402e-005,2.864411e-008,-3.883991e-002,2.291603e-004,3,9.474992e-001,1.825000e+000,,,,,,,,,,,,,,,,,,0,4.000000e+000,1.000000e+000,2,2,1.985779e-001,0,,0,
1654708209.139,,1.000000e+003,3.381245e+002,4.401501e-005,2.783380e-009,-4.078699e-002,7.409758e-004,3,9.461133e-001,1.825000e+000,,,,,,,,,,,,,,,,,,0,4.000000e+000,1.000000e+000,2,2,1.736145e-001,0,,0,
1654708328.342,,1.000000e+003,3.400976e+002,4.405370e-005,1.187695e-008,-4.225922e-002,1.783341e-006,3,9.457836e-001,1.825000e+000,,,,,,,,,,,,,,,,,,0,4.000000e+000,1.000000e+000,2,2,1.944275e-001,0,,0,
1654708450.089,,1.000000e+003,3.421091e+002,4.407470e-005,4.887635e-009,-4.342907e-002,5.899611e-004,3,9.465947e-001,1.825000e+000,,,,,,,,,,,,,,,,,,0,4.000000e+000,1.000000e+000,2,2,2.155151e-001,0,,0,
1654708572.230,,1.000000e+003,3.441365e+002,4.416326e-005,3.791776e-008,-4.416803e-002,2.119399e-003,3,9.468675e-001,1.825000e+000,,,,,,,,,,,,,,,,,,0,4.000000e+000,1.000000e+000,2,2,1.992798e-001,0,,0,
1654708692.686,,1.000000e+003,3.461317e+002,4.424455e-005,1.354389e-008,-4.570878e-002,6.979966e-004,3,9.470890e-001,1.825000e+000,,,,,,,,,,,,,,,,,,0,4.000000e+000,1.000000e+000,2,2,2.015991e-001,0,,0,
1654708812.562,,1.000000e+003,3.481514e+002,4.429279e-005,9.901320e-009,-4.600043e-002,7.166282e-004,3,9.465594e-001,1.825000e+000,,,,,,,,,,,,,,,,,,0,4.000000e+000,1.000000e+000,2,2,1.848145e-001,0,,0,
1654708931.500,,1.000000e+003,3.501273e+002,4.441164e-005,4.433085e-008,-4.733438e-002,5.398458e-004,3,9.469941e-001,1.825000e+000,,,,,,,,,,,,,,,,,,0,4.000000e+000,1.000000e+000,2,2,2.264099e-001,0,,0,
1654709051.630,,1.000000e+003,3.521368e+002,4.447628e-005,7.105335e-008,-4.872654e-002,1.213047e-003,3,9.471483e-001,1.825000e+000,,,,,,,,,,,,,,,,,,0,4.000000e+000,1.000000e+000,2,2,2.290955e-001,0,,0,
1654709171.786,,1.000000e+003,3.541405e+002,4.456355e-005,2.507357e-008,-4.931202e-002,7.266802e-004,3,9.470915e-001,1.825000e+000,,,,,,,,,,,,,,,,,,0,4.000000e+000,1.000000e+000,2,2,2.117004e-001,0,,0,
1654709291.460,,1.000000e+003,3.561378e+002,4.468225e-005,4.810719e-008,-5.030215e-002,8.379426e-004,3,9.475446e-001,1.825000e+000,,,,,,,,,,,,,,,,,,0,4.000000e+000,1.000000e+000,2,2,2.142029e-001,0,,0,
1654709413.858,,1.000000e+003,3.581510e+002,4.485678e-005,5.431963e-008,-5.216442e-002,2.073414e-004,3,9.473916e-001,1.825000e+000,,,,,,,,,,,,,,,,,,0,4.000000e+000,1.000000e+000,2,2,2.062988e-001,0,,0,
1654709532.030,,1.000000e+003,3.601335e+002,4.499167e-005,1.050327e-008,-5.309547e-002,1.057040e-003,3,9.472525e-001,1.825000e+000,,,,,,,,,,,,,,,,,,0,4.000000e+000,1.000000e+000,2,2,2.088013e-001,0,,0,
1654709652.017,,1.000000e+003,3.621286e+002,4.518116e-005,3.738012e-008,-5.485405e-002,6.196667e-004,3,9.480948e-001,1.825000e+000,,,,,,,,,,,,,,,,,,0,4.000000e+000,1.000000e+000,2,2,2.322998e-001,0,,0,
1654709772.200,,1.000000e+003,3.641149e+002,4.540123e-005,1.597487e-009,-5.661430e-002,2.843200e-004,3,9.480524e-001,1.825000e+000,,,,,,,,,,,,,,,,,,0,4.000000e+000,1.000000e+000,2,2,1.922913e-001,0,,0,
1654709894.266,,1.000000e+003,3.661593e+002,4.557717e-005,2.135125e-009,-5.758733e-002,8.113269e-007,3,9.483799e-001,1.825000e+000,,,,,,,,,,,,,,,,,,0,4.000000e+000,1.000000e+000,2,2,2.161255e-001,0,,0,
1654710012.782,,1.000000e+003,3.681240e+002,4.577546e-005,1.001965e-008,-5.795945e-002,1.555219e-005,3,9.493331e-001,1.825000e+000,,,,,,,,,,,,,,,,,,0,4.000000e+000,1.000000e+000,2,2,1.968079e-001,0,,0,
1654710132.704,,1.000000e+003,3.701192e+002,4.604440e-005,3.459931e-008,-6.036653e-002,1.271671e-003,3,9.481481e-001,1.825000e+000,,,,,,,,,,,,,,,,,,0,4.000000e+000,1.000000e+000,2,2,1.990967e-001,0,,0,
1654710254.420,,1.000000e+003,3.721595e+002,4.630879e-005,1.001579e-007,-6.077245e-002,4.199090e-004,3,9.493091e-001,1.825000e+000,,,,,,,,,,,,,,,,,,0,4.000000e+000,1.000000e+000,2,2,2.236938e-001,0,,0,
1654710371.549,,1.000000e+003,3.741188e+002,4.669565e-005,5.074651e-008,-6.295612e-002,6.073097e-004,3,9.500644e-001,1.825000e+000,,,,,,,,,,,,,,,,,,0,4.000000e+000,1.000000e+000,2,2,2.146912e-001,0,,0,
1654710491.723,,1.000000e+003,3.761227e+002,4.724476e-005,2.274808e-008,-6.538555e-002,5.722647e-004,3,9.504908e-001,1.825000e+000,,,,,,,,,,,,,,,,,,0,4.000000e+000,1.000000e+000,2,2,2.286987e-001,0,,0,
1654710611.422,,1.000000e+003,3.781144e+002,4.850175e-005,9.461432e-008,-6.872977e-002,8.358879e-004,3,9.515710e-001,1.825000e+000,,,,,,,,,,,,,,,,,,0,4.000000e+000,1.000000e+000,2,2,2.196045e-001,0,,0,
1654710731.369,,1.000000e+003,3.801195e+002,5.226632e-005,1.992354e-007,-7.748869e-002,1.902351e-004,3,9.544895e-001,1.825000e+000,,,,,,,,,,,,,,,,,,0,4.000000e+000,1.000000e+000,2,2,2.218933e-001,0,,0,
1654710852.019,,1.000000e+003,3.821380e+002,5.936340e-005,2.541570e-007,-9.003287e-002,1.032703e-004,3,9.588814e-001,1.825000e+000,,,,,,,,,,,,,,,,,,0,4.000000e+000,1.000000e+000,2,2,1.891174e-001,0,,0,
1654710970.399,,1.000000e+003,3.840982e+002,6.803234e-005,3.596064e-007,-1.012428e-001,7.487914e-005,3,9.635875e-001,1.825000e+000,,,,,,,,,,,,,,,,,,0,4.000000e+000,1.000000e+000,2,2,1.911011e-001,0,,0,
1654711091.794,,1.000000e+003,3.861248e+002,7.898211e-005,5.210476e-007,-1.115645e-001,7.536173e-004,3,9.675887e-001,1.825000e+000,,,,,,,,,,,,,,,,,,0,4.000000e+000,1.000000e+000,2,2,2.536011e-001,0,,0,
1654711210.978,,1.000000e+003,3.881189e+002,9.299311e-005,5.140454e-007,-1.208169e-001,5.124793e-004,3,9.717070e-001,1.825000e+000,,,,,,,,,,,,,,,,,,0,4.000000e+000,1.000000e+000,2,2,2.196045e-001,0,,0,
1654711331.377,,1.000000e+003,3.901377e+002,1.056872e-004,3.973647e-007,-1.263042e-001,5.161092e-004,3,9.739510e-001,1.825000e+000,,,,,,,,,,,,,,,,,,0,4.000000e+000,1.000000e+000,2,2,2.466736e-001,0,,0,
1654711452.268,,1.000000e+003,3.921564e+002,1.136698e-004,2.217134e-007,-1.292732e-001,5.641461e-004,3,9.746135e-001,1.825000e+000,,,,,,,,,,,,,,,,,,0,4.000000e+000,1.000000e+000,2,2,1.994934e-001,0,,0,
1654711569.235,,1.000000e+003,3.940994e+002,1.177276e-004,8.991705e-008,-1.300991e-001,1.655423e-004,3,9.756262e-001,1.825000e+000,,,,,,,,,,,,,,,,,,0,4.000000e+000,1.000000e+000,2,2,1.638794e-001,0,,0,
1654711688.688,,1.000000e+003,3.960907e+002,1.200363e-004,6.334889e-008,-1.306460e-001,2.246322e-004,3,9.752647e-001,1.825000e+000,,,,,,,,,,,,,,,,,,0,4.000000e+000,1.000000e+000,2,2,1.781006e-001,0,,0,
1654711812.819,,1.000000e+003,3.981578e+002,1.214690e-004,2.215899e-008,-1.315076e-001,1.826961e-004,3,9.758677e-001,1.825000e+000,,,,,,,,,,,,,,,,,,0,4.000000e+000,1.000000e+000,2,2,2.183228e-001,0,,0,
1654712176.566,,1.000000e+003,3.999849e+002,1.232353e-004,1.009426e-008,-1.295376e-001,1.198762e-004,3,9.760528e-001,1.825000e+000,,,,,,,,,,,,,,,,,,0,4.000000e+000,1.000000e+000,2,2,1.300049e-002,0,,0,
1654712498.757,,1.000000e+003,3.988361e+002,1.238870e-004,1.925214e-008,-1.275098e-001,8.768652e-005,3,9.761703e-001,1.825000e+000,,,,,,,,,,,,,,,,,,0,4.000000e+000,1.000000e+000,2,2,2.833252e-001,0,,0,
1654712586.401,,1.000000e+003,3.967436e+002,1.243428e-004,8.930481e-008,-1.261549e-001,1.584827e-004,3,9.759005e-001,1.825000e+000,,,,,,,,,,,,,,,,,,0,4.000000e+000,1.000000e+000,2,2,4.465027e-001,0,,0,
1654712643.339,,1.000000e+003,3.947115e+002,1.248457e-004,7.327336e-008,-1.247168e-001,1.612802e-004,3,9.761738e-001,1.825000e+000,,,,,,,,,,,,,,,,,,0,4.000000e+000,1.000000e+000,2,2,5.435181e-001,0,,0,
1654712699.313,,1.000000e+003,3.927560e+002,1.252688e-004,3.542764e-008,-1.238991e-001,1.855989e-004,3,9.761271e-001,1.825000e+000,,,,,,,,,,,,,,,,,,0,4.000000e+000,1.000000e+000,2,2,4.378052e-001,0,,0,
1654712770.745,,1.000000e+003,3.908206e+002,1.256973e-004,2.356355e-008,-1.232435e-001,1.644359e-004,3,9.765626e-001,1.825000e+000,,,,,,,,,,,,,,,,,,0,4.000000e+000,1.000000e+000,2,2,2.847900e-001,0,,0,
1654713091.636,,1.000000e+003,3.889141e+002,1.262911e-004,4.205424e-008,-1.238134e-001,2.787698e-004,3,9.775702e-001,1.825000e+000,,,,,,,,,,,,,,,,,,0,4.000000e+000,1.000000e+000,2,2,1.716003e-001,0,,0,
1654713199.765,,1.000000e+003,3.868145e+002,1.268296e-004,3.948180e-008,-1.229784e-001,2.966137e-004,3,9.776661e-001,1.825000e+000,,,,,,,,,,,,,,,,,,0,4.000000e+000,1.000000e+000,2,2,3.030090e-001,0,,0,
1654713278.392,,1.000000e+003,3.848282e+002,1.272921e-004,3.367838e-008,-1.218570e-001,2.444096e-004,3,9.775535e-001,1.825000e+000,,,,,,,,,,,,,,,,,,0,4.000000e+000,1.000000e+000,2,2,3.117981e-001,0,,0,
1654713377.849,,1.000000e+003,3.828988e+002,1.276902e-004,6.661589e-008,-1.214927e-001,5.626077e-005,3,9.779273e-001,1.825000e+000,,,,,,,,,,,,,,,,,,0,4.000000e+000,1.000000e+000,2,2,2.018127e-001,0,,0,
1654713529.063,,1.000000e+003,3.808867e+002,1.280761e-004,6.379650e-009,-1.208387e-001,2.996220e-004,3,9.785503e-001,1.825000e+000,,,,,,,,,,,,,,,,,,0,4.000000e+000,1.000000e+000,2,2,1.996155e-001,0,,0,
1654713658.722,,1.000000e+003,3.788441e+002,1.283872e-004,3.469706e-008,-1.200712e-001,3.134676e-006,3,9.783072e-001,1.825000e+000,,,,,,,,,,,,,,,,,,0,4.000000e+000,1.000000e+000,2,2,2.205200e-001,0,,0,
1654713770.135,,1.000000e+003,3.768645e+002,1.287464e-004,5.679946e-008,-1.192095e-001,5.227263e-005,3,9.781499e-001,1.825000e+000,,,,,,,,,,,,,,,,,,0,4.000000e+000,1.000000e+000,2,2,1.950989e-001,0,,0,
1654713889.265,,1.000000e+003,3.748723e+002,1.291131e-004,3.643603e-008,-1.186313e-001,2.165769e-004,3,9.786859e-001,1.825000e+000,,,,,,,,,,,,,,,,,,0,4.000000e+000,1.000000e+000,2,2,2.156982e-001,0,,0,
1654714013.395,,1.000000e+003,3.728767e+002,1.293556e-004,5.865162e-009,-1.178158e-001,3.184405e-004,3,9.787034e-001,1.825000e+000,,,,,,,,,,,,,,,,,,0,4.000000e+000,1.000000e+000,2,2,2.246094e-001,0,,0,
1654714136.313,,1.000000e+003,3.708420e+002,1.294767e-004,7.587668e-008,-1.169529e-001,1.208561e-005,3,9.785897e-001,1.825000e+000,,,,,,,,,,,,,,,,,,0,4.000000e+000,1.000000e+000,2,2,2.108765e-001,0,,0,
1654714253.693,,1.000000e+003,3.688909e+002,1.295923e-004,3.597300e-008,-1.163656e-001,1.043134e-006,3,9.785996e-001,1.825000e+000,,,,,,,,,,,,,,,,,,0,4.000000e+000,1.000000e+000,2,2,1.977234e-001,0,,0,
1654714375.340,,1.000000e+003,3.668714e+002,1.295849e-004,1.269756e-008,-1.156836e-001,4.941718e-005,3,9.785478e-001,1.825000e+000,,,,,,,,,,,,,,,,,,0,4.000000e+000,1.000000e+000,2,2,2.171021e-001,0,,0,
1654714495.074,,1.000000e+003,3.648938e+002,1.293816e-004,2.035314e-008,-1.149302e-001,2.695238e-004,3,9.786513e-001,1.825000e+000,,,,,,,,,,,,,,,,,,0,4.000000e+000,1.000000e+000,2,2,2.039185e-001,0,,0,
1654714616.977,,1.000000e+003,3.628615e+002,1.289477e-004,1.053671e-008,-1.141776e-001,1.819163e-005,3,9.786659e-001,1.825000e+000,,,,,,,,,,,,,,,,,,0,4.000000e+000,1.000000e+000,2,2,2.015991e-001,0,,0,
1654714738.927,,1.000000e+003,3.608579e+002,1.281111e-004,3.465590e-008,-1.134866e-001,2.244320e-004,3,9.788363e-001,1.825000e+000,,,,,,,,,,,,,,,,,,0,4.000000e+000,1.000000e+000,2,2,1.991882e-001,0,,0,
1654714857.123,,1.000000e+003,3.588801e+002,1.266697e-004,9.333839e-008,-1.124875e-001,7.735527e-005,3,9.783245e-001,1.825000e+000,,,,,,,,,,,,,,,,,,0,4.000000e+000,1.000000e+000,2,2,2.073059e-001,0,,0,
1654714976.792,,1.000000e+003,3.568941e+002,1.240327e-004,1.874279e-007,-1.111661e-001,9.460914e-005,3,9.778290e-001,1.825000e+000,,,,,,,,,,,,,,,,,,0,4.000000e+000,1.000000e+000,2,2,1.945801e-001,0,,0,
1654715099.483,,1.000000e+003,3.548677e+002,1.176762e-004,4.874979e-007,-1.090873e-001,3.395192e-004,3,9.774451e-001,1.825000e+000,,,,,,,,,,,,,,,,,,0,4.000000e+000,1.000000e+000,2,2,2.226868e-001,0,,0,
1654715219.664,,1.000000e+003,3.528754e+002,7.666786e-005,3.527092e-006,-9.085271e-002,3.162183e-003,3,9.672860e-001,1.825000e+000,,,,,,,,,,,,,,,,,,0,4.000000e+000,1.000000e+000,2,2,2.301025e-001,0,,0,
1654715339.794,,1.000000e+003,3.508743e+002,4.875736e-005,1.088502e-007,-4.580902e-002,5.844108e-004,3,9.513171e-001,1.825000e+000,,,,,,,,,,,,,,,,,,0,4.000000e+000,1.000000e+000,2,2,2.371826e-001,0,,0,
1654715460.765,,1.000000e+003,3.488628e+002,4.780250e-005,2.864669e-008,-4.394649e-002,2.392861e-004,3,9.503941e-001,1.825000e+000,,,,,,,,,,,,,,,,,,0,4.000000e+000,1.000000e+000,2,2,2.051086e-001,0,,0,
1654715581.209,,1.000000e+003,3.468705e+002,4.735675e-005,1.652021e-008,-4.165078e-002,1.057543e-004,3,9.496436e-001,1.825000e+000,,,,,,,,,,,,,,,,,,0,4.000000e+000,1.000000e+000,2,2,2.315063e-001,0,,0,
1654715702.154,,1.000000e+003,3.448616e+002,4.702916e-005,2.747880e-008,-4.084538e-002,3.337530e-004,3,9.498212e-001,1.825000e+000,,,,,,,,,,,,,,,,,,0,4.000000e+000,1.000000e+000,2,2,2.096863e-001,0,,0,
1654715821.625,,1.000000e+003,3.428841e+002,4.681329e-005,5.376913e-008,-3.858143e-002,5.336186e-004,3,9.488652e-001,1.825000e+000,,,,,,,,,,,,,,,,,,0,4.000000e+000,1.000000e+000,2,2,2.166138e-001,0,,0,
1654715942.573,,1.000000e+003,3.408745e+002,4.666939e-005,1.692665e-009,-3.788760e-002,3.162067e-004,3,9.499481e-001,1.825000e+000,,,,,,,,,,,,,,,,,,0,4.000000e+000,1.000000e+000,2,2,2.232056e-001,0,,0,
1654716065.255,,1.000000e+003,3.388483e+002,4.651381e-005,1.247890e-008,-3.710555e-002,3.311636e-004,3,9.492821e-001,1.825000e+000,,,,,,,,,,,,,,,,,,0,4.000000e+000,1.000000e+000,2,2,2.113037e-001,0,,0,
1654716184.191,,1.000000e+003,3.368452e+002,4.644112e-005,1.956083e-008,-3.601174e-002,2.242476e-005,3,9.490602e-001,1.825000e+000,,,,,,,,,,,,,,,,,,0,4.000000e+000,1.000000e+000,2,2,2.084961e-001,0,,0,
1654716303.136,,1.000000e+003,3.348917e+002,4.638577e-005,7.213120e-009,-3.453386e-002,1.750174e-004,3,9.491215e-001,1.825000e+000,,,,,,,,,,,,,,,,,,0,4.000000e+000,1.000000e+000,2,2,2.059937e-001,0,,0,
1654716423.549,,1.000000e+003,3.328844e+002,4.629704e-005,6.330774e-009,-3.336143e-002,7.759472e-004,3,9.488521e-001,1.825000e+000,,,,,,,,,,,,,,,,,,0,4.000000e+000,1.000000e+000,2,2,2.033997e-001,0,,0,
1654716545.177,,1.000000e+003,3.308632e+002,4.627989e-005,3.454786e-008,-3.343709e-002,1.796141e-004,3,9.484727e-001,1.825000e+000,,,,,,,,,,,,,,,,,,0,4.000000e+000,1.000000e+000,2,2,2.182007e-001,0,,0,
1654716665.637,,1.000000e+003,3.288570e+002,4.625034e-005,3.677817e-008,-3.265483e-002,8.528573e-004,3,9.490222e-001,1.825000e+000,,,,,,,,,,,,,,,,,,0,4.000000e+000,1.000000e+000,2,2,2.069092e-001,0,,0,
1654716783.562,,1.000000e+003,3.268872e+002,4.624352e-005,7.164244e-009,-3.203862e-002,9.701256e-004,3,9.490601e-001,1.825000e+000,,,,,,,,,,,,,,,,,,0,4.000000e+000,1.000000e+000,2,2,2.042847e-001,0,,0,
1654716905.735,,1.000000e+003,3.248562e+002,4.623953e-005,1.037722e-008,-3.077977e-002,2.159236e-004,3,9.485310e-001,1.825000e+000,,,,,,,,,,,,,,,,,,0,4.000000e+000,1.000000e+000,2,2,2.099915e-001,0,,0,
1654717025.360,,1.000000e+003,3.228746e+002,4.623240e-005,3.532731e-008,-3.037482e-002,6.262587e-004,3,9.484193e-001,1.825000e+000,,,,,,,,,,,,,,,,,,0,4.000000e+000,1.000000e+000,2,2,2.071838e-001,0,,0,
1654717145.791,,1.000000e+003,3.208675e+002,4.626767e-005,1.318890e-008,-3.012625e-002,4.366137e-004,3,9.478129e-001,1.825000e+000,,,,,,,,,,,,,,,,,,0,4.000000e+000,1.000000e+000,2,2,2.127075e-001,0,,0,
1654717267.473,,1.000000e+003,3.188484e+002,4.627816e-005,7.390619e-009,-2.820288e-002,4.991978e-004,3,9.482692e-001,1.825000e+000,,,,,,,,,,,,,,,,,,0,4.000000e+000,1.000000e+000,2,2,2.098083e-001,0,,0,
1654717385.599,,1.000000e+003,3.168920e+002,4.632886e-005,4.553218e-008,-2.884960e-002,7.937147e-004,3,9.483696e-001,1.825000e+000,,,,,,,,,,,,,,,,,,0,4.000000e+000,1.000000e+000,2,2,2.070007e-001,0,,0,
1654717506.309,,1.000000e+003,3.148806e+002,4.632402e-005,3.527072e-008,-2.734496e-002,2.411709e-004,3,9.480860e-001,1.825000e+000,,,,,,,,,,,,,,,,,,0,4.000000e+000,1.000000e+000,2,2,2.120972e-001,0,,0,
1654717627.771,,1.000000e+003,3.128516e+002,4.640543e-005,7.915396e-009,-2.717131e-002,4.853723e-004,3,9.486573e-001,1.825000e+000,,,,,,,,,,,,,,,,,,0,4.000000e+000,1.000000e+000,2,2,2.092285e-001,0,,0,
1654717745.713,,1.000000e+003,3.108848e+002,4.643334e-005,4.686985e-009,-2.723851e-002,2.857807e-004,3,9.486099e-001,1.825000e+000,,,,,,,,,,,,,,,,,,0,4.000000e+000,1.000000e+000,2,2,2.063904e-001,0,,0,
1654717866.162,,1.000000e+003,3.088783e+002,4.644256e-005,4.051078e-008,-2.590812e-002,2.238577e-004,3,9.479015e-001,1.825000e+000,,,,,,,,,,,,,,,,,,0,4.000000e+000,1.000000e+000,2,2,2.110901e-001,0,,0,
1654717985.887,,1.000000e+003,3.068862e+002,4.658055e-005,5.685150e-010,-2.525631e-002,1.196004e-003,3,9.485089e-001,1.825000e+000,,,,,,,,,,,,,,,,,,0,4.000000e+000,1.000000e+000,2,2,2.082825e-001,0,,0,
1654718107.073,,1.000000e+003,3.048646e+002,4.661778e-005,2.523820e-008,-2.543827e-002,4.023707e-005,3,9.476020e-001,1.825000e+000,,,,,,,,,,,,,,,,,,0,4.000000e+000,1.000000e+000,2,2,2.126160e-001,0,,0,
1654718225.451,,1.000000e+003,3.028823e+002,4.672024e-005,2.487292e-008,-2.405384e-002,3.596838e-005,3,9.479576e-001,1.825000e+000,,,,,,,,,,,,,,,,,,0,4.000000e+000,1.000000e+000,2,2,2.169189e-001,0,,0,
1654718344.357,,1.000000e+003,3.008900e+002,4.676266e-005,2.214872e-009,-2.437612e-002,5.854777e-004,3,9.483166e-001,1.825000e+000,,,,,,,,,,,,,,,,,,0,4.000000e+000,1.000000e+000,2,2,2.138977e-001,0,,0,
1654718945.786,,1.000000e+003,3.000176e+002,4.676904e-005,1.223452e-008,-2.474374e-002,3.609535e-004,3,9.483134e-001,1.825000e+000,,,,,,,,,,,,,,,,,,0,4.000000e+000,1.000000e+000,2,2,7.110596e-003,0,,0,
1654719105.663,,1.000000e+003,3.021467e+002,4.658749e-005,2.545172e-008,-2.555487e-002,7.976291e-006,3,9.479065e-001,1.825000e+000,,,,,,,,,,,,,,,,,,0,4.000000e+000,1.000000e+000,2,2,2.732849e-001,0,,0,
1654719208.569,,1.000000e+003,3.041534e+002,4.654037e-005,3.146865e-008,-2.650034e-002,3.718933e-004,3,9.480320e-001,1.825000e+000,,,,,,,,,,,,,,,,,,0,4.000000e+000,1.000000e+000,2,2,2.188721e-001,0,,0,
1654719322.714,,1.000000e+003,3.061426e+002,4.645194e-005,1.219851e-008,-2.804575e-002,7.963147e-004,3,9.488541e-001,1.825000e+000,,,,,,,,,,,,,,,,,,0,4.000000e+000,1.000000e+000,2,2,2.292786e-001,0,,0,
1654719442.906,,1.000000e+003,3.081168e+002,4.630062e-005,5.705671e-009,-2.899626e-002,1.032550e-003,3,9.481007e-001,1.825000e+000,,,,,,,,,,,,,,,,,,0,4.000000e+000,1.000000e+000,2,2,2.025757e-001,0,,0,
1654719563.284,,1.000000e+003,3.101241e+002,4.621737e-005,3.565401e-008,-3.008663e-002,1.369048e-004,3,9.483064e-001,1.825000e+000,,,,,,,,,,,,,,,,,,0,4.000000e+000,1.000000e+000,2,2,2.130127e-001,0,,0,
1654719683.697,,1.000000e+003,3.121384e+002,4.613453e-005,9.968203e-009,-3.082946e-002,5.637273e-005,3,9.479800e-001,1.825000e+000,,,,,,,,,,,,,,,,,,0,4.000000e+000,1.000000e+000,2,2,2.005005e-001,0,,0,
1654719802.617,,1.000000e+003,3.141223e+002,4.606329e-005,3.539419e-008,-3.151115e-002,3.964333e-004,3,9.477533e-001,1.825000e+000,,,,,,,,,,,,,,,,,,0,4.000000e+000,1.000000e+000,2,2,2.189026e-001,0,,0,
1654719923.268,,1.000000e+003,3.161413e+002,4.599170e-005,6.657474e-008,-3.209911e-002,4.786012e-004,3,9.475930e-001,1.825000e+000,,,,,,,,,,,,,,,,,,0,4.000000e+000,1.000000e+000,2,2,2.218933e-001,0,,0,
1654720042.719,,1.000000e+003,3.181459e+002,4.590479e-005,2.535654e-008,-3.331258e-002,1.932038e-004,3,9.473243e-001,1.825000e+000,,,,,,,,,,,,,,,,,,0,4.000000e+000,1.000000e+000,2,2,2.169189e-001,0,,0,
1654720163.845,,1.000000e+003,3.201534e+002,4.586042e-005,1.424874e-008,-3.451693e-002,3.847586e-004,3,9.471043e-001,1.825000e+000,,,,,,,,,,,,,,,,,,0,4.000000e+000,1.000000e+000,2,2,2.442017e-001,0,,0,
1654720283.046,,1.000000e+003,3.221531e+002,4.579379e-005,6.634322e-009,-3.630008e-002,4.559393e-004,3,9.481603e-001,1.825000e+000,,,,,,,,,,,,,,,,,,0,4.000000e+000,1.000000e+000,2,2,1.979980e-001,0,,0,
1654720401.238,,1.000000e+003,3.241211e+002,4.575368e-005,3.660067e-008,-3.617289e-002,3.622469e-004,3,9.481347e-001,1.825000e+000,,,,,,,,,,,,,,,,,,0,4.000000e+000,1.000000e+000,2,2,2.173157e-001,0,,0,
1654720521.181,,1.000000e+003,3.261147e+002,4.575201e-005,1.112323e-008,-3.765194e-002,8.716337e-004,3,9.475511e-001,1.825000e+000,,,,,,,,,,,,,,,,,,0,4.000000e+000,1.000000e+000,2,2,2.030945e-001,0,,0,
1654720641.367,,1.000000e+003,3.281240e+002,4.564412e-005,7.974563e-010,-3.763375e-002,9.714717e-004,3,9.475529e-001,1.825000e+000,,,,,,,,,,,,,,,,,,0,4.000000e+000,1.000000e+000,2,2,2.230225e-001,0,,0,
1654720762.264,,1.000000e+003,3.301466e+002,4.561710e-005,5.150024e-008,-3.872370e-002,1.162331e-003,3,9.482861e-001,1.825000e+000,,,,,,,,,,,,,,,,,,0,4.000000e+000,1.000000e+000,2,2,2.084961e-001,0,,0,
1654720880.706,,1.000000e+003,3.321233e+002,4.567411e-005,2.447676e-008,-4.006596e-002,7.482225e-004,3,9.477148e-001,1.825000e+000,,,,,,,,,,,,,,,,,,0,4.000000e+000,1.000000e+000,2,2,1.937256e-001,0,,0,
1654720998.831,,1.000000e+003,3.340985e+002,4.563482e-005,5.479356e-010,-4.150071e-002,2.082739e-004,3,9.479599e-001,1.825000e+000,,,,,,,,,,,,,,,,,,0,4.000000e+000,1.000000e+000,2,2,1.961060e-001,0,,0,
1654721119.206,,1.000000e+003,3.361122e+002,4.562929e-005,2.640352e-008,-4.180016e-002,3.015660e-004,3,9.480695e-001,1.825000e+000,,,,,,,,,,,,,,,,,,0,4.000000e+000,1.000000e+000,2,2,2.075806e-001,0,,0,
1654721241.338,,1.000000e+003,3.381428e+002,4.564161e-005,1.895888e-008,-4.321598e-002,2.595061e-004,3,9.477935e-001,1.825000e+000,,,,,,,,,,,,,,,,,,0,4.000000e+000,1.000000e+000,2,2,2.193909e-001,0,,0,
1654721360.964,,1.000000e+003,3.401299e+002,4.568335e-005,7.280049e-010,-4.376891e-002,4.032663e-004,3,9.484930e-001,1.825000e+000,,,,,,,,,,,,,,,,,,0,4.000000e+000,1.000000e+000,2,2,2.312927e-001,0,,0,
1654721479.843,,1.000000e+003,3.421278e+002,4.571937e-005,2.057437e-008,-4.435669e-002,4.941823e-004,3,9.483566e-001,1.825000e+000,,,,,,,,,,,,,,,,,,0,4.000000e+000,1.000000e+000,2,2,2.249146e-001,0,,0,
1654721600.502,,1.000000e+003,3.441294e+002,4.577900e-005,1.893830e-008,-4.561894e-002,6.047704e-004,3,9.483598e-001,1.825000e+000,,,,,,,,,,,,,,,,,,0,4.000000e+000,1.000000e+000,2,2,1.897888e-001,0,,0,
1654721720.129,,1.000000e+003,3.461197e+002,4.578843e-005,2.702605e-008,-4.694895e-002,5.908277e-004,3,9.491354e-001,1.825000e+000,,,,,,,,,,,,,,,,,,0,4.000000e+000,1.000000e+000,2,2,1.919861e-001,0,,0,
1654721840.809,,1.000000e+003,3.481490e+002,4.586170e-005,6.179000e-009,-4.735063e-002,1.860994e-004,3,9.487608e-001,1.825000e+000,,,,,,,,,,,,,,,,,,0,4.000000e+000,1.000000e+000,2,2,2.041931e-001,0,,0,
1654721961.002,,1.000000e+003,3.501519e+002,4.596011e-005,3.302755e-008,-4.896758e-002,2.644688e-004,3,9.481149e-001,1.825000e+000,,,,,,,,,,,,,,,,,,0,4.000000e+000,1.000000e+000,2,2,2.066956e-001,0,,0,
1654722078.694,,1.000000e+003,3.521119e+002,4.605977e-005,4.058280e-008,-5.043448e-002,5.531958e-004,3,9.484863e-001,1.825000e+000,,,,,,,,,,,,,,,,,,0,4.000000e+000,1.000000e+000,2,2,2.090759e-001,0,,0,
1654722198.881,,1.000000e+003,3.541229e+002,4.619978e-005,1.569703e-008,-5.210847e-002,2.861271e-004,3,9.496439e-001,1.825000e+000,,,,,,,,,,,,,,,,,,0,4.000000e+000,1.000000e+000,2,2,2.217102e-001,0,,0,
1654722319.760,,1.000000e+003,3.561352e+002,4.633581e-005,3.283719e-008,-5.264777e-002,1.448482e-004,3,9.493777e-001,1.825000e+000,,,,,,,,,,,,,,,,,,0,4.000000e+000,1.000000e+000,2,2,2.243958e-001,0,,0,
1654722437.712,,1.000000e+003,3.581097e+002,4.650694e-005,1.973061e-008,-5.379357e-002,7.806123e-005,3,9.496359e-001,1.825000e+000,,,,,,,,,,,,,,,,,,0,4.000000e+000,1.000000e+000,2,2,2.165833e-001,0,,0,
1654722558.911,,1.000000e+003,3.601256e+002,4.674721e-005,4.861139e-008,-5.501712e-002,6.581863e-004,3,9.495345e-001,1.825000e+000,,,,,,,,,,,,,,,,,,0,4.000000e+000,1.000000e+000,2,2,2.297058e-001,0,,0,
1654722678.307,,1.000000e+003,3.621207e+002,4.700145e-005,7.464508e-011,-5.699110e-002,1.393059e-004,3,9.498175e-001,1.825000e+000,,,,,,,,,,,,,,,,,,0,4.000000e+000,1.000000e+000,2,2,2.218018e-001,0,,0,
1654722798.960,,1.000000e+003,3.641309e+002,4.737108e-005,2.693344e-008,-5.850743e-002,7.423640e-004,3,9.504173e-001,1.825000e+000,,,,,,,,,,,,,,,,,,0,4.000000e+000,1.000000e+000,2,2,2.137146e-001,0,,0,
1654722919.665,,1.000000e+003,3.661431e+002,4.790892e-005,3.840652e-008,-6.053517e-002,1.374525e-003,3,9.517938e-001,1.825000e+000,,,,,,,,,,,,,,,,,,0,4.000000e+000,1.000000e+000,2,2,1.837158e-001,0,,0,
1654723039.184,,1.000000e+003,3.681295e+002,4.890931e-005,4.720169e-008,-6.261937e-002,8.501546e-005,3,9.520422e-001,1.825000e+000,,,,,,,,,,,,,,,,,,0,4.000000e+000,1.000000e+000,2,2,2.404785e-001,0,,0,
1654723158.405,,1.000000e+003,3.701302e+002,5.205339e-005,2.071431e-007,-6.959134e-002,9.354283e-004,3,9.541953e-001,1.825000e+000,,,,,,,,,,,,,,,,,,0,4.000000e+000,1.000000e+000,2,2,1.990051e-001,0,,0,
1654723280.859,,1.000000e+003,3.721595e+002,6.943637e-005,1.109936e-006,-9.520262e-002,7.266064e-004,3,9.645537e-001,1.825000e+000,,,,,,,,,,,,,,,,,,0,4.000000e+000,1.000000e+000,2,2,2.236938e-001,0,,0,
1654723399.019,,1.000000e+003,3.741387e+002,9.183257e-005,8.423042e-007,-1.127814e-001,3.063339e-004,3,9.720536e-001,1.825000e+000,,,,,,,,,,,,,,,,,,0,4.000000e+000,1.000000e+000,2,2,2.486877e-001,0,,0,
1654723518.173,,1.000000e+003,3.761256e+002,1.094608e-004,5.039872e-007,-1.222553e-001,2.378136e-004,3,9.754094e-001,1.825000e+000,,,,,,,,,,,,,,,,,,0,4.000000e+000,1.000000e+000,2,2,2.057800e-001,0,,0,
1654723638.656,,1.000000e+003,3.781346e+002,1.181842e-004,2.219707e-007,-1.254827e-001,1.654685e-004,3,9.770385e-001,1.825000e+000,,,,,,,,,,,,,,,,,,0,4.000000e+000,1.000000e+000,2,2,2.080994e-001,0,,0,
1654723759.536,,1.000000e+003,3.801545e+002,1.219378e-004,8.998395e-009,-1.268462e-001,2.802765e-006,3,9.776410e-001,1.825000e+000,,,,,,,,,,,,,,,,,,0,4.000000e+000,1.000000e+000,2,2,1.987915e-001,0,,0,
1654723875.059,,1.000000e+003,3.820789e+002,1.235983e-004,5.666570e-008,-1.275604e-001,1.155140e-004,3,9.779269e-001,1.825000e+000,,,,,,,,,,,,,,,,,,0,4.000000e+000,1.000000e+000,2,2,1.890869e-001,0,,0,
1654723998.260,,1.000000e+003,3.841400e+002,1.243961e-004,5.995842e-008,-1.281341e-001,3.147527e-004,3,9.773066e-001,1.825000e+000,,,,,,,,,,,,,,,,,,0,4.000000e+000,1.000000e+000,2,2,2.149963e-001,0,,0,
1654724117.209,,1.000000e+003,3.861219e+002,1.249583e-004,2.579642e-008,-1.286283e-001,3.460783e-004,3,9.773741e-001,1.825000e+000,,,,,,,,,,,,,,,,,,0,4.000000e+000,1.000000e+000,2,2,2.174072e-001,0,,0,
1654724238.901,,1.000000e+003,3.881464e+002,1.251827e-004,3.907021e-008,-1.286502e-001,1.017530e-004,3,9.775836e-001,1.825000e+000,,,,,,,,,,,,,,,,,,0,4.000000e+000,1.000000e+000,2,2,2.319031e-001,0,,0,
1654724356.825,,1.000000e+003,3.901191e+002,1.250366e-004,1.417929e-008,-1.289624e-001,3.301152e-005,3,9.773585e-001,1.825000e+000,,,,,,,,,,,,,,,,,,0,4.000000e+000,1.000000e+000,2,2,2.342834e-001,0,,0,
1654724476.980,,1.000000e+003,3.921190e+002,1.248211e-004,8.272965e-009,-1.288647e-001,8.924595e-005,3,9.768423e-001,1.825000e+000,,,,,,,,,,,,,,,,,,0,4.000000e+000,1.000000e+000,2,2,2.120056e-001,0,,0,
1654724596.878,,1.000000e+003,3.941246e+002,1.245389e-004,3.828819e-008,-1.290476e-001,4.009219e-004,3,9.765298e-001,1.825000e+000,,,,,,,,,,,,,,,,,,0,4.000000e+000,1.000000e+000,2,2,1.890259e-001,0,,0,
1654724717.093,,1.000000e+003,3.961225e+002,1.242042e-004,4.095324e-008,-1.292799e-001,1.505591e-004,3,9.764576e-001,1.825000e+000,,,,,,,,,,,,,,,,,,0,4.000000e+000,1.000000e+000,2,2,2.036133e-001,0,,0,
1654724836.304,,1.000000e+003,3.981097e+002,1.238160e-004,1.822316e-008,-1.292055e-001,3.416213e-004,3,9.757837e-001,1.825000e+000,,,,,,,,,,,,,,,,,,0,4.000000e+000,1.000000e+000,2,2,2.053223e-001,0,,0,
1654725202.214,,1.000000e+003,3.999785e+002,1.236741e-004,1.059895e-009,-1.275291e-001,1.981323e-004,3,9.761164e-001,1.825000e+000,,,,,,,,,,,,,,,,,,0,4.000000e+000,1.000000e+000,2,2,3.878784e-002,0,,0,
1654725525.106,,1.000000e+003,3.988489e+002,1.240037e-004,4.880432e-008,-1.251949e-001,4.014803e-004,3,9.759288e-001,1.825000e+000,,,,,,,,,,,,,,,,,,0,4.000000e+000,1.000000e+000,2,2,3.090210e-001,0,,0,
1654725612.023,,1.000000e+003,3.967436e+002,1.244680e-004,6.370389e-008,-1.239147e-001,1.174896e-004,3,9.758785e-001,1.825000e+000,,,,,,,,,,,,,,,,,,0,4.000000e+000,1.000000e+000,2,2,4.465027e-001,0,,0,
1654725670.154,,1.000000e+003,3.946894e+002,1.250142e-004,1.023831e-007,-1.227374e-001,2.782219e-005,3,9.760851e-001,1.825000e+000,,,,,,,,,,,,,,,,,,0,4.000000e+000,1.000000e+000,2,2,4.676208e-001,0,,0,
1654725726.065,,1.000000e+003,3.927154e+002,1.254691e-004,5.687149e-008,-1.216888e-001,9.417713e-005,3,9.764285e-001,1.825000e+000,,,,,,,,,,,,,,,,,,0,4.000000e+000,1.000000e+000,2,2,4.501953e-001,0,,0,
1654725795.692,,1.000000e+003,3.908298e+002,1.259178e-004,3.572604e-008,-1.207795e-001,4.004741e-004,3,9.766747e-001,1.825000e+000,,,,,,,,,,,,,,,,,,0,4.000000e+000,1.000000e+000,2,2,2.724915e-001,0,,0,
1654726117.877,,1.000000e+003,3.889293e+002,1.265645e-004,2.515846e-008,-1.215871e-001,1.331314e-005,3,9.776347e-001,1.825000e+000,,,,,,,,,,,,,,,,,,0,4.000000e+000,1.000000e+000,2,2,1.349182e-001,0,,0,
1654726228.397,,1.000000e+003,3.868145e+002,1.271043e-004,5.319805e-008,-1.204853e-001,1.589516e-004,3,9.776627e-001,1.825000e+000,,,,,,,,,,,,,,,,,,0,4.000000e+000,1.000000e+000,2,2,2.909241e-001,0,,0,
1654726307.097,,1.000000e+003,3.848163e+002,1.274937e-004,3.836022e-008,-1.197037e-001,2.001396e-004,3,9.776831e-001,1.825000e+000,,,,,,,,,,,,,,,,,,0,4.000000e+000,1.000000e+000,2,2,2.636108e-001,0,,0,
1654726404.314,,1.000000e+003,3.828810e+002,1.279421e-004,6.626604e-008,-1.191150e-001,2.323767e-004,3,9.781159e-001,1.825000e+000,,,,,,,,,,,,,,,,,,0,4.000000e+000,1.000000e+000,2,2,2.254944e-001,0,,0,
1654726555.696,,1.000000e+003,3.808807e+002,1.283347e-004,1.611376e-008,-1.181576e-001,4.166216e-005,3,9.777383e-001,1.825000e+000,,,,,,,,,,,,,,,,,,0,4.000000e+000,1.000000e+000,2,2,1.760864e-001,0,,0,
1654726684.871,,1.000000e+003,3.788644e+002,1.288294e-004,1.780158e-009,-1.174787e-001,1.584195e-005,3,9.783238e-001,1.825000e+000,,,,,,,,,,,,,,,,,,0,4.000000e+000,1.000000e+000,2,2,2.320862e-001,0,,0,
1654726797.001,,1.000000e+003,3.768645e+002,1.291455e-004,1.670439e-007,-1.168014e-001,4.192189e-004,3,9.782301e-001,1.825000e+000,,,,,,,,,,,,,,,,,,0,4.000000e+000,1.000000e+000,2,2,2.411194e-001,0,,0,
1654726915.442,,1.000000e+003,3.748609e+002,1.295689e-004,4.419451e-008,-1.160875e-001,2.855449e-006,3,9.785183e-001,1.825000e+000,,,,,,,,,,,,,,,,,,0,4.000000e+000,1.000000e+000,2,2,1.929932e-001,0,,0,
1654727037.645,,1.000000e+003,3.728711e+002,1.298602e-004,6.974398e-008,-1.156303e-001,1.555008e-004,3,9.788920e-001,1.825000e+000,,,,,,,,,,,,,,,,,,0,4.000000e+000,1.000000e+000,2,2,2.021179e-001,0,,0,
1654727159.676,,1.000000e+003,3.708726e+002,1.300995e-004,2.618744e-008,-1.147527e-001,1.059203e-004,3,9.788122e-001,1.825000e+000,,,,,,,,,,,,,,,,,,0,4.000000e+000,1.000000e+000,2,2,1.997986e-001,0,,0,
1654727280.555,,1.000000e+003,3.688551e+002,1.302843e-004,1.680318e-008,-1.141682e-001,1.926585e-004,3,9.787074e-001,1.825000e+000,,,,,,,,,,,,,,,,,,0,4.000000e+000,1.000000e+000,2,2,1.866150e-001,0,,0,
1654727399.962,,1.000000e+003,3.668905e+002,1.303316e-004,4.425625e-008,-1.133695e-001,8.192294e-005,3,9.785379e-001,1.825000e+000,,,,,,,,,,,,,,,,,,0,4.000000e+000,1.000000e+000,2,2,2.279053e-001,0,,0,
1654727520.840,,1.000000e+003,3.648912e+002,1.302720e-004,9.490244e-008,-1.126867e-001,5.495422e-005,3,9.784182e-001,1.825000e+000,,,,,,,,,,,,,,,,,,0,4.000000e+000,1.000000e+000,2,2,2.038879e-001,0,,0,
1654727643.043,,1.000000e+003,3.628615e+002,1.301573e-004,7.605160e-008,-1.120658e-001,2.212868e-004,3,9.788898e-001,1.825000e+000,,,,,,,,,,,,,,,,,,0,4.000000e+000,1.000000e+000,2,2,1.802979e-001,0,,0,
1654727762.263,,1.000000e+003,3.609025e+002,1.296962e-004,7.834622e-008,-1.114409e-001,1.389318e-004,3,9.786268e-001,1.825000e+000,,,,,,,,,,,,,,,,,,0,4.000000e+000,1.000000e+000,2,2,2.096863e-001,0,,0,
1654727884.920,,1.000000e+003,3.588671e+002,1.288516e-004,5.396978e-008,-1.101928e-001,1.782390e-004,3,9.785818e-001,1.825000e+000,,,,,,,,,,,,,,,,,,0,4.000000e+000,1.000000e+000,2,2,2.176819e-001,0,,0,
1654728004.851,,1.000000e+003,3.568813e+002,1.273064e-004,8.126851e-008,-1.094321e-001,1.804201e-004,3,9.784989e-001,1.825000e+000,,,,,,,,,,,,,,,,,,0,4.000000e+000,1.000000e+000,2,2,2.253113e-001,0,,0,
1654728127.015,,1.000000e+003,3.548450e+002,1.242407e-004,2.542805e-007,-1.081801e-001,1.490471e-004,3,9.780688e-001,1.825000e+000,,,,,,,,,,,,,,,,,,0,4.000000e+000,1.000000e+000,2,2,2.225952e-001,0,,0,
1654728246.957,,1.000000e+003,3.528554e+002,1.145165e-004,1.088487e-006,-1.058624e-001,3.635693e-004,3,9.766163e-001,1.825000e+000,,,,,,,,,,,,,,,,,,0,4.000000e+000,1.000000e+000,2,2,2.201233e-001,0,,0,
1654728366.961,,1.000000e+003,3.508669e+002,5.314626e-005,1.710153e-006,-5.134280e-002,3.738662e-003,3,9.538792e-001,1.825000e+000,,,,,,,,,,,,,,,,,,0,4.000000e+000,1.000000e+000,2,2,2.471008e-001,0,,0,
1654728485.176,,1.000000e+003,3.488872e+002,4.827975e-005,3.629455e-008,-4.283386e-002,1.793981e-004,3,9.506999e-001,1.825000e+000,,,,,,,,,,,,,,,,,,0,4.000000e+000,1.000000e+000,2,2,2.149048e-001,0,,0,
1654728606.806,,1.000000e+003,3.468754e+002,4.756652e-005,3.775569e-008,-4.100658e-002,2.544300e-004,3,9.501687e-001,1.825000e+000,,,,,,,,,,,,,,,,,,0,4.000000e+000,1.000000e+000,2,2,1.930237e-001,0,,0,
1654728725.481,,1.000000e+003,3.448950e+002,4.715593e-005,9.556613e-009,-4.019630e-002,4.827447e-004,3,9.496659e-001,1.825000e+000,,,,,,,,,,,,,,,,,,0,4.000000e+000,1.000000e+000,2,2,2.096863e-001,0,,0,
1654728847.108,,1.000000e+003,3.428818e+002,4.688733e-005,3.699425e-008,-3.797473e-002,1.062575e-004,3,9.495308e-001,1.825000e+000,,,,,,,,,,,,,,,,,,0,4.000000e+000,1.000000e+000,2,2,2.260132e-001,0,,0,
1654728970.057,,1.000000e+003,3.408536e+002,4.671690e-005,3.737240e-008,-3.789222e-002,1.309366e-003,3,9.496468e-001,1.825000e+000,,,,,,,,,,,,,,,,,,0,4.000000e+000,1.000000e+000,2,2,2.324219e-001,0,,0,
1654729088.434,,1.000000e+003,3.388851e+002,4.658285e-005,4.363886e-008,-3.628946e-002,6.479815e-004,3,9.494030e-001,1.825000e+000,,,,,,,,,,,,,,,,,,0,4.000000e+000,1.000000e+000,2,2,1.929932e-001,0,,0,
1654729208.580,,1.000000e+003,3.368882e+002,4.648220e-005,2.029656e-009,-3.472941e-002,4.081369e-004,3,9.485562e-001,1.825000e+000,,,,,,,,,,,,,,,,,,0,4.000000e+000,1.000000e+000,2,2,2.268066e-001,0,,0,
1654729329.214,,1.000000e+003,3.348670e+002,4.635098e-005,1.157598e-008,-3.362828e-002,4.669081e-004,3,9.489875e-001,1.825000e+000,,,,,,,,,,,,,,,,,,0,4.000000e+000,1.000000e+000,2,2,1.970825e-001,0,,0,
1654729451.129,,1.000000e+003,3.328445e+002,4.629384e-005,8.077460e-009,-3.349784e-002,2.560421e-004,3,9.493242e-001,1.825000e+000,,,,,,,,,,,,,,,,,,0,4.000000e+000,1.000000e+000,2,2,2.033997e-001,0,,0,
1654729570.547,,1.000000e+003,3.308653e+002,4.626293e-005,1.614720e-008,-3.206158e-002,6.356193e-004,3,9.480183e-001,1.825000e+000,,,,,,,,,,,,,,,,,,0,4.000000e+000,1.000000e+000,2,2,2.268982e-001,0,,0,
1654729691.223,,1.000000e+003,3.288657e+002,4.622612e-005,4.877345e-009,-3.204502e-002,3.307369e-004,3,9.490913e-001,1.825000e+000,,,,,,,,,,,,,,,,,,0,4.000000e+000,1.000000e+000,2,2,2.069092e-001,0,,0,
1654729811.849,,1.000000e+003,3.268489e+002,4.620504e-005,3.107250e-008,-3.069155e-002,6.550911e-004,3,9.483060e-001,1.825000e+000,,,,,,,,,,,,,,,,,,0,4.000000e+000,1.000000e+000,2,2,2.127075e-001,0,,0,
1654729929.759,,1.000000e+003,3.248898e+002,4.619285e-005,3.122941e-009,-3.008754e-002,5.717694e-004,3,9.484181e-001,1.825000e+000,,,,,,,,,,,,,,,,,,0,4.000000e+000,1.000000e+000,2,2,2.099915e-001,0,,0,
1654730050.671,,1.000000e+003,3.228871e+002,4.622453e-005,1.615749e-008,-2.962749e-002,4.095304e-004,3,9.481156e-001,1.825000e+000,,,,,,,,,,,,,,,,,,0,4.000000e+000,1.000000e+000,2,2,2.237854e-001,0,,0,
1654730172.102,,1.000000e+003,3.208654e+002,4.620166e-005,1.191039e-008,-2.880505e-002,7.465063e-004,3,9.477295e-001,1.825000e+000,,,,,,,,,,,,,,,,,,0,4.000000e+000,1.000000e+000,2,2,2.044983e-001,0,,0,
1654730292.227,,1.000000e+003,3.188686e+002,4.621360e-005,3.815699e-008,-2.839972e-002,1.391794e-004,3,9.484103e-001,1.825000e+000,,,,,,,,,,,,,,,,,,0,4.000000e+000,1.000000e+000,2,2,2.098999e-001,0,,0,
1654730412.641,,1.000000e+003,3.168622e+002,4.626039e-005,3.610161e-008,-2.751073e-002,2.364702e-005,3,9.485416e-001,1.825000e+000,,,,,,,,,,,,,,,,,,0,4.000000e+000,1.000000e+000,2,2,1.991272e-001,0,,0,
1654730531.405,,1.000000e+003,3.148943e+002,4.632166e-005,2.164193e-008,-2.656538e-002,1.097794e-005,3,9.482026e-001,1.825000e+000,,,,,,,,,,,,,,,,,,0,4.000000e+000,1.000000e+000,2,2,2.200012e-001,0,,0,
1654730652.032,,1.000000e+003,3.128749e+002,4.634897e-005,8.118105e-008,-2.623458e-002,7.028843e-004,3,9.478157e-001,1.825000e+000,,,,,,,,,,,,,,,,,,0,4.000000e+000,1.000000e+000,2,2,2.092896e-001,0,,0,
1654730772.661,,1.000000e+003,3.108810e+002,4.637107e-005,2.343494e-009,-2.664984e-002,3.122462e-004,3,9.483212e-001,1.825000e+000,,,,,,,,,,,,,,,,,,0,4.000000e+000,1.000000e+000,2,2,2.139893e-001,0,,0,
1654730892.800,,1.000000e+003,3.088688e+002,4.643240e-005,2.345550e-008,-2.441845e-002,4.203226e-004,3,9.476473e-001,1.825000e+000,,,,,,,,,,,,,,,,,,0,4.000000e+000,1.000000e+000,2,2,2.186890e-001,0,,0,
1654731014.211,,1.000000e+003,3.068453e+002,4.651844e-005,3.002038e-009,-2.426751e-002,4.215212e-005,3,9.477557e-001,1.825000e+000,,,,,,,,,,,,,,,,,,0,4.000000e+000,1.000000e+000,2,2,2.231140e-001,0,,0,
1654731132.087,,1.000000e+003,3.048812e+002,4.657904e-005,1.107435e-008,-2.368536e-002,2.898017e-004,3,9.482329e-001,1.825000e+000,,,,,,,,,,,,,,,,,,0,4.000000e+000,1.000000e+000,2,2,2.200012e-001,0,,0,
1654731251.712,,1.000000e+003,3.028823e+002,4.662415e-005,1.191811e-008,-2.315372e-002,3.945300e-004,3,9.481356e-001,1.825000e+000,,,,,,,,,,,,,,,,,,0,4.000000e+000,1.000000e+000,2,2,1.879883e-001,0,,0,
1654731372.409,,1.000000e+003,3.008633e+002,4.673231e-005,4.885063e-009,-2.313799e-002,6.657371e-004,3,9.482515e-001,1.825000e+000,,,,,,,,,,,,,,,,,,0,4.000000e+000,1.000000e+000,2,2,2.066956e-001,0,,0,
1654731722.114,,1.000000e+003,3.000087e+002,4.675636e-005,3.920398e-009,-2.371593e-002,1.846638e-004,3,9.488541e-001,1.825000e+000,,,,,,,,,,,,,,,,,,0,4.000000e+000,1.000000e+000,2,2,1.422119e-002,0,,0,