File: spin_crossover/dane/AOT — kopia/Medium AOT/FeTrz_AOT_medium_XTvT_MCE.rso.dat
[Header]
TITLE,MPMS RSO Measurement
BYAPP,MPMS Measurement,1.1,Summary
FILEOPENTIME, 1657274938.969000 7/8/2022, 12:08:58 PM

INFO, APPNAME, MPMS MultiVu Application, Revision 1.60,  Build 081

INFO, NAME, FeTrz_AOT_medium
INFO, WEIGHT, 3.740
INFO, AREA, 0.000
INFO, LENGTH, 0.000
INFO, SHAPE, 0
INFO, COMMENT, w torebce papierowej, na drucie Cu
INFO, SEQUENCE FILE: FeTrz_HTvT_MCE_reverse.seq


INFO, BACKGROUND DATA FILE:, None


STARTUPAXIS,X,4,LINEAR,AUTO,0.000000,0.000000
STARTUPAXIS,Y1,5,LINEAR,AUTO,0.000000,0.000000


STARTUPGROUP,Longitudinal
FIELDGROUP,Longitudinal,1,2,3,4,5,6,7,8,9,10,11,19,20,21,22,23,35
FIELDGROUP,Transverse,1,2,3,4,12,13,14,15,16,17,18,24,25,26,27,28,35

PLOT_APPEARANCE,ALL,HORZ_GRID_ON,VERT_GRID_ON,MARKERS_AND_LINES

[Data]
Time,Comment,Field (Oe),Temperature (K),Long Moment (emu),Long Scan Std Dev,Long Offset (cm),Long Offset Std Dev,Long Algorithm,Long Reg Fit,Long Reg Factor,Trans Moment (emu),Trans Scan Std Dev,Trans Offset (cm),Trans Offset Std Dev,Trans Algorithm,Trans Reg Fit,Trans Reg Factor,Long Moment [w/o ABS] (emu),Long Scan Std Dev [w/o ABS],Long Offset [w/o ABS] (cm),Long Offset Std Dev [w/o ABS],Long Reg Fit [w/o ABS],Trans Moment [w/o ABS] (emu),Trans Scan Std Dev [w/o ABS],Trans Offset [w/o ABS] (cm),Trans Offset Std Dev [w/o ABS],Trans Reg Fit [w/o ABS],RSO Position (deg),Amplitude (cm),Frequency,Cycles to Average,Scans per Measurement,Delta Temp (K),Error,EC Comp. Running,Using ABS,
1657274938.968,,7.000000e+004,4.000002e+002,6.681458e-003,3.207112e-007,-1.243588e-001,8.369311e-005,3,9.714098e-001,1.825000e+000,,,,,,,,,,,,,,,,,,0,4.000000e+000,1.000000e+000,2,2,1.300049e-002,0,,0,
1657275816.863,,7.000000e+004,3.704447e+002,7.043207e-003,3.498847e-006,-1.111850e-001,6.080210e-005,3,9.742169e-001,1.825000e+000,,,,,,,,,,,,,,,,,,0,4.000000e+000,1.000000e+000,2,2,9.303894e-001,0,,0,
1657276542.494,,7.000000e+004,3.435316e+002,2.743772e-003,2.075571e-004,-7.649614e-003,1.668293e-002,3,9.368943e-001,1.825000e+000,,,,,,,,,,,,,,,,,,0,4.000000e+000,1.000000e+000,2,2,7.941895e-001,0,,0,
1657277502.331,,7.000000e+004,3.154565e+002,2.528220e-003,4.807046e-006,1.577278e-002,4.633507e-003,3,9.337888e-001,1.825000e+000,,,,,,,,,,,,,,,,,,0,4.000000e+000,1.000000e+000,2,2,7.651062e-001,0,,0,
1657278839.686,,7.000000e+004,3.112709e+002,2.529304e-003,2.182911e-006,1.746837e-002,3.223826e-004,3,9.322395e-001,1.825000e+000,,,,,,,,,,,,,,,,,,0,4.000000e+000,1.000000e+000,2,2,3.679810e-001,0,,0,
1657279684.513,,7.000000e+004,3.392820e+002,2.497951e-003,1.429799e-005,3.586970e-003,1.967504e-003,3,9.303838e-001,1.825000e+000,,,,,,,,,,,,,,,,,,0,4.000000e+000,1.000000e+000,2,2,4.143982e-001,0,,0,
1657280524.055,,7.000000e+004,3.672917e+002,2.644965e-003,3.133684e-006,-1.757340e-002,2.616937e-004,3,9.359839e-001,1.825000e+000,,,,,,,,,,,,,,,,,,0,4.000000e+000,1.000000e+000,2,2,4.134216e-001,0,,0,
1657281361.954,,7.000000e+004,3.952142e+002,6.709326e-003,1.977280e-006,-1.220379e-001,1.024853e-004,3,9.702338e-001,1.825000e+000,,,,,,,,,,,,,,,,,,0,4.000000e+000,1.000000e+000,2,2,4.055786e-001,0,,0,
1657282930.070,,6.500000e+004,3.775702e+002,6.506631e-003,3.459005e-006,-1.102560e-001,1.693777e-005,3,9.743360e-001,1.825000e+000,,,,,,,,,,,,,,,,,,0,4.000000e+000,1.000000e+000,2,2,6.913147e-001,0,,0,
1657283651.296,,6.500000e+004,3.486002e+002,6.221931e-003,1.370418e-004,-9.384990e-002,1.197123e-003,3,9.731227e-001,1.825000e+000,,,,,,,,,,,,,,,,,,0,4.000000e+000,1.000000e+000,2,2,7.799988e-001,0,,0,
1657284603.212,,6.500000e+004,3.217233e+002,2.391865e-003,5.049390e-007,1.748979e-002,3.251498e-005,3,9.338236e-001,1.825000e+000,,,,,,,,,,,,,,,,,,0,4.000000e+000,1.000000e+000,2,2,4.689026e-001,0,,0,
1657285892.883,,6.500000e+004,3.052759e+002,2.403500e-003,1.157063e-006,2.024884e-002,5.656371e-005,3,9.325969e-001,1.825000e+000,,,,,,,,,,,,,,,,,,0,4.000000e+000,1.000000e+000,2,2,4.999084e-001,0,,0,
1657286718.174,,6.500000e+004,3.332758e+002,2.377618e-003,1.655252e-006,5.823058e-003,3.363668e-004,3,9.339619e-001,1.825000e+000,,,,,,,,,,,,,,,,,,0,4.000000e+000,1.000000e+000,2,2,4.078064e-001,0,,0,
1657287564.555,,6.500000e+004,3.614904e+002,2.463776e-003,9.138952e-007,-1.277820e-002,7.010799e-004,3,9.364853e-001,1.825000e+000,,,,,,,,,,,,,,,,,,0,4.000000e+000,1.000000e+000,2,2,4.102783e-001,0,,0,
1657288398.319,,6.500000e+004,3.892791e+002,6.353318e-003,2.550872e-006,-1.202016e-001,5.402172e-005,3,9.726617e-001,1.825000e+000,,,,,,,,,,,,,,,,,,0,4.000000e+000,1.000000e+000,2,2,4.053040e-001,0,,0,
1657289737.070,,6.000000e+004,3.836396e+002,5.919237e-003,4.545604e-006,-1.071748e-001,3.662034e-005,3,9.717003e-001,1.825000e+000,,,,,,,,,,,,,,,,,,0,4.000000e+000,1.000000e+000,2,2,5.718079e-001,0,,0,
1657290770.853,,6.000000e+004,3.553547e+002,6.195312e-003,3.125123e-006,-1.004440e-001,2.459585e-004,3,9.754437e-001,1.825000e+000,,,,,,,,,,,,,,,,,,0,4.000000e+000,1.000000e+000,2,2,1.035187e+000,0,,0,
1657291477.810,,6.000000e+004,3.276638e+002,2.247604e-003,1.194863e-005,1.587543e-002,5.131853e-004,3,9.346105e-001,1.825000e+000,,,,,,,,,,,,,,,,,,0,4.000000e+000,1.000000e+000,2,2,5.644226e-001,0,,0,
1657292671.195,,6.000000e+004,3.001031e+002,2.267668e-003,8.698056e-006,2.417747e-002,1.278514e-003,3,9.343324e-001,1.825000e+000,,,,,,,,,,,,,,,,,,0,4.000000e+000,1.000000e+000,2,2,0.000000e+000,0,,0,
1657293757.399,,6.000000e+004,3.272708e+002,2.224175e-003,6.796673e-006,6.221698e-003,4.001239e-003,3,9.345912e-001,1.825000e+000,,,,,,,,,,,,,,,,,,0,4.000000e+000,1.000000e+000,2,2,4.093933e-001,0,,0,
1657294596.502,,6.000000e+004,3.552631e+002,2.265604e-003,5.688014e-006,-1.005976e-002,1.238101e-003,3,9.350421e-001,1.825000e+000,,,,,,,,,,,,,,,,,,0,4.000000e+000,1.000000e+000,2,2,4.057007e-001,0,,0,
1657295436.088,,6.000000e+004,3.832379e+002,5.941594e-003,9.433651e-007,-1.184956e-001,3.240039e-005,3,9.736133e-001,1.825000e+000,,,,,,,,,,,,,,,,,,0,4.000000e+000,1.000000e+000,2,2,4.161072e-001,0,,0,
1657296852.325,,5.500000e+004,3.893499e+002,5.370275e-003,3.032268e-006,-1.092479e-001,9.794928e-005,3,9.706738e-001,1.825000e+000,,,,,,,,,,,,,,,,,,0,4.000000e+000,1.000000e+000,2,2,8.109131e-001,0,,0,
1657297620.110,,5.500000e+004,3.618326e+002,5.654339e-003,1.579190e-006,-1.002960e-001,6.049126e-005,3,9.748888e-001,1.825000e+000,,,,,,,,,,,,,,,,,,0,4.000000e+000,1.000000e+000,2,2,2.635193e-001,0,,0,
1657298592.262,,5.500000e+004,3.330546e+002,2.076481e-003,6.256173e-007,1.005350e-002,1.995212e-004,3,9.354018e-001,1.825000e+000,,,,,,,,,,,,,,,,,,0,4.000000e+000,1.000000e+000,2,2,8.323059e-001,0,,0,
1657299486.137,,5.500000e+004,3.058044e+002,2.084264e-003,1.514652e-007,2.030955e-002,4.009087e-005,3,9.345253e-001,1.825000e+000,,,,,,,,,,,,,,,,,,0,4.000000e+000,1.000000e+000,2,2,3.247070e-001,0,,0,
1657300786.455,,5.500000e+004,3.214747e+002,2.058052e-003,3.905169e-007,1.055283e-002,1.359657e-004,3,9.342149e-001,1.825000e+000,,,,,,,,,,,,,,,,,,0,4.000000e+000,1.000000e+000,2,2,4.106140e-001,0,,0,
1657301620.135,,5.500000e+004,3.492839e+002,2.080713e-003,5.968060e-007,-6.181403e-003,2.372472e-005,3,9.356988e-001,1.825000e+000,,,,,,,,,,,,,,,,,,0,4.000000e+000,1.000000e+000,2,2,4.111023e-001,0,,0,
1657302458.611,,5.500000e+004,3.772477e+002,5.510759e-003,1.155746e-006,-1.170225e-001,7.918866e-005,3,9.742807e-001,1.825000e+000,,,,,,,,,,,,,,,,,,0,4.000000e+000,1.000000e+000,2,2,4.140930e-001,0,,0,
1657303964.788,,5.000000e+004,3.955441e+002,4.832877e-003,2.604214e-006,-1.131161e-001,2.594560e-004,3,9.705509e-001,1.825000e+000,,,,,,,,,,,,,,,,,,0,4.000000e+000,1.000000e+000,2,2,7.867126e-001,0,,0,
1657304712.234,,5.000000e+004,3.666511e+002,5.120282e-003,2.189661e-006,-1.026291e-001,8.048995e-005,3,9.747834e-001,1.825000e+000,,,,,,,,,,,,,,,,,,0,4.000000e+000,1.000000e+000,2,2,6.504211e-001,0,,0,
1657305700.538,,5.000000e+004,3.396669e+002,1.917672e-003,1.502387e-006,3.906770e-003,1.923811e-004,3,9.366438e-001,1.825000e+000,,,,,,,,,,,,,,,,,,0,4.000000e+000,1.000000e+000,2,2,5.630188e-001,0,,0,
1657306411.338,,5.000000e+004,3.116491e+002,1.903779e-003,2.778235e-007,1.813827e-002,2.726559e-004,3,9.350641e-001,1.825000e+000,,,,,,,,,,,,,,,,,,0,4.000000e+000,1.000000e+000,2,2,5.762939e-001,0,,0,
1657307808.238,,5.000000e+004,3.152790e+002,1.900067e-003,1.326827e-005,3.884698e-003,1.186625e-002,3,9.297535e-001,1.825000e+000,,,,,,,,,,,,,,,,,,0,4.000000e+000,1.000000e+000,2,2,4.018860e-001,0,,0,
1657308651.221,,5.000000e+004,3.433259e+002,1.893636e-003,6.717154e-007,-3.596267e-003,1.872038e-004,3,9.356159e-001,1.825000e+000,,,,,,,,,,,,,,,,,,0,4.000000e+000,1.000000e+000,2,2,4.059143e-001,0,,0,
1657309489.899,,5.000000e+004,3.712937e+002,4.792020e-003,5.269541e-005,-1.103738e-001,1.097583e-003,3,9.733310e-001,1.825000e+000,,,,,,,,,,,,,,,,,,0,4.000000e+000,1.000000e+000,2,2,4.116821e-001,0,,0,
1657310329.999,,5.000000e+004,3.992832e+002,4.797633e-003,1.481067e-006,-1.202528e-001,7.222916e-005,3,9.699788e-001,1.825000e+000,,,,,,,,,,,,,,,,,,0,4.000000e+000,1.000000e+000,2,2,4.256897e-001,0,,0,
1657311833.062,,4.500000e+004,3.731452e+002,4.568920e-003,2.476786e-006,-1.061499e-001,2.231623e-004,3,9.747198e-001,1.825000e+000,,,,,,,,,,,,,,,,,,0,4.000000e+000,1.000000e+000,2,2,9.783020e-001,0,,0,
1657312551.067,,4.500000e+004,3.456555e+002,3.643178e-003,1.422471e-004,-8.101619e-002,2.700802e-003,3,9.681112e-001,1.825000e+000,,,,,,,,,,,,,,,,,,0,4.000000e+000,1.000000e+000,2,2,5.267029e-001,0,,0,
1657313512.938,,4.500000e+004,3.174898e+002,1.720039e-003,9.894631e-008,1.467563e-002,2.992327e-004,3,9.352766e-001,1.825000e+000,,,,,,,,,,,,,,,,,,0,4.000000e+000,1.000000e+000,2,2,8.239746e-001,0,,0,
1657314841.665,,4.500000e+004,3.093027e+002,1.732840e-003,1.437487e-005,1.308895e-002,7.687196e-004,3,9.345925e-001,1.825000e+000,,,,,,,,,,,,,,,,,,0,4.000000e+000,1.000000e+000,2,2,4.387207e-001,0,,0,
1657315682.208,,4.500000e+004,3.372690e+002,1.709029e-003,2.127922e-007,-5.536511e-004,4.108535e-006,3,9.354086e-001,1.825000e+000,,,,,,,,,,,,,,,,,,0,4.000000e+000,1.000000e+000,2,2,4.182129e-001,0,,0,
1657316520.387,,4.500000e+004,3.652503e+002,2.058225e-003,2.350938e-005,-3.758760e-002,1.478208e-003,3,9.464171e-001,1.825000e+000,,,,,,,,,,,,,,,,,,0,4.000000e+000,1.000000e+000,2,2,3.654785e-001,0,,0,
1657317360.168,,4.500000e+004,3.932380e+002,4.387824e-003,1.893645e-006,-1.204541e-001,9.425091e-006,3,9.716946e-001,1.825000e+000,,,,,,,,,,,,,,,,,,0,4.000000e+000,1.000000e+000,2,2,4.139099e-001,0,,0,
1657318933.028,,4.000000e+004,3.797787e+002,4.015750e-003,8.979255e-007,-1.095004e-001,1.277998e-004,3,9.742671e-001,1.825000e+000,,,,,,,,,,,,,,,,,,0,4.000000e+000,1.000000e+000,2,2,3.265991e-001,0,,0,
1657319669.063,,4.000000e+004,3.507072e+002,4.168259e-003,9.213038e-007,-9.769511e-002,2.352690e-004,3,9.752637e-001,1.825000e+000,,,,,,,,,,,,,,,,,,0,4.000000e+000,1.000000e+000,2,2,9.476929e-001,0,,0,
1657320493.367,,4.000000e+004,3.239773e+002,1.534952e-003,3.137964e-007,1.163522e-002,1.976009e-004,3,9.359330e-001,1.825000e+000,,,,,,,,,,,,,,,,,,0,4.000000e+000,1.000000e+000,2,2,2.511597e-002,0,,0,
1657321892.349,,4.000000e+004,3.033515e+002,1.546006e-003,1.473516e-008,1.617870e-002,2.429568e-004,3,9.354043e-001,1.825000e+000,,,,,,,,,,,,,,,,,,0,4.000000e+000,1.000000e+000,2,2,4.353027e-001,0,,0,
1657322705.275,,4.000000e+004,3.312761e+002,1.525261e-003,2.262924e-007,1.788297e-003,9.395891e-005,3,9.353139e-001,1.825000e+000,,,,,,,,,,,,,,,,,,0,4.000000e+000,1.000000e+000,2,2,4.201050e-001,0,,0,
1657323543.415,,4.000000e+004,3.592430e+002,1.591060e-003,1.042229e-006,-1.907978e-002,3.156878e-004,3,9.385276e-001,1.825000e+000,,,,,,,,,,,,,,,,,,0,4.000000e+000,1.000000e+000,2,2,4.049988e-001,0,,0,
1657324385.398,,4.000000e+004,3.873214e+002,3.955016e-003,7.928876e-007,-1.197960e-001,7.865129e-005,3,9.732232e-001,1.825000e+000,,,,,,,,,,,,,,,,,,0,4.000000e+000,1.000000e+000,2,2,4.132080e-001,0,,0,
1657325750.292,,3.500000e+004,3.854714e+002,3.464618e-003,2.693941e-006,-1.082244e-001,1.975107e-005,3,9.716697e-001,1.825000e+000,,,,,,,,,,,,,,,,,,0,4.000000e+000,1.000000e+000,2,2,6.740112e-001,0,,0,
1657326783.461,,3.500000e+004,3.575383e+002,3.638072e-003,1.496872e-006,-1.014365e-001,2.674007e-004,3,9.749907e-001,1.825000e+000,,,,,,,,,,,,,,,,,,0,4.000000e+000,1.000000e+000,2,2,8.942871e-001,0,,0,
1657327487.512,,3.500000e+004,3.294205e+002,1.353340e-003,4.350510e-007,8.034572e-003,3.050049e-005,3,9.360080e-001,1.825000e+000,,,,,,,,,,,,,,,,,,0,4.000000e+000,1.000000e+000,2,2,7.005920e-001,0,,0,
1657328424.434,,3.500000e+004,3.015853e+002,1.360584e-003,1.009458e-005,1.444172e-002,9.214625e-004,3,9.330277e-001,1.825000e+000,,,,,,,,,,,,,,,,,,0,4.000000e+000,1.000000e+000,2,2,5.586853e-001,0,,0,
1657329740.524,,3.500000e+004,3.252475e+002,1.343610e-003,1.408874e-006,2.990073e-003,1.271426e-003,3,9.354867e-001,1.825000e+000,,,,,,,,,,,,,,,,,,0,4.000000e+000,1.000000e+000,2,2,4.125977e-001,0,,0,
1657330580.060,,3.500000e+004,3.532663e+002,1.372605e-003,8.393973e-007,-1.446570e-002,2.208653e-004,3,9.374067e-001,1.825000e+000,,,,,,,,,,,,,,,,,,0,4.000000e+000,1.000000e+000,2,2,4.211121e-001,0,,0,
1657331429.102,,3.500000e+004,3.815399e+002,3.499568e-003,9.273953e-007,-1.182458e-001,5.739874e-005,3,9.734717e-001,1.825000e+000,,,,,,,,,,,,,,,,,,0,4.000000e+000,1.000000e+000,2,2,3.650818e-001,0,,0,
1657332862.284,,3.000000e+004,3.912949e+002,2.934742e-003,2.674678e-006,-1.105786e-001,1.083174e-004,3,9.704452e-001,1.825000e+000,,,,,,,,,,,,,,,,,,0,4.000000e+000,1.000000e+000,2,2,8.689880e-001,0,,0,
1657333613.799,,3.000000e+004,3.634320e+002,3.099115e-003,1.029140e-006,-1.010227e-001,4.620351e-006,3,9.745189e-001,1.825000e+000,,,,,,,,,,,,,,,,,,0,4.000000e+000,1.000000e+000,2,2,5.852966e-001,0,,0,
1657334613.120,,3.000000e+004,3.347885e+002,1.171801e-003,2.161672e-007,3.159900e-003,2.136164e-004,3,9.365338e-001,1.825000e+000,,,,,,,,,,,,,,,,,,0,4.000000e+000,1.000000e+000,2,2,1.047394e+000,0,,0,
1657335375.290,,3.000000e+004,3.078729e+002,1.166668e-003,9.798649e-006,1.312752e-002,2.171769e-003,3,9.319422e-001,1.825000e+000,,,,,,,,,,,,,,,,,,0,4.000000e+000,1.000000e+000,2,2,2.246094e-001,0,,0,
1657336767.832,,3.000000e+004,3.192371e+002,1.161550e-003,1.424102e-007,5.659422e-003,1.046197e-004,3,9.353340e-001,1.825000e+000,,,,,,,,,,,,,,,,,,0,4.000000e+000,1.000000e+000,2,2,4.045105e-001,0,,0,
1657337607.974,,3.000000e+004,3.472891e+002,1.172398e-003,2.029140e-007,-1.092390e-002,1.725255e-004,3,9.368027e-001,1.825000e+000,,,,,,,,,,,,,,,,,,0,4.000000e+000,1.000000e+000,2,2,4.060974e-001,0,,0,
1657338447.232,,3.000000e+004,3.752827e+002,3.037502e-003,2.588080e-007,-1.166324e-001,1.367139e-005,3,9.737288e-001,1.825000e+000,,,,,,,,,,,,,,,,,,0,4.000000e+000,1.000000e+000,2,2,4.096985e-001,0,,0,
1657339949.007,,2.500000e+004,3.978012e+002,2.421821e-003,5.054329e-007,-1.147839e-001,2.538663e-004,3,9.699330e-001,1.825000e+000,,,,,,,,,,,,,,,,,,0,4.000000e+000,1.000000e+000,2,2,3.589172e-001,0,,0,
1657340726.628,,2.500000e+004,3.685035e+002,2.570698e-003,1.437438e-006,-1.036880e-001,2.944326e-004,3,9.742516e-001,1.825000e+000,,,,,,,,,,,,,,,,,,0,4.000000e+000,1.000000e+000,2,2,8.981018e-001,0,,0,
1657341688.309,,2.500000e+004,3.417827e+002,1.022987e-003,2.301366e-006,-6.657329e-003,2.352354e-004,3,9.392677e-001,1.825000e+000,,,,,,,,,,,,,,,,,,0,4.000000e+000,1.000000e+000,2,2,3.180237e-001,0,,0,
1657342411.019,,2.500000e+004,3.136456e+002,9.813342e-004,2.026671e-007,1.091451e-002,1.252795e-004,3,9.356729e-001,1.825000e+000,,,,,,,,,,,,,,,,,,0,4.000000e+000,1.000000e+000,2,2,6.311035e-001,0,,0,
1657343790.219,,2.500000e+004,3.132933e+002,9.777545e-004,2.403687e-007,6.931643e-003,2.352443e-004,3,9.356819e-001,1.825000e+000,,,,,,,,,,,,,,,,,,0,4.000000e+000,1.000000e+000,2,2,4.042053e-001,0,,0,
1657344636.769,,2.500000e+004,3.413974e+002,9.769336e-004,2.386401e-007,-9.009605e-003,2.640006e-004,3,9.360650e-001,1.825000e+000,,,,,,,,,,,,,,,,,,0,4.000000e+000,1.000000e+000,2,2,4.197998e-001,0,,0,
1657345472.951,,2.500000e+004,3.692882e+002,2.337522e-003,3.074464e-005,-1.076015e-001,1.283466e-003,3,9.717867e-001,1.825000e+000,,,,,,,,,,,,,,,,,,0,4.000000e+000,1.000000e+000,2,2,4.179993e-001,0,,0,
1657346312.723,,2.500000e+004,3.972891e+002,2.427123e-003,1.155581e-006,-1.210773e-001,2.678432e-005,3,9.702200e-001,1.825000e+000,,,,,,,,,,,,,,,,,,0,4.000000e+000,1.000000e+000,2,2,4.091187e-001,0,,0,
1657347836.264,,2.000000e+004,3.754453e+002,2.038107e-003,1.534409e-006,-1.083173e-001,3.318906e-004,3,9.740350e-001,1.825000e+000,,,,,,,,,,,,,,,,,,0,4.000000e+000,1.000000e+000,2,2,1.002197e+000,0,,0,
1657348550.346,,2.000000e+004,3.471587e+002,2.030552e-003,1.307869e-005,-9.461090e-002,3.000856e-004,3,9.737417e-001,1.825000e+000,,,,,,,,,,,,,,,,,,0,4.000000e+000,1.000000e+000,2,2,6.379089e-001,0,,0,
1657349509.269,,2.000000e+004,3.195754e+002,7.894023e-004,9.927558e-008,5.905453e-003,3.653309e-005,3,9.364550e-001,1.825000e+000,,,,,,,,,,,,,,,,,,0,4.000000e+000,1.000000e+000,2,2,6.407166e-001,0,,0,
1657350816.212,,2.000000e+004,3.072770e+002,8.016889e-004,1.368991e-005,7.869789e-003,9.475563e-004,3,9.315583e-001,1.825000e+000,,,,,,,,,,,,,,,,,,0,4.000000e+000,1.000000e+000,2,2,4.846191e-001,0,,0,
1657351650.081,,2.000000e+004,3.352476e+002,7.852766e-004,1.856277e-008,-7.134194e-003,3.010322e-004,3,9.362626e-001,1.825000e+000,,,,,,,,,,,,,,,,,,0,4.000000e+000,1.000000e+000,2,2,4.129028e-001,0,,0,
1657352490.027,,2.000000e+004,3.632512e+002,9.141865e-004,8.045644e-006,-3.906406e-002,1.220981e-003,3,9.453919e-001,1.825000e+000,,,,,,,,,,,,,,,,,,0,4.000000e+000,1.000000e+000,2,2,4.144897e-001,0,,0,
1657353329.281,,2.000000e+004,3.912513e+002,1.976345e-003,7.574909e-007,-1.218378e-001,3.883832e-005,3,9.725485e-001,1.825000e+000,,,,,,,,,,,,,,,,,,0,4.000000e+000,1.000000e+000,2,2,4.219055e-001,0,,0,
1657354645.067,,1.500000e+004,3.818169e+002,1.514400e-003,8.520743e-007,-1.092643e-001,3.124140e-006,3,9.731761e-001,1.825000e+000,,,,,,,,,,,,,,,,,,0,4.000000e+000,1.000000e+000,2,2,3.891907e-001,0,,0,
1657355669.102,,1.500000e+004,3.528736e+002,1.581523e-003,5.890681e-007,-1.008922e-001,5.105040e-006,3,9.747078e-001,1.825000e+000,,,,,,,,,,,,,,,,,,0,4.000000e+000,1.000000e+000,2,2,1.030609e+000,0,,0,
1657356394.456,,1.500000e+004,3.256395e+002,5.988004e-004,2.543628e-008,1.746789e-003,7.359053e-005,3,9.365727e-001,1.825000e+000,,,,,,,,,,,,,,,,,,0,4.000000e+000,1.000000e+000,2,2,4.135742e-001,0,,0,
1657357866.953,,1.500000e+004,3.012239e+002,6.042998e-004,2.336187e-007,7.622712e-003,1.054115e-003,3,9.362774e-001,1.825000e+000,,,,,,,,,,,,,,,,,,0,4.000000e+000,1.000000e+000,2,2,3.000183e-001,0,,0,
1657358677.987,,1.500000e+004,3.292561e+002,5.948152e-004,1.828696e-007,-6.990523e-003,5.293365e-004,3,9.363821e-001,1.825000e+000,,,,,,,,,,,,,,,,,,0,4.000000e+000,1.000000e+000,2,2,4.060974e-001,0,,0,
1657359516.405,,1.500000e+004,3.572196e+002,6.160177e-004,2.516463e-007,-2.651392e-002,4.590753e-004,3,9.388222e-001,1.825000e+000,,,,,,,,,,,,,,,,,,0,4.000000e+000,1.000000e+000,2,2,4.207764e-001,0,,0,
1657360357.178,,1.500000e+004,3.852669e+002,1.504445e-003,3.259795e-007,-1.211960e-001,1.149081e-004,3,9.731482e-001,1.825000e+000,,,,,,,,,,,,,,,,,,0,4.000000e+000,1.000000e+000,2,2,4.085999e-001,0,,0,
1657361736.890,,1.000000e+004,3.872122e+002,1.001572e-003,7.079353e-007,-1.116970e-001,1.803622e-004,3,9.714815e-001,1.825000e+000,,,,,,,,,,,,,,,,,,0,4.000000e+000,1.000000e+000,2,2,7.530823e-001,0,,0,
1657362766.354,,1.000000e+004,3.597266e+002,1.053321e-003,4.208923e-007,-1.052319e-001,4.016595e-005,3,9.746171e-001,1.825000e+000,,,,,,,,,,,,,,,,,,0,4.000000e+000,1.000000e+000,2,2,4.894714e-001,0,,0,
1657363480.549,,1.000000e+004,3.312938e+002,4.070156e-004,5.044040e-008,-7.099599e-003,4.032643e-004,3,9.366174e-001,1.825000e+000,,,,,,,,,,,,,,,,,,0,4.000000e+000,1.000000e+000,2,2,8.582764e-001,0,,0,
1657364407.143,,1.000000e+004,3.036728e+002,4.100791e-004,4.702420e-008,2.311384e-003,4.559171e-004,3,9.366091e-001,1.825000e+000,,,,,,,,,,,,,,,,,,0,4.000000e+000,1.000000e+000,2,2,5.162048e-001,0,,0,
1657365703.013,,1.000000e+004,3.233337e+002,4.043271e-004,9.386317e-008,-9.195185e-003,2.858702e-004,3,9.363060e-001,1.825000e+000,,,,,,,,,,,,,,,,,,0,4.000000e+000,1.000000e+000,2,2,3.740845e-001,0,,0,
1657366542.034,,1.000000e+004,3.513326e+002,4.110290e-004,1.307622e-007,-2.601325e-002,7.591504e-004,3,9.376054e-001,1.825000e+000,,,,,,,,,,,,,,,,,,0,4.000000e+000,1.000000e+000,2,2,4.161987e-001,0,,0,
1657367379.417,,1.000000e+004,3.792430e+002,1.019609e-003,3.048238e-007,-1.208492e-001,1.083279e-004,3,9.736723e-001,1.825000e+000,,,,,,,,,,,,,,,,,,0,4.000000e+000,1.000000e+000,2,2,4.187012e-001,0,,0,
1657368832.414,,9.000000e+003,3.933731e+002,8.909531e-004,5.374958e-007,-1.151149e-001,9.704312e-006,3,9.702603e-001,1.825000e+000,,,,,,,,,,,,,,,,,,0,4.000000e+000,1.000000e+000,2,2,9.286804e-001,0,,0,
1657369575.081,,9.000000e+003,3.652155e+002,9.430049e-004,2.735018e-007,-1.053398e-001,2.366229e-004,3,9.743850e-001,1.825000e+000,,,,,,,,,,,,,,,,,,0,4.000000e+000,1.000000e+000,2,2,7.094116e-001,0,,0,
1657370572.589,,9.000000e+003,3.374763e+002,3.708900e-004,1.259055e-007,-1.292020e-002,1.205334e-005,3,9.380890e-001,1.825000e+000,,,,,,,,,,,,,,,,,,0,4.000000e+000,1.000000e+000,2,2,9.197083e-001,0,,0,
1657371293.953,,9.000000e+003,3.097420e+002,3.703525e-004,1.146485e-007,1.475381e-004,4.405028e-004,3,9.363434e-001,1.825000e+000,,,,,,,,,,,,,,,,,,0,4.000000e+000,1.000000e+000,2,2,4.400940e-001,0,,0,
1657372710.171,,9.000000e+003,3.172319e+002,3.672878e-004,1.554988e-007,-7.653543e-003,2.884488e-004,3,9.362085e-001,1.825000e+000,,,,,,,,,,,,,,,,,,0,4.000000e+000,1.000000e+000,2,2,3.991089e-001,0,,0,
1657373559.846,,9.000000e+003,3.452681e+002,3.691331e-004,4.768274e-008,-2.367278e-002,3.692064e-005,3,9.376009e-001,1.825000e+000,,,,,,,,,,,,,,,,,,0,4.000000e+000,1.000000e+000,2,2,4.299011e-001,0,,0,
1657374400.680,,9.000000e+003,3.732996e+002,9.281154e-004,1.835281e-007,-1.194616e-001,2.085848e-004,3,9.737566e-001,1.825000e+000,,,,,,,,,,,,,,,,,,0,4.000000e+000,1.000000e+000,2,2,4.050903e-001,0,,0,
1657375839.073,,8.000000e+003,4.000067e+002,7.833304e-004,2.428383e-008,-1.195280e-001,9.391898e-005,3,9.697258e-001,1.825000e+000,,,,,,,,,,,,,,,,,,0,4.000000e+000,1.000000e+000,2,2,1.287842e-002,0,,0,
1657376697.650,,8.000000e+003,3.708133e+002,8.330818e-004,6.224892e-007,-1.087447e-001,2.076364e-004,3,9.741826e-001,1.825000e+000,,,,,,,,,,,,,,,,,,0,4.000000e+000,1.000000e+000,2,2,9.100952e-001,0,,0,
1657377432.039,,8.000000e+003,3.437608e+002,6.102442e-004,2.270884e-005,-7.921621e-002,2.418539e-003,3,9.647912e-001,1.825000e+000,,,,,,,,,,,,,,,,,,0,4.000000e+000,1.000000e+000,2,2,3.501892e-001,0,,0,
1657378388.508,,8.000000e+003,3.154250e+002,3.309152e-004,5.838409e-008,-4.505798e-003,8.284477e-004,3,9.368149e-001,1.825000e+000,,,,,,,,,,,,,,,,,,0,4.000000e+000,1.000000e+000,2,2,7.255859e-001,0,,0,
1657379735.247,,8.000000e+003,3.112154e+002,3.305820e-004,8.003374e-008,-7.989890e-003,1.788607e-006,3,9.368615e-001,1.825000e+000,,,,,,,,,,,,,,,,,,0,4.000000e+000,1.000000e+000,2,2,4.214783e-001,0,,0,
1657380585.674,,8.000000e+003,3.393119e+002,3.291870e-004,5.657309e-008,-2.211840e-002,8.371286e-005,3,9.373726e-001,1.825000e+000,,,,,,,,,,,,,,,,,,0,4.000000e+000,1.000000e+000,2,2,3.960876e-001,0,,0,
1657381426.981,,8.000000e+003,3.672617e+002,6.628804e-004,1.214455e-005,-9.916505e-002,1.951141e-003,3,9.680911e-001,1.825000e+000,,,,,,,,,,,,,,,,,,0,4.000000e+000,1.000000e+000,2,2,4.024048e-001,0,,0,
1657382267.604,,8.000000e+003,3.953093e+002,7.932691e-004,3.280375e-007,-1.246832e-001,3.034889e-004,3,9.712396e-001,1.825000e+000,,,,,,,,,,,,,,,,,,0,4.000000e+000,1.000000e+000,2,2,4.055786e-001,0,,0,
1657383813.866,,7.000000e+003,3.774810e+002,7.240194e-004,3.093924e-007,-1.126839e-001,1.853408e-004,3,9.739698e-001,1.825000e+000,,,,,,,,,,,,,,,,,,0,4.000000e+000,1.000000e+000,2,2,8.637085e-001,0,,0,
1657384531.454,,7.000000e+003,3.488636e+002,7.493192e-004,8.770166e-007,-1.008961e-001,1.545683e-004,3,9.746664e-001,1.825000e+000,,,,,,,,,,,,,,,,,,0,4.000000e+000,1.000000e+000,2,2,6.640015e-001,0,,0,
1657385482.029,,7.000000e+003,3.216452e+002,2.922766e-004,8.089808e-008,-1.027825e-002,3.641521e-004,3,9.369586e-001,1.825000e+000,,,,,,,,,,,,,,,,,,0,4.000000e+000,1.000000e+000,2,2,6.166992e-001,0,,0,
1657386785.235,,7.000000e+003,3.054672e+002,2.940297e-004,1.794534e-008,-7.246195e-003,1.296852e-004,3,9.364691e-001,1.825000e+000,,,,,,,,,,,,,,,,,,0,4.000000e+000,1.000000e+000,2,2,4.563904e-001,0,,0,
1657387607.622,,7.000000e+003,3.333135e+002,2.907480e-004,4.634507e-008,-2.140457e-002,2.135002e-006,3,9.370646e-001,1.825000e+000,,,,,,,,,,,,,,,,,,0,4.000000e+000,1.000000e+000,2,2,4.168091e-001,0,,0,
1657388453.699,,7.000000e+003,3.615246e+002,3.203270e-004,1.597629e-006,-4.545119e-002,7.546630e-004,3,9.430484e-001,1.825000e+000,,,,,,,,,,,,,,,,,,0,4.000000e+000,1.000000e+000,2,2,4.211121e-001,0,,0,
1657389285.658,,7.000000e+003,3.892761e+002,7.075848e-004,1.000988e-007,-1.248357e-001,8.438853e-005,3,9.728033e-001,1.825000e+000,,,,,,,,,,,,,,,,,,0,4.000000e+000,1.000000e+000,2,2,3.930054e-001,0,,0,
1657390611.056,,6.000000e+003,3.835920e+002,6.151318e-004,4.471929e-007,-1.132453e-001,2.946855e-004,3,9.726779e-001,1.825000e+000,,,,,,,,,,,,,,,,,,0,4.000000e+000,1.000000e+000,2,2,6.430969e-001,0,,0,
1657391629.561,,6.000000e+003,3.552990e+002,6.440337e-004,1.765311e-007,-1.051169e-001,3.821982e-004,3,9.746673e-001,1.825000e+000,,,,,,,,,,,,,,,,,,0,4.000000e+000,1.000000e+000,2,2,1.034912e+000,0,,0,
1657392343.702,,6.000000e+003,3.277086e+002,2.536738e-004,2.339892e-008,-1.455811e-002,1.191505e-004,3,9.373576e-001,1.825000e+000,,,,,,,,,,,,,,,,,,0,4.000000e+000,1.000000e+000,2,2,5.047913e-001,0,,0,
1657393523.901,,6.000000e+003,3.000818e+002,2.565965e-004,4.696246e-008,-6.717547e-003,1.003065e-003,3,9.367175e-001,1.825000e+000,,,,,,,,,,,,,,,,,,0,4.000000e+000,1.000000e+000,2,2,0.000000e+000,0,,0,
1657394610.454,,6.000000e+003,3.272793e+002,2.520588e-004,2.856437e-008,-2.043782e-002,1.269213e-004,3,9.367400e-001,1.825000e+000,,,,,,,,,,,,,,,,,,0,4.000000e+000,1.000000e+000,2,2,4.093933e-001,0,,0,
1657395451.257,,6.000000e+003,3.553315e+002,2.591331e-004,1.411343e-007,-3.868756e-002,9.067368e-005,3,9.394017e-001,1.825000e+000,,,,,,,,,,,,,,,,,,0,4.000000e+000,1.000000e+000,2,2,4.161987e-001,0,,0,
1657396291.850,,6.000000e+003,3.833300e+002,6.156830e-004,2.135331e-007,-1.239645e-001,1.056306e-005,3,9.735012e-001,1.825000e+000,,,,,,,,,,,,,,,,,,0,4.000000e+000,1.000000e+000,2,2,4.043884e-001,0,,0,
1657397696.384,,5.000000e+003,3.892271e+002,5.077980e-004,3.230984e-007,-1.155882e-001,1.627975e-004,3,9.710293e-001,1.825000e+000,,,,,,,,,,,,,,,,,,0,4.000000e+000,1.000000e+000,2,2,7.858276e-001,0,,0,
1657398471.003,,5.000000e+003,3.617800e+002,5.350658e-004,1.053671e-007,-1.064305e-001,1.242858e-004,3,9.744848e-001,1.825000e+000,,,,,,,,,,,,,,,,,,0,4.000000e+000,1.000000e+000,2,2,2.844849e-001,0,,0,
1657399428.541,,5.000000e+003,3.332650e+002,2.149230e-004,2.163298e-010,-2.138233e-002,6.668290e-004,3,9.379292e-001,1.825000e+000,,,,,,,,,,,,,,,,,,0,4.000000e+000,1.000000e+000,2,2,7.179871e-001,0,,0,
1657400333.296,,5.000000e+003,3.057417e+002,2.159513e-004,1.829519e-008,-1.219766e-002,9.727690e-005,3,9.373578e-001,1.825000e+000,,,,,,,,,,,,,,,,,,0,4.000000e+000,1.000000e+000,2,2,3.984070e-001,0,,0,
1657401635.281,,5.000000e+003,3.214233e+002,2.134466e-004,7.768774e-009,-2.155361e-002,1.761159e-004,3,9.369269e-001,1.825000e+000,,,,,,,,,,,,,,,,,,0,4.000000e+000,1.000000e+000,2,2,4.515076e-001,0,,0,
1657402467.210,,5.000000e+003,3.492153e+002,2.159773e-004,4.363886e-008,-3.726765e-002,1.646677e-004,3,9.385580e-001,1.825000e+000,,,,,,,,,,,,,,,,,,0,4.000000e+000,1.000000e+000,2,2,4.109192e-001,0,,0,
1657403307.712,,5.000000e+003,3.772219e+002,5.208728e-004,1.229009e-007,-1.232051e-001,1.509015e-004,3,9.733512e-001,1.825000e+000,,,,,,,,,,,,,,,,,,0,4.000000e+000,1.000000e+000,2,2,4.025879e-001,0,,0,
1657404797.046,,4.000000e+003,3.955822e+002,4.034625e-004,2.793875e-007,-1.205240e-001,8.970430e-005,3,9.699831e-001,1.825000e+000,,,,,,,,,,,,,,,,,,0,4.000000e+000,1.000000e+000,2,2,6.979980e-001,0,,0,
1657405544.727,,4.000000e+003,3.668327e+002,4.278529e-004,1.121172e-007,-1.098357e-001,1.246651e-004,3,9.741300e-001,1.825000e+000,,,,,,,,,,,,,,,,,,0,4.000000e+000,1.000000e+000,2,2,6.400146e-001,0,,0,
1657406530.318,,4.000000e+003,3.396162e+002,1.774524e-004,3.753910e-007,-3.033780e-002,6.310081e-004,3,9.392215e-001,1.825000e+000,,,,,,,,,,,,,,,,,,0,4.000000e+000,1.000000e+000,2,2,6.549072e-001,0,,0,
1657407243.158,,4.000000e+003,3.117182e+002,1.755592e-004,7.034078e-008,-1.796019e-002,4.422416e-004,3,9.372909e-001,1.825000e+000,,,,,,,,,,,,,,,,,,0,4.000000e+000,1.000000e+000,2,2,5.152283e-001,0,,0,
1657408646.152,,4.000000e+003,3.153302e+002,1.744411e-004,4.861911e-008,-2.412243e-002,1.604307e-004,3,9.366173e-001,1.825000e+000,,,,,,,,,,,,,,,,,,0,4.000000e+000,1.000000e+000,2,2,4.334717e-001,0,,0,
1657409485.956,,4.000000e+003,3.432623e+002,1.746910e-004,4.980243e-008,-3.870243e-002,2.692077e-004,3,9.382807e-001,1.825000e+000,,,,,,,,,,,,,,,,,,0,4.000000e+000,1.000000e+000,2,2,4.529114e-001,0,,0,
1657410323.840,,4.000000e+003,3.712186e+002,4.236343e-004,1.169534e-007,-1.225072e-001,1.582087e-005,3,9.737679e-001,1.825000e+000,,,,,,,,,,,,,,,,,,0,4.000000e+000,1.000000e+000,2,2,4.226074e-001,0,,0,
1657411166.066,,4.000000e+003,3.992831e+002,4.010250e-004,1.750699e-007,-1.273056e-001,6.765623e-005,3,9.699723e-001,1.825000e+000,,,,,,,,,,,,,,,,,,0,4.000000e+000,1.000000e+000,2,2,3.740234e-001,0,,0,
1657412654.118,,3.000000e+003,3.730610e+002,3.208815e-004,1.756462e-007,-1.149492e-001,1.009364e-004,3,9.739740e-001,1.825000e+000,,,,,,,,,,,,,,,,,,0,4.000000e+000,1.000000e+000,2,2,1.045502e+000,0,,0,
1657413373.845,,3.000000e+003,3.455717e+002,3.095258e-004,3.138479e-006,-1.008485e-001,3.469634e-004,3,9.726155e-001,1.825000e+000,,,,,,,,,,,,,,,,,,0,4.000000e+000,1.000000e+000,2,2,5.264893e-001,0,,0,
1657414330.645,,3.000000e+003,3.174958e+002,1.347020e-004,3.786631e-009,-2.625636e-002,7.796205e-004,3,9.381880e-001,1.825000e+000,,,,,,,,,,,,,,,,,,0,4.000000e+000,1.000000e+000,2,2,7.997131e-001,0,,0,
1657415660.467,,3.000000e+003,3.093292e+002,1.349720e-004,3.809268e-008,-2.676436e-002,2.048205e-005,3,9.374844e-001,1.825000e+000,,,,,,,,,,,,,,,,,,0,4.000000e+000,1.000000e+000,2,2,4.387207e-001,0,,0,
1657416501.098,,3.000000e+003,3.373235e+002,1.339994e-004,4.110758e-008,-4.151528e-002,2.353454e-004,3,9.382547e-001,1.825000e+000,,,,,,,,,,,,,,,,,,0,4.000000e+000,1.000000e+000,2,2,4.183960e-001,0,,0,
1657417346.061,,3.000000e+003,3.654682e+002,2.235635e-004,4.763119e-006,-9.542444e-002,1.579163e-003,3,9.628466e-001,1.825000e+000,,,,,,,,,,,,,,,,,,0,4.000000e+000,1.000000e+000,2,2,4.521179e-001,0,,0,
1657418179.116,,3.000000e+003,3.932694e+002,3.085510e-004,1.942912e-007,-1.300441e-001,1.826855e-004,3,9.716356e-001,1.825000e+000,,,,,,,,,,,,,,,,,,0,4.000000e+000,1.000000e+000,2,2,4.140015e-001,0,,0,
1657419735.957,,2.500000e+003,3.797263e+002,2.659662e-004,9.596229e-008,-1.195584e-001,1.881646e-004,3,9.734826e-001,1.825000e+000,,,,,,,,,,,,,,,,,,0,4.000000e+000,1.000000e+000,2,2,4.432068e-001,0,,0,
1657420478.088,,2.500000e+003,3.501110e+002,2.770374e-004,4.128251e-008,-1.074843e-001,3.943575e-004,3,9.742700e-001,1.825000e+000,,,,,,,,,,,,,,,,,,0,4.000000e+000,1.000000e+000,2,2,1.052917e+000,0,,0,
1657421388.325,,2.500000e+003,3.238355e+002,1.142507e-004,2.984030e-009,-3.369176e-002,2.794995e-004,3,9.385294e-001,1.825000e+000,,,,,,,,,,,,,,,,,,0,4.000000e+000,1.000000e+000,2,2,2.919006e-001,0,,0,
1657422695.551,,2.500000e+003,3.033079e+002,1.151897e-004,1.234257e-008,-2.853938e-002,2.798906e-004,3,9.379549e-001,1.825000e+000,,,,,,,,,,,,,,,,,,0,4.000000e+000,1.000000e+000,2,2,5.367126e-001,0,,0,
1657423509.918,,2.500000e+003,3.312936e+002,1.136472e-004,4.023295e-008,-4.254609e-002,2.875732e-005,3,9.382577e-001,1.825000e+000,,,,,,,,,,,,,,,,,,0,4.000000e+000,1.000000e+000,2,2,4.203186e-001,0,,0,
1657424350.553,,2.500000e+003,3.593235e+002,1.197257e-004,2.179011e-007,-6.160117e-002,5.257029e-004,3,9.418542e-001,1.825000e+000,,,,,,,,,,,,,,,,,,0,4.000000e+000,1.000000e+000,2,2,4.468079e-001,0,,0,
1657425187.740,,2.500000e+003,3.872577e+002,2.622014e-004,8.456124e-008,-1.302064e-001,8.503126e-005,3,9.727508e-001,1.825000e+000,,,,,,,,,,,,,,,,,,0,4.000000e+000,1.000000e+000,2,2,4.251709e-001,0,,0,
1657426541.921,,2.000000e+003,3.851169e+002,2.121624e-004,2.602691e-007,-1.201985e-001,3.725571e-004,3,9.716601e-001,1.825000e+000,,,,,,,,,,,,,,,,,,0,4.000000e+000,1.000000e+000,2,2,7.204895e-001,0,,0,
1657427562.391,,2.000000e+003,3.575382e+002,2.223632e-004,9.020002e-008,-1.130175e-001,1.643727e-004,3,9.742072e-001,1.825000e+000,,,,,,,,,,,,,,,,,,0,4.000000e+000,1.000000e+000,2,2,8.943787e-001,0,,0,
1657428276.728,,2.000000e+003,3.291008e+002,9.381579e-005,9.286508e-009,-4.006833e-002,7.873268e-004,3,9.394454e-001,1.825000e+000,,,,,,,,,,,,,,,,,,0,4.000000e+000,1.000000e+000,2,2,6.301270e-001,0,,0,
1657429204.500,,2.000000e+003,3.015353e+002,9.476070e-005,6.265434e-008,-3.178088e-002,1.632374e-004,3,9.385411e-001,1.825000e+000,,,,,,,,,,,,,,,,,,0,4.000000e+000,1.000000e+000,2,2,6.730957e-001,0,,0,
1657430518.242,,2.000000e+003,3.252959e+002,9.323635e-005,2.903255e-008,-4.558474e-002,1.837629e-004,3,9.381328e-001,1.825000e+000,,,,,,,,,,,,,,,,,,0,4.000000e+000,1.000000e+000,2,2,4.547119e-001,0,,0,
1657431357.732,,2.000000e+003,3.533264e+002,9.503565e-005,5.569331e-008,-6.102705e-002,1.189595e-005,3,9.406718e-001,1.825000e+000,,,,,,,,,,,,,,,,,,0,4.000000e+000,1.000000e+000,2,2,4.212952e-001,0,,0,
1657432207.492,,2.000000e+003,3.816489e+002,2.139339e-004,2.557005e-008,-1.305586e-001,3.792900e-004,3,9.730957e-001,1.825000e+000,,,,,,,,,,,,,,,,,,0,4.000000e+000,1.000000e+000,2,2,4.243164e-001,0,,0,
1657433630.090,,1.500000e+003,3.911863e+002,1.590740e-004,2.910149e-007,-1.247847e-001,4.976489e-005,3,9.700760e-001,1.825000e+000,,,,,,,,,,,,,,,,,,0,4.000000e+000,1.000000e+000,2,2,9.304199e-001,0,,0,
1657434394.075,,1.500000e+003,3.629671e+002,1.678267e-004,1.382841e-007,-1.146629e-001,2.750082e-006,3,9.737723e-001,1.825000e+000,,,,,,,,,,,,,,,,,,0,4.000000e+000,1.000000e+000,2,2,4.880981e-001,0,,0,
1657435365.407,,1.500000e+003,3.350550e+002,7.295526e-005,2.335775e-008,-5.070753e-002,3.527981e-004,3,9.396076e-001,1.825000e+000,,,,,,,,,,,,,,,,,,0,4.000000e+000,1.000000e+000,2,2,9.324036e-001,0,,0,
1657436160.524,,1.500000e+003,3.078916e+002,7.316317e-005,1.849584e-008,-3.989079e-002,7.047822e-004,3,9.389285e-001,1.825000e+000,,,,,,,,,,,,,,,,,,0,4.000000e+000,1.000000e+000,2,2,1.647949e-001,0,,0,
1657437529.381,,1.500000e+003,3.192856e+002,7.249117e-005,2.576555e-008,-4.983290e-002,3.882778e-005,3,9.381683e-001,1.825000e+000,,,,,,,,,,,,,,,,,,0,4.000000e+000,1.000000e+000,2,2,4.046936e-001,0,,0,
1657438369.123,,1.500000e+003,3.473013e+002,7.289505e-005,3.786631e-009,-6.374733e-002,7.473163e-005,3,9.393288e-001,1.825000e+000,,,,,,,,,,,,,,,,,,0,4.000000e+000,1.000000e+000,2,2,4.159851e-001,0,,0,
1657439210.105,,1.500000e+003,3.753026e+002,1.642440e-004,2.318283e-008,-1.309143e-001,3.937148e-004,3,9.731745e-001,1.825000e+000,,,,,,,,,,,,,,,,,,0,4.000000e+000,1.000000e+000,2,2,4.097900e-001,0,,0,
1657440701.607,,1.000000e+003,3.977659e+002,1.066732e-004,3.425975e-008,-1.321000e-001,3.127823e-004,3,9.688131e-001,1.825000e+000,,,,,,,,,,,,,,,,,,0,4.000000e+000,1.000000e+000,2,2,3.970947e-001,0,,0,
1657441485.214,,1.000000e+003,3.680331e+002,1.132258e-004,2.519962e-008,-1.206348e-001,5.302179e-004,3,9.732616e-001,1.825000e+000,,,,,,,,,,,,,,,,,,0,4.000000e+000,1.000000e+000,2,2,8.739929e-001,0,,0,
1657442436.743,,1.000000e+003,3.418481e+002,5.514844e-005,1.726210e-007,-6.803150e-002,1.263615e-004,3,9.444544e-001,1.825000e+000,,,,,,,,,,,,,,,,,,0,4.000000e+000,1.000000e+000,2,2,3.181152e-001,0,,0,
1657443166.261,,1.000000e+003,3.135269e+002,5.122236e-005,1.073994e-008,-5.211126e-002,2.355113e-004,3,9.395387e-001,1.825000e+000,,,,,,,,,,,,,,,,,,0,4.000000e+000,1.000000e+000,2,2,7.163086e-001,0,,0,
1657444543.378,,1.000000e+003,3.132759e+002,5.107054e-005,2.328315e-008,-5.700523e-002,1.504145e-003,3,9.393815e-001,1.825000e+000,,,,,,,,,,,,,,,,,,0,4.000000e+000,1.000000e+000,2,2,4.429932e-001,0,,0,
1657445392.210,,1.000000e+003,3.414510e+002,5.087620e-005,4.031527e-008,-7.117905e-002,1.822008e-004,3,9.397752e-001,1.825000e+000,,,,,,,,,,,,,,,,,,0,4.000000e+000,1.000000e+000,2,2,4.479980e-001,0,,0,
1657446224.743,,1.000000e+003,3.692222e+002,1.113675e-004,4.711629e-007,-1.316791e-001,6.354691e-004,3,9.727747e-001,1.825000e+000,,,,,,,,,,,,,,,,,,0,4.000000e+000,1.000000e+000,2,2,4.068909e-001,0,,0,
1657447066.906,,1.000000e+003,3.972891e+002,1.071577e-004,2.371275e-008,-1.383768e-001,3.696279e-005,3,9.697253e-001,1.825000e+000,,,,,,,,,,,,,,,,,,0,4.000000e+000,1.000000e+000,2,2,4.091187e-001,0,,0,
1657448576.737,,9.000000e+002,3.753001e+002,1.012887e-004,5.520455e-008,-1.255774e-001,3.948738e-004,3,9.731429e-001,1.825000e+000,,,,,,,,,,,,,,,,,,0,4.000000e+000,1.000000e+000,2,2,1.035919e+000,0,,0,
1657449308.598,,9.000000e+002,3.462840e+002,1.018301e-004,5.407165e-007,-1.117719e-001,1.925321e-004,3,9.729382e-001,1.825000e+000,,,,,,,,,,,,,,,,,,0,4.000000e+000,1.000000e+000,2,2,5.863953e-001,0,,0,
1657450256.671,,9.000000e+002,3.193951e+002,4.664171e-005,2.916632e-008,-5.790580e-002,2.599117e-004,3,9.398689e-001,1.825000e+000,,,,,,,,,,,,,,,,,,0,4.000000e+000,1.000000e+000,2,2,8.019104e-001,0,,0,
1657451563.765,,9.000000e+002,3.073162e+002,4.682553e-005,3.197543e-009,-5.578602e-002,6.082422e-004,3,9.396103e-001,1.825000e+000,,,,,,,,,,,,,,,,,,0,4.000000e+000,1.000000e+000,2,2,4.773865e-001,0,,0,
1657452397.200,,9.000000e+002,3.352610e+002,4.639709e-005,1.389117e-010,-7.097702e-002,5.316614e-004,3,9.398055e-001,1.825000e+000,,,,,,,,,,,,,,,,,,0,4.000000e+000,1.000000e+000,2,2,4.399109e-001,0,,0,
1657453238.245,,9.000000e+002,3.633017e+002,5.814176e-005,9.867621e-007,-9.622647e-002,1.389829e-003,3,9.533780e-001,1.825000e+000,,,,,,,,,,,,,,,,,,0,4.000000e+000,1.000000e+000,2,2,4.465942e-001,0,,0,
1657454077.147,,9.000000e+002,3.912668e+002,9.838927e-005,3.287582e-009,-1.393825e-001,1.630451e-004,3,9.717541e-001,1.825000e+000,,,,,,,,,,,,,,,,,,0,4.000000e+000,1.000000e+000,2,2,4.591980e-001,0,,0,
1657455382.441,,8.000000e+002,3.817815e+002,8.946926e-005,2.615656e-008,-1.267918e-001,1.381363e-005,3,9.721193e-001,1.825000e+000,,,,,,,,,,,,,,,,,,0,4.000000e+000,1.000000e+000,2,2,3.420105e-001,0,,0,
1657456389.763,,8.000000e+002,3.526086e+002,9.347068e-005,4.568653e-008,-1.176868e-001,6.332564e-005,3,9.734968e-001,1.825000e+000,,,,,,,,,,,,,,,,,,0,4.000000e+000,1.000000e+000,2,2,8.686218e-001,0,,0,
1657457126.300,,8.000000e+002,3.258105e+002,4.219347e-005,4.276166e-008,-6.186022e-002,1.184158e-003,3,9.404972e-001,1.825000e+000,,,,,,,,,,,,,,,,,,0,4.000000e+000,1.000000e+000,2,2,2.956848e-001,0,,0,
1657458589.932,,8.000000e+002,3.012454e+002,4.259392e-005,4.458038e-009,-5.627576e-002,3.425090e-004,3,9.390697e-001,1.825000e+000,,,,,,,,,,,,,,,,,,0,4.000000e+000,1.000000e+000,2,2,3.788147e-001,0,,0,
1657459401.382,,8.000000e+002,3.293036e+002,4.195613e-005,3.576463e-008,-7.031986e-002,7.754019e-004,3,9.403666e-001,1.825000e+000,,,,,,,,,,,,,,,,,,0,4.000000e+000,1.000000e+000,2,2,4.063110e-001,0,,0,
1657460241.037,,8.000000e+002,3.572709e+002,4.310754e-005,3.948180e-008,-8.696522e-002,3.958695e-004,3,9.418472e-001,1.825000e+000,,,,,,,,,,,,,,,,,,0,4.000000e+000,1.000000e+000,2,2,4.208984e-001,0,,0,
1657461081.504,,8.000000e+002,3.852850e+002,8.906751e-005,6.559206e-008,-1.389407e-001,3.281870e-004,3,9.723762e-001,1.825000e+000,,,,,,,,,,,,,,,,,,0,4.000000e+000,1.000000e+000,2,2,4.446716e-001,0,,0,
1657462457.020,,7.000000e+002,3.867422e+002,7.793448e-005,7.449785e-009,-1.301156e-001,2.806243e-004,3,9.706323e-001,1.825000e+000,,,,,,,,,,,,,,,,,,0,4.000000e+000,1.000000e+000,2,2,7.148132e-001,0,,0,
1657463477.392,,7.000000e+002,3.596720e+002,8.176963e-005,4.115903e-011,-1.223858e-001,1.598050e-004,3,9.734102e-001,1.825000e+000,,,,,,,,,,,,,,,,,,0,4.000000e+000,1.000000e+000,2,2,6.246033e-001,0,,0,
1657464197.455,,7.000000e+002,3.307214e+002,3.765938e-005,1.962257e-008,-6.803187e-002,1.337372e-003,3,9.405598e-001,1.825000e+000,,,,,,,,,,,,,,,,,,0,4.000000e+000,1.000000e+000,2,2,8.724060e-001,0,,0,
1657465117.610,,7.000000e+002,3.036056e+002,3.801028e-005,2.671736e-008,-6.066636e-002,2.424787e-004,3,9.405741e-001,1.825000e+000,,,,,,,,,,,,,,,,,,0,4.000000e+000,1.000000e+000,2,2,5.375977e-001,0,,0,
1657466415.253,,7.000000e+002,3.232237e+002,3.750851e-005,1.602887e-008,-7.051294e-002,6.587026e-005,3,9.400129e-001,1.825000e+000,,,,,,,,,,,,,,,,,,0,4.000000e+000,1.000000e+000,2,2,4.570007e-001,0,,0,
1657467255.571,,7.000000e+002,3.512755e+002,3.789991e-005,1.733824e-009,-8.623444e-002,7.310424e-004,3,9.421406e-001,1.825000e+000,,,,,,,,,,,,,,,,,,0,4.000000e+000,1.000000e+000,2,2,4.060974e-001,0,,0,
1657468095.617,,7.000000e+002,3.792896e+002,7.925856e-005,3.025189e-008,-1.382801e-001,1.265564e-004,3,9.724561e-001,1.825000e+000,,,,,,,,,,,,,,,,,,0,4.000000e+000,1.000000e+000,2,2,4.421997e-001,0,,0,
1657469550.188,,6.000000e+002,3.933793e+002,6.641833e-005,9.456287e-009,-1.347783e-001,7.764503e-005,3,9.697719e-001,1.825000e+000,,,,,,,,,,,,,,,,,,0,4.000000e+000,1.000000e+000,2,2,9.037170e-001,0,,0,
1657470302.075,,6.000000e+002,3.646815e+002,7.018498e-005,4.612384e-008,-1.229606e-001,1.782970e-004,3,9.729537e-001,1.825000e+000,,,,,,,,,,,,,,,,,,0,4.000000e+000,1.000000e+000,2,2,6.539001e-001,0,,0,
1657471280.501,,6.000000e+002,3.372967e+002,3.316160e-005,2.429412e-008,-7.584541e-002,9.286268e-004,3,9.412464e-001,1.825000e+000,,,,,,,,,,,,,,,,,,0,4.000000e+000,1.000000e+000,2,2,1.018799e+000,0,,0,
1657472018.532,,6.000000e+002,3.097780e+002,3.326063e-005,1.632985e-008,-6.479216e-002,1.109758e-003,3,9.421693e-001,1.825000e+000,,,,,,,,,,,,,,,,,,0,4.000000e+000,1.000000e+000,2,2,3.869019e-001,0,,0,
1657473411.547,,6.000000e+002,3.172159e+002,3.300464e-005,3.536847e-008,-7.224138e-002,5.770009e-004,3,9.404881e-001,1.825000e+000,,,,,,,,,,,,,,,,,,0,4.000000e+000,1.000000e+000,2,2,3.992004e-001,0,,0,
1657474254.269,,6.000000e+002,3.452992e+002,3.296239e-005,3.595499e-008,-8.612035e-002,3.235297e-005,3,9.409458e-001,1.825000e+000,,,,,,,,,,,,,,,,,,0,4.000000e+000,1.000000e+000,2,2,4.587097e-001,0,,0,
1657475092.161,,6.000000e+002,3.732659e+002,6.918178e-005,1.743600e-008,-1.386377e-001,6.310437e-005,3,9.722999e-001,1.825000e+000,,,,,,,,,,,,,,,,,,0,4.000000e+000,1.000000e+000,2,2,4.049988e-001,0,,0,
1657476526.249,,5.000000e+002,4.000164e+002,5.509573e-005,5.546180e-009,-1.405045e-001,4.345235e-004,3,9.688017e-001,1.825000e+000,,,,,,,,,,,,,,,,,,0,4.000000e+000,1.000000e+000,2,2,0.000000e+000,0,,0,
1657477386.770,,5.000000e+002,3.702565e+002,5.867524e-005,5.032978e-008,-1.278831e-001,2.887059e-004,3,9.724607e-001,1.825000e+000,,,,,,,,,,,,,,,,,,0,4.000000e+000,1.000000e+000,2,2,8.741150e-001,0,,0,
1657478128.765,,5.000000e+002,3.437963e+002,4.948768e-005,9.329209e-007,-1.112721e-001,5.533618e-004,3,9.684243e-001,1.825000e+000,,,,,,,,,,,,,,,,,,0,4.000000e+000,1.000000e+000,2,2,2.366943e-001,0,,0,
1657479057.074,,5.000000e+002,3.155908e+002,2.839830e-005,4.891494e-009,-7.219341e-002,2.156454e-003,3,9.402802e-001,1.825000e+000,,,,,,,,,,,,,,,,,,0,4.000000e+000,1.000000e+000,2,2,8.132019e-001,0,,0,
1657480408.259,,5.000000e+002,3.112671e+002,2.839814e-005,3.960785e-008,-7.533693e-002,5.571603e-004,3,9.414728e-001,1.825000e+000,,,,,,,,,,,,,,,,,,0,4.000000e+000,1.000000e+000,2,2,4.139099e-001,0,,0,
1657481252.980,,5.000000e+002,3.392935e+002,2.819328e-005,1.288406e-008,-8.849814e-002,4.002581e-004,3,9.424832e-001,1.825000e+000,,,,,,,,,,,,,,,,,,0,4.000000e+000,1.000000e+000,2,2,4.143982e-001,0,,0,
1657482093.250,,5.000000e+002,3.673297e+002,5.369802e-005,4.989864e-007,-1.326059e-001,5.259084e-004,3,9.700933e-001,1.825000e+000,,,,,,,,,,,,,,,,,,0,4.000000e+000,1.000000e+000,2,2,4.569092e-001,0,,0,
1657482933.686,,5.000000e+002,3.953251e+002,5.606822e-005,1.401208e-008,-1.451558e-001,1.956667e-004,3,9.704722e-001,1.825000e+000,,,,,,,,,,,,,,,,,,0,4.000000e+000,1.000000e+000,2,2,4.182739e-001,0,,0,
1657484469.303,,4.000000e+002,3.775242e+002,4.700451e-005,2.288442e-008,-1.342678e-001,3.250681e-004,3,9.728898e-001,1.825000e+000,,,,,,,,,,,,,,,,,,0,4.000000e+000,1.000000e+000,2,2,8.526001e-001,0,,0,
1657485193.958,,4.000000e+002,3.482958e+002,4.867672e-005,6.447048e-008,-1.213843e-001,2.840171e-004,3,9.735810e-001,1.825000e+000,,,,,,,,,,,,,,,,,,0,4.000000e+000,1.000000e+000,2,2,8.174133e-001,0,,0,
1657486135.682,,4.000000e+002,3.215384e+002,2.356370e-005,1.131745e-008,-8.311297e-002,9.314085e-004,3,9.424931e-001,1.825000e+000,,,,,,,,,,,,,,,,,,0,4.000000e+000,1.000000e+000,2,2,6.983032e-001,0,,0,
1657487433.187,,4.000000e+002,3.053127e+002,2.370936e-005,3.420058e-009,-7.802460e-002,4.735356e-004,3,9.426025e-001,1.825000e+000,,,,,,,,,,,,,,,,,,0,4.000000e+000,1.000000e+000,2,2,5.443115e-001,0,,0,
1657488257.527,,4.000000e+002,3.332759e+002,2.338702e-005,4.700747e-008,-9.360424e-002,1.086135e-003,3,9.424304e-001,1.825000e+000,,,,,,,,,,,,,,,,,,0,4.000000e+000,1.000000e+000,2,2,4.611206e-001,0,,0,
1657489103.324,,4.000000e+002,3.614956e+002,2.574948e-005,1.532917e-007,-1.090785e-001,7.228712e-004,3,9.486858e-001,1.825000e+000,,,,,,,,,,,,,,,,,,0,4.000000e+000,1.000000e+000,2,2,4.102783e-001,0,,0,
1657489937.560,,4.000000e+002,3.892976e+002,4.604205e-005,1.299085e-009,-1.464699e-001,2.113770e-004,3,9.709412e-001,1.825000e+000,,,,,,,,,,,,,,,,,,0,4.000000e+000,1.000000e+000,2,2,4.544983e-001,0,,0,
1657491252.995,,3.000000e+002,3.836396e+002,3.549616e-005,7.415829e-008,-1.379864e-001,2.103865e-004,3,9.710324e-001,1.825000e+000,,,,,,,,,,,,,,,,,,0,4.000000e+000,1.000000e+000,2,2,5.718994e-001,0,,0,
1657492281.617,,3.000000e+002,3.549290e+002,3.717846e-005,2.431213e-008,-1.289106e-001,9.877535e-004,3,9.735082e-001,1.825000e+000,,,,,,,,,,,,,,,,,,0,4.000000e+000,1.000000e+000,2,2,1.002106e+000,0,,0,
1657492990.387,,3.000000e+002,3.277001e+002,1.858266e-005,6.676381e-008,-9.138223e-002,7.073611e-004,3,9.450581e-001,1.825000e+000,,,,,,,,,,,,,,,,,,0,4.000000e+000,1.000000e+000,2,2,5.219116e-001,0,,0,
1657494176.168,,3.000000e+002,3.000800e+002,1.877579e-005,3.485141e-008,-8.425217e-002,6.711886e-004,3,9.445587e-001,1.825000e+000,,,,,,,,,,,,,,,,,,0,4.000000e+000,1.000000e+000,2,2,1.409912e-002,0,,0,
1657495265.647,,3.000000e+002,3.272964e+002,1.845421e-005,4.397586e-008,-9.726155e-002,2.354802e-003,3,9.427749e-001,1.825000e+000,,,,,,,,,,,,,,,,,,0,4.000000e+000,1.000000e+000,2,2,4.606934e-001,0,,0,
1657496106.096,,3.000000e+002,3.553189e+002,1.874471e-005,2.688971e-008,-1.126035e-001,1.533619e-005,3,9.466945e-001,1.825000e+000,,,,,,,,,,,,,,,,,,0,4.000000e+000,1.000000e+000,2,2,4.060059e-001,0,,0,
1657496946.019,,3.000000e+002,3.833152e+002,3.560224e-005,4.723256e-008,-1.481882e-001,4.249245e-004,3,9.722886e-001,1.825000e+000,,,,,,,,,,,,,,,,,,0,4.000000e+000,1.000000e+000,2,2,4.637756e-001,0,,0,
1657498341.406,,2.000000e+002,3.891167e+002,2.400721e-005,6.680625e-008,-1.449245e-001,4.791359e-004,3,9.694977e-001,1.825000e+000,,,,,,,,,,,,,,,,,,0,4.000000e+000,1.000000e+000,2,2,8.836060e-001,0,,0,
1657499116.558,,2.000000e+002,3.618669e+002,2.528053e-005,5.620795e-010,-1.352290e-001,5.017899e-004,3,9.734787e-001,1.825000e+000,,,,,,,,,,,,,,,,,,0,4.000000e+000,1.000000e+000,2,2,2.319946e-001,0,,0,
1657500071.840,,2.000000e+002,3.329683e+002,1.343695e-005,1.184480e-008,-1.078457e-001,4.228857e-004,3,9.478335e-001,1.825000e+000,,,,,,,,,,,,,,,,,,0,4.000000e+000,1.000000e+000,2,2,7.699280e-001,0,,0,
1657500976.424,,2.000000e+002,3.056514e+002,1.357773e-005,2.353268e-008,-1.004147e-001,1.846801e-003,3,9.479148e-001,1.825000e+000,,,,,,,,,,,,,,,,,,0,4.000000e+000,1.000000e+000,2,2,4.718018e-001,0,,0,
1657502266.304,,2.000000e+002,3.214623e+002,1.341147e-005,4.799207e-008,-1.119766e-001,1.727557e-003,3,9.475142e-001,1.825000e+000,,,,,,,,,,,,,,,,,,0,4.000000e+000,1.000000e+000,2,2,4.434204e-001,0,,0,
1657503100.943,,2.000000e+002,3.493083e+002,1.340789e-005,1.048526e-008,-1.205900e-001,1.245028e-003,3,9.461746e-001,1.825000e+000,,,,,,,,,,,,,,,,,,0,4.000000e+000,1.000000e+000,2,2,4.895020e-001,0,,0,
1657503938.837,,2.000000e+002,3.772534e+002,2.465116e-005,1.835693e-008,-1.515619e-001,8.104839e-005,3,9.714572e-001,1.825000e+000,,,,,,,,,,,,,,,,,,0,4.000000e+000,1.000000e+000,2,2,4.141235e-001,0,,0,
1657505414.251,,1.000000e+002,3.955282e+002,1.262894e-005,5.869921e-008,-1.633385e-001,1.413416e-003,3,9.679629e-001,1.825000e+000,,,,,,,,,,,,,,,,,,0,4.000000e+000,1.000000e+000,2,2,7.994995e-001,0,,0,
1657506172.860,,1.000000e+002,3.662154e+002,1.342900e-005,7.317947e-009,-1.512136e-001,2.670793e-003,3,9.721223e-001,1.825000e+000,,,,,,,,,,,,,,,,,,0,4.000000e+000,1.000000e+000,2,2,7.460022e-001,0,,0,
1657507145.756,,1.000000e+002,3.394480e+002,8.136214e-006,1.204095e-008,-1.359383e-001,1.216579e-003,3,9.497701e-001,1.825000e+000,,,,,,,,,,,,,,,,,,0,4.000000e+000,1.000000e+000,2,2,7.926941e-001,0,,0,
1657507862.595,,1.000000e+002,3.116875e+002,8.148986e-006,4.308836e-008,-1.296102e-001,5.111464e-004,3,9.504330e-001,1.825000e+000,,,,,,,,,,,,,,,,,,0,4.000000e+000,1.000000e+000,2,2,5.614014e-001,0,,0,
1657509253.927,,1.000000e+002,3.152672e+002,8.119117e-006,3.002937e-008,-1.333782e-001,7.701810e-004,3,9.515867e-001,1.825000e+000,,,,,,,,,,,,,,,,,,0,4.000000e+000,1.000000e+000,2,2,4.333191e-001,0,,0,
1657510097.075,,1.000000e+002,3.433165e+002,8.012017e-006,5.694738e-009,-1.451815e-001,2.411400e-003,3,9.500378e-001,1.825000e+000,,,,,,,,,,,,,,,,,,0,4.000000e+000,1.000000e+000,2,2,4.059143e-001,0,,0,
1657510936.677,,1.000000e+002,3.713021e+002,1.331174e-005,5.256137e-009,-1.639935e-001,1.667909e-003,3,9.697258e-001,1.825000e+000,,,,,,,,,,,,,,,,,,0,4.000000e+000,1.000000e+000,2,2,4.674072e-001,0,,0,
1657511776.480,,1.000000e+002,3.992832e+002,1.269024e-005,5.676731e-009,-1.661355e-001,6.074941e-004,3,9.693837e-001,1.825000e+000,,,,,,,,,,,,,,,,,,0,4.000000e+000,1.000000e+000,2,2,4.772949e-001,0,,0,
1657513256.208,,0.000000e+000,3.727324e+002,1.306581e-006,1.927384e-008,-3.721511e-001,2.242935e-002,3,8.574772e-001,1.825000e+000,,,,,,,,,,,,,,,,,,0,4.000000e+000,1.000000e+000,2,2,9.422913e-001,0,,0,
1657513985.198,,0.000000e+000,3.451797e+002,1.475140e-006,1.603241e-008,-3.613034e-001,6.480499e-003,3,8.922419e-001,1.825000e+000,,,,,,,,,,,,,,,,,,0,4.000000e+000,1.000000e+000,2,2,5.348206e-001,0,,0,
1657514928.089,,0.000000e+000,3.175238e+002,2.276958e-006,6.772590e-009,-2.646980e-001,9.251486e-003,3,9.364852e-001,1.825000e+000,,,,,,,,,,,,,,,,,,0,4.000000e+000,1.000000e+000,2,2,7.997131e-001,0,,0,
1657516256.181,,0.000000e+000,3.093311e+002,2.283598e-006,3.539098e-008,-2.741003e-001,5.517823e-003,3,9.295616e-001,1.825000e+000,,,,,,,,,,,,,,,,,,0,4.000000e+000,1.000000e+000,2,2,4.463196e-001,0,,0,
1657517097.238,,0.000000e+000,3.372531e+002,2.219001e-006,1.078576e-008,-2.782299e-001,1.093260e-002,3,9.297783e-001,1.825000e+000,,,,,,,,,,,,,,,,,,0,4.000000e+000,1.000000e+000,2,2,4.091187e-001,0,,0,
1657517936.955,,0.000000e+000,3.652638e+002,1.674909e-006,9.191568e-009,-3.365508e-001,7.118582e-003,3,9.119803e-001,1.825000e+000,,,,,,,,,,,,,,,,,,0,4.000000e+000,1.000000e+000,2,2,4.085999e-001,0,,0,
1657518776.405,,0.000000e+000,3.932569e+002,1.308932e-006,2.069150e-008,-3.985443e-001,1.531208e-002,3,8.749056e-001,1.825000e+000,,,,,,,,,,,,,,,,,,0,4.000000e+000,1.000000e+000,2,2,4.641113e-001,0,,0,
1657519234.959,,0.000000e+000,3.999905e+002,1.350530e-006,2.064945e-009,-3.739156e-001,2.666262e-002,3,8.862259e-001,1.825000e+000,,,,,,,,,,,,,,,,,,0,4.000000e+000,1.000000e+000,2,2,0.000000e+000,0,,0,