File: spin_crossover/dane/AOT — kopia/Medium AOT/FeTrz_AOT_medium_XTvT_MCE.rso.csv
Field (Oe),Temperature (K),Long Moment (emu),Long Offset (cm)
7.000000e+004,4.000002e+002,6.681458e-003,-1.243588e-001
7.000000e+004,3.909632e+002,6.795771e-003,-1.182547e-001
7.000000e+004,3.831667e+002,6.884227e-003,-1.140388e-001
7.000000e+004,3.752289e+002,6.991738e-003,-1.139608e-001
7.000000e+004,3.662858e+002,7.078005e-003,-1.088331e-001
7.000000e+004,3.599636e+002,7.109387e-003,-1.065517e-001
7.000000e+004,3.507589e+002,7.064386e-003,-1.030912e-001
7.000000e+004,3.435316e+002,2.743772e-003,-7.649614e-003
7.000000e+004,3.353286e+002,2.525759e-003,7.430212e-003
7.000000e+004,3.275248e+002,2.500021e-003,7.649811e-003
7.000000e+004,3.194903e+002,2.539776e-003,1.508430e-002
7.000000e+004,3.115857e+002,2.557542e-003,1.955631e-002
7.000000e+004,3.037510e+002,2.608609e-003,8.366844e-003
7.000000e+004,3.033460e+002,2.547887e-003,1.630418e-002
7.000000e+004,3.112709e+002,2.529304e-003,1.746837e-002
7.000000e+004,3.192512e+002,2.515922e-003,1.417005e-002
7.000000e+004,3.272495e+002,2.509793e-003,9.951541e-003
7.000000e+004,3.352656e+002,2.496189e-003,2.725100e-003
7.000000e+004,3.432741e+002,2.471887e-003,-4.236621e-003
7.000000e+004,3.512830e+002,2.497980e-003,-7.034349e-003
7.000000e+004,3.592923e+002,2.554734e-003,-9.748410e-003
7.000000e+004,3.672917e+002,2.644965e-003,-1.757340e-002
7.000000e+004,3.752628e+002,5.488375e-003,-9.770812e-002
7.000000e+004,3.832736e+002,6.875296e-003,-1.213340e-001
7.000000e+004,3.912729e+002,6.767816e-003,-1.220850e-001
7.000000e+004,3.992703e+002,6.666473e-003,-1.224483e-001
6.500000e+004,3.934421e+002,6.279691e-003,-1.138357e-001
6.500000e+004,3.855316e+002,6.367538e-003,-1.094028e-001
6.500000e+004,3.775702e+002,6.506631e-003,-1.102560e-001
6.500000e+004,3.683310e+002,6.598031e-003,-1.052611e-001
6.500000e+004,3.617958e+002,6.646844e-003,-1.018227e-001
6.500000e+004,3.530286e+002,6.682405e-003,-1.003211e-001
6.500000e+004,3.453160e+002,2.931573e-003,-2.290896e-002
6.500000e+004,3.373648e+002,2.354310e-003,1.539918e-003
6.500000e+004,3.293924e+002,2.361053e-003,3.348358e-003
6.500000e+004,3.217233e+002,2.391865e-003,1.748979e-002
6.500000e+004,3.136164e+002,2.391438e-003,1.935861e-002
6.500000e+004,3.059243e+002,2.401106e-003,1.450997e-002
6.500000e+004,3.012490e+002,2.419910e-003,2.492932e-002
6.500000e+004,3.092233e+002,2.397712e-003,2.775699e-002
6.500000e+004,3.172538e+002,2.372659e-003,1.344376e-002
6.500000e+004,3.252938e+002,2.395527e-003,-1.821451e-003
6.500000e+004,3.332758e+002,2.377618e-003,5.823058e-003
6.500000e+004,3.414860e+002,2.380409e-003,3.175724e-003
6.500000e+004,3.492471e+002,2.397964e-003,-2.317705e-003
6.500000e+004,3.573043e+002,2.432796e-003,-8.649804e-003
6.500000e+004,3.652637e+002,2.515666e-003,-1.710682e-002
6.500000e+004,3.732630e+002,5.835980e-003,-1.063593e-001
6.500000e+004,3.815634e+002,6.435868e-003,-1.182735e-001
6.500000e+004,3.892791e+002,6.353318e-003,-1.202016e-001
6.500000e+004,3.973051e+002,6.231654e-003,-1.199216e-001
6.000000e+004,3.956233e+002,5.783427e-003,-1.130357e-001
6.000000e+004,3.873550e+002,5.869004e-003,-1.082495e-001
6.000000e+004,3.797729e+002,5.996397e-003,-1.094959e-001
6.000000e+004,3.705943e+002,6.086650e-003,-1.047482e-001
6.000000e+004,3.634613e+002,6.143644e-003,-1.009174e-001
6.000000e+004,3.553547e+002,6.195312e-003,-1.004440e-001
6.000000e+004,3.469053e+002,4.950090e-003,-8.285341e-002
6.000000e+004,3.396024e+002,2.258229e-003,6.120980e-003
6.000000e+004,3.312390e+002,2.248466e-003,6.470888e-003
6.000000e+004,3.239084e+002,2.240325e-003,1.374529e-002
6.000000e+004,3.155078e+002,2.234077e-003,1.696128e-002
6.000000e+004,3.078167e+002,2.249802e-003,2.266371e-002
6.000000e+004,3.001031e+002,2.267668e-003,2.417747e-002
6.000000e+004,3.073442e+002,2.241936e-003,1.927515e-002
6.000000e+004,3.152495e+002,2.229416e-003,1.549626e-002
6.000000e+004,3.232839e+002,2.220862e-003,1.155441e-002
6.000000e+004,3.312585e+002,2.218558e-003,7.237207e-003
6.000000e+004,3.392290e+002,2.223562e-003,2.327478e-003
6.000000e+004,3.472770e+002,2.239151e-003,-2.808807e-003
6.000000e+004,3.552631e+002,2.265604e-003,-1.005976e-002
6.000000e+004,3.632512e+002,2.339398e-003,-1.757240e-002
6.000000e+004,3.712520e+002,4.858031e-003,-9.536120e-002
6.000000e+004,3.792634e+002,5.980513e-003,-1.173937e-001
6.000000e+004,3.872728e+002,5.900887e-003,-1.196055e-001
6.000000e+004,3.952776e+002,5.789883e-003,-1.199194e-001
5.500000e+004,3.977115e+002,5.288581e-003,-1.144386e-001
5.500000e+004,3.893499e+002,5.370275e-003,-1.092479e-001
5.500000e+004,3.817668e+002,5.472745e-003,-1.074684e-001
5.500000e+004,3.727101e+002,5.572237e-003,-1.056333e-001
5.500000e+004,3.648745e+002,5.634450e-003,-1.014919e-001
5.500000e+004,3.573764e+002,5.686796e-003,-1.014055e-001
5.500000e+004,3.487709e+002,5.543858e-003,-9.474155e-002
5.500000e+004,3.418108e+002,2.106084e-003,3.554916e-003
5.500000e+004,3.330546e+002,2.076481e-003,1.005350e-002
5.500000e+004,3.257872e+002,2.070673e-003,1.461362e-002
5.500000e+004,3.174577e+002,2.084218e-003,2.014545e-002
5.500000e+004,3.096320e+002,2.090747e-003,9.921137e-003
5.500000e+004,3.015926e+002,2.103906e-003,2.167465e-002
5.500000e+004,3.053292e+002,2.078843e-003,1.879266e-002
5.500000e+004,3.132486e+002,2.063774e-003,1.431147e-002
5.500000e+004,3.214747e+002,2.058052e-003,1.055283e-002
5.500000e+004,3.292821e+002,2.060721e-003,7.474353e-003
5.500000e+004,3.372531e+002,2.057791e-003,1.767771e-003
5.500000e+004,3.452131e+002,2.031730e-003,-9.470711e-003
5.500000e+004,3.532237e+002,2.094922e-003,-9.284317e-003
5.500000e+004,3.615167e+002,2.153013e-003,-1.747426e-002
5.500000e+004,3.693295e+002,3.709171e-003,-7.825025e-002
5.500000e+004,3.772477e+002,5.510759e-003,-1.170225e-001
5.500000e+004,3.852849e+002,5.439003e-003,-1.191710e-001
5.500000e+004,3.933384e+002,5.343589e-003,-1.201179e-001
5.000000e+004,4.000035e+002,4.789078e-003,-1.160593e-001
5.000000e+004,3.913167e+002,4.870747e-003,-1.105613e-001
5.000000e+004,3.837052e+002,4.952951e-003,-1.075416e-001
5.000000e+004,3.753456e+002,5.052703e-003,-1.072752e-001
5.000000e+004,3.666511e+002,5.120282e-003,-1.026291e-001
5.000000e+004,3.596720e+002,5.168268e-003,-1.025462e-001
5.000000e+004,3.507466e+002,5.192139e-003,-9.771076e-002
5.000000e+004,3.437868e+002,2.217858e-003,-1.657716e-002
5.000000e+004,3.352187e+002,1.906013e-003,7.401169e-003
5.000000e+004,3.276509e+002,1.898078e-003,1.226654e-002
5.000000e+004,3.195268e+002,1.898107e-003,1.419877e-002
5.000000e+004,3.116491e+002,1.903779e-003,1.813827e-002
5.000000e+004,3.037073e+002,1.889899e-003,1.463217e-002
5.000000e+004,3.033061e+002,1.911176e-003,1.640904e-002
5.000000e+004,3.112173e+002,1.884083e-003,1.267008e-002
5.000000e+004,3.192654e+002,1.886910e-003,1.009712e-002
5.000000e+004,3.272601e+002,1.882826e-003,6.057836e-003
5.000000e+004,3.353194e+002,1.884472e-003,1.511236e-003
5.000000e+004,3.433259e+002,1.893636e-003,-3.596267e-003
5.000000e+004,3.512112e+002,1.913977e-003,-9.503955e-003
5.000000e+004,3.592585e+002,1.955856e-003,-1.649007e-002
5.000000e+004,3.672644e+002,2.697478e-003,-5.611622e-002
5.000000e+004,3.753026e+002,5.033902e-003,-1.165255e-001
5.000000e+004,3.832795e+002,4.971165e-003,-1.189927e-001
5.000000e+004,3.913133e+002,4.895483e-003,-1.207643e-001
5.000000e+004,3.992832e+002,4.797633e-003,-1.202528e-001
4.500000e+004,3.933478e+002,4.371418e-003,-1.116978e-001
4.500000e+004,3.855887e+002,4.443342e-003,-1.084384e-001
4.500000e+004,3.775558e+002,4.534666e-003,-1.085308e-001
4.500000e+004,3.686788e+002,4.600903e-003,-1.036910e-001
4.500000e+004,3.618142e+002,4.642111e-003,-1.004602e-001
4.500000e+004,3.529561e+002,4.684082e-003,-9.921759e-002
4.500000e+004,3.456555e+002,3.643178e-003,-8.101619e-002
4.500000e+004,3.373011e+002,1.730249e-003,4.657087e-003
4.500000e+004,3.296152e+002,1.720782e-003,1.040337e-002
4.500000e+004,3.216370e+002,1.718387e-003,1.181968e-002
4.500000e+004,3.136494e+002,1.723198e-003,1.619209e-002
4.500000e+004,3.057970e+002,1.730340e-003,1.774113e-002
4.500000e+004,3.012293e+002,1.733115e-003,1.817152e-002
4.500000e+004,3.093027e+002,1.732840e-003,1.308895e-002
4.500000e+004,3.172559e+002,1.712755e-003,9.416113e-003
4.500000e+004,3.252327e+002,1.707077e-003,6.077434e-003
4.500000e+004,3.333291e+002,1.702502e-003,7.008864e-004
4.500000e+004,3.414533e+002,1.713818e-003,-3.377746e-003
4.500000e+004,3.492912e+002,1.729768e-003,-8.673141e-003
4.500000e+004,3.572504e+002,1.762130e-003,-1.580819e-002
4.500000e+004,3.652503e+002,2.058225e-003,-3.758760e-002
4.500000e+004,3.732518e+002,4.549866e-003,-1.158851e-001
4.500000e+004,3.815075e+002,4.493983e-003,-1.183562e-001
4.500000e+004,3.892883e+002,4.430708e-003,-1.202604e-001
4.500000e+004,3.973082e+002,4.342474e-003,-1.202181e-001
4.000000e+004,3.955980e+002,3.873213e-003,-1.130384e-001
4.000000e+004,3.873580e+002,3.936639e-003,-1.087159e-001
4.000000e+004,3.797787e+002,4.015750e-003,-1.095004e-001
4.000000e+004,3.705112e+002,4.080841e-003,-1.044359e-001
4.000000e+004,3.634214e+002,4.122873e-003,-1.008813e-001
4.000000e+004,3.553065e+002,4.162554e-003,-1.003060e-001
4.000000e+004,3.470524e+002,3.894134e-003,-9.178039e-002
4.000000e+004,3.395931e+002,1.554354e-003,1.537316e-003
4.000000e+004,3.308152e+002,1.539003e-003,8.345817e-003
4.000000e+004,3.239773e+002,1.534952e-003,1.163522e-002
4.000000e+004,3.155216e+002,1.538968e-003,1.431912e-002
4.000000e+004,3.078598e+002,1.544296e-003,1.742791e-002
4.000000e+004,3.000923e+002,1.552570e-003,1.835229e-002
4.000000e+004,3.072864e+002,1.534857e-003,1.286010e-002
4.000000e+004,3.152692e+002,1.533017e-003,9.111007e-003
4.000000e+004,3.232943e+002,1.518460e-003,4.922566e-003
4.000000e+004,3.312761e+002,1.525261e-003,1.788297e-003
4.000000e+004,3.392474e+002,1.530231e-003,-3.276984e-003
4.000000e+004,3.473254e+002,1.542570e-003,-8.504120e-003
4.000000e+004,3.553011e+002,1.567084e-003,-1.500781e-002
4.000000e+004,3.632246e+002,1.689425e-003,-2.794531e-002
4.000000e+004,3.712270e+002,4.017288e-003,-1.143593e-001
4.000000e+004,3.792866e+002,4.011204e-003,-1.178287e-001
4.000000e+004,3.873214e+002,3.955016e-003,-1.197960e-001
4.000000e+004,3.953378e+002,3.881548e-003,-1.203859e-001
3.500000e+004,3.978044e+002,3.377190e-003,-1.145979e-001
3.500000e+004,3.891719e+002,3.435512e-003,-1.096173e-001
3.500000e+004,3.817785e+002,3.499591e-003,-1.073823e-001
3.500000e+004,3.728952e+002,3.559372e-003,-1.057808e-001
3.500000e+004,3.651000e+002,3.602301e-003,-1.016457e-001
3.500000e+004,3.575383e+002,3.638072e-003,-1.014365e-001
3.500000e+004,3.488318e+002,3.625116e-003,-9.589813e-002
3.500000e+004,3.418598e+002,1.398891e-003,-2.514139e-003
3.500000e+004,3.329484e+002,1.355903e-003,5.812125e-003
3.500000e+004,3.257978e+002,1.352013e-003,1.002384e-002
3.500000e+004,3.175498e+002,1.353016e-003,1.190981e-002
3.500000e+004,3.097515e+002,1.357715e-003,1.572071e-002
3.500000e+004,3.015853e+002,1.360584e-003,1.444172e-002
3.500000e+004,3.053624e+002,1.367717e-003,1.499315e-002
3.500000e+004,3.131981e+002,1.358642e-003,1.099435e-002
3.500000e+004,3.214644e+002,1.344315e-003,6.053890e-003
3.500000e+004,3.293188e+002,1.328958e-003,1.834346e-003
3.500000e+004,3.372167e+002,1.344933e-003,-3.112901e-003
3.500000e+004,3.452585e+002,1.353619e-003,-8.179018e-003
3.500000e+004,3.532663e+002,1.372605e-003,-1.446570e-002
3.500000e+004,3.614904e+002,1.437678e-003,-2.440850e-002
3.500000e+004,3.692717e+002,3.104340e-003,-1.023328e-001
3.500000e+004,3.772851e+002,3.524167e-003,-1.170458e-001
3.500000e+004,3.852789e+002,3.476582e-003,-1.192718e-001
3.500000e+004,3.932976e+002,3.419169e-003,-1.204656e-001
3.000000e+004,4.000035e+002,2.885511e-003,-1.158510e-001
3.000000e+004,3.912949e+002,2.934742e-003,-1.105786e-001
3.000000e+004,3.836783e+002,2.988232e-003,-1.076914e-001
3.000000e+004,3.752603e+002,3.041854e-003,-1.070137e-001
3.000000e+004,3.665752e+002,3.085012e-003,-1.024588e-001
3.000000e+004,3.596511e+002,3.114639e-003,-1.025400e-001
3.000000e+004,3.507169e+002,3.135755e-003,-9.780445e-002
3.000000e+004,3.437608e+002,1.820578e-003,-5.630088e-002
3.000000e+004,3.347885e+002,1.171801e-003,3.159900e-003
3.000000e+004,3.276659e+002,1.176708e-003,8.987140e-003
3.000000e+004,3.195288e+002,1.168033e-003,1.641757e-002
3.000000e+004,3.116779e+002,1.171109e-003,1.343022e-002
3.000000e+004,3.037292e+002,1.176594e-003,1.478195e-002
3.000000e+004,3.034059e+002,1.177106e-003,1.438536e-002
3.000000e+004,3.112710e+002,1.168169e-003,8.109866e-003
3.000000e+004,3.192371e+002,1.161550e-003,5.659422e-003
3.000000e+004,3.272495e+002,1.167870e-003,4.303996e-003
3.000000e+004,3.352566e+002,1.160566e-003,-3.159073e-003
3.000000e+004,3.432646e+002,1.166632e-003,-8.279927e-003
3.000000e+004,3.512235e+002,1.180382e-003,-1.434027e-002
3.000000e+004,3.592897e+002,1.213663e-003,-2.182356e-002
3.000000e+004,3.674903e+002,2.180186e-003,-8.429206e-002
3.000000e+004,3.752827e+002,3.037502e-003,-1.166324e-001
3.000000e+004,3.832557e+002,2.997951e-003,-1.190651e-001
3.000000e+004,3.912574e+002,2.952913e-003,-1.207658e-001
3.000000e+004,3.992993e+002,2.894409e-003,-1.200878e-001
2.500000e+004,3.934987e+002,2.442097e-003,-1.121148e-001
2.500000e+004,3.855767e+002,2.485296e-003,-1.087347e-001
2.500000e+004,3.774925e+002,2.531412e-003,-1.086362e-001
2.500000e+004,3.685035e+002,2.570698e-003,-1.036880e-001
2.500000e+004,3.618010e+002,2.595346e-003,-1.008370e-001
2.500000e+004,3.530687e+002,2.619358e-003,-9.940194e-002
2.500000e+004,3.456316e+002,2.290854e-003,-8.833838e-002
2.500000e+004,3.374739e+002,9.855622e-004,-5.294894e-004
2.500000e+004,3.294724e+002,9.802915e-004,5.087272e-003
2.500000e+004,3.216884e+002,9.782709e-004,7.075896e-003
2.500000e+004,3.136456e+002,9.813342e-004,1.091451e-002
2.500000e+004,3.057841e+002,9.784515e-004,1.052668e-002
2.500000e+004,3.012222e+002,9.756500e-004,9.236215e-003
2.500000e+004,3.092744e+002,9.803353e-004,8.687533e-003
2.500000e+004,3.172060e+002,9.753442e-004,4.832499e-003
2.500000e+004,3.252560e+002,9.728119e-004,6.906522e-004
2.500000e+004,3.332692e+002,9.729943e-004,-4.165939e-003
2.500000e+004,3.413974e+002,9.769336e-004,-9.009605e-003
2.500000e+004,3.493181e+002,9.868246e-004,-1.425910e-002
2.500000e+004,3.572889e+002,1.007143e-003,-2.122484e-002
2.500000e+004,3.652557e+002,1.351870e-003,-5.674107e-002
2.500000e+004,3.732292e+002,2.543153e-003,-1.167110e-001
2.500000e+004,3.815075e+002,2.510641e-003,-1.191432e-001
2.500000e+004,3.892791e+002,2.474835e-003,-1.210140e-001
2.500000e+004,3.972891e+002,2.427123e-003,-1.210773e-001
2.000000e+004,3.954996e+002,1.949933e-003,-1.140420e-001
2.000000e+004,3.872517e+002,1.984917e-003,-1.100878e-001
2.000000e+004,3.797322e+002,2.021614e-003,-1.106117e-001
2.000000e+004,3.707800e+002,2.054105e-003,-1.056933e-001
2.000000e+004,3.636796e+002,2.076095e-003,-1.022324e-001
2.000000e+004,3.552432e+002,2.097465e-003,-1.013781e-001
2.000000e+004,3.471587e+002,2.030552e-003,-9.461090e-002
2.000000e+004,3.393651e+002,7.990851e-004,-4.383525e-003
2.000000e+004,3.312718e+002,7.909823e-004,1.475801e-003
2.000000e+004,3.239022e+002,7.886211e-004,4.137672e-003
2.000000e+004,3.156460e+002,7.906115e-004,7.886700e-003
2.000000e+004,3.078803e+002,7.944349e-004,9.133102e-003
2.000000e+004,3.000818e+002,7.985453e-004,1.101235e-002
2.000000e+004,3.072770e+002,8.016889e-004,7.869789e-003
2.000000e+004,3.152514e+002,7.875151e-004,3.571847e-003
2.000000e+004,3.232943e+002,7.848387e-004,-3.853496e-004
2.000000e+004,3.312980e+002,7.845461e-004,-4.899633e-003
2.000000e+004,3.393050e+002,7.866858e-004,-9.241336e-003
2.000000e+004,3.473134e+002,7.934293e-004,-1.528382e-002
2.000000e+004,3.553214e+002,8.067748e-004,-2.137976e-002
2.000000e+004,3.632512e+002,9.141865e-004,-3.906406e-002
2.000000e+004,3.712576e+002,2.044912e-003,-1.163998e-001
2.000000e+004,3.792517e+002,2.020434e-003,-1.189595e-001
2.000000e+004,3.872577e+002,1.991914e-003,-1.209591e-001
2.000000e+004,3.952744e+002,1.956143e-003,-1.215731e-001
1.500000e+004,3.977179e+002,1.460521e-003,-1.158049e-001
1.500000e+004,3.893069e+002,1.486895e-003,-1.115887e-001
1.500000e+004,3.818169e+002,1.514400e-003,-1.092643e-001
1.500000e+004,3.730327e+002,1.539979e-003,-1.076026e-001
1.500000e+004,3.648021e+002,1.559892e-003,-1.033488e-001
1.500000e+004,3.575279e+002,1.574712e-003,-1.032885e-001
1.500000e+004,3.485173e+002,1.572864e-003,-9.763222e-002
1.500000e+004,3.419464e+002,6.357430e-004,-1.204775e-002
1.500000e+004,3.330767e+002,6.003547e-004,-2.660221e-003
1.500000e+004,3.256395e+002,5.988004e-004,1.746789e-003
1.500000e+004,3.173918e+002,5.991498e-004,3.285254e-003
1.500000e+004,3.095847e+002,6.016790e-004,7.147179e-003
1.500000e+004,3.015729e+002,6.048640e-004,8.256661e-003
1.500000e+004,3.053495e+002,6.021861e-004,6.187672e-003
1.500000e+004,3.132564e+002,5.979751e-004,1.275191e-003
1.500000e+004,3.214254e+002,5.955674e-004,-2.576529e-003
1.500000e+004,3.292561e+002,5.948152e-004,-6.990523e-003
1.500000e+004,3.372713e+002,5.960576e-004,-1.126281e-002
1.500000e+004,3.452609e+002,6.000315e-004,-1.683564e-002
1.500000e+004,3.533314e+002,6.086499e-004,-2.240317e-002
1.500000e+004,3.614615e+002,6.458950e-004,-3.302477e-002
1.500000e+004,3.692167e+002,1.442186e-003,-1.109585e-001
1.500000e+004,3.772276e+002,1.525454e-003,-1.192186e-001
1.500000e+004,3.852669e+002,1.504445e-003,-1.211960e-001
1.500000e+004,3.932349e+002,1.480223e-003,-1.225071e-001
1.000000e+004,4.000035e+002,9.749185e-004,-1.187300e-001
1.000000e+004,3.913353e+002,9.925137e-004,-1.134282e-001
1.000000e+004,3.836575e+002,1.011439e-003,-1.108130e-001
1.000000e+004,3.753569e+002,1.028626e-003,-1.100280e-001
1.000000e+004,3.667379e+002,1.043404e-003,-1.057420e-001
1.000000e+004,3.597266e+002,1.053321e-003,-1.052319e-001
1.000000e+004,3.507269e+002,1.061857e-003,-1.007138e-001
1.000000e+004,3.437230e+002,7.268232e-004,-7.510681e-002
1.000000e+004,3.352187e+002,4.079686e-004,-9.815305e-003
1.000000e+004,3.275974e+002,4.066715e-004,-4.389754e-003
1.000000e+004,3.195795e+002,4.064374e-004,-3.130004e-003
1.000000e+004,3.116068e+002,4.079896e-004,9.390436e-004
1.000000e+004,3.036728e+002,4.100791e-004,2.311384e-003
1.000000e+004,3.033170e+002,4.094985e-004,9.691031e-004
1.000000e+004,3.112518e+002,4.067268e-004,-2.878177e-003
1.000000e+004,3.192714e+002,4.047826e-004,-7.029384e-003
1.000000e+004,3.272686e+002,4.038570e-004,-1.100783e-002
1.000000e+004,3.353104e+002,4.043055e-004,-1.509113e-002
1.000000e+004,3.433637e+002,4.063989e-004,-2.075611e-002
1.000000e+004,3.513326e+002,4.110290e-004,-2.601325e-002
1.000000e+004,3.592611e+002,4.240943e-004,-3.388165e-002
1.000000e+004,3.672590e+002,7.961887e-004,-9.461734e-002
1.000000e+004,3.752258e+002,1.026092e-003,-1.195552e-001
1.000000e+004,3.832795e+002,1.012647e-003,-1.221640e-001
1.000000e+004,3.912389e+002,9.972518e-004,-1.234883e-001
1.000000e+004,3.992864e+002,9.769399e-004,-1.229272e-001
9.000000e+003,3.933731e+002,8.909531e-004,-1.151149e-001
9.000000e+003,3.855737e+002,9.067616e-004,-1.116380e-001
9.000000e+003,3.774839e+002,9.239706e-004,-1.116691e-001
9.000000e+003,3.688104e+002,9.377063e-004,-1.071980e-001
9.000000e+003,3.618300e+002,9.473722e-004,-1.038584e-001
9.000000e+003,3.530611e+002,9.567678e-004,-1.024208e-001
9.000000e+003,3.456340e+002,8.757082e-004,-9.409434e-002
9.000000e+003,3.374763e+002,3.708900e-004,-1.292020e-002
9.000000e+003,3.295634e+002,3.687688e-004,-8.080220e-003
9.000000e+003,3.217068e+002,3.682836e-004,-6.391245e-003
9.000000e+003,3.136417e+002,3.695531e-004,-2.263006e-003
9.000000e+003,3.058376e+002,3.709267e-004,-3.885638e-004
9.000000e+003,3.012490e+002,3.720037e-004,1.264569e-004
9.000000e+003,3.092971e+002,3.693378e-004,-4.775438e-003
9.000000e+003,3.172319e+002,3.672878e-004,-7.653543e-003
9.000000e+003,3.252496e+002,3.662976e-004,-1.214343e-002
9.000000e+003,3.332648e+002,3.662841e-004,-1.612438e-002
9.000000e+003,3.414370e+002,3.676559e-004,-2.166437e-002
9.000000e+003,3.492765e+002,3.712200e-004,-2.647001e-002
9.000000e+003,3.573043e+002,3.792105e-004,-3.303893e-002
9.000000e+003,3.652476e+002,5.495221e-004,-7.263525e-002
9.000000e+003,3.732996e+002,9.281154e-004,-1.194616e-001
9.000000e+003,3.815929e+002,9.161035e-004,-1.220858e-001
9.000000e+003,3.892637e+002,9.030245e-004,-1.237360e-001
9.000000e+003,3.972220e+002,8.856193e-004,-1.238567e-001
8.000000e+003,3.956455e+002,7.900998e-004,-1.167948e-001
8.000000e+003,3.873216e+002,8.049915e-004,-1.130135e-001
8.000000e+003,3.798372e+002,8.197164e-004,-1.135516e-001
8.000000e+003,3.708133e+002,8.330818e-004,-1.087447e-001
8.000000e+003,3.636609e+002,8.423136e-004,-1.049802e-001
8.000000e+003,3.553445e+002,8.510810e-004,-1.039803e-001
8.000000e+003,3.469583e+002,8.306123e-004,-9.749962e-002
8.000000e+003,3.396093e+002,3.350382e-004,-1.692177e-002
8.000000e+003,3.310860e+002,3.307628e-004,-1.071880e-002
8.000000e+003,3.239293e+002,3.300942e-004,-7.080106e-003
8.000000e+003,3.154250e+002,3.309152e-004,-4.505798e-003
8.000000e+003,3.078205e+002,3.323613e-004,-1.804795e-003
8.000000e+003,3.000906e+002,3.341769e-004,-7.794542e-004
8.000000e+003,3.073199e+002,3.315679e-004,-5.149735e-003
8.000000e+003,3.152416e+002,3.296869e-004,-9.086992e-003
8.000000e+003,3.232403e+002,3.285268e-004,-1.339034e-002
8.000000e+003,3.312563e+002,3.281888e-004,-1.772309e-002
8.000000e+003,3.393119e+002,3.291870e-004,-2.211840e-002
8.000000e+003,3.472601e+002,3.316954e-004,-2.684709e-002
8.000000e+003,3.552326e+002,3.373014e-004,-3.337383e-002
8.000000e+003,3.633256e+002,3.980155e-004,-5.343435e-002
8.000000e+003,3.712520e+002,8.296390e-004,-1.194435e-001
8.000000e+003,3.792227e+002,8.194479e-004,-1.218530e-001
8.000000e+003,3.872607e+002,8.078190e-004,-1.238807e-001
8.000000e+003,3.953093e+002,7.932691e-004,-1.246832e-001
7.000000e+003,3.977627e+002,6.916767e-004,-1.186535e-001
7.000000e+003,3.894145e+002,7.043078e-004,-1.138873e-001
7.000000e+003,3.817786e+002,7.176520e-004,-1.119635e-001
7.000000e+003,3.728250e+002,7.300740e-004,-1.100266e-001
7.000000e+003,3.650757e+002,7.389624e-004,-1.060484e-001
7.000000e+003,3.574406e+002,7.466077e-004,-1.056308e-001
7.000000e+003,3.488636e+002,7.493192e-004,-1.008961e-001
7.000000e+003,3.417289e+002,3.158052e-004,-2.668384e-002
7.000000e+003,3.331143e+002,2.931206e-004,-1.422996e-002
7.000000e+003,3.257957e+002,2.924064e-004,-1.035739e-002
7.000000e+003,3.175018e+002,2.927561e-004,-8.244460e-003
7.000000e+003,3.097742e+002,2.941046e-004,-7.030421e-003
7.000000e+003,3.016302e+002,2.955288e-004,-3.659708e-003
7.000000e+003,3.054672e+002,2.940297e-004,-7.246195e-003
7.000000e+003,3.132583e+002,2.922625e-004,-1.097648e-002
7.000000e+003,3.214109e+002,2.909461e-004,-1.495034e-002
7.000000e+003,3.292821e+002,2.905103e-004,-1.879965e-002
7.000000e+003,3.372667e+002,2.910751e-004,-2.380303e-002
7.000000e+003,3.452585e+002,2.929240e-004,-2.856435e-002
7.000000e+003,3.532262e+002,2.970304e-004,-3.412969e-002
7.000000e+003,3.615246e+002,3.203270e-004,-4.545119e-002
7.000000e+003,3.692827e+002,7.080566e-004,-1.167040e-001
7.000000e+003,3.773167e+002,7.226150e-004,-1.216434e-001
7.000000e+003,3.852579e+002,7.129468e-004,-1.237626e-001
7.000000e+003,3.932976e+002,7.014755e-004,-1.251945e-001
6.000000e+003,4.000035e+002,5.925645e-004,-1.209196e-001
6.000000e+003,3.912173e+002,6.035534e-004,-1.156673e-001
6.000000e+003,3.835920e+002,6.151318e-004,-1.132453e-001
6.000000e+003,3.751749e+002,6.255287e-004,-1.120366e-001
6.000000e+003,3.667622e+002,6.342158e-004,-1.075759e-001
6.000000e+003,3.596433e+002,6.406127e-004,-1.073197e-001
6.000000e+003,3.507368e+002,6.460002e-004,-1.026678e-001
6.000000e+003,3.437608e+002,4.664850e-004,-8.135305e-002
6.000000e+003,3.352231e+002,2.546095e-004,-1.850743e-002
6.000000e+003,3.277086e+002,2.536738e-004,-1.455811e-002
6.000000e+003,3.196423e+002,2.536447e-004,-1.265476e-002
6.000000e+003,3.116163e+002,2.546613e-004,-8.519297e-003
6.000000e+003,3.035131e+002,2.559402e-004,-7.286404e-003
6.000000e+003,3.033279e+002,2.554801e-004,-8.788751e-003
6.000000e+003,3.113170e+002,2.538464e-004,-1.269941e-002
6.000000e+003,3.192694e+002,2.525953e-004,-1.696923e-002
6.000000e+003,3.272793e+002,2.520588e-004,-2.043782e-002
6.000000e+003,3.352521e+002,2.522679e-004,-2.542391e-002
6.000000e+003,3.432622e+002,2.534685e-004,-3.014168e-002
6.000000e+003,3.512632e+002,2.564432e-004,-3.542573e-002
6.000000e+003,3.592664e+002,2.655070e-004,-4.325508e-002
6.000000e+003,3.673134e+002,5.246639e-004,-1.041353e-001
6.000000e+003,3.753168e+002,6.239322e-004,-1.216673e-001
6.000000e+003,3.833300e+002,6.156830e-004,-1.239645e-001
6.000000e+003,3.913009e+002,6.064518e-004,-1.256426e-001
6.000000e+003,3.992606e+002,5.941430e-004,-1.252390e-001
5.000000e+003,3.934389e+002,5.030451e-004,-1.177282e-001
5.000000e+003,3.856219e+002,5.122207e-004,-1.142886e-001
5.000000e+003,3.774176e+002,5.217121e-004,-1.139828e-001
5.000000e+003,3.684597e+002,5.298242e-004,-1.094601e-001
5.000000e+003,3.617800e+002,5.350658e-004,-1.064305e-001
5.000000e+003,3.528285e+002,5.405516e-004,-1.049151e-001
5.000000e+003,3.456292e+002,5.048683e-004,-9.730664e-002
5.000000e+003,3.374466e+002,2.157761e-004,-2.408269e-002
5.000000e+003,3.295286e+002,2.146085e-004,-1.899786e-002
5.000000e+003,3.215569e+002,2.143156e-004,-1.714596e-002
5.000000e+003,3.135774e+002,2.150725e-004,-1.336918e-002
5.000000e+003,3.057417e+002,2.159513e-004,-1.219766e-002
5.000000e+003,3.012204e+002,2.165054e-004,-1.137995e-002
5.000000e+003,3.093046e+002,2.149414e-004,-1.574086e-002
5.000000e+003,3.172538e+002,2.138785e-004,-1.936274e-002
5.000000e+003,3.252244e+002,2.132023e-004,-2.375775e-002
5.000000e+003,3.332470e+002,2.132026e-004,-2.789776e-002
5.000000e+003,3.414230e+002,2.140017e-004,-3.274482e-002
5.000000e+003,3.492153e+002,2.159773e-004,-3.726765e-002
5.000000e+003,3.572684e+002,2.207097e-004,-4.435974e-002
5.000000e+003,3.652637e+002,3.422852e-004,-8.526862e-002
5.000000e+003,3.732292e+002,5.242319e-004,-1.219924e-001
5.000000e+003,3.815605e+002,5.173411e-004,-1.246209e-001
5.000000e+003,3.892146e+002,5.100444e-004,-1.266991e-001
5.000000e+003,3.972955e+002,5.002328e-004,-1.265351e-001
4.000000e+003,3.955822e+002,4.034625e-004,-1.205240e-001
4.000000e+003,3.873946e+002,4.108363e-004,-1.164037e-001
4.000000e+003,3.797584e+002,4.184897e-004,-1.166017e-001
4.000000e+003,3.709633e+002,4.250819e-004,-1.120432e-001
4.000000e+003,3.637009e+002,4.298647e-004,-1.083412e-001
4.000000e+003,3.553522e+002,4.344165e-004,-1.073899e-001
4.000000e+003,3.474393e+002,4.305364e-004,-1.021159e-001
4.000000e+003,3.396162e+002,1.774524e-004,-3.033780e-002
4.000000e+003,3.311472e+002,1.750262e-004,-2.485827e-002
4.000000e+003,3.238354e+002,1.746751e-004,-2.268062e-002
4.000000e+003,3.155690e+002,1.751928e-004,-1.926767e-002
4.000000e+003,3.078616e+002,1.757620e-004,-1.629498e-002
4.000000e+003,3.000853e+002,1.768217e-004,-1.541211e-002
4.000000e+003,3.073498e+002,1.754331e-004,-1.935007e-002
4.000000e+003,3.153302e+002,1.744411e-004,-2.412243e-002
4.000000e+003,3.233296e+002,1.738455e-004,-2.798374e-002
4.000000e+003,3.312892e+002,1.737116e-004,-3.192118e-002
4.000000e+003,3.392866e+002,1.741615e-004,-3.639062e-002
4.000000e+003,3.473133e+002,1.754571e-004,-4.148179e-002
4.000000e+003,3.553290e+002,1.784095e-004,-4.677216e-002
4.000000e+003,3.635730e+002,2.250213e-004,-7.058638e-002
4.000000e+003,3.712186e+002,4.236343e-004,-1.225072e-001
4.000000e+003,3.792576e+002,4.183217e-004,-1.251315e-001
4.000000e+003,3.872273e+002,4.124527e-004,-1.272880e-001
4.000000e+003,3.952776e+002,4.051682e-004,-1.280574e-001
3.000000e+003,3.977755e+002,3.041831e-004,-1.232135e-001
3.000000e+003,3.893806e+002,3.098793e-004,-1.190835e-001
3.000000e+003,3.817432e+002,3.156396e-004,-1.164853e-001
3.000000e+003,3.730610e+002,3.208815e-004,-1.149492e-001
3.000000e+003,3.651348e+002,3.249542e-004,-1.106037e-001
3.000000e+003,3.575434e+002,3.282866e-004,-1.103547e-001
3.000000e+003,3.487587e+002,3.297424e-004,-1.054245e-001
3.000000e+003,3.418037e+002,1.470245e-004,-4.365624e-002
3.000000e+003,3.331431e+002,1.349513e-004,-3.252140e-002
3.000000e+003,3.258062e+002,1.346517e-004,-2.835405e-002
3.000000e+003,3.174958e+002,1.347020e-004,-2.625636e-002
3.000000e+003,3.097704e+002,1.352888e-004,-2.388895e-002
3.000000e+003,3.016105e+002,1.360042e-004,-2.179311e-002
3.000000e+003,3.053090e+002,1.354275e-004,-2.483172e-002
3.000000e+003,3.132525e+002,1.345609e-004,-2.927759e-002
3.000000e+003,3.215178e+002,1.340370e-004,-3.315112e-002
3.000000e+003,3.292778e+002,1.338008e-004,-3.747504e-002
3.000000e+003,3.373235e+002,1.339994e-004,-4.151528e-002
3.000000e+003,3.452968e+002,1.347965e-004,-4.620435e-002
3.000000e+003,3.532939e+002,1.365681e-004,-5.172038e-002
3.000000e+003,3.615772e+002,1.492824e-004,-6.258242e-002
3.000000e+003,3.692524e+002,3.165953e-004,-1.227246e-001
3.000000e+003,3.772736e+002,3.177783e-004,-1.264021e-001
3.000000e+003,3.852880e+002,3.135502e-004,-1.288363e-001
3.000000e+003,3.932694e+002,3.085510e-004,-1.300441e-001
2.500000e+003,4.000035e+002,2.541872e-004,-1.262207e-001
2.500000e+003,3.911027e+002,2.589819e-004,-1.208964e-001
2.500000e+003,3.834015e+002,2.638873e-004,-1.183357e-001
2.500000e+003,3.752546e+002,2.681521e-004,-1.169855e-001
2.500000e+003,3.662560e+002,2.721018e-004,-1.122606e-001
2.500000e+003,3.595315e+002,2.746400e-004,-1.122606e-001
2.500000e+003,3.501110e+002,2.770374e-004,-1.074843e-001
2.500000e+003,3.437750e+002,2.126817e-004,-9.185724e-002
2.500000e+003,3.350505e+002,1.147036e-004,-3.829973e-002
2.500000e+003,3.276658e+002,1.143590e-004,-3.373372e-002
2.500000e+003,3.195106e+002,1.143447e-004,-3.191260e-002
2.500000e+003,3.115165e+002,1.147772e-004,-2.843552e-002
2.500000e+003,3.035040e+002,1.153616e-004,-2.685617e-002
2.500000e+003,3.033079e+002,1.151897e-004,-2.853938e-002
2.500000e+003,3.113304e+002,1.144388e-004,-3.264924e-002
2.500000e+003,3.192978e+002,1.139600e-004,-3.625216e-002
2.500000e+003,3.272772e+002,1.136555e-004,-4.039818e-002
2.500000e+003,3.353194e+002,1.137040e-004,-4.483520e-002
2.500000e+003,3.433141e+002,1.142655e-004,-4.939467e-002
2.500000e+003,3.513127e+002,1.154751e-004,-5.443228e-002
2.500000e+003,3.593235e+002,1.197257e-004,-6.160117e-002
2.500000e+003,3.673026e+002,2.346148e-004,-1.138325e-001
2.500000e+003,3.752799e+002,2.675701e-004,-1.269594e-001
2.500000e+003,3.833181e+002,2.641644e-004,-1.293976e-001
2.500000e+003,3.913226e+002,2.601025e-004,-1.310220e-001
2.500000e+003,3.993122e+002,2.550325e-004,-1.307182e-001
2.000000e+003,3.934044e+002,2.081541e-004,-1.236764e-001
2.000000e+003,3.851169e+002,2.121624e-004,-1.201985e-001
2.000000e+003,3.775156e+002,2.156668e-004,-1.198331e-001
2.000000e+003,3.681069e+002,2.190829e-004,-1.149870e-001
2.000000e+003,3.618590e+002,2.210617e-004,-1.122512e-001
2.000000e+003,3.528534e+002,2.234080e-004,-1.103364e-001
2.000000e+003,3.456077e+002,2.110344e-004,-1.038342e-001
2.000000e+003,3.372375e+002,9.426395e-005,-4.495744e-002
2.000000e+003,3.291008e+002,9.381579e-005,-4.006833e-002
2.000000e+003,3.215179e+002,9.370665e-005,-3.824176e-002
2.000000e+003,3.135989e+002,9.403819e-005,-3.447133e-002
2.000000e+003,3.057436e+002,9.437956e-005,-3.284074e-002
2.000000e+003,3.012579e+002,9.466364e-005,-3.296228e-002
2.000000e+003,3.093689e+002,9.400306e-005,-3.687532e-002
2.000000e+003,3.172878e+002,9.351039e-005,-4.107818e-002
2.000000e+003,3.252959e+002,9.323635e-005,-4.558474e-002
2.000000e+003,3.332626e+002,9.320355e-005,-4.933395e-002
2.000000e+003,3.415328e+002,9.350880e-005,-5.347351e-002
2.000000e+003,3.493010e+002,9.429548e-005,-5.856097e-002
2.000000e+003,3.572838e+002,9.628951e-005,-6.420014e-002
2.000000e+003,3.652691e+002,1.518796e-004,-9.962265e-002
2.000000e+003,3.732771e+002,2.167899e-004,-1.279012e-001
2.000000e+003,3.816489e+002,2.139339e-004,-1.305586e-001
2.000000e+003,3.892791e+002,2.109821e-004,-1.325891e-001
2.000000e+003,3.972795e+002,2.070407e-004,-1.326147e-001
1.500000e+003,3.955282e+002,1.575048e-004,-1.272811e-001
1.500000e+003,3.869634e+002,1.605911e-004,-1.228806e-001
1.500000e+003,3.797497e+002,1.632461e-004,-1.232889e-001
1.500000e+003,3.700521e+002,1.659828e-004,-1.179799e-001
1.500000e+003,3.629671e+002,1.678267e-004,-1.146629e-001
1.500000e+003,3.551771e+002,1.693875e-004,-1.138511e-001
1.500000e+003,3.467316e+002,1.663990e-004,-1.078396e-001
1.500000e+003,3.394686e+002,7.361671e-005,-5.397443e-002
1.500000e+003,3.308020e+002,7.280349e-005,-4.814427e-002
1.500000e+003,3.237521e+002,7.266380e-005,-4.655832e-002
1.500000e+003,3.154842e+002,7.287996e-005,-4.242278e-002
1.500000e+003,3.078916e+002,7.316317e-005,-3.989079e-002
1.500000e+003,3.000836e+002,7.352968e-005,-3.880690e-002
1.500000e+003,3.074188e+002,7.306520e-005,-4.317639e-002
1.500000e+003,3.153008e+002,7.263823e-005,-4.749679e-002
1.500000e+003,3.232590e+002,7.241801e-005,-5.142367e-002
1.500000e+003,3.312607e+002,7.229894e-005,-5.587168e-002
1.500000e+003,3.392866e+002,7.244271e-005,-6.040493e-002
1.500000e+003,3.473013e+002,7.289505e-005,-6.374733e-002
1.500000e+003,3.552631e+002,7.397626e-005,-6.962259e-002
1.500000e+003,3.632778e+002,9.109737e-005,-8.662102e-002
1.500000e+003,3.713049e+002,1.652353e-004,-1.296920e-001
1.500000e+003,3.792924e+002,1.631831e-004,-1.323741e-001
1.500000e+003,3.872212e+002,1.610362e-004,-1.345001e-001
1.500000e+003,3.953188e+002,1.582260e-004,-1.352361e-001
1.000000e+003,3.977659e+002,1.066732e-004,-1.321000e-001
1.000000e+003,3.889174e+002,1.087383e-004,-1.274481e-001
1.000000e+003,3.817226e+002,1.105114e-004,-1.249091e-001
1.000000e+003,3.727382e+002,1.124295e-004,-1.229509e-001
1.000000e+003,3.644324e+002,1.138786e-004,-1.186253e-001
1.000000e+003,3.573508e+002,1.149183e-004,-1.183497e-001
1.000000e+003,3.479653e+002,1.151404e-004,-1.127986e-001
1.000000e+003,3.418481e+002,5.514844e-005,-6.803150e-002
1.000000e+003,3.323611e+002,5.112813e-005,-5.918014e-002
1.000000e+003,3.257028e+002,5.104325e-005,-5.633120e-002
1.000000e+003,3.173439e+002,5.111630e-005,-5.384753e-002
1.000000e+003,3.096681e+002,5.131658e-005,-5.072438e-002
1.000000e+003,3.014834e+002,5.158259e-005,-5.002426e-002
1.000000e+003,3.053127e+002,5.135969e-005,-5.293102e-002
1.000000e+003,3.132759e+002,5.107054e-005,-5.700523e-002
1.000000e+003,3.214438e+002,5.083324e-005,-6.063162e-002
1.000000e+003,3.292670e+002,5.077005e-005,-6.563552e-002
1.000000e+003,3.372713e+002,5.076654e-005,-6.903308e-002
1.000000e+003,3.452610e+002,5.098606e-005,-7.317767e-002
1.000000e+003,3.532939e+002,5.160948e-005,-7.835324e-002
1.000000e+003,3.614562e+002,5.580288e-005,-8.591413e-002
1.000000e+003,3.692222e+002,1.113675e-004,-1.316791e-001
1.000000e+003,3.772592e+002,1.113485e-004,-1.347622e-001
1.000000e+003,3.852880e+002,1.099059e-004,-1.367203e-001
1.000000e+003,3.932725e+002,1.082716e-004,-1.384581e-001
9.000000e+002,4.000035e+002,9.613564e-005,-1.348028e-001
9.000000e+002,3.911089e+002,9.781061e-005,-1.290496e-001
9.000000e+002,3.835294e+002,9.962320e-005,-1.268032e-001
9.000000e+002,3.753001e+002,1.012887e-004,-1.255774e-001
9.000000e+002,3.660613e+002,1.027974e-004,-1.208278e-001
9.000000e+002,3.595809e+002,1.036804e-004,-1.205982e-001
9.000000e+002,3.502117e+002,1.045967e-004,-1.152116e-001
9.000000e+002,3.436970e+002,8.346143e-005,-1.037072e-001
9.000000e+002,3.348869e+002,4.674437e-005,-6.379952e-002
9.000000e+002,3.272879e+002,4.664347e-005,-5.867786e-002
9.000000e+002,3.193951e+002,4.664171e-005,-5.790580e-002
9.000000e+002,3.116222e+002,4.679650e-005,-5.446023e-002
9.000000e+002,3.035512e+002,4.708301e-005,-5.315083e-002
9.000000e+002,3.032753e+002,4.700873e-005,-5.416087e-002
9.000000e+002,3.112614e+002,4.671836e-005,-5.833194e-002
9.000000e+002,3.193018e+002,4.647417e-005,-6.210136e-002
9.000000e+002,3.272451e+002,4.638398e-005,-6.681953e-002
9.000000e+002,3.352610e+002,4.639709e-005,-7.097702e-002
9.000000e+002,3.432929e+002,4.649547e-005,-7.540500e-002
9.000000e+002,3.512483e+002,4.696444e-005,-7.913427e-002
9.000000e+002,3.592637e+002,4.844241e-005,-8.519246e-002
9.000000e+002,3.672999e+002,9.109119e-005,-1.249205e-001
9.000000e+002,3.752685e+002,1.011643e-004,-1.354088e-001
9.000000e+002,3.832795e+002,9.989036e-005,-1.377313e-001
9.000000e+002,3.912668e+002,9.838927e-005,-1.393825e-001
9.000000e+002,3.993316e+002,9.655993e-005,-1.388433e-001
8.000000e+002,3.934578e+002,8.712290e-005,-1.319310e-001
8.000000e+002,3.853001e+002,8.880203e-005,-1.284821e-001
8.000000e+002,3.773112e+002,9.036512e-005,-1.275898e-001
8.000000e+002,3.677329e+002,9.172602e-005,-1.222396e-001
8.000000e+002,3.618300e+002,9.251344e-005,-1.197961e-001
8.000000e+002,3.526086e+002,9.347068e-005,-1.176868e-001
8.000000e+002,3.453685e+002,8.841524e-005,-1.118189e-001
8.000000e+002,3.373647e+002,4.236203e-005,-6.895334e-002
8.000000e+002,3.291245e+002,4.221137e-005,-6.313045e-002
8.000000e+002,3.215240e+002,4.220449e-005,-6.193031e-002
8.000000e+002,3.134997e+002,4.234099e-005,-5.803432e-002
8.000000e+002,3.057749e+002,4.249143e-005,-5.700662e-002
8.000000e+002,3.012454e+002,4.259392e-005,-5.627576e-002
8.000000e+002,3.093216e+002,4.233259e-005,-6.083209e-002
8.000000e+002,3.172958e+002,4.210458e-005,-6.524554e-002
8.000000e+002,3.252959e+002,4.201370e-005,-7.003371e-002
8.000000e+002,3.332493e+002,4.190601e-005,-7.248686e-002
8.000000e+002,3.414978e+002,4.205938e-005,-7.698878e-002
8.000000e+002,3.492373e+002,4.234103e-005,-8.168402e-002
8.000000e+002,3.572709e+002,4.310754e-005,-8.696522e-002
8.000000e+002,3.652880e+002,6.655394e-005,-1.127488e-001
8.000000e+002,3.732602e+002,9.078988e-005,-1.354128e-001
8.000000e+002,3.814810e+002,8.964402e-005,-1.378941e-001
8.000000e+002,3.892883e+002,8.841658e-005,-1.405012e-001
8.000000e+002,3.972507e+002,8.682336e-005,-1.404299e-001
7.000000e+002,3.955091e+002,7.649230e-005,-1.343629e-001
7.000000e+002,3.867422e+002,7.793448e-005,-1.301156e-001
7.000000e+002,3.798079e+002,7.925752e-005,-1.299152e-001
7.000000e+002,3.701017e+002,8.050873e-005,-1.244678e-001
7.000000e+002,3.627311e+002,8.144962e-005,-1.211216e-001
7.000000e+002,3.552228e+002,8.223428e-005,-1.200668e-001
7.000000e+002,3.465679e+002,8.100634e-005,-1.143063e-001
7.000000e+002,3.395771e+002,3.808401e-005,-7.427635e-002
7.000000e+002,3.307214e+002,3.765938e-005,-6.803187e-002
7.000000e+002,3.239773e+002,3.763021e-005,-6.546982e-002
7.000000e+002,3.154980e+002,3.773715e-005,-6.273169e-002
7.000000e+002,3.078130e+002,3.790382e-005,-5.966631e-002
7.000000e+002,3.001013e+002,3.814504e-005,-5.934574e-002
7.000000e+002,3.073591e+002,3.779661e-005,-6.405191e-002
7.000000e+002,3.152456e+002,3.757556e-005,-6.740265e-002
7.000000e+002,3.232237e+002,3.750851e-005,-7.051294e-002
7.000000e+002,3.312542e+002,3.743055e-005,-7.547645e-002
7.000000e+002,3.392405e+002,3.744401e-005,-7.977965e-002
7.000000e+002,3.473182e+002,3.769310e-005,-8.329588e-002
7.000000e+002,3.552302e+002,3.816764e-005,-8.869982e-002
7.000000e+002,3.632805e+002,4.695877e-005,-1.019225e-001
7.000000e+002,3.712492e+002,8.022583e-005,-1.360035e-001
7.000000e+002,3.792896e+002,7.925856e-005,-1.382801e-001
7.000000e+002,3.872394e+002,7.823916e-005,-1.406971e-001
7.000000e+002,3.953188e+002,7.690886e-005,-1.418880e-001
6.000000e+002,3.978204e+002,6.579480e-005,-1.367258e-001
6.000000e+002,3.888653e+002,6.703805e-005,-1.322507e-001
6.000000e+002,3.817609e+002,6.818317e-005,-1.296691e-001
6.000000e+002,3.728701e+002,6.937337e-005,-1.275681e-001
6.000000e+002,3.646815e+002,7.018498e-005,-1.229606e-001
6.000000e+002,3.573842e+002,7.090754e-005,-1.231708e-001
6.000000e+002,3.481475e+002,7.114989e-005,-1.175577e-001
6.000000e+002,3.417663e+002,3.619476e-005,-8.290549e-002
6.000000e+002,3.327848e+002,3.306320e-005,-7.370009e-002
6.000000e+002,3.258379e+002,3.303210e-005,-7.000770e-002
6.000000e+002,3.174678e+002,3.312468e-005,-6.909791e-002
6.000000e+002,3.097780e+002,3.326063e-005,-6.479216e-002
6.000000e+002,3.015353e+002,3.341162e-005,-6.284864e-002
6.000000e+002,3.053090e+002,3.328942e-005,-6.601562e-002
6.000000e+002,3.132739e+002,3.305991e-005,-7.084617e-002
6.000000e+002,3.214890e+002,3.291800e-005,-7.452559e-002
6.000000e+002,3.293145e+002,3.285446e-005,-7.900441e-002
6.000000e+002,3.373554e+002,3.291029e-005,-8.229481e-002
6.000000e+002,3.452992e+002,3.296239e-005,-8.612035e-002
6.000000e+002,3.533390e+002,3.333339e-005,-9.128184e-002
6.000000e+002,3.615904e+002,3.643927e-005,-9.843856e-002
6.000000e+002,3.693019e+002,6.928315e-005,-1.362929e-001
6.000000e+002,3.773081e+002,6.876392e-005,-1.393352e-001
6.000000e+002,3.852489e+002,6.788608e-005,-1.416503e-001
6.000000e+002,3.932725e+002,6.686616e-005,-1.432000e-001
5.000000e+002,4.000164e+002,5.509573e-005,-1.405045e-001
5.000000e+002,3.912080e+002,5.622419e-005,-1.359883e-001
5.000000e+002,3.835622e+002,5.721905e-005,-1.318593e-001
5.000000e+002,3.751239e+002,5.818378e-005,-1.308134e-001
5.000000e+002,3.660938e+002,5.900161e-005,-1.254645e-001
5.000000e+002,3.595471e+002,5.957193e-005,-1.257459e-001
5.000000e+002,3.503841e+002,6.004058e-005,-1.206383e-001
5.000000e+002,3.437963e+002,4.948768e-005,-1.112721e-001
5.000000e+002,3.349047e+002,2.835990e-005,-7.957247e-002
5.000000e+002,3.276787e+002,2.835221e-005,-7.568793e-002
5.000000e+002,3.194133e+002,2.838038e-005,-7.507361e-002
5.000000e+002,3.117086e+002,2.845233e-005,-7.117879e-002
5.000000e+002,3.035112e+002,2.860230e-005,-6.957567e-002
5.000000e+002,3.032753e+002,2.857621e-005,-7.020357e-002
5.000000e+002,3.112671e+002,2.839814e-005,-7.533693e-002
5.000000e+002,3.193423e+002,2.825974e-005,-7.977390e-002
5.000000e+002,3.273283e+002,2.819500e-005,-8.338241e-002
5.000000e+002,3.352431e+002,2.820353e-005,-8.678405e-002
5.000000e+002,3.432505e+002,2.826020e-005,-9.088497e-002
5.000000e+002,3.512780e+002,2.847682e-005,-9.484103e-002
5.000000e+002,3.592950e+002,2.935777e-005,-1.007872e-001
5.000000e+002,3.673297e+002,5.369802e-005,-1.326059e-001
5.000000e+002,3.752970e+002,5.809645e-005,-1.401934e-001
5.000000e+002,3.832705e+002,5.738435e-005,-1.424530e-001
5.000000e+002,3.912637e+002,5.655168e-005,-1.442290e-001
5.000000e+002,3.992735e+002,5.552627e-005,-1.440887e-001
4.000000e+002,3.933418e+002,4.532924e-005,-1.381570e-001
4.000000e+002,3.851619e+002,4.624109e-005,-1.344475e-001
4.000000e+002,3.775242e+002,4.700451e-005,-1.342678e-001
4.000000e+002,3.680387e+002,4.772568e-005,-1.286037e-001
4.000000e+002,3.618300e+002,4.812399e-005,-1.260719e-001
4.000000e+002,3.525763e+002,4.868906e-005,-1.246914e-001
4.000000e+002,3.452634e+002,4.615685e-005,-1.183423e-001
4.000000e+002,3.373033e+002,2.356996e-005,-8.787723e-002
4.000000e+002,3.291742e+002,2.355412e-005,-8.379137e-002
4.000000e+002,3.215384e+002,2.356370e-005,-8.311297e-002
4.000000e+002,3.135618e+002,2.366909e-005,-7.651484e-002
4.000000e+002,3.057270e+002,2.372470e-005,-7.643592e-002
4.000000e+002,3.012419e+002,2.378951e-005,-7.668653e-002
4.000000e+002,3.092706e+002,2.362485e-005,-8.077833e-002
4.000000e+002,3.172838e+002,2.349791e-005,-8.555151e-002
4.000000e+002,3.252748e+002,2.341159e-005,-8.889933e-002
4.000000e+002,3.332759e+002,2.338702e-005,-9.360424e-002
4.000000e+002,3.414580e+002,2.340640e-005,-9.625138e-002
4.000000e+002,3.492643e+002,2.354227e-005,-1.005321e-001
4.000000e+002,3.572632e+002,2.393982e-005,-1.043005e-001
4.000000e+002,3.652718e+002,3.644279e-005,-1.245011e-001
4.000000e+002,3.732968e+002,4.729454e-005,-1.420333e-001
4.000000e+002,3.814869e+002,4.670567e-005,-1.449025e-001
4.000000e+002,3.892976e+002,4.604205e-005,-1.464699e-001
4.000000e+002,3.972380e+002,4.525611e-005,-1.464961e-001
3.000000e+002,3.955409e+002,3.450514e-005,-1.440703e-001
3.000000e+002,3.869968e+002,3.514729e-005,-1.381571e-001
3.000000e+002,3.796855e+002,3.578363e-005,-1.395534e-001
3.000000e+002,3.704947e+002,3.633158e-005,-1.339463e-001
3.000000e+002,3.632858e+002,3.675013e-005,-1.301499e-001
3.000000e+002,3.549290e+002,3.717846e-005,-1.289106e-001
3.000000e+002,3.464211e+002,3.657693e-005,-1.228969e-001
3.000000e+002,3.395194e+002,1.871748e-005,-9.724915e-002
3.000000e+002,3.309723e+002,1.856875e-005,-9.385440e-002
3.000000e+002,3.237854e+002,1.854364e-005,-9.046422e-002
3.000000e+002,3.154744e+002,1.864525e-005,-8.924986e-002
3.000000e+002,3.078916e+002,1.869202e-005,-8.498150e-002
3.000000e+002,3.000800e+002,1.877579e-005,-8.425217e-002
3.000000e+002,3.072733e+002,1.868693e-005,-8.953163e-002
3.000000e+002,3.152987e+002,1.857469e-005,-9.319744e-002
3.000000e+002,3.232672e+002,1.849983e-005,-9.779067e-002
3.000000e+002,3.313111e+002,1.843937e-005,-1.020201e-001
3.000000e+002,3.392705e+002,1.845737e-005,-1.050681e-001
3.000000e+002,3.472722e+002,1.852932e-005,-1.072312e-001
3.000000e+002,3.553189e+002,1.874471e-005,-1.126035e-001
3.000000e+002,3.633309e+002,2.305624e-005,-1.212598e-001
3.000000e+002,3.712465e+002,3.620897e-005,-1.444903e-001
3.000000e+002,3.792867e+002,3.580507e-005,-1.467918e-001
3.000000e+002,3.873336e+002,3.530757e-005,-1.496337e-001
3.000000e+002,3.952745e+002,3.475816e-005,-1.506440e-001
2.000000e+002,3.977820e+002,2.355316e-005,-1.498798e-001
2.000000e+002,3.891167e+002,2.400721e-005,-1.449245e-001
2.000000e+002,3.817844e+002,2.444351e-005,-1.430030e-001
2.000000e+002,3.724328e+002,2.486972e-005,-1.396095e-001
2.000000e+002,3.643575e+002,2.521293e-005,-1.361229e-001
2.000000e+002,3.574125e+002,2.544328e-005,-1.365173e-001
2.000000e+002,3.482375e+002,2.555129e-005,-1.305528e-001
2.000000e+002,3.416239e+002,1.442924e-005,-1.141973e-001
2.000000e+002,3.329683e+002,1.343695e-005,-1.078457e-001
2.000000e+002,3.258379e+002,1.348113e-005,-1.076898e-001
2.000000e+002,3.174458e+002,1.353152e-005,-1.047168e-001
2.000000e+002,3.097628e+002,1.353636e-005,-1.024684e-001
2.000000e+002,3.016283e+002,1.363247e-005,-1.001752e-001
2.000000e+002,3.053072e+002,1.356120e-005,-1.022332e-001
2.000000e+002,3.132953e+002,1.345186e-005,-1.088270e-001
2.000000e+002,3.214623e+002,1.341147e-005,-1.119766e-001
2.000000e+002,3.293167e+002,1.335209e-005,-1.152123e-001
2.000000e+002,3.372826e+002,1.333418e-005,-1.166337e-001
2.000000e+002,3.452872e+002,1.336948e-005,-1.216928e-001
2.000000e+002,3.532838e+002,1.345094e-005,-1.251747e-001
2.000000e+002,3.615220e+002,1.451803e-005,-1.287223e-001
2.000000e+002,3.692360e+002,2.489927e-005,-1.499711e-001
2.000000e+002,3.772534e+002,2.465116e-005,-1.515619e-001
2.000000e+002,3.852759e+002,2.434518e-005,-1.540330e-001
2.000000e+002,3.933008e+002,2.404117e-005,-1.556719e-001
1.000000e+002,4.000067e+002,1.240465e-005,-1.674611e-001
1.000000e+002,3.910313e+002,1.270026e-005,-1.608790e-001
1.000000e+002,3.836188e+002,1.300717e-005,-1.602479e-001
1.000000e+002,3.752802e+002,1.326973e-005,-1.576195e-001
1.000000e+002,3.662154e+002,1.342900e-005,-1.512136e-001
1.000000e+002,3.596668e+002,1.359683e-005,-1.495701e-001
1.000000e+002,3.501995e+002,1.372903e-005,-1.454471e-001
1.000000e+002,3.438176e+002,1.199161e-005,-1.414251e-001
1.000000e+002,3.352506e+002,8.079836e-006,-1.364932e-001
1.000000e+002,3.276359e+002,8.095851e-006,-1.341247e-001
1.000000e+002,3.195248e+002,8.124874e-006,-1.352619e-001
1.000000e+002,3.116875e+002,8.148986e-006,-1.296102e-001
1.000000e+002,3.037020e+002,8.188760e-006,-1.267666e-001
1.000000e+002,3.033678e+002,8.157187e-006,-1.270410e-001
1.000000e+002,3.112633e+002,8.097414e-006,-1.348808e-001
1.000000e+002,3.192978e+002,8.121748e-006,-1.366772e-001
1.000000e+002,3.272558e+002,8.062891e-006,-1.418054e-001
1.000000e+002,3.353037e+002,8.038767e-006,-1.430936e-001
1.000000e+002,3.433165e+002,8.012017e-006,-1.451815e-001
1.000000e+002,3.513301e+002,8.009173e-006,-1.496721e-001
1.000000e+002,3.592897e+002,8.133411e-006,-1.530403e-001
1.000000e+002,3.672944e+002,1.258841e-005,-1.597358e-001
1.000000e+002,3.752913e+002,1.331464e-005,-1.636510e-001
1.000000e+002,3.833092e+002,1.311631e-005,-1.681676e-001
1.000000e+002,3.913133e+002,1.289576e-005,-1.690821e-001
1.000000e+002,3.992832e+002,1.269024e-005,-1.661355e-001
0.000000e+000,3.934045e+002,1.155989e-006,-4.180284e-001
0.000000e+000,3.850658e+002,1.295636e-006,-4.280973e-001
0.000000e+000,3.774637e+002,1.281403e-006,-3.767667e-001
0.000000e+000,3.680878e+002,1.328172e-006,-3.693986e-001
0.000000e+000,3.618326e+002,1.395305e-006,-3.882938e-001
0.000000e+000,3.525089e+002,1.371717e-006,-3.761950e-001
0.000000e+000,3.451797e+002,1.475140e-006,-3.613034e-001
0.000000e+000,3.373943e+002,2.251486e-006,-2.833563e-001
0.000000e+000,3.295438e+002,2.256588e-006,-2.774512e-001
0.000000e+000,3.216638e+002,2.248874e-006,-2.734278e-001
0.000000e+000,3.135852e+002,2.287781e-006,-2.720926e-001
0.000000e+000,3.057583e+002,2.301456e-006,-2.818897e-001
0.000000e+000,3.012508e+002,2.263932e-006,-2.704147e-001
0.000000e+000,3.093311e+002,2.283598e-006,-2.741003e-001
0.000000e+000,3.172359e+002,2.266140e-006,-2.775710e-001
0.000000e+000,3.252560e+002,2.247958e-006,-2.837467e-001
0.000000e+000,3.333002e+002,2.217916e-006,-2.859766e-001
0.000000e+000,3.415070e+002,2.190565e-006,-2.905060e-001
0.000000e+000,3.492153e+002,2.154116e-006,-3.058971e-001
0.000000e+000,3.572632e+002,2.116761e-006,-3.116620e-001
0.000000e+000,3.652638e+002,1.674909e-006,-3.365508e-001
0.000000e+000,3.732433e+002,1.339097e-006,-3.901310e-001
0.000000e+000,3.815694e+002,1.329420e-006,-3.965142e-001
0.000000e+000,3.893006e+002,1.297213e-006,-3.619687e-001
0.000000e+000,3.972571e+002,1.291979e-006,-4.029139e-001
0.000000e+000,3.999905e+002,1.350530e-006,-3.739156e-001