File: spin_crossover/dane/Trt_TEOS — kopia/Small TEOS/FeTrz_Trt_small_FC_FH.rso.csv
Field (Oe),Temperature (K),Long Moment (emu),Long Offset (cm)
1.000000e+003,3.000016e+002,3.688359e-005,-5.736395e-003
1.000000e+003,3.011255e+002,3.685967e-005,-1.003214e-002
1.000000e+003,3.021215e+002,3.683095e-005,-6.035130e-003
1.000000e+003,3.031356e+002,3.683159e-005,-7.292954e-003
1.000000e+003,3.041424e+002,3.674224e-005,-7.236742e-003
1.000000e+003,3.051454e+002,3.674234e-005,-8.022808e-003
1.000000e+003,3.061444e+002,3.670334e-005,-8.726929e-003
1.000000e+003,3.071244e+002,3.669568e-005,-8.041345e-003
1.000000e+003,3.081336e+002,3.667887e-005,-9.571889e-003
1.000000e+003,3.091348e+002,3.666195e-005,-9.141077e-003
1.000000e+003,3.101127e+002,3.663152e-005,-1.023212e-002
1.000000e+003,3.111354e+002,3.662882e-005,-1.017381e-002
1.000000e+003,3.120999e+002,3.662329e-005,-1.077427e-002
1.000000e+003,3.131562e+002,3.656712e-005,-1.234832e-002
1.000000e+003,3.141184e+002,3.655172e-005,-1.179199e-002
1.000000e+003,3.151302e+002,3.655069e-005,-1.224647e-002
1.000000e+003,3.161135e+002,3.658251e-005,-1.229710e-002
1.000000e+003,3.171112e+002,3.653868e-005,-1.253292e-002
1.000000e+003,3.181439e+002,3.653846e-005,-1.416206e-002
1.000000e+003,3.191230e+002,3.656250e-005,-1.307714e-002
1.000000e+003,3.201331e+002,3.652453e-005,-1.445521e-002
1.000000e+003,3.211377e+002,3.654339e-005,-1.401871e-002
1.000000e+003,3.221448e+002,3.652109e-005,-1.387267e-002
1.000000e+003,3.231048e+002,3.654455e-005,-1.578141e-002
1.000000e+003,3.241252e+002,3.653290e-005,-1.565216e-002
1.000000e+003,3.251609e+002,3.654386e-005,-1.662327e-002
1.000000e+003,3.260978e+002,3.656725e-005,-1.576661e-002
1.000000e+003,3.271043e+002,3.653347e-005,-1.815216e-002
1.000000e+003,3.281432e+002,3.662554e-005,-1.814409e-002
1.000000e+003,3.291180e+002,3.657678e-005,-1.811257e-002
1.000000e+003,3.301466e+002,3.661075e-005,-1.886239e-002
1.000000e+003,3.311166e+002,3.660721e-005,-1.921835e-002
1.000000e+003,3.321321e+002,3.660806e-005,-2.014382e-002
1.000000e+003,3.331300e+002,3.665629e-005,-2.123803e-002
1.000000e+003,3.341008e+002,3.667528e-005,-2.038283e-002
1.000000e+003,3.351472e+002,3.670100e-005,-2.101317e-002
1.000000e+003,3.361100e+002,3.670113e-005,-2.312957e-002
1.000000e+003,3.371016e+002,3.669812e-005,-2.494716e-002
1.000000e+003,3.381245e+002,3.679062e-005,-2.386761e-002
1.000000e+003,3.391126e+002,3.683154e-005,-2.182845e-002
1.000000e+003,3.401438e+002,3.682920e-005,-2.272879e-002
1.000000e+003,3.411165e+002,3.692165e-005,-2.424925e-002
1.000000e+003,3.421068e+002,3.687035e-005,-2.461152e-002
1.000000e+003,3.431409e+002,3.691852e-005,-2.540321e-002
1.000000e+003,3.441080e+002,3.698133e-005,-2.521392e-002
1.000000e+003,3.451000e+002,3.701498e-005,-2.588337e-002
1.000000e+003,3.461389e+002,3.700824e-005,-2.567482e-002
1.000000e+003,3.471119e+002,3.713637e-005,-2.716042e-002
1.000000e+003,3.481272e+002,3.714878e-005,-2.747000e-002
1.000000e+003,3.491242e+002,3.718493e-005,-2.967748e-002
1.000000e+003,3.501174e+002,3.723476e-005,-2.939494e-002
1.000000e+003,3.511340e+002,3.731177e-005,-3.061555e-002
1.000000e+003,3.521094e+002,3.733396e-005,-2.972546e-002
1.000000e+003,3.531181e+002,3.740549e-005,-3.178373e-002
1.000000e+003,3.541430e+002,3.750359e-005,-3.054025e-002
1.000000e+003,3.551286e+002,3.751271e-005,-3.141048e-002
1.000000e+003,3.561097e+002,3.764419e-005,-3.152624e-002
1.000000e+003,3.571324e+002,3.766565e-005,-3.336562e-002
1.000000e+003,3.581278e+002,3.777973e-005,-3.463773e-002
1.000000e+003,3.591471e+002,3.786828e-005,-3.409728e-002
1.000000e+003,3.601204e+002,3.786432e-005,-3.555874e-002
1.000000e+003,3.611649e+002,3.799105e-005,-3.427660e-002
1.000000e+003,3.621233e+002,3.806023e-005,-3.531815e-002
1.000000e+003,3.631322e+002,3.815762e-005,-3.670055e-002
1.000000e+003,3.641149e+002,3.822237e-005,-3.614996e-002
1.000000e+003,3.651140e+002,3.833567e-005,-3.766498e-002
1.000000e+003,3.661404e+002,3.841478e-005,-3.711299e-002
1.000000e+003,3.671131e+002,3.856520e-005,-3.847026e-002
1.000000e+003,3.681049e+002,3.869717e-005,-4.053887e-002
1.000000e+003,3.691215e+002,3.882866e-005,-3.950968e-002
1.000000e+003,3.701082e+002,3.897326e-005,-3.973104e-002
1.000000e+003,3.711031e+002,3.911024e-005,-4.227463e-002
1.000000e+003,3.721455e+002,3.930025e-005,-4.240946e-002
1.000000e+003,3.731210e+002,3.951364e-005,-4.340427e-002
1.000000e+003,3.741500e+002,3.965693e-005,-4.528804e-002
1.000000e+003,3.751279e+002,4.001263e-005,-4.513711e-002
1.000000e+003,3.761399e+002,4.037016e-005,-4.614089e-002
1.000000e+003,3.771546e+002,4.083265e-005,-4.692930e-002
1.000000e+003,3.781838e+002,4.141692e-005,-5.100540e-002
1.000000e+003,3.791171e+002,4.205154e-005,-5.167999e-002
1.000000e+003,3.801049e+002,4.306439e-005,-5.308192e-002
1.000000e+003,3.811039e+002,4.436688e-005,-5.811977e-002
1.000000e+003,3.821292e+002,4.617029e-005,-6.248483e-002
1.000000e+003,3.831125e+002,4.872418e-005,-6.751803e-002
1.000000e+003,3.841341e+002,5.318556e-005,-7.628375e-002
1.000000e+003,3.851163e+002,6.056462e-005,-8.675307e-002
1.000000e+003,3.861188e+002,7.613190e-005,-9.983988e-002
1.000000e+003,3.872452e+002,9.693162e-005,-1.045562e-001
1.000000e+003,3.881464e+002,1.055120e-004,-1.028150e-001
1.000000e+003,3.891194e+002,1.063069e-004,-1.030467e-001
1.000000e+003,3.901438e+002,1.065712e-004,-1.034693e-001
1.000000e+003,3.911241e+002,1.067385e-004,-1.036840e-001
1.000000e+003,3.921346e+002,1.068361e-004,-1.043637e-001
1.000000e+003,3.931035e+002,1.069639e-004,-1.043638e-001
1.000000e+003,3.941120e+002,1.069730e-004,-1.042520e-001
1.000000e+003,3.951323e+002,1.070009e-004,-1.048319e-001
1.000000e+003,3.961066e+002,1.069733e-004,-1.042941e-001
1.000000e+003,3.971011e+002,1.069842e-004,-1.047072e-001
1.000000e+003,3.981674e+002,1.069351e-004,-1.050908e-001
1.000000e+003,3.991453e+002,1.074463e-004,-1.092089e-001
1.000000e+003,3.999816e+002,1.071498e-004,-1.038061e-001
1.000000e+003,4.000140e+002,1.072514e-004,-1.027415e-001
1.000000e+003,3.988457e+002,1.074287e-004,-1.009338e-001
1.000000e+003,3.978307e+002,1.076273e-004,-1.007162e-001
1.000000e+003,3.967723e+002,1.078237e-004,-9.989245e-002
1.000000e+003,3.956936e+002,1.080338e-004,-9.918167e-002
1.000000e+003,3.947052e+002,1.082802e-004,-9.830941e-002
1.000000e+003,3.937281e+002,1.084164e-004,-9.739386e-002
1.000000e+003,3.927310e+002,1.087227e-004,-9.710819e-002
1.000000e+003,3.918076e+002,1.088966e-004,-9.632851e-002
1.000000e+003,3.908051e+002,1.090945e-004,-9.588714e-002
1.000000e+003,3.899187e+002,1.092139e-004,-9.512010e-002
1.000000e+003,3.888986e+002,1.093960e-004,-9.573802e-002
1.000000e+003,3.878415e+002,1.096035e-004,-9.528877e-002
1.000000e+003,3.868356e+002,1.098292e-004,-9.459913e-002
1.000000e+003,3.857630e+002,1.101018e-004,-9.413660e-002
1.000000e+003,3.848313e+002,1.102516e-004,-9.420761e-002
1.000000e+003,3.838416e+002,1.104718e-004,-9.292220e-002
1.000000e+003,3.828780e+002,1.106055e-004,-9.261945e-002
1.000000e+003,3.818959e+002,1.108414e-004,-9.235709e-002
1.000000e+003,3.808719e+002,1.110172e-004,-9.230405e-002
1.000000e+003,3.799063e+002,1.111988e-004,-9.175527e-002
1.000000e+003,3.788818e+002,1.114107e-004,-9.083574e-002
1.000000e+003,3.778603e+002,1.116001e-004,-9.035505e-002
1.000000e+003,3.768616e+002,1.118067e-004,-9.016432e-002
1.000000e+003,3.759057e+002,1.119703e-004,-8.945958e-002
1.000000e+003,3.748723e+002,1.121443e-004,-8.935207e-002
1.000000e+003,3.738674e+002,1.123247e-004,-8.916104e-002
1.000000e+003,3.728571e+002,1.125383e-004,-8.870465e-002
1.000000e+003,3.718774e+002,1.126861e-004,-8.836269e-002
1.000000e+003,3.708448e+002,1.128367e-004,-8.777213e-002
1.000000e+003,3.698762e+002,1.131249e-004,-8.791548e-002
1.000000e+003,3.688771e+002,1.132027e-004,-8.688574e-002
1.000000e+003,3.678483e+002,1.133083e-004,-8.679701e-002
1.000000e+003,3.668796e+002,1.134077e-004,-8.614602e-002
1.000000e+003,3.658947e+002,1.135649e-004,-8.603510e-002
1.000000e+003,3.648643e+002,1.136786e-004,-8.579786e-002
1.000000e+003,3.638827e+002,1.137954e-004,-8.527090e-002
1.000000e+003,3.628801e+002,1.139386e-004,-8.467052e-002
1.000000e+003,3.618674e+002,1.139754e-004,-8.407063e-002
1.000000e+003,3.609078e+002,1.140474e-004,-8.400267e-002
1.000000e+003,3.598909e+002,1.141008e-004,-8.327647e-002
1.000000e+003,3.588878e+002,1.141579e-004,-8.336913e-002
1.000000e+003,3.578674e+002,1.140890e-004,-8.263527e-002
1.000000e+003,3.568813e+002,1.140252e-004,-8.264864e-002
1.000000e+003,3.558651e+002,1.138874e-004,-8.195354e-002
1.000000e+003,3.548779e+002,1.137862e-004,-8.160633e-002
1.000000e+003,3.538762e+002,1.135538e-004,-8.092062e-002
1.000000e+003,3.528629e+002,1.132312e-004,-8.041538e-002
1.000000e+003,3.518855e+002,1.126277e-004,-8.023635e-002
1.000000e+003,3.508940e+002,1.088227e-004,-7.887973e-002
1.000000e+003,3.498544e+002,9.068433e-005,-7.380250e-002
1.000000e+003,3.488676e+002,6.597912e-005,-5.832124e-002
1.000000e+003,3.478721e+002,4.389016e-005,-3.278903e-002
1.000000e+003,3.468753e+002,3.925793e-005,-2.067866e-002
1.000000e+003,3.458726e+002,3.900605e-005,-1.936593e-002
1.000000e+003,3.449045e+002,3.884845e-005,-1.864731e-002
1.000000e+003,3.438710e+002,3.872921e-005,-1.766902e-002
1.000000e+003,3.428817e+002,3.862366e-005,-1.683857e-002
1.000000e+003,3.418492e+002,3.854020e-005,-1.532571e-002
1.000000e+003,3.408931e+002,3.849369e-005,-1.600018e-002
1.000000e+003,3.398825e+002,3.843724e-005,-1.413361e-002
1.000000e+003,3.388690e+002,3.838287e-005,-1.483901e-002
1.000000e+003,3.378847e+002,3.833372e-005,-1.442626e-002
1.000000e+003,3.368679e+002,3.826147e-005,-1.262599e-002
1.000000e+003,3.358912e+002,3.823604e-005,-1.315246e-002
1.000000e+003,3.348894e+002,3.817989e-005,-1.246255e-002
1.000000e+003,3.338537e+002,3.818758e-005,-1.299721e-002
1.000000e+003,3.328999e+002,3.815346e-005,-1.168397e-002
1.000000e+003,3.318859e+002,3.814795e-005,-1.104168e-002
1.000000e+003,3.308719e+002,3.809216e-005,-1.189112e-002
1.000000e+003,3.298905e+002,3.810178e-005,-1.106454e-002
1.000000e+003,3.288721e+002,3.806736e-005,-9.609655e-003
1.000000e+003,3.278818e+002,3.806742e-005,-8.788217e-003
1.000000e+003,3.268872e+002,3.802683e-005,-9.598294e-003
1.000000e+003,3.258609e+002,3.802623e-005,-9.448554e-003
1.000000e+003,3.248730e+002,3.799112e-005,-8.886019e-003
1.000000e+003,3.238601e+002,3.802692e-005,-7.725316e-003
1.000000e+003,3.228622e+002,3.801263e-005,-7.784365e-003
1.000000e+003,3.218893e+002,3.801711e-005,-6.540250e-003
1.000000e+003,3.208593e+002,3.802739e-005,-7.351334e-003
1.000000e+003,3.198891e+002,3.803477e-005,-7.566528e-003
1.000000e+003,3.188787e+002,3.806595e-005,-7.221922e-003
1.000000e+003,3.178730e+002,3.804167e-005,-6.291032e-003
1.000000e+003,3.168900e+002,3.803892e-005,-5.404169e-003
1.000000e+003,3.158720e+002,3.807777e-005,-4.062930e-003
1.000000e+003,3.148747e+002,3.805571e-005,-5.006805e-003
1.000000e+003,3.138548e+002,3.802963e-005,-4.252913e-003
1.000000e+003,3.128748e+002,3.807455e-005,-4.247611e-003
1.000000e+003,3.118803e+002,3.812489e-005,-4.224051e-003
1.000000e+003,3.108905e+002,3.811662e-005,-4.315546e-003
1.000000e+003,3.099018e+002,3.814348e-005,-3.795975e-003
1.000000e+003,3.088538e+002,3.813107e-005,-4.505755e-003
1.000000e+003,3.078676e+002,3.815252e-005,-1.965350e-003
1.000000e+003,3.068751e+002,3.824092e-005,-1.817932e-003
1.000000e+003,3.058746e+002,3.825099e-005,-3.905313e-003
1.000000e+003,3.048701e+002,3.821083e-005,-1.118082e-003
1.000000e+003,3.038654e+002,3.826609e-005,-1.498732e-003
1.000000e+003,3.028805e+002,3.831043e-005,-6.682714e-004
1.000000e+003,3.018736e+002,3.832737e-005,-2.032922e-003
1.000000e+003,3.008419e+002,3.834630e-005,-1.245227e-003
1.000000e+003,2.999999e+002,3.836390e-005,4.536582e-004
1.000000e+003,3.000123e+002,3.833627e-005,-1.454274e-003
1.000000e+003,3.011219e+002,3.829662e-005,-1.943814e-003
1.000000e+003,3.021485e+002,3.823652e-005,-3.081249e-003
1.000000e+003,3.031682e+002,3.820537e-005,-3.429475e-003
1.000000e+003,3.041498e+002,3.817029e-005,-2.774377e-003
1.000000e+003,3.051197e+002,3.813952e-005,-4.414931e-003
1.000000e+003,3.061463e+002,3.808318e-005,-4.737385e-003
1.000000e+003,3.071319e+002,3.807553e-005,-6.516751e-003
1.000000e+003,3.081580e+002,3.804482e-005,-5.531400e-003
1.000000e+003,3.091348e+002,3.801176e-005,-6.691892e-003
1.000000e+003,3.101355e+002,3.795750e-005,-7.210106e-003
1.000000e+003,3.111335e+002,3.790183e-005,-7.703295e-003
1.000000e+003,3.121076e+002,3.791240e-005,-7.898282e-003
1.000000e+003,3.131523e+002,3.794262e-005,-7.822803e-003
1.000000e+003,3.141223e+002,3.783725e-005,-9.243790e-003
1.000000e+003,3.151322e+002,3.784645e-005,-9.006394e-003
1.000000e+003,3.161096e+002,3.783697e-005,-9.605434e-003
1.000000e+003,3.171013e+002,3.783625e-005,-9.700093e-003
1.000000e+003,3.181540e+002,3.779911e-005,-1.045182e-002
1.000000e+003,3.191109e+002,3.780935e-005,-1.129575e-002
1.000000e+003,3.201229e+002,3.779043e-005,-1.168193e-002
1.000000e+003,3.211233e+002,3.776718e-005,-1.171086e-002
1.000000e+003,3.221428e+002,3.774981e-005,-1.271232e-002
1.000000e+003,3.231380e+002,3.772281e-005,-1.306135e-002
1.000000e+003,3.241169e+002,3.775878e-005,-1.405812e-002
1.000000e+003,3.251357e+002,3.771597e-005,-1.360851e-002
1.000000e+003,3.261232e+002,3.774392e-005,-1.424508e-002
1.000000e+003,3.271192e+002,3.775533e-005,-1.640522e-002
1.000000e+003,3.281454e+002,3.771024e-005,-1.524335e-002
1.000000e+003,3.291288e+002,3.769302e-005,-1.590805e-002
1.000000e+003,3.301206e+002,3.772217e-005,-1.638361e-002
1.000000e+003,3.311362e+002,3.775026e-005,-1.598238e-002
1.000000e+003,3.321123e+002,3.772140e-005,-1.662594e-002
1.000000e+003,3.331544e+002,3.769950e-005,-1.730113e-002
1.000000e+003,3.341187e+002,3.774376e-005,-1.805667e-002
1.000000e+003,3.351292e+002,3.774399e-005,-1.843289e-002
1.000000e+003,3.361393e+002,3.775852e-005,-1.955257e-002
1.000000e+003,3.371198e+002,3.779675e-005,-2.142724e-002
1.000000e+003,3.381085e+002,3.780544e-005,-2.084205e-002
1.000000e+003,3.391517e+002,3.784478e-005,-2.131022e-002
1.000000e+003,3.401045e+002,3.783352e-005,-2.188471e-002
1.000000e+003,3.411258e+002,3.788796e-005,-2.219199e-002
1.000000e+003,3.421325e+002,3.790954e-005,-2.304570e-002
1.000000e+003,3.431315e+002,3.794226e-005,-2.236086e-002
1.000000e+003,3.441460e+002,3.795268e-005,-2.429909e-002
1.000000e+003,3.451358e+002,3.803353e-005,-2.505010e-002
1.000000e+003,3.461076e+002,3.803272e-005,-2.475450e-002
1.000000e+003,3.471360e+002,3.812332e-005,-2.507552e-002
1.000000e+003,3.481271e+002,3.810168e-005,-2.648376e-002
1.000000e+003,3.491291e+002,3.820383e-005,-2.617780e-002
1.000000e+003,3.501101e+002,3.818781e-005,-2.819905e-002
1.000000e+003,3.511464e+002,3.831950e-005,-2.857902e-002
1.000000e+003,3.521368e+002,3.837547e-005,-2.895631e-002
1.000000e+003,3.531006e+002,3.840897e-005,-2.911904e-002
1.000000e+003,3.541204e+002,3.851145e-005,-3.051246e-002
1.000000e+003,3.551311e+002,3.858583e-005,-3.023252e-002
1.000000e+003,3.561147e+002,3.865887e-005,-3.113539e-002
1.000000e+003,3.571222e+002,3.876010e-005,-3.083947e-002
1.000000e+003,3.581458e+002,3.885138e-005,-3.188657e-002
1.000000e+003,3.591290e+002,3.894743e-005,-3.260772e-002
1.000000e+003,3.601256e+002,3.908997e-005,-3.373574e-002
1.000000e+003,3.611413e+002,3.920263e-005,-3.477876e-002
1.000000e+003,3.621259e+002,3.934437e-005,-3.485409e-002
1.000000e+003,3.631242e+002,3.949273e-005,-3.516172e-002
1.000000e+003,3.641255e+002,3.971007e-005,-3.648608e-002
1.000000e+003,3.651220e+002,3.997628e-005,-3.606878e-002
1.000000e+003,3.661323e+002,4.036512e-005,-4.371034e-002
1.000000e+003,3.671105e+002,4.061045e-005,-3.981607e-002
1.000000e+003,3.681186e+002,4.122633e-005,-4.208643e-002
1.000000e+003,3.691463e+002,4.236779e-005,-4.414406e-002
1.000000e+003,3.701192e+002,4.470461e-005,-5.541955e-002
1.000000e+003,3.711448e+002,4.892272e-005,-6.520799e-002
1.000000e+003,3.721428e+002,5.707783e-005,-7.588471e-002
1.000000e+003,3.731238e+002,7.423411e-005,-9.125052e-002
1.000000e+003,3.741161e+002,9.648429e-005,-9.746608e-002
1.000000e+003,3.751279e+002,1.098041e-004,-9.654403e-002
1.000000e+003,3.761170e+002,1.107871e-004,-9.661955e-002
1.000000e+003,3.771201e+002,1.107392e-004,-9.642923e-002
1.000000e+003,3.781230e+002,1.105994e-004,-9.672844e-002
1.000000e+003,3.791084e+002,1.105512e-004,-9.748305e-002
1.000000e+003,3.801487e+002,1.104251e-004,-9.745605e-002
1.000000e+003,3.811450e+002,1.103317e-004,-9.800705e-002
1.000000e+003,3.821084e+002,1.102410e-004,-9.808369e-002
1.000000e+003,3.831333e+002,1.100438e-004,-9.813152e-002
1.000000e+003,3.840952e+002,1.099491e-004,-9.767132e-002
1.000000e+003,3.851373e+002,1.097956e-004,-9.866688e-002
1.000000e+003,3.861128e+002,1.096105e-004,-9.900810e-002
1.000000e+003,3.871237e+002,1.094449e-004,-9.894899e-002
1.000000e+003,3.881555e+002,1.092763e-004,-9.922710e-002
1.000000e+003,3.891439e+002,1.091363e-004,-9.957450e-002
1.000000e+003,3.901161e+002,1.089607e-004,-9.975518e-002
1.000000e+003,3.911241e+002,1.088263e-004,-9.967029e-002
1.000000e+003,3.921346e+002,1.086158e-004,-9.972987e-002
1.000000e+003,3.931129e+002,1.084466e-004,-1.004194e-001
1.000000e+003,3.941057e+002,1.082295e-004,-1.001788e-001
1.000000e+003,3.951228e+002,1.080651e-004,-1.000156e-001
1.000000e+003,3.960971e+002,1.079103e-004,-1.005549e-001
1.000000e+003,3.971171e+002,1.076829e-004,-1.004788e-001
1.000000e+003,3.981449e+002,1.074916e-004,-1.004260e-001
1.000000e+003,3.991581e+002,1.073908e-004,-1.006419e-001
1.000000e+003,3.999849e+002,1.073005e-004,-9.889288e-002
1.000000e+003,4.000043e+002,1.073806e-004,-9.801543e-002
1.000000e+003,3.988585e+002,1.075400e-004,-9.725716e-002
1.000000e+003,3.978339e+002,1.077586e-004,-9.645565e-002
1.000000e+003,3.967851e+002,1.079162e-004,-9.549513e-002
1.000000e+003,3.957349e+002,1.081757e-004,-9.463422e-002
1.000000e+003,3.947273e+002,1.084190e-004,-9.417430e-002
1.000000e+003,3.937502e+002,1.085488e-004,-9.379388e-002
1.000000e+003,3.927592e+002,1.088444e-004,-9.281884e-002
1.000000e+003,3.917827e+002,1.090320e-004,-9.251326e-002
1.000000e+003,3.908515e+002,1.093120e-004,-9.198780e-002
1.000000e+003,3.899219e+002,1.094412e-004,-9.182044e-002
1.000000e+003,3.889171e+002,1.095471e-004,-9.209676e-002
1.000000e+003,3.878598e+002,1.097632e-004,-9.152850e-002
1.000000e+003,3.868054e+002,1.100242e-004,-9.137836e-002
1.000000e+003,3.858202e+002,1.102303e-004,-9.082367e-002
1.000000e+003,3.848403e+002,1.104369e-004,-9.003215e-002
1.000000e+003,3.838565e+002,1.106449e-004,-8.967014e-002
1.000000e+003,3.828958e+002,1.108151e-004,-8.917867e-002
1.000000e+003,3.819047e+002,1.110502e-004,-8.910383e-002
1.000000e+003,3.808984e+002,1.112332e-004,-8.894663e-002
1.000000e+003,3.798538e+002,1.115351e-004,-8.846211e-002
1.000000e+003,3.788760e+002,1.116577e-004,-8.764395e-002
1.000000e+003,3.778805e+002,1.118540e-004,-8.758685e-002
1.000000e+003,3.768617e+002,1.120675e-004,-8.710419e-002
1.000000e+003,3.758971e+002,1.122589e-004,-8.672325e-002
1.000000e+003,3.748893e+002,1.124487e-004,-8.621584e-002
1.000000e+003,3.738788e+002,1.126141e-004,-8.571094e-002
1.000000e+003,3.728851e+002,1.128124e-004,-8.523782e-002
1.000000e+003,3.718885e+002,1.129913e-004,-8.517466e-002
1.000000e+003,3.708921e+002,1.132259e-004,-8.485991e-002
1.000000e+003,3.698817e+002,1.133744e-004,-8.478612e-002
1.000000e+003,3.688908e+002,1.135607e-004,-8.463085e-002
1.000000e+003,3.678701e+002,1.137691e-004,-8.399699e-002
1.000000e+003,3.668497e+002,1.139287e-004,-8.370613e-002
1.000000e+003,3.658920e+002,1.140480e-004,-8.305417e-002
1.000000e+003,3.648831e+002,1.142098e-004,-8.313422e-002
1.000000e+003,3.638667e+002,1.143845e-004,-8.236586e-002
1.000000e+003,3.628641e+002,1.144725e-004,-8.153077e-002
1.000000e+003,3.618700e+002,1.146176e-004,-8.164547e-002
1.000000e+003,3.608658e+002,1.147665e-004,-8.121797e-002
1.000000e+003,3.598857e+002,1.148593e-004,-8.114674e-002
1.000000e+003,3.588827e+002,1.149640e-004,-8.106607e-002
1.000000e+003,3.578829e+002,1.149914e-004,-8.087602e-002
1.000000e+003,3.568915e+002,1.150266e-004,-8.024935e-002
1.000000e+003,3.558423e+002,1.150573e-004,-7.999399e-002
1.000000e+003,3.548880e+002,1.150139e-004,-7.941018e-002
1.000000e+003,3.538987e+002,1.149464e-004,-7.941037e-002
1.000000e+003,3.528379e+002,1.148483e-004,-7.877857e-002
1.000000e+003,3.518756e+002,1.146410e-004,-7.810391e-002
1.000000e+003,3.508694e+002,1.140424e-004,-7.781347e-002
1.000000e+003,3.498766e+002,1.017431e-004,-7.656191e-002
1.000000e+003,3.488969e+002,6.478080e-005,-6.434673e-002
1.000000e+003,3.478527e+002,4.180417e-005,-3.590800e-002
1.000000e+003,3.468753e+002,3.982852e-005,-2.401417e-002
1.000000e+003,3.458870e+002,3.916102e-005,-2.030937e-002
1.000000e+003,3.448687e+002,3.887745e-005,-1.792131e-002
1.000000e+003,3.438639e+002,3.869682e-005,-1.666089e-002
1.000000e+003,3.428723e+002,3.859655e-005,-1.610879e-002
1.000000e+003,3.418914e+002,3.851802e-005,-1.494987e-002
1.000000e+003,3.408629e+002,3.842917e-005,-1.512691e-002
1.000000e+003,3.398778e+002,3.834197e-005,-1.386607e-002
1.000000e+003,3.388805e+002,3.829762e-005,-1.172425e-002
1.000000e+003,3.378778e+002,3.823041e-005,-1.261598e-002
1.000000e+003,3.368610e+002,3.821174e-005,-1.243183e-002
1.000000e+003,3.358456e+002,3.814731e-005,-1.201748e-002
1.000000e+003,3.348871e+002,3.813166e-005,-1.160627e-002
1.000000e+003,3.338804e+002,3.809395e-005,-1.160501e-002
1.000000e+003,3.328622e+002,3.805420e-005,-1.038533e-002
1.000000e+003,3.318859e+002,3.805755e-005,-1.065214e-002
1.000000e+003,3.308741e+002,3.802014e-005,-9.890087e-003
1.000000e+003,3.298644e+002,3.800027e-005,-8.355252e-003
1.000000e+003,3.288850e+002,3.800463e-005,-9.537295e-003
1.000000e+003,3.278711e+002,3.795588e-005,-8.240268e-003
1.000000e+003,3.268829e+002,3.797601e-005,-8.425088e-003
1.000000e+003,3.258609e+002,3.795545e-005,-7.970061e-003
1.000000e+003,3.248751e+002,3.794899e-005,-7.777308e-003
1.000000e+003,3.238893e+002,3.795006e-005,-6.896357e-003
1.000000e+003,3.228663e+002,3.793346e-005,-7.071374e-003
1.000000e+003,3.218893e+002,3.794808e-005,-6.337959e-003
1.000000e+003,3.208695e+002,3.793903e-005,-7.101931e-003
1.000000e+003,3.198810e+002,3.793517e-005,-5.566247e-003
1.000000e+003,3.188969e+002,3.794896e-005,-4.307976e-003
1.000000e+003,3.178770e+002,3.793838e-005,-4.924806e-003
1.000000e+003,3.168900e+002,3.797986e-005,-4.160648e-003
1.000000e+003,3.158759e+002,3.803489e-005,-4.399395e-003
1.000000e+003,3.148845e+002,3.798740e-005,-2.893481e-003
1.000000e+003,3.138489e+002,3.801179e-005,-4.014844e-003
1.000000e+003,3.128904e+002,3.805198e-005,-2.551094e-003
1.000000e+003,3.118803e+002,3.805888e-005,-2.684812e-003
1.000000e+003,3.108810e+002,3.804864e-005,-2.662238e-003
1.000000e+003,3.098790e+002,3.808351e-005,-2.177322e-003
1.000000e+003,3.088896e+002,3.809545e-005,-2.519096e-003
1.000000e+003,3.078601e+002,3.812038e-005,-1.884223e-003
1.000000e+003,3.068583e+002,3.814523e-005,-1.426643e-003
1.000000e+003,3.058561e+002,3.819258e-005,-1.754292e-003
1.000000e+003,3.048958e+002,3.814770e-005,-2.371999e-004
1.000000e+003,3.038618e+002,3.818134e-005,-9.315269e-005
1.000000e+003,3.028751e+002,3.823042e-005,-4.626290e-004
1.000000e+003,3.018862e+002,3.827060e-005,-1.917683e-004
1.000000e+003,3.008419e+002,3.830343e-005,8.585300e-004
1.000000e+003,3.000105e+002,3.831282e-005,4.919771e-004