File: spin_crossover/dane/Trt_TEOS — kopia/Small TEOS/FeTrz_Trt_small_XTvT_MCE.rso.csv
Field (Oe),Temperature (K),Long Moment (emu),Long Offset (cm)
7.000000e+004,3.999970e+002,1.345480e-002,-8.862163e-002
7.000000e+004,3.910747e+002,1.371995e-002,-8.195877e-002
7.000000e+004,3.835622e+002,1.392621e-002,-7.721330e-002
7.000000e+004,3.753285e+002,1.408262e-002,-7.506016e-002
7.000000e+004,3.662803e+002,1.435257e-002,-6.985657e-002
7.000000e+004,3.597109e+002,1.466682e-002,-7.093856e-002
7.000000e+004,3.504407e+002,1.431517e-002,-6.674197e-002
7.000000e+004,3.433826e+002,3.966706e-003,-1.993469e-002
7.000000e+004,3.351784e+002,3.876788e-003,-1.697911e-002
7.000000e+004,3.274991e+002,3.858093e-003,-1.223860e-002
7.000000e+004,3.195105e+002,3.831160e-003,-1.048922e-002
7.000000e+004,3.114954e+002,3.841910e-003,-6.082801e-003
7.000000e+004,3.037382e+002,3.846752e-003,-4.481658e-003
7.000000e+004,3.033424e+002,3.836446e-003,-5.827628e-003
7.000000e+004,3.112671e+002,3.812521e-003,-1.011757e-002
7.000000e+004,3.192350e+002,3.799402e-003,-1.451257e-002
7.000000e+004,3.272495e+002,3.799652e-003,-1.875752e-002
7.000000e+004,3.352296e+002,3.818959e-003,-2.347105e-002
7.000000e+004,3.432268e+002,3.853342e-003,-2.793166e-002
7.000000e+004,3.512409e+002,3.907612e-003,-3.290179e-002
7.000000e+004,3.592871e+002,4.013093e-003,-3.815744e-002
7.000000e+004,3.672563e+002,4.246341e-003,-4.445489e-002
7.000000e+004,3.752087e+002,1.080054e-002,-6.501445e-002
7.000000e+004,3.832201e+002,1.388829e-002,-8.750498e-002
7.000000e+004,3.913071e+002,1.371399e-002,-8.966361e-002
7.000000e+004,3.992671e+002,1.351352e-002,-9.139051e-002
6.500000e+004,3.935394e+002,1.273282e-002,-8.246063e-002
6.500000e+004,3.855497e+002,1.294447e-002,-7.743470e-002
6.500000e+004,3.775904e+002,1.312879e-002,-7.594818e-002
6.500000e+004,3.684706e+002,1.344219e-002,-7.103007e-002
6.500000e+004,3.618353e+002,1.363390e-002,-6.810801e-002
6.500000e+004,3.525562e+002,1.380446e-002,-6.697231e-002
6.500000e+004,3.449604e+002,4.106771e-003,-2.885173e-002
6.500000e+004,3.373966e+002,3.600830e-003,-1.832015e-002
6.500000e+004,3.289973e+002,3.575900e-003,-1.280139e-002
6.500000e+004,3.216329e+002,3.545503e-003,-1.153496e-002
6.500000e+004,3.134706e+002,3.548840e-003,-7.073806e-003
6.500000e+004,3.059225e+002,3.549555e-003,-5.117719e-003
6.500000e+004,3.012829e+002,3.551691e-003,-4.614506e-003
6.500000e+004,3.093330e+002,3.528730e-003,-9.445881e-003
6.500000e+004,3.172398e+002,3.515815e-003,-1.363872e-002
6.500000e+004,3.252812e+002,3.515526e-003,-1.832553e-002
6.500000e+004,3.332581e+002,3.532297e-003,-2.237971e-002
6.500000e+004,3.414720e+002,3.563070e-003,-2.707296e-002
6.500000e+004,3.493058e+002,3.609456e-003,-3.181819e-002
6.500000e+004,3.573120e+002,3.697107e-003,-3.713766e-002
6.500000e+004,3.652073e+002,3.887420e-003,-4.323389e-002
6.500000e+004,3.732799e+002,9.612684e-003,-6.394015e-002
6.500000e+004,3.814634e+002,1.303542e-002,-8.699909e-002
6.500000e+004,3.892607e+002,1.284353e-002,-8.948752e-002
6.500000e+004,3.972252e+002,1.264668e-002,-9.118722e-002
6.000000e+004,3.955282e+002,1.173004e-002,-8.385202e-002
6.000000e+004,3.875982e+002,1.193193e-002,-7.882708e-002
6.000000e+004,3.796389e+002,1.210870e-002,-7.739848e-002
6.000000e+004,3.704863e+002,1.240381e-002,-7.244905e-002
6.000000e+004,3.634613e+002,1.259943e-002,-6.867597e-002
6.000000e+004,3.550809e+002,1.280172e-002,-6.822709e-002
6.000000e+004,3.467195e+002,7.846406e-003,-6.400906e-002
6.000000e+004,3.395217e+002,3.332264e-003,-1.963146e-002
6.000000e+004,3.309418e+002,3.299666e-003,-1.440243e-002
6.000000e+004,3.239397e+002,3.280556e-003,-1.081064e-002
6.000000e+004,3.155395e+002,3.267803e-003,-8.243121e-003
6.000000e+004,3.078205e+002,3.274499e-003,-4.491668e-003
6.000000e+004,3.001066e+002,3.282916e-003,-3.407186e-003
6.000000e+004,3.072099e+002,3.256283e-003,-8.076396e-003
6.000000e+004,3.152475e+002,3.241824e-003,-1.256648e-002
6.000000e+004,3.232153e+002,3.238718e-003,-1.686768e-002
6.000000e+004,3.312345e+002,3.250953e-003,-2.120426e-002
6.000000e+004,3.392498e+002,3.276879e-003,-2.580944e-002
6.000000e+004,3.473641e+002,3.318429e-003,-3.068686e-002
6.000000e+004,3.552859e+002,3.384798e-003,-3.586239e-002
6.000000e+004,3.633123e+002,3.531995e-003,-4.174342e-002
6.000000e+004,3.712548e+002,6.267090e-003,-5.291673e-002
6.000000e+004,3.792489e+002,1.215946e-002,-8.671756e-002
6.000000e+004,3.873245e+002,1.193189e-002,-8.919708e-002
6.000000e+004,3.952554e+002,1.175082e-002,-9.113923e-002
5.500000e+004,3.978140e+002,1.072422e-002,-8.587961e-002
5.500000e+004,3.893499e+002,1.092396e-002,-8.023685e-002
5.500000e+004,3.817992e+002,1.108775e-002,-7.636119e-002
5.500000e+004,3.730552e+002,1.132980e-002,-7.415666e-002
5.500000e+004,3.650999e+002,1.154157e-002,-6.978376e-002
5.500000e+004,3.574766e+002,1.172909e-002,-6.966154e-002
5.500000e+004,3.487074e+002,1.106879e-002,-6.654962e-002
5.500000e+004,3.417874e+002,3.064862e-003,-2.112318e-002
5.500000e+004,3.329197e+002,3.026654e-003,-1.551658e-002
5.500000e+004,3.258147e+002,3.010601e-003,-1.118610e-002
5.500000e+004,3.175917e+002,2.992305e-003,-9.183500e-003
5.500000e+004,3.097742e+002,2.998890e-003,-5.431939e-003
5.500000e+004,3.015944e+002,3.006150e-003,-3.850810e-003
5.500000e+004,3.052594e+002,2.988123e-003,-7.236024e-003
5.500000e+004,3.133050e+002,2.972772e-003,-1.177043e-002
5.500000e+004,3.214069e+002,2.966136e-003,-1.622700e-002
5.500000e+004,3.292195e+002,2.973086e-003,-2.024298e-002
5.500000e+004,3.373190e+002,2.994945e-003,-2.493455e-002
5.500000e+004,3.452872e+002,3.026418e-003,-2.974046e-002
5.500000e+004,3.532462e+002,3.079472e-003,-3.475583e-002
5.500000e+004,3.614904e+002,3.193633e-003,-4.072072e-002
5.500000e+004,3.692607e+002,3.988448e-003,-4.701976e-002
5.500000e+004,3.772362e+002,1.123546e-002,-8.631681e-002
5.500000e+004,3.852639e+002,1.099805e-002,-8.866984e-002
5.500000e+004,3.932693e+002,1.083723e-002,-9.101258e-002
5.000000e+004,4.000035e+002,9.722807e-003,-8.788153e-002
5.000000e+004,3.913197e+002,9.908105e-003,-8.192915e-002
5.000000e+004,3.836605e+002,1.006597e-002,-7.739542e-002
5.000000e+004,3.753029e+002,1.026226e-002,-7.577105e-002
5.000000e+004,3.664994e+002,1.047916e-002,-7.085538e-002
5.000000e+004,3.595575e+002,1.064277e-002,-7.111666e-002
5.000000e+004,3.506700e+002,1.073983e-002,-6.649571e-002
5.000000e+004,3.438081e+002,4.136280e-003,-4.710228e-002
5.000000e+004,3.350572e+002,2.748472e-003,-1.787636e-002
5.000000e+004,3.275974e+002,2.737878e-003,-1.273110e-002
5.000000e+004,3.195754e+002,2.719614e-003,-1.062887e-002
5.000000e+004,3.115818e+002,2.722807e-003,-6.553832e-003
5.000000e+004,3.035893e+002,2.727126e-003,-4.915104e-003
5.000000e+004,3.033079e+002,2.721276e-003,-6.098004e-003
5.000000e+004,3.112652e+002,2.704705e-003,-1.082194e-002
5.000000e+004,3.192897e+002,2.697621e-003,-1.505933e-002
5.000000e+004,3.272836e+002,2.712307e-003,-1.942220e-002
5.000000e+004,3.353149e+002,2.715269e-003,-2.411706e-002
5.000000e+004,3.432151e+002,2.741723e-003,-2.858255e-002
5.000000e+004,3.512434e+002,2.786804e-003,-3.371223e-002
5.000000e+004,3.592222e+002,2.868456e-003,-3.905711e-002
5.000000e+004,3.672699e+002,3.149804e-003,-4.621559e-002
5.000000e+004,3.752798e+002,1.028295e-002,-8.610103e-002
5.000000e+004,3.832795e+002,1.007362e-002,-8.841915e-002
5.000000e+004,3.912823e+002,9.906515e-003,-9.094977e-002
5.000000e+004,3.992928e+002,9.749964e-003,-9.256642e-002
4.500000e+004,3.934515e+002,8.891141e-003,-8.348957e-002
4.500000e+004,3.856039e+002,9.043399e-003,-7.862902e-002
4.500000e+004,3.775271e+002,9.202387e-003,-7.734033e-002
4.500000e+004,3.683366e+002,9.414053e-003,-7.212274e-002
4.500000e+004,3.618274e+002,9.548781e-003,-6.903053e-002
4.500000e+004,3.527410e+002,9.699119e-003,-6.782711e-002
4.500000e+004,3.452490e+002,5.942248e-003,-6.322072e-002
4.500000e+004,3.374648e+002,2.489097e-003,-1.926257e-002
4.500000e+004,3.290727e+002,2.465838e-003,-1.304097e-002
4.500000e+004,3.216472e+002,2.450039e-003,-1.142850e-002
4.500000e+004,3.133363e+002,2.450905e-003,-7.093269e-003
4.500000e+004,3.058875e+002,2.452316e-003,-4.702649e-003
4.500000e+004,3.011918e+002,2.467226e-003,-4.426973e-003
4.500000e+004,3.092611e+002,2.439655e-003,-9.589940e-003
4.500000e+004,3.172459e+002,2.431457e-003,-1.396506e-002
4.500000e+004,3.252307e+002,2.430688e-003,-1.874116e-002
4.500000e+004,3.332316e+002,2.443112e-003,-2.307420e-002
4.500000e+004,3.414510e+002,2.462480e-003,-2.803842e-002
4.500000e+004,3.492912e+002,2.498994e-003,-3.282122e-002
4.500000e+004,3.572761e+002,2.562513e-003,-3.786434e-002
4.500000e+004,3.652691e+002,2.723774e-003,-4.446337e-002
4.500000e+004,3.734544e+002,8.800022e-003,-8.150868e-002
4.500000e+004,3.814752e+002,9.131881e-003,-8.834993e-002
4.500000e+004,3.892392e+002,8.967192e-003,-9.070717e-002
4.500000e+004,3.972794e+002,8.829650e-003,-9.270618e-002
4.000000e+004,3.955599e+002,7.882465e-003,-8.555518e-002
4.000000e+004,3.873672e+002,8.025412e-003,-8.020229e-002
4.000000e+004,3.797176e+002,8.149723e-003,-7.919505e-002
4.000000e+004,3.706885e+002,8.339409e-003,-7.376000e-002
4.000000e+004,3.636716e+002,8.478627e-003,-7.009853e-002
4.000000e+004,3.552761e+002,8.627763e-003,-6.900828e-002
4.000000e+004,3.468546e+002,7.303257e-003,-6.655683e-002
4.000000e+004,3.395724e+002,2.223402e-003,-1.983093e-002
4.000000e+004,3.309439e+002,2.199039e-003,-1.421497e-002
4.000000e+004,3.239105e+002,2.189665e-003,-1.072111e-002
4.000000e+004,3.154192e+002,2.180791e-003,-7.920552e-003
4.000000e+004,3.077831e+002,2.184902e-003,-4.573288e-003
4.000000e+004,3.001101e+002,2.192777e-003,-2.315183e-003
4.000000e+004,3.073386e+002,2.174604e-003,-8.215927e-003
4.000000e+004,3.152495e+002,2.164708e-003,-1.278695e-002
4.000000e+004,3.232340e+002,2.162689e-003,-1.735949e-002
4.000000e+004,3.312585e+002,2.172491e-003,-2.178328e-002
4.000000e+004,3.392682e+002,2.187473e-003,-2.628304e-002
4.000000e+004,3.472747e+002,2.214854e-003,-3.107779e-002
4.000000e+004,3.553240e+002,2.262458e-003,-3.599241e-002
4.000000e+004,3.632007e+002,2.367108e-003,-4.218381e-002
4.000000e+004,3.712520e+002,5.959525e-003,-6.704922e-002
4.000000e+004,3.792488e+002,8.186940e-003,-8.751646e-002
4.000000e+004,3.872910e+002,8.009944e-003,-8.976718e-002
4.000000e+004,3.953030e+002,7.896323e-003,-9.203693e-002
3.500000e+004,3.976954e+002,6.875360e-003,-8.692963e-002
3.500000e+004,3.893530e+002,7.006492e-003,-8.119433e-002
3.500000e+004,3.817726e+002,7.113959e-003,-7.712541e-002
3.500000e+004,3.727830e+002,7.273485e-003,-7.478164e-002
3.500000e+004,3.648289e+002,7.414239e-003,-7.063852e-002
3.500000e+004,3.575203e+002,7.540872e-003,-7.028157e-002
3.500000e+004,3.487953e+002,7.511397e-003,-6.564216e-002
3.500000e+004,3.419229e+002,2.031565e-003,-2.114323e-002
3.500000e+004,3.331122e+002,1.927691e-003,-1.557754e-002
3.500000e+004,3.256922e+002,1.918421e-003,-1.119727e-002
3.500000e+004,3.175118e+002,1.910024e-003,-9.234407e-003
3.500000e+004,3.096681e+002,1.913647e-003,-5.292958e-003
3.500000e+004,3.015908e+002,1.918829e-003,-3.881150e-003
3.500000e+004,3.053605e+002,1.907737e-003,-7.280705e-003
3.500000e+004,3.133069e+002,1.898542e-003,-1.167301e-002
3.500000e+004,3.213925e+002,1.895724e-003,-1.638950e-002
3.500000e+004,3.293275e+002,1.900771e-003,-2.037481e-002
3.500000e+004,3.372621e+002,1.910998e-003,-2.496753e-002
3.500000e+004,3.452633e+002,1.934040e-003,-2.960612e-002
3.500000e+004,3.532688e+002,1.967886e-003,-3.483603e-002
3.500000e+004,3.614641e+002,2.047540e-003,-4.064228e-002
3.500000e+004,3.692717e+002,3.315935e-003,-5.213404e-002
3.500000e+004,3.772247e+002,7.215019e-003,-8.690596e-002
3.500000e+004,3.852188e+002,7.062319e-003,-8.929746e-002
3.500000e+004,3.932192e+002,6.952603e-003,-9.151328e-002
3.000000e+004,4.000099e+002,5.878314e-003,-8.866058e-002
3.000000e+004,3.914657e+002,5.987226e-003,-8.247077e-002
3.000000e+004,3.835652e+002,6.086693e-003,-7.755153e-002
3.000000e+004,3.753144e+002,6.205918e-003,-7.614149e-002
3.000000e+004,3.666891e+002,6.341175e-003,-7.147699e-002
3.000000e+004,3.597032e+002,6.449861e-003,-7.121257e-002
3.000000e+004,3.508997e+002,6.524750e-003,-6.652059e-002
3.000000e+004,3.437608e+002,3.229953e-003,-5.724724e-002
3.000000e+004,3.353967e+002,1.659123e-003,-1.708432e-002
3.000000e+004,3.275632e+002,1.650114e-003,-1.235406e-002
3.000000e+004,3.195836e+002,1.639462e-003,-1.048959e-002
3.000000e+004,3.116221e+002,1.641186e-003,-6.211640e-003
3.000000e+004,3.035966e+002,1.643528e-003,-4.758372e-003
3.000000e+004,3.033587e+002,1.640253e-003,-6.185031e-003
3.000000e+004,3.112652e+002,1.631073e-003,-1.066644e-002
3.000000e+004,3.193464e+002,1.626826e-003,-1.495555e-002
3.000000e+004,3.272665e+002,1.630259e-003,-1.931291e-002
3.000000e+004,3.353149e+002,1.637651e-003,-2.391902e-002
3.000000e+004,3.432929e+002,1.653260e-003,-2.840046e-002
3.000000e+004,3.512557e+002,1.679752e-003,-3.411784e-002
3.000000e+004,3.592196e+002,1.732913e-003,-3.923212e-002
3.000000e+004,3.672237e+002,1.971308e-003,-4.613244e-002
3.000000e+004,3.752798e+002,6.227576e-003,-8.666055e-002
3.000000e+004,3.832795e+002,6.099823e-003,-8.890730e-002
3.000000e+004,3.912451e+002,5.993680e-003,-9.129490e-002
3.000000e+004,3.992606e+002,5.899373e-003,-9.345822e-002
2.500000e+004,3.933794e+002,4.977845e-003,-8.413425e-002
2.500000e+004,3.855828e+002,5.064013e-003,-7.929046e-002
2.500000e+004,3.775212e+002,5.153040e-003,-7.770845e-002
2.500000e+004,3.686021e+002,5.278887e-003,-7.319147e-002
2.500000e+004,3.618379e+002,5.353380e-003,-6.935231e-002
2.500000e+004,3.527885e+002,5.442216e-003,-6.750353e-002
2.500000e+004,3.454952e+002,3.974549e-003,-6.539051e-002
2.500000e+004,3.374490e+002,1.387253e-003,-1.832180e-002
2.500000e+004,3.293254e+002,1.376827e-003,-1.326010e-002
2.500000e+004,3.216658e+002,1.367358e-003,-1.105488e-002
2.500000e+004,3.136047e+002,1.369681e-003,-6.819293e-003
2.500000e+004,3.058542e+002,1.369847e-003,-4.723640e-003
2.500000e+004,3.012580e+002,1.371822e-003,-3.723303e-003
2.500000e+004,3.093216e+002,1.362980e-003,-8.831408e-003
2.500000e+004,3.172658e+002,1.358858e-003,-1.311970e-002
2.500000e+004,3.252475e+002,1.360145e-003,-1.752879e-002
2.500000e+004,3.333002e+002,1.365864e-003,-2.202099e-002
2.500000e+004,3.414767e+002,1.373140e-003,-2.622461e-002
2.500000e+004,3.492888e+002,1.396968e-003,-3.151878e-002
2.500000e+004,3.573094e+002,1.430706e-003,-3.676996e-002
2.500000e+004,3.652476e+002,1.528702e-003,-4.372354e-002
2.500000e+004,3.732518e+002,4.963933e-003,-8.174292e-002
2.500000e+004,3.815105e+002,5.119861e-003,-8.758467e-002
2.500000e+004,3.892607e+002,5.015190e-003,-8.975103e-002
2.500000e+004,3.972795e+002,4.948159e-003,-9.217274e-002
2.000000e+004,3.956487e+002,3.970796e-003,-8.479673e-002
2.000000e+004,3.874188e+002,4.045174e-003,-7.933058e-002
2.000000e+004,3.797263e+002,4.107121e-003,-7.775910e-002
2.000000e+004,3.707440e+002,4.200161e-003,-7.277112e-002
2.000000e+004,3.636396e+002,4.271456e-003,-6.910754e-002
2.000000e+004,3.552786e+002,4.347917e-003,-6.793630e-002
2.000000e+004,3.470620e+002,4.030294e-003,-6.460319e-002
2.000000e+004,3.396001e+002,1.115912e-003,-1.878667e-002
2.000000e+004,3.308588e+002,1.105325e-003,-1.326521e-002
2.000000e+004,3.238625e+002,1.099164e-003,-1.131488e-002
2.000000e+004,3.155316e+002,1.097896e-003,-7.519530e-003
2.000000e+004,3.078916e+002,1.100367e-003,-3.991239e-003
2.000000e+004,3.000906e+002,1.103552e-003,-2.690288e-003
2.000000e+004,3.073218e+002,1.095450e-003,-7.836873e-003
2.000000e+004,3.152731e+002,1.090158e-003,-1.210436e-002
2.000000e+004,3.233067e+002,1.090209e-003,-1.646550e-002
2.000000e+004,3.312345e+002,1.094355e-003,-2.088167e-002
2.000000e+004,3.392705e+002,1.100029e-003,-2.507041e-002
2.000000e+004,3.472698e+002,1.113543e-003,-3.064157e-002
2.000000e+004,3.552834e+002,1.140094e-003,-3.532290e-002
2.000000e+004,3.632060e+002,1.194542e-003,-4.185342e-002
2.000000e+004,3.712937e+002,3.283044e-003,-7.103777e-002
2.000000e+004,3.792256e+002,4.126919e-003,-8.676578e-002
2.000000e+004,3.872242e+002,4.039790e-003,-8.883767e-002
2.000000e+004,3.953125e+002,3.981547e-003,-9.150916e-002
1.500000e+004,3.978108e+002,2.969546e-003,-8.645818e-002
1.500000e+004,3.893438e+002,3.027516e-003,-8.067305e-002
1.500000e+004,3.817638e+002,3.071736e-003,-7.627025e-002
1.500000e+004,3.727999e+002,3.138735e-003,-7.400710e-002
1.500000e+004,3.650731e+002,3.198103e-003,-6.968231e-002
1.500000e+004,3.573635e+002,3.250982e-003,-6.911835e-002
1.500000e+004,3.486490e+002,3.256769e-003,-6.407951e-002
1.500000e+004,3.416658e+002,8.437622e-004,-2.016941e-002
1.500000e+004,3.330280e+002,8.345529e-004,-1.462888e-002
1.500000e+004,3.257239e+002,8.296968e-004,-1.039197e-002
1.500000e+004,3.175358e+002,8.266942e-004,-8.281332e-003
1.500000e+004,3.097155e+002,8.272710e-004,-5.180285e-003
1.500000e+004,3.016069e+002,8.293677e-004,-3.247736e-003
1.500000e+004,3.053513e+002,8.249504e-004,-6.418475e-003
1.500000e+004,3.132545e+002,8.209783e-004,-1.113148e-002
1.500000e+004,3.214151e+002,8.196345e-004,-1.615471e-002
1.500000e+004,3.292670e+002,8.222261e-004,-1.970119e-002
1.500000e+004,3.372803e+002,8.264579e-004,-2.400732e-002
1.500000e+004,3.452394e+002,8.358267e-004,-2.914834e-002
1.500000e+004,3.532487e+002,8.513177e-004,-3.463269e-002
1.500000e+004,3.615009e+002,8.848121e-004,-4.033675e-002
1.500000e+004,3.692964e+002,1.634407e-003,-5.591128e-002
1.500000e+004,3.772678e+002,3.118180e-003,-8.636991e-002
1.500000e+004,3.852669e+002,3.056064e-003,-8.877286e-002
1.500000e+004,3.932819e+002,3.008134e-003,-9.126121e-002
1.000000e+004,4.000035e+002,1.980603e-003,-8.866106e-002
1.000000e+004,3.912422e+002,2.017747e-003,-8.218254e-002
1.000000e+004,3.836545e+002,2.048423e-003,-7.751728e-002
1.000000e+004,3.752147e+002,2.086486e-003,-7.572381e-002
1.000000e+004,3.667541e+002,2.130311e-003,-7.077067e-002
1.000000e+004,3.596589e+002,2.163032e-003,-7.030334e-002
1.000000e+004,3.506726e+002,2.188608e-003,-6.515677e-002
1.000000e+004,3.437679e+002,1.146394e-003,-5.712914e-002
1.000000e+004,3.353225e+002,5.603607e-004,-1.640380e-002
1.000000e+004,3.277257e+002,5.568282e-004,-1.222304e-002
1.000000e+004,3.194316e+002,5.546095e-004,-1.011350e-002
1.000000e+004,3.116491e+002,5.544502e-004,-6.362933e-003
1.000000e+004,3.036747e+002,5.556779e-004,-4.087124e-003
1.000000e+004,3.033170e+002,5.544909e-004,-5.294013e-003
1.000000e+004,3.112767e+002,5.510675e-004,-1.027512e-002
1.000000e+004,3.192735e+002,5.498932e-004,-1.464406e-002
1.000000e+004,3.272558e+002,5.512786e-004,-1.890729e-002
1.000000e+004,3.352386e+002,5.537240e-004,-2.309858e-002
1.000000e+004,3.432151e+002,5.574606e-004,-2.770565e-002
1.000000e+004,3.512533e+002,5.677335e-004,-3.251943e-002
1.000000e+004,3.592248e+002,5.846107e-004,-3.861929e-002
1.000000e+004,3.672264e+002,6.959850e-004,-4.562324e-002
1.000000e+004,3.752912e+002,2.091747e-003,-8.572419e-002
1.000000e+004,3.832855e+002,2.054619e-003,-8.837661e-002
1.000000e+004,3.912420e+002,2.014777e-003,-9.065051e-002
1.000000e+004,3.993219e+002,1.987242e-003,-9.284315e-002
9.000000e+003,3.933103e+002,1.809772e-003,-8.368763e-002
9.000000e+003,3.855226e+002,1.840302e-003,-7.888933e-002
9.000000e+003,3.774895e+002,1.871537e-003,-7.715378e-002
9.000000e+003,3.687721e+002,1.911540e-003,-7.213797e-002
9.000000e+003,3.618326e+002,1.937357e-003,-6.843650e-002
9.000000e+003,3.530710e+002,1.964309e-003,-6.657103e-002
9.000000e+003,3.456531e+002,1.561076e-003,-6.406908e-002
9.000000e+003,3.373421e+002,5.064431e-004,-1.758050e-002
9.000000e+003,3.294659e+002,5.024129e-004,-1.283418e-002
9.000000e+003,3.216493e+002,4.988669e-004,-1.090699e-002
9.000000e+003,3.135677e+002,4.996649e-004,-7.036114e-003
9.000000e+003,3.057546e+002,4.999682e-004,-5.026900e-003
9.000000e+003,3.012382e+002,5.010184e-004,-4.419188e-003
9.000000e+003,3.093216e+002,4.975958e-004,-9.667372e-003
9.000000e+003,3.172538e+002,4.957287e-004,-1.361925e-002
9.000000e+003,3.252244e+002,4.961465e-004,-1.804462e-002
9.000000e+003,3.332781e+002,4.986230e-004,-2.281905e-002
9.000000e+003,3.414814e+002,5.015219e-004,-2.692146e-002
9.000000e+003,3.492936e+002,5.074065e-004,-3.112415e-002
9.000000e+003,3.572273e+002,5.213293e-004,-3.721486e-002
9.000000e+003,3.652368e+002,5.574792e-004,-4.392485e-002
9.000000e+003,3.732771e+002,1.805977e-003,-8.252433e-002
9.000000e+003,3.814928e+002,1.859522e-003,-8.806269e-002
9.000000e+003,3.892269e+002,1.825254e-003,-9.020181e-002
9.000000e+003,3.972955e+002,1.797844e-003,-9.281196e-002
8.000000e+003,3.954869e+002,1.607413e-003,-8.612008e-002
8.000000e+003,3.872639e+002,1.642196e-003,-8.105939e-002
8.000000e+003,3.797467e+002,1.663444e-003,-7.900752e-002
8.000000e+003,3.706496e+002,1.702014e-003,-7.369485e-002
8.000000e+003,3.636956e+002,1.725331e-003,-6.972224e-002
8.000000e+003,3.552559e+002,1.740734e-003,-6.756505e-002
8.000000e+003,3.472700e+002,1.670375e-003,-6.358536e-002
8.000000e+003,3.394365e+002,4.515362e-004,-1.910014e-002
8.000000e+003,3.314010e+002,4.474545e-004,-1.399648e-002
8.000000e+003,3.238480e+002,4.451153e-004,-1.179875e-002
8.000000e+003,3.155118e+002,4.448212e-004,-8.148761e-003
8.000000e+003,3.078954e+002,4.453905e-004,-4.460220e-003
8.000000e+003,3.000888e+002,4.473556e-004,-3.211750e-003
8.000000e+003,3.072919e+002,4.440249e-004,-8.052636e-003
8.000000e+003,3.152259e+002,4.416328e-004,-1.269140e-002
8.000000e+003,3.232569e+002,4.413878e-004,-1.720532e-002
8.000000e+003,3.312761e+002,4.429794e-004,-2.137626e-002
8.000000e+003,3.392543e+002,4.460656e-004,-2.586867e-002
8.000000e+003,3.472867e+002,4.499647e-004,-3.030736e-002
8.000000e+003,3.552555e+002,4.597203e-004,-3.582060e-002
8.000000e+003,3.632618e+002,4.819553e-004,-4.219413e-002
8.000000e+003,3.712715e+002,1.352961e-003,-7.227224e-002
8.000000e+003,3.792285e+002,1.666367e-003,-8.783126e-002
8.000000e+003,3.873153e+002,1.640647e-003,-9.076080e-002
8.000000e+003,3.952903e+002,1.614390e-003,-9.316057e-002
7.000000e+003,3.977979e+002,1.402733e-003,-8.796817e-002
7.000000e+003,3.893929e+002,1.430477e-003,-8.189269e-002
7.000000e+003,3.818080e+002,1.458143e-003,-7.769670e-002
7.000000e+003,3.727857e+002,1.488760e-003,-7.532985e-002
7.000000e+003,3.649576e+002,1.514033e-003,-7.072414e-002
7.000000e+003,3.573277e+002,1.527339e-003,-6.922092e-002
7.000000e+003,3.484564e+002,1.526220e-003,-6.382671e-002
7.000000e+003,3.417172e+002,3.986740e-004,-2.038456e-002
7.000000e+003,3.332783e+002,3.936939e-004,-1.546162e-002
7.000000e+003,3.258232e+002,3.921017e-004,-1.105052e-002
7.000000e+003,3.173399e+002,3.905578e-004,-8.745519e-003
7.000000e+003,3.097439e+002,3.913438e-004,-5.275745e-003
7.000000e+003,3.015926e+002,3.926741e-004,-3.488095e-003
7.000000e+003,3.054378e+002,3.907485e-004,-6.991782e-003
7.000000e+003,3.133011e+002,3.886615e-004,-1.139507e-002
7.000000e+003,3.214130e+002,3.879215e-004,-1.582292e-002
7.000000e+003,3.292411e+002,3.891057e-004,-2.036699e-002
7.000000e+003,3.373054e+002,3.909846e-004,-2.450138e-002
7.000000e+003,3.452968e+002,3.942271e-004,-2.935858e-002
7.000000e+003,3.533289e+002,4.011730e-004,-3.451738e-002
7.000000e+003,3.614588e+002,4.164636e-004,-4.046170e-002
7.000000e+003,3.692882e+002,8.251833e-004,-5.912972e-002
7.000000e+003,3.772621e+002,1.476579e-003,-8.758129e-002
7.000000e+003,3.852669e+002,1.450193e-003,-9.033005e-002
7.000000e+003,3.932600e+002,1.421457e-003,-9.246239e-002
6.000000e+003,4.000035e+002,1.198151e-003,-8.934245e-002
6.000000e+003,3.912980e+002,1.220167e-003,-8.296757e-002
6.000000e+003,3.836366e+002,1.242965e-003,-7.844813e-002
6.000000e+003,3.753768e+002,1.269433e-003,-7.658334e-002
6.000000e+003,3.667975e+002,1.293006e-003,-7.175212e-002
6.000000e+003,3.596094e+002,1.306721e-003,-7.086767e-002
6.000000e+003,3.506183e+002,1.321741e-003,-6.547567e-002
6.000000e+003,3.437513e+002,7.430154e-004,-5.930876e-002
6.000000e+003,3.351626e+002,3.390101e-004,-1.635943e-002
6.000000e+003,3.276423e+002,3.375105e-004,-1.196910e-002
6.000000e+003,3.195025e+002,3.360028e-004,-9.692264e-003
6.000000e+003,3.116913e+002,3.360462e-004,-6.131235e-003
6.000000e+003,3.035493e+002,3.372322e-004,-4.625184e-003
6.000000e+003,3.033025e+002,3.368778e-004,-5.152379e-003
6.000000e+003,3.113073e+002,3.344966e-004,-9.802118e-003
6.000000e+003,3.193038e+002,3.334317e-004,-1.500754e-002
6.000000e+003,3.273689e+002,3.341281e-004,-1.887152e-002
6.000000e+003,3.352745e+002,3.355811e-004,-2.347112e-002
6.000000e+003,3.432858e+002,3.376675e-004,-2.762457e-002
6.000000e+003,3.512508e+002,3.427534e-004,-3.268377e-002
6.000000e+003,3.592637e+002,3.537311e-004,-3.910030e-002
6.000000e+003,3.672672e+002,4.425372e-004,-4.670691e-002
6.000000e+003,3.752713e+002,1.269981e-003,-8.670396e-002
6.000000e+003,3.832646e+002,1.249519e-003,-8.987312e-002
6.000000e+003,3.913009e+002,1.225248e-003,-9.168525e-002
6.000000e+003,3.992638e+002,1.200090e-003,-9.364181e-002
5.000000e+003,3.934828e+002,1.011853e-003,-8.456384e-002
5.000000e+003,3.855737e+002,1.032436e-003,-7.923691e-002
5.000000e+003,3.774349e+002,1.053173e-003,-7.805051e-002
5.000000e+003,3.688050e+002,1.074758e-003,-7.291357e-002
5.000000e+003,3.619038e+002,1.090165e-003,-6.900943e-002
5.000000e+003,3.531487e+002,1.102097e-003,-6.692682e-002
5.000000e+003,3.457058e+002,9.135202e-004,-6.456175e-002
5.000000e+003,3.374263e+002,2.844835e-004,-1.820896e-002
5.000000e+003,3.295634e+002,2.822199e-004,-1.325914e-002
5.000000e+003,3.215980e+002,2.813318e-004,-1.102882e-002
5.000000e+003,3.136262e+002,2.812661e-004,-7.798668e-003
5.000000e+003,3.057565e+002,2.818492e-004,-4.840949e-003
5.000000e+003,3.012651e+002,2.826875e-004,-4.571334e-003
5.000000e+003,3.092952e+002,2.804492e-004,-9.618847e-003
5.000000e+003,3.172419e+002,2.793313e-004,-1.426800e-002
5.000000e+003,3.252538e+002,2.792973e-004,-1.794143e-002
5.000000e+003,3.332736e+002,2.804929e-004,-2.354561e-002
5.000000e+003,3.414884e+002,2.817201e-004,-2.722323e-002
5.000000e+003,3.492202e+002,2.854113e-004,-3.183618e-002
5.000000e+003,3.572453e+002,2.931258e-004,-3.812369e-002
5.000000e+003,3.652745e+002,3.148855e-004,-4.524396e-002
5.000000e+003,3.732264e+002,1.008569e-003,-8.295789e-002
5.000000e+003,3.815517e+002,1.047321e-003,-8.923554e-002
5.000000e+003,3.893068e+002,1.026431e-003,-9.119666e-002
5.000000e+003,3.973019e+002,1.005329e-003,-9.329964e-002
4.000000e+003,3.955440e+002,8.062673e-004,-8.599627e-002
4.000000e+003,3.872639e+002,8.229778e-004,-8.030753e-002
4.000000e+003,3.798430e+002,8.397870e-004,-7.916676e-002
4.000000e+003,3.706027e+002,8.576171e-004,-7.390661e-002
4.000000e+003,3.635438e+002,8.704736e-004,-6.996182e-002
4.000000e+003,3.551366e+002,8.816323e-004,-6.856912e-002
4.000000e+003,3.467317e+002,8.252023e-004,-6.423812e-002
4.000000e+003,3.396162e+002,2.296440e-004,-1.966103e-002
4.000000e+003,3.302707e+002,2.269510e-004,-1.353320e-002
4.000000e+003,3.239502e+002,2.266972e-004,-1.089175e-002
4.000000e+003,3.153896e+002,2.261291e-004,-8.627732e-003
4.000000e+003,3.078224e+002,2.266723e-004,-4.841566e-003
4.000000e+003,3.001083e+002,2.279652e-004,-4.132711e-003
4.000000e+003,3.073908e+002,2.260237e-004,-8.532910e-003
4.000000e+003,3.152475e+002,2.247455e-004,-1.305197e-002
4.000000e+003,3.232922e+002,2.244300e-004,-1.706327e-002
4.000000e+003,3.312958e+002,2.254760e-004,-2.180622e-002
4.000000e+003,3.392314e+002,2.267123e-004,-2.626514e-002
4.000000e+003,3.473134e+002,2.288533e-004,-3.163692e-002
4.000000e+003,3.552681e+002,2.337834e-004,-3.736249e-002
4.000000e+003,3.632937e+002,2.453290e-004,-4.331286e-002
4.000000e+003,3.712742e+002,6.903263e-004,-7.301530e-002
4.000000e+003,3.793215e+002,8.428805e-004,-8.795726e-002
4.000000e+003,3.872486e+002,8.270681e-004,-9.045509e-002
4.000000e+003,3.952554e+002,8.097265e-004,-9.255300e-002
3.000000e+003,3.977435e+002,6.026500e-004,-8.724664e-002
3.000000e+003,3.892977e+002,6.150602e-004,-8.133451e-002
3.000000e+003,3.817726e+002,6.267063e-004,-7.760137e-002
3.000000e+003,3.728755e+002,6.416163e-004,-7.521181e-002
3.000000e+003,3.649925e+002,6.520721e-004,-7.031150e-002
3.000000e+003,3.574585e+002,6.596271e-004,-6.944437e-002
3.000000e+003,3.488807e+002,6.628190e-004,-6.501334e-002
3.000000e+003,3.416588e+002,1.744340e-004,-2.081153e-002
3.000000e+003,3.330502e+002,1.726959e-004,-1.618845e-002
3.000000e+003,3.256986e+002,1.720741e-004,-1.098948e-002
3.000000e+003,3.174898e+002,1.715482e-004,-9.547500e-003
3.000000e+003,3.097496e+002,1.716084e-004,-5.888551e-003
3.000000e+003,3.016123e+002,1.724441e-004,-4.422519e-003
3.000000e+003,3.053899e+002,1.715839e-004,-7.310106e-003
3.000000e+003,3.132584e+002,1.704733e-004,-1.256600e-002
3.000000e+003,3.214438e+002,1.700076e-004,-1.714794e-002
3.000000e+003,3.292627e+002,1.707026e-004,-2.102961e-002
3.000000e+003,3.373008e+002,1.713793e-004,-2.552213e-002
3.000000e+003,3.452729e+002,1.726702e-004,-3.004544e-002
3.000000e+003,3.532487e+002,1.761737e-004,-3.565136e-002
3.000000e+003,3.614930e+002,1.830413e-004,-4.174157e-002
3.000000e+003,3.692635e+002,3.639435e-004,-5.983293e-002
3.000000e+003,3.772132e+002,6.359613e-004,-8.732733e-002
3.000000e+003,3.852639e+002,6.246840e-004,-8.995407e-002
3.000000e+003,3.932694e+002,6.119361e-004,-9.193625e-002
2.500000e+003,4.000035e+002,5.008724e-004,-8.901610e-002
2.500000e+003,3.913539e+002,5.102733e-004,-8.252595e-002
2.500000e+003,3.836723e+002,5.202867e-004,-7.786899e-002
2.500000e+003,3.752688e+002,5.319135e-004,-7.638477e-002
2.500000e+003,3.663560e+002,5.423251e-004,-7.089801e-002
2.500000e+003,3.597292e+002,5.475230e-004,-7.066235e-002
2.500000e+003,3.504727e+002,5.544347e-004,-6.555997e-002
2.500000e+003,3.437206e+002,3.334445e-004,-6.088351e-002
2.500000e+003,3.352411e+002,1.448937e-004,-1.746549e-002
2.500000e+003,3.276509e+002,1.444209e-004,-1.297824e-002
2.500000e+003,3.194945e+002,1.438330e-004,-1.082064e-002
2.500000e+003,3.115781e+002,1.437402e-004,-7.400895e-003
2.500000e+003,3.035712e+002,1.441741e-004,-4.971283e-003
2.500000e+003,3.033733e+002,1.440160e-004,-6.933198e-003
2.500000e+003,3.113572e+002,1.430543e-004,-1.159540e-002
2.500000e+003,3.193039e+002,1.425695e-004,-1.666427e-002
2.500000e+003,3.272451e+002,1.431448e-004,-2.013675e-002
2.500000e+003,3.353194e+002,1.434333e-004,-2.425323e-002
2.500000e+003,3.432552e+002,1.446158e-004,-2.910227e-002
2.500000e+003,3.512508e+002,1.467349e-004,-3.447335e-002
2.500000e+003,3.593157e+002,1.515372e-004,-4.057455e-002
2.500000e+003,3.673461e+002,1.951239e-004,-4.810066e-002
2.500000e+003,3.753481e+002,5.323159e-004,-8.676714e-002
2.500000e+003,3.832379e+002,5.236956e-004,-8.933873e-002
2.500000e+003,3.913258e+002,5.124880e-004,-9.167990e-002
2.500000e+003,3.992928e+002,5.021897e-004,-9.348863e-002
2.000000e+003,3.934735e+002,4.065988e-004,-8.406187e-002
2.000000e+003,3.855887e+002,4.151357e-004,-7.891676e-002
2.000000e+003,3.774839e+002,4.246710e-004,-7.796426e-002
2.000000e+003,3.685335e+002,4.332133e-004,-7.255146e-002
2.000000e+003,3.618195e+002,4.384846e-004,-6.859663e-002
2.000000e+003,3.529310e+002,4.430842e-004,-6.661420e-002
2.000000e+003,3.454474e+002,3.656575e-004,-6.461470e-002
2.000000e+003,3.374672e+002,1.173996e-004,-1.963970e-002
2.000000e+003,3.293189e+002,1.166352e-004,-1.489127e-002
2.000000e+003,3.216699e+002,1.160406e-004,-1.250821e-002
2.000000e+003,3.132760e+002,1.159841e-004,-9.055376e-003
2.000000e+003,3.058727e+002,1.160977e-004,-6.562695e-003
2.000000e+003,3.012490e+002,1.164098e-004,-5.950983e-003
2.000000e+003,3.092895e+002,1.155306e-004,-1.017898e-002
2.000000e+003,3.172419e+002,1.151683e-004,-1.524488e-002
2.000000e+003,3.252664e+002,1.153706e-004,-1.933338e-002
2.000000e+003,3.332803e+002,1.156886e-004,-2.374982e-002
2.000000e+003,3.414884e+002,1.164320e-004,-2.903233e-002
2.000000e+003,3.493181e+002,1.179664e-004,-3.367441e-002
2.000000e+003,3.572658e+002,1.210662e-004,-3.858847e-002
2.000000e+003,3.652745e+002,1.298190e-004,-4.541576e-002
2.000000e+003,3.735361e+002,4.111083e-004,-8.373164e-002
2.000000e+003,3.814752e+002,4.209414e-004,-8.817282e-002
2.000000e+003,3.892638e+002,4.136330e-004,-9.085517e-002
2.000000e+003,3.972124e+002,4.045800e-004,-9.266402e-002
1.500000e+003,3.955250e+002,3.040903e-004,-8.509867e-002
1.500000e+003,3.874371e+002,3.102548e-004,-7.959447e-002
1.500000e+003,3.797146e+002,3.172529e-004,-7.871263e-002
1.500000e+003,3.706247e+002,3.240113e-004,-7.327762e-002
1.500000e+003,3.636024e+002,3.279408e-004,-6.917126e-002
1.500000e+003,3.552304e+002,3.325463e-004,-6.803080e-002
1.500000e+003,3.469848e+002,3.201433e-004,-6.331357e-002
1.500000e+003,3.395516e+002,8.933722e-005,-1.962610e-002
1.500000e+003,3.311035e+002,8.851101e-005,-1.488715e-002
1.500000e+003,3.239940e+002,8.809837e-005,-1.245111e-002
1.500000e+003,3.151965e+002,8.797205e-005,-9.227831e-003
1.500000e+003,3.078542e+002,8.811490e-005,-6.721114e-003
1.500000e+003,3.000959e+002,8.860709e-005,-4.496328e-003
1.500000e+003,3.073554e+002,8.799064e-005,-9.495458e-003
1.500000e+003,3.152120e+002,8.745743e-005,-1.425648e-002
1.500000e+003,3.232319e+002,8.746788e-005,-1.852112e-002
1.500000e+003,3.312279e+002,8.772861e-005,-2.244217e-002
1.500000e+003,3.392751e+002,8.814968e-005,-2.716961e-002
1.500000e+003,3.473013e+002,8.906957e-005,-3.131355e-002
1.500000e+003,3.553011e+002,9.108365e-005,-3.726885e-002
1.500000e+003,3.632273e+002,9.532495e-005,-4.344380e-002
1.500000e+003,3.712520e+002,2.630348e-004,-7.328779e-002
1.500000e+003,3.793215e+002,3.180739e-004,-8.751252e-002
1.500000e+003,3.873062e+002,3.125800e-004,-9.002002e-002
1.500000e+003,3.952903e+002,3.056108e-004,-9.160111e-002
1.000000e+003,3.977659e+002,2.019238e-004,-8.658927e-002
1.000000e+003,3.888837e+002,2.063135e-004,-8.025889e-002
1.000000e+003,3.817491e+002,2.101682e-004,-7.664664e-002
1.000000e+003,3.726485e+002,2.153649e-004,-7.441799e-002
1.000000e+003,3.642854e+002,2.191022e-004,-6.967665e-002
1.000000e+003,3.573585e+002,2.213083e-004,-6.852105e-002
1.000000e+003,3.479459e+002,2.210398e-004,-6.358761e-002
1.000000e+003,3.419253e+002,6.101496e-005,-2.191565e-002
1.000000e+003,3.325287e+002,6.005871e-005,-1.583640e-002
1.000000e+003,3.257619e+002,5.985604e-005,-1.258947e-002
1.000000e+003,3.174499e+002,5.976488e-005,-9.956360e-003
1.000000e+003,3.097231e+002,5.980722e-005,-1.050941e-002
1.000000e+003,3.015406e+002,5.996267e-005,-5.310843e-003
1.000000e+003,3.053458e+002,5.967040e-005,-8.438977e-003
1.000000e+003,3.132856e+002,5.932722e-005,-1.288424e-002
1.000000e+003,3.214562e+002,5.923157e-005,-1.758796e-002
1.000000e+003,3.292777e+002,5.951595e-005,-2.175832e-002
1.000000e+003,3.373054e+002,5.972390e-005,-2.570753e-002
1.000000e+003,3.452681e+002,6.019395e-005,-3.084704e-002
1.000000e+003,3.532939e+002,6.141253e-005,-3.562900e-002
1.000000e+003,3.615509e+002,6.366323e-005,-4.164876e-002
1.000000e+003,3.692827e+002,1.286179e-004,-6.077555e-002
1.000000e+003,3.772851e+002,2.131678e-004,-8.672190e-002
1.000000e+003,3.852579e+002,2.096920e-004,-8.905657e-002
1.000000e+003,3.932976e+002,2.052463e-004,-9.129627e-002
9.000000e+002,4.000035e+002,1.809853e-004,-8.874309e-002
9.000000e+002,3.911956e+002,1.844463e-004,-8.185475e-002
9.000000e+002,3.836009e+002,1.882050e-004,-7.701109e-002
9.000000e+002,3.750272e+002,1.927037e-004,-7.533491e-002
9.000000e+002,3.659804e+002,1.962304e-004,-7.015117e-002
9.000000e+002,3.596407e+002,1.982308e-004,-6.962680e-002
9.000000e+002,3.505393e+002,2.008923e-004,-6.469790e-002
9.000000e+002,3.438152e+002,1.231817e-004,-6.115574e-002
9.000000e+002,3.348646e+002,5.435933e-005,-1.755708e-002
9.000000e+002,3.274522e+002,5.411545e-005,-1.281148e-002
9.000000e+002,3.194235e+002,5.400991e-005,-1.125012e-002
9.000000e+002,3.116490e+002,5.399459e-005,-7.240326e-003
9.000000e+002,3.035748e+002,5.414957e-005,-5.438183e-003
9.000000e+002,3.033514e+002,5.405182e-005,-7.303484e-003
9.000000e+002,3.112575e+002,5.369449e-005,-1.205694e-002
9.000000e+002,3.192452e+002,5.359536e-005,-1.651009e-002
9.000000e+002,3.272537e+002,5.376398e-005,-1.972357e-002
9.000000e+002,3.353284e+002,5.389314e-005,-2.465506e-002
9.000000e+002,3.432599e+002,5.422802e-005,-2.857310e-002
9.000000e+002,3.512582e+002,5.514573e-005,-3.469848e-002
9.000000e+002,3.592664e+002,5.676604e-005,-4.027226e-002
9.000000e+002,3.672563e+002,7.365954e-005,-4.864608e-002
9.000000e+002,3.752884e+002,1.924206e-004,-8.565830e-002
9.000000e+002,3.832557e+002,1.895479e-004,-8.804543e-002
9.000000e+002,3.913165e+002,1.858639e-004,-9.079777e-002
9.000000e+002,3.992444e+002,1.818723e-004,-9.206542e-002
8.000000e+002,3.934202e+002,1.630749e-004,-8.280793e-002
8.000000e+002,3.854233e+002,1.664438e-004,-7.797170e-002
8.000000e+002,3.775818e+002,1.701233e-004,-7.654221e-002
8.000000e+002,3.681534e+002,1.737816e-004,-7.129414e-002
8.000000e+002,3.618485e+002,1.757165e-004,-6.796877e-002
8.000000e+002,3.522870e+002,1.782717e-004,-6.542675e-002
8.000000e+002,3.449102e+002,1.371244e-004,-6.297307e-002
8.000000e+002,3.372466e+002,4.874259e-005,-1.870012e-002
8.000000e+002,3.286956e+002,4.839811e-005,-1.361330e-002
8.000000e+002,3.215303e+002,4.825422e-005,-1.175799e-002
8.000000e+002,3.134724e+002,4.827924e-005,-8.151195e-003
8.000000e+002,3.058118e+002,4.830279e-005,-6.823807e-003
8.000000e+002,3.012651e+002,4.842088e-005,-5.956410e-003
8.000000e+002,3.093783e+002,4.802542e-005,-1.101068e-002
8.000000e+002,3.173018e+002,4.785565e-005,-1.502013e-002
8.000000e+002,3.253233e+002,4.802108e-005,-1.907096e-002
8.000000e+002,3.332936e+002,4.806946e-005,-2.293061e-002
8.000000e+002,3.415561e+002,4.835667e-005,-2.775335e-002
8.000000e+002,3.493230e+002,4.906533e-005,-3.329421e-002
8.000000e+002,3.573351e+002,5.018355e-005,-3.802064e-002
8.000000e+002,3.652531e+002,5.388951e-005,-4.535406e-002
8.000000e+002,3.732405e+002,1.628041e-004,-8.152224e-002
8.000000e+002,3.815664e+002,1.692481e-004,-8.770782e-002
8.000000e+002,3.892515e+002,1.660632e-004,-9.004728e-002
8.000000e+002,3.972476e+002,1.624868e-004,-9.176670e-002
7.000000e+002,3.955884e+002,1.419697e-004,-8.433634e-002
7.000000e+002,3.870180e+002,1.450388e-004,-7.839400e-002
7.000000e+002,3.797235e+002,1.482684e-004,-7.786407e-002
7.000000e+002,3.701294e+002,1.514246e-004,-7.227186e-002
7.000000e+002,3.631927e+002,1.536046e-004,-6.856968e-002
7.000000e+002,3.549087e+002,1.554905e-004,-6.703073e-002
7.000000e+002,3.462047e+002,1.419212e-004,-6.320201e-002
7.000000e+002,3.395863e+002,4.310982e-005,-1.976690e-002
7.000000e+002,3.305165e+002,4.259879e-005,-1.413757e-002
7.000000e+002,3.238000e+002,4.245738e-005,-1.352046e-002
7.000000e+002,3.154526e+002,4.248837e-005,-8.292202e-003
7.000000e+002,3.079103e+002,4.246634e-005,-6.198653e-003
7.000000e+002,3.000782e+002,4.265068e-005,-5.117659e-003
7.000000e+002,3.072939e+002,4.233812e-005,-9.351331e-003
7.000000e+002,3.153145e+002,4.220191e-005,-1.406138e-002
7.000000e+002,3.233587e+002,4.219799e-005,-1.796454e-002
7.000000e+002,3.312717e+002,4.229969e-005,-2.257349e-002
7.000000e+002,3.392912e+002,4.252463e-005,-2.686815e-002
7.000000e+002,3.473158e+002,4.295427e-005,-3.129414e-002
7.000000e+002,3.553164e+002,4.381715e-005,-3.732127e-002
7.000000e+002,3.633070e+002,4.591922e-005,-4.327674e-002
7.000000e+002,3.712770e+002,1.248176e-004,-7.283580e-002
7.000000e+002,3.792866e+002,1.488389e-004,-8.650532e-002
7.000000e+002,3.872546e+002,1.461790e-004,-8.910622e-002
7.000000e+002,3.952998e+002,1.429403e-004,-9.098600e-002
6.000000e+002,3.977628e+002,1.209672e-004,-8.586992e-002
6.000000e+002,3.891412e+002,1.235617e-004,-7.997417e-002
6.000000e+002,3.817579e+002,1.258841e-004,-7.520287e-002
6.000000e+002,3.723235e+002,1.292656e-004,-7.295248e-002
6.000000e+002,3.644458e+002,1.312481e-004,-6.855749e-002
6.000000e+002,3.572660e+002,1.326737e-004,-6.773943e-002
6.000000e+002,3.485149e+002,1.336025e-004,-6.286389e-002
6.000000e+002,3.417593e+002,3.738611e-005,-2.158477e-002
6.000000e+002,3.327561e+002,3.685028e-005,-1.648434e-002
6.000000e+002,3.257957e+002,3.671704e-005,-1.159193e-002
6.000000e+002,3.174099e+002,3.667314e-005,-1.042624e-002
6.000000e+002,3.097648e+002,3.662859e-005,-7.204746e-003
6.000000e+002,3.015425e+002,3.675147e-005,-6.153972e-003
6.000000e+002,3.053109e+002,3.661323e-005,-8.459830e-003
6.000000e+002,3.132564e+002,3.639425e-005,-1.403767e-002
6.000000e+002,3.215116e+002,3.638645e-005,-1.809950e-002
6.000000e+002,3.293253e+002,3.649121e-005,-2.210193e-002
6.000000e+002,3.373031e+002,3.652347e-005,-2.606446e-002
6.000000e+002,3.453279e+002,3.689151e-005,-3.036791e-002
6.000000e+002,3.532387e+002,3.757612e-005,-3.627617e-002
6.000000e+002,3.616010e+002,3.899393e-005,-4.208654e-002
6.000000e+002,3.693158e+002,8.000950e-005,-6.220470e-002
6.000000e+002,3.773311e+002,1.279537e-004,-8.604828e-002
6.000000e+002,3.852308e+002,1.257657e-004,-8.826055e-002
6.000000e+002,3.932819e+002,1.231881e-004,-9.074941e-002
5.000000e+002,4.000099e+002,1.003304e-004,-8.673605e-002
5.000000e+002,3.912205e+002,1.022831e-004,-8.110470e-002
5.000000e+002,3.834669e+002,1.043398e-004,-7.669478e-002
5.000000e+002,3.750982e+002,1.069386e-004,-7.479319e-002
5.000000e+002,3.660182e+002,1.089645e-004,-6.969932e-002
5.000000e+002,3.596044e+002,1.100554e-004,-6.914689e-002
5.000000e+002,3.505985e+002,1.115037e-004,-6.409331e-002
5.000000e+002,3.437750e+002,6.914067e-005,-6.041990e-002
5.000000e+002,3.347527e+002,3.093637e-005,-1.832090e-002
5.000000e+002,3.276659e+002,3.079422e-005,-1.187958e-002
5.000000e+002,3.195187e+002,3.075842e-005,-1.177770e-002
5.000000e+002,3.116721e+002,3.076483e-005,-7.954583e-003
5.000000e+002,3.036165e+002,3.082022e-005,-5.874936e-003
5.000000e+002,3.033007e+002,3.076109e-005,-8.799825e-003
5.000000e+002,3.113054e+002,3.059270e-005,-1.170458e-002
5.000000e+002,3.193079e+002,3.051152e-005,-1.593618e-002
5.000000e+002,3.273156e+002,3.059369e-005,-2.069409e-002
5.000000e+002,3.352790e+002,3.071101e-005,-2.593254e-002
5.000000e+002,3.432434e+002,3.089996e-005,-3.001104e-002
5.000000e+002,3.512607e+002,3.140953e-005,-3.394467e-002
5.000000e+002,3.592664e+002,3.227096e-005,-4.001544e-002
5.000000e+002,3.673215e+002,4.274444e-005,-4.886517e-002
5.000000e+002,3.753026e+002,1.066764e-004,-8.497023e-002
5.000000e+002,3.833479e+002,1.051509e-004,-8.796516e-002
5.000000e+002,3.912513e+002,1.031144e-004,-9.014408e-002
5.000000e+002,3.992574e+002,1.009616e-004,-9.177588e-002
4.000000e+002,3.932288e+002,8.116556e-005,-8.189325e-002
4.000000e+002,3.850328e+002,8.291409e-005,-7.729610e-002
4.000000e+002,3.775414e+002,8.478602e-005,-7.600226e-002
4.000000e+002,3.681588e+002,8.661444e-005,-7.103717e-002
4.000000e+002,3.618274e+002,8.760033e-005,-6.802195e-002
4.000000e+002,3.524515e+002,8.884528e-005,-6.552608e-002
4.000000e+002,3.448626e+002,6.897090e-005,-6.301749e-002
4.000000e+002,3.371467e+002,2.514550e-005,-2.039395e-002
4.000000e+002,3.287732e+002,2.491129e-005,-1.514208e-002
4.000000e+002,3.215384e+002,2.484733e-005,-1.204496e-002
4.000000e+002,3.135541e+002,2.485737e-005,-1.089571e-002
4.000000e+002,3.058026e+002,2.486010e-005,-6.560069e-003
4.000000e+002,3.012186e+002,2.494951e-005,-7.479464e-003
4.000000e+002,3.093103e+002,2.474081e-005,-1.117152e-002
4.000000e+002,3.173458e+002,2.469238e-005,-1.709109e-002
4.000000e+002,3.252538e+002,2.472663e-005,-2.136311e-002
4.000000e+002,3.333091e+002,2.476895e-005,-2.343977e-002
4.000000e+002,3.415304e+002,2.491063e-005,-3.330868e-002
4.000000e+002,3.493328e+002,2.524937e-005,-3.506769e-002
4.000000e+002,3.572940e+002,2.579203e-005,-3.923465e-002
4.000000e+002,3.652504e+002,2.756223e-005,-4.477279e-002
4.000000e+002,3.735051e+002,8.207992e-005,-8.459163e-002
4.000000e+002,3.815723e+002,8.434016e-005,-8.810602e-002
4.000000e+002,3.892791e+002,8.289650e-005,-9.056886e-002
4.000000e+002,3.973563e+002,8.101553e-005,-9.246255e-002
3.000000e+002,3.955695e+002,6.020027e-005,-8.421150e-002
3.000000e+002,3.870575e+002,6.148012e-005,-7.874575e-002
3.000000e+002,3.796651e+002,6.307056e-005,-7.870065e-002
3.000000e+002,3.700410e+002,6.450986e-005,-7.234801e-002
3.000000e+002,3.630494e+002,6.532177e-005,-6.842435e-002
3.000000e+002,3.550783e+002,6.612265e-005,-6.808311e-002
3.000000e+002,3.467003e+002,6.323877e-005,-6.353138e-002
3.000000e+002,3.394825e+002,1.915731e-005,-2.422141e-002
3.000000e+002,3.304730e+002,1.893433e-005,-1.644216e-002
3.000000e+002,3.238834e+002,1.887384e-005,-1.437889e-002
3.000000e+002,3.154645e+002,1.885275e-005,-1.202832e-002
3.000000e+002,3.078673e+002,1.888433e-005,-8.933532e-003
3.000000e+002,3.000959e+002,1.895974e-005,-8.191245e-003
3.000000e+002,3.073032e+002,1.881916e-005,-1.340050e-002
3.000000e+002,3.152495e+002,1.878818e-005,-1.910087e-002
3.000000e+002,3.232673e+002,1.874124e-005,-2.198040e-002
3.000000e+002,3.312651e+002,1.878949e-005,-2.682390e-002
3.000000e+002,3.393050e+002,1.888794e-005,-2.843888e-002
3.000000e+002,3.472698e+002,1.905627e-005,-3.398800e-002
3.000000e+002,3.553138e+002,1.940825e-005,-3.750803e-002
3.000000e+002,3.632485e+002,2.023662e-005,-4.368465e-002
3.000000e+002,3.712549e+002,5.294830e-005,-7.383309e-002
3.000000e+002,3.792518e+002,6.341332e-005,-8.749662e-002
3.000000e+002,3.872698e+002,6.224036e-005,-8.970498e-002
3.000000e+002,3.953188e+002,6.092757e-005,-9.203190e-002
2.000000e+002,3.976954e+002,3.926240e-005,-8.656627e-002
2.000000e+002,3.890339e+002,4.025142e-005,-8.164510e-002
2.000000e+002,3.817609e+002,4.106078e-005,-7.722460e-002
2.000000e+002,3.726848e+002,4.215672e-005,-7.467437e-002
2.000000e+002,3.644110e+002,4.284219e-005,-7.013149e-002
2.000000e+002,3.573405e+002,4.330806e-005,-6.915772e-002
2.000000e+002,3.481305e+002,4.348592e-005,-6.360818e-002
2.000000e+002,3.417850e+002,1.295353e-005,-2.728878e-002
2.000000e+002,3.328512e+002,1.279462e-005,-2.208278e-002
2.000000e+002,3.257766e+002,1.276083e-005,-1.918178e-002
2.000000e+002,3.173980e+002,1.272376e-005,-1.569768e-002
2.000000e+002,3.097173e+002,1.275797e-005,-1.148007e-002
2.000000e+002,3.014745e+002,1.278947e-005,-9.963106e-003
2.000000e+002,3.053366e+002,1.280391e-005,-1.480373e-002
2.000000e+002,3.132836e+002,1.266610e-005,-1.997431e-002
2.000000e+002,3.214952e+002,1.266020e-005,-2.509606e-002
2.000000e+002,3.292907e+002,1.273027e-005,-2.261746e-002
2.000000e+002,3.372986e+002,1.267699e-005,-3.164798e-002
2.000000e+002,3.452992e+002,1.280095e-005,-3.627330e-002
2.000000e+002,3.533214e+002,1.304472e-005,-4.087073e-002
2.000000e+002,3.615983e+002,1.343406e-005,-4.735292e-002
2.000000e+002,3.693460e+002,2.699286e-005,-6.401731e-002
2.000000e+002,3.772592e+002,4.188944e-005,-8.679350e-002
2.000000e+002,3.852519e+002,4.117710e-005,-8.877976e-002
2.000000e+002,3.932474e+002,4.022343e-005,-8.727130e-002
1.000000e+002,4.000035e+002,1.859250e-005,-8.977510e-002
1.000000e+002,3.914470e+002,1.900667e-005,-8.396679e-002
1.000000e+002,3.836575e+002,1.949462e-005,-7.965510e-002
1.000000e+002,3.751209e+002,2.010736e-005,-7.708511e-002
1.000000e+002,3.662722e+002,2.046625e-005,-7.345511e-002
1.000000e+002,3.596226e+002,2.082501e-005,-7.278001e-002
1.000000e+002,3.504875e+002,2.103562e-005,-6.683329e-002
1.000000e+002,3.438460e+002,1.353222e-005,-6.336857e-002
1.000000e+002,3.347593e+002,6.577999e-006,-2.979244e-002
1.000000e+002,3.276380e+002,6.599293e-006,-2.423313e-002
1.000000e+002,3.193507e+002,6.524792e-006,-2.129913e-002
1.000000e+002,3.115857e+002,6.617584e-006,-2.291436e-002
1.000000e+002,3.036638e+002,6.583005e-006,-2.030559e-002
1.000000e+002,3.032808e+002,6.610692e-006,-2.093635e-002
1.000000e+002,3.112518e+002,6.543933e-006,-2.257981e-002
1.000000e+002,3.192593e+002,6.542429e-006,-2.812445e-002
1.000000e+002,3.272729e+002,6.532765e-006,-3.141223e-002
1.000000e+002,3.353419e+002,6.529242e-006,-3.927850e-002
1.000000e+002,3.433024e+002,6.564999e-006,-4.351852e-002
1.000000e+002,3.512830e+002,6.666816e-006,-5.230007e-002
1.000000e+002,3.592326e+002,6.822908e-006,-5.056879e-002
1.000000e+002,3.672699e+002,8.663241e-006,-5.507993e-002
1.000000e+002,3.752571e+002,2.014227e-005,-8.773150e-002
1.000000e+002,3.832706e+002,1.994718e-005,-8.910164e-002
1.000000e+002,3.912482e+002,1.951947e-005,-9.073999e-002
1.000000e+002,3.992671e+002,1.910054e-005,-9.318406e-002
0.000000e+000,3.934296e+002,-2.223592e-006,-7.065693e-002
0.000000e+000,3.853302e+002,-2.225806e-006,-6.052234e-002
0.000000e+000,3.773659e+002,-2.035457e-006,-4.594009e-002
0.000000e+000,3.680331e+002,-2.051676e-006,-6.065741e-002
0.000000e+000,3.618353e+002,-2.087315e-006,-1.195149e-002
0.000000e+000,3.524514e+002,-2.064058e-006,-4.354557e-002
0.000000e+000,3.448936e+002,-1.415970e-006,-4.909658e-002
0.000000e+000,3.372852e+002,1.905864e-007,-6.992610e-001
0.000000e+000,3.288485e+002,2.058941e-007,-7.460411e-001
0.000000e+000,3.215651e+002,2.000516e-007,-7.135183e-001
0.000000e+000,3.135930e+002,2.145053e-007,-7.381482e-001
0.000000e+000,3.057177e+002,1.820897e-007,-7.310147e-001
0.000000e+000,3.012615e+002,1.411456e-007,-3.272689e-001
0.000000e+000,3.093424e+002,1.002751e-007,-3.883053e-001
0.000000e+000,3.173138e+002,1.838784e-007,-7.891423e-001
0.000000e+000,3.253254e+002,1.811100e-007,-7.331259e-001
0.000000e+000,3.332980e+002,2.162099e-007,-7.677439e-001
0.000000e+000,3.415094e+002,1.920605e-007,-7.286542e-001
0.000000e+000,3.492741e+002,1.349645e-007,-3.988874e-001
0.000000e+000,3.572658e+002,1.047288e-007,-4.390430e-001
0.000000e+000,3.652798e+002,-1.264412e-007,9.497970e-001
0.000000e+000,3.732546e+002,-1.757548e-006,-5.211089e-002
0.000000e+000,3.815340e+002,-1.894205e-006,-8.036394e-002
0.000000e+000,3.892546e+002,-1.825236e-006,-8.508968e-002
0.000000e+000,3.972731e+002,-1.796044e-006,-7.245048e-002
0.000000e+000,3.999841e+002,-1.741987e-006,-6.337081e-002