File: spin_crossover/dane/FeTrz_Trt_big_FC_FH.rso.csv
Field (Oe),Temperature (K),Long Moment (emu),Long Offset (cm)
1.000000e+003,2.999981e+002,4.101315e-005,-3.205599e-002
1.000000e+003,3.011147e+002,4.093155e-005,-3.003811e-002
1.000000e+003,3.021215e+002,4.091299e-005,-3.168267e-002
1.000000e+003,3.031356e+002,4.084411e-005,-3.302720e-002
1.000000e+003,3.041205e+002,4.077659e-005,-3.193814e-002
1.000000e+003,3.051270e+002,4.066811e-005,-3.200895e-002
1.000000e+003,3.061481e+002,4.064581e-005,-3.283670e-002
1.000000e+003,3.071169e+002,4.059679e-005,-3.273994e-002
1.000000e+003,3.081636e+002,4.055700e-005,-3.403375e-002
1.000000e+003,3.091462e+002,4.050819e-005,-3.262889e-002
1.000000e+003,3.101545e+002,4.047290e-005,-3.448205e-002
1.000000e+003,3.111431e+002,4.042481e-005,-3.507658e-002
1.000000e+003,3.121269e+002,4.037292e-005,-3.503314e-002
1.000000e+003,3.131289e+002,4.030552e-005,-3.637759e-002
1.000000e+003,3.141301e+002,4.023235e-005,-3.458720e-002
1.000000e+003,3.151500e+002,4.022716e-005,-3.575502e-002
1.000000e+003,3.161294e+002,4.023372e-005,-3.598487e-002
1.000000e+003,3.171073e+002,4.016364e-005,-3.772336e-002
1.000000e+003,3.181439e+002,4.008673e-005,-3.727152e-002
1.000000e+003,3.191271e+002,4.006012e-005,-3.822655e-002
1.000000e+003,3.201575e+002,4.005353e-005,-3.848244e-002
1.000000e+003,3.211418e+002,4.002701e-005,-3.938840e-002
1.000000e+003,3.221407e+002,4.002858e-005,-3.769669e-002
1.000000e+003,3.231048e+002,3.998155e-005,-3.999852e-002
1.000000e+003,3.241169e+002,3.996372e-005,-4.009020e-002
1.000000e+003,3.251315e+002,3.992651e-005,-3.982967e-002
1.000000e+003,3.261232e+002,3.992916e-005,-4.078247e-002
1.000000e+003,3.271256e+002,3.989700e-005,-4.056136e-002
1.000000e+003,3.281368e+002,3.989039e-005,-4.123730e-002
1.000000e+003,3.291396e+002,3.987555e-005,-4.189973e-002
1.000000e+003,3.301444e+002,3.985775e-005,-4.367446e-002
1.000000e+003,3.311252e+002,3.981205e-005,-4.444189e-002
1.000000e+003,3.321387e+002,3.987226e-005,-4.277674e-002
1.000000e+003,3.331255e+002,3.986853e-005,-4.387791e-002
1.000000e+003,3.341521e+002,3.983615e-005,-4.364900e-002
1.000000e+003,3.351472e+002,3.985464e-005,-4.523616e-002
1.000000e+003,3.361145e+002,3.986194e-005,-4.492543e-002
1.000000e+003,3.371425e+002,3.986169e-005,-4.570105e-002
1.000000e+003,3.381405e+002,3.987920e-005,-4.572812e-002
1.000000e+003,3.391448e+002,3.988617e-005,-4.664918e-002
1.000000e+003,3.401276e+002,3.988721e-005,-4.698804e-002
1.000000e+003,3.411235e+002,3.987624e-005,-4.777445e-002
1.000000e+003,3.421372e+002,3.991603e-005,-4.751151e-002
1.000000e+003,3.431267e+002,3.995457e-005,-5.029882e-002
1.000000e+003,3.441199e+002,3.994208e-005,-4.988448e-002
1.000000e+003,3.451382e+002,3.999766e-005,-4.959769e-002
1.000000e+003,3.461100e+002,3.999488e-005,-5.119685e-002
1.000000e+003,3.471119e+002,4.004225e-005,-5.110914e-002
1.000000e+003,3.481418e+002,4.002891e-005,-5.149721e-002
1.000000e+003,3.491095e+002,4.006873e-005,-5.231428e-002
1.000000e+003,3.501371e+002,4.011051e-005,-5.289973e-002
1.000000e+003,3.511191e+002,4.012492e-005,-5.234473e-002
1.000000e+003,3.521343e+002,4.020156e-005,-5.411532e-002
1.000000e+003,3.531231e+002,4.022209e-005,-5.437491e-002
1.000000e+003,3.541229e+002,4.024429e-005,-5.418415e-002
1.000000e+003,3.551590e+002,4.031177e-005,-5.504605e-002
1.000000e+003,3.561173e+002,4.035805e-005,-5.642107e-002
1.000000e+003,3.571452e+002,4.044289e-005,-5.793481e-002
1.000000e+003,3.581252e+002,4.046123e-005,-5.778164e-002
1.000000e+003,3.591186e+002,4.056327e-005,-5.790228e-002
1.000000e+003,3.601361e+002,4.060009e-005,-5.870183e-002
1.000000e+003,3.611229e+002,4.064156e-005,-5.842948e-002
1.000000e+003,3.621286e+002,4.072380e-005,-6.062715e-002
1.000000e+003,3.631242e+002,4.078312e-005,-5.978842e-002
1.000000e+003,3.641016e+002,4.083761e-005,-6.001250e-002
1.000000e+003,3.651274e+002,4.092840e-005,-6.106286e-002
1.000000e+003,3.661296e+002,4.098412e-005,-6.179979e-002
1.000000e+003,3.671620e+002,4.110593e-005,-6.293793e-002
1.000000e+003,3.681377e+002,4.110545e-005,-6.191441e-002
1.000000e+003,3.691545e+002,4.125742e-005,-6.377164e-002
1.000000e+003,3.701330e+002,4.131994e-005,-6.561568e-002
1.000000e+003,3.711309e+002,4.146847e-005,-6.579483e-002
1.000000e+003,3.721232e+002,4.149873e-005,-6.606656e-002
1.000000e+003,3.731238e+002,4.159316e-005,-6.628292e-002
1.000000e+003,3.741471e+002,4.179719e-005,-6.736410e-002
1.000000e+003,3.751194e+002,4.193800e-005,-6.841567e-002
1.000000e+003,3.761256e+002,4.210005e-005,-6.822734e-002
1.000000e+003,3.771575e+002,4.253841e-005,-7.108939e-002
1.000000e+003,3.781202e+002,4.319145e-005,-7.382332e-002
1.000000e+003,3.791229e+002,4.433468e-005,-7.593451e-002
1.000000e+003,3.801429e+002,4.650901e-005,-8.296243e-002
1.000000e+003,3.811391e+002,5.030441e-005,-9.188644e-002
1.000000e+003,3.821468e+002,5.580713e-005,-1.021294e-001
1.000000e+003,3.831095e+002,6.176182e-005,-1.117891e-001
1.000000e+003,3.841191e+002,6.785206e-005,-1.192748e-001
1.000000e+003,3.851403e+002,7.388026e-005,-1.247209e-001
1.000000e+003,3.861429e+002,8.015551e-005,-1.299560e-001
1.000000e+003,3.872787e+002,8.919445e-005,-1.360876e-001
1.000000e+003,3.881281e+002,9.704049e-005,-1.405986e-001
1.000000e+003,3.891379e+002,1.056973e-004,-1.451923e-001
1.000000e+003,3.901006e+002,1.117189e-004,-1.484118e-001
1.000000e+003,3.911024e+002,1.157185e-004,-1.494590e-001
1.000000e+003,3.921470e+002,1.185422e-004,-1.503490e-001
1.000000e+003,3.931285e+002,1.205241e-004,-1.506865e-001
1.000000e+003,3.941025e+002,1.219782e-004,-1.511425e-001
1.000000e+003,3.951450e+002,1.219791e-004,-1.501482e-001
1.000000e+003,3.961098e+002,1.218548e-004,-1.488337e-001
1.000000e+003,3.971139e+002,1.228169e-004,-1.488825e-001
1.000000e+003,3.981353e+002,1.235929e-004,-1.492989e-001
1.000000e+003,3.991162e+002,1.242424e-004,-1.494370e-001
1.000000e+003,3.999784e+002,1.258413e-004,-1.471178e-001
1.000000e+003,4.000108e+002,1.263256e-004,-1.462265e-001
1.000000e+003,3.988747e+002,1.264019e-004,-1.450250e-001
1.000000e+003,3.978339e+002,1.265128e-004,-1.440426e-001
1.000000e+003,3.967914e+002,1.267070e-004,-1.433845e-001
1.000000e+003,3.956999e+002,1.269357e-004,-1.429855e-001
1.000000e+003,3.947242e+002,1.270423e-004,-1.420077e-001
1.000000e+003,3.936935e+002,1.272143e-004,-1.409801e-001
1.000000e+003,3.927310e+002,1.273911e-004,-1.400083e-001
1.000000e+003,3.918013e+002,1.275103e-004,-1.399410e-001
1.000000e+003,3.908020e+002,1.275759e-004,-1.394804e-001
1.000000e+003,3.898942e+002,1.276461e-004,-1.393110e-001
1.000000e+003,3.889263e+002,1.273498e-004,-1.389732e-001
1.000000e+003,3.878781e+002,1.275474e-004,-1.387263e-001
1.000000e+003,3.868145e+002,1.277448e-004,-1.377195e-001
1.000000e+003,3.858051e+002,1.279420e-004,-1.375712e-001
1.000000e+003,3.848253e+002,1.281484e-004,-1.367624e-001
1.000000e+003,3.838595e+002,1.283863e-004,-1.361971e-001
1.000000e+003,3.828869e+002,1.284038e-004,-1.358072e-001
1.000000e+003,3.819018e+002,1.285060e-004,-1.352070e-001
1.000000e+003,3.808837e+002,1.287883e-004,-1.348277e-001
1.000000e+003,3.798917e+002,1.289964e-004,-1.341275e-001
1.000000e+003,3.788848e+002,1.291409e-004,-1.341555e-001
1.000000e+003,3.778516e+002,1.292299e-004,-1.333849e-001
1.000000e+003,3.768932e+002,1.293363e-004,-1.328318e-001
1.000000e+003,3.758914e+002,1.293862e-004,-1.329249e-001
1.000000e+003,3.748808e+002,1.292855e-004,-1.319307e-001
1.000000e+003,3.738674e+002,1.292509e-004,-1.314178e-001
1.000000e+003,3.728795e+002,1.291751e-004,-1.309491e-001
1.000000e+003,3.718774e+002,1.292638e-004,-1.307491e-001
1.000000e+003,3.708698e+002,1.292734e-004,-1.303239e-001
1.000000e+003,3.698983e+002,1.292831e-004,-1.298182e-001
1.000000e+003,3.688744e+002,1.292183e-004,-1.298706e-001
1.000000e+003,3.678919e+002,1.292015e-004,-1.293351e-001
1.000000e+003,3.668660e+002,1.290212e-004,-1.293027e-001
1.000000e+003,3.658839e+002,1.288577e-004,-1.287006e-001
1.000000e+003,3.648643e+002,1.285784e-004,-1.289262e-001
1.000000e+003,3.638640e+002,1.282321e-004,-1.284231e-001
1.000000e+003,3.628801e+002,1.278038e-004,-1.283633e-001
1.000000e+003,3.618832e+002,1.272351e-004,-1.280030e-001
1.000000e+003,3.608737e+002,1.264848e-004,-1.277233e-001
1.000000e+003,3.598779e+002,1.255146e-004,-1.271844e-001
1.000000e+003,3.588775e+002,1.242116e-004,-1.276868e-001
1.000000e+003,3.578520e+002,1.224349e-004,-1.277003e-001
1.000000e+003,3.568710e+002,1.196311e-004,-1.276756e-001
1.000000e+003,3.558702e+002,1.147532e-004,-1.283668e-001
1.000000e+003,3.548804e+002,1.089542e-004,-1.295730e-001
1.000000e+003,3.538762e+002,1.039494e-004,-1.296011e-001
1.000000e+003,3.528929e+002,9.197379e-005,-1.256359e-001
1.000000e+003,3.518632e+002,5.873793e-005,-9.805298e-002
1.000000e+003,3.508546e+002,4.337506e-005,-4.720460e-002
1.000000e+003,3.498422e+002,4.221252e-005,-4.315256e-002
1.000000e+003,3.488872e+002,4.172419e-005,-4.296578e-002
1.000000e+003,3.478843e+002,4.145711e-005,-4.004194e-002
1.000000e+003,3.468657e+002,4.129896e-005,-4.069121e-002
1.000000e+003,3.458893e+002,4.118451e-005,-4.025244e-002
1.000000e+003,3.448544e+002,4.111108e-005,-4.032641e-002
1.000000e+003,3.438805e+002,4.102111e-005,-3.815734e-002
1.000000e+003,3.428888e+002,4.091538e-005,-3.843933e-002
1.000000e+003,3.418820e+002,4.093209e-005,-3.890833e-002
1.000000e+003,3.408885e+002,4.086456e-005,-3.680255e-002
1.000000e+003,3.398779e+002,4.083652e-005,-3.659260e-002
1.000000e+003,3.388736e+002,4.083750e-005,-3.597925e-002
1.000000e+003,3.378961e+002,4.081990e-005,-3.636622e-002
1.000000e+003,3.368655e+002,4.082626e-005,-3.554011e-002
1.000000e+003,3.358935e+002,4.079716e-005,-3.572419e-002
1.000000e+003,3.348894e+002,4.081850e-005,-3.418437e-002
1.000000e+003,3.338536e+002,4.080899e-005,-3.306639e-002
1.000000e+003,3.328932e+002,4.079952e-005,-3.227291e-002
1.000000e+003,3.318661e+002,4.086798e-005,-3.287498e-002
1.000000e+003,3.308522e+002,4.082160e-005,-3.266720e-002
1.000000e+003,3.298926e+002,4.084632e-005,-3.185161e-002
1.000000e+003,3.288807e+002,4.084755e-005,-3.150562e-002
1.000000e+003,3.278690e+002,4.089180e-005,-3.125303e-002
1.000000e+003,3.268850e+002,4.084400e-005,-3.123522e-002
1.000000e+003,3.258820e+002,4.085114e-005,-2.807670e-002
1.000000e+003,3.248667e+002,4.092404e-005,-3.095654e-002
1.000000e+003,3.238935e+002,4.096646e-005,-2.930713e-002
1.000000e+003,3.228788e+002,4.095471e-005,-2.994989e-002
1.000000e+003,3.218502e+002,4.097501e-005,-3.017702e-002
1.000000e+003,3.208531e+002,4.104171e-005,-2.857980e-002
1.000000e+003,3.198992e+002,4.109041e-005,-2.902340e-002
1.000000e+003,3.188343e+002,4.106886e-005,-2.859345e-002
1.000000e+003,3.178750e+002,4.111863e-005,-2.821793e-002
1.000000e+003,3.168900e+002,4.112193e-005,-2.786891e-002
1.000000e+003,3.158601e+002,4.116442e-005,-2.755101e-002
1.000000e+003,3.148688e+002,4.121581e-005,-2.669365e-002
1.000000e+003,3.138645e+002,4.124870e-005,-2.698953e-002
1.000000e+003,3.128748e+002,4.129055e-005,-2.594178e-002
1.000000e+003,3.118765e+002,4.135969e-005,-2.675293e-002
1.000000e+003,3.108829e+002,4.138811e-005,-2.588507e-002
1.000000e+003,3.098638e+002,4.146550e-005,-2.830271e-002
1.000000e+003,3.088820e+002,4.145165e-005,-2.316879e-002
1.000000e+003,3.078694e+002,4.150982e-005,-2.528518e-002
1.000000e+003,3.068602e+002,4.156093e-005,-2.446317e-002
1.000000e+003,3.058488e+002,4.160493e-005,-2.463411e-002
1.000000e+003,3.048775e+002,4.164374e-005,-2.327478e-002
1.000000e+003,3.038436e+002,4.173047e-005,-2.411000e-002
1.000000e+003,3.029022e+002,4.175986e-005,-2.333735e-002
1.000000e+003,3.018934e+002,4.180860e-005,-2.355955e-002
1.000000e+003,3.008721e+002,4.189750e-005,-2.235615e-002
1.000000e+003,3.000034e+002,4.192663e-005,-2.406930e-002
1.000000e+003,3.000212e+002,4.189515e-005,-2.315620e-002
1.000000e+003,3.011237e+002,4.182151e-005,-2.429440e-002
1.000000e+003,3.021378e+002,4.175097e-005,-2.470936e-002
1.000000e+003,3.031719e+002,4.170353e-005,-2.588035e-002
1.000000e+003,3.041351e+002,4.162692e-005,-2.602958e-002
1.000000e+003,3.051454e+002,4.157201e-005,-2.688362e-002
1.000000e+003,3.061666e+002,4.155739e-005,-2.745165e-002
1.000000e+003,3.071188e+002,4.148014e-005,-2.773898e-002
1.000000e+003,3.081355e+002,4.143672e-005,-2.892069e-002
1.000000e+003,3.091236e+002,4.135876e-005,-2.959337e-002
1.000000e+003,3.101488e+002,4.128412e-005,-2.852295e-002
1.000000e+003,3.111278e+002,4.124050e-005,-2.885512e-002
1.000000e+003,3.121133e+002,4.122064e-005,-2.885856e-002
1.000000e+003,3.131270e+002,4.117707e-005,-3.008126e-002
1.000000e+003,3.141145e+002,4.108790e-005,-3.177134e-002
1.000000e+003,3.151165e+002,4.105056e-005,-3.145992e-002
1.000000e+003,3.161373e+002,4.104593e-005,-3.087278e-002
1.000000e+003,3.171033e+002,4.096894e-005,-3.217617e-002
1.000000e+003,3.181238e+002,4.089256e-005,-3.211883e-002
1.000000e+003,3.191352e+002,4.087820e-005,-3.330650e-002
1.000000e+003,3.201208e+002,4.083778e-005,-3.311762e-002
1.000000e+003,3.211152e+002,4.079311e-005,-3.452669e-002
1.000000e+003,3.221654e+002,4.076410e-005,-3.513680e-002
1.000000e+003,3.231173e+002,4.072774e-005,-3.325686e-002
1.000000e+003,3.241190e+002,4.069166e-005,-3.521784e-002
1.000000e+003,3.251315e+002,4.064717e-005,-3.476041e-002
1.000000e+003,3.261190e+002,4.066163e-005,-3.624072e-002
1.000000e+003,3.271512e+002,4.060478e-005,-3.653094e-002
1.000000e+003,3.281325e+002,4.058504e-005,-3.651526e-002
1.000000e+003,3.291374e+002,4.054410e-005,-3.739967e-002
1.000000e+003,3.301271e+002,4.050625e-005,-3.723904e-002
1.000000e+003,3.311252e+002,4.052524e-005,-3.936327e-002
1.000000e+003,3.321212e+002,4.050474e-005,-3.890151e-002
1.000000e+003,3.331367e+002,4.045745e-005,-3.818049e-002
1.000000e+003,3.341410e+002,4.043531e-005,-3.914554e-002
1.000000e+003,3.351180e+002,4.045152e-005,-3.992299e-002
1.000000e+003,3.361077e+002,4.039063e-005,-3.963984e-002
1.000000e+003,3.371402e+002,4.044596e-005,-4.256297e-002
1.000000e+003,3.381542e+002,4.041048e-005,-4.116724e-002
1.000000e+003,3.391218e+002,4.040823e-005,-4.197443e-002
1.000000e+003,3.401484e+002,4.038148e-005,-4.233773e-002
1.000000e+003,3.411328e+002,4.038726e-005,-4.146667e-002
1.000000e+003,3.421232e+002,4.036766e-005,-4.351047e-002
1.000000e+003,3.431408e+002,4.038400e-005,-4.335919e-002
1.000000e+003,3.441175e+002,4.034823e-005,-4.424248e-002
1.000000e+003,3.451358e+002,4.036972e-005,-4.487834e-002
1.000000e+003,3.461221e+002,4.040026e-005,-4.553246e-002
1.000000e+003,3.471216e+002,4.038049e-005,-4.687888e-002
1.000000e+003,3.481418e+002,4.039327e-005,-4.645133e-002
1.000000e+003,3.491217e+002,4.044597e-005,-4.874586e-002
1.000000e+003,3.501076e+002,4.042867e-005,-4.830572e-002
1.000000e+003,3.511488e+002,4.041404e-005,-4.942650e-002
1.000000e+003,3.521119e+002,4.045411e-005,-4.922425e-002
1.000000e+003,3.531482e+002,4.049868e-005,-4.936294e-002
1.000000e+003,3.541229e+002,4.051690e-005,-5.016540e-002
1.000000e+003,3.551843e+002,4.053242e-005,-5.021696e-002
1.000000e+003,3.561148e+002,4.058880e-005,-5.109019e-002
1.000000e+003,3.571094e+002,4.061680e-005,-5.185262e-002
1.000000e+003,3.581303e+002,4.067819e-005,-5.244681e-002
1.000000e+003,3.591290e+002,4.072414e-005,-5.241930e-002
1.000000e+003,3.601309e+002,4.077539e-005,-5.358289e-002
1.000000e+003,3.611203e+002,4.078285e-005,-5.382374e-002
1.000000e+003,3.621259e+002,4.085239e-005,-5.487827e-002
1.000000e+003,3.631375e+002,4.090118e-005,-5.519614e-002
1.000000e+003,3.641123e+002,4.097187e-005,-5.615001e-002
1.000000e+003,3.651596e+002,4.103850e-005,-5.633867e-002
1.000000e+003,3.661350e+002,4.114111e-005,-5.798432e-002
1.000000e+003,3.671267e+002,4.123452e-005,-5.861094e-002
1.000000e+003,3.681240e+002,4.138007e-005,-5.828445e-002
1.000000e+003,3.690996e+002,4.141538e-005,-5.942333e-002
1.000000e+003,3.701386e+002,4.167834e-005,-6.008818e-002
1.000000e+003,3.710975e+002,4.199039e-005,-6.161881e-002
1.000000e+003,3.721567e+002,4.269581e-005,-6.376034e-002
1.000000e+003,3.731351e+002,4.467164e-005,-6.920126e-002
1.000000e+003,3.741273e+002,5.615526e-005,-8.954238e-002
1.000000e+003,3.751194e+002,8.488859e-005,-1.186084e-001
1.000000e+003,3.761227e+002,1.083997e-004,-1.366858e-001
1.000000e+003,3.771690e+002,1.155503e-004,-1.394922e-001
1.000000e+003,3.781491e+002,1.182201e-004,-1.396370e-001
1.000000e+003,3.791112e+002,1.200382e-004,-1.398816e-001
1.000000e+003,3.801399e+002,1.214891e-004,-1.403040e-001
1.000000e+003,3.811098e+002,1.225965e-004,-1.403647e-001
1.000000e+003,3.821232e+002,1.235031e-004,-1.408123e-001
1.000000e+003,3.831452e+002,1.242187e-004,-1.408160e-001
1.000000e+003,3.841580e+002,1.247524e-004,-1.408591e-001
1.000000e+003,3.851102e+002,1.253010e-004,-1.413766e-001
1.000000e+003,3.861460e+002,1.256881e-004,-1.414469e-001
1.000000e+003,3.871025e+002,1.259998e-004,-1.412843e-001
1.000000e+003,3.881555e+002,1.261890e-004,-1.419376e-001
1.000000e+003,3.891164e+002,1.258989e-004,-1.422269e-001
1.000000e+003,3.901222e+002,1.259029e-004,-1.425167e-001
1.000000e+003,3.911396e+002,1.259975e-004,-1.423017e-001
1.000000e+003,3.921284e+002,1.260480e-004,-1.425588e-001
1.000000e+003,3.931348e+002,1.260096e-004,-1.422909e-001
1.000000e+003,3.940931e+002,1.260299e-004,-1.429804e-001
1.000000e+003,3.951450e+002,1.260304e-004,-1.433182e-001
1.000000e+003,3.961130e+002,1.260257e-004,-1.432355e-001
1.000000e+003,3.971522e+002,1.259735e-004,-1.435568e-001
1.000000e+003,3.981417e+002,1.259285e-004,-1.434903e-001
1.000000e+003,3.991195e+002,1.259527e-004,-1.438286e-001
1.000000e+003,3.999816e+002,1.262000e-004,-1.423909e-001
1.000000e+003,4.000043e+002,1.263603e-004,-1.414492e-001
1.000000e+003,3.988650e+002,1.264336e-004,-1.400033e-001
1.000000e+003,3.978467e+002,1.265256e-004,-1.392650e-001
1.000000e+003,3.967819e+002,1.266933e-004,-1.381422e-001
1.000000e+003,3.957126e+002,1.269095e-004,-1.377544e-001
1.000000e+003,3.947431e+002,1.270381e-004,-1.367164e-001
1.000000e+003,3.937030e+002,1.272973e-004,-1.363703e-001
1.000000e+003,3.927560e+002,1.274739e-004,-1.359993e-001
1.000000e+003,3.917733e+002,1.275792e-004,-1.351026e-001
1.000000e+003,3.908237e+002,1.276533e-004,-1.348766e-001
1.000000e+003,3.899311e+002,1.277456e-004,-1.342753e-001
1.000000e+003,3.888802e+002,1.275431e-004,-1.345403e-001
1.000000e+003,3.878689e+002,1.277147e-004,-1.342055e-001
1.000000e+003,3.867781e+002,1.279544e-004,-1.335392e-001
1.000000e+003,3.858202e+002,1.280636e-004,-1.325697e-001
1.000000e+003,3.848283e+002,1.283279e-004,-1.321087e-001
1.000000e+003,3.838715e+002,1.284511e-004,-1.318731e-001
1.000000e+003,3.828839e+002,1.286417e-004,-1.312568e-001
1.000000e+003,3.818988e+002,1.289012e-004,-1.310132e-001
1.000000e+003,3.808925e+002,1.291084e-004,-1.303529e-001
1.000000e+003,3.798800e+002,1.292874e-004,-1.296863e-001
1.000000e+003,3.788731e+002,1.293716e-004,-1.293821e-001
1.000000e+003,3.778603e+002,1.295127e-004,-1.286158e-001
1.000000e+003,3.768731e+002,1.296083e-004,-1.283115e-001
1.000000e+003,3.758771e+002,1.296034e-004,-1.277446e-001
1.000000e+003,3.749006e+002,1.295990e-004,-1.275055e-001
1.000000e+003,3.738506e+002,1.295417e-004,-1.273116e-001
1.000000e+003,3.728655e+002,1.296602e-004,-1.267746e-001
1.000000e+003,3.718774e+002,1.296950e-004,-1.265317e-001
1.000000e+003,3.708560e+002,1.297420e-004,-1.259027e-001
1.000000e+003,3.698762e+002,1.297970e-004,-1.257332e-001
1.000000e+003,3.688881e+002,1.298537e-004,-1.256317e-001
1.000000e+003,3.678810e+002,1.297969e-004,-1.251938e-001
1.000000e+003,3.668823e+002,1.298065e-004,-1.250537e-001
1.000000e+003,3.658920e+002,1.296772e-004,-1.243892e-001
1.000000e+003,3.648777e+002,1.295655e-004,-1.247923e-001
1.000000e+003,3.638774e+002,1.293747e-004,-1.239987e-001
1.000000e+003,3.628694e+002,1.290180e-004,-1.241731e-001
1.000000e+003,3.618727e+002,1.286571e-004,-1.236724e-001
1.000000e+003,3.608684e+002,1.280908e-004,-1.235878e-001
1.000000e+003,3.598831e+002,1.274695e-004,-1.232531e-001
1.000000e+003,3.588956e+002,1.266302e-004,-1.233047e-001
1.000000e+003,3.578597e+002,1.254664e-004,-1.230353e-001
1.000000e+003,3.568787e+002,1.238226e-004,-1.231939e-001
1.000000e+003,3.558881e+002,1.211784e-004,-1.231929e-001
1.000000e+003,3.548728e+002,1.170647e-004,-1.237577e-001
1.000000e+003,3.539014e+002,1.121829e-004,-1.246812e-001
1.000000e+003,3.528754e+002,1.076059e-004,-1.251840e-001
1.000000e+003,3.518756e+002,9.714447e-005,-1.242802e-001
1.000000e+003,3.508718e+002,6.912755e-005,-1.084159e-001
1.000000e+003,3.498667e+002,4.673713e-005,-5.704392e-002
1.000000e+003,3.488774e+002,4.246991e-005,-4.167708e-002
1.000000e+003,3.478721e+002,4.177118e-005,-4.033488e-002
1.000000e+003,3.468849e+002,4.146358e-005,-3.913706e-002
1.000000e+003,3.458366e+002,4.122053e-005,-3.868564e-002
1.000000e+003,3.448807e+002,4.106518e-005,-3.646518e-002
1.000000e+003,3.438663e+002,4.096611e-005,-3.589759e-002
1.000000e+003,3.428864e+002,4.087204e-005,-3.507884e-002
1.000000e+003,3.418633e+002,4.080881e-005,-3.575759e-002
1.000000e+003,3.408885e+002,4.075496e-005,-3.452864e-002
1.000000e+003,3.398848e+002,4.070703e-005,-3.337876e-002
1.000000e+003,3.388690e+002,4.069707e-005,-3.364778e-002
1.000000e+003,3.378892e+002,4.062947e-005,-3.280772e-002
1.000000e+003,3.368565e+002,4.060919e-005,-3.222030e-002
1.000000e+003,3.358614e+002,4.065829e-005,-3.231686e-002
1.000000e+003,3.348647e+002,4.061069e-005,-3.217543e-002
1.000000e+003,3.338804e+002,4.061222e-005,-3.107489e-002
1.000000e+003,3.328667e+002,4.066537e-005,-3.168669e-002
1.000000e+003,3.318485e+002,4.063239e-005,-3.062652e-002
1.000000e+003,3.308784e+002,4.065249e-005,-3.137426e-002
1.000000e+003,3.298970e+002,4.065159e-005,-2.961055e-002
1.000000e+003,3.288743e+002,4.070205e-005,-2.882351e-002
1.000000e+003,3.278904e+002,4.073391e-005,-2.988882e-002
1.000000e+003,3.268681e+002,4.068632e-005,-2.969078e-002
1.000000e+003,3.258736e+002,4.072060e-005,-2.784459e-002
1.000000e+003,3.248646e+002,4.072938e-005,-2.817235e-002
1.000000e+003,3.238789e+002,4.081299e-005,-2.771829e-002
1.000000e+003,3.228849e+002,4.083605e-005,-2.762536e-002
1.000000e+003,3.218790e+002,4.082369e-005,-2.653833e-002
1.000000e+003,3.208940e+002,4.085802e-005,-2.723689e-002
1.000000e+003,3.198708e+002,4.087921e-005,-2.684258e-002