File: spin_crossover/dane/FeTrz_Trt_medium_FC_FH.rso.csv
Field (Oe),Temperature (K),Long Moment (emu),Long Offset (cm)
1.000000e+003,3.000034e+002,4.492341e-005,-2.028146e-002
1.000000e+003,3.011594e+002,4.484083e-005,-2.080627e-002
1.000000e+003,3.021485e+002,4.474737e-005,-2.146966e-002
1.000000e+003,3.031718e+002,4.464213e-005,-2.161333e-002
1.000000e+003,3.041388e+002,4.464341e-005,-2.378275e-002
1.000000e+003,3.051381e+002,4.457265e-005,-2.362829e-002
1.000000e+003,3.061222e+002,4.455642e-005,-2.374614e-002
1.000000e+003,3.071300e+002,4.446258e-005,-2.529071e-002
1.000000e+003,3.081093e+002,4.442814e-005,-2.572290e-002
1.000000e+003,3.091481e+002,4.437800e-005,-2.483481e-002
1.000000e+003,3.101279e+002,4.440554e-005,-2.611949e-002
1.000000e+003,3.111488e+002,4.432636e-005,-2.685920e-002
1.000000e+003,3.121249e+002,4.431162e-005,-2.697032e-002
1.000000e+003,3.131290e+002,4.424299e-005,-2.719779e-002
1.000000e+003,3.141516e+002,4.423402e-005,-2.776703e-002
1.000000e+003,3.151303e+002,4.419775e-005,-2.941396e-002
1.000000e+003,3.161293e+002,4.420477e-005,-2.965227e-002
1.000000e+003,3.171352e+002,4.414132e-005,-2.980408e-002
1.000000e+003,3.181259e+002,4.414320e-005,-2.945304e-002
1.000000e+003,3.191089e+002,4.407384e-005,-3.081480e-002
1.000000e+003,3.201392e+002,4.411222e-005,-3.103663e-002
1.000000e+003,3.211069e+002,4.409509e-005,-3.253625e-002
1.000000e+003,3.221284e+002,4.407466e-005,-3.245724e-002
1.000000e+003,3.231484e+002,4.406208e-005,-3.350879e-002
1.000000e+003,3.241190e+002,4.402740e-005,-3.379358e-002
1.000000e+003,3.251357e+002,4.404855e-005,-3.368151e-002
1.000000e+003,3.261232e+002,4.398010e-005,-3.437675e-002
1.000000e+003,3.271129e+002,4.396444e-005,-3.463250e-002
1.000000e+003,3.281540e+002,4.395701e-005,-3.629947e-002
1.000000e+003,3.291375e+002,4.394590e-005,-3.640521e-002
1.000000e+003,3.301379e+002,4.398461e-005,-3.740000e-002
1.000000e+003,3.311275e+002,4.397838e-005,-3.745522e-002
1.000000e+003,3.321079e+002,4.397430e-005,-3.816759e-002
1.000000e+003,3.331566e+002,4.400578e-005,-3.962215e-002
1.000000e+003,3.340985e+002,4.397917e-005,-4.002979e-002
1.000000e+003,3.351248e+002,4.398918e-005,-3.914307e-002
1.000000e+003,3.361371e+002,4.400402e-005,-3.883991e-002
1.000000e+003,3.371038e+002,4.401440e-005,-3.992973e-002
1.000000e+003,3.381245e+002,4.401501e-005,-4.078699e-002
1.000000e+003,3.391379e+002,4.404395e-005,-4.199673e-002
1.000000e+003,3.400976e+002,4.405370e-005,-4.225922e-002
1.000000e+003,3.411351e+002,4.408781e-005,-4.250012e-002
1.000000e+003,3.421091e+002,4.407470e-005,-4.342907e-002
1.000000e+003,3.431314e+002,4.415700e-005,-4.338014e-002
1.000000e+003,3.441365e+002,4.416326e-005,-4.416803e-002
1.000000e+003,3.451406e+002,4.421827e-005,-4.356298e-002
1.000000e+003,3.461317e+002,4.424455e-005,-4.570878e-002
1.000000e+003,3.471288e+002,4.429634e-005,-4.688207e-002
1.000000e+003,3.481514e+002,4.429279e-005,-4.600043e-002
1.000000e+003,3.491193e+002,4.436450e-005,-4.769567e-002
1.000000e+003,3.501273e+002,4.441164e-005,-4.733438e-002
1.000000e+003,3.511216e+002,4.446508e-005,-4.880422e-002
1.000000e+003,3.521368e+002,4.447628e-005,-4.872654e-002
1.000000e+003,3.531231e+002,4.454284e-005,-4.986298e-002
1.000000e+003,3.541405e+002,4.456355e-005,-4.931202e-002
1.000000e+003,3.551438e+002,4.467168e-005,-5.059735e-002
1.000000e+003,3.561378e+002,4.468225e-005,-5.030215e-002
1.000000e+003,3.571401e+002,4.481724e-005,-5.184814e-002
1.000000e+003,3.581510e+002,4.485678e-005,-5.216442e-002
1.000000e+003,3.591264e+002,4.492575e-005,-5.324220e-002
1.000000e+003,3.601335e+002,4.499167e-005,-5.309547e-002
1.000000e+003,3.611255e+002,4.508452e-005,-5.405322e-002
1.000000e+003,3.621286e+002,4.518116e-005,-5.485405e-002
1.000000e+003,3.631375e+002,4.526206e-005,-5.483835e-002
1.000000e+003,3.641149e+002,4.540123e-005,-5.661430e-002
1.000000e+003,3.651166e+002,4.547873e-005,-5.711592e-002
1.000000e+003,3.661593e+002,4.557717e-005,-5.758733e-002
1.000000e+003,3.671295e+002,4.569342e-005,-5.820680e-002
1.000000e+003,3.681240e+002,4.577546e-005,-5.795945e-002
1.000000e+003,3.691353e+002,4.590846e-005,-5.972464e-002
1.000000e+003,3.701192e+002,4.604440e-005,-6.036653e-002
1.000000e+003,3.711059e+002,4.615200e-005,-6.049333e-002
1.000000e+003,3.721595e+002,4.630879e-005,-6.077245e-002
1.000000e+003,3.731126e+002,4.645609e-005,-6.254472e-002
1.000000e+003,3.741188e+002,4.669565e-005,-6.295612e-002
1.000000e+003,3.751536e+002,4.693655e-005,-6.318909e-002
1.000000e+003,3.761227e+002,4.724476e-005,-6.538555e-002
1.000000e+003,3.771288e+002,4.778689e-005,-6.750743e-002
1.000000e+003,3.781144e+002,4.850175e-005,-6.872977e-002
1.000000e+003,3.791084e+002,4.996786e-005,-7.233104e-002
1.000000e+003,3.801195e+002,5.226632e-005,-7.748869e-002
1.000000e+003,3.811157e+002,5.544319e-005,-8.398795e-002
1.000000e+003,3.821380e+002,5.936340e-005,-9.003287e-002
1.000000e+003,3.830977e+002,6.341670e-005,-9.567860e-002
1.000000e+003,3.840982e+002,6.803234e-005,-1.012428e-001
1.000000e+003,3.851433e+002,7.320388e-005,-1.064957e-001
1.000000e+003,3.861248e+002,7.898211e-005,-1.115645e-001
1.000000e+003,3.871481e+002,8.586473e-005,-1.161749e-001
1.000000e+003,3.881189e+002,9.299311e-005,-1.208169e-001
1.000000e+003,3.890979e+002,9.977182e-005,-1.238894e-001
1.000000e+003,3.901377e+002,1.056872e-004,-1.263042e-001
1.000000e+003,3.911365e+002,1.102095e-004,-1.280308e-001
1.000000e+003,3.921564e+002,1.136698e-004,-1.292732e-001
1.000000e+003,3.931285e+002,1.160553e-004,-1.296546e-001
1.000000e+003,3.940994e+002,1.177276e-004,-1.300991e-001
1.000000e+003,3.951323e+002,1.190636e-004,-1.306326e-001
1.000000e+003,3.960907e+002,1.200363e-004,-1.306460e-001
1.000000e+003,3.971171e+002,1.207995e-004,-1.308955e-001
1.000000e+003,3.981578e+002,1.214690e-004,-1.315076e-001
1.000000e+003,3.991292e+002,1.218727e-004,-1.309641e-001
1.000000e+003,3.999849e+002,1.232353e-004,-1.295376e-001
1.000000e+003,4.000076e+002,1.236201e-004,-1.286478e-001
1.000000e+003,3.988361e+002,1.238870e-004,-1.275098e-001
1.000000e+003,3.978307e+002,1.240980e-004,-1.268308e-001
1.000000e+003,3.967436e+002,1.243428e-004,-1.261549e-001
1.000000e+003,3.956714e+002,1.246137e-004,-1.255400e-001
1.000000e+003,3.947115e+002,1.248457e-004,-1.247168e-001
1.000000e+003,3.936589e+002,1.250398e-004,-1.241237e-001
1.000000e+003,3.927560e+002,1.252688e-004,-1.238991e-001
1.000000e+003,3.917827e+002,1.254752e-004,-1.234605e-001
1.000000e+003,3.908206e+002,1.256973e-004,-1.232435e-001
1.000000e+003,3.899372e+002,1.259037e-004,-1.227727e-001
1.000000e+003,3.889141e+002,1.262911e-004,-1.238134e-001
1.000000e+003,3.878171e+002,1.265886e-004,-1.232912e-001
1.000000e+003,3.868145e+002,1.268296e-004,-1.229784e-001
1.000000e+003,3.857720e+002,1.269764e-004,-1.228481e-001
1.000000e+003,3.848282e+002,1.272921e-004,-1.218570e-001
1.000000e+003,3.838655e+002,1.274682e-004,-1.215868e-001
1.000000e+003,3.828988e+002,1.276902e-004,-1.214927e-001
1.000000e+003,3.819283e+002,1.278743e-004,-1.212241e-001
1.000000e+003,3.808867e+002,1.280761e-004,-1.208387e-001
1.000000e+003,3.798946e+002,1.282885e-004,-1.203344e-001
1.000000e+003,3.788441e+002,1.283872e-004,-1.200712e-001
1.000000e+003,3.778776e+002,1.285895e-004,-1.193833e-001
1.000000e+003,3.768645e+002,1.287464e-004,-1.192095e-001
1.000000e+003,3.758685e+002,1.289519e-004,-1.189919e-001
1.000000e+003,3.748723e+002,1.291131e-004,-1.186313e-001
1.000000e+003,3.738731e+002,1.291438e-004,-1.181279e-001
1.000000e+003,3.728767e+002,1.293556e-004,-1.178158e-001
1.000000e+003,3.718941e+002,1.293495e-004,-1.176905e-001
1.000000e+003,3.708420e+002,1.294767e-004,-1.169529e-001
1.000000e+003,3.698734e+002,1.295557e-004,-1.167812e-001
1.000000e+003,3.688909e+002,1.295923e-004,-1.163656e-001
1.000000e+003,3.678865e+002,1.296135e-004,-1.160108e-001
1.000000e+003,3.668714e+002,1.295849e-004,-1.156836e-001
1.000000e+003,3.658677e+002,1.294579e-004,-1.153426e-001
1.000000e+003,3.648938e+002,1.293816e-004,-1.149302e-001
1.000000e+003,3.638614e+002,1.292239e-004,-1.146464e-001
1.000000e+003,3.628615e+002,1.289477e-004,-1.141776e-001
1.000000e+003,3.618911e+002,1.286228e-004,-1.138277e-001
1.000000e+003,3.608579e+002,1.281111e-004,-1.134866e-001
1.000000e+003,3.598649e+002,1.274839e-004,-1.126900e-001
1.000000e+003,3.588801e+002,1.266697e-004,-1.124875e-001
1.000000e+003,3.578546e+002,1.255083e-004,-1.117506e-001
1.000000e+003,3.568941e+002,1.240327e-004,-1.111661e-001
1.000000e+003,3.558932e+002,1.217265e-004,-1.103408e-001
1.000000e+003,3.548677e+002,1.176762e-004,-1.090873e-001
1.000000e+003,3.538837e+002,1.078275e-004,-1.067442e-001
1.000000e+003,3.528754e+002,7.666786e-005,-9.085271e-002
1.000000e+003,3.518607e+002,4.987369e-005,-4.783394e-002
1.000000e+003,3.508743e+002,4.875736e-005,-4.580902e-002
1.000000e+003,3.498691e+002,4.815677e-005,-4.488221e-002
1.000000e+003,3.488628e+002,4.780250e-005,-4.394649e-002
1.000000e+003,3.478891e+002,4.753863e-005,-4.302387e-002
1.000000e+003,3.468705e+002,4.735675e-005,-4.165078e-002
1.000000e+003,3.458893e+002,4.715073e-005,-4.109593e-002
1.000000e+003,3.448616e+002,4.702916e-005,-4.084538e-002
1.000000e+003,3.438805e+002,4.687136e-005,-3.993066e-002
1.000000e+003,3.428841e+002,4.681329e-005,-3.858143e-002
1.000000e+003,3.418750e+002,4.674524e-005,-3.853049e-002
1.000000e+003,3.408745e+002,4.666939e-005,-3.788760e-002
1.000000e+003,3.398964e+002,4.660620e-005,-3.787608e-002
1.000000e+003,3.388483e+002,4.651381e-005,-3.710555e-002
1.000000e+003,3.378824e+002,4.651595e-005,-3.679556e-002
1.000000e+003,3.368452e+002,4.644112e-005,-3.601174e-002
1.000000e+003,3.358840e+002,4.645769e-005,-3.543423e-002
1.000000e+003,3.348917e+002,4.638577e-005,-3.453386e-002
1.000000e+003,3.338648e+002,4.634276e-005,-3.549770e-002
1.000000e+003,3.328844e+002,4.629704e-005,-3.336143e-002
1.000000e+003,3.318815e+002,4.631520e-005,-3.363232e-002
1.000000e+003,3.308632e+002,4.627989e-005,-3.343709e-002
1.000000e+003,3.298774e+002,4.624525e-005,-3.280088e-002
1.000000e+003,3.288570e+002,4.625034e-005,-3.265483e-002
1.000000e+003,3.278904e+002,4.626120e-005,-3.257180e-002
1.000000e+003,3.268872e+002,4.624352e-005,-3.203862e-002
1.000000e+003,3.258778e+002,4.625336e-005,-3.148171e-002
1.000000e+003,3.248562e+002,4.623953e-005,-3.077977e-002
1.000000e+003,3.238455e+002,4.623693e-005,-3.114606e-002
1.000000e+003,3.228746e+002,4.623240e-005,-3.037482e-002
1.000000e+003,3.218873e+002,4.625586e-005,-3.025813e-002
1.000000e+003,3.208675e+002,4.626767e-005,-3.012625e-002
1.000000e+003,3.198708e+002,4.628662e-005,-2.927385e-002
1.000000e+003,3.188484e+002,4.627816e-005,-2.820288e-002
1.000000e+003,3.178810e+002,4.627769e-005,-2.861777e-002
1.000000e+003,3.168920e+002,4.632886e-005,-2.884960e-002
1.000000e+003,3.158582e+002,4.633582e-005,-2.820419e-002
1.000000e+003,3.148806e+002,4.632402e-005,-2.734496e-002
1.000000e+003,3.138860e+002,4.639161e-005,-2.811502e-002
1.000000e+003,3.128516e+002,4.640543e-005,-2.717131e-002
1.000000e+003,3.118803e+002,4.645767e-005,-2.726519e-002
1.000000e+003,3.108848e+002,4.643334e-005,-2.723851e-002
1.000000e+003,3.098752e+002,4.647610e-005,-2.703258e-002
1.000000e+003,3.088783e+002,4.644256e-005,-2.590812e-002
1.000000e+003,3.078544e+002,4.651210e-005,-2.662486e-002
1.000000e+003,3.068862e+002,4.658055e-005,-2.525631e-002
1.000000e+003,3.058876e+002,4.659824e-005,-2.548076e-002
1.000000e+003,3.048646e+002,4.661778e-005,-2.543827e-002
1.000000e+003,3.038891e+002,4.667958e-005,-2.444848e-002
1.000000e+003,3.028823e+002,4.672024e-005,-2.405384e-002
1.000000e+003,3.018557e+002,4.675301e-005,-2.420127e-002
1.000000e+003,3.008900e+002,4.676266e-005,-2.437612e-002
1.000000e+003,3.000070e+002,4.682318e-005,-2.390295e-002
1.000000e+003,3.000176e+002,4.676904e-005,-2.474374e-002
1.000000e+003,3.011523e+002,4.669014e-005,-2.488612e-002
1.000000e+003,3.021467e+002,4.658749e-005,-2.555487e-002
1.000000e+003,3.031646e+002,4.657251e-005,-2.601858e-002
1.000000e+003,3.041534e+002,4.654037e-005,-2.650034e-002
1.000000e+003,3.051234e+002,4.645925e-005,-2.758488e-002
1.000000e+003,3.061426e+002,4.645194e-005,-2.804575e-002
1.000000e+003,3.071356e+002,4.631584e-005,-2.831585e-002
1.000000e+003,3.081168e+002,4.630062e-005,-2.899626e-002
1.000000e+003,3.091348e+002,4.629063e-005,-2.895431e-002
1.000000e+003,3.101241e+002,4.621737e-005,-3.008663e-002
1.000000e+003,3.111411e+002,4.617409e-005,-3.022392e-002
1.000000e+003,3.121384e+002,4.613453e-005,-3.082946e-002
1.000000e+003,3.131523e+002,4.606804e-005,-3.139741e-002
1.000000e+003,3.141223e+002,4.606329e-005,-3.151115e-002
1.000000e+003,3.151067e+002,4.599000e-005,-3.254358e-002
1.000000e+003,3.161413e+002,4.599170e-005,-3.209911e-002
1.000000e+003,3.171451e+002,4.594503e-005,-3.344187e-002
1.000000e+003,3.181459e+002,4.590479e-005,-3.331258e-002
1.000000e+003,3.191412e+002,4.588555e-005,-3.400587e-002
1.000000e+003,3.201534e+002,4.586042e-005,-3.451693e-002
1.000000e+003,3.211049e+002,4.583816e-005,-3.499259e-002
1.000000e+003,3.221531e+002,4.579379e-005,-3.630008e-002
1.000000e+003,3.231173e+002,4.578496e-005,-3.534103e-002
1.000000e+003,3.241211e+002,4.575368e-005,-3.617289e-002
1.000000e+003,3.251336e+002,4.576604e-005,-3.611312e-002
1.000000e+003,3.261147e+002,4.575201e-005,-3.765194e-002
1.000000e+003,3.271491e+002,4.567989e-005,-3.752553e-002
1.000000e+003,3.281240e+002,4.564412e-005,-3.763375e-002
1.000000e+003,3.291266e+002,4.565042e-005,-3.844517e-002
1.000000e+003,3.301466e+002,4.561710e-005,-3.872370e-002
1.000000e+003,3.311253e+002,4.563387e-005,-3.922036e-002
1.000000e+003,3.321233e+002,4.567411e-005,-4.006596e-002
1.000000e+003,3.331233e+002,4.562814e-005,-4.030197e-002
1.000000e+003,3.340985e+002,4.563482e-005,-4.150071e-002
1.000000e+003,3.351359e+002,4.562324e-005,-4.222699e-002
1.000000e+003,3.361122e+002,4.562929e-005,-4.180016e-002
1.000000e+003,3.371198e+002,4.562105e-005,-4.181960e-002
1.000000e+003,3.381428e+002,4.564161e-005,-4.321598e-002
1.000000e+003,3.391218e+002,4.564771e-005,-4.285264e-002
1.000000e+003,3.401299e+002,4.568335e-005,-4.376891e-002
1.000000e+003,3.411235e+002,4.570135e-005,-4.460806e-002
1.000000e+003,3.421278e+002,4.571937e-005,-4.435669e-002
1.000000e+003,3.431432e+002,4.570937e-005,-4.538815e-002
1.000000e+003,3.441294e+002,4.577900e-005,-4.561894e-002
1.000000e+003,3.451311e+002,4.573772e-005,-4.609979e-002
1.000000e+003,3.461197e+002,4.578843e-005,-4.694895e-002
1.000000e+003,3.471192e+002,4.583847e-005,-4.804519e-002
1.000000e+003,3.481490e+002,4.586170e-005,-4.735063e-002
1.000000e+003,3.491120e+002,4.594422e-005,-4.933625e-002
1.000000e+003,3.501519e+002,4.596011e-005,-4.896758e-002
1.000000e+003,3.511191e+002,4.602894e-005,-4.914792e-002
1.000000e+003,3.521119e+002,4.605977e-005,-5.043448e-002
1.000000e+003,3.531582e+002,4.614189e-005,-5.082504e-002
1.000000e+003,3.541229e+002,4.619978e-005,-5.210847e-002
1.000000e+003,3.551286e+002,4.623085e-005,-5.266351e-002
1.000000e+003,3.561352e+002,4.633581e-005,-5.264777e-002
1.000000e+003,3.571350e+002,4.639939e-005,-5.295806e-002
1.000000e+003,3.581097e+002,4.650694e-005,-5.379357e-002
1.000000e+003,3.591290e+002,4.658826e-005,-5.451962e-002
1.000000e+003,3.601256e+002,4.674721e-005,-5.501712e-002
1.000000e+003,3.611492e+002,4.690222e-005,-5.627853e-002
1.000000e+003,3.621207e+002,4.700145e-005,-5.699110e-002
1.000000e+003,3.631428e+002,4.717017e-005,-5.659277e-002
1.000000e+003,3.641309e+002,4.737108e-005,-5.850743e-002
1.000000e+003,3.651140e+002,4.758850e-005,-5.847041e-002
1.000000e+003,3.661431e+002,4.790892e-005,-6.053517e-002
1.000000e+003,3.671458e+002,4.833096e-005,-6.165693e-002
1.000000e+003,3.681295e+002,4.890931e-005,-6.261937e-002
1.000000e+003,3.691463e+002,5.000846e-005,-6.509990e-002
1.000000e+003,3.701302e+002,5.205339e-005,-6.959134e-002
1.000000e+003,3.711086e+002,5.728335e-005,-7.938349e-002
1.000000e+003,3.721595e+002,6.943637e-005,-9.520262e-002
1.000000e+003,3.731126e+002,8.137609e-005,-1.060103e-001
1.000000e+003,3.741387e+002,9.183257e-005,-1.127814e-001
1.000000e+003,3.751393e+002,1.014326e-004,-1.185983e-001
1.000000e+003,3.761256e+002,1.094608e-004,-1.222553e-001
1.000000e+003,3.771690e+002,1.148706e-004,-1.240648e-001
1.000000e+003,3.781346e+002,1.181842e-004,-1.254827e-001
1.000000e+003,3.791578e+002,1.204697e-004,-1.266183e-001
1.000000e+003,3.801545e+002,1.219378e-004,-1.268462e-001
1.000000e+003,3.811098e+002,1.229540e-004,-1.271852e-001
1.000000e+003,3.820789e+002,1.235983e-004,-1.275604e-001
1.000000e+003,3.831333e+002,1.241452e-004,-1.273543e-001
1.000000e+003,3.841400e+002,1.243961e-004,-1.281341e-001
1.000000e+003,3.851403e+002,1.248198e-004,-1.279892e-001
1.000000e+003,3.861219e+002,1.249583e-004,-1.286283e-001
1.000000e+003,3.871177e+002,1.250500e-004,-1.288298e-001
1.000000e+003,3.881464e+002,1.251827e-004,-1.286502e-001
1.000000e+003,3.891041e+002,1.251337e-004,-1.289316e-001
1.000000e+003,3.901191e+002,1.250366e-004,-1.289624e-001
1.000000e+003,3.911396e+002,1.249504e-004,-1.289549e-001
1.000000e+003,3.921190e+002,1.248211e-004,-1.288647e-001
1.000000e+003,3.931254e+002,1.246361e-004,-1.290053e-001
1.000000e+003,3.941246e+002,1.245389e-004,-1.290476e-001
1.000000e+003,3.951323e+002,1.243570e-004,-1.290396e-001
1.000000e+003,3.961225e+002,1.242042e-004,-1.292799e-001
1.000000e+003,3.971490e+002,1.239891e-004,-1.288699e-001
1.000000e+003,3.981097e+002,1.238160e-004,-1.292055e-001
1.000000e+003,3.991678e+002,1.236337e-004,-1.289777e-001
1.000000e+003,3.999785e+002,1.236741e-004,-1.275291e-001
1.000000e+003,4.000043e+002,1.237630e-004,-1.262479e-001
1.000000e+003,3.988489e+002,1.240037e-004,-1.251949e-001
1.000000e+003,3.978275e+002,1.242106e-004,-1.243548e-001
1.000000e+003,3.967436e+002,1.244680e-004,-1.239147e-001
1.000000e+003,3.957285e+002,1.247213e-004,-1.233457e-001
1.000000e+003,3.946894e+002,1.250142e-004,-1.227374e-001
1.000000e+003,3.937469e+002,1.252056e-004,-1.219840e-001
1.000000e+003,3.927154e+002,1.254691e-004,-1.216888e-001
1.000000e+003,3.917951e+002,1.257099e-004,-1.212508e-001
1.000000e+003,3.908298e+002,1.259178e-004,-1.207795e-001
1.000000e+003,3.899218e+002,1.261325e-004,-1.205176e-001
1.000000e+003,3.889293e+002,1.265645e-004,-1.215871e-001
1.000000e+003,3.878262e+002,1.268093e-004,-1.212800e-001
1.000000e+003,3.868145e+002,1.271043e-004,-1.204853e-001
1.000000e+003,3.857630e+002,1.273277e-004,-1.202128e-001
1.000000e+003,3.848163e+002,1.274937e-004,-1.197037e-001
1.000000e+003,3.838505e+002,1.277421e-004,-1.190376e-001
1.000000e+003,3.828810e+002,1.279421e-004,-1.191150e-001
1.000000e+003,3.819165e+002,1.281103e-004,-1.184399e-001
1.000000e+003,3.808807e+002,1.283347e-004,-1.181576e-001
1.000000e+003,3.798917e+002,1.286089e-004,-1.179935e-001
1.000000e+003,3.788644e+002,1.288294e-004,-1.174787e-001
1.000000e+003,3.778459e+002,1.289219e-004,-1.175315e-001
1.000000e+003,3.768645e+002,1.291455e-004,-1.168014e-001
1.000000e+003,3.758628e+002,1.293213e-004,-1.163670e-001
1.000000e+003,3.748609e+002,1.295689e-004,-1.160875e-001
1.000000e+003,3.738788e+002,1.296691e-004,-1.157563e-001
1.000000e+003,3.728711e+002,1.298602e-004,-1.156303e-001
1.000000e+003,3.718579e+002,1.299591e-004,-1.151927e-001
1.000000e+003,3.708726e+002,1.300995e-004,-1.147527e-001
1.000000e+003,3.698845e+002,1.301749e-004,-1.146396e-001
1.000000e+003,3.688551e+002,1.302843e-004,-1.141682e-001
1.000000e+003,3.678864e+002,1.303456e-004,-1.138653e-001
1.000000e+003,3.668905e+002,1.303316e-004,-1.133695e-001
1.000000e+003,3.658596e+002,1.303456e-004,-1.130412e-001
1.000000e+003,3.648912e+002,1.302720e-004,-1.126867e-001
1.000000e+003,3.638880e+002,1.302806e-004,-1.123866e-001
1.000000e+003,3.628615e+002,1.301573e-004,-1.120658e-001
1.000000e+003,3.618859e+002,1.300085e-004,-1.116455e-001
1.000000e+003,3.609025e+002,1.296962e-004,-1.114409e-001
1.000000e+003,3.598701e+002,1.293670e-004,-1.107140e-001
1.000000e+003,3.588671e+002,1.288516e-004,-1.101928e-001
1.000000e+003,3.578752e+002,1.282209e-004,-1.101381e-001
1.000000e+003,3.568813e+002,1.273064e-004,-1.094321e-001
1.000000e+003,3.558728e+002,1.260583e-004,-1.087086e-001
1.000000e+003,3.548450e+002,1.242407e-004,-1.081801e-001
1.000000e+003,3.538787e+002,1.214886e-004,-1.071896e-001
1.000000e+003,3.528554e+002,1.145165e-004,-1.058624e-001
1.000000e+003,3.518756e+002,9.266259e-005,-9.653941e-002
1.000000e+003,3.508669e+002,5.314626e-005,-5.134280e-002
1.000000e+003,3.498618e+002,4.901525e-005,-4.427218e-002
1.000000e+003,3.488872e+002,4.827975e-005,-4.283386e-002
1.000000e+003,3.478624e+002,4.785390e-005,-4.167021e-002
1.000000e+003,3.468754e+002,4.756652e-005,-4.100658e-002
1.000000e+003,3.458750e+002,4.736079e-005,-3.979840e-002
1.000000e+003,3.448950e+002,4.715593e-005,-4.019630e-002
1.000000e+003,3.438615e+002,4.705500e-005,-3.820639e-002
1.000000e+003,3.428818e+002,4.688733e-005,-3.797473e-002
1.000000e+003,3.418750e+002,4.684871e-005,-3.797492e-002
1.000000e+003,3.408536e+002,4.671690e-005,-3.789222e-002
1.000000e+003,3.398455e+002,4.663557e-005,-3.663711e-002
1.000000e+003,3.388851e+002,4.658285e-005,-3.628946e-002
1.000000e+003,3.378665e+002,4.652830e-005,-3.529852e-002
1.000000e+003,3.368882e+002,4.648220e-005,-3.472941e-002
1.000000e+003,3.358637e+002,4.636576e-005,-3.468934e-002
1.000000e+003,3.348670e+002,4.635098e-005,-3.362828e-002
1.000000e+003,3.338781e+002,4.633150e-005,-3.409095e-002
1.000000e+003,3.328445e+002,4.629384e-005,-3.349784e-002
1.000000e+003,3.318705e+002,4.627597e-005,-3.274813e-002
1.000000e+003,3.308653e+002,4.626293e-005,-3.206158e-002
1.000000e+003,3.298774e+002,4.623751e-005,-3.224246e-002
1.000000e+003,3.288657e+002,4.622612e-005,-3.204502e-002
1.000000e+003,3.278818e+002,4.619922e-005,-3.136147e-002
1.000000e+003,3.268489e+002,4.620504e-005,-3.069155e-002
1.000000e+003,3.258736e+002,4.621454e-005,-3.127570e-002
1.000000e+003,3.248898e+002,4.619285e-005,-3.008754e-002
1.000000e+003,3.238788e+002,4.621064e-005,-3.028094e-002
1.000000e+003,3.228871e+002,4.622453e-005,-2.962749e-002
1.000000e+003,3.218873e+002,4.619682e-005,-2.923471e-002
1.000000e+003,3.208654e+002,4.620166e-005,-2.880505e-002
1.000000e+003,3.198931e+002,4.620515e-005,-2.868408e-002
1.000000e+003,3.188686e+002,4.621360e-005,-2.839972e-002
1.000000e+003,3.178830e+002,4.623237e-005,-2.842357e-002
1.000000e+003,3.168622e+002,4.626039e-005,-2.751073e-002
1.000000e+003,3.158780e+002,4.627329e-005,-2.718866e-002
1.000000e+003,3.148943e+002,4.632166e-005,-2.656538e-002
1.000000e+003,3.138450e+002,4.628774e-005,-2.668902e-002
1.000000e+003,3.128749e+002,4.634897e-005,-2.623458e-002
1.000000e+003,3.118669e+002,4.641297e-005,-2.612611e-002
1.000000e+003,3.108810e+002,4.637107e-005,-2.664984e-002
1.000000e+003,3.098714e+002,4.639796e-005,-2.537257e-002
1.000000e+003,3.088688e+002,4.643240e-005,-2.441845e-002
1.000000e+003,3.078863e+002,4.647729e-005,-2.498345e-002
1.000000e+003,3.068453e+002,4.651844e-005,-2.426751e-002
1.000000e+003,3.058876e+002,4.650686e-005,-2.430166e-002
1.000000e+003,3.048812e+002,4.657904e-005,-2.368536e-002
1.000000e+003,3.038454e+002,4.662082e-005,-2.205409e-002
1.000000e+003,3.028823e+002,4.662415e-005,-2.315372e-002
1.000000e+003,3.018701e+002,4.667127e-005,-2.285028e-002
1.000000e+003,3.008633e+002,4.673231e-005,-2.313799e-002
1.000000e+003,3.000087e+002,4.675636e-005,-2.371593e-002