File: dane/AOT — kopia/Small AOT/FeTrz_AOT_small_XTvT_MCE.rso.dat
[Header]
TITLE,MPMS RSO Measurement
BYAPP,MPMS Measurement,1.1,Summary
FILEOPENTIME, 1661166932.703000 8/22/2022, 1:15:32 PM

INFO, APPNAME, MPMS MultiVu Application, Revision 1.60,  Build 081

INFO, NAME, FeTrz_AOT_small
INFO, WEIGHT, 3.220
INFO, AREA, 0.000
INFO, LENGTH, 0.000
INFO, SHAPE, 0
INFO, COMMENT,
INFO, SEQUENCE FILE: FeTrz_HTvT_MCE_reverse.seq


INFO, BACKGROUND DATA FILE:, None


STARTUPAXIS,X,4,LINEAR,AUTO,0.000000,0.000000
STARTUPAXIS,Y1,5,LINEAR,AUTO,0.000000,0.000000


STARTUPGROUP,Longitudinal
FIELDGROUP,Longitudinal,1,2,3,4,5,6,7,8,9,10,11,19,20,21,22,23,35
FIELDGROUP,Transverse,1,2,3,4,12,13,14,15,16,17,18,24,25,26,27,28,35

PLOT_APPEARANCE,ALL,HORZ_GRID_ON,VERT_GRID_ON,MARKERS_AND_LINES

[Data]
Time,Comment,Field (Oe),Temperature (K),Long Moment (emu),Long Scan Std Dev,Long Offset (cm),Long Offset Std Dev,Long Algorithm,Long Reg Fit,Long Reg Factor,Trans Moment (emu),Trans Scan Std Dev,Trans Offset (cm),Trans Offset Std Dev,Trans Algorithm,Trans Reg Fit,Trans Reg Factor,Long Moment [w/o ABS] (emu),Long Scan Std Dev [w/o ABS],Long Offset [w/o ABS] (cm),Long Offset Std Dev [w/o ABS],Long Reg Fit [w/o ABS],Trans Moment [w/o ABS] (emu),Trans Scan Std Dev [w/o ABS],Trans Offset [w/o ABS] (cm),Trans Offset Std Dev [w/o ABS],Trans Reg Fit [w/o ABS],RSO Position (deg),Amplitude (cm),Frequency,Cycles to Average,Scans per Measurement,Delta Temp (K),Error,EC Comp. Running,Using ABS,
1661166932.702,,7.000000e+004,4.000000e+002,3.934791e-003,1.218307e-006,-1.306971e-001,1.462285e-004,3,9.765353e-001,1.825000e+000,,,,,,,,,,,,,,,,,,0,4.000000e+000,1.000000e+000,2,2,1.290894e-002,0,,0,
1661167801.266,,7.000000e+004,3.711686e+002,4.171042e-003,4.771155e-006,-1.186434e-001,1.708212e-004,3,9.772283e-001,1.825000e+000,,,,,,,,,,,,,,,,,,0,4.000000e+000,1.000000e+000,2,2,8.565063e-001,0,,0,
1661168530.065,,7.000000e+004,3.437203e+002,4.101524e-003,1.711623e-005,-1.012546e-001,4.284807e-004,3,9.747375e-001,1.825000e+000,,,,,,,,,,,,,,,,,,0,4.000000e+000,1.000000e+000,2,2,4.544067e-001,0,,0,
1661169482.061,,7.000000e+004,3.156155e+002,1.879445e-003,9.278892e-007,-2.895192e-002,6.059795e-005,3,9.380444e-001,1.825000e+000,,,,,,,,,,,,,,,,,,0,4.000000e+000,1.000000e+000,2,2,7.343750e-001,0,,0,
1661170807.990,,7.000000e+004,3.112467e+002,1.857231e-003,4.766223e-008,-2.989195e-002,2.017596e-004,3,9.363676e-001,1.825000e+000,,,,,,,,,,,,,,,,,,0,4.000000e+000,1.000000e+000,2,2,3.757019e-001,0,,0,
1661171651.381,,7.000000e+004,3.392099e+002,1.968969e-003,1.629568e-006,-4.825193e-002,1.729101e-004,3,9.442286e-001,1.825000e+000,,,,,,,,,,,,,,,,,,0,4.000000e+000,1.000000e+000,2,2,4.141846e-001,0,,0,
1661172492.526,,7.000000e+004,3.672857e+002,4.073095e-003,6.636482e-006,-1.219758e-001,3.035311e-004,3,9.756441e-001,1.825000e+000,,,,,,,,,,,,,,,,,,0,4.000000e+000,1.000000e+000,2,2,4.024048e-001,0,,0,
1661173330.737,,7.000000e+004,3.952103e+002,3.971400e-003,1.111623e-006,-1.316388e-001,1.554797e-004,3,9.766936e-001,1.825000e+000,,,,,,,,,,,,,,,,,,0,4.000000e+000,1.000000e+000,2,2,4.183044e-001,0,,0,
1661174877.615,,6.500000e+004,3.775823e+002,3.829180e-003,3.395291e-006,-1.172587e-001,1.350807e-004,3,9.768208e-001,1.825000e+000,,,,,,,,,,,,,,,,,,0,4.000000e+000,1.000000e+000,2,2,7.492065e-001,0,,0,
1661175583.563,,6.500000e+004,3.495341e+002,4.018580e-003,1.323345e-006,-1.064163e-001,1.101929e-004,3,9.760708e-001,1.825000e+000,,,,,,,,,,,,,,,,,,0,4.000000e+000,1.000000e+000,2,2,7.059937e-001,0,,0,
1661176544.577,,6.500000e+004,3.216162e+002,1.889404e-003,1.232301e-006,-3.686443e-002,1.693039e-004,3,9.418724e-001,1.825000e+000,,,,,,,,,,,,,,,,,,0,4.000000e+000,1.000000e+000,2,2,5.755005e-001,0,,0,
1661177822.045,,6.500000e+004,3.052558e+002,1.845026e-003,5.944187e-007,-3.159916e-002,5.432729e-005,3,9.391518e-001,1.825000e+000,,,,,,,,,,,,,,,,,,0,4.000000e+000,1.000000e+000,2,2,4.927063e-001,0,,0,
1661178646.739,,6.500000e+004,3.332258e+002,1.893843e-003,1.371831e-006,-4.782634e-002,3.484623e-004,3,9.439214e-001,1.825000e+000,,,,,,,,,,,,,,,,,,0,4.000000e+000,1.000000e+000,2,2,4.255066e-001,0,,0,
1661179492.082,,6.500000e+004,3.614052e+002,3.576953e-003,1.127247e-005,-1.129750e-001,3.084991e-004,3,9.735662e-001,1.825000e+000,,,,,,,,,,,,,,,,,,0,4.000000e+000,1.000000e+000,2,2,4.626770e-001,0,,0,
1661180326.624,,6.500000e+004,3.892195e+002,3.741341e-003,9.459992e-007,-1.293035e-001,8.387223e-006,3,9.769958e-001,1.825000e+000,,,,,,,,,,,,,,,,,,0,4.000000e+000,1.000000e+000,2,2,3.928833e-001,0,,0,
1661181649.900,,6.000000e+004,3.835127e+002,3.506192e-003,2.665788e-006,-1.170438e-001,3.387026e-005,3,9.773750e-001,1.825000e+000,,,,,,,,,,,,,,,,,,0,4.000000e+000,1.000000e+000,2,2,5.476990e-001,0,,0,
1661182667.221,,6.000000e+004,3.554470e+002,3.673853e-003,2.590220e-006,-1.097179e-001,2.685281e-004,3,9.755473e-001,1.825000e+000,,,,,,,,,,,,,,,,,,0,4.000000e+000,1.000000e+000,2,2,9.141846e-001,0,,0,
1661183389.636,,6.000000e+004,3.277453e+002,1.959444e-003,7.857095e-006,-4.850033e-002,3.787974e-004,3,9.498008e-001,1.825000e+000,,,,,,,,,,,,,,,,,,0,4.000000e+000,1.000000e+000,2,2,4.193115e-001,0,,0,
1661184565.226,,6.000000e+004,3.000760e+002,1.779495e-003,2.700033e-007,-3.289892e-002,1.697886e-004,3,9.411301e-001,1.825000e+000,,,,,,,,,,,,,,,,,,0,4.000000e+000,1.000000e+000,2,2,2.130127e-002,0,,0,
1661185639.448,,6.000000e+004,3.271964e+002,1.774730e-003,2.406157e-007,-4.767923e-002,1.371063e-004,3,9.433184e-001,1.825000e+000,,,,,,,,,,,,,,,,,,0,4.000000e+000,1.000000e+000,2,2,3.922119e-001,0,,0,
1661186480.140,,6.000000e+004,3.552285e+002,2.893114e-003,1.411162e-005,-1.013058e-001,4.707487e-004,3,9.688630e-001,1.825000e+000,,,,,,,,,,,,,,,,,,0,4.000000e+000,1.000000e+000,2,2,4.464111e-001,0,,0,
1661187319.732,,6.000000e+004,3.832331e+002,3.498496e-003,1.088245e-006,-1.281540e-001,1.097082e-004,3,9.770961e-001,1.825000e+000,,,,,,,,,,,,,,,,,,0,4.000000e+000,1.000000e+000,2,2,4.042053e-001,0,,0,
1661188720.119,,5.500000e+004,3.894500e+002,3.172000e-003,4.129403e-006,-1.203089e-001,1.558432e-004,3,9.769328e-001,1.825000e+000,,,,,,,,,,,,,,,,,,0,4.000000e+000,1.000000e+000,2,2,7.251892e-001,0,,0,
1661189510.013,,5.500000e+004,3.618765e+002,3.358497e-003,3.427724e-007,-1.102274e-001,7.707078e-005,3,9.782339e-001,1.825000e+000,,,,,,,,,,,,,,,,,,0,4.000000e+000,1.000000e+000,2,2,2.004089e-001,0,,0,
1661190442.307,,5.500000e+004,3.336298e+002,2.445643e-003,4.999390e-005,-7.730073e-002,1.547580e-003,3,9.619033e-001,1.825000e+000,,,,,,,,,,,,,,,,,,0,4.000000e+000,1.000000e+000,2,2,6.932983e-001,0,,0,
1661191359.113,,5.500000e+004,3.057456e+002,1.663547e-003,4.675666e-008,-3.729068e-002,2.482845e-004,3,9.419490e-001,1.825000e+000,,,,,,,,,,,,,,,,,,0,4.000000e+000,1.000000e+000,2,2,5.089111e-001,0,,0,
1661192640.477,,5.500000e+004,3.213123e+002,1.651529e-003,3.240862e-007,-4.708031e-002,7.720512e-005,3,9.428259e-001,1.825000e+000,,,,,,,,,,,,,,,,,,0,4.000000e+000,1.000000e+000,2,2,4.102173e-001,0,,0,
1661193476.334,,5.500000e+004,3.492155e+002,2.252271e-003,8.743825e-006,-8.692617e-002,2.171722e-004,3,9.615024e-001,1.825000e+000,,,,,,,,,,,,,,,,,,0,4.000000e+000,1.000000e+000,2,2,4.110107e-001,0,,0,
1661194318.049,,5.500000e+004,3.772827e+002,3.243057e-003,7.309844e-007,-1.269260e-001,1.123319e-004,3,9.767979e-001,1.825000e+000,,,,,,,,,,,,,,,,,,0,4.000000e+000,1.000000e+000,2,2,4.258118e-001,0,,0,
1661195803.306,,5.000000e+004,3.955719e+002,2.840490e-003,1.458841e-006,-1.243281e-001,1.594731e-004,3,9.761161e-001,1.825000e+000,,,,,,,,,,,,,,,,,,0,4.000000e+000,1.000000e+000,2,2,7.489014e-001,0,,0,
1661196542.359,,5.000000e+004,3.673729e+002,3.021311e-003,2.486170e-006,-1.125799e-001,4.094566e-005,3,9.777577e-001,1.825000e+000,,,,,,,,,,,,,,,,,,0,4.000000e+000,1.000000e+000,2,2,6.640015e-001,0,,0,
1661197529.718,,5.000000e+004,3.395832e+002,2.998062e-003,9.027493e-006,-1.013785e-001,3.808863e-004,3,9.706333e-001,1.825000e+000,,,,,,,,,,,,,,,,,,0,4.000000e+000,1.000000e+000,2,2,6.550293e-001,0,,0,
1661198249.204,,5.000000e+004,3.117286e+002,1.543329e-003,3.009548e-007,-4.002501e-002,1.807415e-004,3,9.435239e-001,1.825000e+000,,,,,,,,,,,,,,,,,,0,4.000000e+000,1.000000e+000,2,2,4.615173e-001,0,,0,
1661199630.315,,5.000000e+004,3.152329e+002,1.527516e-003,4.371097e-008,-4.633167e-002,5.663483e-005,3,9.429457e-001,1.825000e+000,,,,,,,,,,,,,,,,,,0,4.000000e+000,1.000000e+000,2,2,3.859253e-001,0,,0,
1661200471.922,,5.000000e+004,3.432454e+002,1.795606e-003,4.697892e-006,-7.383762e-002,2.633019e-004,3,9.546942e-001,1.825000e+000,,,,,,,,,,,,,,,,,,0,4.000000e+000,1.000000e+000,2,2,4.247131e-001,0,,0,
1661201310.872,,5.000000e+004,3.712269e+002,2.980152e-003,1.565360e-006,-1.256598e-001,5.942706e-005,3,9.769465e-001,1.825000e+000,,,,,,,,,,,,,,,,,,0,4.000000e+000,1.000000e+000,2,2,4.226990e-001,0,,0,
1661202152.440,,5.000000e+004,3.992764e+002,2.823111e-003,8.095158e-007,-1.321028e-001,5.073427e-005,3,9.765084e-001,1.825000e+000,,,,,,,,,,,,,,,,,,0,4.000000e+000,1.000000e+000,2,2,3.999023e-001,0,,0,
1661203628.422,,4.500000e+004,3.732661e+002,2.683361e-003,2.256832e-006,-1.158655e-001,2.254856e-006,3,9.775378e-001,1.825000e+000,,,,,,,,,,,,,,,,,,0,4.000000e+000,1.000000e+000,2,2,8.665771e-001,0,,0,
1661204351.073,,4.500000e+004,3.457081e+002,2.790580e-003,2.230820e-007,-1.048826e-001,5.620282e-005,3,9.745890e-001,1.825000e+000,,,,,,,,,,,,,,,,,,0,4.000000e+000,1.000000e+000,2,2,4.311218e-001,0,,0,
1661205297.770,,4.500000e+004,3.175551e+002,1.423771e-003,9.743989e-007,-4.509291e-002,1.330997e-004,3,9.447970e-001,1.825000e+000,,,,,,,,,,,,,,,,,,0,4.000000e+000,1.000000e+000,2,2,6.322021e-001,0,,0,
1661206620.015,,4.500000e+004,3.092503e+002,1.402695e-003,5.325985e-008,-4.505152e-002,1.685795e-004,3,9.441037e-001,1.825000e+000,,,,,,,,,,,,,,,,,,0,4.000000e+000,1.000000e+000,2,2,4.385986e-001,0,,0,
1661207461.932,,4.500000e+004,3.372635e+002,1.501018e-003,1.702749e-006,-6.450449e-002,2.291366e-004,3,9.500397e-001,1.825000e+000,,,,,,,,,,,,,,,,,,0,4.000000e+000,1.000000e+000,2,2,4.002075e-001,0,,0,
1661208299.051,,4.500000e+004,3.652093e+002,2.675002e-003,2.656075e-006,-1.220590e-001,1.739400e-004,3,9.752997e-001,1.825000e+000,,,,,,,,,,,,,,,,,,0,4.000000e+000,1.000000e+000,2,2,4.192810e-001,0,,0,
1661209140.177,,4.500000e+004,3.932120e+002,2.573855e-003,9.305234e-007,-1.307306e-001,3.681527e-005,3,9.769336e-001,1.825000e+000,,,,,,,,,,,,,,,,,,0,4.000000e+000,1.000000e+000,2,2,4.138794e-001,0,,0,
1661210693.173,,4.000000e+004,3.797271e+002,2.353676e-003,6.796179e-007,-1.188572e-001,3.510306e-005,3,9.775429e-001,1.825000e+000,,,,,,,,,,,,,,,,,,0,4.000000e+000,1.000000e+000,2,2,3.848877e-001,0,,0,
1661211410.622,,4.000000e+004,3.514770e+002,2.469906e-003,1.323181e-006,-1.078132e-001,3.157853e-005,3,9.757268e-001,1.825000e+000,,,,,,,,,,,,,,,,,,0,4.000000e+000,1.000000e+000,2,2,8.133850e-001,0,,0,
1661212400.925,,4.000000e+004,3.239189e+002,1.319586e-003,9.446821e-007,-5.093892e-002,1.167257e-004,3,9.480591e-001,1.825000e+000,,,,,,,,,,,,,,,,,,0,4.000000e+000,1.000000e+000,2,2,1.502991e-001,0,,0,
1661214960.963,,4.000000e+004,3.033241e+002,1.267930e-003,2.216826e-007,-4.526821e-002,1.343273e-004,3,9.432899e-001,1.825000e+000,,,,,,,,,,,,,,,,,,0,4.000000e+000,1.000000e+000,2,2,4.206848e-001,0,,0,
1661215769.559,,4.000000e+004,3.312680e+002,1.286114e-003,1.164307e-006,-5.987821e-002,1.132697e-004,3,9.469084e-001,1.825000e+000,,,,,,,,,,,,,,,,,,0,4.000000e+000,1.000000e+000,2,2,4.114990e-001,0,,0,
1661216610.311,,4.000000e+004,3.592910e+002,2.237742e-003,4.765063e-006,-1.156229e-001,3.570154e-004,3,9.732131e-001,1.825000e+000,,,,,,,,,,,,,,,,,,0,4.000000e+000,1.000000e+000,2,2,4.052124e-001,0,,0,
1661217449.810,,4.000000e+004,3.872896e+002,2.318226e-003,9.124134e-007,-1.307034e-001,1.657320e-004,3,9.772068e-001,1.825000e+000,,,,,,,,,,,,,,,,,,0,4.000000e+000,1.000000e+000,2,2,3.644714e-001,0,,0,
1661218792.674,,3.500000e+004,3.856113e+002,2.044069e-003,1.701844e-006,-1.194253e-001,5.257293e-005,3,9.781104e-001,1.825000e+000,,,,,,,,,,,,,,,,,,0,4.000000e+000,1.000000e+000,2,2,6.864014e-001,0,,0,
1661219824.448,,3.500000e+004,3.574699e+002,2.139577e-003,8.256502e-007,-1.115487e-001,1.444952e-004,3,9.760844e-001,1.825000e+000,,,,,,,,,,,,,,,,,,0,4.000000e+000,1.000000e+000,2,2,8.221741e-001,0,,0,
1661220529.789,,3.500000e+004,3.296418e+002,1.327381e-003,1.143949e-005,-6.511509e-002,9.071899e-004,3,9.560192e-001,1.825000e+000,,,,,,,,,,,,,,,,,,0,4.000000e+000,1.000000e+000,2,2,6.238708e-001,0,,0,
1661221459.622,,3.500000e+004,3.016675e+002,1.132137e-003,1.013336e-007,-4.329393e-002,4.994401e-006,3,9.441601e-001,1.825000e+000,,,,,,,,,,,,,,,,,,0,4.000000e+000,1.000000e+000,2,2,6.164856e-001,0,,0,
1661222766.751,,3.500000e+004,3.252434e+002,1.125760e-003,7.624299e-007,-5.642677e-002,3.345510e-007,3,9.463928e-001,1.825000e+000,,,,,,,,,,,,,,,,,,0,4.000000e+000,1.000000e+000,2,2,3.705139e-001,0,,0,
1661223606.339,,3.500000e+004,3.532595e+002,1.704767e-003,7.533502e-006,-1.033163e-001,2.525703e-004,3,9.681785e-001,1.825000e+000,,,,,,,,,,,,,,,,,,0,4.000000e+000,1.000000e+000,2,2,4.111023e-001,0,,0,
1661224450.219,,3.500000e+004,3.814026e+002,2.055027e-003,9.499504e-007,-1.289981e-001,3.129825e-004,3,9.775867e-001,1.825000e+000,,,,,,,,,,,,,,,,,,0,4.000000e+000,1.000000e+000,2,2,4.120178e-001,0,,0,
1661225868.925,,3.000000e+004,3.914523e+002,1.731007e-003,1.325485e-006,-1.225533e-001,1.421455e-004,3,9.777824e-001,1.825000e+000,,,,,,,,,,,,,,,,,,0,4.000000e+000,1.000000e+000,2,2,9.566040e-001,0,,0,
1661226620.705,,3.000000e+004,3.636920e+002,1.834229e-003,4.939084e-007,-1.117647e-001,1.234481e-004,3,9.790826e-001,1.825000e+000,,,,,,,,,,,,,,,,,,0,4.000000e+000,1.000000e+000,2,2,4.475708e-001,0,,0,
1661227597.803,,3.000000e+004,3.354763e+002,1.604140e-003,2.747612e-005,-9.433462e-002,1.554270e-003,3,9.673703e-001,1.825000e+000,,,,,,,,,,,,,,,,,,0,4.000000e+000,1.000000e+000,2,2,8.293152e-001,0,,0,
1661228437.916,,3.000000e+004,3.079238e+002,9.803178e-004,1.634837e-007,-4.629116e-002,2.770023e-004,3,9.464207e-001,1.825000e+000,,,,,,,,,,,,,,,,,,0,4.000000e+000,1.000000e+000,2,2,1.274109e-001,0,,0,
1661229754.667,,3.000000e+004,3.192488e+002,9.735051e-004,9.752633e-007,-5.435497e-002,6.032325e-007,3,9.468043e-001,1.825000e+000,,,,,,,,,,,,,,,,,,0,4.000000e+000,1.000000e+000,2,2,3.640747e-001,0,,0,
1661230594.197,,3.000000e+004,3.472578e+002,1.244938e-003,3.798238e-006,-8.903544e-002,5.129430e-004,3,9.609818e-001,1.825000e+000,,,,,,,,,,,,,,,,,,0,4.000000e+000,1.000000e+000,2,2,3.480835e-001,0,,0,
1661231435.045,,3.000000e+004,3.753058e+002,1.785732e-003,1.776424e-007,-1.271778e-001,4.669028e-004,3,9.777498e-001,1.825000e+000,,,,,,,,,,,,,,,,,,0,4.000000e+000,1.000000e+000,2,2,3.641968e-001,0,,0,
1661232919.265,,2.500000e+004,3.977879e+002,1.426098e-003,3.706782e-007,-1.262279e-001,6.440671e-004,3,9.784548e-001,1.825000e+000,,,,,,,,,,,,,,,,,,0,4.000000e+000,1.000000e+000,2,2,3.587952e-001,0,,0,
1661233682.715,,2.500000e+004,3.692633e+002,1.515693e-003,1.548732e-006,-1.146491e-001,1.364135e-004,3,9.789722e-001,1.825000e+000,,,,,,,,,,,,,,,,,,0,4.000000e+000,1.000000e+000,2,2,8.361206e-001,0,,0,
1661234650.018,,2.500000e+004,3.417776e+002,1.531980e-003,6.376357e-007,-1.053726e-001,4.803160e-005,3,9.718427e-001,1.825000e+000,,,,,,,,,,,,,,,,,,0,4.000000e+000,1.000000e+000,2,2,4.114990e-001,0,,0,
1661235372.650,,2.500000e+004,3.136835e+002,8.294048e-004,4.181346e-007,-4.860196e-002,6.238024e-004,3,9.480440e-001,1.825000e+000,,,,,,,,,,,,,,,,,,0,4.000000e+000,1.000000e+000,2,2,5.769043e-001,0,,0,
1661236736.921,,2.500000e+004,3.132398e+002,8.195350e-004,3.552027e-008,-5.350560e-002,4.261626e-004,3,9.454836e-001,1.825000e+000,,,,,,,,,,,,,,,,,,0,4.000000e+000,1.000000e+000,2,2,3.573914e-001,0,,0,
1661237584.814,,2.500000e+004,3.413853e+002,9.259275e-004,2.601415e-006,-7.653622e-002,1.617422e-003,3,9.555859e-001,1.825000e+000,,,,,,,,,,,,,,,,,,0,4.000000e+000,1.000000e+000,2,2,4.291992e-001,0,,0,
1661238420.593,,2.500000e+004,3.692632e+002,1.503089e-003,5.177813e-008,-1.258922e-001,1.599051e-004,3,9.773802e-001,1.825000e+000,,,,,,,,,,,,,,,,,,0,4.000000e+000,1.000000e+000,2,2,3.741150e-001,0,,0,
1661239258.291,,2.500000e+004,3.971735e+002,1.429494e-003,6.688343e-007,-1.327243e-001,2.413223e-004,3,9.780077e-001,1.825000e+000,,,,,,,,,,,,,,,,,,0,4.000000e+000,1.000000e+000,2,2,3.580017e-001,0,,0,
1661240772.234,,2.000000e+004,3.753914e+002,1.198210e-003,1.404922e-006,-1.181599e-001,4.902943e-004,3,9.787405e-001,1.825000e+000,,,,,,,,,,,,,,,,,,0,4.000000e+000,1.000000e+000,2,2,8.197937e-001,0,,0,
1661241478.450,,2.000000e+004,3.476379e+002,1.249019e-003,6.689989e-007,-1.070349e-001,3.814817e-005,3,9.763507e-001,1.825000e+000,,,,,,,,,,,,,,,,,,0,4.000000e+000,1.000000e+000,2,2,6.008911e-001,0,,0,
1661242441.151,,2.000000e+004,3.196662e+002,6.786639e-004,4.968718e-007,-5.405448e-002,5.889232e-005,3,9.487457e-001,1.825000e+000,,,,,,,,,,,,,,,,,,0,4.000000e+000,1.000000e+000,2,2,7.058105e-001,0,,0,
1661243730.969,,2.000000e+004,3.072774e+002,6.669801e-004,9.548896e-008,-5.166756e-002,7.213723e-004,3,9.460478e-001,1.825000e+000,,,,,,,,,,,,,,,,,,0,4.000000e+000,1.000000e+000,2,2,4.772034e-001,0,,0,
1661244566.241,,2.000000e+004,3.352623e+002,6.981359e-004,8.738474e-007,-6.981878e-002,2.996483e-004,3,9.517044e-001,1.825000e+000,,,,,,,,,,,,,,,,,,0,4.000000e+000,1.000000e+000,2,2,3.682251e-001,0,,0,
1661245405.117,,2.000000e+004,3.632264e+002,1.193348e-003,1.000247e-006,-1.225844e-001,8.198089e-005,3,9.760471e-001,1.825000e+000,,,,,,,,,,,,,,,,,,0,4.000000e+000,1.000000e+000,2,2,4.145203e-001,0,,0,
1661246246.300,,2.000000e+004,3.912595e+002,1.160375e-003,6.450443e-007,-1.321736e-001,5.766742e-005,3,9.780256e-001,1.825000e+000,,,,,,,,,,,,,,,,,,0,4.000000e+000,1.000000e+000,2,2,3.600159e-001,0,,0,
1661247536.345,,1.500000e+004,3.817560e+002,8.932444e-004,9.223740e-008,-1.195219e-001,3.234929e-004,3,9.788799e-001,1.825000e+000,,,,,,,,,,,,,,,,,,0,4.000000e+000,1.000000e+000,2,2,3.891907e-001,0,,0,
1661248542.364,,1.500000e+004,3.534201e+002,9.325130e-004,5.256009e-007,-1.111937e-001,1.092341e-004,3,9.766530e-001,1.825000e+000,,,,,,,,,,,,,,,,,,0,4.000000e+000,1.000000e+000,2,2,8.131104e-001,0,,0,
1661249296.079,,1.500000e+004,3.258571e+002,5.429843e-004,7.373641e-007,-6.054946e-002,4.251142e-004,3,9.533046e-001,1.825000e+000,,,,,,,,,,,,,,,,,,0,4.000000e+000,1.000000e+000,2,2,2.620850e-001,0,,0,
1661250731.643,,1.500000e+004,3.011719e+002,5.118941e-004,9.050872e-008,-5.046472e-002,1.540996e-006,3,9.467058e-001,1.825000e+000,,,,,,,,,,,,,,,,,,0,4.000000e+000,1.000000e+000,2,2,3.286133e-001,0,,0,
1661251544.554,,1.500000e+004,3.292653e+002,5.142965e-004,1.135166e-007,-6.451738e-002,8.481526e-005,3,9.495817e-001,1.825000e+000,,,,,,,,,,,,,,,,,,0,4.000000e+000,1.000000e+000,2,2,3.457031e-001,0,,0,
1661252384.321,,1.500000e+004,3.572720e+002,8.293268e-004,2.359442e-006,-1.148048e-001,5.571708e-004,3,9.728117e-001,1.825000e+000,,,,,,,,,,,,,,,,,,0,4.000000e+000,1.000000e+000,2,2,4.003906e-001,0,,0,
1661253223.596,,1.500000e+004,3.852472e+002,8.840189e-004,2.592196e-007,-1.309979e-001,2.966085e-005,3,9.784827e-001,1.825000e+000,,,,,,,,,,,,,,,,,,0,4.000000e+000,1.000000e+000,2,2,3.605042e-001,0,,0,
1661254579.745,,1.000000e+004,3.874964e+002,5.932562e-004,2.873312e-007,-1.234579e-001,2.018518e-004,3,9.789950e-001,1.825000e+000,,,,,,,,,,,,,,,,,,0,4.000000e+000,1.000000e+000,2,2,7.541809e-001,0,,0,
1661255609.335,,1.000000e+004,3.597045e+002,6.201447e-004,8.573427e-008,-1.147531e-001,4.336384e-005,3,9.772782e-001,1.825000e+000,,,,,,,,,,,,,,,,,,0,4.000000e+000,1.000000e+000,2,2,4.582214e-001,0,,0,
1661256318.141,,1.000000e+004,3.315924e+002,4.369863e-004,5.849995e-006,-8.119354e-002,3.280921e-004,3,9.600468e-001,1.825000e+000,,,,,,,,,,,,,,,,,,0,4.000000e+000,1.000000e+000,2,2,7.106018e-001,0,,0,
1661257246.998,,1.000000e+004,3.036964e+002,3.480907e-004,8.268849e-008,-5.602900e-002,9.508145e-003,3,9.455478e-001,1.825000e+000,,,,,,,,,,,,,,,,,,0,4.000000e+000,1.000000e+000,2,2,5.235901e-001,0,,0,
1661258528.190,,1.000000e+004,3.232422e+002,3.457410e-004,1.243414e-007,-6.423014e-002,1.188488e-004,3,9.490161e-001,1.825000e+000,,,,,,,,,,,,,,,,,,0,4.000000e+000,1.000000e+000,2,2,3.573914e-001,0,,0,
1661259367.377,,1.000000e+004,3.512513e+002,4.797088e-004,1.476848e-006,-1.038674e-001,1.419032e-004,3,9.666283e-001,1.825000e+000,,,,,,,,,,,,,,,,,,0,4.000000e+000,1.000000e+000,2,2,3.665161e-001,0,,0,
1661260207.239,,1.000000e+004,3.792408e+002,6.012683e-004,1.952173e-007,-1.309259e-001,4.468514e-004,3,9.786526e-001,1.825000e+000,,,,,,,,,,,,,,,,,,0,4.000000e+000,1.000000e+000,2,2,4.186096e-001,0,,0,
1661261640.037,,9.000000e+003,3.934883e+002,5.273502e-004,4.278070e-007,-1.267417e-001,2.924675e-004,3,9.782649e-001,1.825000e+000,,,,,,,,,,,,,,,,,,0,4.000000e+000,1.000000e+000,2,2,8.414001e-001,0,,0,
1661262380.959,,9.000000e+003,3.655591e+002,5.592106e-004,4.897101e-007,-1.153979e-001,7.652814e-005,3,9.795741e-001,1.825000e+000,,,,,,,,,,,,,,,,,,0,4.000000e+000,1.000000e+000,2,2,6.571960e-001,0,,0,
1661263376.407,,9.000000e+003,3.374184e+002,5.290479e-004,4.635865e-006,-1.033722e-001,7.001961e-004,3,9.703617e-001,1.825000e+000,,,,,,,,,,,,,,,,,,0,4.000000e+000,1.000000e+000,2,2,8.188782e-001,0,,0,
1661264103.561,,9.000000e+003,3.097918e+002,3.167199e-004,7.295439e-008,-5.515779e-002,1.326743e-003,3,9.495109e-001,1.825000e+000,,,,,,,,,,,,,,,,,,0,4.000000e+000,1.000000e+000,2,2,3.794250e-001,0,,0,
1661265494.272,,9.000000e+003,3.172592e+002,3.132189e-004,3.414142e-007,-6.209398e-002,2.769469e-004,3,9.479803e-001,1.825000e+000,,,,,,,,,,,,,,,,,,0,4.000000e+000,1.000000e+000,2,2,3.592834e-001,0,,0,
1661266334.806,,9.000000e+003,3.452584e+002,3.757600e-004,1.049802e-006,-9.047346e-002,1.865841e-004,3,9.605001e-001,1.825000e+000,,,,,,,,,,,,,,,,,,0,4.000000e+000,1.000000e+000,2,2,4.107971e-001,0,,0,
1661267173.542,,9.000000e+003,3.732322e+002,5.476509e-004,2.278564e-007,-1.295751e-001,1.010260e-004,3,9.783896e-001,1.825000e+000,,,,,,,,,,,,,,,,,,0,4.000000e+000,1.000000e+000,2,2,3.937988e-001,0,,0,
1661268595.050,,8.000000e+003,4.000032e+002,4.645343e-004,4.780622e-008,-1.314187e-001,2.428501e-004,3,9.783918e-001,1.825000e+000,,,,,,,,,,,,,,,,,,0,4.000000e+000,1.000000e+000,2,2,1.290894e-002,0,,0,
1661269437.581,,8.000000e+003,3.711603e+002,4.925465e-004,5.202090e-007,-1.181618e-001,1.249022e-004,3,9.792457e-001,1.825000e+000,,,,,,,,,,,,,,,,,,0,4.000000e+000,1.000000e+000,2,2,8.897095e-001,0,,0,
1661270192.033,,8.000000e+003,3.438268e+002,5.063555e-004,2.175255e-007,-1.073378e-001,1.247125e-004,3,9.749807e-001,1.825000e+000,,,,,,,,,,,,,,,,,,0,4.000000e+000,1.000000e+000,2,2,2.556152e-001,0,,0,
1661271115.594,,8.000000e+003,3.155721e+002,2.853307e-004,2.181429e-008,-5.814709e-002,1.209167e-003,3,9.506316e-001,1.825000e+000,,,,,,,,,,,,,,,,,,0,4.000000e+000,1.000000e+000,2,2,6.632080e-001,0,,0,
1661272457.929,,8.000000e+003,3.112640e+002,2.818850e-004,9.096146e-009,-6.115189e-002,1.967389e-004,3,9.473424e-001,1.825000e+000,,,,,,,,,,,,,,,,,,0,4.000000e+000,1.000000e+000,2,2,3.756104e-001,0,,0,
1661273301.329,,8.000000e+003,3.392329e+002,3.062599e-004,4.935174e-007,-8.137728e-002,5.633190e-004,3,9.557315e-001,1.825000e+000,,,,,,,,,,,,,,,,,,0,4.000000e+000,1.000000e+000,2,2,4.142151e-001,0,,0,
1661274140.449,,8.000000e+003,3.672150e+002,4.906583e-004,1.340550e-007,-1.276705e-001,3.276707e-004,3,9.770803e-001,1.825000e+000,,,,,,,,,,,,,,,,,,0,4.000000e+000,1.000000e+000,2,2,4.023132e-001,0,,0,
1661274980.114,,8.000000e+003,3.952262e+002,4.689546e-004,2.068242e-008,-1.357076e-001,1.084649e-004,3,9.784077e-001,1.825000e+000,,,,,,,,,,,,,,,,,,0,4.000000e+000,1.000000e+000,2,2,4.055176e-001,0,,0,
1661276509.992,,7.000000e+003,3.775793e+002,4.269909e-004,3.900436e-007,-1.220430e-001,5.968520e-005,3,9.785759e-001,1.825000e+000,,,,,,,,,,,,,,,,,,0,4.000000e+000,1.000000e+000,2,2,6.685791e-001,0,,0,
1661277215.782,,7.000000e+003,3.495488e+002,4.450573e-004,8.546673e-008,-1.105171e-001,5.448902e-004,3,9.759526e-001,1.825000e+000,,,,,,,,,,,,,,,,,,0,4.000000e+000,1.000000e+000,2,2,7.453003e-001,0,,0,
1661278172.603,,7.000000e+003,3.216306e+002,2.567563e-004,3.668710e-007,-6.424312e-002,2.839064e-004,3,9.512935e-001,1.825000e+000,,,,,,,,,,,,,,,,,,0,4.000000e+000,1.000000e+000,2,2,6.329956e-001,0,,0,
1661279456.185,,7.000000e+003,3.052944e+002,2.515859e-004,1.905663e-008,-5.921093e-002,3.807230e-004,3,9.480700e-001,1.825000e+000,,,,,,,,,,,,,,,,,,0,4.000000e+000,1.000000e+000,2,2,4.559937e-001,0,,0,
1661280279.381,,7.000000e+003,3.332037e+002,2.580979e-004,1.168505e-007,-7.554056e-002,4.860375e-004,3,9.519868e-001,1.825000e+000,,,,,,,,,,,,,,,,,,0,4.000000e+000,1.000000e+000,2,2,3.722229e-001,0,,0,
1661281127.096,,7.000000e+003,3.614946e+002,4.220545e-004,6.797208e-007,-1.237405e-001,2.127151e-004,3,9.754243e-001,1.825000e+000,,,,,,,,,,,,,,,,,,0,4.000000e+000,1.000000e+000,2,2,4.208984e-001,0,,0,
1661281959.044,,7.000000e+003,3.892195e+002,4.174494e-004,1.385001e-007,-1.340596e-001,2.034007e-004,3,9.787167e-001,1.825000e+000,,,,,,,,,,,,,,,,,,0,4.000000e+000,1.000000e+000,2,2,4.174194e-001,0,,0,
1661283262.459,,6.000000e+003,3.836736e+002,3.645234e-004,1.742262e-007,-1.227520e-001,9.335527e-005,3,9.788865e-001,1.825000e+000,,,,,,,,,,,,,,,,,,0,4.000000e+000,1.000000e+000,2,2,5.720215e-001,0,,0,
1661284285.964,,6.000000e+003,3.553886e+002,3.800011e-004,2.965302e-007,-1.139222e-001,2.109134e-004,3,9.764259e-001,1.825000e+000,,,,,,,,,,,,,,,,,,0,4.000000e+000,1.000000e+000,2,2,9.036865e-001,0,,0,
1661285010.508,,6.000000e+003,3.277389e+002,2.386377e-004,8.050604e-007,-7.124227e-002,1.803253e-004,3,9.557843e-001,1.825000e+000,,,,,,,,,,,,,,,,,,0,4.000000e+000,1.000000e+000,2,2,3.936157e-001,0,,0,
1661286184.770,,6.000000e+003,3.000671e+002,2.203433e-004,4.506914e-008,-5.741015e-002,7.966966e-004,3,9.481114e-001,1.825000e+000,,,,,,,,,,,,,,,,,,0,4.000000e+000,1.000000e+000,2,2,1.422119e-002,0,,0,
1661287261.200,,6.000000e+003,3.272327e+002,2.192834e-004,1.228597e-007,-7.248768e-002,6.058873e-004,3,9.501859e-001,1.825000e+000,,,,,,,,,,,,,,,,,,0,4.000000e+000,1.000000e+000,2,2,4.179993e-001,0,,0,
1661288100.136,,6.000000e+003,3.552158e+002,3.269377e-004,1.103577e-006,-1.149481e-001,2.901811e-004,3,9.707267e-001,1.825000e+000,,,,,,,,,,,,,,,,,,0,4.000000e+000,1.000000e+000,2,2,4.158936e-001,0,,0,
1661288940.110,,6.000000e+003,3.832420e+002,3.636288e-004,7.328366e-008,-1.337301e-001,2.893592e-004,3,9.784790e-001,1.825000e+000,,,,,,,,,,,,,,,,,,0,4.000000e+000,1.000000e+000,2,2,3.923035e-001,0,,0,
1661290322.297,,5.000000e+003,3.894316e+002,3.021052e-004,2.722053e-007,-1.263790e-001,8.858214e-005,3,9.785342e-001,1.825000e+000,,,,,,,,,,,,,,,,,,0,4.000000e+000,1.000000e+000,2,2,8.236084e-001,0,,0,
1661291110.262,,5.000000e+003,3.618448e+002,3.181903e-004,2.002388e-008,-1.156336e-001,1.433309e-004,3,9.792306e-001,1.825000e+000,,,,,,,,,,,,,,,,,,0,4.000000e+000,1.000000e+000,2,2,2.214050e-001,0,,0,
1661292052.632,,5.000000e+003,3.334300e+002,2.497424e-004,3.766072e-006,-9.346484e-002,1.209588e-003,3,9.635484e-001,1.825000e+000,,,,,,,,,,,,,,,,,,0,4.000000e+000,1.000000e+000,2,2,7.631836e-001,0,,0,
1661292963.813,,5.000000e+003,3.057695e+002,1.852237e-004,1.053980e-007,-6.082145e-002,3.576871e-004,3,9.475362e-001,1.825000e+000,,,,,,,,,,,,,,,,,,0,4.000000e+000,1.000000e+000,2,2,4.723206e-001,0,,0,
1661294249.389,,5.000000e+003,3.214149e+002,1.842363e-004,2.012677e-008,-7.142654e-002,1.068950e-005,3,9.501498e-001,1.825000e+000,,,,,,,,,,,,,,,,,,0,4.000000e+000,1.000000e+000,2,2,4.104004e-001,0,,0,
1661295082.617,,5.000000e+003,3.492107e+002,2.373178e-004,9.607547e-007,-1.031979e-001,8.210206e-005,3,9.643742e-001,1.825000e+000,,,,,,,,,,,,,,,,,,0,4.000000e+000,1.000000e+000,2,2,4.012146e-001,0,,0,
1661295923.161,,5.000000e+003,3.772625e+002,3.083600e-004,1.609936e-007,-1.329743e-001,1.212280e-003,3,9.782047e-001,1.825000e+000,,,,,,,,,,,,,,,,,,0,4.000000e+000,1.000000e+000,2,2,4.141846e-001,0,,0,
1661297388.685,,4.000000e+003,3.955370e+002,2.403393e-004,1.808631e-007,-1.307797e-001,4.100572e-004,3,9.779069e-001,1.825000e+000,,,,,,,,,,,,,,,,,,0,4.000000e+000,1.000000e+000,2,2,8.374939e-001,0,,0,
1661298125.746,,4.000000e+003,3.675635e+002,2.550270e-004,1.561987e-008,-1.187984e-001,7.832465e-005,3,9.795225e-001,1.825000e+000,,,,,,,,,,,,,,,,,,0,4.000000e+000,1.000000e+000,2,2,7.299194e-001,0,,0,
1661299112.305,,4.000000e+003,3.396478e+002,2.513470e-004,7.094582e-007,-1.086311e-001,7.781364e-006,3,9.707466e-001,1.825000e+000,,,,,,,,,,,,,,,,,,0,4.000000e+000,1.000000e+000,2,2,6.369019e-001,0,,0,
1661299836.677,,4.000000e+003,3.117189e+002,1.516199e-004,4.634507e-008,-6.403504e-002,1.310978e-004,3,9.513576e-001,1.825000e+000,,,,,,,,,,,,,,,,,,0,4.000000e+000,1.000000e+000,2,2,5.307007e-001,0,,0,
1661301216.714,,4.000000e+003,3.152526e+002,1.500011e-004,3.766051e-009,-7.034746e-002,1.146911e-003,3,9.487604e-001,1.825000e+000,,,,,,,,,,,,,,,,,,0,4.000000e+000,1.000000e+000,2,2,4.489746e-001,0,,0,
1661302057.595,,4.000000e+003,3.432218e+002,1.709003e-004,4.870348e-007,-9.341818e-002,5.050246e-004,3,9.586930e-001,1.825000e+000,,,,,,,,,,,,,,,,,,0,4.000000e+000,1.000000e+000,2,2,4.151917e-001,0,,0,
1661302897.361,,4.000000e+003,3.712324e+002,2.511230e-004,7.110223e-008,-1.317673e-001,4.576094e-004,3,9.775737e-001,1.825000e+000,,,,,,,,,,,,,,,,,,0,4.000000e+000,1.000000e+000,2,2,4.226990e-001,0,,0,
1661303738.499,,4.000000e+003,3.992409e+002,2.389662e-004,1.146382e-007,-1.384147e-001,1.292749e-004,3,9.781508e-001,1.825000e+000,,,,,,,,,,,,,,,,,,0,4.000000e+000,1.000000e+000,2,2,4.127808e-001,0,,0,
1661305207.275,,3.000000e+003,3.730610e+002,1.915248e-004,1.027124e-007,-1.230276e-001,9.689033e-005,3,9.786507e-001,1.825000e+000,,,,,,,,,,,,,,,,,,0,4.000000e+000,1.000000e+000,2,2,1.034424e+000,0,,0,
1661305927.932,,3.000000e+003,3.456602e+002,1.974646e-004,7.185338e-008,-1.113227e-001,1.447955e-004,3,9.749339e-001,1.825000e+000,,,,,,,,,,,,,,,,,,0,4.000000e+000,1.000000e+000,2,2,5.267029e-001,0,,0,
1661306876.195,,3.000000e+003,3.174751e+002,1.174530e-004,1.157238e-007,-6.936957e-002,6.293051e-005,3,9.515644e-001,1.825000e+000,,,,,,,,,,,,,,,,,,0,4.000000e+000,1.000000e+000,2,2,7.198181e-001,0,,0,
1661308200.363,,3.000000e+003,3.092711e+002,1.161192e-004,9.885370e-008,-6.949544e-002,8.414618e-005,3,9.483804e-001,1.825000e+000,,,,,,,,,,,,,,,,,,0,4.000000e+000,1.000000e+000,2,2,4.385986e-001,0,,0,
1661309041.490,,3.000000e+003,3.372658e+002,1.225332e-004,5.928959e-008,-8.905062e-002,1.389676e-003,3,9.536288e-001,1.825000e+000,,,,,,,,,,,,,,,,,,0,4.000000e+000,1.000000e+000,2,2,3.910217e-001,0,,0,
1661309880.309,,3.000000e+003,3.652174e+002,1.912160e-004,1.636072e-008,-1.302230e-001,2.932683e-004,3,9.764669e-001,1.825000e+000,,,,,,,,,,,,,,,,,,0,4.000000e+000,1.000000e+000,2,2,4.515991e-001,0,,0,
1661310720.485,,3.000000e+003,3.932622e+002,1.841713e-004,2.171163e-009,-1.391629e-001,2.300691e-004,3,9.782729e-001,1.825000e+000,,,,,,,,,,,,,,,,,,0,4.000000e+000,1.000000e+000,2,2,3.889160e-001,0,,0,
1661312254.271,,2.500000e+003,3.797796e+002,1.589374e-004,9.295767e-008,-1.270526e-001,8.799208e-005,3,9.780018e-001,1.825000e+000,,,,,,,,,,,,,,,,,,0,4.000000e+000,1.000000e+000,2,2,4.317017e-001,0,,0,
1661312979.811,,2.500000e+003,3.511797e+002,1.654796e-004,1.614051e-007,-1.151808e-001,2.970352e-004,3,9.754606e-001,1.825000e+000,,,,,,,,,,,,,,,,,,0,4.000000e+000,1.000000e+000,2,2,8.121033e-001,0,,0,
1661313913.902,,2.500000e+003,3.237604e+002,1.019563e-004,1.169380e-007,-7.591711e-002,8.836666e-004,3,9.526854e-001,1.825000e+000,,,,,,,,,,,,,,,,,,0,4.000000e+000,1.000000e+000,2,2,4.502258e-001,0,,0,
1661315205.426,,2.500000e+003,3.032915e+002,9.938625e-005,1.773440e-008,-6.923340e-002,5.092815e-004,3,9.481019e-001,1.825000e+000,,,,,,,,,,,,,,,,,,0,4.000000e+000,1.000000e+000,2,2,4.931946e-001,0,,0,
1661316019.196,,2.500000e+003,3.312812e+002,1.006082e-004,5.182951e-008,-8.435862e-002,4.014118e-004,3,9.524091e-001,1.825000e+000,,,,,,,,,,,,,,,,,,0,4.000000e+000,1.000000e+000,2,2,4.114990e-001,0,,0,
1661316857.223,,2.500000e+003,3.592288e+002,1.537071e-004,3.232116e-007,-1.246993e-001,5.146235e-004,3,9.733468e-001,1.825000e+000,,,,,,,,,,,,,,,,,,0,4.000000e+000,1.000000e+000,2,2,4.049988e-001,0,,0,
1661317698.408,,2.500000e+003,3.872774e+002,1.567902e-004,2.995349e-008,-1.381187e-001,6.873413e-004,3,9.784427e-001,1.825000e+000,,,,,,,,,,,,,,,,,,0,4.000000e+000,1.000000e+000,2,2,4.010010e-001,0,,0,
1661319020.417,,2.000000e+003,3.855119e+002,1.279093e-004,1.437376e-007,-1.288113e-001,3.425380e-004,3,9.784797e-001,1.825000e+000,,,,,,,,,,,,,,,,,,0,4.000000e+000,1.000000e+000,2,2,6.980896e-001,0,,0,
1661320051.523,,2.000000e+003,3.575136e+002,1.328695e-004,7.222381e-008,-1.196491e-001,8.626459e-004,3,9.756347e-001,1.825000e+000,,,,,,,,,,,,,,,,,,0,4.000000e+000,1.000000e+000,2,2,8.739929e-001,0,,0,
1661320757.924,,2.000000e+003,3.296418e+002,9.144256e-005,6.812900e-007,-8.601606e-002,9.341427e-004,3,9.572440e-001,1.825000e+000,,,,,,,,,,,,,,,,,,0,4.000000e+000,1.000000e+000,2,2,6.930847e-001,0,,0,
1661321688.792,,2.000000e+003,3.016138e+002,8.174901e-005,1.683404e-008,-6.844348e-002,3.777727e-004,3,9.476979e-001,1.825000e+000,,,,,,,,,,,,,,,,,,0,4.000000e+000,1.000000e+000,2,2,6.880188e-001,0,,0,
1661322998.347,,2.000000e+003,3.252708e+002,8.141985e-005,4.146773e-008,-8.342075e-002,6.202962e-004,3,9.514317e-001,1.825000e+000,,,,,,,,,,,,,,,,,,0,4.000000e+000,1.000000e+000,2,2,4.126892e-001,0,,0,
1661323837.587,,2.000000e+003,3.532820e+002,1.113510e-004,5.940123e-007,-1.184601e-001,4.470132e-003,3,9.682618e-001,1.825000e+000,,,,,,,,,,,,,,,,,,0,4.000000e+000,1.000000e+000,2,2,4.411926e-001,0,,0,
1661324683.349,,2.000000e+003,3.814732e+002,1.285140e-004,1.165830e-008,-1.381058e-001,8.137503e-005,3,9.785305e-001,1.825000e+000,,,,,,,,,,,,,,,,,,0,4.000000e+000,1.000000e+000,2,2,4.592896e-001,0,,0,
1661326109.731,,1.500000e+003,3.897885e+002,9.682489e-005,1.736191e-007,-1.316090e-001,3.170391e-004,3,9.782338e-001,1.825000e+000,,,,,,,,,,,,,,,,,,0,4.000000e+000,1.000000e+000,2,2,9.237061e-001,0,,0,
1661326860.430,,1.500000e+003,3.627567e+002,1.016912e-004,4.806346e-008,-1.211620e-001,5.581191e-004,3,9.787301e-001,1.825000e+000,,,,,,,,,,,,,,,,,,0,4.000000e+000,1.000000e+000,2,2,4.241028e-001,0,,0,
1661327844.195,,1.500000e+003,3.340380e+002,8.340068e-005,3.050517e-006,-1.031511e-001,3.476151e-003,3,9.640319e-001,1.825000e+000,,,,,,,,,,,,,,,,,,0,4.000000e+000,1.000000e+000,2,2,1.621704e+000,0,,0,
1661328714.456,,1.500000e+003,3.068937e+002,6.309282e-005,1.123642e-008,-7.457601e-002,8.447440e-004,3,9.495846e-001,1.825000e+000,,,,,,,,,,,,,,,,,,0,4.000000e+000,1.000000e+000,2,2,2.305908e-001,0,,0,
1661330003.744,,1.500000e+003,3.202881e+002,6.264103e-005,1.133828e-007,-8.483087e-002,8.176331e-004,3,9.466698e-001,1.825000e+000,,,,,,,,,,,,,,,,,,0,4.000000e+000,1.000000e+000,2,2,3.829956e-001,0,,0,
1661330841.407,,1.500000e+003,3.482545e+002,7.661676e-005,2.508180e-007,-1.110859e-001,2.281204e-006,3,9.617398e-001,1.825000e+000,,,,,,,,,,,,,,,,,,0,4.000000e+000,1.000000e+000,2,2,4.475098e-001,0,,0,
1661331682.586,,1.500000e+003,3.762930e+002,9.897977e-005,6.678053e-008,-1.378685e-001,2.577385e-004,3,9.776163e-001,1.825000e+000,,,,,,,,,,,,,,,,,,0,4.000000e+000,1.000000e+000,2,2,3.890076e-001,0,,0,
1661333157.178,,1.000000e+003,3.966660e+002,6.538263e-005,2.519447e-008,-1.396602e-001,2.927415e-004,3,9.766563e-001,1.825000e+000,,,,,,,,,,,,,,,,,,0,4.000000e+000,1.000000e+000,2,2,5.484009e-001,0,,0,
1661333917.646,,1.000000e+003,3.677516e+002,6.915508e-005,9.011769e-008,-1.268789e-001,2.405637e-004,3,9.783375e-001,1.825000e+000,,,,,,,,,,,,,,,,,,0,4.000000e+000,1.000000e+000,2,2,8.288879e-001,0,,0,
1661334893.125,,1.000000e+003,3.406569e+002,6.841263e-005,8.393870e-008,-1.165026e-001,2.867039e-005,3,9.692373e-001,1.825000e+000,,,,,,,,,,,,,,,,,,0,4.000000e+000,1.000000e+000,2,2,5.479126e-001,0,,0,
1661335607.448,,1.000000e+003,3.126041e+002,4.415596e-005,1.778070e-008,-7.917203e-002,6.449310e-004,3,9.491676e-001,1.825000e+000,,,,,,,,,,,,,,,,,,0,4.000000e+000,1.000000e+000,2,2,5.802002e-001,0,,0,
1661336977.423,,1.000000e+003,3.142633e+002,4.380492e-005,5.661940e-009,-8.665853e-002,1.836338e-004,3,9.500026e-001,1.825000e+000,,,,,,,,,,,,,,,,,,0,4.000000e+000,1.000000e+000,2,2,3.990173e-001,0,,0,
1661337819.960,,1.000000e+003,3.422857e+002,4.827465e-005,2.159563e-008,-1.062315e-001,1.527007e-003,3,9.582697e-001,1.825000e+000,,,,,,,,,,,,,,,,,,0,4.000000e+000,1.000000e+000,2,2,4.034119e-001,0,,0,
1661338659.931,,1.000000e+003,3.702645e+002,6.823987e-005,9.554042e-009,-1.383679e-001,9.084121e-004,3,9.757563e-001,1.825000e+000,,,,,,,,,,,,,,,,,,0,4.000000e+000,1.000000e+000,2,2,4.093933e-001,0,,0,
1661339500.618,,1.000000e+003,3.982948e+002,6.544581e-005,1.462689e-008,-1.463768e-001,2.182258e-004,3,9.777726e-001,1.825000e+000,,,,,,,,,,,,,,,,,,0,4.000000e+000,1.000000e+000,2,2,3.981934e-001,0,,0,
1661340975.303,,9.000000e+002,3.742309e+002,6.184657e-005,4.713738e-008,-1.321001e-001,1.348278e-004,3,9.763608e-001,1.825000e+000,,,,,,,,,,,,,,,,,,0,4.000000e+000,1.000000e+000,2,2,9.500732e-001,0,,0,
1661341688.670,,9.000000e+002,3.465630e+002,6.363087e-005,5.070793e-008,-1.190524e-001,8.731615e-004,3,9.735988e-001,1.825000e+000,,,,,,,,,,,,,,,,,,0,4.000000e+000,1.000000e+000,2,2,6.068115e-001,0,,0,
1661342649.778,,9.000000e+002,3.184439e+002,4.054741e-005,2.389282e-008,-8.637615e-002,3.965175e-004,3,9.524565e-001,1.825000e+000,,,,,,,,,,,,,,,,,,0,4.000000e+000,1.000000e+000,2,2,8.290100e-001,0,,0,
1661343951.962,,9.000000e+002,3.083159e+002,4.006522e-005,7.949095e-008,-8.359160e-002,1.214151e-003,3,9.499068e-001,1.825000e+000,,,,,,,,,,,,,,,,,,0,4.000000e+000,1.000000e+000,2,2,4.958191e-001,0,,0,
1661344788.282,,9.000000e+002,3.362236e+002,4.169950e-005,5.756605e-008,-1.019590e-001,1.473080e-003,3,9.551271e-001,1.825000e+000,,,,,,,,,,,,,,,,,,0,4.000000e+000,1.000000e+000,2,2,4.064941e-001,0,,0,
1661345630.425,,9.000000e+002,3.642952e+002,6.169693e-005,1.752860e-008,-1.366656e-001,3.069660e-004,3,9.745793e-001,1.825000e+000,,,,,,,,,,,,,,,,,,0,4.000000e+000,1.000000e+000,2,2,4.492188e-001,0,,0,
1661346469.096,,9.000000e+002,3.922613e+002,5.993083e-005,7.015043e-009,-1.467692e-001,5.738293e-004,3,9.775611e-001,1.825000e+000,,,,,,,,,,,,,,,,,,0,4.000000e+000,1.000000e+000,2,2,4.117126e-001,0,,0,
1661347747.881,,8.000000e+002,3.808208e+002,5.488972e-005,9.482012e-009,-1.347481e-001,5.519130e-005,3,9.786505e-001,1.825000e+000,,,,,,,,,,,,,,,,,,0,4.000000e+000,1.000000e+000,2,2,2.933044e-001,0,,0,
1661348748.427,,8.000000e+002,3.522352e+002,5.665239e-005,1.653564e-008,-1.230443e-001,1.824168e-004,3,9.738128e-001,1.825000e+000,,,,,,,,,,,,,,,,,,0,4.000000e+000,1.000000e+000,2,2,8.870239e-001,0,,0,
1661349525.844,,8.000000e+002,3.248775e+002,3.751603e-005,3.762450e-008,-9.000404e-002,2.498781e-005,3,9.534646e-001,1.825000e+000,,,,,,,,,,,,,,,,,,0,4.000000e+000,1.000000e+000,2,2,1.848145e-001,0,,0,
1661350950.905,,8.000000e+002,3.022655e+002,3.642935e-005,2.115574e-008,-8.322294e-002,7.693539e-004,3,9.491617e-001,1.825000e+000,,,,,,,,,,,,,,,,,,0,4.000000e+000,1.000000e+000,2,2,4.536133e-001,0,,0,
1661351760.443,,8.000000e+002,3.302233e+002,3.660737e-005,2.284841e-008,-9.817170e-002,1.830580e-003,3,9.534880e-001,1.825000e+000,,,,,,,,,,,,,,,,,,0,4.000000e+000,1.000000e+000,2,2,3.999939e-001,0,,0,
1661352601.875,,8.000000e+002,3.582915e+002,5.240113e-005,7.307529e-008,-1.316165e-001,3.208218e-004,3,9.713221e-001,1.825000e+000,,,,,,,,,,,,,,,,,,0,4.000000e+000,1.000000e+000,2,2,4.028931e-001,0,,0,
1661353442.281,,8.000000e+002,3.862928e+002,5.421850e-005,1.182036e-008,-1.456646e-001,2.416384e-004,3,9.776422e-001,1.825000e+000,,,,,,,,,,,,,,,,,,0,4.000000e+000,1.000000e+000,2,2,4.471130e-001,0,,0,
1661354770.316,,7.000000e+002,3.865469e+002,4.783094e-005,1.110265e-008,-1.366554e-001,9.929798e-005,3,9.778094e-001,1.825000e+000,,,,,,,,,,,,,,,,,,0,4.000000e+000,1.000000e+000,2,2,8.108215e-001,0,,0,
1661355796.644,,7.000000e+002,3.585320e+002,4.956890e-005,2.342721e-008,-1.270246e-001,7.569469e-004,3,9.743991e-001,1.825000e+000,,,,,,,,,,,,,,,,,,0,4.000000e+000,1.000000e+000,2,2,8.067017e-001,0,,0,
1661356501.085,,7.000000e+002,3.305563e+002,3.651919e-005,2.721358e-007,-9.949343e-002,6.704773e-004,3,9.588523e-001,1.825000e+000,,,,,,,,,,,,,,,,,,0,4.000000e+000,1.000000e+000,2,2,6.882019e-001,0,,0,
1661357429.969,,7.000000e+002,3.026097e+002,3.238365e-005,1.962514e-008,-8.257240e-002,5.403226e-005,3,9.497774e-001,1.825000e+000,,,,,,,,,,,,,,,,,,0,4.000000e+000,1.000000e+000,2,2,6.206055e-001,0,,0,
1661358734.928,,7.000000e+002,3.243306e+002,3.224731e-005,1.186409e-008,-9.739049e-002,1.251482e-003,3,9.518864e-001,1.825000e+000,,,,,,,,,,,,,,,,,,0,4.000000e+000,1.000000e+000,2,2,4.100037e-001,0,,0,
1661359572.016,,7.000000e+002,3.522798e+002,4.153795e-005,8.406990e-008,-1.249940e-001,1.214267e-003,3,9.663531e-001,1.825000e+000,,,,,,,,,,,,,,,,,,0,4.000000e+000,1.000000e+000,2,2,4.085999e-001,0,,0,
1661360410.510,,7.000000e+002,3.802293e+002,4.827258e-005,4.341506e-008,-1.453727e-001,5.771800e-004,3,9.776859e-001,1.825000e+000,,,,,,,,,,,,,,,,,,0,4.000000e+000,1.000000e+000,2,2,4.093018e-001,0,,0,
1661361825.464,,6.000000e+002,3.922772e+002,4.085484e-005,5.812684e-008,-1.412852e-001,4.480210e-005,3,9.778343e-001,1.825000e+000,,,,,,,,,,,,,,,,,,0,4.000000e+000,1.000000e+000,2,2,8.735962e-001,0,,0,
1661362568.740,,6.000000e+002,3.646137e+002,4.306722e-005,1.584880e-008,-1.282474e-001,3.039104e-004,3,9.775490e-001,1.825000e+000,,,,,,,,,,,,,,,,,,0,4.000000e+000,1.000000e+000,2,2,6.322021e-001,0,,0,
1661363553.344,,6.000000e+002,3.364588e+002,3.925738e-005,3.223421e-007,-1.168194e-001,1.352050e-003,3,9.654487e-001,1.825000e+000,,,,,,,,,,,,,,,,,,0,4.000000e+000,1.000000e+000,2,2,8.416138e-001,0,,0,
1661364323.625,,6.000000e+002,3.088651e+002,2.816188e-005,2.989561e-008,-8.752397e-002,4.482844e-005,3,9.484476e-001,1.825000e+000,,,,,,,,,,,,,,,,,,0,4.000000e+000,1.000000e+000,2,2,2.412720e-001,0,,0,
1661365699.373,,6.000000e+002,3.183150e+002,2.796331e-005,3.009240e-008,-9.762567e-002,1.274995e-003,3,9.491689e-001,1.825000e+000,,,,,,,,,,,,,,,,,,0,4.000000e+000,1.000000e+000,2,2,4.502869e-001,0,,0,
1661366536.567,,6.000000e+002,3.462142e+002,3.230242e-005,8.138169e-008,-1.176679e-001,2.523016e-005,3,9.598827e-001,1.825000e+000,,,,,,,,,,,,,,,,,,0,4.000000e+000,1.000000e+000,2,2,4.035950e-001,0,,0,
1661367376.933,,6.000000e+002,3.742392e+002,4.216660e-005,4.390640e-008,-1.433161e-001,2.260125e-004,3,9.764008e-001,1.825000e+000,,,,,,,,,,,,,,,,,,0,4.000000e+000,1.000000e+000,2,2,4.526062e-001,0,,0,
1661368824.271,,5.000000e+002,3.988220e+002,3.401780e-005,7.633972e-008,-1.476862e-001,6.899334e-004,3,9.776610e-001,1.825000e+000,,,,,,,,,,,,,,,,,,0,4.000000e+000,1.000000e+000,2,2,3.090820e-001,0,,0,
1661369621.844,,5.000000e+002,3.698807e+002,3.599530e-005,5.070021e-008,-1.335806e-001,2.471133e-003,3,9.774494e-001,1.825000e+000,,,,,,,,,,,,,,,,,,0,4.000000e+000,1.000000e+000,2,2,1.015808e+000,0,,0,
1661370497.724,,5.000000e+002,3.429955e+002,3.612240e-005,2.148501e-008,-1.216983e-001,6.448205e-004,3,9.698988e-001,1.825000e+000,,,,,,,,,,,,,,,,,,0,4.000000e+000,1.000000e+000,2,2,9.399414e-003,0,,0,
1661371298.382,,5.000000e+002,3.146749e+002,2.409129e-005,6.815679e-009,-9.318094e-002,1.679283e-003,3,9.508915e-001,1.825000e+000,,,,,,,,,,,,,,,,,,0,4.000000e+000,1.000000e+000,2,2,6.670227e-001,0,,0,
1661372658.058,,5.000000e+002,3.122930e+002,2.386178e-005,3.032135e-008,-9.720627e-002,5.234639e-004,3,9.508908e-001,1.825000e+000,,,,,,,,,,,,,,,,,,0,4.000000e+000,1.000000e+000,2,2,3.937073e-001,0,,0,
1661373502.005,,5.000000e+002,3.402835e+002,2.553439e-005,3.028019e-008,-1.141513e-001,8.448547e-004,3,9.570017e-001,1.825000e+000,,,,,,,,,,,,,,,,,,0,4.000000e+000,1.000000e+000,2,2,4.633179e-001,0,,0,
1661374339.340,,5.000000e+002,3.682484e+002,3.565336e-005,3.434721e-008,-1.442426e-001,2.823101e-004,3,9.751791e-001,1.825000e+000,,,,,,,,,,,,,,,,,,0,4.000000e+000,1.000000e+000,2,2,4.265747e-001,0,,0,
1661375180.024,,5.000000e+002,3.962678e+002,3.438993e-005,3.591126e-008,-1.530551e-001,5.482251e-004,3,9.784240e-001,1.825000e+000,,,,,,,,,,,,,,,,,,0,4.000000e+000,1.000000e+000,2,2,4.073792e-001,0,,0,
1661376680.988,,4.000000e+002,3.764191e+002,2.875806e-005,4.325429e-008,-1.389675e-001,1.973526e-005,3,9.765644e-001,1.825000e+000,,,,,,,,,,,,,,,,,,0,4.000000e+000,1.000000e+000,2,2,8.474121e-001,0,,0,
1661377389.406,,4.000000e+002,3.483130e+002,2.966327e-005,3.358834e-008,-1.260684e-001,1.231826e-003,3,9.727815e-001,1.825000e+000,,,,,,,,,,,,,,,,,,0,4.000000e+000,1.000000e+000,2,2,7.592773e-001,0,,0,
1661378343.315,,4.000000e+002,3.205452e+002,1.988032e-005,3.886185e-008,-9.916300e-002,8.995086e-004,3,9.530215e-001,1.825000e+000,,,,,,,,,,,,,,,,,,0,4.000000e+000,1.000000e+000,2,2,7.102051e-001,0,,0,
1661379639.082,,4.000000e+002,3.063129e+002,1.967882e-005,3.214134e-008,-9.691177e-002,3.116285e-004,3,9.483008e-001,1.825000e+000,,,,,,,,,,,,,,,,,,0,4.000000e+000,1.000000e+000,2,2,5.036926e-001,0,,0,
1661380466.784,,4.000000e+002,3.342307e+002,2.009442e-005,1.789903e-008,-1.126321e-001,5.823220e-004,3,9.526170e-001,1.825000e+000,,,,,,,,,,,,,,,,,,0,4.000000e+000,1.000000e+000,2,2,4.461060e-001,0,,0,
1661381307.060,,4.000000e+002,3.622513e+002,2.856379e-005,3.755762e-008,-1.415237e-001,1.935404e-003,3,9.732873e-001,1.825000e+000,,,,,,,,,,,,,,,,,,0,4.000000e+000,1.000000e+000,2,2,4.440002e-001,0,,0,
1661382148.407,,4.000000e+002,3.903000e+002,2.813306e-005,5.371768e-008,-1.533747e-001,4.819176e-004,3,9.776751e-001,1.825000e+000,,,,,,,,,,,,,,,,,,0,4.000000e+000,1.000000e+000,2,2,3.827209e-001,0,,0,
1661383439.186,,3.000000e+002,3.827434e+002,2.174471e-005,1.196699e-008,-1.426138e-001,5.497424e-004,3,9.773753e-001,1.825000e+000,,,,,,,,,,,,,,,,,,0,4.000000e+000,1.000000e+000,2,2,4.860229e-001,0,,0,
1661384452.453,,3.000000e+002,3.542426e+002,2.240853e-005,9.426705e-009,-1.313652e-001,1.675917e-003,3,9.734976e-001,1.825000e+000,,,,,,,,,,,,,,,,,,0,4.000000e+000,1.000000e+000,2,2,9.075928e-001,0,,0,
1661385197.885,,3.000000e+002,3.268472e+002,1.593729e-005,1.521984e-008,-1.035984e-001,1.783549e-004,3,9.550689e-001,1.825000e+000,,,,,,,,,,,,,,,,,,0,4.000000e+000,1.000000e+000,2,2,2.723083e-001,0,,0,
1661386589.111,,3.000000e+002,3.000353e+002,1.527453e-005,1.247376e-008,-9.714307e-002,5.598155e-005,3,9.513768e-001,1.825000e+000,,,,,,,,,,,,,,,,,,0,4.000000e+000,1.000000e+000,2,2,1.419067e-002,0,,0,
1661387445.672,,3.000000e+002,3.282081e+002,1.524665e-005,8.921220e-009,-1.095921e-001,4.212894e-004,3,9.523251e-001,1.825000e+000,,,,,,,,,,,,,,,,,,0,4.000000e+000,1.000000e+000,2,2,4.205017e-001,0,,0,
1661388287.198,,3.000000e+002,3.562715e+002,2.039574e-005,1.297976e-007,-1.390103e-001,4.943509e-004,3,9.707398e-001,1.825000e+000,,,,,,,,,,,,,,,,,,0,4.000000e+000,1.000000e+000,2,2,4.081726e-001,0,,0,
1661389125.769,,3.000000e+002,3.842464e+002,2.170251e-005,7.991026e-008,-1.545653e-001,6.362067e-005,3,9.762333e-001,1.825000e+000,,,,,,,,,,,,,,,,,,0,4.000000e+000,1.000000e+000,2,2,4.064941e-001,0,,0,
1661390478.451,,2.000000e+002,3.884142e+002,1.465571e-005,5.978092e-008,-1.490170e-001,3.141141e-003,3,9.769245e-001,1.825000e+000,,,,,,,,,,,,,,,,,,0,4.000000e+000,1.000000e+000,2,2,9.413147e-001,0,,0,
1661391484.172,,2.000000e+002,3.608146e+002,1.520744e-005,2.434107e-008,-1.393500e-001,1.806108e-003,3,9.758426e-001,1.825000e+000,,,,,,,,,,,,,,,,,,0,4.000000e+000,1.000000e+000,2,2,3.249207e-001,0,,0,
1661392204.407,,2.000000e+002,3.325140e+002,1.241705e-005,1.311378e-007,-1.226941e-001,1.151484e-003,3,9.596946e-001,1.825000e+000,,,,,,,,,,,,,,,,,,0,4.000000e+000,1.000000e+000,2,2,7.059021e-001,0,,0,
1661393124.893,,2.000000e+002,3.047018e+002,1.065845e-005,9.003538e-012,-1.057007e-001,3.045484e-003,3,9.473226e-001,1.825000e+000,,,,,,,,,,,,,,,,,,0,4.000000e+000,1.000000e+000,2,2,6.224976e-001,0,,0,
1661394414.542,,2.000000e+002,3.222690e+002,1.058853e-005,2.133195e-008,-1.176026e-001,2.778742e-003,3,9.512502e-001,1.825000e+000,,,,,,,,,,,,,,,,,,0,4.000000e+000,1.000000e+000,2,2,4.540100e-001,0,,0,
1661395253.274,,2.000000e+002,3.502390e+002,1.266554e-005,1.837429e-008,-1.391021e-001,8.619031e-004,3,9.616480e-001,1.825000e+000,,,,,,,,,,,,,,,,,,0,4.000000e+000,1.000000e+000,2,2,4.627075e-001,0,,0,
1661396093.402,,2.000000e+002,3.782635e+002,1.494240e-005,1.932867e-008,-1.561014e-001,3.968336e-004,3,9.747477e-001,1.825000e+000,,,,,,,,,,,,,,,,,,0,4.000000e+000,1.000000e+000,2,2,4.512939e-001,0,,0,
1661397538.927,,1.000000e+002,3.946125e+002,7.476401e-006,6.353572e-008,-1.659793e-001,6.974271e-003,3,9.620570e-001,1.825000e+000,,,,,,,,,,,,,,,,,,0,4.000000e+000,1.000000e+000,2,2,7.579041e-001,0,,0,
1661398279.724,,1.000000e+002,3.664258e+002,7.955108e-006,4.447105e-009,-1.501669e-001,2.281725e-004,3,9.673640e-001,1.825000e+000,,,,,,,,,,,,,,,,,,0,4.000000e+000,1.000000e+000,2,2,6.929016e-001,0,,0,
1661399265.629,,1.000000e+002,3.385053e+002,7.737151e-006,5.592548e-008,-1.420568e-001,4.257674e-004,3,9.600049e-001,1.825000e+000,,,,,,,,,,,,,,,,,,0,4.000000e+000,1.000000e+000,2,2,8.706055e-001,0,,0,
1661399996.204,,1.000000e+002,3.107856e+002,5.814672e-006,1.485294e-008,-1.206122e-001,5.837291e-003,3,9.421787e-001,1.825000e+000,,,,,,,,,,,,,,,,,,0,4.000000e+000,1.000000e+000,2,2,4.126282e-001,0,,0,
1661401395.326,,1.000000e+002,3.165542e+002,5.795707e-006,1.955954e-008,-1.340164e-001,9.386946e-004,3,9.424697e-001,1.825000e+000,,,,,,,,,,,,,,,,,,0,4.000000e+000,1.000000e+000,2,2,3.576965e-001,0,,0,
1661402227.300,,1.000000e+002,3.442726e+002,6.248007e-006,2.376355e-008,-1.450852e-001,1.058961e-002,3,9.447794e-001,1.825000e+000,,,,,,,,,,,,,,,,,,0,4.000000e+000,1.000000e+000,2,2,4.843140e-001,0,,0,
1661403065.320,,1.000000e+002,3.722086e+002,7.843288e-006,3.032006e-008,-1.618356e-001,1.828847e-003,3,9.681545e-001,1.825000e+000,,,,,,,,,,,,,,,,,,0,4.000000e+000,1.000000e+000,2,2,4.028015e-001,0,,0,
1661404152.803,,1.000000e+002,3.999903e+002,7.597190e-006,2.856051e-009,-1.708635e-001,8.414092e-003,3,9.683599e-001,1.825000e+000,,,,,,,,,,,,,,,,,,0,4.000000e+000,1.000000e+000,2,2,2.590942e-002,0,,0,
1661405347.847,,0.000000e+000,3.720775e+002,4.631582e-007,6.073765e-008,-5.348827e-001,3.935061e-002,3,6.181763e-001,1.825000e+000,,,,,,,,,,,,,,,,,,0,4.000000e+000,1.000000e+000,2,2,1.017181e+000,0,,0,
1661406082.442,,0.000000e+000,3.447791e+002,4.620302e-007,2.087896e-010,-4.673889e-001,6.284961e-002,3,5.804806e-001,1.825000e+000,,,,,,,,,,,,,,,,,,0,4.000000e+000,1.000000e+000,2,2,4.000854e-001,0,,0,
1661407021.041,,0.000000e+000,3.166299e+002,7.698037e-007,1.131407e-008,-3.409244e-001,1.922573e-002,3,7.566528e-001,1.825000e+000,,,,,,,,,,,,,,,,,,0,4.000000e+000,1.000000e+000,2,2,7.713013e-001,0,,0,
1661408354.770,,0.000000e+000,3.102498e+002,7.568319e-007,3.531336e-008,-3.108176e-001,6.885967e-002,3,7.192764e-001,1.825000e+000,,,,,,,,,,,,,,,,,,0,4.000000e+000,1.000000e+000,2,2,4.643860e-001,0,,0,
1661409198.561,,0.000000e+000,3.382738e+002,7.348579e-007,1.278670e-007,-3.426004e-001,1.412282e-001,3,7.287899e-001,1.825000e+000,,,,,,,,,,,,,,,,,,0,4.000000e+000,1.000000e+000,2,2,4.118042e-001,0,,0,
1661410037.223,,0.000000e+000,3.662201e+002,4.743284e-007,6.356409e-008,-4.757063e-001,4.182019e-002,3,6.354498e-001,1.825000e+000,,,,,,,,,,,,,,,,,,0,4.000000e+000,1.000000e+000,2,2,4.541931e-001,0,,0,
1661410876.771,,0.000000e+000,3.942243e+002,5.095338e-007,3.620761e-008,-5.761641e-001,9.300423e-002,3,5.018880e-001,1.825000e+000,,,,,,,,,,,,,,,,,,0,4.000000e+000,1.000000e+000,2,2,3.908997e-001,0,,0,
1661411306.267,,0.000000e+000,3.999871e+002,4.123796e-007,5.878261e-008,-4.280556e-001,2.950832e-002,3,6.011534e-001,1.825000e+000,,,,,,,,,,,,,,,,,,0,4.000000e+000,1.000000e+000,2,2,1.300049e-002,0,,0,