File: spin_crossover/dane/AOT — kopia/Small AOT/FeTrz_AOT_small_XTvT_MCE.rso.csv
Field (Oe),Temperature (K),Long Moment (emu),Long Offset (cm)
7.000000e+004,4.000000e+002,3.934791e-003,-1.306971e-001
7.000000e+004,3.912379e+002,4.007389e-003,-1.252876e-001
7.000000e+004,3.835842e+002,4.079464e-003,-1.212460e-001
7.000000e+004,3.755337e+002,4.129121e-003,-1.208341e-001
7.000000e+004,3.671227e+002,4.211355e-003,-1.165819e-001
7.000000e+004,3.599285e+002,4.270148e-003,-1.138994e-001
7.000000e+004,3.512615e+002,4.305916e-003,-1.118988e-001
7.000000e+004,3.437203e+002,4.101524e-003,-1.012546e-001
7.000000e+004,3.354628e+002,2.576349e-003,-6.551617e-002
7.000000e+004,3.276962e+002,1.998685e-003,-3.763123e-002
7.000000e+004,3.196824e+002,1.887165e-003,-3.152229e-002
7.000000e+004,3.117055e+002,1.876308e-003,-2.691785e-002
7.000000e+004,3.036691e+002,1.875375e-003,-2.572362e-002
7.000000e+004,3.033223e+002,1.872617e-003,-2.674631e-002
7.000000e+004,3.112467e+002,1.857231e-003,-2.989195e-002
7.000000e+004,3.192468e+002,1.854853e-003,-3.336282e-002
7.000000e+004,3.272220e+002,1.868730e-003,-3.761267e-002
7.000000e+004,3.352196e+002,1.916918e-003,-4.342956e-002
7.000000e+004,3.432855e+002,2.058792e-003,-5.413028e-002
7.000000e+004,3.512241e+002,2.452016e-003,-7.444988e-002
7.000000e+004,3.592184e+002,3.306449e-003,-1.023196e-001
7.000000e+004,3.672857e+002,4.073095e-003,-1.219758e-001
7.000000e+004,3.752091e+002,4.121395e-003,-1.268097e-001
7.000000e+004,3.832122e+002,4.067456e-003,-1.290373e-001
7.000000e+004,3.911912e+002,4.002455e-003,-1.308205e-001
7.000000e+004,3.992635e+002,3.939795e-003,-1.321996e-001
6.500000e+004,3.935353e+002,3.705407e-003,-1.229276e-001
6.500000e+004,3.856173e+002,3.777063e-003,-1.185413e-001
6.500000e+004,3.775823e+002,3.829180e-003,-1.172587e-001
6.500000e+004,3.691946e+002,3.905937e-003,-1.128982e-001
6.500000e+004,3.618000e+002,3.964814e-003,-1.098066e-001
6.500000e+004,3.533625e+002,3.997014e-003,-1.083208e-001
6.500000e+004,3.456818e+002,4.008867e-003,-1.029319e-001
6.500000e+004,3.374799e+002,3.373916e-003,-8.747626e-002
6.500000e+004,3.295444e+002,2.109159e-003,-4.797742e-002
6.500000e+004,3.216162e+002,1.889404e-003,-3.686443e-002
6.500000e+004,3.136758e+002,1.858148e-003,-3.154262e-002
6.500000e+004,3.057326e+002,1.849929e-003,-3.025129e-002
6.500000e+004,3.012057e+002,1.854068e-003,-2.976460e-002
6.500000e+004,3.092786e+002,1.837596e-003,-3.310305e-002
6.500000e+004,3.172333e+002,1.832498e-003,-3.744514e-002
6.500000e+004,3.252056e+002,1.844779e-003,-4.184737e-002
6.500000e+004,3.332258e+002,1.893843e-003,-4.782634e-002
6.500000e+004,3.413643e+002,2.041612e-003,-5.886745e-002
6.500000e+004,3.492058e+002,2.430852e-003,-7.791600e-002
6.500000e+004,3.572207e+002,3.187623e-003,-1.026523e-001
6.500000e+004,3.652711e+002,3.798321e-003,-1.195226e-001
6.500000e+004,3.732012e+002,3.850719e-003,-1.249667e-001
6.500000e+004,3.814084e+002,3.799427e-003,-1.274263e-001
6.500000e+004,3.892195e+002,3.741341e-003,-1.293035e-001
6.500000e+004,3.971959e+002,3.681307e-003,-1.306832e-001
6.000000e+004,3.955973e+002,3.406019e-003,-1.236124e-001
6.000000e+004,3.875056e+002,3.474039e-003,-1.190008e-001
6.000000e+004,3.797912e+002,3.520329e-003,-1.182528e-001
6.000000e+004,3.711658e+002,3.591525e-003,-1.140706e-001
6.000000e+004,3.637480e+002,3.651002e-003,-1.105032e-001
6.000000e+004,3.554470e+002,3.673853e-003,-1.097179e-001
6.000000e+004,3.475071e+002,3.718143e-003,-1.053215e-001
6.000000e+004,3.395509e+002,3.529438e-003,-9.846173e-002
6.000000e+004,3.316077e+002,2.238256e-003,-6.222652e-002
6.000000e+004,3.236979e+002,1.833434e-003,-4.354464e-002
6.000000e+004,3.155444e+002,1.780580e-003,-3.671167e-002
6.000000e+004,3.079237e+002,1.767785e-003,-3.447674e-002
6.000000e+004,3.000760e+002,1.779495e-003,-3.289892e-002
6.000000e+004,3.072643e+002,1.762678e-003,-3.729720e-002
6.000000e+004,3.152821e+002,1.753232e-003,-4.093561e-002
6.000000e+004,3.232298e+002,1.761470e-003,-4.516602e-002
6.000000e+004,3.312659e+002,1.799777e-003,-5.062755e-002
6.000000e+004,3.392260e+002,1.918033e-003,-6.015464e-002
6.000000e+004,3.472432e+002,2.244783e-003,-7.764037e-002
6.000000e+004,3.552285e+002,2.893114e-003,-1.013058e-001
6.000000e+004,3.632556e+002,3.474952e-003,-1.182327e-001
6.000000e+004,3.712546e+002,3.571555e-003,-1.247611e-001
6.000000e+004,3.792961e+002,3.522832e-003,-1.271012e-001
6.000000e+004,3.872228e+002,3.470311e-003,-1.291476e-001
6.000000e+004,3.952547e+002,3.413990e-003,-1.306850e-001
5.500000e+004,3.977910e+002,3.108268e-003,-1.254291e-001
5.500000e+004,3.894500e+002,3.172000e-003,-1.203089e-001
5.500000e+004,3.817914e+002,3.226240e-003,-1.166947e-001
5.500000e+004,3.732691e+002,3.277443e-003,-1.151548e-001
5.500000e+004,3.655699e+002,3.335072e-003,-1.114070e-001
5.500000e+004,3.575805e+002,3.357925e-003,-1.108041e-001
5.500000e+004,3.495782e+002,3.401838e-003,-1.066451e-001
5.500000e+004,3.416584e+002,3.333675e-003,-1.025359e-001
5.500000e+004,3.336298e+002,2.445643e-003,-7.730073e-002
5.500000e+004,3.259205e+002,1.780611e-003,-4.816421e-002
5.500000e+004,3.175610e+002,1.680814e-003,-4.136159e-002
5.500000e+004,3.098354e+002,1.664189e-003,-3.718579e-002
5.500000e+004,3.016101e+002,1.670304e-003,-3.611338e-002
5.500000e+004,3.052907e+002,1.660617e-003,-3.946475e-002
5.500000e+004,3.132321e+002,1.649455e-003,-4.284357e-002
5.500000e+004,3.213123e+002,1.651529e-003,-4.708031e-002
5.500000e+004,3.292480e+002,1.679637e-003,-5.228446e-002
5.500000e+004,3.372294e+002,1.767362e-003,-6.049544e-002
5.500000e+004,3.452847e+002,2.021405e-003,-7.610638e-002
5.500000e+004,3.531993e+002,2.551949e-003,-9.829298e-002
5.500000e+004,3.613999e+002,3.137189e-003,-1.164036e-001
5.500000e+004,3.692714e+002,3.285840e-003,-1.244170e-001
5.500000e+004,3.772827e+002,3.243057e-003,-1.269260e-001
5.500000e+004,3.852502e+002,3.194618e-003,-1.290082e-001
5.500000e+004,3.932434e+002,3.143175e-003,-1.307116e-001
5.000000e+004,4.000097e+002,2.820726e-003,-1.271002e-001
5.000000e+004,3.915143e+002,2.868517e-003,-1.218028e-001
5.000000e+004,3.836497e+002,2.922218e-003,-1.176528e-001
5.000000e+004,3.753970e+002,2.964450e-003,-1.166493e-001
5.000000e+004,3.673729e+002,3.021311e-003,-1.125799e-001
5.000000e+004,3.595927e+002,3.040162e-003,-1.119288e-001
5.000000e+004,3.513579e+002,3.083488e-003,-1.079295e-001
5.000000e+004,3.437937e+002,3.091406e-003,-1.034652e-001
5.000000e+004,3.354899e+002,2.602327e-003,-9.024325e-002
5.000000e+004,3.277303e+002,1.717230e-003,-5.445294e-002
5.000000e+004,3.195770e+002,1.566327e-003,-4.507583e-002
5.000000e+004,3.117286e+002,1.543329e-003,-4.002501e-002
5.000000e+004,3.036455e+002,1.545322e-003,-3.916410e-002
5.000000e+004,3.032734e+002,1.542353e-003,-4.078492e-002
5.000000e+004,3.112524e+002,1.531335e-003,-4.428429e-002
5.000000e+004,3.192468e+002,1.528711e-003,-4.812491e-002
5.000000e+004,3.272540e+002,1.546033e-003,-5.311263e-002
5.000000e+004,3.352263e+002,1.610161e-003,-6.039348e-002
5.000000e+004,3.432454e+002,1.795606e-003,-7.383762e-002
5.000000e+004,3.512241e+002,2.221563e-003,-9.465749e-002
5.000000e+004,3.592365e+002,2.769040e-003,-1.138520e-001
5.000000e+004,3.672748e+002,2.985708e-003,-1.236494e-001
5.000000e+004,3.752830e+002,2.960168e-003,-1.267418e-001
5.000000e+004,3.832360e+002,2.915798e-003,-1.290744e-001
5.000000e+004,3.912750e+002,2.869259e-003,-1.308490e-001
5.000000e+004,3.992764e+002,2.823111e-003,-1.321028e-001
4.500000e+004,3.934915e+002,2.570597e-003,-1.231702e-001
4.500000e+004,3.856323e+002,2.620637e-003,-1.188954e-001
4.500000e+004,3.775247e+002,2.657096e-003,-1.179341e-001
4.500000e+004,3.693486e+002,2.708783e-003,-1.137250e-001
4.500000e+004,3.618685e+002,2.748962e-003,-1.106004e-001
4.500000e+004,3.533074e+002,2.765824e-003,-1.089097e-001
4.500000e+004,3.457081e+002,2.790580e-003,-1.048826e-001
4.500000e+004,3.375118e+002,2.598401e-003,-9.815393e-002
4.500000e+004,3.297003e+002,1.667577e-003,-6.254853e-002
4.500000e+004,3.215792e+002,1.445822e-003,-4.870683e-002
4.500000e+004,3.137224e+002,1.414700e-003,-4.264119e-002
4.500000e+004,3.057364e+002,1.411100e-003,-4.116074e-002
4.500000e+004,3.011861e+002,1.414159e-003,-4.110400e-002
4.500000e+004,3.092503e+002,1.402695e-003,-4.505152e-002
4.500000e+004,3.172791e+002,1.397484e-003,-4.888818e-002
4.500000e+004,3.252308e+002,1.408314e-003,-5.330475e-002
4.500000e+004,3.332946e+002,1.452699e-003,-5.988740e-002
4.500000e+004,3.413876e+002,1.586688e-003,-7.137561e-002
4.500000e+004,3.492352e+002,1.906309e-003,-9.051369e-002
4.500000e+004,3.572669e+002,2.405337e-003,-1.106420e-001
4.500000e+004,3.652093e+002,2.675002e-003,-1.220590e-001
4.500000e+004,3.732181e+002,2.674909e-003,-1.259643e-001
4.500000e+004,3.813966e+002,2.634539e-003,-1.281254e-001
4.500000e+004,3.892779e+002,2.593960e-003,-1.300170e-001
4.500000e+004,3.972406e+002,2.552561e-003,-1.314891e-001
4.000000e+004,3.956417e+002,2.277647e-003,-1.245444e-001
4.000000e+004,3.876060e+002,2.322439e-003,-1.197173e-001
4.000000e+004,3.797271e+002,2.353676e-003,-1.188572e-001
4.000000e+004,3.710964e+002,2.400874e-003,-1.145682e-001
4.000000e+004,3.637187e+002,2.439374e-003,-1.109830e-001
4.000000e+004,3.554064e+002,2.452320e-003,-1.098189e-001
4.000000e+004,3.476863e+002,2.481516e-003,-1.058457e-001
4.000000e+004,3.396133e+002,2.414035e-003,-1.024868e-001
4.000000e+004,3.316363e+002,1.648239e-003,-7.261641e-002
4.000000e+004,3.239189e+002,1.319586e-003,-5.093892e-002
4.000000e+004,3.159058e+002,1.272597e-003,-4.541351e-002
4.000000e+004,3.079201e+002,1.268801e-003,-4.325113e-002
4.000000e+004,3.001805e+002,1.274315e-003,-4.272049e-002
4.000000e+004,3.072214e+002,1.262779e-003,-4.728780e-002
4.000000e+004,3.152762e+002,1.258131e-003,-5.067068e-002
4.000000e+004,3.232173e+002,1.260000e-003,-5.457035e-002
4.000000e+004,3.312680e+002,1.286114e-003,-5.987821e-002
4.000000e+004,3.392813e+002,1.372726e-003,-6.903088e-002
4.000000e+004,3.472892e+002,1.607699e-003,-8.641030e-002
4.000000e+004,3.552234e+002,2.032501e-003,-1.074513e-001
4.000000e+004,3.632317e+002,2.356589e-003,-1.213844e-001
4.000000e+004,3.712769e+002,2.388116e-003,-1.265621e-001
4.000000e+004,3.792408e+002,2.354725e-003,-1.286732e-001
4.000000e+004,3.872896e+002,2.318226e-003,-1.307034e-001
4.000000e+004,3.952389e+002,2.281568e-003,-1.320113e-001
3.500000e+004,3.977686e+002,1.985983e-003,-1.267867e-001
3.500000e+004,3.894193e+002,2.025559e-003,-1.214753e-001
3.500000e+004,3.818149e+002,2.060238e-003,-1.179170e-001
3.500000e+004,3.733281e+002,2.092275e-003,-1.162662e-001
3.500000e+004,3.655914e+002,2.129181e-003,-1.123779e-001
3.500000e+004,3.574699e+002,2.139577e-003,-1.115487e-001
3.500000e+004,3.495463e+002,2.168003e-003,-1.074312e-001
3.500000e+004,3.418032e+002,2.137511e-003,-1.048319e-001
3.500000e+004,3.335433e+002,1.648345e-003,-8.467848e-002
3.500000e+004,3.258909e+002,1.206213e-003,-5.486966e-002
3.500000e+004,3.175231e+002,1.137008e-003,-4.806560e-002
3.500000e+004,3.098146e+002,1.128361e-003,-4.405691e-002
3.500000e+004,3.016675e+002,1.132137e-003,-4.329393e-002
3.500000e+004,3.052760e+002,1.124789e-003,-4.634033e-002
3.500000e+004,3.132243e+002,1.121108e-003,-5.038609e-002
3.500000e+004,3.213287e+002,1.119886e-003,-5.427945e-002
3.500000e+004,3.292200e+002,1.137956e-003,-5.915821e-002
3.500000e+004,3.372499e+002,1.199116e-003,-6.738799e-002
3.500000e+004,3.452298e+002,1.367195e-003,-8.273684e-002
3.500000e+004,3.532595e+002,1.704767e-003,-1.033163e-001
3.500000e+004,3.613526e+002,2.030124e-003,-1.188429e-001
3.500000e+004,3.692549e+002,2.095402e-003,-1.251019e-001
3.500000e+004,3.772079e+002,2.070412e-003,-1.276637e-001
3.500000e+004,3.852682e+002,2.040201e-003,-1.296278e-001
3.500000e+004,3.932904e+002,2.007590e-003,-1.316011e-001
3.000000e+004,4.000162e+002,1.701281e-003,-1.282418e-001
3.000000e+004,3.914523e+002,1.731007e-003,-1.225533e-001
3.000000e+004,3.836229e+002,1.762550e-003,-1.185683e-001
3.000000e+004,3.755110e+002,1.787296e-003,-1.174941e-001
3.000000e+004,3.674409e+002,1.820976e-003,-1.135805e-001
3.000000e+004,3.597306e+002,1.829702e-003,-1.127252e-001
3.000000e+004,3.514150e+002,1.855665e-003,-1.087557e-001
3.000000e+004,3.438079e+002,1.863350e-003,-1.045924e-001
3.000000e+004,3.354763e+002,1.604140e-003,-9.433462e-002
3.000000e+004,3.276918e+002,1.084634e-003,-6.014293e-002
3.000000e+004,3.195364e+002,9.939863e-004,-5.082178e-002
3.000000e+004,3.117094e+002,9.825353e-004,-4.614503e-002
3.000000e+004,3.036382e+002,9.818405e-004,-4.520512e-002
3.000000e+004,3.033368e+002,9.796412e-004,-4.671837e-002
3.000000e+004,3.112793e+002,9.723509e-004,-5.064390e-002
3.000000e+004,3.192488e+002,9.735051e-004,-5.435497e-002
3.000000e+004,3.272156e+002,9.827020e-004,-5.860359e-002
3.000000e+004,3.352645e+002,1.023069e-003,-6.636066e-002
3.000000e+004,3.432101e+002,1.136045e-003,-7.931972e-002
3.000000e+004,3.512216e+002,1.389185e-003,-9.882131e-002
3.000000e+004,3.592235e+002,1.697543e-003,-1.161701e-001
3.000000e+004,3.672531e+002,1.801913e-003,-1.245723e-001
3.000000e+004,3.753058e+002,1.785732e-003,-1.271778e-001
3.000000e+004,3.832152e+002,1.759693e-003,-1.291860e-001
3.000000e+004,3.912346e+002,1.732706e-003,-1.314595e-001
3.000000e+004,3.992731e+002,1.704672e-003,-1.328331e-001
2.500000e+004,3.934789e+002,1.439302e-003,-1.250427e-001
2.500000e+004,3.856473e+002,1.467264e-003,-1.198156e-001
2.500000e+004,3.775362e+002,1.486969e-003,-1.187649e-001
2.500000e+004,3.692633e+002,1.515693e-003,-1.146491e-001
2.500000e+004,3.618527e+002,1.536764e-003,-1.116867e-001
2.500000e+004,3.534905e+002,1.545338e-003,-1.098370e-001
2.500000e+004,3.457225e+002,1.558960e-003,-1.056129e-001
2.500000e+004,3.375823e+002,1.457407e-003,-1.006304e-001
2.500000e+004,3.296591e+002,9.692603e-004,-6.770820e-002
2.500000e+004,3.216861e+002,8.462445e-004,-5.359773e-002
2.500000e+004,3.136835e+002,8.294048e-004,-4.860196e-002
2.500000e+004,3.057603e+002,8.258916e-004,-4.725861e-002
2.500000e+004,3.012361e+002,8.292840e-004,-4.723460e-002
2.500000e+004,3.092314e+002,8.214660e-004,-5.053519e-002
2.500000e+004,3.172213e+002,8.202310e-004,-5.514836e-002
2.500000e+004,3.252245e+002,8.256384e-004,-5.954970e-002
2.500000e+004,3.332480e+002,8.504119e-004,-6.776072e-002
2.500000e+004,3.413853e+002,9.259275e-004,-7.653622e-002
2.500000e+004,3.492058e+002,1.100808e-003,-9.432109e-002
2.500000e+004,3.573029e+002,1.367984e-003,-1.140790e-001
2.500000e+004,3.652496e+002,1.500365e-003,-1.240550e-001
2.500000e+004,3.732209e+002,1.495704e-003,-1.278850e-001
2.500000e+004,3.813643e+002,1.475113e-003,-1.297729e-001
2.500000e+004,3.892379e+002,1.452275e-003,-1.315696e-001
2.500000e+004,3.971735e+002,1.429494e-003,-1.327243e-001
2.000000e+004,3.954926e+002,1.148970e-003,-1.260470e-001
2.000000e+004,3.875847e+002,1.171581e-003,-1.214640e-001
2.000000e+004,3.799838e+002,1.189867e-003,-1.182793e-001
2.000000e+004,3.710881e+002,1.210567e-003,-1.164251e-001
2.000000e+004,3.636654e+002,1.229635e-003,-1.120915e-001
2.000000e+004,3.554419e+002,1.234055e-003,-1.111520e-001
2.000000e+004,3.476379e+002,1.249019e-003,-1.070349e-001
2.000000e+004,3.396386e+002,1.211183e-003,-1.042736e-001
2.000000e+004,3.315486e+002,8.534418e-004,-7.763701e-002
2.000000e+004,3.238959e+002,6.922215e-004,-5.710831e-002
2.000000e+004,3.156077e+002,6.729052e-004,-5.065444e-002
2.000000e+004,3.079070e+002,6.703944e-004,-4.801078e-002
2.000000e+004,3.000919e+002,6.736969e-004,-4.695112e-002
2.000000e+004,3.072774e+002,6.669801e-004,-5.166756e-002
2.000000e+004,3.152349e+002,6.642328e-004,-5.415529e-002
2.000000e+004,3.232215e+002,6.669341e-004,-5.948929e-002
2.000000e+004,3.312812e+002,6.814979e-004,-6.485441e-002
2.000000e+004,3.392306e+002,7.266145e-004,-7.481012e-002
2.000000e+004,3.474803e+002,8.486941e-004,-9.135830e-002
2.000000e+004,3.552462e+002,1.047636e-003,-1.107041e-001
2.000000e+004,3.632264e+002,1.193348e-003,-1.225844e-001
2.000000e+004,3.712380e+002,1.203082e-003,-1.270729e-001
2.000000e+004,3.792582e+002,1.187355e-003,-1.290167e-001
2.000000e+004,3.872440e+002,1.169909e-003,-1.317747e-001
2.000000e+004,3.952135e+002,1.151241e-003,-1.332681e-001
1.500000e+004,3.978167e+002,8.611516e-004,-1.285379e-001
1.500000e+004,3.893825e+002,8.784067e-004,-1.233814e-001
1.500000e+004,3.817560e+002,8.932444e-004,-1.195219e-001
1.500000e+004,3.732746e+002,9.068870e-004,-1.179637e-001
1.500000e+004,3.656480e+002,9.223741e-004,-1.137960e-001
1.500000e+004,3.576061e+002,9.258699e-004,-1.131202e-001
1.500000e+004,3.495684e+002,9.376599e-004,-1.086769e-001
1.500000e+004,3.417869e+002,9.231929e-004,-1.072673e-001
1.500000e+004,3.335011e+002,7.226403e-004,-8.919391e-002
1.500000e+004,3.258571e+002,5.429843e-004,-6.054946e-002
1.500000e+004,3.175951e+002,5.135287e-004,-5.396368e-002
1.500000e+004,3.097786e+002,5.117600e-004,-5.030786e-002
1.500000e+004,3.016371e+002,5.119020e-004,-4.953168e-002
1.500000e+004,3.053422e+002,5.090639e-004,-5.200075e-002
1.500000e+004,3.132593e+002,5.057867e-004,-5.708753e-002
1.500000e+004,3.213184e+002,5.071571e-004,-6.062455e-002
1.500000e+004,3.292653e+002,5.142965e-004,-6.451738e-002
1.500000e+004,3.372363e+002,5.403516e-004,-7.438278e-002
1.500000e+004,3.451820e+002,6.101639e-004,-8.778526e-002
1.500000e+004,3.532294e+002,7.503288e-004,-1.065908e-001
1.500000e+004,3.614104e+002,8.852102e-004,-1.214658e-001
1.500000e+004,3.692769e+002,9.075903e-004,-1.269988e-001
1.500000e+004,3.772137e+002,8.973676e-004,-1.295122e-001
1.500000e+004,3.852472e+002,8.840189e-004,-1.309979e-001
1.500000e+004,3.932245e+002,8.704864e-004,-1.328538e-001
1.000000e+004,4.000097e+002,5.775669e-004,-1.306594e-001
1.000000e+004,3.914211e+002,5.875415e-004,-1.252191e-001
1.000000e+004,3.836527e+002,5.983471e-004,-1.211344e-001
1.000000e+004,3.755024e+002,6.066384e-004,-1.204327e-001
1.000000e+004,3.675171e+002,6.174062e-004,-1.155571e-001
1.000000e+004,3.597045e+002,6.201447e-004,-1.147531e-001
1.000000e+004,3.514846e+002,6.282276e-004,-1.102732e-001
1.000000e+004,3.437795e+002,6.304888e-004,-1.071337e-001
1.000000e+004,3.354651e+002,5.429585e-004,-9.757066e-002
1.000000e+004,3.277047e+002,3.817528e-004,-6.771025e-002
1.000000e+004,3.196317e+002,3.516108e-004,-5.833520e-002
1.000000e+004,3.116536e+002,3.484442e-004,-5.384075e-002
1.000000e+004,3.036964e+002,3.480907e-004,-5.602900e-002
1.000000e+004,3.032988e+002,3.476753e-004,-5.397495e-002
1.000000e+004,3.112582e+002,3.449954e-004,-5.906035e-002
1.000000e+004,3.192144e+002,3.450798e-004,-6.170942e-002
1.000000e+004,3.272220e+002,3.482016e-004,-6.667461e-002
1.000000e+004,3.352802e+002,3.613043e-004,-7.296191e-002
1.000000e+004,3.432289e+002,3.981053e-004,-8.500433e-002
1.000000e+004,3.512513e+002,4.797088e-004,-1.038674e-001
1.000000e+004,3.592340e+002,5.784762e-004,-1.195376e-001
1.000000e+004,3.672123e+002,6.103748e-004,-1.266244e-001
1.000000e+004,3.752091e+002,6.052406e-004,-1.297639e-001
1.000000e+004,3.832212e+002,5.970211e-004,-1.308502e-001
1.000000e+004,3.911943e+002,5.876754e-004,-1.337809e-001
1.000000e+004,3.992344e+002,5.782949e-004,-1.347909e-001
9.000000e+003,3.934883e+002,5.273502e-004,-1.267417e-001
9.000000e+003,3.855842e+002,5.372576e-004,-1.220331e-001
9.000000e+003,3.775621e+002,5.445486e-004,-1.214730e-001
9.000000e+003,3.693212e+002,5.549461e-004,-1.168887e-001
9.000000e+003,3.618475e+002,5.622627e-004,-1.136479e-001
9.000000e+003,3.534729e+002,5.647625e-004,-1.121760e-001
9.000000e+003,3.456435e+002,5.697922e-004,-1.076466e-001
9.000000e+003,3.374184e+002,5.290479e-004,-1.033722e-001
9.000000e+003,3.296548e+002,3.655094e-004,-7.455253e-002
9.000000e+003,3.216018e+002,3.221279e-004,-6.111066e-002
9.000000e+003,3.135862e+002,3.171218e-004,-5.615013e-002
9.000000e+003,3.057640e+002,3.155739e-004,-5.352992e-002
9.000000e+003,3.011986e+002,3.169110e-004,-5.273712e-002
9.000000e+003,3.092919e+002,3.141758e-004,-5.840496e-002
9.000000e+003,3.172592e+002,3.132189e-004,-6.209398e-002
9.000000e+003,3.252266e+002,3.152639e-004,-6.686781e-002
9.000000e+003,3.332214e+002,3.239627e-004,-7.263693e-002
9.000000e+003,3.414063e+002,3.510318e-004,-8.368358e-002
9.000000e+003,3.492131e+002,4.119024e-004,-9.904604e-002
9.000000e+003,3.572310e+002,5.038508e-004,-1.168586e-001
9.000000e+003,3.652281e+002,5.428433e-004,-1.078718e-001
9.000000e+003,3.732322e+002,5.476509e-004,-1.295751e-001
9.000000e+003,3.815232e+002,5.400282e-004,-1.317333e-001
9.000000e+003,3.892257e+002,5.318976e-004,-1.332036e-001
9.000000e+003,3.972182e+002,5.237136e-004,-1.345474e-001
8.000000e+003,3.955529e+002,4.678508e-004,-1.284461e-001
8.000000e+003,3.874721e+002,4.770997e-004,-1.237202e-001
8.000000e+003,3.798350e+002,4.830919e-004,-1.227380e-001
8.000000e+003,3.711603e+002,4.925465e-004,-1.181618e-001
8.000000e+003,3.636681e+002,5.000320e-004,-1.144507e-001
8.000000e+003,3.554317e+002,5.016683e-004,-1.130454e-001
8.000000e+003,3.476306e+002,5.069853e-004,-1.090805e-001
8.000000e+003,3.396432e+002,4.915554e-004,-1.063430e-001
8.000000e+003,3.314634e+002,3.516604e-004,-8.212103e-002
8.000000e+003,3.237521e+002,2.928982e-004,-6.422417e-002
8.000000e+003,3.155721e+002,2.853307e-004,-5.814709e-002
8.000000e+003,3.079144e+002,2.833933e-004,-5.595594e-002
8.000000e+003,3.000707e+002,2.857665e-004,-5.478759e-002
8.000000e+003,3.072755e+002,2.828971e-004,-5.904748e-002
8.000000e+003,3.152427e+002,2.814731e-004,-6.252092e-002
8.000000e+003,3.232173e+002,2.826661e-004,-6.723259e-002
8.000000e+003,3.312483e+002,2.882949e-004,-7.314128e-002
8.000000e+003,3.392329e+002,3.062599e-004,-8.137728e-002
8.000000e+003,3.472336e+002,3.515820e-004,-9.591059e-002
8.000000e+003,3.552183e+002,4.299483e-004,-1.134417e-001
8.000000e+003,3.632529e+002,4.861357e-004,-1.248393e-001
8.000000e+003,3.712769e+002,4.891815e-004,-1.298157e-001
8.000000e+003,3.792815e+002,4.834464e-004,-1.317497e-001
8.000000e+003,3.872653e+002,4.762320e-004,-1.337615e-001
8.000000e+003,3.952262e+002,4.689546e-004,-1.357076e-001
7.000000e+003,3.978071e+002,4.097412e-004,-1.307714e-001
7.000000e+003,3.895176e+002,4.177666e-004,-1.251683e-001
7.000000e+003,3.817973e+002,4.248235e-004,-1.215498e-001
7.000000e+003,3.733506e+002,4.310526e-004,-1.198197e-001
7.000000e+003,3.656399e+002,4.383775e-004,-1.154043e-001
7.000000e+003,3.576061e+002,4.396969e-004,-1.147912e-001
7.000000e+003,3.495488e+002,4.450573e-004,-1.105171e-001
7.000000e+003,3.417822e+002,4.376581e-004,-1.084497e-001
7.000000e+003,3.334589e+002,3.448403e-004,-9.200157e-002
7.000000e+003,3.258550e+002,2.663404e-004,-6.666338e-002
7.000000e+003,3.175091e+002,2.537520e-004,-6.021980e-002
7.000000e+003,3.097956e+002,2.521873e-004,-5.757915e-002
7.000000e+003,3.016263e+002,2.528987e-004,-5.562883e-002
7.000000e+003,3.052944e+002,2.515859e-004,-5.921093e-002
7.000000e+003,3.132437e+002,2.498580e-004,-6.177948e-002
7.000000e+003,3.213717e+002,2.505134e-004,-6.765883e-002
7.000000e+003,3.292308e+002,2.538390e-004,-7.191476e-002
7.000000e+003,3.372181e+002,2.657435e-004,-7.973444e-002
7.000000e+003,3.452202e+002,2.975918e-004,-9.241109e-002
7.000000e+003,3.532670e+002,3.611076e-004,-1.106420e-001
7.000000e+003,3.614946e+002,4.220545e-004,-1.237405e-001
7.000000e+003,3.692164e+002,4.312876e-004,-1.287436e-001
7.000000e+003,3.772281e+002,4.268406e-004,-1.312632e-001
7.000000e+003,3.851962e+002,4.206555e-004,-1.333445e-001
7.000000e+003,3.932214e+002,4.142387e-004,-1.350787e-001
6.000000e+003,4.000032e+002,3.522153e-004,-1.328207e-001
6.000000e+003,3.914055e+002,3.582566e-004,-1.272139e-001
6.000000e+003,3.836736e+002,3.645234e-004,-1.227520e-001
6.000000e+003,3.755593e+002,3.695757e-004,-1.214757e-001
6.000000e+003,3.675607e+002,3.763209e-004,-1.174739e-001
6.000000e+003,3.597228e+002,3.773824e-004,-1.159701e-001
6.000000e+003,3.513754e+002,3.823184e-004,-1.117640e-001
6.000000e+003,3.438718e+002,3.831138e-004,-1.079855e-001
6.000000e+003,3.354696e+002,3.299485e-004,-9.988903e-002
6.000000e+003,3.277389e+002,2.386377e-004,-7.124227e-002
6.000000e+003,3.196459e+002,2.215278e-004,-6.397086e-002
6.000000e+003,3.117343e+002,2.194367e-004,-5.978603e-002
6.000000e+003,3.037418e+002,2.193021e-004,-5.853700e-002
6.000000e+003,3.033387e+002,2.191573e-004,-5.965009e-002
6.000000e+003,3.112276e+002,2.173100e-004,-6.369570e-002
6.000000e+003,3.192750e+002,2.173597e-004,-6.837299e-002
6.000000e+003,3.272327e+002,2.192834e-004,-7.248768e-002
6.000000e+003,3.352128e+002,2.271372e-004,-7.954551e-002
6.000000e+003,3.432289e+002,2.487949e-004,-9.018826e-002
6.000000e+003,3.512464e+002,2.962386e-004,-1.064630e-001
6.000000e+003,3.592963e+002,3.537956e-004,-1.212354e-001
6.000000e+003,3.672205e+002,3.716589e-004,-1.282296e-001
6.000000e+003,3.752261e+002,3.686903e-004,-1.313388e-001
6.000000e+003,3.832420e+002,3.636288e-004,-1.337301e-001
6.000000e+003,3.912130e+002,3.582555e-004,-1.357376e-001
6.000000e+003,3.992441e+002,3.526298e-004,-1.367348e-001
5.000000e+003,3.934318e+002,2.991204e-004,-1.291199e-001
5.000000e+003,3.854518e+002,3.047001e-004,-1.242509e-001
5.000000e+003,3.775938e+002,3.086507e-004,-1.231384e-001
5.000000e+003,3.693239e+002,3.144860e-004,-1.189812e-001
5.000000e+003,3.618448e+002,3.181903e-004,-1.156336e-001
5.000000e+003,3.534226e+002,3.196378e-004,-1.136676e-001
5.000000e+003,3.456746e+002,3.221061e-004,-1.093544e-001
5.000000e+003,3.374298e+002,2.982044e-004,-1.050957e-001
5.000000e+003,3.297089e+002,2.117001e-004,-7.841478e-002
5.000000e+003,3.215854e+002,1.887578e-004,-6.735341e-002
5.000000e+003,3.136699e+002,1.859351e-004,-6.213276e-002
5.000000e+003,3.057695e+002,1.852237e-004,-6.082145e-002
5.000000e+003,3.011915e+002,1.860749e-004,-6.039438e-002
5.000000e+003,3.093127e+002,1.842516e-004,-6.466258e-002
5.000000e+003,3.172233e+002,1.835820e-004,-6.886309e-002
5.000000e+003,3.252476e+002,1.849744e-004,-7.273309e-002
5.000000e+003,3.332614e+002,1.896419e-004,-7.854588e-002
5.000000e+003,3.414319e+002,2.045162e-004,-8.868795e-002
5.000000e+003,3.492107e+002,2.373178e-004,-1.031979e-001
5.000000e+003,3.572259e+002,2.865481e-004,-1.188616e-001
5.000000e+003,3.652361e+002,3.112174e-004,-1.277289e-001
5.000000e+003,3.732715e+002,3.101142e-004,-1.316591e-001
5.000000e+003,3.814143e+002,3.060891e-004,-1.336359e-001
5.000000e+003,3.892410e+002,3.017249e-004,-1.358470e-001
5.000000e+003,3.972182e+002,2.969028e-004,-1.370990e-001
4.000000e+003,3.955370e+002,2.403393e-004,-1.307797e-001
4.000000e+003,3.870742e+002,2.454080e-004,-1.261820e-001
4.000000e+003,3.798408e+002,2.481741e-004,-1.252102e-001
4.000000e+003,3.712187e+002,2.528813e-004,-1.206517e-001
4.000000e+003,3.637560e+002,2.566754e-004,-1.166658e-001
4.000000e+003,3.554013e+002,2.572401e-004,-1.151018e-001
4.000000e+003,3.475555e+002,2.599522e-004,-1.113223e-001
4.000000e+003,3.396478e+002,2.513470e-004,-1.086311e-001
4.000000e+003,3.315573e+002,1.847504e-004,-8.686075e-002
4.000000e+003,3.234918e+002,1.553762e-004,-7.109613e-002
4.000000e+003,3.156136e+002,1.520386e-004,-6.585477e-002
4.000000e+003,3.078994e+002,1.509937e-004,-6.320978e-002
4.000000e+003,3.000601e+002,1.522939e-004,-6.134983e-002
4.000000e+003,3.073109e+002,1.507754e-004,-6.596191e-002
4.000000e+003,3.152526e+002,1.500011e-004,-7.034746e-002
4.000000e+003,3.232817e+002,1.506818e-004,-7.416420e-002
4.000000e+003,3.312440e+002,1.535189e-004,-7.946832e-002
4.000000e+003,3.392330e+002,1.622655e-004,-8.741786e-002
4.000000e+003,3.472433e+002,1.843246e-004,-1.008842e-001
4.000000e+003,3.552919e+002,2.226538e-004,-1.165908e-001
4.000000e+003,3.632291e+002,2.495772e-004,-1.272289e-001
4.000000e+003,3.712324e+002,2.511230e-004,-1.317673e-001
4.000000e+003,3.792699e+002,2.479826e-004,-1.341168e-001
4.000000e+003,3.872167e+002,2.446657e-004,-1.362375e-001
4.000000e+003,3.952801e+002,2.409106e-004,-1.378748e-001
3.000000e+003,3.977527e+002,1.821689e-004,-1.338181e-001
3.000000e+003,3.886527e+002,1.859562e-004,-1.280630e-001
3.000000e+003,3.817973e+002,1.886766e-004,-1.247841e-001
3.000000e+003,3.730610e+002,1.915248e-004,-1.230276e-001
3.000000e+003,3.654003e+002,1.945770e-004,-1.187807e-001
3.000000e+003,3.574084e+002,1.949046e-004,-1.176818e-001
3.000000e+003,3.493087e+002,1.971781e-004,-1.132565e-001
3.000000e+003,3.417495e+002,1.938663e-004,-1.115139e-001
3.000000e+003,3.334633e+002,1.542316e-004,-9.632318e-002
3.000000e+003,3.259057e+002,1.226895e-004,-7.454867e-002
3.000000e+003,3.174751e+002,1.174530e-004,-6.936957e-002
3.000000e+003,3.098487e+002,1.166409e-004,-6.614155e-002
3.000000e+003,3.016389e+002,1.172168e-004,-6.419587e-002
3.000000e+003,3.053257e+002,1.165999e-004,-6.822440e-002
3.000000e+003,3.132049e+002,1.157701e-004,-7.205807e-002
3.000000e+003,3.213923e+002,1.160456e-004,-7.677931e-002
3.000000e+003,3.292222e+002,1.175576e-004,-8.088429e-002
3.000000e+003,3.372658e+002,1.225332e-004,-8.905062e-002
3.000000e+003,3.452489e+002,1.357802e-004,-9.944423e-002
3.000000e+003,3.532921e+002,1.622847e-004,-1.148994e-001
3.000000e+003,3.614341e+002,1.874225e-004,-1.269227e-001
3.000000e+003,3.692769e+002,1.913485e-004,-1.319190e-001
3.000000e+003,3.772741e+002,1.894417e-004,-1.349951e-001
3.000000e+003,3.852352e+002,1.868625e-004,-1.366039e-001
3.000000e+003,3.932622e+002,1.841713e-004,-1.391629e-001
2.500000e+003,3.999968e+002,1.529848e-004,-1.354820e-001
2.500000e+003,3.913466e+002,1.556013e-004,-1.311695e-001
2.500000e+003,3.836318e+002,1.583113e-004,-1.267474e-001
2.500000e+003,3.754028e+002,1.603962e-004,-1.251140e-001
2.500000e+003,3.670331e+002,1.632618e-004,-1.200082e-001
2.500000e+003,3.596084e+002,1.634331e-004,-1.193348e-001
2.500000e+003,3.511797e+002,1.654796e-004,-1.151808e-001
2.500000e+003,3.438339e+002,1.656261e-004,-1.112334e-001
2.500000e+003,3.353393e+002,1.421251e-004,-1.033619e-001
2.500000e+003,3.277581e+002,1.071805e-004,-7.906575e-002
2.500000e+003,3.194857e+002,1.002960e-004,-7.289407e-002
2.500000e+003,3.117535e+002,9.953482e-005,-7.268552e-002
2.500000e+003,3.035547e+002,9.943212e-005,-6.670708e-002
2.500000e+003,3.032915e+002,9.938625e-005,-6.923340e-002
2.500000e+003,3.112639e+002,9.859486e-005,-7.284280e-002
2.500000e+003,3.192710e+002,9.843182e-005,-7.795233e-002
2.500000e+003,3.272477e+002,9.947020e-005,-8.131441e-002
2.500000e+003,3.352555e+002,1.026213e-004,-8.807214e-002
2.500000e+003,3.432501e+002,1.113810e-004,-9.679705e-002
2.500000e+003,3.512711e+002,1.305489e-004,-1.119817e-001
2.500000e+003,3.592288e+002,1.537071e-004,-1.246993e-001
2.500000e+003,3.673021e+002,1.612709e-004,-1.319458e-001
2.500000e+003,3.752745e+002,1.599730e-004,-1.352899e-001
2.500000e+003,3.832271e+002,1.578612e-004,-1.376920e-001
2.500000e+003,3.912688e+002,1.556104e-004,-1.386086e-001
2.500000e+003,3.992893e+002,1.532883e-004,-1.410844e-001
2.000000e+003,3.933973e+002,1.255967e-004,-1.332378e-001
2.000000e+003,3.855119e+002,1.279093e-004,-1.288113e-001
2.000000e+003,3.776082e+002,1.294622e-004,-1.275206e-001
2.000000e+003,3.689529e+002,1.318566e-004,-1.224458e-001
2.000000e+003,3.618370e+002,1.331733e-004,-1.193344e-001
2.000000e+003,3.531670e+002,1.337050e-004,-1.169520e-001
2.000000e+003,3.456866e+002,1.345944e-004,-1.128091e-001
2.000000e+003,3.375482e+002,1.249307e-004,-1.093345e-001
2.000000e+003,3.296418e+002,9.144256e-005,-8.601606e-002
2.000000e+003,3.215525e+002,8.271627e-005,-7.677893e-002
2.000000e+003,3.135803e+002,8.170448e-005,-7.232091e-002
2.000000e+003,3.057105e+002,8.146754e-005,-7.066049e-002
2.000000e+003,3.012451e+002,8.172430e-005,-7.063524e-002
2.000000e+003,3.093146e+002,8.101060e-005,-7.333577e-002
2.000000e+003,3.172791e+002,8.071792e-005,-7.997490e-002
2.000000e+003,3.252708e+002,8.141985e-005,-8.342075e-002
2.000000e+003,3.332414e+002,8.322934e-005,-8.812820e-002
2.000000e+003,3.414389e+002,8.890487e-005,-9.782422e-002
2.000000e+003,3.492646e+002,1.017868e-004,-1.105456e-001
2.000000e+003,3.572977e+002,1.209385e-004,-1.240160e-001
2.000000e+003,3.652684e+002,1.304838e-004,-1.322885e-001
2.000000e+003,3.732378e+002,1.300386e-004,-1.355252e-001
2.000000e+003,3.814732e+002,1.285140e-004,-1.381058e-001
2.000000e+003,3.893239e+002,1.267205e-004,-1.403329e-001
2.000000e+003,3.972119e+002,1.248429e-004,-1.419798e-001
1.500000e+003,3.955496e+002,9.567321e-005,-1.356009e-001
1.500000e+003,3.860935e+002,9.763137e-005,-1.277359e-001
1.500000e+003,3.786979e+002,9.875630e-005,-1.299026e-001
1.500000e+003,3.698226e+002,1.006153e-004,-1.248509e-001
1.500000e+003,3.627567e+002,1.016912e-004,-1.211620e-001
1.500000e+003,3.541570e+002,1.019337e-004,-1.190670e-001
1.500000e+003,3.465872e+002,1.027657e-004,-1.144237e-001
1.500000e+003,3.385236e+002,9.764561e-005,-1.119781e-001
1.500000e+003,3.301886e+002,7.154226e-005,-9.040280e-002
1.500000e+003,3.226204e+002,6.433982e-005,-8.121695e-002
1.500000e+003,3.145650e+002,6.332916e-005,-7.516420e-002
1.500000e+003,3.068937e+002,6.309282e-005,-7.457601e-002
1.500000e+003,3.000441e+002,6.347230e-005,-7.144240e-002
1.500000e+003,3.082839e+002,6.293527e-005,-7.799202e-002
1.500000e+003,3.162287e+002,6.264512e-005,-8.129181e-002
1.500000e+003,3.242260e+002,6.299644e-005,-8.503503e-002
1.500000e+003,3.322846e+002,6.421046e-005,-9.070793e-002
1.500000e+003,3.402673e+002,6.787301e-005,-9.914208e-002
1.500000e+003,3.482545e+002,7.661676e-005,-1.110859e-001
1.500000e+003,3.562740e+002,9.090824e-005,-1.236733e-001
1.500000e+003,3.642658e+002,9.940242e-005,-1.319434e-001
1.500000e+003,3.722645e+002,9.946946e-005,-1.357143e-001
1.500000e+003,3.802731e+002,9.831884e-005,-1.385307e-001
1.500000e+003,3.882795e+002,9.705171e-005,-1.412077e-001
1.500000e+003,3.962360e+002,9.573674e-005,-1.438494e-001
1.000000e+003,3.966660e+002,6.538263e-005,-1.396602e-001
1.000000e+003,3.883898e+002,6.665165e-005,-1.345371e-001
1.000000e+003,3.808355e+002,6.752339e-005,-1.313049e-001
1.000000e+003,3.719294e+002,6.856128e-005,-1.281972e-001
1.000000e+003,3.644317e+002,6.954230e-005,-1.248466e-001
1.000000e+003,3.564733e+002,6.953799e-005,-1.230411e-001
1.000000e+003,3.481695e+002,7.028916e-005,-1.192690e-001
1.000000e+003,3.406569e+002,6.841263e-005,-1.165026e-001
1.000000e+003,3.324127e+002,5.375775e-005,-1.018801e-001
1.000000e+003,3.248943e+002,4.561045e-005,-8.761998e-002
1.000000e+003,3.165583e+002,4.433157e-005,-8.439739e-002
1.000000e+003,3.088387e+002,4.412459e-005,-7.912029e-002
1.000000e+003,3.005093e+002,5.355290e-005,-4.737922e-002
1.000000e+003,3.063389e+002,4.403027e-005,-8.241484e-002
1.000000e+003,3.142633e+002,4.380492e-005,-8.665853e-002
1.000000e+003,3.222195e+002,4.393090e-005,-9.061490e-002
1.000000e+003,3.302841e+002,4.452233e-005,-9.504233e-002
1.000000e+003,3.382281e+002,4.641943e-005,-1.016516e-001
1.000000e+003,3.462695e+002,5.116841e-005,-1.126660e-001
1.000000e+003,3.542550e+002,5.998669e-005,-1.237831e-001
1.000000e+003,3.622196e+002,6.742172e-005,-1.341780e-001
1.000000e+003,3.702645e+002,6.823987e-005,-1.383679e-001
1.000000e+003,3.782548e+002,6.763118e-005,-1.412994e-001
1.000000e+003,3.862082e+002,6.683597e-005,-1.436816e-001
1.000000e+003,3.942148e+002,6.593145e-005,-1.460892e-001
9.000000e+002,3.988349e+002,5.907645e-005,-1.432348e-001
9.000000e+002,3.903403e+002,6.007351e-005,-1.375625e-001
9.000000e+002,3.826871e+002,6.100229e-005,-1.328840e-001
9.000000e+002,3.742309e+002,6.184657e-005,-1.321001e-001
9.000000e+002,3.659420e+002,6.282594e-005,-1.268241e-001
9.000000e+002,3.586043e+002,6.278213e-005,-1.244006e-001
9.000000e+002,3.498949e+002,6.351846e-005,-1.200653e-001
9.000000e+002,3.429154e+002,6.322328e-005,-1.178946e-001
9.000000e+002,3.344653e+002,5.313439e-005,-1.090854e-001
9.000000e+002,3.267558e+002,4.244572e-005,-9.052826e-002
9.000000e+002,3.184439e+002,4.054741e-005,-8.637615e-002
9.000000e+002,3.107321e+002,4.023716e-005,-8.230045e-002
9.000000e+002,3.026422e+002,4.032339e-005,-7.984622e-002
9.000000e+002,3.043232e+002,4.025145e-005,-8.187450e-002
9.000000e+002,3.122601e+002,4.002119e-005,-8.814795e-002
9.000000e+002,3.202801e+002,3.996821e-005,-9.225437e-002
9.000000e+002,3.282424e+002,4.035063e-005,-9.503920e-002
9.000000e+002,3.362236e+002,4.169950e-005,-1.019590e-001
9.000000e+002,3.442987e+002,4.516044e-005,-1.099876e-001
9.000000e+002,3.522275e+002,5.220962e-005,-1.224582e-001
9.000000e+002,3.602548e+002,5.996450e-005,-1.335175e-001
9.000000e+002,3.682730e+002,6.188096e-005,-1.396279e-001
9.000000e+002,3.762072e+002,6.141902e-005,-1.419110e-001
9.000000e+002,3.842852e+002,6.067530e-005,-1.444743e-001
9.000000e+002,3.922613e+002,5.993083e-005,-1.467692e-001
9.000000e+002,3.999838e+002,5.908450e-005,-1.459569e-001
8.000000e+002,3.923926e+002,5.355874e-005,-1.398313e-001
8.000000e+002,3.845995e+002,5.446596e-005,-1.358096e-001
8.000000e+002,3.763647e+002,5.518182e-005,-1.337833e-001
8.000000e+002,3.676344e+002,5.609678e-005,-1.286445e-001
8.000000e+002,3.609142e+002,5.648450e-005,-1.254087e-001
8.000000e+002,3.522352e+002,5.665239e-005,-1.230443e-001
8.000000e+002,3.446696e+002,5.693796e-005,-1.186351e-001
8.000000e+002,3.364498e+002,5.139531e-005,-1.141619e-001
8.000000e+002,3.283907e+002,3.918778e-005,-9.409182e-002
8.000000e+002,3.206125e+002,3.675140e-005,-8.833358e-002
8.000000e+002,3.126448e+002,3.641077e-005,-8.491506e-002
8.000000e+002,3.046669e+002,3.638757e-005,-8.300777e-002
8.000000e+002,3.022655e+002,3.642935e-005,-8.322294e-002
8.000000e+002,3.102669e+002,3.614713e-005,-8.827989e-002
8.000000e+002,3.182426e+002,3.604609e-005,-9.283515e-002
8.000000e+002,3.262783e+002,3.639837e-005,-9.730494e-002
8.000000e+002,3.342932e+002,3.712418e-005,-1.019753e-001
8.000000e+002,3.422177e+002,3.959626e-005,-1.082490e-001
8.000000e+002,3.502340e+002,4.505963e-005,-1.195770e-001
8.000000e+002,3.582915e+002,5.240113e-005,-1.316165e-001
8.000000e+002,3.662147e+002,5.540476e-005,-1.387803e-001
8.000000e+002,3.742448e+002,5.521150e-005,-1.424975e-001
8.000000e+002,3.822579e+002,5.452351e-005,-1.447971e-001
8.000000e+002,3.902876e+002,5.386106e-005,-1.468608e-001
8.000000e+002,3.982948e+002,5.311353e-005,-1.487015e-001
7.000000e+002,3.945020e+002,4.694855e-005,-1.417934e-001
7.000000e+002,3.865469e+002,4.783094e-005,-1.366554e-001
7.000000e+002,3.786284e+002,4.845613e-005,-1.347879e-001
7.000000e+002,3.697039e+002,4.933436e-005,-1.297625e-001
7.000000e+002,3.627779e+002,4.984163e-005,-1.266308e-001
7.000000e+002,3.542250e+002,4.991223e-005,-1.241959e-001
7.000000e+002,3.466810e+002,5.030123e-005,-1.203172e-001
7.000000e+002,3.383633e+002,4.771347e-005,-1.176487e-001
7.000000e+002,3.305563e+002,3.651919e-005,-9.949343e-002
7.000000e+002,3.226701e+002,3.285531e-005,-9.117365e-002
7.000000e+002,3.145865e+002,3.240554e-005,-8.695220e-002
7.000000e+002,3.067934e+002,3.226168e-005,-8.547081e-002
7.000000e+002,3.000317e+002,3.250599e-005,-8.280876e-002
7.000000e+002,3.083477e+002,3.218995e-005,-8.890901e-002
7.000000e+002,3.162168e+002,3.203978e-005,-9.305048e-002
7.000000e+002,3.243306e+002,3.224731e-005,-9.739049e-002
7.000000e+002,3.322825e+002,3.276656e-005,-1.007869e-001
7.000000e+002,3.402418e+002,3.443778e-005,-1.079691e-001
7.000000e+002,3.482593e+002,3.840763e-005,-1.198082e-001
7.000000e+002,3.562715e+002,4.486508e-005,-1.309111e-001
7.000000e+002,3.642444e+002,4.869406e-005,-1.382236e-001
7.000000e+002,3.722029e+002,4.877187e-005,-1.409781e-001
7.000000e+002,3.802293e+002,4.827258e-005,-1.453727e-001
7.000000e+002,3.882460e+002,4.770800e-005,-1.466314e-001
7.000000e+002,3.962455e+002,4.706477e-005,-1.493048e-001
6.000000e+002,3.967011e+002,4.053143e-005,-1.445242e-001
6.000000e+002,3.883041e+002,4.132941e-005,-1.397511e-001
6.000000e+002,3.808589e+002,4.190781e-005,-1.352648e-001
6.000000e+002,3.720439e+002,4.252244e-005,-1.332694e-001
6.000000e+002,3.646137e+002,4.306722e-005,-1.282474e-001
6.000000e+002,3.564275e+002,4.302253e-005,-1.273864e-001
6.000000e+002,3.483763e+002,4.342938e-005,-1.217066e-001
6.000000e+002,3.406500e+002,4.238728e-005,-1.207914e-001
6.000000e+002,3.325780e+002,3.392872e-005,-1.075785e-001
6.000000e+002,3.249699e+002,2.902919e-005,-9.433140e-002
6.000000e+002,3.166080e+002,2.833065e-005,-9.181839e-002
6.000000e+002,3.088651e+002,2.816188e-005,-8.752397e-002
6.000000e+002,3.005590e+002,2.833919e-005,-8.598981e-002
6.000000e+002,3.062964e+002,2.813202e-005,-9.036722e-002
6.000000e+002,3.142437e+002,2.797923e-005,-9.434012e-002
6.000000e+002,3.222855e+002,2.807383e-005,-9.905656e-002
6.000000e+002,3.302254e+002,2.844770e-005,-1.032055e-001
6.000000e+002,3.382235e+002,2.951617e-005,-1.083739e-001
6.000000e+002,3.462142e+002,3.230242e-005,-1.176679e-001
6.000000e+002,3.542600e+002,3.750261e-005,-1.294767e-001
6.000000e+002,3.622064e+002,4.178781e-005,-1.381364e-001
6.000000e+002,3.702064e+002,4.227755e-005,-1.433502e-001
6.000000e+002,3.782375e+002,4.196430e-005,-1.460563e-001
6.000000e+002,3.862928e+002,4.148911e-005,-1.485889e-001
6.000000e+002,3.942842e+002,4.091564e-005,-1.503637e-001
5.000000e+002,3.988220e+002,3.401780e-005,-1.476862e-001
5.000000e+002,3.903218e+002,3.461337e-005,-1.419715e-001
5.000000e+002,3.827049e+002,3.522880e-005,-1.378282e-001
5.000000e+002,3.742678e+002,3.569346e-005,-1.357895e-001
5.000000e+002,3.661607e+002,3.618699e-005,-1.312804e-001
5.000000e+002,3.585009e+002,3.615805e-005,-1.296336e-001
5.000000e+002,3.501063e+002,3.655667e-005,-1.254858e-001
5.000000e+002,3.429955e+002,3.612240e-005,-1.216983e-001
5.000000e+002,3.345345e+002,3.091989e-005,-1.140846e-001
5.000000e+002,3.268430e+002,2.522454e-005,-9.835228e-002
5.000000e+002,3.185747e+002,2.416529e-005,-9.573415e-002
5.000000e+002,3.108123e+002,2.403692e-005,-9.264098e-002
5.000000e+002,3.025936e+002,2.404434e-005,-8.806656e-002
5.000000e+002,3.043433e+002,2.399873e-005,-9.252983e-002
5.000000e+002,3.122930e+002,2.386178e-005,-9.720627e-002
5.000000e+002,3.202231e+002,2.385029e-005,-1.002483e-001
5.000000e+002,3.282489e+002,2.412777e-005,-1.048380e-001
5.000000e+002,3.362054e+002,2.476731e-005,-1.111910e-001
5.000000e+002,3.442298e+002,2.664791e-005,-1.172247e-001
5.000000e+002,3.522449e+002,3.046151e-005,-1.286046e-001
5.000000e+002,3.602835e+002,3.466006e-005,-1.380583e-001
5.000000e+002,3.682484e+002,3.565336e-005,-1.442426e-001
5.000000e+002,3.762215e+002,3.541751e-005,-1.466387e-001
5.000000e+002,3.842703e+002,3.499750e-005,-1.493857e-001
5.000000e+002,3.922457e+002,3.462729e-005,-1.515946e-001
5.000000e+002,3.999903e+002,3.419400e-005,-1.510226e-001
4.000000e+002,3.924020e+002,2.791213e-005,-1.452651e-001
4.000000e+002,3.845965e+002,2.842662e-005,-1.404397e-001
4.000000e+002,3.764191e+002,2.875806e-005,-1.389675e-001
4.000000e+002,3.678989e+002,2.930771e-005,-1.350280e-001
4.000000e+002,3.608224e+002,2.928398e-005,-1.330573e-001
4.000000e+002,3.520361e+002,2.952553e-005,-1.289110e-001
4.000000e+002,3.447481e+002,2.963264e-005,-1.236910e-001
4.000000e+002,3.365334e+002,2.697965e-005,-1.199604e-001
4.000000e+002,3.286444e+002,2.117399e-005,-1.030550e-001
4.000000e+002,3.205452e+002,1.988032e-005,-9.916300e-002
4.000000e+002,3.126679e+002,1.973668e-005,-9.596036e-002
4.000000e+002,3.045974e+002,1.972678e-005,-9.454384e-002
4.000000e+002,3.029728e+002,1.976848e-005,-9.547970e-002
4.000000e+002,3.102194e+002,1.958704e-005,-9.908544e-002
4.000000e+002,3.182788e+002,1.953237e-005,-1.042047e-001
4.000000e+002,3.262614e+002,1.969286e-005,-1.073230e-001
4.000000e+002,3.342307e+002,2.009442e-005,-1.126321e-001
4.000000e+002,3.422458e+002,2.127674e-005,-1.187830e-001
4.000000e+002,3.502710e+002,2.393544e-005,-1.291542e-001
4.000000e+002,3.582863e+002,2.747965e-005,-1.393064e-001
4.000000e+002,3.662309e+002,2.893135e-005,-1.449117e-001
4.000000e+002,3.742193e+002,2.884943e-005,-1.482000e-001
4.000000e+002,3.822549e+002,2.848449e-005,-1.505727e-001
4.000000e+002,3.903000e+002,2.813306e-005,-1.533747e-001
4.000000e+002,3.982787e+002,2.777862e-005,-1.551784e-001
3.000000e+002,3.944863e+002,2.123861e-005,-1.492611e-001
3.000000e+002,3.865197e+002,2.158625e-005,-1.420923e-001
3.000000e+002,3.785646e+002,2.186776e-005,-1.452087e-001
3.000000e+002,3.697894e+002,2.229947e-005,-1.383794e-001
3.000000e+002,3.627196e+002,2.234279e-005,-1.350156e-001
3.000000e+002,3.542426e+002,2.240853e-005,-1.313652e-001
3.000000e+002,3.466352e+002,2.264021e-005,-1.282729e-001
3.000000e+002,3.385579e+002,2.158426e-005,-1.254126e-001
3.000000e+002,3.306435e+002,1.700398e-005,-1.114749e-001
3.000000e+002,3.225997e+002,1.548912e-005,-1.038901e-001
3.000000e+002,3.145473e+002,1.532809e-005,-1.014100e-001
3.000000e+002,3.067934e+002,1.519315e-005,-9.921838e-002
3.000000e+002,3.000353e+002,1.527453e-005,-9.714307e-002
3.000000e+002,3.082839e+002,1.514506e-005,-1.027231e-001
3.000000e+002,3.162505e+002,1.515588e-005,-1.080704e-001
3.000000e+002,3.243054e+002,1.518920e-005,-1.108957e-001
3.000000e+002,3.322604e+002,1.544912e-005,-1.160209e-001
3.000000e+002,3.402511e+002,1.609572e-005,-1.208485e-001
3.000000e+002,3.482253e+002,1.772996e-005,-1.279175e-001
3.000000e+002,3.562715e+002,2.039574e-005,-1.390103e-001
3.000000e+002,3.642791e+002,2.193977e-005,-1.461704e-001
3.000000e+002,3.722057e+002,2.196981e-005,-1.491433e-001
3.000000e+002,3.802820e+002,2.174691e-005,-1.508409e-001
3.000000e+002,3.882795e+002,2.158936e-005,-1.558821e-001
3.000000e+002,3.962518e+002,2.127598e-005,-1.566623e-001
2.000000e+002,3.967011e+002,1.445399e-005,-1.556744e-001
2.000000e+002,3.884142e+002,1.465571e-005,-1.490170e-001
2.000000e+002,3.808442e+002,1.491341e-005,-1.467138e-001
2.000000e+002,3.720830e+002,1.516461e-005,-1.436430e-001
2.000000e+002,3.646057e+002,1.529941e-005,-1.394148e-001
2.000000e+002,3.565194e+002,1.530970e-005,-1.389719e-001
2.000000e+002,3.485077e+002,1.544451e-005,-1.328031e-001
2.000000e+002,3.406407e+002,1.515433e-005,-1.330543e-001
2.000000e+002,3.325140e+002,1.241705e-005,-1.226941e-001
2.000000e+002,3.249153e+002,1.090383e-005,-1.108167e-001
2.000000e+002,3.166259e+002,1.067076e-005,-1.081743e-001
2.000000e+002,3.089085e+002,1.062804e-005,-1.058326e-001
2.000000e+002,3.006870e+002,1.072008e-005,-1.085791e-001
2.000000e+002,3.063445e+002,1.062224e-005,-1.101089e-001
2.000000e+002,3.142614e+002,1.055163e-005,-1.106455e-001
2.000000e+002,3.222690e+002,1.058853e-005,-1.176026e-001
2.000000e+002,3.302276e+002,1.069400e-005,-1.212281e-001
2.000000e+002,3.382898e+002,1.105975e-005,-1.284835e-001
2.000000e+002,3.463296e+002,1.194207e-005,-1.312650e-001
2.000000e+002,3.542348e+002,1.355714e-005,-1.421394e-001
2.000000e+002,3.622460e+002,1.489010e-005,-1.459738e-001
2.000000e+002,3.702561e+002,1.507074e-005,-1.514301e-001
2.000000e+002,3.782635e+002,1.494240e-005,-1.561014e-001
2.000000e+002,3.862686e+002,1.478594e-005,-1.590302e-001
2.000000e+002,3.942653e+002,1.457686e-005,-1.599168e-001
1.000000e+002,3.988091e+002,7.444914e-006,-1.710485e-001
1.000000e+002,3.902786e+002,7.599837e-006,-1.632414e-001
1.000000e+002,3.827226e+002,7.680774e-006,-1.599758e-001
1.000000e+002,3.743187e+002,7.874983e-006,-1.482117e-001
1.000000e+002,3.664258e+002,7.955108e-006,-1.501669e-001
1.000000e+002,3.585656e+002,7.972678e-006,-1.463046e-001
1.000000e+002,3.502367e+002,8.046793e-006,-1.438507e-001
1.000000e+002,3.429955e+002,7.978516e-006,-1.438853e-001
1.000000e+002,3.343581e+002,6.953575e-006,-1.349143e-001
1.000000e+002,3.268217e+002,6.052564e-006,-1.283808e-001
1.000000e+002,3.185466e+002,5.809743e-006,-1.279442e-001
1.000000e+002,3.107856e+002,5.814672e-006,-1.206122e-001
1.000000e+002,3.026404e+002,5.844187e-006,-1.217524e-001
1.000000e+002,3.042903e+002,5.842045e-006,-1.209371e-001
1.000000e+002,3.122601e+002,5.784042e-006,-1.175336e-001
1.000000e+002,3.202637e+002,5.771408e-006,-1.276815e-001
1.000000e+002,3.282017e+002,5.852887e-006,-1.360821e-001
1.000000e+002,3.365989e+002,5.950355e-006,-1.426107e-001
1.000000e+002,3.442726e+002,6.248007e-006,-1.450852e-001
1.000000e+002,3.522150e+002,6.950861e-006,-1.565732e-001
1.000000e+002,3.602704e+002,7.639724e-006,-1.552382e-001
1.000000e+002,3.682566e+002,7.884732e-006,-1.620544e-001
1.000000e+002,3.762729e+002,7.828783e-006,-1.678075e-001
1.000000e+002,3.842374e+002,7.742534e-006,-1.668059e-001
1.000000e+002,3.922613e+002,7.659390e-006,-1.749924e-001
1.000000e+002,3.999903e+002,7.597190e-006,-1.708635e-001
0.000000e+000,3.923676e+002,4.320476e-007,-6.425183e-001
0.000000e+000,3.846234e+002,3.969890e-007,-5.776430e-001
0.000000e+000,3.764821e+002,4.080507e-007,-4.938412e-001
0.000000e+000,3.680600e+002,4.373059e-007,-5.804048e-001
0.000000e+000,3.608198e+002,4.501836e-007,-5.518705e-001
0.000000e+000,3.520086e+002,4.939864e-007,-5.883307e-001
0.000000e+000,3.447791e+002,4.620302e-007,-4.673889e-001
0.000000e+000,3.364136e+002,5.317125e-007,-3.918303e-001
0.000000e+000,3.287305e+002,6.829495e-007,-3.840951e-001
0.000000e+000,3.206167e+002,7.592300e-007,-3.461260e-001
0.000000e+000,3.126738e+002,7.230384e-007,-3.311498e-001
0.000000e+000,3.046139e+002,7.436181e-007,-3.417577e-001
0.000000e+000,3.022781e+002,7.358597e-007,-3.010491e-001
0.000000e+000,3.102498e+002,7.568319e-007,-3.108176e-001
0.000000e+000,3.182667e+002,7.722944e-007,-3.660097e-001
0.000000e+000,3.262677e+002,7.087437e-007,-3.224999e-001
0.000000e+000,3.342552e+002,7.132238e-007,-3.768267e-001
0.000000e+000,3.425674e+002,6.930279e-007,-3.581490e-001
0.000000e+000,3.502882e+002,5.909009e-007,-4.122643e-001
0.000000e+000,3.582579e+002,4.979825e-007,-5.025683e-001
0.000000e+000,3.662201e+002,4.743284e-007,-4.757063e-001
0.000000e+000,3.742533e+002,3.719174e-007,-4.746674e-001
0.000000e+000,3.822342e+002,4.164958e-007,-4.874396e-001
0.000000e+000,3.903031e+002,4.641339e-007,-5.482778e-001
0.000000e+000,3.983076e+002,4.784104e-007,-4.944513e-001
0.000000e+000,3.999871e+002,4.123796e-007,-4.280556e-001