File: STO/STO-N10-2g-15a-500C-vac-MvT-231114.rso.dat
Time,Comment,Field (Oe),Temperature (K),Long Moment (emu),Long Scan Std Dev,Long Offset (cm),Long Offset Std Dev,Long Algorithm,Long Reg Fit,Long Reg Factor,Trans Moment (emu),Trans Scan Std Dev,Trans Offset (cm),Trans Offset Std Dev,Trans Algorithm,Trans Reg Fit,Trans Reg Factor,Long Moment [w/o ABS] (emu),Long Scan Std Dev [w/o ABS],Long Offset [w/o ABS] (cm),Long Offset Std Dev [w/o ABS],Long Reg Fit [w/o ABS],Trans Moment [w/o ABS] (emu),Trans Scan Std Dev [w/o ABS],Trans Offset [w/o ABS] (cm),Trans Offset Std Dev [w/o ABS],Trans Reg Fit [w/o ABS],RSO Position (deg),Amplitude (cm),Frequency,Cycles to Average,Scans per Measurement,Delta Temp (K),Error,EC Comp. Running,Using ABS,
1699984780.459,,3.000000e+002,1.999791e+000,7.927019e-005,9.600345e-009,-5.255961e-002,1.096240e-004,3,9.687377e-001,1.825000e+000,,,,,,,,,,,,,,,,,,0,4.000000e+000,1.000000e+000,2,2,2.912045e-003,0,,0,
1699985006.223,,3.000000e+002,4.075309e+000,4.619070e-005,3.381292e-007,-5.340919e-002,4.410194e-004,3,9.634426e-001,1.825000e+000,,,,,,,,,,,,,,,,,,0,4.000000e+000,1.000000e+000,2,2,1.026049e-001,0,,0,
1699985326.922,,3.000000e+002,6.130302e+000,3.391357e-005,2.583938e-007,-5.082478e-002,2.269002e-004,3,9.623037e-001,1.825000e+000,,,,,,,,,,,,,,,,,,0,4.000000e+000,1.000000e+000,2,2,1.922140e-001,0,,0,
1699985480.862,,3.000000e+002,8.111250e+000,2.710644e-005,2.036266e-007,-4.852193e-002,1.034334e-003,3,9.609995e-001,1.825000e+000,,,,,,,,,,,,,,,,,,0,4.000000e+000,1.000000e+000,2,2,1.675243e-001,0,,0,
1699985641.516,,3.000000e+002,1.023058e+001,2.248298e-005,1.299905e-007,-4.493255e-002,1.929693e-004,3,9.602726e-001,1.825000e+000,,,,,,,,,,,,,,,,,,0,4.000000e+000,1.000000e+000,2,2,1.642895e-001,0,,0,
1699985789.956,,3.000000e+002,1.212672e+001,1.970960e-005,1.008306e-007,-4.037525e-002,7.329995e-004,3,9.599456e-001,1.825000e+000,,,,,,,,,,,,,,,,,,0,4.000000e+000,1.000000e+000,2,2,1.726799e-001,0,,0,
1699985944.644,,3.000000e+002,1.414332e+001,1.775632e-005,7.491973e-008,-3.746881e-002,2.099242e-003,3,9.620826e-001,1.825000e+000,,,,,,,,,,,,,,,,,,0,4.000000e+000,1.000000e+000,2,2,1.806698e-001,0,,0,
1699986098.584,,3.000000e+002,1.611464e+001,1.639741e-005,3.815571e-008,-3.324964e-002,7.237562e-004,3,9.619903e-001,1.825000e+000,,,,,,,,,,,,,,,,,,0,4.000000e+000,1.000000e+000,2,2,1.799793e-001,0,,0,
1699986250.809,,3.000000e+002,1.810857e+001,1.540602e-005,8.836330e-009,-3.038990e-002,1.054198e-004,3,9.627500e-001,1.825000e+000,,,,,,,,,,,,,,,,,,0,4.000000e+000,1.000000e+000,2,2,1.640701e-001,0,,0,
1699986403.748,,3.000000e+002,2.012261e+001,1.469954e-005,5.248805e-008,-2.884156e-002,4.650338e-004,3,9.638026e-001,1.825000e+000,,,,,,,,,,,,,,,,,,0,4.000000e+000,1.000000e+000,2,2,1.801910e-001,0,,0,
1699986552.187,,3.000000e+002,2.209445e+001,1.413358e-005,4.894838e-008,-2.512209e-002,2.062825e-004,3,9.644400e-001,1.825000e+000,,,,,,,,,,,,,,,,,,0,4.000000e+000,1.000000e+000,2,2,1.640701e-001,0,,0,
1699986708.626,,3.000000e+002,2.412594e+001,1.376105e-005,3.260245e-008,-2.575308e-002,3.788568e-003,3,9.654948e-001,1.825000e+000,,,,,,,,,,,,,,,,,,0,4.000000e+000,1.000000e+000,2,2,1.750393e-001,0,,0,
1699986860.334,,3.000000e+002,2.608736e+001,1.338572e-005,7.282576e-009,-2.556682e-002,2.216002e-004,3,9.645189e-001,1.825000e+000,,,,,,,,,,,,,,,,,,0,4.000000e+000,1.000000e+000,2,2,1.688099e-001,0,,0,
1699987023.586,,3.000000e+002,2.812036e+001,1.317072e-005,1.430984e-008,-2.335875e-002,2.164395e-003,3,9.674439e-001,1.825000e+000,,,,,,,,,,,,,,,,,,0,4.000000e+000,1.000000e+000,2,2,1.770802e-001,0,,0,
1699987179.026,,3.000000e+002,3.014204e+001,1.293059e-005,2.563886e-008,-2.231502e-002,3.403758e-003,3,9.669202e-001,1.825000e+000,,,,,,,,,,,,,,,,,,0,4.000000e+000,1.000000e+000,2,2,1.326313e-001,0,,0,
1699987328.965,,3.000000e+002,3.210016e+001,1.280705e-005,5.887928e-008,-1.593051e-002,1.226601e-003,3,9.709388e-001,1.825000e+000,,,,,,,,,,,,,,,,,,0,4.000000e+000,1.000000e+000,2,2,1.628799e-001,0,,0,
1699987485.914,,3.000000e+002,3.410812e+001,1.261908e-005,3.162814e-008,-1.930180e-002,2.568821e-003,3,9.695336e-001,1.825000e+000,,,,,,,,,,,,,,,,,,0,4.000000e+000,1.000000e+000,2,2,1.797676e-001,0,,0,
1699987648.103,,3.000000e+002,3.612697e+001,1.244905e-005,1.541213e-008,-1.755203e-002,1.034153e-003,3,9.696077e-001,1.825000e+000,,,,,,,,,,,,,,,,,,0,4.000000e+000,1.000000e+000,2,2,1.662102e-001,0,,0,
1699987801.793,,3.000000e+002,3.814378e+001,1.227157e-005,2.146186e-008,-1.595580e-002,8.738043e-004,3,9.715812e-001,1.825000e+000,,,,,,,,,,,,,,,,,,0,4.000000e+000,1.000000e+000,2,2,1.795197e-001,0,,0,
1699987951.231,,3.000000e+002,4.010182e+001,1.233497e-005,1.405838e-008,-1.167170e-002,1.502473e-003,3,9.728794e-001,1.825000e+000,,,,,,,,,,,,,,,,,,0,4.000000e+000,1.000000e+000,2,2,1.778488e-001,0,,0,
1699988107.483,,3.000000e+002,4.212209e+001,1.282404e-005,8.646612e-009,-1.064930e-002,1.045524e-003,3,9.737014e-001,1.825000e+000,,,,,,,,,,,,,,,,,,0,4.000000e+000,1.000000e+000,2,2,1.624413e-001,0,,0,
1699988260.684,,3.000000e+002,4.411045e+001,1.399258e-005,3.780843e-008,-1.379332e-002,4.994757e-004,3,9.804368e-001,1.825000e+000,,,,,,,,,,,,,,,,,,0,4.000000e+000,1.000000e+000,2,2,1.802216e-001,0,,0,
1699988412.233,,3.000000e+002,4.612597e+001,1.616447e-005,9.542465e-008,-1.884250e-002,2.134853e-003,3,9.796984e-001,1.825000e+000,,,,,,,,,,,,,,,,,,0,4.000000e+000,1.000000e+000,2,2,1.795311e-001,0,,0,
1699988564.691,,3.000000e+002,4.812302e+001,1.841131e-005,1.270682e-007,-1.507365e-002,1.419045e-004,3,9.798152e-001,1.825000e+000,,,,,,,,,,,,,,,,,,0,4.000000e+000,1.000000e+000,2,2,1.792793e-001,0,,0,
1699988720.660,,3.000000e+002,5.011629e+001,2.105260e-005,2.711994e-008,-2.680593e-002,9.377292e-004,3,9.817712e-001,1.825000e+000,,,,,,,,,,,,,,,,,,0,4.000000e+000,1.000000e+000,2,2,1.773300e-001,0,,0,
1699988873.106,,3.000000e+002,5.212391e+001,1.900927e-005,2.849607e-007,-1.596132e-002,8.312280e-005,3,9.840174e-001,1.825000e+000,,,,,,,,,,,,,,,,,,0,4.000000e+000,1.000000e+000,2,2,1.601906e-001,0,,0,
1699989025.046,,3.000000e+002,5.409943e+001,1.378900e-005,3.971654e-008,-1.181453e-003,1.621976e-003,3,9.820507e-001,1.825000e+000,,,,,,,,,,,,,,,,,,0,4.000000e+000,1.000000e+000,2,2,1.653023e-001,0,,0,
1699989178.741,,3.000000e+002,5.611141e+001,1.349345e-005,1.143900e-008,-1.460442e-003,1.719265e-004,3,9.798660e-001,1.825000e+000,,,,,,,,,,,,,,,,,,0,4.000000e+000,1.000000e+000,2,2,1.733894e-001,0,,0,
1699989335.681,,3.000000e+002,5.812725e+001,1.407817e-005,2.893094e-008,-3.228820e-003,4.735913e-004,3,9.808906e-001,1.825000e+000,,,,,,,,,,,,,,,,,,0,4.000000e+000,1.000000e+000,2,2,1.609383e-001,0,,0,
1699989494.418,,3.000000e+002,6.012460e+001,1.408170e-005,5.571261e-009,-4.935690e-003,2.572676e-003,3,9.828572e-001,1.825000e+000,,,,,,,,,,,,,,,,,,0,4.000000e+000,1.000000e+000,2,2,1.584091e-001,0,,0,
1699989648.486,,3.000000e+002,6.213543e+001,1.316182e-005,6.786738e-009,-1.430808e-003,3.900117e-003,3,9.812593e-001,1.825000e+000,,,,,,,,,,,,,,,,,,0,4.000000e+000,1.000000e+000,2,2,1.665115e-001,0,,0,
1699989797.175,,3.000000e+002,6.410934e+001,1.192976e-005,3.229055e-008,2.256769e-003,1.694161e-003,3,9.826101e-001,1.825000e+000,,,,,,,,,,,,,,,,,,0,4.000000e+000,1.000000e+000,2,2,1.822968e-001,0,,0,
1699989953.877,,3.000000e+002,6.611067e+001,1.070995e-005,6.824039e-009,8.647792e-003,1.251603e-003,3,9.806525e-001,1.825000e+000,,,,,,,,,,,,,,,,,,0,4.000000e+000,1.000000e+000,2,2,1.675797e-001,0,,0,
1699990115.281,,3.000000e+002,6.821304e+001,9.656957e-006,3.263718e-008,1.597574e-002,7.092992e-004,3,9.792792e-001,1.825000e+000,,,,,,,,,,,,,,,,,,0,4.000000e+000,1.000000e+000,2,2,1.701508e-001,0,,0,
1699990264.221,,3.000000e+002,7.011967e+001,8.904065e-006,4.633992e-008,1.760941e-002,2.132886e-003,3,9.783443e-001,1.825000e+000,,,,,,,,,,,,,,,,,,0,4.000000e+000,1.000000e+000,2,2,1.788406e-001,0,,0,
1699990417.184,,3.000000e+002,7.213060e+001,8.366937e-006,1.088078e-008,2.147709e-002,1.964226e-003,3,9.779058e-001,1.825000e+000,,,,,,,,,,,,,,,,,,0,4.000000e+000,1.000000e+000,2,2,1.513367e-001,0,,0,
1699990573.125,,3.000000e+002,7.413136e+001,7.911909e-006,2.183165e-008,2.596345e-002,2.521325e-003,3,9.763675e-001,1.825000e+000,,,,,,,,,,,,,,,,,,0,4.000000e+000,1.000000e+000,2,2,1.774292e-001,0,,0,
1699990721.858,,3.000000e+002,7.609940e+001,7.562482e-006,2.313813e-008,3.346217e-002,1.262983e-004,3,9.757134e-001,1.825000e+000,,,,,,,,,,,,,,,,,,0,4.000000e+000,1.000000e+000,2,2,1.796951e-001,0,,0,
1699990877.048,,3.000000e+002,7.812000e+001,7.217766e-006,1.676459e-008,3.313231e-002,2.206171e-003,3,9.758584e-001,1.825000e+000,,,,,,,,,,,,,,,,,,0,4.000000e+000,1.000000e+000,2,2,1.772614e-001,0,,0,
1699991027.736,,3.000000e+002,8.011522e+001,7.022900e-006,3.696595e-009,3.568897e-002,1.829500e-003,3,9.751844e-001,1.825000e+000,,,,,,,,,,,,,,,,,,0,4.000000e+000,1.000000e+000,2,2,1.806107e-001,0,,0,
1699991181.676,,3.000000e+002,8.212611e+001,6.874584e-006,2.148727e-008,3.526985e-002,6.696924e-004,3,9.722825e-001,1.825000e+000,,,,,,,,,,,,,,,,,,0,4.000000e+000,1.000000e+000,2,2,1.936035e-001,0,,0,
1699991331.365,,3.000000e+002,8.410773e+001,6.734311e-006,4.855586e-011,3.680467e-002,2.413157e-003,3,9.732577e-001,1.825000e+000,,,,,,,,,,,,,,,,,,0,4.000000e+000,1.000000e+000,2,2,1.789398e-001,0,,0,
1699991485.137,,3.000000e+002,8.613639e+001,6.632162e-006,1.389760e-008,3.906775e-002,1.355084e-003,3,9.715736e-001,1.825000e+000,,,,,,,,,,,,,,,,,,0,4.000000e+000,1.000000e+000,2,2,1.759872e-001,0,,0,
1699991632.626,,3.000000e+002,8.809386e+001,6.547420e-006,3.150692e-008,4.067073e-002,1.022941e-003,3,9.740886e-001,1.825000e+000,,,,,,,,,,,,,,,,,,0,4.000000e+000,1.000000e+000,2,2,1.804199e-001,0,,0,
1699991785.816,,3.000000e+002,9.011021e+001,6.489536e-006,1.827461e-008,4.053123e-002,1.043912e-003,3,9.733168e-001,1.825000e+000,,,,,,,,,,,,,,,,,,0,4.000000e+000,1.000000e+000,2,2,1.762085e-001,0,,0,
1699991939.807,,3.000000e+002,9.210371e+001,6.431301e-006,2.524849e-009,4.032436e-002,3.535462e-003,3,9.719377e-001,1.825000e+000,,,,,,,,,,,,,,,,,,0,4.000000e+000,1.000000e+000,2,2,1.651230e-001,0,,0,
1699992093.818,,3.000000e+002,9.411568e+001,6.368155e-006,1.320530e-008,3.807381e-002,2.965215e-003,3,9.757336e-001,1.825000e+000,,,,,,,,,,,,,,,,,,0,4.000000e+000,1.000000e+000,2,2,1.652832e-001,0,,0,
1699992246.556,,3.000000e+002,9.612743e+001,6.335980e-006,1.984315e-009,4.363700e-002,1.026197e-004,3,9.736674e-001,1.825000e+000,,,,,,,,,,,,,,,,,,0,4.000000e+000,1.000000e+000,2,2,1.651611e-001,0,,0,
1699992398.057,,3.000000e+002,9.812526e+001,6.353966e-006,1.203484e-008,3.950628e-002,9.036916e-004,3,9.717765e-001,1.825000e+000,,,,,,,,,,,,,,,,,,0,4.000000e+000,1.000000e+000,2,2,1.780319e-001,0,,0,
1699992548.508,,3.000000e+002,1.001156e+002,6.353010e-006,6.816643e-009,3.566168e-002,2.568408e-003,3,9.717987e-001,1.825000e+000,,,,,,,,,,,,,,,,,,0,4.000000e+000,1.000000e+000,2,2,1.637039e-001,0,,0,
1699992701.448,,3.000000e+002,1.021277e+002,6.345699e-006,3.317193e-008,3.787382e-002,4.559420e-003,3,9.728647e-001,1.825000e+000,,,,,,,,,,,,,,,,,,0,4.000000e+000,1.000000e+000,2,2,1.587982e-001,0,,0,
1699992850.636,,3.000000e+002,1.040986e+002,6.351288e-006,8.383259e-009,3.985830e-002,4.703646e-003,3,9.735467e-001,1.825000e+000,,,,,,,,,,,,,,,,,,0,4.000000e+000,1.000000e+000,2,2,1.791992e-001,0,,0,
1699993005.326,,3.000000e+002,1.061407e+002,6.374740e-006,4.214299e-009,3.918458e-002,2.826789e-003,3,9.713665e-001,1.825000e+000,,,,,,,,,,,,,,,,,,0,4.000000e+000,1.000000e+000,2,2,1.856003e-001,0,,0,
1699993155.266,,3.000000e+002,1.081109e+002,6.427334e-006,3.119951e-008,3.515146e-002,1.194903e-003,3,9.734098e-001,1.825000e+000,,,,,,,,,,,,,,,,,,0,4.000000e+000,1.000000e+000,2,2,1.557999e-001,0,,0,
1699993310.516,,3.000000e+002,1.101025e+002,6.447581e-006,3.449545e-008,3.651798e-002,4.071957e-003,3,9.706767e-001,1.825000e+000,,,,,,,,,,,,,,,,,,0,4.000000e+000,1.000000e+000,2,2,1.817932e-001,0,,0,
1699993463.210,,3.000000e+002,1.121220e+002,6.458966e-006,1.898300e-008,3.485757e-002,7.531062e-004,3,9.730263e-001,1.825000e+000,,,,,,,,,,,,,,,,,,0,4.000000e+000,1.000000e+000,2,2,1.622009e-001,0,,0,
1699993613.432,,3.000000e+002,1.140972e+002,6.464681e-006,5.460646e-009,3.593497e-002,1.461042e-003,3,9.761015e-001,1.825000e+000,,,,,,,,,,,,,,,,,,0,4.000000e+000,1.000000e+000,2,2,1.805038e-001,0,,0,
1699993767.157,,3.000000e+002,1.161113e+002,6.490215e-006,1.283294e-008,3.602477e-002,2.561783e-003,3,9.727843e-001,1.825000e+000,,,,,,,,,,,,,,,,,,0,4.000000e+000,1.000000e+000,2,2,1.680984e-001,0,,0,
1699993924.596,,3.000000e+002,1.181327e+002,6.475826e-006,3.841488e-008,3.317031e-002,2.099240e-003,3,9.731275e-001,1.825000e+000,,,,,,,,,,,,,,,,,,0,4.000000e+000,1.000000e+000,2,2,1.781006e-001,0,,0,
1699994078.036,,3.000000e+002,1.200986e+002,6.520436e-006,3.577042e-008,3.083778e-002,3.784128e-004,3,9.750862e-001,1.825000e+000,,,,,,,,,,,,,,,,,,0,4.000000e+000,1.000000e+000,2,2,1.689987e-001,0,,0,
1699994237.726,,3.000000e+002,1.221232e+002,6.503651e-006,5.043300e-008,2.989016e-002,1.169127e-003,3,9.733496e-001,1.825000e+000,,,,,,,,,,,,,,,,,,0,4.000000e+000,1.000000e+000,2,2,1.741028e-001,0,,0,
1699994387.915,,3.000000e+002,1.241038e+002,6.512087e-006,1.496002e-008,3.204952e-002,5.297167e-003,3,9.710540e-001,1.825000e+000,,,,,,,,,,,,,,,,,,0,4.000000e+000,1.000000e+000,2,2,1.690979e-001,0,,0,
1699994538.604,,3.000000e+002,1.261287e+002,6.526161e-006,9.882026e-009,2.793102e-002,3.637136e-003,3,9.723585e-001,1.825000e+000,,,,,,,,,,,,,,,,,,0,4.000000e+000,1.000000e+000,2,2,1.688004e-001,0,,0,
1699994695.044,,3.000000e+002,1.281277e+002,6.536041e-006,9.270429e-009,3.010623e-002,5.888705e-003,3,9.715160e-001,1.825000e+000,,,,,,,,,,,,,,,,,,0,4.000000e+000,1.000000e+000,2,2,1.737061e-001,0,,0,
1699994847.016,,3.000000e+002,1.301129e+002,6.526997e-006,2.609708e-008,3.246599e-002,5.981165e-004,3,9.712676e-001,1.825000e+000,,,,,,,,,,,,,,,,,,0,4.000000e+000,1.000000e+000,2,2,1.786041e-001,0,,0,
1699994997.455,,3.000000e+002,1.321025e+002,6.538511e-006,2.987471e-008,3.259353e-002,1.712790e-003,3,9.753354e-001,1.825000e+000,,,,,,,,,,,,,,,,,,0,4.000000e+000,1.000000e+000,2,2,1.950073e-001,0,,0,
1699995151.413,,3.000000e+002,1.341272e+002,6.528008e-006,7.687735e-009,2.778512e-002,1.611858e-003,3,9.718750e-001,1.825000e+000,,,,,,,,,,,,,,,,,,0,4.000000e+000,1.000000e+000,2,2,1.945038e-001,0,,0,
1699995301.357,,3.000000e+002,1.360966e+002,6.501432e-006,6.268071e-009,3.080693e-002,1.339572e-004,3,9.750770e-001,1.825000e+000,,,,,,,,,,,,,,,,,,0,4.000000e+000,1.000000e+000,2,2,1.815948e-001,0,,0,
1699995457.046,,3.000000e+002,1.381206e+002,6.504375e-006,3.960013e-008,2.375881e-002,1.317197e-003,3,9.724297e-001,1.825000e+000,,,,,,,,,,,,,,,,,,0,4.000000e+000,1.000000e+000,2,2,1.739960e-001,0,,0,
1699995612.244,,3.000000e+002,1.401025e+002,6.513014e-006,4.177963e-009,2.807636e-002,4.777345e-003,3,9.730773e-001,1.825000e+000,,,,,,,,,,,,,,,,,,0,4.000000e+000,1.000000e+000,2,2,1.849976e-001,0,,0,
1699995771.184,,3.000000e+002,1.421481e+002,6.524933e-006,2.433045e-008,2.537569e-002,1.440546e-003,3,9.747760e-001,1.825000e+000,,,,,,,,,,,,,,,,,,0,4.000000e+000,1.000000e+000,2,2,1.898956e-001,0,,0,
1699995919.123,,3.000000e+002,1.441040e+002,6.505877e-006,1.295159e-008,2.793886e-002,3.939853e-003,3,9.713887e-001,1.825000e+000,,,,,,,,,,,,,,,,,,0,4.000000e+000,1.000000e+000,2,2,1.947937e-001,0,,0,
1699996073.106,,3.000000e+002,1.461207e+002,6.533481e-006,2.394652e-008,2.421850e-002,3.240985e-003,3,9.740287e-001,1.825000e+000,,,,,,,,,,,,,,,,,,0,4.000000e+000,1.000000e+000,2,2,1.793060e-001,0,,0,
1699996226.115,,3.000000e+002,1.481015e+002,6.517563e-006,5.799886e-009,2.317603e-002,2.570802e-003,3,9.722518e-001,1.825000e+000,,,,,,,,,,,,,,,,,,0,4.000000e+000,1.000000e+000,2,2,1.981049e-001,0,,0,
1699996380.303,,3.000000e+002,1.501211e+002,6.512434e-006,6.573547e-009,2.260965e-002,4.007321e-003,3,9.707549e-001,1.825000e+000,,,,,,,,,,,,,,,,,,0,4.000000e+000,1.000000e+000,2,2,1.815033e-001,0,,0,
1699996536.993,,3.000000e+002,1.520951e+002,6.523216e-006,7.924721e-009,2.451444e-002,7.097437e-003,3,9.737897e-001,1.825000e+000,,,,,,,,,,,,,,,,,,0,4.000000e+000,1.000000e+000,2,2,1.860962e-001,0,,0,
1699996693.500,,3.000000e+002,1.541229e+002,6.514298e-006,1.223163e-008,2.386379e-002,1.442968e-003,3,9.713147e-001,1.825000e+000,,,,,,,,,,,,,,,,,,0,4.000000e+000,1.000000e+000,2,2,1.907959e-001,0,,0,
1699996846.440,,3.000000e+002,1.561127e+002,6.539950e-006,2.529287e-008,1.933071e-002,4.917039e-003,3,9.748460e-001,1.825000e+000,,,,,,,,,,,,,,,,,,0,4.000000e+000,1.000000e+000,2,2,1.956024e-001,0,,0,
1699997000.152,,3.000000e+002,1.581148e+002,6.526688e-006,1.348441e-008,1.948568e-002,7.283873e-003,3,9.743646e-001,1.825000e+000,,,,,,,,,,,,,,,,,,0,4.000000e+000,1.000000e+000,2,2,1.521912e-001,0,,0,
1699997156.342,,3.000000e+002,1.601178e+002,6.527098e-006,1.053157e-008,2.310701e-002,2.209408e-003,3,9.717793e-001,1.825000e+000,,,,,,,,,,,,,,,,,,0,4.000000e+000,1.000000e+000,2,2,1.804962e-001,0,,0,
1699997307.281,,3.000000e+002,1.621147e+002,6.513475e-006,4.942010e-008,2.295833e-002,1.614066e-003,3,9.765805e-001,1.825000e+000,,,,,,,,,,,,,,,,,,0,4.000000e+000,1.000000e+000,2,2,1.554108e-001,0,,0,
1699997460.751,,3.000000e+002,1.641051e+002,6.506331e-006,1.875276e-008,2.056087e-002,1.027922e-003,3,9.715781e-001,1.825000e+000,,,,,,,,,,,,,,,,,,0,4.000000e+000,1.000000e+000,2,2,1.674957e-001,0,,0,
1699997615.967,,3.000000e+002,1.661048e+002,6.550642e-006,2.010008e-008,1.594281e-002,4.272245e-003,3,9.705998e-001,1.825000e+000,,,,,,,,,,,,,,,,,,0,4.000000e+000,1.000000e+000,2,2,1.713104e-001,0,,0,
1699997770.407,,3.000000e+002,1.681154e+002,6.560374e-006,3.162171e-008,2.372759e-002,1.810089e-003,3,9.699587e-001,1.825000e+000,,,,,,,,,,,,,,,,,,0,4.000000e+000,1.000000e+000,2,2,1.618042e-001,0,,0,
1699997921.846,,3.000000e+002,1.701130e+002,6.533616e-006,7.444640e-009,2.047034e-002,1.346656e-003,3,9.746615e-001,1.825000e+000,,,,,,,,,,,,,,,,,,0,4.000000e+000,1.000000e+000,2,2,1.561127e-001,0,,0,
1699998078.035,,3.000000e+002,1.721105e+002,6.529569e-006,4.462154e-008,1.957288e-002,1.567562e-003,3,9.700254e-001,1.825000e+000,,,,,,,,,,,,,,,,,,0,4.000000e+000,1.000000e+000,2,2,1.596069e-001,0,,0,
1699998230.287,,3.000000e+002,1.741172e+002,6.526943e-006,4.171854e-009,1.397824e-002,2.527056e-003,3,9.739066e-001,1.825000e+000,,,,,,,,,,,,,,,,,,0,4.000000e+000,1.000000e+000,2,2,1.582031e-001,0,,0,
1699998382.534,,3.000000e+002,1.761078e+002,6.553752e-006,4.052557e-009,1.631318e-002,6.342368e-003,3,9.707398e-001,1.825000e+000,,,,,,,,,,,,,,,,,,0,4.000000e+000,1.000000e+000,2,2,1.615906e-001,0,,0,
1699998538.225,,3.000000e+002,1.781138e+002,6.531767e-006,2.640191e-008,2.144028e-002,1.263154e-003,3,9.709353e-001,1.825000e+000,,,,,,,,,,,,,,,,,,0,4.000000e+000,1.000000e+000,2,2,1.501007e-001,0,,0,
1699998693.417,,3.000000e+002,1.801255e+002,6.538786e-006,2.321723e-008,1.744414e-002,7.720420e-004,3,9.748632e-001,1.825000e+000,,,,,,,,,,,,,,,,,,0,4.000000e+000,1.000000e+000,2,2,1.635132e-001,0,,0,
1699998847.357,,3.000000e+002,1.821449e+002,6.547946e-006,3.458742e-008,1.942352e-002,2.575159e-003,3,9.718502e-001,1.825000e+000,,,,,,,,,,,,,,,,,,0,4.000000e+000,1.000000e+000,2,2,1.616974e-001,0,,0,
1699998995.812,,3.000000e+002,1.840894e+002,6.548447e-006,7.872630e-009,1.807291e-002,8.295306e-003,3,9.691503e-001,1.825000e+000,,,,,,,,,,,,,,,,,,0,4.000000e+000,1.000000e+000,2,2,1.757050e-001,0,,0,
1699999156.039,,3.000000e+002,1.861190e+002,6.552009e-006,3.393369e-009,1.886656e-002,1.420674e-003,3,9.731266e-001,1.825000e+000,,,,,,,,,,,,,,,,,,0,4.000000e+000,1.000000e+000,2,2,1.741028e-001,0,,0,
1699999311.730,,3.000000e+002,1.881298e+002,6.558508e-006,2.471246e-008,2.076923e-002,4.007651e-003,3,9.721118e-001,1.825000e+000,,,,,,,,,,,,,,,,,,0,4.000000e+000,1.000000e+000,2,2,1.831970e-001,0,,0,
1699999463.422,,3.000000e+002,1.901080e+002,6.570463e-006,1.679031e-008,1.734148e-002,3.814107e-003,3,9.718382e-001,1.825000e+000,,,,,,,,,,,,,,,,,,0,4.000000e+000,1.000000e+000,2,2,1.698914e-001,0,,0,
1699999616.862,,3.000000e+002,1.921209e+002,6.549183e-006,2.582408e-008,1.709626e-002,2.002829e-003,3,9.738698e-001,1.825000e+000,,,,,,,,,,,,,,,,,,0,4.000000e+000,1.000000e+000,2,2,1.850128e-001,0,,0,
1699999768.843,,3.000000e+002,1.941120e+002,6.543398e-006,1.186377e-008,1.314035e-002,1.811494e-003,3,9.733351e-001,1.825000e+000,,,,,,,,,,,,,,,,,,0,4.000000e+000,1.000000e+000,2,2,1.946106e-001,0,,0,
1699999926.536,,3.000000e+002,1.961480e+002,6.560522e-006,1.592662e-009,1.534271e-002,2.315335e-003,3,9.747955e-001,1.825000e+000,,,,,,,,,,,,,,,,,,0,4.000000e+000,1.000000e+000,2,2,1.924896e-001,0,,0,
1700000075.728,,3.000000e+002,1.980999e+002,6.562238e-006,2.244003e-008,1.587077e-002,4.319762e-004,3,9.717966e-001,1.825000e+000,,,,,,,,,,,,,,,,,,0,4.000000e+000,1.000000e+000,2,2,1.656036e-001,0,,0,
1700000226.451,,3.000000e+002,2.001022e+002,6.586502e-006,1.109879e-008,1.483832e-002,1.389667e-003,3,9.772165e-001,1.825000e+000,,,,,,,,,,,,,,,,,,0,4.000000e+000,1.000000e+000,2,2,1.752014e-001,0,,0,
1700000384.394,,3.000000e+002,2.021298e+002,6.587427e-006,3.650292e-009,1.177434e-002,5.201238e-004,3,9.721913e-001,1.825000e+000,,,,,,,,,,,,,,,,,,0,4.000000e+000,1.000000e+000,2,2,1.786041e-001,0,,0,
1700000537.364,,3.000000e+002,2.041292e+002,6.586941e-006,1.343971e-008,1.125424e-002,3.051058e-003,3,9.704586e-001,1.825000e+000,,,,,,,,,,,,,,,,,,0,4.000000e+000,1.000000e+000,2,2,1.560059e-001,0,,0,
1700000695.594,,3.000000e+002,2.061109e+002,6.580254e-006,1.797074e-008,1.480486e-002,5.679953e-004,3,9.742257e-001,1.825000e+000,,,,,,,,,,,,,,,,,,0,4.000000e+000,1.000000e+000,2,2,1.590118e-001,0,,0,
1700000850.536,,3.000000e+002,2.081379e+002,6.614012e-006,2.504752e-008,1.078888e-002,1.653290e-003,3,9.716513e-001,1.825000e+000,,,,,,,,,,,,,,,,,,0,4.000000e+000,1.000000e+000,2,2,1.822968e-001,0,,0,
1700000999.531,,3.000000e+002,2.101092e+002,6.605763e-006,1.603498e-008,1.133113e-002,1.202261e-003,3,9.771625e-001,1.825000e+000,,,,,,,,,,,,,,,,,,0,4.000000e+000,1.000000e+000,2,2,1.788025e-001,0,,0,
1700001152.471,,3.000000e+002,2.121034e+002,6.604506e-006,1.570732e-008,1.211076e-002,4.061896e-004,3,9.746335e-001,1.825000e+000,,,,,,,,,,,,,,,,,,0,4.000000e+000,1.000000e+000,2,2,1.750946e-001,0,,0,
1700001309.413,,3.000000e+002,2.141278e+002,6.613582e-006,6.019508e-010,9.209460e-003,2.230573e-003,3,9.732361e-001,1.825000e+000,,,,,,,,,,,,,,,,,,0,4.000000e+000,1.000000e+000,2,2,1.569977e-001,0,,0,
1700001460.604,,3.000000e+002,2.161214e+002,6.570160e-006,4.889404e-008,7.883158e-003,7.610940e-004,3,9.713249e-001,1.825000e+000,,,,,,,,,,,,,,,,,,0,4.000000e+000,1.000000e+000,2,2,1.817932e-001,0,,0,
1700001613.084,,3.000000e+002,2.181073e+002,6.578357e-006,1.117243e-008,7.452773e-003,5.652795e-003,3,9.712628e-001,1.825000e+000,,,,,,,,,,,,,,,,,,0,4.000000e+000,1.000000e+000,2,2,1.923981e-001,0,,0,
1700001771.275,,3.000000e+002,2.201444e+002,6.593486e-006,1.293294e-008,7.997772e-003,3.347979e-003,3,9.735768e-001,1.825000e+000,,,,,,,,,,,,,,,,,,0,4.000000e+000,1.000000e+000,2,2,1.733093e-001,0,,0,
1700001921.753,,3.000000e+002,2.220963e+002,6.640497e-006,1.762603e-008,8.871090e-003,6.862692e-006,3,9.726753e-001,1.825000e+000,,,,,,,,,,,,,,,,,,0,4.000000e+000,1.000000e+000,2,2,1.840973e-001,0,,0,
1700002077.194,,3.000000e+002,2.241156e+002,6.637708e-006,1.786302e-008,1.051171e-002,6.181395e-004,3,9.726741e-001,1.825000e+000,,,,,,,,,,,,,,,,,,0,4.000000e+000,1.000000e+000,2,2,1.717072e-001,0,,0,
1700002227.664,,3.000000e+002,2.261137e+002,6.614501e-006,2.138019e-009,6.669713e-003,2.733042e-003,3,9.707249e-001,1.825000e+000,,,,,,,,,,,,,,,,,,0,4.000000e+000,1.000000e+000,2,2,1.826935e-001,0,,0,
1700002378.403,,3.000000e+002,2.281006e+002,6.637619e-006,2.704502e-008,5.764052e-003,1.604636e-004,3,9.721867e-001,1.825000e+000,,,,,,,,,,,,,,,,,,0,4.000000e+000,1.000000e+000,2,2,1.696930e-001,0,,0,
1700002534.599,,3.000000e+002,2.301281e+002,6.632785e-006,1.504941e-008,4.269793e-003,1.771503e-003,3,9.727110e-001,1.825000e+000,,,,,,,,,,,,,,,,,,0,4.000000e+000,1.000000e+000,2,2,1.644135e-001,0,,0,
1700002685.290,,3.000000e+002,2.321119e+002,6.630058e-006,3.221530e-008,2.578160e-003,2.061988e-003,3,9.754192e-001,1.825000e+000,,,,,,,,,,,,,,,,,,0,4.000000e+000,1.000000e+000,2,2,1.755981e-001,0,,0,
1700002837.830,,3.000000e+002,2.341316e+002,6.615212e-006,4.458037e-009,5.664721e-003,8.628665e-004,3,9.720395e-001,1.825000e+000,,,,,,,,,,,,,,,,,,0,4.000000e+000,1.000000e+000,2,2,1.616974e-001,0,,0,
1700002986.771,,3.000000e+002,2.361225e+002,6.621776e-006,1.785627e-008,1.566537e-003,7.972135e-004,3,9.719861e-001,1.825000e+000,,,,,,,,,,,,,,,,,,0,4.000000e+000,1.000000e+000,2,2,1.817932e-001,0,,0,
1700003139.183,,3.000000e+002,2.381059e+002,6.646928e-006,1.751767e-008,6.455871e-003,5.410700e-003,3,9.712902e-001,1.825000e+000,,,,,,,,,,,,,,,,,,0,4.000000e+000,1.000000e+000,2,2,1.584015e-001,0,,0,
1700003293.374,,3.000000e+002,2.401164e+002,6.618064e-006,7.123085e-009,4.933863e-003,2.522421e-003,3,9.705057e-001,1.825000e+000,,,,,,,,,,,,,,,,,,0,4.000000e+000,1.000000e+000,2,2,1.611023e-001,0,,0,
1700003445.116,,3.000000e+002,2.421341e+002,6.694603e-006,8.038231e-009,4.001675e-003,4.785882e-003,3,9.725153e-001,1.825000e+000,,,,,,,,,,,,,,,,,,0,4.000000e+000,1.000000e+000,2,2,1.639099e-001,0,,0,
1700003597.307,,3.000000e+002,2.441097e+002,6.636681e-006,5.155394e-008,2.331525e-003,2.093600e-003,3,9.723564e-001,1.825000e+000,,,,,,,,,,,,,,,,,,0,4.000000e+000,1.000000e+000,2,2,1.665039e-001,0,,0,
1700003752.299,,3.000000e+002,2.461111e+002,6.644975e-006,9.499376e-009,-2.181177e-004,4.748369e-003,3,9.730654e-001,1.825000e+000,,,,,,,,,,,,,,,,,,0,4.000000e+000,1.000000e+000,2,2,1.975098e-001,0,,0,
1700003903.740,,3.000000e+002,2.481217e+002,6.637444e-006,1.396192e-008,2.641065e-003,4.400548e-003,3,9.717008e-001,1.825000e+000,,,,,,,,,,,,,,,,,,0,4.000000e+000,1.000000e+000,2,2,1.817017e-001,0,,0,
1700004053.462,,3.000000e+002,2.500977e+002,6.640166e-006,3.737336e-008,1.575947e-003,2.608751e-003,3,9.719931e-001,1.825000e+000,,,,,,,,,,,,,,,,,,0,4.000000e+000,1.000000e+000,2,2,1.652069e-001,0,,0,
1700004207.403,,3.000000e+002,2.521277e+002,6.639508e-006,3.471668e-008,2.579546e-003,3.409386e-003,3,9.705991e-001,1.825000e+000,,,,,,,,,,,,,,,,,,0,4.000000e+000,1.000000e+000,2,2,1.777039e-001,0,,0,
1700004361.904,,3.000000e+002,2.541335e+002,6.694850e-006,3.307739e-008,1.961361e-003,5.037705e-004,3,9.706268e-001,1.825000e+000,,,,,,,,,,,,,,,,,,0,4.000000e+000,1.000000e+000,2,2,1.806030e-001,0,,0,
1700004511.094,,3.000000e+002,2.561104e+002,6.652501e-006,1.058237e-008,2.157254e-003,3.133882e-003,3,9.680415e-001,1.825000e+000,,,,,,,,,,,,,,,,,,0,4.000000e+000,1.000000e+000,2,2,1.629944e-001,0,,0,
1700004666.587,,3.000000e+002,2.581185e+002,6.668127e-006,1.786334e-008,-1.194842e-003,6.214960e-004,3,9.734343e-001,1.825000e+000,,,,,,,,,,,,,,,,,,0,4.000000e+000,1.000000e+000,2,2,1.656189e-001,0,,0,
1700004817.103,,3.000000e+002,2.600953e+002,6.693969e-006,3.351856e-008,-8.901594e-004,3.749453e-004,3,9.715444e-001,1.825000e+000,,,,,,,,,,,,,,,,,,0,4.000000e+000,1.000000e+000,2,2,1.682129e-001,0,,0,
1700004970.295,,3.000000e+002,2.621295e+002,6.632004e-006,1.162292e-008,-5.417690e-004,1.051199e-003,3,9.764661e-001,1.825000e+000,,,,,,,,,,,,,,,,,,0,4.000000e+000,1.000000e+000,2,2,1.923218e-001,0,,0,
1700005122.990,,3.000000e+002,2.641381e+002,6.656679e-006,5.510808e-009,-1.250590e-004,1.533763e-003,3,9.730885e-001,1.825000e+000,,,,,,,,,,,,,,,,,,0,4.000000e+000,1.000000e+000,2,2,1.628113e-001,0,,0,
1700005275.432,,3.000000e+002,2.660954e+002,6.640294e-006,8.975563e-009,2.971339e-003,1.821325e-004,3,9.714483e-001,1.825000e+000,,,,,,,,,,,,,,,,,,0,4.000000e+000,1.000000e+000,2,2,1.652832e-001,0,,0,
1700005430.123,,3.000000e+002,2.681366e+002,6.656385e-006,1.175219e-008,-1.816546e-003,1.880854e-003,3,9.718000e-001,1.825000e+000,,,,,,,,,,,,,,,,,,0,4.000000e+000,1.000000e+000,2,2,1.791992e-001,0,,0,
1700005579.065,,3.000000e+002,2.700857e+002,6.651849e-006,5.656473e-009,-1.036141e-003,2.251749e-003,3,9.743358e-001,1.825000e+000,,,,,,,,,,,,,,,,,,0,4.000000e+000,1.000000e+000,2,2,1.705017e-001,0,,0,
1700005736.044,,3.000000e+002,2.721254e+002,6.654474e-006,1.162100e-008,2.149228e-003,8.111288e-004,3,9.719234e-001,1.825000e+000,,,,,,,,,,,,,,,,,,0,4.000000e+000,1.000000e+000,2,2,1.501160e-001,0,,0,
1700005887.486,,3.000000e+002,2.741301e+002,6.676142e-006,5.463540e-009,-1.964879e-003,2.043711e-003,3,9.702909e-001,1.825000e+000,,,,,,,,,,,,,,,,,,0,4.000000e+000,1.000000e+000,2,2,1.877136e-001,0,,0,
1700006037.225,,3.000000e+002,2.761183e+002,6.655147e-006,1.546872e-008,1.044226e-003,1.459535e-003,3,9.741286e-001,1.825000e+000,,,,,,,,,,,,,,,,,,0,4.000000e+000,1.000000e+000,2,2,1.548157e-001,0,,0,
1700006188.916,,3.000000e+002,2.781159e+002,6.659465e-006,4.386652e-009,2.639878e-003,2.576215e-003,3,9.723535e-001,1.825000e+000,,,,,,,,,,,,,,,,,,0,4.000000e+000,1.000000e+000,2,2,1.692200e-001,0,,0,
1700006344.385,,3.000000e+002,2.801561e+002,6.672556e-006,8.693881e-009,8.936384e-004,1.433767e-003,3,9.726065e-001,1.825000e+000,,,,,,,,,,,,,,,,,,0,4.000000e+000,1.000000e+000,2,2,1.594849e-001,0,,0,
1700006493.827,,3.000000e+002,2.820970e+002,6.705407e-006,4.337133e-009,-1.015569e-003,4.012166e-003,3,9.711138e-001,1.825000e+000,,,,,,,,,,,,,,,,,,0,4.000000e+000,1.000000e+000,2,2,1.618958e-001,0,,0,
1700006651.548,,3.000000e+002,2.841295e+002,6.672226e-006,4.147737e-008,1.700553e-003,3.567731e-005,3,9.725185e-001,1.825000e+000,,,,,,,,,,,,,,,,,,0,4.000000e+000,1.000000e+000,2,2,1.643066e-001,0,,0,
1700006799.017,,3.000000e+002,2.860965e+002,6.654990e-006,1.308536e-008,-1.109236e-004,8.826497e-005,3,9.688498e-001,1.825000e+000,,,,,,,,,,,,,,,,,,0,4.000000e+000,1.000000e+000,2,2,1.923828e-001,0,,0,
1700006951.460,,3.000000e+002,2.881214e+002,6.662495e-006,8.707707e-009,1.855540e-003,1.015254e-003,3,9.723875e-001,1.825000e+000,,,,,,,,,,,,,,,,,,0,4.000000e+000,1.000000e+000,2,2,1.561890e-001,0,,0,
1700007108.223,,3.000000e+002,2.901434e+002,6.638812e-006,3.838723e-009,2.335456e-003,9.119486e-004,3,9.705506e-001,1.825000e+000,,,,,,,,,,,,,,,,,,0,4.000000e+000,1.000000e+000,2,2,1.716919e-001,0,,0,
1700007257.490,,3.000000e+002,2.920914e+002,6.660113e-006,4.100597e-008,1.263546e-003,2.166828e-003,3,9.666227e-001,1.825000e+000,,,,,,,,,,,,,,,,,,0,4.000000e+000,1.000000e+000,2,2,1.740112e-001,0,,0,
1700007415.434,,3.000000e+002,2.941178e+002,6.692811e-006,2.561925e-008,5.047448e-003,8.538063e-004,3,9.716808e-001,1.825000e+000,,,,,,,,,,,,,,,,,,0,4.000000e+000,1.000000e+000,2,2,1.630249e-001,0,,0,
1700007567.885,,3.000000e+002,2.961220e+002,6.694932e-006,1.200139e-008,2.328656e-003,1.256509e-003,3,9.759575e-001,1.825000e+000,,,,,,,,,,,,,,,,,,0,4.000000e+000,1.000000e+000,2,2,1.789856e-001,0,,0,
1700007720.829,,3.000000e+002,2.981014e+002,6.709332e-006,1.187084e-008,2.098932e-003,1.158793e-003,3,9.694484e-001,1.825000e+000,,,,,,,,,,,,,,,,,,0,4.000000e+000,1.000000e+000,2,2,1.957092e-001,0,,0,
1700007871.274,,3.000000e+002,3.001182e+002,6.664600e-006,2.979721e-008,7.721746e-004,1.216478e-003,3,9.733151e-001,1.825000e+000,,,,,,,,,,,,,,,,,,0,4.000000e+000,1.000000e+000,2,2,1.701050e-001,0,,0,
1700008026.225,,3.000000e+002,3.021141e+002,6.692260e-006,1.096824e-008,3.831707e-003,4.020470e-003,3,9.746660e-001,1.825000e+000,,,,,,,,,,,,,,,,,,0,4.000000e+000,1.000000e+000,2,2,1.726074e-001,0,,0,
1700008180.241,,3.000000e+002,3.041095e+002,6.656472e-006,2.137858e-008,5.444760e-003,6.481964e-003,3,9.742063e-001,1.825000e+000,,,,,,,,,,,,,,,,,,0,4.000000e+000,1.000000e+000,2,2,1.604919e-001,0,,0,
1700008333.730,,3.000000e+002,3.061002e+002,6.706418e-006,3.275809e-008,5.304272e-003,7.713697e-005,3,9.711233e-001,1.825000e+000,,,,,,,,,,,,,,,,,,0,4.000000e+000,1.000000e+000,2,2,1.775208e-001,0,,0,
1700008487.926,,3.000000e+002,3.081190e+002,6.693523e-006,2.480861e-008,1.004254e-002,2.762574e-004,3,9.697354e-001,1.825000e+000,,,,,,,,,,,,,,,,,,0,4.000000e+000,1.000000e+000,2,2,1.649780e-001,0,,0,
1700008643.119,,3.000000e+002,3.101170e+002,6.650549e-006,1.385130e-008,1.127408e-002,2.495087e-003,3,9.724537e-001,1.825000e+000,,,,,,,,,,,,,,,,,,0,4.000000e+000,1.000000e+000,2,2,1.825256e-001,0,,0,
1700008790.312,,3.000000e+002,3.121006e+002,6.672700e-006,4.797278e-009,8.629764e-003,2.077139e-003,3,9.742948e-001,1.825000e+000,,,,,,,,,,,,,,,,,,0,4.000000e+000,1.000000e+000,2,2,1.850891e-001,0,,0,
1700008945.006,,3.000000e+002,3.141115e+002,6.660240e-006,2.007564e-008,1.165167e-002,2.744864e-003,3,9.715213e-001,1.825000e+000,,,,,,,,,,,,,,,,,,0,4.000000e+000,1.000000e+000,2,2,1.563110e-001,0,,0,
1700009100.220,,3.000000e+002,3.161305e+002,6.662291e-006,4.330702e-009,1.208046e-002,4.156468e-003,3,9.738811e-001,1.825000e+000,,,,,,,,,,,,,,,,,,0,4.000000e+000,1.000000e+000,2,2,1.742859e-001,0,,0,
1700009252.663,,3.000000e+002,3.181092e+002,6.668506e-006,2.703087e-008,1.217771e-002,1.170389e-003,3,9.712095e-001,1.825000e+000,,,,,,,,,,,,,,,,,,0,4.000000e+000,1.000000e+000,2,2,1.766968e-001,0,,0,
1700009407.930,,3.000000e+002,3.201266e+002,6.659152e-006,5.434086e-008,1.769638e-002,8.350872e-004,3,9.671937e-001,1.825000e+000,,,,,,,,,,,,,,,,,,0,4.000000e+000,1.000000e+000,2,2,1.628113e-001,0,,0,
1700009558.372,,3.000000e+002,3.221013e+002,6.659289e-006,2.052549e-008,1.601563e-002,2.013118e-004,3,9.737478e-001,1.825000e+000,,,,,,,,,,,,,,,,,,0,4.000000e+000,1.000000e+000,2,2,1.813965e-001,0,,0,
1700009714.566,,3.000000e+002,3.241064e+002,6.652693e-006,3.546623e-008,2.064211e-002,6.392889e-003,3,9.747870e-001,1.825000e+000,,,,,,,,,,,,,,,,,,0,4.000000e+000,1.000000e+000,2,2,1.670837e-001,0,,0,
1700009869.306,,3.000000e+002,3.261382e+002,6.673935e-006,3.837051e-008,2.442009e-002,3.672038e-003,3,9.737854e-001,1.825000e+000,,,,,,,,,,,,,,,,,,0,4.000000e+000,1.000000e+000,2,2,1.694031e-001,0,,0,
1700010019.049,,3.000000e+002,3.281308e+002,6.641282e-006,2.643728e-008,2.493127e-002,2.066605e-004,3,9.738809e-001,1.825000e+000,,,,,,,,,,,,,,,,,,0,4.000000e+000,1.000000e+000,2,2,1.631165e-001,0,,0,
1700010172.565,,3.000000e+002,3.301016e+002,6.652362e-006,3.774090e-008,2.769083e-002,1.037607e-003,3,9.723938e-001,1.825000e+000,,,,,,,,,,,,,,,,,,0,4.000000e+000,1.000000e+000,2,2,1.737976e-001,0,,0,
1700010337.760,,3.000000e+002,3.321462e+002,6.618313e-006,2.596170e-008,3.005522e-002,1.133539e-003,3,9.728914e-001,1.825000e+000,,,,,,,,,,,,,,,,,,0,4.000000e+000,1.000000e+000,2,2,1.849976e-001,0,,0,
1700010488.202,,3.000000e+002,3.341219e+002,6.637642e-006,2.837529e-008,2.865140e-002,5.146894e-004,3,9.729441e-001,1.825000e+000,,,,,,,,,,,,,,,,,,0,4.000000e+000,1.000000e+000,2,2,1.693115e-001,0,,0,
1700010638.896,,3.000000e+002,3.361090e+002,6.646546e-006,8.834400e-009,3.714151e-002,2.608911e-003,3,9.744055e-001,1.825000e+000,,,,,,,,,,,,,,,,,,0,4.000000e+000,1.000000e+000,2,2,1.806030e-001,0,,0,
1700010793.642,,3.000000e+002,3.381420e+002,6.681264e-006,2.188342e-008,3.675494e-002,8.130918e-004,3,9.745574e-001,1.825000e+000,,,,,,,,,,,,,,,,,,0,4.000000e+000,1.000000e+000,2,2,1.921082e-001,0,,0,
1700010942.585,,3.000000e+002,3.400946e+002,6.633142e-006,3.607139e-008,4.013583e-002,9.322988e-004,3,9.723774e-001,1.825000e+000,,,,,,,,,,,,,,,,,,0,4.000000e+000,1.000000e+000,2,2,1.665955e-001,0,,0,
1700011097.278,,3.000000e+002,3.421087e+002,6.632804e-006,4.462347e-008,3.953026e-002,2.519359e-003,3,9.733891e-001,1.825000e+000,,,,,,,,,,,,,,,,,,0,4.000000e+000,1.000000e+000,2,2,1.781006e-001,0,,0,
1700011248.237,,3.000000e+002,3.441078e+002,6.599977e-006,5.555536e-008,4.358284e-002,1.485924e-003,3,9.722866e-001,1.825000e+000,,,,,,,,,,,,,,,,,,0,4.000000e+000,1.000000e+000,2,2,1.612854e-001,0,,0,
1700011401.180,,3.000000e+002,3.461172e+002,6.622255e-006,1.267795e-008,4.678374e-002,2.252343e-003,3,9.755429e-001,1.825000e+000,,,,,,,,,,,,,,,,,,0,4.000000e+000,1.000000e+000,2,2,1.632996e-001,0,,0,
1700011552.623,,3.000000e+002,3.481030e+002,6.655053e-006,2.941038e-008,4.368762e-002,1.867411e-003,3,9.740982e-001,1.825000e+000,,,,,,,,,,,,,,,,,,0,4.000000e+000,1.000000e+000,2,2,1.846008e-001,0,,0,
1700011704.069,,3.000000e+002,3.501424e+002,6.632391e-006,1.623756e-008,4.846486e-002,1.578199e-003,3,9.728651e-001,1.825000e+000,,,,,,,,,,,,,,,,,,0,4.000000e+000,1.000000e+000,2,2,1.574097e-001,0,,0,
1700011853.264,,3.000000e+002,3.520950e+002,6.592239e-006,8.171997e-009,5.502107e-002,3.298623e-004,3,9.707266e-001,1.825000e+000,,,,,,,,,,,,,,,,,,0,4.000000e+000,1.000000e+000,2,2,1.593018e-001,0,,0,
1700012008.462,,3.000000e+002,3.541312e+002,6.606905e-006,1.161456e-009,5.592006e-002,1.208495e-003,3,9.726691e-001,1.825000e+000,,,,,,,,,,,,,,,,,,0,4.000000e+000,1.000000e+000,2,2,1.712952e-001,0,,0,
1700012160.204,,3.000000e+002,3.561081e+002,6.626292e-006,1.839133e-008,5.862743e-002,3.665893e-003,3,9.712829e-001,1.825000e+000,,,,,,,,,,,,,,,,,,0,4.000000e+000,1.000000e+000,2,2,1.733093e-001,0,,0,
1700012317.906,,3.000000e+002,3.581264e+002,6.622613e-006,2.347029e-009,5.717249e-002,2.752658e-003,3,9.734001e-001,1.825000e+000,,,,,,,,,,,,,,,,,,0,4.000000e+000,1.000000e+000,2,2,1.652222e-001,0,,0,
1700012470.602,,3.000000e+002,3.601166e+002,6.614866e-006,4.437137e-008,6.152442e-002,1.557476e-003,3,9.736812e-001,1.825000e+000,,,,,,,,,,,,,,,,,,0,4.000000e+000,1.000000e+000,2,2,1.564941e-001,0,,0,
1700012623.558,,3.000000e+002,3.621328e+002,6.587299e-006,1.499797e-008,6.533142e-002,4.771442e-003,3,9.747822e-001,1.825000e+000,,,,,,,,,,,,,,,,,,0,4.000000e+000,1.000000e+000,2,2,1.795044e-001,0,,0,
1700012772.537,,3.000000e+002,3.641061e+002,6.584053e-006,4.641710e-008,6.998871e-002,1.578795e-003,3,9.694328e-001,1.825000e+000,,,,,,,,,,,,,,,,,,0,4.000000e+000,1.000000e+000,2,2,1.708984e-001,0,,0,
1700012930.235,,3.000000e+002,3.661100e+002,6.607322e-006,6.668085e-009,6.810549e-002,8.784984e-005,3,9.723428e-001,1.825000e+000,,,,,,,,,,,,,,,,,,0,4.000000e+000,1.000000e+000,2,2,1.513062e-001,0,,0,
1700013087.723,,3.000000e+002,3.681044e+002,6.612411e-006,3.842196e-008,7.107691e-002,2.878066e-003,3,9.721737e-001,1.825000e+000,,,,,,,,,,,,,,,,,,0,4.000000e+000,1.000000e+000,2,2,1.530151e-001,0,,0,
1700013240.420,,3.000000e+002,3.701162e+002,6.600811e-006,4.668334e-008,7.346843e-002,1.168253e-003,3,9.750441e-001,1.825000e+000,,,,,,,,,,,,,,,,,,0,4.000000e+000,1.000000e+000,2,2,1.547852e-001,0,,0,
1700013394.120,,3.000000e+002,3.721204e+002,6.569676e-006,8.560435e-009,7.569265e-002,5.596153e-004,3,9.746643e-001,1.825000e+000,,,,,,,,,,,,,,,,,,0,4.000000e+000,1.000000e+000,2,2,1.676941e-001,0,,0,
1700013546.064,,3.000000e+002,3.740964e+002,6.628642e-006,2.633857e-008,8.360938e-002,4.097095e-004,3,9.726046e-001,1.825000e+000,,,,,,,,,,,,,,,,,,0,4.000000e+000,1.000000e+000,2,2,1.808167e-001,0,,0,
1700013704.043,,3.000000e+002,3.761174e+002,6.578676e-006,1.543367e-008,8.305707e-002,1.137628e-003,3,9.721140e-001,1.825000e+000,,,,,,,,,,,,,,,,,,0,4.000000e+000,1.000000e+000,2,2,1.715088e-001,0,,0,
1700013857.240,,3.000000e+002,3.781353e+002,6.601576e-006,9.933475e-009,8.952496e-002,2.432811e-003,3,9.734414e-001,1.825000e+000,,,,,,,,,,,,,,,,,,0,4.000000e+000,1.000000e+000,2,2,1.734009e-001,0,,0,
1700014004.965,,3.000000e+002,3.801173e+002,6.613605e-006,1.332524e-008,9.436876e-002,1.148823e-003,3,9.728435e-001,1.825000e+000,,,,,,,,,,,,,,,,,,0,4.000000e+000,1.000000e+000,2,2,1.869812e-001,0,,0,
1700014156.163,,3.000000e+002,3.821153e+002,6.561139e-006,3.345007e-008,9.530148e-002,4.019308e-003,3,9.688118e-001,1.825000e+000,,,,,,,,,,,,,,,,,,0,4.000000e+000,1.000000e+000,2,2,1.536865e-001,0,,0,
1700014307.611,,3.000000e+002,3.841054e+002,6.554731e-006,8.053021e-009,1.028751e-001,1.110743e-003,3,9.748656e-001,1.825000e+000,,,,,,,,,,,,,,,,,,0,4.000000e+000,1.000000e+000,2,2,1.553040e-001,0,,0,
1700014461.095,,3.000000e+002,3.861172e+002,6.602165e-006,2.979882e-008,1.048023e-001,2.098033e-003,3,9.733552e-001,1.825000e+000,,,,,,,,,,,,,,,,,,0,4.000000e+000,1.000000e+000,2,2,1.812134e-001,0,,0,
1700014611.319,,3.000000e+002,3.881114e+002,6.597457e-006,3.166512e-008,1.084590e-001,8.166374e-004,3,9.718112e-001,1.825000e+000,,,,,,,,,,,,,,,,,,0,4.000000e+000,1.000000e+000,2,2,1.831055e-001,0,,0,
1700015013.529,,3.000000e+002,3.899853e+002,6.613134e-006,1.909168e-008,1.132186e-001,1.787564e-003,3,9.716097e-001,1.825000e+000,,,,,,,,,,,,,,,,,,0,4.000000e+000,1.000000e+000,2,2,1.239014e-002,0,,0,