File: STO/STO-N11-12p5g-15a-600C-vac_MvH_T-300-K-full_220125.rso.dat
Time,Comment,Field (Oe),Temperature (K),Long Moment (emu),Long Scan Std Dev,Long Offset (cm),Long Offset Std Dev,Long Algorithm,Long Reg Fit,Long Reg Factor,Trans Moment (emu),Trans Scan Std Dev,Trans Offset (cm),Trans Offset Std Dev,Trans Algorithm,Trans Reg Fit,Trans Reg Factor,Long Moment [w/o ABS] (emu),Long Scan Std Dev [w/o ABS],Long Offset [w/o ABS] (cm),Long Offset Std Dev [w/o ABS],Long Reg Fit [w/o ABS],Trans Moment [w/o ABS] (emu),Trans Scan Std Dev [w/o ABS],Trans Offset [w/o ABS] (cm),Trans Offset Std Dev [w/o ABS],Trans Reg Fit [w/o ABS],RSO Position (deg),Amplitude (cm),Frequency,Cycles to Average,Scans per Measurement,Delta Temp (K),Error,EC Comp. Running,Using ABS,
1643112921.980,,0.000000e+000,2.999857e+002,2.131972e-006,2.593421e-008,-7.541291e-004,2.983896e-002,3,9.126197e-001,1.825000e+000,,,,,,,,,,,,,,,,,,0,4.000000e+000,1.000000e+000,2,2,0.000000e+000,0,,0,
1643112952.216,,5.031284e+001,2.999998e+002,4.322196e-006,2.019484e-007,-9.921508e-003,2.694700e-003,3,9.540588e-001,1.825000e+000,,,,,,,,,,,,,,,,,,0,4.000000e+000,1.000000e+000,2,2,0.000000e+000,0,,0,
1643112994.259,,1.005819e+002,2.999998e+002,6.544143e-006,8.516415e-008,-8.283695e-003,7.530723e-003,3,9.698852e-001,1.825000e+000,,,,,,,,,,,,,,,,,,0,4.000000e+000,1.000000e+000,2,2,0.000000e+000,0,,0,
1643113069.756,,2.011201e+002,2.999998e+002,1.075680e-005,4.532381e-008,-1.093159e-002,2.530034e-003,3,9.753923e-001,1.825000e+000,,,,,,,,,,,,,,,,,,0,4.000000e+000,1.000000e+000,2,2,0.000000e+000,0,,0,
1643113101.905,,3.014102e+002,2.999998e+002,1.552748e-005,1.088322e-007,-5.745495e-003,2.006787e-003,3,9.788544e-001,1.825000e+000,,,,,,,,,,,,,,,,,,0,4.000000e+000,1.000000e+000,2,2,0.000000e+000,0,,0,
1643113132.170,,4.019046e+002,2.999998e+002,2.021944e-005,1.198422e-007,-8.096290e-004,6.038442e-004,3,9.743545e-001,1.825000e+000,,,,,,,,,,,,,,,,,,0,4.000000e+000,1.000000e+000,2,2,0.000000e+000,0,,0,
1643113172.566,,5.023406e+002,2.999998e+002,2.457210e-005,8.813564e-008,2.620412e-003,1.520033e-003,3,9.816517e-001,1.825000e+000,,,,,,,,,,,,,,,,,,0,4.000000e+000,1.000000e+000,2,2,0.000000e+000,0,,0,
1643113204.338,,6.027621e+002,2.999963e+002,2.823161e-005,6.528851e-008,6.934252e-003,2.454038e-003,3,9.817556e-001,1.825000e+000,,,,,,,,,,,,,,,,,,0,4.000000e+000,1.000000e+000,2,2,1.409912e-002,0,,0,
1643113235.763,,7.030814e+002,2.999998e+002,3.114438e-005,1.815113e-008,7.128839e-003,8.337075e-004,3,9.782391e-001,1.825000e+000,,,,,,,,,,,,,,,,,,0,4.000000e+000,1.000000e+000,2,2,0.000000e+000,0,,0,
1643113266.393,,8.035029e+002,2.999927e+002,3.392046e-005,9.201101e-008,7.597763e-003,5.943792e-005,3,9.826739e-001,1.825000e+000,,,,,,,,,,,,,,,,,,0,4.000000e+000,1.000000e+000,2,2,1.409912e-002,0,,0,
1643113296.545,,9.039099e+002,2.999998e+002,3.602284e-005,8.434515e-008,1.222268e-002,2.532856e-003,3,9.809501e-001,1.825000e+000,,,,,,,,,,,,,,,,,,0,4.000000e+000,1.000000e+000,2,2,0.000000e+000,0,,0,
1643113331.362,,1.004390e+003,2.999927e+002,3.768382e-005,1.161817e-007,1.242748e-002,7.194131e-004,3,9.832150e-001,1.825000e+000,,,,,,,,,,,,,,,,,,0,4.000000e+000,1.000000e+000,2,2,1.409912e-002,0,,0,
1643113403.829,,1.255297e+003,2.999998e+002,4.035377e-005,8.776906e-008,1.662654e-002,9.655988e-004,3,9.771502e-001,1.825000e+000,,,,,,,,,,,,,,,,,,0,4.000000e+000,1.000000e+000,2,2,0.000000e+000,0,,0,
1643113427.831,,1.506206e+003,2.999998e+002,4.115434e-005,4.926016e-007,2.504747e-002,2.407573e-003,3,9.698847e-001,1.825000e+000,,,,,,,,,,,,,,,,,,0,4.000000e+000,1.000000e+000,2,2,0.000000e+000,0,,0,
1643113467.206,,1.757375e+003,2.999998e+002,4.106033e-005,1.271788e-007,2.325579e-002,6.043937e-004,3,9.815829e-001,1.825000e+000,,,,,,,,,,,,,,,,,,0,4.000000e+000,1.000000e+000,2,2,0.000000e+000,0,,0,
1643113500.231,,2.008429e+003,2.999998e+002,3.995539e-005,2.122005e-007,3.058133e-002,2.254548e-003,3,9.726439e-001,1.825000e+000,,,,,,,,,,,,,,,,,,0,4.000000e+000,1.000000e+000,2,2,0.000000e+000,0,,0,
1643113588.152,,3.012060e+003,2.999963e+002,2.895772e-005,6.161816e-007,6.441003e-002,9.877752e-003,3,9.553388e-001,1.825000e+000,,,,,,,,,,,,,,,,,,0,4.000000e+000,1.000000e+000,2,2,1.409912e-002,0,,0,
1643113614.087,,4.015618e+003,2.999998e+002,1.259937e-005,5.078581e-007,1.597265e-001,5.845068e-002,3,7.955714e-001,1.825000e+000,,,,,,,,,,,,,,,,,,0,4.000000e+000,1.000000e+000,2,2,0.000000e+000,0,,0,
1643113639.773,,5.019468e+003,2.999998e+002,-1.057176e-005,3.137673e-006,-5.498235e-001,2.111737e-001,3,2.562665e-001,1.825000e+000,,,,,,,,,,,,,,,,,,0,4.000000e+000,1.000000e+000,2,2,0.000000e+000,0,,0,
1643113665.774,,6.022808e+003,2.999998e+002,-3.114367e-005,1.796911e-006,-1.513425e-001,2.171648e-003,3,8.539469e-001,1.825000e+000,,,,,,,,,,,,,,,,,,0,4.000000e+000,1.000000e+000,2,2,0.000000e+000,0,,0,
1643113735.962,,7.013894e+003,2.999998e+002,-5.854888e-005,9.273644e-008,-7.131366e-002,7.954459e-003,3,9.179049e-001,1.825000e+000,,,,,,,,,,,,,,,,,,0,4.000000e+000,1.000000e+000,2,2,0.000000e+000,0,,0,
1643113761.648,,8.017378e+003,2.999998e+002,-8.361129e-005,2.475356e-007,-6.396938e-002,7.622774e-003,3,9.546161e-001,1.825000e+000,,,,,,,,,,,,,,,,,,0,4.000000e+000,1.000000e+000,2,2,0.000000e+000,0,,0,
1643113787.648,,9.021593e+003,2.999998e+002,-1.109758e-004,1.887630e-006,-5.383184e-002,4.454482e-003,3,9.654008e-001,1.825000e+000,,,,,,,,,,,,,,,,,,0,4.000000e+000,1.000000e+000,2,2,0.000000e+000,0,,0,
1643113813.156,,1.002640e+004,2.999963e+002,-1.368455e-004,1.064681e-007,-5.408799e-002,2.326669e-003,3,9.663886e-001,1.825000e+000,,,,,,,,,,,,,,,,,,0,4.000000e+000,1.000000e+000,2,2,1.409912e-002,0,,0,
1643113970.907,,1.500000e+004,2.999998e+002,-2.731500e-004,3.605531e-008,-3.492661e-002,4.767230e-004,3,9.827925e-001,1.825000e+000,,,,,,,,,,,,,,,,,,0,4.000000e+000,1.000000e+000,2,2,0.000000e+000,0,,0,
1643114110.348,,2.000000e+004,2.999998e+002,-4.116355e-004,5.580753e-007,-3.124623e-002,9.790752e-004,3,9.833738e-001,1.825000e+000,,,,,,,,,,,,,,,,,,0,4.000000e+000,1.000000e+000,2,2,0.000000e+000,0,,0,
1643114251.541,,2.500000e+004,2.999998e+002,-5.518181e-004,3.291076e-007,-2.705856e-002,2.054585e-003,3,9.854349e-001,1.825000e+000,,,,,,,,,,,,,,,,,,0,4.000000e+000,1.000000e+000,2,2,0.000000e+000,0,,0,
1643114393.733,,3.000000e+004,2.999927e+002,-6.910687e-004,7.770825e-008,-2.571133e-002,3.002502e-004,3,9.842693e-001,1.825000e+000,,,,,,,,,,,,,,,,,,0,4.000000e+000,1.000000e+000,2,2,1.409912e-002,0,,0,
1643114536.929,,3.500000e+004,2.999998e+002,-8.313479e-004,1.833923e-006,-2.432246e-002,1.300168e-003,3,9.833850e-001,1.825000e+000,,,,,,,,,,,,,,,,,,0,4.000000e+000,1.000000e+000,2,2,0.000000e+000,0,,0,
1643114680.871,,4.000000e+004,2.999998e+002,-9.707407e-004,1.496542e-007,-2.259993e-002,3.187382e-004,3,9.843115e-001,1.825000e+000,,,,,,,,,,,,,,,,,,0,4.000000e+000,1.000000e+000,2,2,0.000000e+000,0,,0,
1643114820.313,,4.500000e+004,2.999998e+002,-1.109543e-003,6.494901e-008,-2.104555e-002,1.359486e-004,3,9.839851e-001,1.825000e+000,,,,,,,,,,,,,,,,,,0,4.000000e+000,1.000000e+000,2,2,0.000000e+000,0,,0,
1643114958.819,,5.000000e+004,2.999998e+002,-1.249044e-003,3.846723e-007,-2.021511e-002,1.910503e-004,3,9.836705e-001,1.825000e+000,,,,,,,,,,,,,,,,,,0,4.000000e+000,1.000000e+000,2,2,0.000000e+000,0,,0,
1643115099.830,,5.500000e+004,2.999998e+002,-1.388377e-003,1.643892e-007,-1.958719e-002,5.833388e-006,3,9.836341e-001,1.825000e+000,,,,,,,,,,,,,,,,,,0,4.000000e+000,1.000000e+000,2,2,0.000000e+000,0,,0,
1643115242.772,,6.000000e+004,2.999998e+002,-1.527854e-003,3.712554e-008,-1.908679e-002,1.100612e-004,3,9.836096e-001,1.825000e+000,,,,,,,,,,,,,,,,,,0,4.000000e+000,1.000000e+000,2,2,0.000000e+000,0,,0,
1643115394.022,,6.500000e+004,2.999998e+002,-1.667324e-003,1.654614e-008,-1.871712e-002,5.257293e-005,3,9.837379e-001,1.825000e+000,,,,,,,,,,,,,,,,,,0,4.000000e+000,1.000000e+000,2,2,0.000000e+000,0,,0,
1643115532.478,,7.000000e+004,2.999998e+002,-1.806916e-003,1.959993e-007,-1.835337e-002,1.179282e-004,3,9.838372e-001,1.825000e+000,,,,,,,,,,,,,,,,,,0,4.000000e+000,1.000000e+000,2,2,0.000000e+000,0,,0,
1643115601.166,,6.524477e+004,3.000069e+002,-1.676205e-003,7.354296e-007,-1.939980e-002,4.444530e-004,3,9.835890e-001,1.825000e+000,,,,,,,,,,,,,,,,,,0,4.000000e+000,1.000000e+000,2,2,1.422119e-002,0,,0,
1643115670.161,,5.520846e+004,2.999998e+002,-1.393283e-003,1.778070e-007,-2.010667e-002,2.829858e-004,3,9.830290e-001,1.825000e+000,,,,,,,,,,,,,,,,,,0,4.000000e+000,1.000000e+000,2,2,0.000000e+000,0,,0,
1643115738.349,,4.517653e+004,3.000034e+002,-1.112707e-003,2.820217e-006,-2.119402e-002,2.757076e-004,3,9.822229e-001,1.825000e+000,,,,,,,,,,,,,,,,,,0,4.000000e+000,1.000000e+000,2,2,1.422119e-002,0,,0,
1643115807.315,,3.514970e+004,2.999998e+002,-8.329051e-004,5.651958e-007,-2.346599e-002,9.637232e-004,3,9.826745e-001,1.825000e+000,,,,,,,,,,,,,,,,,,0,4.000000e+000,1.000000e+000,2,2,0.000000e+000,0,,0,
1643115876.753,,2.512214e+004,2.999998e+002,-5.551831e-004,7.907473e-007,-2.592344e-002,9.456831e-004,3,9.814419e-001,1.825000e+000,,,,,,,,,,,,,,,,,,0,4.000000e+000,1.000000e+000,2,2,0.000000e+000,0,,0,
1643115944.976,,1.508276e+004,2.999963e+002,-2.677079e-004,4.630062e-006,-4.670015e-002,1.875773e-002,3,9.418445e-001,1.825000e+000,,,,,,,,,,,,,,,,,,0,4.000000e+000,1.000000e+000,2,2,1.409912e-002,0,,0,
1643116038.396,,1.003135e+004,2.999998e+002,-1.353455e-004,1.254610e-006,-4.622757e-002,3.060707e-003,3,9.754174e-001,1.825000e+000,,,,,,,,,,,,,,,,,,0,4.000000e+000,1.000000e+000,2,2,0.000000e+000,0,,0,
1643116064.167,,9.021594e+003,3.000034e+002,-1.033322e-004,6.545377e-006,-3.079234e-002,2.273414e-002,3,8.733526e-001,1.825000e+000,,,,,,,,,,,,,,,,,,0,4.000000e+000,1.000000e+000,2,2,1.422119e-002,0,,0,
1643116089.853,,8.015920e+003,2.999998e+002,-8.208011e-005,5.957770e-009,-6.075169e-002,1.519790e-002,3,9.348546e-001,1.825000e+000,,,,,,,,,,,,,,,,,,0,4.000000e+000,1.000000e+000,2,2,0.000000e+000,0,,0,
1643116115.788,,7.011559e+003,2.999998e+002,-5.660098e-005,1.419331e-006,-9.002617e-002,5.097435e-003,3,9.031653e-001,1.825000e+000,,,,,,,,,,,,,,,,,,0,4.000000e+000,1.000000e+000,2,2,0.000000e+000,0,,0,
1643116185.476,,6.022515e+003,2.999998e+002,-3.049452e-005,3.384842e-007,-1.893979e-001,4.577783e-002,3,6.731027e-001,1.825000e+000,,,,,,,,,,,,,,,,,,0,4.000000e+000,1.000000e+000,2,2,0.000000e+000,0,,0,
1643116210.912,,5.019177e+003,2.999998e+002,-9.907633e-006,2.253991e-006,-5.137566e-001,1.887441e-002,3,5.519744e-001,1.825000e+000,,,,,,,,,,,,,,,,,,0,4.000000e+000,1.000000e+000,2,2,0.000000e+000,0,,0,
1643116236.847,,4.015619e+003,2.999998e+002,1.694524e-005,3.074336e-006,1.662510e-001,2.790804e-002,3,8.211013e-001,1.825000e+000,,,,,,,,,,,,,,,,,,0,4.000000e+000,1.000000e+000,2,2,0.000000e+000,0,,0,
1643116262.283,,3.011987e+003,2.999998e+002,3.171147e-005,5.647277e-007,6.895015e-002,6.128184e-003,3,8.670220e-001,1.825000e+000,,,,,,,,,,,,,,,,,,0,4.000000e+000,1.000000e+000,2,2,0.000000e+000,0,,0,
1643116419.554,,2.000000e+003,2.999998e+002,4.325021e-005,6.196235e-008,2.789216e-002,7.636799e-004,3,9.817446e-001,1.825000e+000,,,,,,,,,,,,,,,,,,0,4.000000e+000,1.000000e+000,2,2,0.000000e+000,0,,0,
1643116540.744,,1.750000e+003,2.999963e+002,4.509770e-005,1.197393e-007,2.241538e-002,4.365808e-003,3,9.781826e-001,1.825000e+000,,,,,,,,,,,,,,,,,,0,4.000000e+000,1.000000e+000,2,2,1.409912e-002,0,,0,
1643116668.540,,1.500000e+003,2.999998e+002,4.655739e-005,8.936397e-008,1.386996e-002,8.884384e-004,3,9.841689e-001,1.825000e+000,,,,,,,,,,,,,,,,,,0,4.000000e+000,1.000000e+000,2,2,0.000000e+000,0,,0,
1643116790.231,,1.250000e+003,2.999998e+002,4.653020e-005,1.065144e-007,1.533487e-002,4.349700e-003,3,9.800305e-001,1.825000e+000,,,,,,,,,,,,,,,,,,0,4.000000e+000,1.000000e+000,2,2,0.000000e+000,0,,0,
1643116911.232,,1.000000e+003,2.999998e+002,4.543349e-005,4.178928e-008,1.089722e-002,2.903142e-003,3,9.773725e-001,1.825000e+000,,,,,,,,,,,,,,,,,,0,4.000000e+000,1.000000e+000,2,2,0.000000e+000,0,,0,
1643117033.227,,9.000000e+002,2.999998e+002,4.492749e-005,9.929101e-008,8.710368e-003,3.223316e-003,3,9.829565e-001,1.825000e+000,,,,,,,,,,,,,,,,,,0,4.000000e+000,1.000000e+000,2,2,0.000000e+000,0,,0,
1643117154.715,,8.000000e+002,2.999998e+002,4.394788e-005,1.810200e-007,8.867124e-003,1.006962e-003,3,9.831998e-001,1.825000e+000,,,,,,,,,,,,,,,,,,0,4.000000e+000,1.000000e+000,2,2,0.000000e+000,0,,0,
1643117276.406,,7.000000e+002,3.000034e+002,4.256226e-005,3.135855e-007,3.825160e-003,6.297849e-004,3,9.820858e-001,1.825000e+000,,,,,,,,,,,,,,,,,,0,4.000000e+000,1.000000e+000,2,2,1.422119e-002,0,,0,
1643117392.096,,6.000000e+002,2.999998e+002,4.126810e-005,8.411106e-008,4.707136e-003,4.792114e-003,3,9.739608e-001,1.825000e+000,,,,,,,,,,,,,,,,,,0,4.000000e+000,1.000000e+000,2,2,0.000000e+000,0,,0,
1643117508.287,,5.000000e+002,2.999998e+002,3.902754e-005,6.561521e-008,2.167035e-003,2.864263e-003,3,9.851681e-001,1.825000e+000,,,,,,,,,,,,,,,,,,0,4.000000e+000,1.000000e+000,2,2,0.000000e+000,0,,0,
1643117623.477,,4.000000e+002,2.999998e+002,5.115080e-005,2.030055e-005,2.419959e-001,3.352142e-001,3,5.929940e-001,1.825000e+000,,,,,,,,,,,,,,,,,,0,4.000000e+000,1.000000e+000,2,2,0.000000e+000,0,,0,
1643117744.418,,3.000000e+002,2.999963e+002,3.354222e-005,2.191487e-007,-4.505254e-004,1.076465e-002,3,9.733316e-001,1.825000e+000,,,,,,,,,,,,,,,,,,0,4.000000e+000,1.000000e+000,2,2,1.409912e-002,0,,0,
1643117866.359,,2.000000e+002,3.000034e+002,2.947673e-005,1.101004e-008,1.611792e-003,2.372250e-003,3,9.744281e-001,1.825000e+000,,,,,,,,,,,,,,,,,,0,4.000000e+000,1.000000e+000,2,2,1.422119e-002,0,,0,
1643117988.371,,1.000000e+002,2.999998e+002,2.410871e-005,2.186046e-007,9.798320e-003,3.477298e-003,3,9.806870e-001,1.825000e+000,,,,,,,,,,,,,,,,,,0,4.000000e+000,1.000000e+000,2,2,0.000000e+000,0,,0,
1643118097.879,,7.500000e+001,2.999998e+002,2.203074e-005,1.575246e-007,6.288013e-003,6.571321e-003,3,9.733666e-001,1.825000e+000,,,,,,,,,,,,,,,,,,0,4.000000e+000,1.000000e+000,2,2,0.000000e+000,0,,0,
1643118207.129,,5.000000e+001,2.999998e+002,2.040013e-005,1.428476e-007,4.388645e-003,4.359961e-003,3,9.740920e-001,1.825000e+000,,,,,,,,,,,,,,,,,,0,4.000000e+000,1.000000e+000,2,2,0.000000e+000,0,,0,
1643118322.370,,2.500000e+001,2.999963e+002,1.855570e-005,1.518279e-007,4.815921e-003,9.083452e-003,3,9.671929e-001,1.825000e+000,,,,,,,,,,,,,,,,,,0,4.000000e+000,1.000000e+000,2,2,1.409912e-002,0,,0,
1643118437.061,,0.000000e+000,2.999998e+002,1.639079e-005,2.643272e-007,1.350319e-002,4.360704e-004,3,9.348860e-001,1.825000e+000,,,,,,,,,,,,,,,,,,0,4.000000e+000,1.000000e+000,2,2,0.000000e+000,0,,0,
1643118546.036,,-2.500000e+001,2.999998e+002,1.454534e-005,3.376250e-007,2.380990e-002,2.378029e-003,3,9.291149e-001,1.825000e+000,,,,,,,,,,,,,,,,,,0,4.000000e+000,1.000000e+000,2,2,0.000000e+000,0,,0,
1643118655.490,,-5.000000e+001,2.999998e+002,1.219958e-005,2.407334e-007,1.203852e-002,1.403670e-003,3,9.373634e-001,1.825000e+000,,,,,,,,,,,,,,,,,,0,4.000000e+000,1.000000e+000,2,2,0.000000e+000,0,,0,
1643118770.931,,-7.500000e+001,3.000034e+002,1.021209e-005,3.280368e-007,2.121749e-002,5.532318e-003,3,9.548076e-001,1.825000e+000,,,,,,,,,,,,,,,,,,0,4.000000e+000,1.000000e+000,2,2,1.422119e-002,0,,0,
1643118880.371,,-1.000000e+002,3.000104e+002,8.613323e-006,2.060215e-007,1.364453e-002,1.474258e-002,3,9.602841e-001,1.825000e+000,,,,,,,,,,,,,,,,,,0,4.000000e+000,1.000000e+000,2,2,1.422119e-002,0,,0,
1643119002.062,,-2.000000e+002,2.999998e+002,3.605429e-007,3.119885e-008,-4.641118e-001,6.563532e-001,3,0.000000e+000,1.825000e+000,,,,,,,,,,,,,,,,,,0,4.000000e+000,1.000000e+000,2,2,0.000000e+000,0,,0,
1643119123.762,,-3.000000e+002,2.999998e+002,-6.421320e-006,1.469976e-007,-1.120540e-002,2.667676e-003,3,9.362125e-001,1.825000e+000,,,,,,,,,,,,,,,,,,0,4.000000e+000,1.000000e+000,2,2,0.000000e+000,0,,0,
1643119245.776,,-4.000000e+002,2.999998e+002,-1.298484e-005,2.322398e-008,-2.741965e-004,6.405128e-003,3,9.679829e-001,1.825000e+000,,,,,,,,,,,,,,,,,,0,4.000000e+000,1.000000e+000,2,2,0.000000e+000,0,,0,
1643119367.967,,-5.000000e+002,2.999998e+002,-1.851867e-005,1.210334e-009,-2.315134e-003,3.036055e-005,3,9.607365e-001,1.825000e+000,,,,,,,,,,,,,,,,,,0,4.000000e+000,1.000000e+000,2,2,0.000000e+000,0,,0,
1643119489.501,,-6.000000e+002,2.999998e+002,-2.361698e-005,2.349255e-007,5.000520e-003,2.765151e-003,3,9.785649e-001,1.825000e+000,,,,,,,,,,,,,,,,,,0,4.000000e+000,1.000000e+000,2,2,0.000000e+000,0,,0,
1643119611.442,,-7.000000e+002,2.999998e+002,-2.744588e-005,1.659596e-007,1.022031e-002,1.417873e-003,3,9.757732e-001,1.825000e+000,,,,,,,,,,,,,,,,,,0,4.000000e+000,1.000000e+000,2,2,0.000000e+000,0,,0,
1643119733.633,,-8.000000e+002,2.999927e+002,-3.081219e-005,6.765516e-008,1.336932e-002,1.576980e-003,3,9.692485e-001,1.825000e+000,,,,,,,,,,,,,,,,,,0,4.000000e+000,1.000000e+000,2,2,1.409912e-002,0,,0,
1643119855.326,,-9.000000e+002,2.999998e+002,-3.363176e-005,1.226230e-007,7.598536e-003,3.630299e-003,3,9.847486e-001,1.825000e+000,,,,,,,,,,,,,,,,,,0,4.000000e+000,1.000000e+000,2,2,0.000000e+000,0,,0,
1643119977.517,,-1.000000e+003,2.999998e+002,-3.585413e-005,7.893274e-008,2.186753e-002,1.783581e-003,3,9.721498e-001,1.825000e+000,,,,,,,,,,,,,,,,,,0,4.000000e+000,1.000000e+000,2,2,0.000000e+000,0,,0,
1643120105.458,,-1.250000e+003,2.999963e+002,-3.938944e-005,4.243753e-008,2.025664e-002,1.175705e-003,3,9.834019e-001,1.825000e+000,,,,,,,,,,,,,,,,,,0,4.000000e+000,1.000000e+000,2,2,1.409912e-002,0,,0,
1643120226.899,,-1.500000e+003,2.999998e+002,-4.122582e-005,1.679932e-007,2.576484e-002,1.313271e-003,3,9.798224e-001,1.825000e+000,,,,,,,,,,,,,,,,,,0,4.000000e+000,1.000000e+000,2,2,0.000000e+000,0,,0,
1643120341.840,,-1.750000e+003,2.999998e+002,-4.101817e-005,5.463862e-008,2.798627e-002,7.114045e-004,3,9.804970e-001,1.825000e+000,,,,,,,,,,,,,,,,,,0,4.000000e+000,1.000000e+000,2,2,0.000000e+000,0,,0,
1643120464.539,,-2.000000e+003,2.999998e+002,-4.014558e-005,2.766659e-008,3.475960e-002,1.450465e-003,3,9.814476e-001,1.825000e+000,,,,,,,,,,,,,,,,,,0,4.000000e+000,1.000000e+000,2,2,0.000000e+000,0,,0,
1643120539.138,,-3.012133e+003,2.999963e+002,-2.959220e-005,2.072627e-007,6.221992e-002,6.087585e-003,3,9.671742e-001,1.825000e+000,,,,,,,,,,,,,,,,,,0,4.000000e+000,1.000000e+000,2,2,1.409912e-002,0,,0,
1643120575.049,,-4.015764e+003,2.999998e+002,-1.260509e-005,2.664456e-007,1.807072e-001,9.912875e-003,3,6.789393e-001,1.825000e+000,,,,,,,,,,,,,,,,,,0,4.000000e+000,1.000000e+000,2,2,0.000000e+000,0,,0,
1643120606.714,,-5.019468e+003,2.999998e+002,8.124528e-006,4.265346e-006,-7.301676e-001,3.495231e-001,3,2.624314e-001,1.825000e+000,,,,,,,,,,,,,,,,,,0,4.000000e+000,1.000000e+000,2,2,0.000000e+000,0,,0,
1643120632.151,,-6.022808e+003,2.999998e+002,3.077018e-005,1.186643e-006,-1.075825e-001,5.454456e-003,3,8.948135e-001,1.825000e+000,,,,,,,,,,,,,,,,,,0,4.000000e+000,1.000000e+000,2,2,0.000000e+000,0,,0,
1643120701.367,,-7.014332e+003,2.999998e+002,5.721577e-005,2.078979e-006,-8.469606e-002,1.434015e-002,3,8.905712e-001,1.825000e+000,,,,,,,,,,,,,,,,,,0,4.000000e+000,1.000000e+000,2,2,0.000000e+000,0,,0,
1643120726.377,,-8.017816e+003,2.999998e+002,8.113368e-005,1.181249e-006,-5.948403e-002,8.276429e-004,3,9.613248e-001,1.825000e+000,,,,,,,,,,,,,,,,,,0,4.000000e+000,1.000000e+000,2,2,0.000000e+000,0,,0,
1643120752.069,,-9.021885e+003,2.999963e+002,1.103998e-004,1.718400e-006,-5.738325e-002,3.034389e-004,3,9.602898e-001,1.825000e+000,,,,,,,,,,,,,,,,,,0,4.000000e+000,1.000000e+000,2,2,1.409912e-002,0,,0,
1643120777.275,,-1.002669e+004,2.999998e+002,1.373453e-004,5.507387e-007,-4.355931e-002,4.430187e-004,3,9.623086e-001,1.825000e+000,,,,,,,,,,,,,,,,,,0,4.000000e+000,1.000000e+000,2,2,0.000000e+000,0,,0,
1643120934.535,,-1.500000e+004,2.999963e+002,2.718647e-004,1.673115e-007,-3.191847e-002,8.844964e-004,3,9.833180e-001,1.825000e+000,,,,,,,,,,,,,,,,,,0,4.000000e+000,1.000000e+000,2,2,1.409912e-002,0,,0,
1643121073.541,,-2.000000e+004,2.999998e+002,4.107274e-004,1.068488e-007,-2.725124e-002,3.753506e-004,3,9.846990e-001,1.825000e+000,,,,,,,,,,,,,,,,,,0,4.000000e+000,1.000000e+000,2,2,0.000000e+000,0,,0,
1643121209.291,,-2.500000e+004,2.999927e+002,5.500411e-004,2.221353e-007,-2.423450e-002,7.739071e-004,3,9.843918e-001,1.825000e+000,,,,,,,,,,,,,,,,,,0,4.000000e+000,1.000000e+000,2,2,1.409912e-002,0,,0,
1643121350.483,,-3.000000e+004,3.000034e+002,6.891940e-004,1.315854e-007,-2.258140e-002,1.674274e-003,3,9.832785e-001,1.825000e+000,,,,,,,,,,,,,,,,,,0,4.000000e+000,1.000000e+000,2,2,4.251099e-002,0,,0,
1643121486.674,,-3.500000e+004,2.999998e+002,8.294348e-004,3.232630e-007,-2.064021e-002,1.022786e-004,3,9.842101e-001,1.825000e+000,,,,,,,,,,,,,,,,,,0,4.000000e+000,1.000000e+000,2,2,0.000000e+000,0,,0,
1643121631.460,,-4.000000e+004,3.000034e+002,9.685662e-004,1.373065e-007,-1.963660e-002,5.287349e-004,3,9.840693e-001,1.825000e+000,,,,,,,,,,,,,,,,,,0,4.000000e+000,1.000000e+000,2,2,1.422119e-002,0,,0,
1643121769.674,,-4.500000e+004,2.999963e+002,1.107618e-003,2.867138e-007,-1.940923e-002,3.952084e-004,3,9.836509e-001,1.825000e+000,,,,,,,,,,,,,,,,,,0,4.000000e+000,1.000000e+000,2,2,1.409912e-002,0,,0,
1643121909.918,,-5.000000e+004,2.999998e+002,1.246915e-003,1.374736e-008,-1.890763e-002,8.847414e-005,3,9.836729e-001,1.825000e+000,,,,,,,,,,,,,,,,,,0,4.000000e+000,1.000000e+000,2,2,0.000000e+000,0,,0,
1643122057.110,,-5.500000e+004,3.000034e+002,1.386395e-003,1.404346e-007,-1.852953e-002,4.762989e-005,3,9.837242e-001,1.825000e+000,,,,,,,,,,,,,,,,,,0,4.000000e+000,1.000000e+000,2,2,1.422119e-002,0,,0,
1643122199.614,,-6.000000e+004,2.999998e+002,1.525874e-003,5.013177e-008,-1.812126e-002,4.969640e-005,3,9.837698e-001,1.825000e+000,,,,,,,,,,,,,,,,,,0,4.000000e+000,1.000000e+000,2,2,0.000000e+000,0,,0,
1643122350.058,,-6.500000e+004,2.999998e+002,1.665293e-003,8.890351e-009,-1.783085e-002,8.146459e-005,3,9.836521e-001,1.825000e+000,,,,,,,,,,,,,,,,,,0,4.000000e+000,1.000000e+000,2,2,0.000000e+000,0,,0,
1643122494.533,,-7.000000e+004,2.999998e+002,1.804633e-003,1.789595e-007,-1.749100e-002,1.079223e-005,3,9.836991e-001,1.825000e+000,,,,,,,,,,,,,,,,,,0,4.000000e+000,1.000000e+000,2,2,0.000000e+000,0,,0,
1643122643.477,,-6.500000e+004,2.999998e+002,1.664627e-003,1.267698e-007,-1.854128e-002,7.702205e-005,3,9.836429e-001,1.825000e+000,,,,,,,,,,,,,,,,,,0,4.000000e+000,1.000000e+000,2,2,0.000000e+000,0,,0,
1643122810.928,,-5.500000e+004,2.999998e+002,1.385089e-003,3.086938e-008,-2.013602e-002,2.038722e-005,3,9.835793e-001,1.825000e+000,,,,,,,,,,,,,,,,,,0,4.000000e+000,1.000000e+000,2,2,0.000000e+000,0,,0,
1643122982.872,,-4.500000e+004,2.999998e+002,1.106176e-003,2.416858e-007,-2.205505e-002,3.564254e-004,3,9.837692e-001,1.825000e+000,,,,,,,,,,,,,,,,,,0,4.000000e+000,1.000000e+000,2,2,0.000000e+000,0,,0,
1643123146.315,,-3.500000e+004,2.999998e+002,8.275937e-004,3.603885e-007,-2.416910e-002,4.662232e-004,3,9.838173e-001,1.825000e+000,,,,,,,,,,,,,,,,,,0,4.000000e+000,1.000000e+000,2,2,0.000000e+000,0,,0,
1643123308.060,,-2.500000e+004,2.999998e+002,5.485956e-004,5.786960e-008,-2.745457e-002,4.683042e-005,3,9.842784e-001,1.825000e+000,,,,,,,,,,,,,,,,,,0,4.000000e+000,1.000000e+000,2,2,0.000000e+000,0,,0,
1643123474.310,,-1.500000e+004,2.999998e+002,2.707757e-004,2.124218e-007,-3.292852e-002,2.527611e-003,3,9.816925e-001,1.825000e+000,,,,,,,,,,,,,,,,,,0,4.000000e+000,1.000000e+000,2,2,0.000000e+000,0,,0,
1643123542.998,,-1.002756e+004,3.000034e+002,1.339589e-004,8.764815e-008,-5.316843e-002,9.944694e-003,3,9.581628e-001,1.825000e+000,,,,,,,,,,,,,,,,,,0,4.000000e+000,1.000000e+000,2,2,1.422119e-002,0,,0,
1643123567.506,,-9.021593e+003,2.999998e+002,1.059376e-004,1.089186e-006,-4.920715e-002,8.548171e-004,3,9.420791e-001,1.825000e+000,,,,,,,,,,,,,,,,,,0,4.000000e+000,1.000000e+000,2,2,0.000000e+000,0,,0,
1643123592.511,,-8.016649e+003,2.999998e+002,8.058838e-005,2.706927e-006,-1.025437e-002,7.189576e-002,3,8.830201e-001,1.825000e+000,,,,,,,,,,,,,,,,,,0,4.000000e+000,1.000000e+000,2,2,0.000000e+000,0,,0,
1643123617.737,,-7.012435e+003,2.999998e+002,5.625619e-005,8.367425e-007,-9.619392e-002,2.250870e-002,3,9.022335e-001,1.825000e+000,,,,,,,,,,,,,,,,,,0,4.000000e+000,1.000000e+000,2,2,0.000000e+000,0,,0,
1643123687.476,,-6.022515e+003,2.999998e+002,3.165760e-005,1.181380e-006,-1.196310e-001,1.201227e-002,3,9.247515e-001,1.825000e+000,,,,,,,,,,,,,,,,,,0,4.000000e+000,1.000000e+000,2,2,0.000000e+000,0,,0,
1643123712.969,,-5.019177e+003,3.000034e+002,3.231798e-006,8.560693e-006,-2.269402e-001,3.209419e-001,3,2.580028e-001,1.825000e+000,,,,,,,,,,,,,,,,,,0,4.000000e+000,1.000000e+000,2,2,1.422119e-002,0,,0,
1643123738.903,,-4.015619e+003,2.999998e+002,-1.659818e-005,1.572518e-006,1.893122e-001,1.170902e-002,3,8.135858e-001,1.825000e+000,,,,,,,,,,,,,,,,,,0,4.000000e+000,1.000000e+000,2,2,0.000000e+000,0,,0,
1643123763.920,,-3.011987e+003,2.999998e+002,-3.081764e-005,2.510342e-006,5.535109e-002,4.421465e-003,3,8.569146e-001,1.825000e+000,,,,,,,,,,,,,,,,,,0,4.000000e+000,1.000000e+000,2,2,0.000000e+000,0,,0,
1643123920.080,,-2.000000e+003,2.999963e+002,-4.350453e-005,2.926356e-007,2.958549e-002,4.375014e-004,3,9.840981e-001,1.825000e+000,,,,,,,,,,,,,,,,,,0,4.000000e+000,1.000000e+000,2,2,1.409912e-002,0,,0,
1643124048.104,,-1.750000e+003,2.999998e+002,-4.515472e-005,1.663802e-007,2.608711e-002,8.161092e-004,3,9.799278e-001,1.825000e+000,,,,,,,,,,,,,,,,,,0,4.000000e+000,1.000000e+000,2,2,0.000000e+000,0,,0,
1643124169.355,,-1.500000e+003,3.000034e+002,-4.531504e-005,1.415158e-006,4.879375e-003,2.726141e-002,3,9.221594e-001,1.825000e+000,,,,,,,,,,,,,,,,,,0,4.000000e+000,1.000000e+000,2,2,1.422119e-002,0,,0,
1643124292.300,,-1.250000e+003,2.999998e+002,-4.641837e-005,1.186255e-007,1.599966e-002,2.224459e-003,3,9.817761e-001,1.825000e+000,,,,,,,,,,,,,,,,,,0,4.000000e+000,1.000000e+000,2,2,0.000000e+000,0,,0,
1643124413.518,,-1.000000e+003,2.999998e+002,-4.584208e-005,3.567202e-008,1.106086e-002,6.214177e-004,3,9.808043e-001,1.825000e+000,,,,,,,,,,,,,,,,,,0,4.000000e+000,1.000000e+000,2,2,0.000000e+000,0,,0,
1643124535.709,,-9.000000e+002,2.999998e+002,-4.506826e-005,1.074457e-007,9.317707e-003,7.832992e-004,3,9.857881e-001,1.825000e+000,,,,,,,,,,,,,,,,,,0,4.000000e+000,1.000000e+000,2,2,0.000000e+000,0,,0,
1643124656.400,,-8.000000e+002,2.999998e+002,-4.422184e-005,1.427370e-007,1.064882e-002,7.546703e-004,3,9.787216e-001,1.825000e+000,,,,,,,,,,,,,,,,,,0,4.000000e+000,1.000000e+000,2,2,0.000000e+000,0,,0,
1643124777.841,,-7.000000e+002,3.000034e+002,-4.276854e-005,1.868491e-007,9.928428e-003,5.446374e-004,3,9.798726e-001,1.825000e+000,,,,,,,,,,,,,,,,,,0,4.000000e+000,1.000000e+000,2,2,1.422119e-002,0,,0,
1643124893.531,,-6.000000e+002,2.999963e+002,-4.131193e-005,3.951807e-007,8.741425e-003,3.442097e-003,3,9.808617e-001,1.825000e+000,,,,,,,,,,,,,,,,,,0,4.000000e+000,1.000000e+000,2,2,1.409912e-002,0,,0,
1643125015.032,,-5.000000e+002,2.999963e+002,-3.947866e-005,1.309680e-007,6.579773e-003,2.736052e-003,3,9.806797e-001,1.825000e+000,,,,,,,,,,,,,,,,,,0,4.000000e+000,1.000000e+000,2,2,1.409912e-002,0,,0,
1643125129.973,,-4.000000e+002,2.999998e+002,-3.650339e-005,2.925635e-008,4.880381e-003,9.813564e-004,3,9.751399e-001,1.825000e+000,,,,,,,,,,,,,,,,,,0,4.000000e+000,1.000000e+000,2,2,0.000000e+000,0,,0,
1643125252.942,,-3.000000e+002,2.999998e+002,-3.353005e-005,4.518490e-008,6.129830e-003,5.996874e-004,3,9.819249e-001,1.825000e+000,,,,,,,,,,,,,,,,,,0,4.000000e+000,1.000000e+000,2,2,0.000000e+000,0,,0,
1643125375.217,,-2.000000e+002,2.999998e+002,-2.978285e-005,2.197879e-007,1.696593e-003,5.181610e-003,3,9.835768e-001,1.825000e+000,,,,,,,,,,,,,,,,,,0,4.000000e+000,1.000000e+000,2,2,0.000000e+000,0,,0,
1643125497.158,,-1.000000e+002,2.999998e+002,-2.389099e-005,7.530817e-008,-9.831346e-004,1.555017e-003,3,9.830145e-001,1.825000e+000,,,,,,,,,,,,,,,,,,0,4.000000e+000,1.000000e+000,2,2,0.000000e+000,0,,0,
1643125606.348,,-7.500000e+001,3.000104e+002,-2.233665e-005,9.181294e-008,6.579222e-003,6.986910e-003,3,9.786961e-001,1.825000e+000,,,,,,,,,,,,,,,,,,0,4.000000e+000,1.000000e+000,2,2,1.422119e-002,0,,0,
1643125716.112,,-5.000000e+001,2.999998e+002,-2.034121e-005,2.422916e-007,1.601067e-002,5.411671e-003,3,9.654783e-001,1.825000e+000,,,,,,,,,,,,,,,,,,0,4.000000e+000,1.000000e+000,2,2,0.000000e+000,0,,0,
1643125831.567,,-2.500000e+001,2.999998e+002,-1.828532e-005,4.051592e-009,1.422043e-002,8.218704e-003,3,9.741150e-001,1.825000e+000,,,,,,,,,,,,,,,,,,0,4.000000e+000,1.000000e+000,2,2,0.000000e+000,0,,0,
1643125946.815,,0.000000e+000,2.999998e+002,-1.652049e-005,1.939658e-007,1.741489e-002,1.319918e-003,3,9.746460e-001,1.825000e+000,,,,,,,,,,,,,,,,,,0,4.000000e+000,1.000000e+000,2,2,2.832031e-002,0,,0,
1643126054.796,,2.500000e+001,2.999963e+002,-1.462175e-005,8.685713e-008,1.309131e-002,9.419571e-003,3,9.711660e-001,1.825000e+000,,,,,,,,,,,,,,,,,,0,4.000000e+000,1.000000e+000,2,2,1.409912e-002,0,,0,
1643126169.805,,5.000000e+001,2.999892e+002,-1.247417e-005,6.085749e-008,1.882777e-002,5.354020e-004,3,9.700918e-001,1.825000e+000,,,,,,,,,,,,,,,,,,0,4.000000e+000,1.000000e+000,2,2,1.409912e-002,0,,0,
1643126285.049,,7.500000e+001,2.999998e+002,-1.028259e-005,1.607929e-007,1.905540e-002,8.987110e-003,3,9.547824e-001,1.825000e+000,,,,,,,,,,,,,,,,,,0,4.000000e+000,1.000000e+000,2,2,0.000000e+000,0,,0,
1643126394.739,,1.000000e+002,2.999998e+002,-8.514135e-006,1.870389e-007,1.929507e-002,1.234134e-002,3,9.248257e-001,1.825000e+000,,,,,,,,,,,,,,,,,,0,4.000000e+000,1.000000e+000,2,2,0.000000e+000,0,,0,
1643126516.430,,2.000000e+002,2.999998e+002,-9.704486e-007,3.825485e-007,2.281377e-001,1.624167e-001,3,4.242223e-001,1.825000e+000,,,,,,,,,,,,,,,,,,0,4.000000e+000,1.000000e+000,2,2,0.000000e+000,0,,0,
1643126637.871,,3.000000e+002,2.999998e+002,6.569918e-006,2.438975e-007,-2.272039e-002,1.162293e-002,3,8.993213e-001,1.825000e+000,,,,,,,,,,,,,,,,,,0,4.000000e+000,1.000000e+000,2,2,0.000000e+000,0,,0,
1643126758.671,,4.000000e+002,2.999998e+002,1.269825e-005,2.797013e-007,-8.704824e-003,4.304671e-003,3,9.408572e-001,1.825000e+000,,,,,,,,,,,,,,,,,,0,4.000000e+000,1.000000e+000,2,2,0.000000e+000,0,,0,
1643126880.401,,5.000000e+002,3.000069e+002,1.851796e-005,5.914488e-007,-1.060013e-003,6.262819e-003,3,9.612911e-001,1.825000e+000,,,,,,,,,,,,,,,,,,0,4.000000e+000,1.000000e+000,2,2,1.422119e-002,0,,0,
1643127003.182,,6.000000e+002,2.999998e+002,2.338159e-005,3.023774e-008,7.034647e-003,4.262202e-003,3,9.621346e-001,1.825000e+000,,,,,,,,,,,,,,,,,,0,4.000000e+000,1.000000e+000,2,2,0.000000e+000,0,,0,
1643127125.373,,7.000000e+002,3.000034e+002,2.768937e-005,1.429942e-007,1.325423e-002,6.398381e-003,3,9.788643e-001,1.825000e+000,,,,,,,,,,,,,,,,,,0,4.000000e+000,1.000000e+000,2,2,1.422119e-002,0,,0,
1643127246.814,,8.000000e+002,2.999998e+002,3.087522e-005,2.083702e-007,8.791535e-003,2.639638e-003,3,9.588882e-001,1.825000e+000,,,,,,,,,,,,,,,,,,0,4.000000e+000,1.000000e+000,2,2,0.000000e+000,0,,0,
1643127368.796,,9.000000e+002,2.999998e+002,3.312242e-005,4.094192e-007,2.468428e-002,1.017619e-002,3,9.508339e-001,1.825000e+000,,,,,,,,,,,,,,,,,,0,4.000000e+000,1.000000e+000,2,2,0.000000e+000,0,,0,
1643127490.748,,1.000000e+003,2.999998e+002,3.615564e-005,1.447769e-008,2.154898e-002,3.911646e-003,3,9.737417e-001,1.825000e+000,,,,,,,,,,,,,,,,,,0,4.000000e+000,1.000000e+000,2,2,0.000000e+000,0,,0,
1643127618.939,,1.250000e+003,2.999998e+002,3.914470e-005,4.489344e-007,1.613715e-002,7.778704e-003,3,9.733568e-001,1.825000e+000,,,,,,,,,,,,,,,,,,0,4.000000e+000,1.000000e+000,2,2,0.000000e+000,0,,0,
1643127747.881,,1.500000e+003,2.999998e+002,4.096734e-005,3.923742e-008,2.588698e-002,3.911254e-004,3,9.810512e-001,1.825000e+000,,,,,,,,,,,,,,,,,,0,4.000000e+000,1.000000e+000,2,2,0.000000e+000,0,,0,
1643127870.071,,1.750000e+003,2.999998e+002,4.109184e-005,1.162228e-008,2.844201e-002,2.002425e-003,3,9.815087e-001,1.825000e+000,,,,,,,,,,,,,,,,,,0,4.000000e+000,1.000000e+000,2,2,0.000000e+000,0,,0,
1643127992.512,,2.000000e+003,2.999998e+002,4.013482e-005,4.732260e-008,3.434816e-002,1.476778e-003,3,9.815614e-001,1.825000e+000,,,,,,,,,,,,,,,,,,0,4.000000e+000,1.000000e+000,2,2,0.000000e+000,0,,0,
1643128053.221,,3.012133e+003,2.999998e+002,2.967212e-005,3.808664e-007,6.523354e-002,9.520109e-003,3,9.288726e-001,1.825000e+000,,,,,,,,,,,,,,,,,,0,4.000000e+000,1.000000e+000,2,2,0.000000e+000,0,,0,