File: STO/STO-N10-2g-15a-500C-vac-MvH-231114.rso.csv
Field (Oe),Temperature (K),Long Moment (emu),Long Offset (cm)
0.000000e+000,2.999941e+002,1.690001e-006,-1.351782e-001
5.000000e+001,3.000012e+002,2.733106e-006,-3.095035e-002
1.000000e+002,3.000012e+002,3.543369e-006,-2.408165e-002
2.000000e+002,3.000012e+002,5.246490e-006,2.417114e-004
3.000000e+002,3.000012e+002,6.306847e-006,-2.025110e-003
4.000000e+002,3.000012e+002,6.983252e-006,6.668851e-003
5.000000e+002,2.999977e+002,7.654383e-006,-2.628663e-003
6.000000e+002,3.000012e+002,7.887626e-006,-3.027197e-003
7.000000e+002,3.000012e+002,7.820685e-006,4.262002e-003
8.000000e+002,3.000012e+002,7.624440e-006,9.169708e-003
9.000000e+002,3.000012e+002,7.265869e-006,1.703845e-002
1.000000e+003,2.999941e+002,6.680673e-006,2.888473e-002
1.250000e+003,3.000012e+002,4.204848e-006,9.066895e-002
1.500000e+003,3.000012e+002,1.495852e-006,7.344280e-001
1.750000e+003,2.999941e+002,-3.957414e-006,-3.633751e-001
2.000000e+003,2.999977e+002,-8.212699e-006,-2.186983e-001
3.000000e+003,2.999977e+002,-3.007922e-005,-1.302278e-001
4.000000e+003,3.000012e+002,-5.477098e-005,-1.023921e-001
5.000000e+003,2.999941e+002,-8.103128e-005,-9.970417e-002
6.000000e+003,3.000012e+002,-1.080195e-004,-9.169674e-002
7.000000e+003,3.000012e+002,-1.356708e-004,-9.190813e-002
8.000000e+003,3.000012e+002,-1.628532e-004,-9.069930e-002
9.000000e+003,3.000012e+002,-1.910031e-004,-8.911014e-002
1.000000e+004,3.000012e+002,-2.193707e-004,-8.819650e-002
1.500000e+004,3.000012e+002,-3.614541e-004,-8.463043e-002
2.000000e+004,3.000012e+002,-5.050221e-004,-8.244596e-002
2.500000e+004,3.000012e+002,-6.479340e-004,-8.020753e-002
3.000000e+004,3.000012e+002,-7.917833e-004,-7.989234e-002
3.500000e+004,2.999977e+002,-9.350301e-004,-7.848611e-002
4.000000e+004,3.000012e+002,-1.078331e-003,-7.721481e-002
4.500000e+004,2.999977e+002,-1.221704e-003,-7.602297e-002
5.000000e+004,2.999977e+002,-1.367142e-003,-7.478473e-002
5.500000e+004,3.000012e+002,-1.510845e-003,-7.385552e-002
6.000000e+004,2.999977e+002,-1.650370e-003,-7.301950e-002
6.500000e+004,3.000012e+002,-1.793478e-003,-7.229292e-002
7.000000e+004,2.999977e+002,-1.935811e-003,-7.171996e-002
6.500000e+004,3.000012e+002,-1.792066e-003,-7.198811e-002
5.500000e+004,2.999977e+002,-1.505348e-003,-7.266432e-002
4.500000e+004,2.999977e+002,-1.220073e-003,-7.332026e-002
3.500000e+004,3.000012e+002,-9.333252e-004,-7.440276e-002
2.500000e+004,2.999977e+002,-6.471586e-004,-7.447590e-002
1.500000e+004,2.999977e+002,-3.604464e-004,-7.645383e-002
1.000000e+004,3.000012e+002,-2.186530e-004,-7.800309e-002
9.000000e+003,3.000012e+002,-1.904076e-004,-7.925057e-002
8.000000e+003,2.999977e+002,-1.622236e-004,-7.957160e-002
7.000000e+003,3.000012e+002,-1.348632e-004,-8.216257e-002
6.000000e+003,3.000012e+002,-1.071847e-004,-8.264793e-002
5.000000e+003,2.999941e+002,-8.029293e-005,-8.516508e-002
4.000000e+003,2.999977e+002,-5.394637e-005,-9.657491e-002
3.000000e+003,2.999977e+002,-2.910081e-005,-1.139256e-001
2.000000e+003,3.000012e+002,-6.970447e-006,-2.230565e-001
1.750000e+003,2.999941e+002,-2.720501e-006,-6.557696e-001
1.500000e+003,3.000012e+002,3.186590e-006,1.837508e-001
1.250000e+003,3.000012e+002,7.031735e-006,5.080688e-002
1.000000e+003,3.000012e+002,9.993359e-006,1.898028e-002
9.000000e+002,3.000012e+002,1.091729e-005,3.893360e-003
8.000000e+002,3.000012e+002,1.170949e-005,-8.394585e-003
7.000000e+002,3.000012e+002,1.266307e-005,-7.444507e-003
6.000000e+002,3.000012e+002,1.331559e-005,-2.573796e-002
5.000000e+002,3.000012e+002,1.327036e-005,-1.891773e-002
4.000000e+002,3.000012e+002,1.350380e-005,-3.835097e-002
3.000000e+002,3.000012e+002,1.327153e-005,-4.002531e-002
2.000000e+002,3.000012e+002,1.190059e-005,-3.394178e-002
1.000000e+002,3.000012e+002,1.077654e-005,-4.689399e-002
7.500000e+001,2.999941e+002,9.994078e-006,-4.175466e-002
5.000000e+001,3.000012e+002,9.241790e-006,-4.126191e-002
2.500000e+001,3.000012e+002,8.163554e-006,-3.956054e-002
0.000000e+000,2.999977e+002,6.465770e-006,-9.957179e-002
-2.500000e+001,3.000012e+002,5.639841e-006,-9.923030e-002
-5.000000e+001,3.000012e+002,4.899283e-006,-1.340283e-001
-7.500000e+001,2.999977e+002,3.992392e-006,-1.839569e-001
-1.000000e+002,3.000012e+002,3.165178e-006,-1.879779e-001
-2.000000e+002,3.000012e+002,1.455232e-006,-8.313438e-001
-3.000000e+002,3.000012e+002,-2.213128e-006,2.313583e-001
-4.000000e+002,2.999977e+002,-3.777675e-006,2.327875e-001
-5.000000e+002,2.999941e+002,-4.694277e-006,8.346710e-002
-6.000000e+002,3.000012e+002,-5.408005e-006,3.048488e-002
-7.000000e+002,3.000012e+002,-6.040298e-006,3.611629e-002
-8.000000e+002,2.999977e+002,-5.798714e-006,3.797740e-002
-9.000000e+002,3.000012e+002,-5.356443e-006,3.278378e-002
-1.000000e+003,3.000012e+002,-5.018133e-006,9.522039e-002
-1.250000e+003,3.000012e+002,-2.964104e-006,1.863814e-001
-1.500000e+003,3.000012e+002,1.896523e-007,0.000000e+000
-1.750000e+003,3.000012e+002,5.009948e-006,-3.376541e-001
-2.000000e+003,3.000012e+002,8.955674e-006,-1.898036e-001
-3.000000e+003,3.000012e+002,3.041258e-005,-1.075189e-001
-4.000000e+003,3.000012e+002,5.494956e-005,-8.680482e-002
-5.000000e+003,2.999977e+002,8.116714e-005,-8.252623e-002
-6.000000e+003,3.000012e+002,1.081013e-004,-7.906073e-002
-7.000000e+003,2.999977e+002,1.357775e-004,-7.783324e-002
-8.000000e+003,2.999977e+002,1.630905e-004,-8.439603e-002
-9.000000e+003,3.000012e+002,1.910633e-004,-7.497977e-002
-1.000000e+004,2.999977e+002,2.188640e-004,-7.371084e-002
-2.000000e+004,3.000012e+002,5.044058e-004,-7.167438e-002
-3.000000e+004,2.999977e+002,7.908164e-004,-6.943658e-002
-4.000000e+004,2.999977e+002,1.077223e-003,-6.827132e-002
-5.000000e+004,3.000012e+002,1.362979e-003,-6.672147e-002
-6.000000e+004,2.999977e+002,1.648839e-003,-6.585359e-002
-7.000000e+004,3.000012e+002,1.934704e-003,-6.514095e-002
-6.500000e+004,2.999977e+002,1.790930e-003,-6.586996e-002
-5.500000e+004,3.000012e+002,1.504542e-003,-6.703226e-002
-4.500000e+004,2.999941e+002,1.218614e-003,-6.817394e-002
-3.500000e+004,2.999941e+002,9.327382e-004,-6.929725e-002
-2.500000e+004,3.000012e+002,6.463121e-004,-7.097235e-002
-1.500000e+004,3.000012e+002,3.603646e-004,-7.318050e-002
-1.000000e+004,3.000012e+002,2.182213e-004,-7.474755e-002
-9.000000e+003,3.000012e+002,1.900232e-004,-7.517497e-002
-8.000000e+003,2.999941e+002,1.620466e-004,-7.382374e-002
-7.000000e+003,3.000012e+002,1.348086e-004,-7.797398e-002
-6.000000e+003,3.000012e+002,1.072190e-004,-7.935128e-002
-5.000000e+003,3.000012e+002,8.011117e-005,-8.340468e-002
-4.000000e+003,2.999941e+002,5.377915e-005,-8.667426e-002
-3.000000e+003,3.000012e+002,2.931584e-005,-1.069325e-001
-2.000000e+003,3.000012e+002,7.077860e-006,-2.331170e-001
-1.750000e+003,3.000012e+002,2.757465e-006,-5.609876e-001
-1.500000e+003,3.000012e+002,-3.297765e-006,1.826664e-001
-1.250000e+003,3.000012e+002,-6.691132e-006,3.991928e-002
-1.000000e+003,3.000012e+002,-1.014076e-005,2.812190e-002
-9.000000e+002,3.000012e+002,-1.106586e-005,4.114381e-003
-8.000000e+002,3.000012e+002,-1.211191e-005,-1.107285e-002
-7.000000e+002,3.000012e+002,-1.287068e-005,-2.277989e-002
-6.000000e+002,3.000012e+002,-1.335066e-005,-1.364642e-002
-5.000000e+002,3.000012e+002,-1.335383e-005,-1.158794e-002
-4.000000e+002,3.000012e+002,-1.368312e-005,-2.214603e-002
-3.000000e+002,2.999977e+002,-1.310589e-005,-2.373853e-002
-2.000000e+002,3.000012e+002,-1.219050e-005,-2.924818e-002
-1.000000e+002,3.000012e+002,-1.031880e-005,-3.571865e-002
-7.500000e+001,2.999977e+002,-9.783624e-006,-3.349484e-002
-5.000000e+001,3.000012e+002,-9.512314e-006,-4.205145e-002
-2.500000e+001,3.000012e+002,-8.163157e-006,-5.574597e-002
0.000000e+000,3.000012e+002,-6.653416e-006,-8.713283e-002
2.500000e+001,3.000012e+002,-5.717724e-006,-1.147625e-001
5.000000e+001,3.000012e+002,-4.906135e-006,-1.160195e-001
7.500000e+001,2.999977e+002,-3.736800e-006,-1.664565e-001
1.000000e+002,3.000012e+002,-3.238537e-006,-1.913830e-001
2.000000e+002,3.000012e+002,-7.992693e-008,1.543283e-001
3.000000e+002,3.000012e+002,2.858312e-006,4.055915e-001
4.000000e+002,3.000012e+002,3.808573e-006,1.273138e-001
5.000000e+002,3.000012e+002,4.671057e-006,7.100564e-002
6.000000e+002,3.000012e+002,5.679205e-006,3.985091e-002
7.000000e+002,2.999977e+002,5.846011e-006,5.791182e-002
8.000000e+002,3.000012e+002,5.725929e-006,7.147284e-002
9.000000e+002,3.000012e+002,5.687558e-006,3.731462e-002
1.000000e+003,3.000012e+002,5.082334e-006,7.718933e-002
1.250000e+003,3.000012e+002,2.893404e-006,2.438705e-001
1.500000e+003,2.999977e+002,-1.516794e-007,0.000000e+000
1.750000e+003,2.999906e+002,-4.173109e-006,-5.607175e-001
2.000000e+003,3.000012e+002,-8.827812e-006,-1.864826e-001
3.000000e+003,3.000012e+002,-3.035681e-005,-1.050999e-001
4.000000e+003,3.000012e+002,-5.513046e-005,-8.833779e-002
5.000000e+003,3.000012e+002,-8.127410e-005,-8.478197e-002