File: STO/STO-N10-2g-15a-500C-vac_MvT_H-300_Oe-K-full_220119.rso.csv
Field (Oe),Temperature (K),Long Moment (emu),Long Offset (cm)
3.000000e+002,1.999872e+000,7.540324e-005,-9.117806e-002
3.000000e+002,3.983302e+000,4.430011e-005,-8.578530e-002
3.000000e+002,6.176014e+000,3.158849e-005,-8.154732e-002
3.000000e+002,8.262341e+000,2.493616e-005,-7.716572e-002
3.000000e+002,1.014718e+001,2.103414e-005,-7.220586e-002
3.000000e+002,1.213629e+001,1.817530e-005,-6.842145e-002
3.000000e+002,1.421016e+001,1.615789e-005,-6.382398e-002
3.000000e+002,1.618846e+001,1.485625e-005,-6.202634e-002
3.000000e+002,1.812722e+001,1.389893e-005,-6.072056e-002
3.000000e+002,2.016010e+001,1.310942e-005,-5.891886e-002
3.000000e+002,2.215065e+001,1.255398e-005,-5.321360e-002
3.000000e+002,2.416533e+001,1.204989e-005,-5.571490e-002
3.000000e+002,2.614691e+001,1.164525e-005,-5.479855e-002
3.000000e+002,2.816124e+001,1.126420e-005,-5.159126e-002
3.000000e+002,3.017739e+001,1.096854e-005,-5.112258e-002
3.000000e+002,3.213875e+001,1.070430e-005,-5.118586e-002
3.000000e+002,3.414985e+001,1.039939e-005,-4.848974e-002
3.000000e+002,3.622422e+001,1.019757e-005,-4.649621e-002
3.000000e+002,3.818670e+001,1.005578e-005,-4.526895e-002
3.000000e+002,4.014483e+001,1.007125e-005,-4.538310e-002
3.000000e+002,4.214507e+001,1.036170e-005,-5.008295e-002
3.000000e+002,4.414931e+001,1.067884e-005,-4.932710e-002
3.000000e+002,4.615688e+001,1.077994e-005,-4.821238e-002
3.000000e+002,4.812666e+001,9.961481e-006,-4.437361e-002
3.000000e+002,5.017009e+001,1.033971e-005,-4.682060e-002
3.000000e+002,5.214130e+001,1.076552e-005,-4.966153e-002
3.000000e+002,5.415266e+001,1.087226e-005,-4.431819e-002
3.000000e+002,5.615798e+001,1.094095e-005,-4.611513e-002
3.000000e+002,5.813528e+001,1.074744e-005,-4.635673e-002
3.000000e+002,6.014521e+001,1.026681e-005,-4.352362e-002
3.000000e+002,6.215710e+001,9.670291e-006,-3.989320e-002
3.000000e+002,6.415526e+001,9.072306e-006,-3.558197e-002
3.000000e+002,6.614611e+001,8.522209e-006,-3.111314e-002
3.000000e+002,6.816394e+001,8.016017e-006,-3.013000e-002
3.000000e+002,7.012918e+001,7.568349e-006,-2.588253e-002
3.000000e+002,7.214192e+001,7.252409e-006,-2.008907e-002
3.000000e+002,7.414561e+001,6.919623e-006,-2.008034e-002
3.000000e+002,7.616342e+001,6.709522e-006,-1.485823e-002
3.000000e+002,7.815691e+001,6.515702e-006,-1.509830e-002
3.000000e+002,8.016745e+001,6.393283e-006,-7.094124e-003
3.000000e+002,8.215478e+001,6.276960e-006,-7.808467e-003
3.000000e+002,8.413425e+001,6.203964e-006,-7.718533e-003
3.000000e+002,8.615720e+001,6.124172e-006,-6.365430e-003
3.000000e+002,8.813133e+001,6.067485e-006,-6.672959e-003
3.000000e+002,9.011795e+001,6.033735e-006,-5.651640e-003
3.000000e+002,9.215665e+001,6.031057e-006,-1.167917e-002
3.000000e+002,9.413073e+001,6.004312e-006,-1.000676e-002
3.000000e+002,9.616151e+001,5.992542e-006,-5.966679e-003
3.000000e+002,9.817555e+001,6.025130e-006,-7.579320e-003
3.000000e+002,1.001607e+002,5.979058e-006,-7.737212e-003
3.000000e+002,1.021580e+002,6.012788e-006,-1.024318e-002
3.000000e+002,1.041521e+002,6.014706e-006,-1.154709e-002
3.000000e+002,1.061379e+002,6.050903e-006,-1.003635e-002
3.000000e+002,1.081578e+002,6.100771e-006,-1.032867e-002
3.000000e+002,1.101705e+002,6.128117e-006,-1.412433e-002
3.000000e+002,1.121387e+002,6.124596e-006,-1.257817e-002
3.000000e+002,1.141605e+002,6.186317e-006,-1.714889e-002
3.000000e+002,1.161275e+002,6.197758e-006,-1.581551e-002
3.000000e+002,1.181481e+002,6.257608e-006,-1.773703e-002
3.000000e+002,1.201253e+002,6.281783e-006,-1.782236e-002
3.000000e+002,1.221567e+002,6.256313e-006,-1.659300e-002
3.000000e+002,1.241637e+002,6.283119e-006,-2.075922e-002
3.000000e+002,1.261296e+002,6.318489e-006,-1.972465e-002
3.000000e+002,1.282003e+002,6.315765e-006,-1.931999e-002
3.000000e+002,1.301315e+002,6.318193e-006,-2.205454e-002
3.000000e+002,1.321516e+002,6.282747e-006,-2.206721e-002
3.000000e+002,1.341436e+002,6.271738e-006,-2.344082e-002
3.000000e+002,1.361693e+002,6.278533e-006,-2.202844e-002
3.000000e+002,1.381376e+002,6.291576e-006,-2.106499e-002
3.000000e+002,1.401485e+002,6.262117e-006,-2.268433e-002
3.000000e+002,1.421624e+002,6.278195e-006,-2.337183e-002
3.000000e+002,1.441690e+002,6.252161e-006,-2.381883e-002
3.000000e+002,1.461889e+002,6.302909e-006,-2.266201e-002
3.000000e+002,1.481057e+002,6.234882e-006,-2.242664e-002
3.000000e+002,1.501490e+002,6.291491e-006,-2.573095e-002
3.000000e+002,1.521533e+002,6.288215e-006,-2.558418e-002
3.000000e+002,1.541556e+002,6.304487e-006,-2.773864e-002
3.000000e+002,1.561501e+002,6.293260e-006,-2.909675e-002
3.000000e+002,1.581476e+002,6.301556e-006,-2.906258e-002
3.000000e+002,1.601187e+002,6.274507e-006,-2.811908e-002
3.000000e+002,1.621449e+002,6.273962e-006,-3.076366e-002
3.000000e+002,1.641336e+002,6.293043e-006,-3.003818e-002
3.000000e+002,1.661470e+002,6.290104e-006,-2.914242e-002
3.000000e+002,1.681404e+002,6.293440e-006,-2.729334e-002
3.000000e+002,1.701544e+002,6.314967e-006,-3.322586e-002
3.000000e+002,1.721362e+002,6.295306e-006,-3.188968e-002
3.000000e+002,1.741385e+002,6.272089e-006,-3.226717e-002
3.000000e+002,1.761540e+002,6.326837e-006,-3.126425e-002
3.000000e+002,1.781307e+002,6.282811e-006,-3.315908e-002
3.000000e+002,1.801618e+002,6.308784e-006,-3.154879e-002
3.000000e+002,1.821792e+002,6.249333e-006,-3.130093e-002
3.000000e+002,1.841242e+002,6.306605e-006,-3.468990e-002
3.000000e+002,1.861612e+002,6.316995e-006,-3.421006e-002
3.000000e+002,1.881546e+002,6.289393e-006,-3.577451e-002
3.000000e+002,1.901331e+002,6.307801e-006,-3.651826e-002
3.000000e+002,1.921391e+002,6.272596e-006,-3.858940e-002
3.000000e+002,1.941644e+002,6.320866e-006,-3.709616e-002
3.000000e+002,1.961381e+002,6.295858e-006,-3.958905e-002
3.000000e+002,1.981571e+002,6.287918e-006,-3.769384e-002
3.000000e+002,2.001604e+002,6.304558e-006,-3.586232e-002
3.000000e+002,2.021586e+002,6.276471e-006,-4.132471e-002
3.000000e+002,2.041145e+002,6.308512e-006,-3.770635e-002
3.000000e+002,2.061654e+002,6.286894e-006,-4.096771e-002
3.000000e+002,2.081646e+002,6.335772e-006,-4.208545e-002
3.000000e+002,2.101774e+002,6.343283e-006,-4.061827e-002
3.000000e+002,2.121131e+002,6.303293e-006,-4.247293e-002
3.000000e+002,2.141733e+002,6.316556e-006,-4.323897e-002
3.000000e+002,2.161276e+002,6.321455e-006,-4.331407e-002
3.000000e+002,2.181837e+002,6.329446e-006,-4.136808e-002
3.000000e+002,2.201297e+002,6.287992e-006,-4.435937e-002
3.000000e+002,2.221483e+002,6.304656e-006,-4.714133e-002
3.000000e+002,2.241587e+002,6.327138e-006,-4.777837e-002
3.000000e+002,2.261216e+002,6.315923e-006,-4.439791e-002
3.000000e+002,2.281711e+002,6.310182e-006,-4.153953e-002
3.000000e+002,2.301750e+002,6.327138e-006,-4.726732e-002
3.000000e+002,2.321343e+002,6.311176e-006,-4.697570e-002
3.000000e+002,2.341606e+002,6.340830e-006,-4.672127e-002
3.000000e+002,2.361279e+002,6.329937e-006,-4.591556e-002
3.000000e+002,2.381532e+002,6.344861e-006,-4.652176e-002
3.000000e+002,2.401576e+002,6.331182e-006,-4.353439e-002
3.000000e+002,2.421485e+002,6.324951e-006,-4.468584e-002
3.000000e+002,2.441427e+002,6.323773e-006,-4.970332e-002
3.000000e+002,2.461609e+002,6.343403e-006,-4.814194e-002
3.000000e+002,2.481507e+002,6.313280e-006,-5.088874e-002
3.000000e+002,2.501488e+002,6.308328e-006,-4.472198e-002
3.000000e+002,2.521104e+002,6.298264e-006,-4.558153e-002
3.000000e+002,2.541433e+002,6.322178e-006,-5.208535e-002
3.000000e+002,2.561457e+002,6.301676e-006,-4.829871e-002
3.000000e+002,2.581205e+002,6.324017e-006,-5.135884e-002
3.000000e+002,2.601471e+002,6.321986e-006,-5.072882e-002
3.000000e+002,2.621419e+002,6.273378e-006,-5.078464e-002
3.000000e+002,2.641369e+002,6.290966e-006,-4.739513e-002
3.000000e+002,2.661464e+002,6.316417e-006,-4.895476e-002
3.000000e+002,2.681322e+002,6.303896e-006,-4.824775e-002
3.000000e+002,2.701636e+002,6.296183e-006,-4.563354e-002
3.000000e+002,2.721292e+002,6.271642e-006,-4.633037e-002
3.000000e+002,2.741631e+002,6.261675e-006,-4.784435e-002
3.000000e+002,2.761339e+002,6.278898e-006,-4.948595e-002
3.000000e+002,2.781587e+002,6.245580e-006,-4.807812e-002
3.000000e+002,2.801289e+002,6.287298e-006,-4.711669e-002
3.000000e+002,2.821378e+002,6.257386e-006,-4.496748e-002
3.000000e+002,2.841359e+002,6.265599e-006,-4.808990e-002
3.000000e+002,2.861317e+002,6.288711e-006,-4.943513e-002
3.000000e+002,2.881569e+002,6.283612e-006,-4.645018e-002
3.000000e+002,2.901562e+002,6.277672e-006,-4.645600e-002
3.000000e+002,2.921343e+002,6.305422e-006,-4.396024e-002
3.000000e+002,2.941476e+002,6.283888e-006,-4.646174e-002
3.000000e+002,2.961176e+002,6.270419e-006,-4.508910e-002
3.000000e+002,2.981458e+002,6.305179e-006,-4.597525e-002
3.000000e+002,3.001629e+002,6.285559e-006,-4.190998e-002
3.000000e+002,3.021413e+002,6.266015e-006,-3.972829e-002
3.000000e+002,3.041589e+002,6.280661e-006,-4.065099e-002
3.000000e+002,3.061056e+002,6.307022e-006,-3.922339e-002
3.000000e+002,3.081243e+002,6.301729e-006,-3.795111e-002
3.000000e+002,3.101756e+002,6.307539e-006,-3.562121e-002
3.000000e+002,3.121443e+002,6.307861e-006,-3.355276e-002
3.000000e+002,3.141714e+002,6.333929e-006,-3.149045e-002
3.000000e+002,3.161434e+002,6.293600e-006,-3.161395e-002
3.000000e+002,3.181541e+002,6.267821e-006,-2.584609e-002
3.000000e+002,3.201435e+002,6.322995e-006,-2.553427e-002
3.000000e+002,3.221596e+002,6.321603e-006,-2.738130e-002
3.000000e+002,3.241360e+002,6.335868e-006,-2.938287e-002
3.000000e+002,3.261765e+002,6.274471e-006,-2.186497e-002
3.000000e+002,3.281223e+002,6.327942e-006,-1.818967e-002
3.000000e+002,3.301406e+002,6.269583e-006,-1.864529e-002
3.000000e+002,3.321239e+002,6.307324e-006,-7.320226e-003
3.000000e+002,3.341482e+002,6.318387e-006,-1.596969e-002
3.000000e+002,3.361445e+002,6.301998e-006,-1.299888e-002
3.000000e+002,3.381663e+002,6.266329e-006,-6.642738e-003
3.000000e+002,3.401398e+002,6.298185e-006,-6.870182e-003
3.000000e+002,3.421825e+002,6.304706e-006,-3.726732e-003
3.000000e+002,3.441372e+002,6.325638e-006,-7.441181e-004
3.000000e+002,3.461613e+002,6.289739e-006,-2.843386e-003
3.000000e+002,3.481523e+002,6.274382e-006,3.976488e-003
3.000000e+002,3.501577e+002,6.282748e-006,1.518714e-003
3.000000e+002,3.521353e+002,6.291082e-006,5.732557e-004
3.000000e+002,3.541415e+002,6.297731e-006,6.812927e-003
3.000000e+002,3.561413e+002,6.295055e-006,-1.328201e-003
3.000000e+002,3.581418e+002,6.273656e-006,3.575761e-003
3.000000e+002,3.601659e+002,6.314319e-006,5.307821e-003
3.000000e+002,3.621720e+002,6.301801e-006,4.368085e-003
3.000000e+002,3.641241e+002,6.339248e-006,8.304316e-003
3.000000e+002,3.661498e+002,6.309873e-006,5.591430e-003
3.000000e+002,3.681499e+002,6.337553e-006,6.693526e-003
3.000000e+002,3.701289e+002,6.297953e-006,6.792688e-003
3.000000e+002,3.721386e+002,6.307315e-006,1.429010e-002
3.000000e+002,3.741627e+002,6.288089e-006,1.626215e-002
3.000000e+002,3.761557e+002,6.336894e-006,1.273314e-002
3.000000e+002,3.781507e+002,6.317372e-006,1.505275e-002
3.000000e+002,3.799867e+002,6.343087e-006,1.606336e-002