File: STO/STO-N10-2g-15a-500C-vac_MvT_H-300_Oe-K-full_220119.rso.dat
Time,Comment,Field (Oe),Temperature (K),Long Moment (emu),Long Scan Std Dev,Long Offset (cm),Long Offset Std Dev,Long Algorithm,Long Reg Fit,Long Reg Factor,Trans Moment (emu),Trans Scan Std Dev,Trans Offset (cm),Trans Offset Std Dev,Trans Algorithm,Trans Reg Fit,Trans Reg Factor,Long Moment [w/o ABS] (emu),Long Scan Std Dev [w/o ABS],Long Offset [w/o ABS] (cm),Long Offset Std Dev [w/o ABS],Long Reg Fit [w/o ABS],Trans Moment [w/o ABS] (emu),Trans Scan Std Dev [w/o ABS],Trans Offset [w/o ABS] (cm),Trans Offset Std Dev [w/o ABS],Trans Reg Fit [w/o ABS],RSO Position (deg),Amplitude (cm),Frequency,Cycles to Average,Scans per Measurement,Delta Temp (K),Error,EC Comp. Running,Using ABS,
1642647734.762,,3.000000e+002,1.999872e+000,7.540324e-005,1.446740e-008,-9.117806e-002,2.450839e-005,3,9.836578e-001,1.825000e+000,,,,,,,,,,,,,,,,,,0,4.000000e+000,1.000000e+000,2,2,2.619028e-004,0,,0,
1642647966.672,,3.000000e+002,3.983302e+000,4.430011e-005,5.924329e-009,-8.578530e-002,4.950095e-004,3,9.833259e-001,1.825000e+000,,,,,,,,,,,,,,,,,,0,4.000000e+000,1.000000e+000,2,2,4.507327e-002,0,,0,
1642648325.373,,3.000000e+002,6.176014e+000,3.158849e-005,4.118913e-007,-8.154732e-002,1.347593e-003,3,9.836360e-001,1.825000e+000,,,,,,,,,,,,,,,,,,0,4.000000e+000,1.000000e+000,2,2,2.772560e-001,0,,0,
1642648450.043,,3.000000e+002,8.262341e+000,2.493616e-005,1.862202e-007,-7.716572e-002,5.190595e-004,3,9.833096e-001,1.825000e+000,,,,,,,,,,,,,,,,,,0,4.000000e+000,1.000000e+000,2,2,2.217636e-001,0,,0,
1642648566.753,,3.000000e+002,1.014718e+001,2.103414e-005,1.399973e-007,-7.220586e-002,3.523371e-004,3,9.829932e-001,1.825000e+000,,,,,,,,,,,,,,,,,,0,4.000000e+000,1.000000e+000,2,2,1.956205e-001,0,,0,
1642648691.940,,3.000000e+002,1.213629e+001,1.817530e-005,9.965759e-008,-6.842145e-002,3.319275e-004,3,9.832543e-001,1.825000e+000,,,,,,,,,,,,,,,,,,0,4.000000e+000,1.000000e+000,2,2,2.288799e-001,0,,0,
1642648817.927,,3.000000e+002,1.421016e+001,1.615789e-005,6.465827e-008,-6.382398e-002,9.244701e-004,3,9.825389e-001,1.825000e+000,,,,,,,,,,,,,,,,,,0,4.000000e+000,1.000000e+000,2,2,2.248898e-001,0,,0,
1642648940.668,,3.000000e+002,1.618846e+001,1.485625e-005,3.335940e-008,-6.202634e-002,1.045155e-003,3,9.810969e-001,1.825000e+000,,,,,,,,,,,,,,,,,,0,4.000000e+000,1.000000e+000,2,2,2.240887e-001,0,,0,
1642649057.605,,3.000000e+002,1.812722e+001,1.389893e-005,5.263082e-008,-6.072056e-002,1.851419e-003,3,9.814078e-001,1.825000e+000,,,,,,,,,,,,,,,,,,0,4.000000e+000,1.000000e+000,2,2,2.055302e-001,0,,0,
1642649180.293,,3.000000e+002,2.016010e+001,1.310942e-005,2.904541e-008,-5.891886e-002,1.838290e-003,3,9.823698e-001,1.825000e+000,,,,,,,,,,,,,,,,,,0,4.000000e+000,1.000000e+000,2,2,2.448597e-001,0,,0,
1642649300.730,,3.000000e+002,2.215065e+001,1.255398e-005,3.969274e-008,-5.321360e-002,3.118506e-003,3,9.813877e-001,1.825000e+000,,,,,,,,,,,,,,,,,,0,4.000000e+000,1.000000e+000,2,2,2.453594e-001,0,,0,
1642649423.668,,3.000000e+002,2.416533e+001,1.204989e-005,1.223066e-008,-5.571490e-002,4.789989e-005,3,9.812630e-001,1.825000e+000,,,,,,,,,,,,,,,,,,0,4.000000e+000,1.000000e+000,2,2,2.247505e-001,0,,0,
1642649544.855,,3.000000e+002,2.614691e+001,1.164525e-005,1.175605e-009,-5.479855e-002,7.889284e-004,3,9.827666e-001,1.825000e+000,,,,,,,,,,,,,,,,,,0,4.000000e+000,1.000000e+000,2,2,2.025986e-001,0,,0,
1642649668.292,,3.000000e+002,2.816124e+001,1.126420e-005,1.867784e-008,-5.159126e-002,4.325320e-006,3,9.791960e-001,1.825000e+000,,,,,,,,,,,,,,,,,,0,4.000000e+000,1.000000e+000,2,2,2.400799e-001,0,,0,
1642649788.730,,3.000000e+002,3.017739e+001,1.096854e-005,4.983459e-009,-5.112258e-002,3.779703e-004,3,9.798360e-001,1.825000e+000,,,,,,,,,,,,,,,,,,0,4.000000e+000,1.000000e+000,2,2,2.200298e-001,0,,0,
1642649910.453,,3.000000e+002,3.213875e+001,1.070430e-005,3.867213e-008,-5.118586e-002,3.445242e-004,3,9.804505e-001,1.825000e+000,,,,,,,,,,,,,,,,,,0,4.000000e+000,1.000000e+000,2,2,1.991081e-001,0,,0,
1642650031.891,,3.000000e+002,3.414985e+001,1.039939e-005,1.946887e-008,-4.848974e-002,6.620612e-004,3,9.818867e-001,1.825000e+000,,,,,,,,,,,,,,,,,,0,4.000000e+000,1.000000e+000,2,2,2.033691e-001,0,,0,
1642650160.807,,3.000000e+002,3.622422e+001,1.019757e-005,2.631284e-008,-4.649621e-002,7.971286e-005,3,9.817294e-001,1.825000e+000,,,,,,,,,,,,,,,,,,0,4.000000e+000,1.000000e+000,2,2,3.439789e-001,0,,0,
1642650277.761,,3.000000e+002,3.818670e+001,1.005578e-005,1.374712e-008,-4.526895e-002,1.088434e-003,3,9.820068e-001,1.825000e+000,,,,,,,,,,,,,,,,,,0,4.000000e+000,1.000000e+000,2,2,2.098312e-001,0,,0,
1642650398.242,,3.000000e+002,4.014483e+001,1.007125e-005,1.340048e-008,-4.538310e-002,2.002215e-003,3,9.818271e-001,1.825000e+000,,,,,,,,,,,,,,,,,,0,4.000000e+000,1.000000e+000,2,2,2.277718e-001,0,,0,
1642650519.179,,3.000000e+002,4.214507e+001,1.036170e-005,4.641453e-008,-5.008295e-002,6.275139e-004,3,9.816881e-001,1.825000e+000,,,,,,,,,,,,,,,,,,0,4.000000e+000,1.000000e+000,2,2,2.449112e-001,0,,0,
1642650639.867,,3.000000e+002,4.414931e+001,1.067884e-005,6.987131e-008,-4.932710e-002,2.508968e-003,3,9.821376e-001,1.825000e+000,,,,,,,,,,,,,,,,,,0,4.000000e+000,1.000000e+000,2,2,2.129707e-001,0,,0,
1642650760.804,,3.000000e+002,4.615688e+001,1.077994e-005,1.991454e-008,-4.821238e-002,7.498715e-005,3,9.836004e-001,1.825000e+000,,,,,,,,,,,,,,,,,,0,4.000000e+000,1.000000e+000,2,2,2.235298e-001,0,,0,
1642650879.021,,3.000000e+002,4.812666e+001,9.961481e-006,4.738305e-008,-4.437361e-002,1.715440e-003,3,9.815652e-001,1.825000e+000,,,,,,,,,,,,,,,,,,0,4.000000e+000,1.000000e+000,2,2,2.429771e-001,0,,0,
1642651003.031,,3.000000e+002,5.017009e+001,1.033971e-005,4.408518e-009,-4.682060e-002,1.689778e-003,3,9.805104e-001,1.825000e+000,,,,,,,,,,,,,,,,,,0,4.000000e+000,1.000000e+000,2,2,2.233696e-001,0,,0,
1642651124.764,,3.000000e+002,5.214130e+001,1.076552e-005,2.823510e-008,-4.966153e-002,2.107032e-003,3,9.825921e-001,1.825000e+000,,,,,,,,,,,,,,,,,,0,4.000000e+000,1.000000e+000,2,2,2.254715e-001,0,,0,
1642651248.452,,3.000000e+002,5.415266e+001,1.087226e-005,3.101590e-008,-4.431819e-002,3.880750e-004,3,9.848553e-001,1.825000e+000,,,,,,,,,,,,,,,,,,0,4.000000e+000,1.000000e+000,2,2,2.178421e-001,0,,0,
1642651369.139,,3.000000e+002,5.615798e+001,1.094095e-005,2.714374e-008,-4.611513e-002,2.239033e-003,3,9.816561e-001,1.825000e+000,,,,,,,,,,,,,,,,,,0,4.000000e+000,1.000000e+000,2,2,2.263489e-001,0,,0,
1642651486.835,,3.000000e+002,5.813528e+001,1.074744e-005,5.135875e-009,-4.635673e-002,1.253571e-003,3,9.852637e-001,1.825000e+000,,,,,,,,,,,,,,,,,,0,4.000000e+000,1.000000e+000,2,2,2.256393e-001,0,,0,
1642651608.343,,3.000000e+002,6.014521e+001,1.026681e-005,3.638330e-008,-4.352362e-002,1.448311e-003,3,9.812473e-001,1.825000e+000,,,,,,,,,,,,,,,,,,0,4.000000e+000,1.000000e+000,2,2,2.244110e-001,0,,0,
1642651732.280,,3.000000e+002,6.215710e+001,9.670291e-006,4.102784e-008,-3.989320e-002,1.712268e-004,3,9.804202e-001,1.825000e+000,,,,,,,,,,,,,,,,,,0,4.000000e+000,1.000000e+000,2,2,2.052689e-001,0,,0,
1642651854.718,,3.000000e+002,6.415526e+001,9.072306e-006,9.713339e-008,-3.558197e-002,6.095488e-005,3,9.833607e-001,1.825000e+000,,,,,,,,,,,,,,,,,,0,4.000000e+000,1.000000e+000,2,2,2.186203e-001,0,,0,
1642651977.932,,3.000000e+002,6.614611e+001,8.522209e-006,2.413398e-008,-3.111314e-002,4.472711e-003,3,9.783584e-001,1.825000e+000,,,,,,,,,,,,,,,,,,0,4.000000e+000,1.000000e+000,2,2,2.092590e-001,0,,0,
1642652098.176,,3.000000e+002,6.816394e+001,8.016017e-006,2.025796e-009,-3.013000e-002,1.364484e-003,3,9.801922e-001,1.825000e+000,,,,,,,,,,,,,,,,,,0,4.000000e+000,1.000000e+000,2,2,1.997452e-001,0,,0,
1642652218.402,,3.000000e+002,7.012918e+001,7.568349e-006,1.136793e-008,-2.588253e-002,2.342605e-003,3,9.782625e-001,1.825000e+000,,,,,,,,,,,,,,,,,,0,4.000000e+000,1.000000e+000,2,2,1.972580e-001,0,,0,
1642652342.103,,3.000000e+002,7.214192e+001,7.252409e-006,1.367412e-008,-2.008907e-002,1.668944e-003,3,9.773936e-001,1.825000e+000,,,,,,,,,,,,,,,,,,0,4.000000e+000,1.000000e+000,2,2,2.270813e-001,0,,0,
1642652465.853,,3.000000e+002,7.414561e+001,6.919623e-006,3.281243e-008,-2.008034e-002,3.759628e-003,3,9.790478e-001,1.825000e+000,,,,,,,,,,,,,,,,,,0,4.000000e+000,1.000000e+000,2,2,2.284851e-001,0,,0,
1642652586.843,,3.000000e+002,7.616342e+001,6.709522e-006,5.416078e-008,-1.485823e-002,1.025966e-003,3,9.761380e-001,1.825000e+000,,,,,,,,,,,,,,,,,,0,4.000000e+000,1.000000e+000,2,2,2.014008e-001,0,,0,
1642652709.546,,3.000000e+002,7.815691e+001,6.515702e-006,1.775305e-008,-1.509830e-002,2.726699e-003,3,9.770490e-001,1.825000e+000,,,,,,,,,,,,,,,,,,0,4.000000e+000,1.000000e+000,2,2,2.054138e-001,0,,0,
1642652832.499,,3.000000e+002,8.016745e+001,6.393283e-006,3.204295e-008,-7.094124e-003,1.569171e-003,3,9.759655e-001,1.825000e+000,,,,,,,,,,,,,,,,,,0,4.000000e+000,1.000000e+000,2,2,2.066269e-001,0,,0,
1642652954.714,,3.000000e+002,8.215478e+001,6.276960e-006,1.175766e-008,-7.808467e-003,8.179742e-004,3,9.718473e-001,1.825000e+000,,,,,,,,,,,,,,,,,,0,4.000000e+000,1.000000e+000,2,2,2.500992e-001,0,,0,
1642653076.171,,3.000000e+002,8.413425e+001,6.203964e-006,6.115010e-009,-7.718533e-003,3.399424e-003,3,9.763024e-001,1.825000e+000,,,,,,,,,,,,,,,,,,0,4.000000e+000,1.000000e+000,2,2,2.250443e-001,0,,0,
1642653198.908,,3.000000e+002,8.615720e+001,6.124172e-006,2.501537e-008,-6.365430e-003,5.157951e-004,3,9.754651e-001,1.825000e+000,,,,,,,,,,,,,,,,,,0,4.000000e+000,1.000000e+000,2,2,2.160950e-001,0,,0,
1642653320.664,,3.000000e+002,8.813133e+001,6.067485e-006,2.173229e-008,-6.672959e-003,3.764777e-003,3,9.734079e-001,1.825000e+000,,,,,,,,,,,,,,,,,,0,4.000000e+000,1.000000e+000,2,2,2.277222e-001,0,,0,
1642653443.351,,3.000000e+002,9.011795e+001,6.033735e-006,3.285327e-009,-5.651640e-003,4.145897e-003,3,9.710375e-001,1.825000e+000,,,,,,,,,,,,,,,,,,0,4.000000e+000,1.000000e+000,2,2,1.906586e-001,0,,0,
1642653567.086,,3.000000e+002,9.215665e+001,6.031057e-006,1.736943e-008,-1.167917e-002,9.439136e-004,3,9.742793e-001,1.825000e+000,,,,,,,,,,,,,,,,,,0,4.000000e+000,1.000000e+000,2,2,1.952896e-001,0,,0,
1642653685.812,,3.000000e+002,9.413073e+001,6.004312e-006,3.688139e-008,-1.000676e-002,1.079747e-003,3,9.769262e-001,1.825000e+000,,,,,,,,,,,,,,,,,,0,4.000000e+000,1.000000e+000,2,2,2.402420e-001,0,,0,
1642653811.499,,3.000000e+002,9.616151e+001,5.992542e-006,1.928879e-008,-5.966679e-003,2.912626e-003,3,9.755831e-001,1.825000e+000,,,,,,,,,,,,,,,,,,0,4.000000e+000,1.000000e+000,2,2,2.138443e-001,0,,0,
1642653935.937,,3.000000e+002,9.817555e+001,6.025130e-006,3.990657e-008,-7.579320e-003,2.264511e-003,3,9.724683e-001,1.825000e+000,,,,,,,,,,,,,,,,,,0,4.000000e+000,1.000000e+000,2,2,2.050858e-001,0,,0,
1642654056.124,,3.000000e+002,1.001607e+002,5.979058e-006,3.310086e-009,-7.737212e-003,5.179774e-003,3,9.731386e-001,1.825000e+000,,,,,,,,,,,,,,,,,,0,4.000000e+000,1.000000e+000,2,2,2.264023e-001,0,,0,
1642654177.061,,3.000000e+002,1.021580e+002,6.012788e-006,2.636911e-008,-1.024318e-002,3.073098e-005,3,9.745950e-001,1.825000e+000,,,,,,,,,,,,,,,,,,0,4.000000e+000,1.000000e+000,2,2,2.166061e-001,0,,0,
1642654300.499,,3.000000e+002,1.041521e+002,6.014706e-006,5.051917e-008,-1.154709e-002,3.170101e-003,3,9.743496e-001,1.825000e+000,,,,,,,,,,,,,,,,,,0,4.000000e+000,1.000000e+000,2,2,2.054977e-001,0,,0,
1642654420.759,,3.000000e+002,1.061379e+002,6.050903e-006,2.751031e-008,-1.003635e-002,2.996142e-003,3,9.767048e-001,1.825000e+000,,,,,,,,,,,,,,,,,,0,4.000000e+000,1.000000e+000,2,2,2.279968e-001,0,,0,
1642654541.990,,3.000000e+002,1.081578e+002,6.100771e-006,3.582283e-008,-1.032867e-002,2.105830e-003,3,9.750215e-001,1.825000e+000,,,,,,,,,,,,,,,,,,0,4.000000e+000,1.000000e+000,2,2,2.639999e-001,0,,0,
1642654664.177,,3.000000e+002,1.101705e+002,6.128117e-006,2.611251e-008,-1.412433e-002,4.190247e-003,3,9.710256e-001,1.825000e+000,,,,,,,,,,,,,,,,,,0,4.000000e+000,1.000000e+000,2,2,1.984024e-001,0,,0,
1642654781.864,,3.000000e+002,1.121387e+002,6.124596e-006,4.190729e-008,-1.257817e-002,2.219092e-003,3,9.762146e-001,1.825000e+000,,,,,,,,,,,,,,,,,,0,4.000000e+000,1.000000e+000,2,2,2.263031e-001,0,,0,
1642654902.865,,3.000000e+002,1.141605e+002,6.186317e-006,3.344171e-008,-1.714889e-002,6.399722e-004,3,9.758528e-001,1.825000e+000,,,,,,,,,,,,,,,,,,0,4.000000e+000,1.000000e+000,2,2,2.335968e-001,0,,0,
1642655020.855,,3.000000e+002,1.161275e+002,6.197758e-006,3.072779e-009,-1.581551e-002,8.623239e-004,3,9.757841e-001,1.825000e+000,,,,,,,,,,,,,,,,,,0,4.000000e+000,1.000000e+000,2,2,1.863022e-001,0,,0,
1642655144.043,,3.000000e+002,1.181481e+002,6.257608e-006,5.605667e-009,-1.773703e-002,7.115644e-003,3,9.730866e-001,1.825000e+000,,,,,,,,,,,,,,,,,,0,4.000000e+000,1.000000e+000,2,2,2.062988e-001,0,,0,
1642655262.491,,3.000000e+002,1.201253e+002,6.281783e-006,3.080657e-008,-1.782236e-002,4.120762e-003,3,9.759473e-001,1.825000e+000,,,,,,,,,,,,,,,,,,0,4.000000e+000,1.000000e+000,2,2,2.029037e-001,0,,0,
1642655384.428,,3.000000e+002,1.221567e+002,6.256313e-006,2.012323e-008,-1.659300e-002,1.061749e-003,3,9.758567e-001,1.825000e+000,,,,,,,,,,,,,,,,,,0,4.000000e+000,1.000000e+000,2,2,2.041016e-001,0,,0,
1642655504.184,,3.000000e+002,1.241637e+002,6.283119e-006,3.129308e-008,-2.075922e-002,7.090796e-003,3,9.736469e-001,1.825000e+000,,,,,,,,,,,,,,,,,,0,4.000000e+000,1.000000e+000,2,2,2.460938e-001,0,,0,
1642655623.621,,3.000000e+002,1.261296e+002,6.318489e-006,1.103930e-008,-1.972465e-002,1.026904e-003,3,9.777286e-001,1.825000e+000,,,,,,,,,,,,,,,,,,0,4.000000e+000,1.000000e+000,2,2,2.108994e-001,0,,0,
1642655747.559,,3.000000e+002,1.282003e+002,6.315765e-006,1.473493e-008,-1.931999e-002,1.204041e-003,3,9.752650e-001,1.825000e+000,,,,,,,,,,,,,,,,,,0,4.000000e+000,1.000000e+000,2,2,2.335968e-001,0,,0,
1642655864.565,,3.000000e+002,1.301315e+002,6.318193e-006,3.548455e-008,-2.205454e-002,4.551765e-003,3,9.780515e-001,1.825000e+000,,,,,,,,,,,,,,,,,,0,4.000000e+000,1.000000e+000,2,2,2.120972e-001,0,,0,
1642655987.002,,3.000000e+002,1.321516e+002,6.282747e-006,2.437837e-008,-2.206721e-002,8.524319e-004,3,9.742510e-001,1.825000e+000,,,,,,,,,,,,,,,,,,0,4.000000e+000,1.000000e+000,2,2,2.180023e-001,0,,0,
1642656107.759,,3.000000e+002,1.341436e+002,6.271738e-006,2.706753e-008,-2.344082e-002,3.838880e-004,3,9.743544e-001,1.825000e+000,,,,,,,,,,,,,,,,,,0,4.000000e+000,1.000000e+000,2,2,1.885986e-001,0,,0,
1642656228.719,,3.000000e+002,1.361693e+002,6.278533e-006,3.807178e-008,-2.202844e-002,4.240118e-003,3,9.745444e-001,1.825000e+000,,,,,,,,,,,,,,,,,,0,4.000000e+000,1.000000e+000,2,2,1.938019e-001,0,,0,
1642656346.959,,3.000000e+002,1.381376e+002,6.291576e-006,8.322678e-008,-2.106499e-002,1.172914e-003,3,9.707302e-001,1.825000e+000,,,,,,,,,,,,,,,,,,0,4.000000e+000,1.000000e+000,2,2,1.927948e-001,0,,0,
1642656468.922,,3.000000e+002,1.401485e+002,6.262117e-006,4.684734e-008,-2.268433e-002,4.152208e-003,3,9.786561e-001,1.825000e+000,,,,,,,,,,,,,,,,,,0,4.000000e+000,1.000000e+000,2,2,2.489014e-001,0,,0,
1642656589.359,,3.000000e+002,1.421624e+002,6.278195e-006,5.837701e-008,-2.337183e-002,3.160910e-003,3,9.715593e-001,1.825000e+000,,,,,,,,,,,,,,,,,,0,4.000000e+000,1.000000e+000,2,2,2.095947e-001,0,,0,
1642656711.089,,3.000000e+002,1.441690e+002,6.252161e-006,1.107757e-008,-2.381883e-002,3.585512e-005,3,9.793822e-001,1.825000e+000,,,,,,,,,,,,,,,,,,0,4.000000e+000,1.000000e+000,2,2,2.151031e-001,0,,0,
1642656831.526,,3.000000e+002,1.461889e+002,6.302909e-006,9.933475e-009,-2.266201e-002,5.884090e-003,3,9.743198e-001,1.825000e+000,,,,,,,,,,,,,,,,,,0,4.000000e+000,1.000000e+000,2,2,2.209015e-001,0,,0,
1642656950.464,,3.000000e+002,1.481057e+002,6.234882e-006,3.215871e-009,-2.242664e-002,9.664101e-004,3,9.750935e-001,1.825000e+000,,,,,,,,,,,,,,,,,,0,4.000000e+000,1.000000e+000,2,2,2.194061e-001,0,,0,
1642657075.447,,3.000000e+002,1.501490e+002,6.291491e-006,1.912995e-008,-2.573095e-002,3.893580e-003,3,9.732795e-001,1.825000e+000,,,,,,,,,,,,,,,,,,0,4.000000e+000,1.000000e+000,2,2,2.105865e-001,0,,0,
1642657200.634,,3.000000e+002,1.521533e+002,6.288215e-006,1.059009e-008,-2.558418e-002,1.118357e-003,3,9.744121e-001,1.825000e+000,,,,,,,,,,,,,,,,,,0,4.000000e+000,1.000000e+000,2,2,1.863098e-001,0,,0,
1642657324.589,,3.000000e+002,1.541556e+002,6.304487e-006,3.775055e-008,-2.773864e-002,4.850344e-003,3,9.798058e-001,1.825000e+000,,,,,,,,,,,,,,,,,,0,4.000000e+000,1.000000e+000,2,2,2.214966e-001,0,,0,
1642657446.809,,3.000000e+002,1.561501e+002,6.293260e-006,3.187799e-008,-2.909675e-002,3.062858e-003,3,9.751005e-001,1.825000e+000,,,,,,,,,,,,,,,,,,0,4.000000e+000,1.000000e+000,2,2,2.112885e-001,0,,0,
1642657567.497,,3.000000e+002,1.581476e+002,6.301556e-006,6.696253e-008,-2.906258e-002,2.992540e-003,3,9.746507e-001,1.825000e+000,,,,,,,,,,,,,,,,,,0,4.000000e+000,1.000000e+000,2,2,2.052002e-001,0,,0,
1642657686.479,,3.000000e+002,1.601187e+002,6.274507e-006,1.241781e-008,-2.811908e-002,1.613750e-003,3,9.747605e-001,1.825000e+000,,,,,,,,,,,,,,,,,,0,4.000000e+000,1.000000e+000,2,2,2.214966e-001,0,,0,
1642657808.167,,3.000000e+002,1.621449e+002,6.273962e-006,2.639934e-008,-3.076366e-002,6.912926e-004,3,9.742635e-001,1.825000e+000,,,,,,,,,,,,,,,,,,0,4.000000e+000,1.000000e+000,2,2,1.973877e-001,0,,0,
1642657930.166,,3.000000e+002,1.641336e+002,6.293043e-006,4.783612e-008,-3.003818e-002,2.762444e-003,3,9.750233e-001,1.825000e+000,,,,,,,,,,,,,,,,,,0,4.000000e+000,1.000000e+000,2,2,2.149048e-001,0,,0,
1642658052.103,,3.000000e+002,1.661470e+002,6.290104e-006,3.095738e-008,-2.914242e-002,1.475819e-003,3,9.726992e-001,1.825000e+000,,,,,,,,,,,,,,,,,,0,4.000000e+000,1.000000e+000,2,2,2.066040e-001,0,,0,
1642658173.541,,3.000000e+002,1.681404e+002,6.293440e-006,3.043196e-009,-2.729334e-002,3.681784e-003,3,9.743373e-001,1.825000e+000,,,,,,,,,,,,,,,,,,0,4.000000e+000,1.000000e+000,2,2,2.292023e-001,0,,0,
1642658296.004,,3.000000e+002,1.701544e+002,6.314967e-006,8.104149e-009,-3.322586e-002,7.803147e-004,3,9.764420e-001,1.825000e+000,,,,,,,,,,,,,,,,,,0,4.000000e+000,1.000000e+000,2,2,2.389069e-001,0,,0,
1642658415.691,,3.000000e+002,1.721362e+002,6.295306e-006,1.375934e-009,-3.188968e-002,1.591190e-003,3,9.737516e-001,1.825000e+000,,,,,,,,,,,,,,,,,,0,4.000000e+000,1.000000e+000,2,2,2.487946e-001,0,,0,
1642658538.714,,3.000000e+002,1.741385e+002,6.272089e-006,4.882201e-008,-3.226717e-002,2.593375e-004,3,9.734846e-001,1.825000e+000,,,,,,,,,,,,,,,,,,0,4.000000e+000,1.000000e+000,2,2,2.302094e-001,0,,0,
1642658661.966,,3.000000e+002,1.761540e+002,6.326837e-006,2.030137e-008,-3.126425e-002,2.528629e-003,3,9.743773e-001,1.825000e+000,,,,,,,,,,,,,,,,,,0,4.000000e+000,1.000000e+000,2,2,2.351990e-001,0,,0,
1642658782.686,,3.000000e+002,1.781307e+002,6.282811e-006,3.884126e-008,-3.315908e-002,2.736634e-003,3,9.722699e-001,1.825000e+000,,,,,,,,,,,,,,,,,,0,4.000000e+000,1.000000e+000,2,2,2.451019e-001,0,,0,
1642658907.126,,3.000000e+002,1.801618e+002,6.308784e-006,2.289568e-008,-3.154879e-002,2.017041e-003,3,9.748305e-001,1.825000e+000,,,,,,,,,,,,,,,,,,0,4.000000e+000,1.000000e+000,2,2,2.351074e-001,0,,0,
1642659029.065,,3.000000e+002,1.821792e+002,6.249333e-006,1.026436e-008,-3.130093e-002,6.623483e-004,3,9.699602e-001,1.825000e+000,,,,,,,,,,,,,,,,,,0,4.000000e+000,1.000000e+000,2,2,2.452087e-001,0,,0,
1642659146.004,,3.000000e+002,1.841242e+002,6.306605e-006,1.933864e-008,-3.468990e-002,4.579729e-004,3,9.721077e-001,1.825000e+000,,,,,,,,,,,,,,,,,,0,4.000000e+000,1.000000e+000,2,2,2.449036e-001,0,,0,
1642659269.943,,3.000000e+002,1.861612e+002,6.316995e-006,1.398089e-008,-3.421006e-002,3.690420e-003,3,9.762627e-001,1.825000e+000,,,,,,,,,,,,,,,,,,0,4.000000e+000,1.000000e+000,2,2,2.176056e-001,0,,0,
1642659392.410,,3.000000e+002,1.881546e+002,6.289393e-006,1.190188e-011,-3.577451e-002,7.996296e-003,3,9.720675e-001,1.825000e+000,,,,,,,,,,,,,,,,,,0,4.000000e+000,1.000000e+000,2,2,2.055054e-001,0,,0,
1642659514.599,,3.000000e+002,1.901331e+002,6.307801e-006,3.044482e-009,-3.651826e-002,4.850098e-003,3,9.736452e-001,1.825000e+000,,,,,,,,,,,,,,,,,,0,4.000000e+000,1.000000e+000,2,2,2.040100e-001,0,,0,
1642659635.853,,3.000000e+002,1.921391e+002,6.272596e-006,5.825611e-009,-3.858940e-002,8.697424e-004,3,9.762250e-001,1.825000e+000,,,,,,,,,,,,,,,,,,0,4.000000e+000,1.000000e+000,2,2,2.313080e-001,0,,0,
1642659758.351,,3.000000e+002,1.941644e+002,6.320866e-006,8.399658e-009,-3.709616e-002,5.103715e-003,3,9.749558e-001,1.825000e+000,,,,,,,,,,,,,,,,,,0,4.000000e+000,1.000000e+000,2,2,2.241974e-001,0,,0,
1642659877.040,,3.000000e+002,1.961381e+002,6.295858e-006,1.753343e-008,-3.958905e-002,3.113259e-003,3,9.739840e-001,1.825000e+000,,,,,,,,,,,,,,,,,,0,4.000000e+000,1.000000e+000,2,2,2.226105e-001,0,,0,
1642659999.730,,3.000000e+002,1.981571e+002,6.287918e-006,4.115260e-009,-3.769384e-002,5.905248e-004,3,9.780842e-001,1.825000e+000,,,,,,,,,,,,,,,,,,0,4.000000e+000,1.000000e+000,2,2,2.209015e-001,0,,0,
1642660122.669,,3.000000e+002,2.001604e+002,6.304558e-006,2.906664e-008,-3.586232e-002,2.389012e-003,3,9.746191e-001,1.825000e+000,,,,,,,,,,,,,,,,,,0,4.000000e+000,1.000000e+000,2,2,2.001953e-001,0,,0,
1642660243.859,,3.000000e+002,2.021586e+002,6.276471e-006,3.923485e-008,-4.132471e-002,8.258122e-004,3,9.764616e-001,1.825000e+000,,,,,,,,,,,,,,,,,,0,4.000000e+000,1.000000e+000,2,2,2.232056e-001,0,,0,
1642660360.802,,3.000000e+002,2.041145e+002,6.308512e-006,3.136029e-008,-3.770635e-002,4.495917e-003,3,9.724439e-001,1.825000e+000,,,,,,,,,,,,,,,,,,0,4.000000e+000,1.000000e+000,2,2,1.820068e-001,0,,0,
1642660484.514,,3.000000e+002,2.061654e+002,6.286894e-006,4.120694e-008,-4.096771e-002,3.593114e-003,3,9.744824e-001,1.825000e+000,,,,,,,,,,,,,,,,,,0,4.000000e+000,1.000000e+000,2,2,2.186890e-001,0,,0,
1642660606.704,,3.000000e+002,2.081646e+002,6.335772e-006,8.406411e-009,-4.208545e-002,9.780874e-003,3,9.729056e-001,1.825000e+000,,,,,,,,,,,,,,,,,,0,4.000000e+000,1.000000e+000,2,2,2.227936e-001,0,,0,
1642660726.758,,3.000000e+002,2.101774e+002,6.343283e-006,2.109240e-008,-4.061827e-002,4.463024e-003,3,9.749544e-001,1.825000e+000,,,,,,,,,,,,,,,,,,0,4.000000e+000,1.000000e+000,2,2,1.994934e-001,0,,0,
1642660843.947,,3.000000e+002,2.121131e+002,6.303293e-006,1.982354e-008,-4.247293e-002,3.251682e-004,3,9.759469e-001,1.825000e+000,,,,,,,,,,,,,,,,,,0,4.000000e+000,1.000000e+000,2,2,2.173004e-001,0,,0,
1642660968.452,,3.000000e+002,2.141733e+002,6.316556e-006,3.285263e-008,-4.323897e-002,4.793377e-003,3,9.755803e-001,1.825000e+000,,,,,,,,,,,,,,,,,,0,4.000000e+000,1.000000e+000,2,2,2.214050e-001,0,,0,
1642661088.391,,3.000000e+002,2.161276e+002,6.321455e-006,2.160431e-008,-4.331407e-002,3.564701e-004,3,9.738069e-001,1.825000e+000,,,,,,,,,,,,,,,,,,0,4.000000e+000,1.000000e+000,2,2,2.180939e-001,0,,0,
1642661211.581,,3.000000e+002,2.181837e+002,6.329446e-006,6.730466e-009,-4.136808e-002,1.795616e-003,3,9.754922e-001,1.825000e+000,,,,,,,,,,,,,,,,,,0,4.000000e+000,1.000000e+000,2,2,2.295990e-001,0,,0,
1642661328.803,,3.000000e+002,2.201297e+002,6.287992e-006,2.714792e-008,-4.435937e-002,2.995166e-004,3,9.721060e-001,1.825000e+000,,,,,,,,,,,,,,,,,,0,4.000000e+000,1.000000e+000,2,2,2.185059e-001,0,,0,
1642661450.493,,3.000000e+002,2.221483e+002,6.304656e-006,2.101683e-008,-4.714133e-002,6.005478e-003,3,9.776860e-001,1.825000e+000,,,,,,,,,,,,,,,,,,0,4.000000e+000,1.000000e+000,2,2,2.301025e-001,0,,0,
1642661571.682,,3.000000e+002,2.241587e+002,6.327138e-006,5.199544e-010,-4.777837e-002,4.201675e-003,3,9.737884e-001,1.825000e+000,,,,,,,,,,,,,,,,,,0,4.000000e+000,1.000000e+000,2,2,2.029877e-001,0,,0,
1642661690.191,,3.000000e+002,2.261216e+002,6.315923e-006,6.845583e-009,-4.439791e-002,7.104562e-004,3,9.747120e-001,1.825000e+000,,,,,,,,,,,,,,,,,,0,4.000000e+000,1.000000e+000,2,2,2.303009e-001,0,,0,
1642661812.881,,3.000000e+002,2.281711e+002,6.310182e-006,5.796349e-009,-4.153953e-002,1.589342e-003,3,9.763193e-001,1.825000e+000,,,,,,,,,,,,,,,,,,0,4.000000e+000,1.000000e+000,2,2,2.263947e-001,0,,0,
1642661934.132,,3.000000e+002,2.301750e+002,6.327138e-006,1.403909e-009,-4.726732e-002,1.227032e-003,3,9.739736e-001,1.825000e+000,,,,,,,,,,,,,,,,,,0,4.000000e+000,1.000000e+000,2,2,2.220917e-001,0,,0,
1642662052.926,,3.000000e+002,2.321343e+002,6.311176e-006,2.886149e-008,-4.697570e-002,3.178281e-003,3,9.768134e-001,1.825000e+000,,,,,,,,,,,,,,,,,,0,4.000000e+000,1.000000e+000,2,2,2.173920e-001,0,,0,
1642662176.645,,3.000000e+002,2.341606e+002,6.340830e-006,2.908754e-008,-4.672127e-002,3.749842e-003,3,9.769959e-001,1.825000e+000,,,,,,,,,,,,,,,,,,0,4.000000e+000,1.000000e+000,2,2,2.298126e-001,0,,0,
1642662296.103,,3.000000e+002,2.361279e+002,6.329937e-006,2.730902e-008,-4.591556e-002,1.036157e-003,3,9.747068e-001,1.825000e+000,,,,,,,,,,,,,,,,,,0,4.000000e+000,1.000000e+000,2,2,2.249908e-001,0,,0,
1642662417.357,,3.000000e+002,2.381532e+002,6.344861e-006,3.794670e-009,-4.652176e-002,1.709192e-003,3,9.734961e-001,1.825000e+000,,,,,,,,,,,,,,,,,,0,4.000000e+000,1.000000e+000,2,2,2.113953e-001,0,,0,
1642662537.296,,3.000000e+002,2.401576e+002,6.331182e-006,2.503144e-008,-4.353439e-002,1.310361e-003,3,9.759241e-001,1.825000e+000,,,,,,,,,,,,,,,,,,0,4.000000e+000,1.000000e+000,2,2,2.060089e-001,0,,0,
1642662657.486,,3.000000e+002,2.421485e+002,6.324951e-006,1.464297e-008,-4.468584e-002,3.701178e-004,3,9.737425e-001,1.825000e+000,,,,,,,,,,,,,,,,,,0,4.000000e+000,1.000000e+000,2,2,2.093964e-001,0,,0,
1642662779.675,,3.000000e+002,2.441427e+002,6.323773e-006,1.528447e-008,-4.970332e-002,3.483908e-003,3,9.702863e-001,1.825000e+000,,,,,,,,,,,,,,,,,,0,4.000000e+000,1.000000e+000,2,2,1.851044e-001,0,,0,
1642662900.614,,3.000000e+002,2.461609e+002,6.343403e-006,4.315492e-008,-4.814194e-002,5.264668e-005,3,9.768240e-001,1.825000e+000,,,,,,,,,,,,,,,,,,0,4.000000e+000,1.000000e+000,2,2,1.977081e-001,0,,0,
1642663021.083,,3.000000e+002,2.481507e+002,6.313280e-006,1.027882e-008,-5.088874e-002,4.108006e-003,3,9.708668e-001,1.825000e+000,,,,,,,,,,,,,,,,,,0,4.000000e+000,1.000000e+000,2,2,2.294922e-001,0,,0,
1642663141.272,,3.000000e+002,2.501488e+002,6.308328e-006,6.313827e-008,-4.472198e-002,4.897411e-004,3,9.724164e-001,1.825000e+000,,,,,,,,,,,,,,,,,,0,4.000000e+000,1.000000e+000,2,2,2.041016e-001,0,,0,
1642663258.961,,3.000000e+002,2.521104e+002,6.298264e-006,4.401283e-008,-4.558153e-002,9.064549e-004,3,9.762272e-001,1.825000e+000,,,,,,,,,,,,,,,,,,0,4.000000e+000,1.000000e+000,2,2,1.776886e-001,0,,0,
1642663382.749,,3.000000e+002,2.541433e+002,6.322178e-006,1.596456e-008,-5.208535e-002,3.821088e-003,3,9.732263e-001,1.825000e+000,,,,,,,,,,,,,,,,,,0,4.000000e+000,1.000000e+000,2,2,2.208099e-001,0,,0,
1642663507.190,,3.000000e+002,2.561457e+002,6.301676e-006,3.443467e-008,-4.829871e-002,4.525439e-004,3,9.745730e-001,1.825000e+000,,,,,,,,,,,,,,,,,,0,4.000000e+000,1.000000e+000,2,2,2.139893e-001,0,,0,
1642663628.630,,3.000000e+002,2.581205e+002,6.324017e-006,1.290239e-008,-5.135884e-002,1.291203e-003,3,9.726436e-001,1.825000e+000,,,,,,,,,,,,,,,,,,0,4.000000e+000,1.000000e+000,2,2,2.276917e-001,0,,0,
1642663751.139,,3.000000e+002,2.601471e+002,6.321986e-006,9.635715e-009,-5.072882e-002,1.545625e-003,3,9.735829e-001,1.825000e+000,,,,,,,,,,,,,,,,,,0,4.000000e+000,1.000000e+000,2,2,2.524109e-001,0,,0,
1642663871.663,,3.000000e+002,2.621419e+002,6.273378e-006,1.990168e-008,-5.078464e-002,4.870374e-003,3,9.757141e-001,1.825000e+000,,,,,,,,,,,,,,,,,,0,4.000000e+000,1.000000e+000,2,2,2.135010e-001,0,,0,
1642663994.352,,3.000000e+002,2.641369e+002,6.290966e-006,2.971296e-008,-4.739513e-002,3.667355e-004,3,9.714737e-001,1.825000e+000,,,,,,,,,,,,,,,,,,0,4.000000e+000,1.000000e+000,2,2,2.602844e-001,0,,0,
1642664115.612,,3.000000e+002,2.661464e+002,6.316417e-006,9.944729e-009,-4.895476e-002,1.052644e-004,3,9.732271e-001,1.825000e+000,,,,,,,,,,,,,,,,,,0,4.000000e+000,1.000000e+000,2,2,2.205200e-001,0,,0,
1642664236.587,,3.000000e+002,2.681322e+002,6.303896e-006,2.790422e-008,-4.824775e-002,3.180954e-004,3,9.782114e-001,1.825000e+000,,,,,,,,,,,,,,,,,,0,4.000000e+000,1.000000e+000,2,2,2.239075e-001,0,,0,
1642664360.820,,3.000000e+002,2.701636e+002,6.296183e-006,2.599193e-008,-4.563354e-002,2.003717e-003,3,9.753516e-001,1.825000e+000,,,,,,,,,,,,,,,,,,0,4.000000e+000,1.000000e+000,2,2,2.048035e-001,0,,0,
1642664480.071,,3.000000e+002,2.721292e+002,6.271642e-006,1.785273e-008,-4.633037e-002,5.999040e-003,3,9.744863e-001,1.825000e+000,,,,,,,,,,,,,,,,,,0,4.000000e+000,1.000000e+000,2,2,2.308960e-001,0,,0,
1642664601.346,,3.000000e+002,2.741631e+002,6.261675e-006,2.929430e-008,-4.784435e-002,2.199270e-003,3,9.722921e-001,1.825000e+000,,,,,,,,,,,,,,,,,,0,4.000000e+000,1.000000e+000,2,2,1.994019e-001,0,,0,
1642664720.068,,3.000000e+002,2.761339e+002,6.278898e-006,2.337383e-008,-4.948595e-002,1.344424e-003,3,9.752805e-001,1.825000e+000,,,,,,,,,,,,,,,,,,0,4.000000e+000,1.000000e+000,2,2,2.380981e-001,0,,0,
1642664842.257,,3.000000e+002,2.781587e+002,6.245580e-006,2.067566e-008,-4.807812e-002,3.051887e-003,3,9.718313e-001,1.825000e+000,,,,,,,,,,,,,,,,,,0,4.000000e+000,1.000000e+000,2,2,2.056274e-001,0,,0,
1642664959.486,,3.000000e+002,2.801289e+002,6.287298e-006,1.149623e-008,-4.711669e-002,1.092736e-004,3,9.756923e-001,1.825000e+000,,,,,,,,,,,,,,,,,,0,4.000000e+000,1.000000e+000,2,2,2.209167e-001,0,,0,
1642665081.729,,3.000000e+002,2.821378e+002,6.257386e-006,7.326629e-009,-4.496748e-002,1.184556e-003,3,9.755604e-001,1.825000e+000,,,,,,,,,,,,,,,,,,0,4.000000e+000,1.000000e+000,2,2,1.993103e-001,0,,0,
1642665203.693,,3.000000e+002,2.841359e+002,6.265599e-006,1.701990e-009,-4.808990e-002,4.112360e-003,3,9.725280e-001,1.825000e+000,,,,,,,,,,,,,,,,,,0,4.000000e+000,1.000000e+000,2,2,2.147827e-001,0,,0,
1642665327.398,,3.000000e+002,2.861317e+002,6.288711e-006,1.761349e-008,-4.943513e-002,9.258872e-005,3,9.762652e-001,1.825000e+000,,,,,,,,,,,,,,,,,,0,4.000000e+000,1.000000e+000,2,2,2.052002e-001,0,,0,
1642665450.843,,3.000000e+002,2.881569e+002,6.283612e-006,4.406267e-009,-4.645018e-002,2.740148e-003,3,9.760919e-001,1.825000e+000,,,,,,,,,,,,,,,,,,0,4.000000e+000,1.000000e+000,2,2,1.952209e-001,0,,0,
1642665573.091,,3.000000e+002,2.901562e+002,6.277672e-006,2.133131e-008,-4.645600e-002,4.327338e-003,3,9.745666e-001,1.825000e+000,,,,,,,,,,,,,,,,,,0,4.000000e+000,1.000000e+000,2,2,1.981201e-001,0,,0,
1642665692.338,,3.000000e+002,2.921343e+002,6.305422e-006,2.469831e-008,-4.396024e-002,5.381670e-003,3,9.738016e-001,1.825000e+000,,,,,,,,,,,,,,,,,,0,4.000000e+000,1.000000e+000,2,2,2.276917e-001,0,,0,
1642665817.529,,3.000000e+002,2.941476e+002,6.283888e-006,7.151060e-009,-4.646174e-002,2.482686e-003,3,9.735748e-001,1.825000e+000,,,,,,,,,,,,,,,,,,0,4.000000e+000,1.000000e+000,2,2,2.037964e-001,0,,0,
1642665937.502,,3.000000e+002,2.961176e+002,6.270419e-006,3.279410e-008,-4.508910e-002,4.143014e-003,3,9.685993e-001,1.825000e+000,,,,,,,,,,,,,,,,,,0,4.000000e+000,1.000000e+000,2,2,2.066040e-001,0,,0,
1642666060.200,,3.000000e+002,2.981458e+002,6.305179e-006,3.971654e-008,-4.597525e-002,5.552152e-003,3,9.723283e-001,1.825000e+000,,,,,,,,,,,,,,,,,,0,4.000000e+000,1.000000e+000,2,2,2.096863e-001,0,,0,
1642666179.640,,3.000000e+002,3.001629e+002,6.285559e-006,2.626782e-008,-4.190998e-002,5.844382e-003,3,9.720500e-001,1.825000e+000,,,,,,,,,,,,,,,,,,0,4.000000e+000,1.000000e+000,2,2,2.268982e-001,0,,0,
1642666298.582,,3.000000e+002,3.021413e+002,6.266015e-006,1.945407e-009,-3.972829e-002,5.150845e-003,3,9.689859e-001,1.825000e+000,,,,,,,,,,,,,,,,,,0,4.000000e+000,1.000000e+000,2,2,2.014160e-001,0,,0,
1642666419.337,,3.000000e+002,3.041589e+002,6.280661e-006,4.856701e-008,-4.065099e-002,1.190538e-003,3,9.713757e-001,1.825000e+000,,,,,,,,,,,,,,,,,,0,4.000000e+000,1.000000e+000,2,2,2.480774e-001,0,,0,
1642666539.532,,3.000000e+002,3.061056e+002,6.307022e-006,2.337962e-008,-3.922339e-002,1.398314e-003,3,9.721565e-001,1.825000e+000,,,,,,,,,,,,,,,,,,0,4.000000e+000,1.000000e+000,2,2,1.922913e-001,0,,0,
1642666664.278,,3.000000e+002,3.081243e+002,6.301729e-006,6.621459e-009,-3.795111e-002,8.103628e-003,3,9.709619e-001,1.825000e+000,,,,,,,,,,,,,,,,,,0,4.000000e+000,1.000000e+000,2,2,2.250061e-001,0,,0,
1642666789.262,,3.000000e+002,3.101756e+002,6.307539e-006,8.052925e-008,-3.562121e-002,2.911873e-003,3,9.655359e-001,1.825000e+000,,,,,,,,,,,,,,,,,,0,4.000000e+000,1.000000e+000,2,2,1.978149e-001,0,,0,
1642666911.954,,3.000000e+002,3.121443e+002,6.307861e-006,2.337707e-010,-3.355276e-002,8.351977e-004,3,9.744444e-001,1.825000e+000,,,,,,,,,,,,,,,,,,0,4.000000e+000,1.000000e+000,2,2,2.160034e-001,0,,0,
1642667036.395,,3.000000e+002,3.141714e+002,6.333929e-006,1.257312e-008,-3.149045e-002,6.510722e-003,3,9.693440e-001,1.825000e+000,,,,,,,,,,,,,,,,,,0,4.000000e+000,1.000000e+000,2,2,2.347107e-001,0,,0,
1642667157.087,,3.000000e+002,3.161434e+002,6.293600e-006,8.660439e-009,-3.161395e-002,2.197468e-003,3,9.736356e-001,1.825000e+000,,,,,,,,,,,,,,,,,,0,4.000000e+000,1.000000e+000,2,2,2.061768e-001,0,,0,
1642667280.559,,3.000000e+002,3.181541e+002,6.267821e-006,1.830066e-008,-2.584609e-002,1.507553e-004,3,9.707109e-001,1.825000e+000,,,,,,,,,,,,,,,,,,0,4.000000e+000,1.000000e+000,2,2,2.088013e-001,0,,0,
1642667399.109,,3.000000e+002,3.201435e+002,6.322995e-006,1.547676e-008,-2.553427e-002,2.217293e-003,3,9.713253e-001,1.825000e+000,,,,,,,,,,,,,,,,,,0,4.000000e+000,1.000000e+000,2,2,2.117004e-001,0,,0,
1642667522.808,,3.000000e+002,3.221596e+002,6.321603e-006,3.352532e-009,-2.738130e-002,1.298237e-003,3,9.675918e-001,1.825000e+000,,,,,,,,,,,,,,,,,,0,4.000000e+000,1.000000e+000,2,2,2.145081e-001,0,,0,
1642667643.525,,3.000000e+002,3.241360e+002,6.335868e-006,2.228569e-008,-2.938287e-002,3.089211e-003,3,9.697216e-001,1.825000e+000,,,,,,,,,,,,,,,,,,0,4.000000e+000,1.000000e+000,2,2,2.173157e-001,0,,0,
1642667767.717,,3.000000e+002,3.261765e+002,6.274471e-006,3.244682e-008,-2.186497e-002,2.028818e-003,3,9.745821e-001,1.825000e+000,,,,,,,,,,,,,,,,,,0,4.000000e+000,1.000000e+000,2,2,2.203064e-001,0,,0,
1642667884.457,,3.000000e+002,3.281223e+002,6.327942e-006,3.088632e-008,-1.818967e-002,4.549081e-004,3,9.664821e-001,1.825000e+000,,,,,,,,,,,,,,,,,,0,4.000000e+000,1.000000e+000,2,2,1.802063e-001,0,,0,
1642668007.220,,3.000000e+002,3.301406e+002,6.269583e-006,3.880525e-008,-1.864529e-002,1.912790e-003,3,9.669076e-001,1.825000e+000,,,,,,,,,,,,,,,,,,0,4.000000e+000,1.000000e+000,2,2,2.260132e-001,0,,0,
1642668128.450,,3.000000e+002,3.321239e+002,6.307324e-006,7.964917e-010,-7.320226e-003,3.494372e-004,3,9.688400e-001,1.825000e+000,,,,,,,,,,,,,,,,,,0,4.000000e+000,1.000000e+000,2,2,2.200012e-001,0,,0,
1642668250.641,,3.000000e+002,3.341482e+002,6.318387e-006,5.895581e-008,-1.596969e-002,9.827795e-003,3,9.682750e-001,1.825000e+000,,,,,,,,,,,,,,,,,,0,4.000000e+000,1.000000e+000,2,2,2.049866e-001,0,,0,
1642668370.333,,3.000000e+002,3.361445e+002,6.301998e-006,4.192787e-008,-1.299888e-002,9.487848e-005,3,9.755207e-001,1.825000e+000,,,,,,,,,,,,,,,,,,0,4.000000e+000,1.000000e+000,2,2,1.807251e-001,0,,0,
1642668492.274,,3.000000e+002,3.381663e+002,6.266329e-006,2.219790e-008,-6.642738e-003,1.389732e-003,3,9.719245e-001,1.825000e+000,,,,,,,,,,,,,,,,,,0,4.000000e+000,1.000000e+000,2,2,2.012024e-001,0,,0,
1642668612.247,,3.000000e+002,3.401398e+002,6.298185e-006,7.869414e-009,-6.870182e-003,7.880816e-004,3,9.710982e-001,1.825000e+000,,,,,,,,,,,,,,,,,,0,4.000000e+000,1.000000e+000,2,2,2.222290e-001,0,,0,
1642668737.189,,3.000000e+002,3.421825e+002,6.304706e-006,5.000243e-008,-3.726732e-003,1.013497e-003,3,9.716048e-001,1.825000e+000,,,,,,,,,,,,,,,,,,0,4.000000e+000,1.000000e+000,2,2,2.344055e-001,0,,0,
1642668855.380,,3.000000e+002,3.441372e+002,6.325638e-006,4.235425e-008,-7.441181e-004,5.398120e-003,3,9.737813e-001,1.825000e+000,,,,,,,,,,,,,,,,,,0,4.000000e+000,1.000000e+000,2,2,2.277222e-001,0,,0,
1642668976.127,,3.000000e+002,3.461613e+002,6.289739e-006,4.838566e-008,-2.843386e-003,1.582669e-003,3,9.677114e-001,1.825000e+000,,,,,,,,,,,,,,,,,,0,4.000000e+000,1.000000e+000,2,2,2.305908e-001,0,,0,
1642669096.600,,3.000000e+002,3.481523e+002,6.274382e-006,1.492272e-008,3.976488e-003,1.568318e-003,3,9.696143e-001,1.825000e+000,,,,,,,,,,,,,,,,,,0,4.000000e+000,1.000000e+000,2,2,2.333984e-001,0,,0,
1642669218.857,,3.000000e+002,3.501577e+002,6.282748e-006,1.132291e-008,1.518714e-003,5.860539e-003,3,9.702544e-001,1.825000e+000,,,,,,,,,,,,,,,,,,0,4.000000e+000,1.000000e+000,2,2,2.164917e-001,0,,0,
1642669339.618,,3.000000e+002,3.521353e+002,6.291082e-006,1.655911e-008,5.732557e-004,5.146289e-003,3,9.703577e-001,1.825000e+000,,,,,,,,,,,,,,,,,,0,4.000000e+000,1.000000e+000,2,2,2.290039e-001,0,,0,
1642669460.882,,3.000000e+002,3.541415e+002,6.297731e-006,3.108118e-008,6.812927e-003,2.716516e-003,3,9.702754e-001,1.825000e+000,,,,,,,,,,,,,,,,,,0,4.000000e+000,1.000000e+000,2,2,2.015076e-001,0,,0,
1642669581.576,,3.000000e+002,3.561413e+002,6.295055e-006,3.359927e-008,-1.328201e-003,3.498518e-007,3,9.703906e-001,1.825000e+000,,,,,,,,,,,,,,,,,,0,4.000000e+000,1.000000e+000,2,2,1.936951e-001,0,,0,
1642669702.088,,3.000000e+002,3.581418e+002,6.273656e-006,2.819072e-009,3.575761e-003,7.913854e-003,3,9.709023e-001,1.825000e+000,,,,,,,,,,,,,,,,,,0,4.000000e+000,1.000000e+000,2,2,2.269897e-001,0,,0,
1642669824.532,,3.000000e+002,3.601659e+002,6.314319e-006,7.646931e-008,5.307821e-003,5.722554e-004,3,9.689627e-001,1.825000e+000,,,,,,,,,,,,,,,,,,0,4.000000e+000,1.000000e+000,2,2,2.192993e-001,0,,0,
1642669950.243,,3.000000e+002,3.621720e+002,6.301801e-006,1.574301e-008,4.368085e-003,6.886765e-003,3,9.703214e-001,1.825000e+000,,,,,,,,,,,,,,,,,,0,4.000000e+000,1.000000e+000,2,2,2.007141e-001,0,,0,
1642670068.461,,3.000000e+002,3.641241e+002,6.339248e-006,7.768767e-009,8.304316e-003,1.461887e-003,3,9.736509e-001,1.825000e+000,,,,,,,,,,,,,,,,,,0,4.000000e+000,1.000000e+000,2,2,1.922913e-001,0,,0,
1642670194.155,,3.000000e+002,3.661498e+002,6.309873e-006,3.013259e-008,5.591430e-003,1.298499e-003,3,9.741281e-001,1.825000e+000,,,,,,,,,,,,,,,,,,0,4.000000e+000,1.000000e+000,2,2,2.162170e-001,0,,0,
1642670315.849,,3.000000e+002,3.681499e+002,6.337553e-006,6.617922e-009,6.693526e-003,1.688175e-003,3,9.754641e-001,1.825000e+000,,,,,,,,,,,,,,,,,,0,4.000000e+000,1.000000e+000,2,2,2.077026e-001,0,,0,
1642670435.953,,3.000000e+002,3.701289e+002,6.297953e-006,2.917789e-009,6.792688e-003,7.270167e-005,3,9.717405e-001,1.825000e+000,,,,,,,,,,,,,,,,,,0,4.000000e+000,1.000000e+000,2,2,2.210999e-001,0,,0,
1642670555.896,,3.000000e+002,3.721386e+002,6.307315e-006,4.228512e-008,1.429010e-002,2.531054e-003,3,9.712956e-001,1.825000e+000,,,,,,,,,,,,,,,,,,0,4.000000e+000,1.000000e+000,2,2,2.348022e-001,0,,0,
1642670676.363,,3.000000e+002,3.741627e+002,6.288089e-006,9.059168e-009,1.626215e-002,2.169246e-005,3,9.739039e-001,1.825000e+000,,,,,,,,,,,,,,,,,,0,4.000000e+000,1.000000e+000,2,2,1.922913e-001,0,,0,
1642670797.335,,3.000000e+002,3.761557e+002,6.336894e-006,2.463722e-008,1.273314e-002,3.092708e-003,3,9.752570e-001,1.825000e+000,,,,,,,,,,,,,,,,,,0,4.000000e+000,1.000000e+000,2,2,2.058105e-001,0,,0,
1642670919.278,,3.000000e+002,3.781507e+002,6.317372e-006,3.381150e-008,1.505275e-002,8.566492e-004,3,9.702882e-001,1.825000e+000,,,,,,,,,,,,,,,,,,0,4.000000e+000,1.000000e+000,2,2,2.543945e-001,0,,0,
1642671286.986,,3.000000e+002,3.799867e+002,6.343087e-006,1.869199e-008,1.606336e-002,1.782514e-003,3,9.733200e-001,1.825000e+000,,,,,,,,,,,,,,,,,,0,4.000000e+000,1.000000e+000,2,2,0.000000e+000,0,,0,