File: STO/STO-N10-2g-15a-500C-vac-MvH-231114.rso.dat
Time,Comment,Field (Oe),Temperature (K),Long Moment (emu),Long Scan Std Dev,Long Offset (cm),Long Offset Std Dev,Long Algorithm,Long Reg Fit,Long Reg Factor,Trans Moment (emu),Trans Scan Std Dev,Trans Offset (cm),Trans Offset Std Dev,Trans Algorithm,Trans Reg Fit,Trans Reg Factor,Long Moment [w/o ABS] (emu),Long Scan Std Dev [w/o ABS],Long Offset [w/o ABS] (cm),Long Offset Std Dev [w/o ABS],Long Reg Fit [w/o ABS],Trans Moment [w/o ABS] (emu),Trans Scan Std Dev [w/o ABS],Trans Offset [w/o ABS] (cm),Trans Offset Std Dev [w/o ABS],Trans Reg Fit [w/o ABS],RSO Position (deg),Amplitude (cm),Frequency,Cycles to Average,Scans per Measurement,Delta Temp (K),Error,EC Comp. Running,Using ABS,
1699957939.048,,0.000000e+000,2.999941e+002,1.690001e-006,1.461676e-008,-1.351782e-001,3.890681e-004,3,9.140491e-001,1.825000e+000,,,,,,,,,,,,,,,,,,0,4.000000e+000,1.000000e+000,2,2,1.409912e-002,0,,0,
1699958053.531,,5.000000e+001,3.000012e+002,2.733106e-006,5.966886e-008,-3.095035e-002,1.331061e-002,3,9.317680e-001,1.825000e+000,,,,,,,,,,,,,,,,,,0,4.000000e+000,1.000000e+000,2,2,0.000000e+000,0,,0,
1699958169.276,,1.000000e+002,3.000012e+002,3.543369e-006,1.538464e-008,-2.408165e-002,6.520328e-004,3,9.533949e-001,1.825000e+000,,,,,,,,,,,,,,,,,,0,4.000000e+000,1.000000e+000,2,2,0.000000e+000,0,,0,
1699958290.967,,2.000000e+002,3.000012e+002,5.246490e-006,5.806253e-008,2.417114e-004,4.824234e-003,3,9.645893e-001,1.825000e+000,,,,,,,,,,,,,,,,,,0,4.000000e+000,1.000000e+000,2,2,0.000000e+000,0,,0,
1699958411.937,,3.000000e+002,3.000012e+002,6.306847e-006,1.141327e-008,-2.025110e-003,6.458819e-003,3,9.674259e-001,1.825000e+000,,,,,,,,,,,,,,,,,,0,4.000000e+000,1.000000e+000,2,2,0.000000e+000,0,,0,
1699958534.128,,4.000000e+002,3.000012e+002,6.983252e-006,8.111545e-009,6.668851e-003,1.142765e-003,3,9.681868e-001,1.825000e+000,,,,,,,,,,,,,,,,,,0,4.000000e+000,1.000000e+000,2,2,0.000000e+000,0,,0,
1699958655.594,,5.000000e+002,2.999977e+002,7.654383e-006,2.691029e-008,-2.628663e-003,6.510264e-003,3,9.669023e-001,1.825000e+000,,,,,,,,,,,,,,,,,,0,4.000000e+000,1.000000e+000,2,2,1.409912e-002,0,,0,
1699958770.825,,6.000000e+002,3.000012e+002,7.887626e-006,7.511523e-009,-3.027197e-003,1.760018e-003,3,9.608508e-001,1.825000e+000,,,,,,,,,,,,,,,,,,0,4.000000e+000,1.000000e+000,2,2,0.000000e+000,0,,0,
1699958886.278,,7.000000e+002,3.000012e+002,7.820685e-006,1.536840e-008,4.262002e-003,3.539883e-003,3,9.613547e-001,1.825000e+000,,,,,,,,,,,,,,,,,,0,4.000000e+000,1.000000e+000,2,2,0.000000e+000,0,,0,
1699959007.719,,8.000000e+002,3.000012e+002,7.624440e-006,5.641070e-008,9.169708e-003,3.749584e-003,3,9.551190e-001,1.825000e+000,,,,,,,,,,,,,,,,,,0,4.000000e+000,1.000000e+000,2,2,0.000000e+000,0,,0,
1699959129.910,,9.000000e+002,3.000012e+002,7.265869e-006,1.214609e-008,1.703845e-002,7.706060e-003,3,9.536538e-001,1.825000e+000,,,,,,,,,,,,,,,,,,0,4.000000e+000,1.000000e+000,2,2,0.000000e+000,0,,0,
1699959252.351,,1.000000e+003,2.999941e+002,6.680673e-006,4.549359e-009,2.888473e-002,1.066572e-003,3,9.370984e-001,1.825000e+000,,,,,,,,,,,,,,,,,,0,4.000000e+000,1.000000e+000,2,2,1.409912e-002,0,,0,
1699959380.792,,1.250000e+003,3.000012e+002,4.204848e-006,1.352074e-008,9.066895e-002,7.286927e-004,3,8.638796e-001,1.825000e+000,,,,,,,,,,,,,,,,,,0,4.000000e+000,1.000000e+000,2,2,0.000000e+000,0,,0,
1699959503.776,,1.500000e+003,3.000012e+002,1.495852e-006,7.378070e-008,7.344280e-001,2.027386e-002,3,3.670472e-001,1.825000e+000,,,,,,,,,,,,,,,,,,0,4.000000e+000,1.000000e+000,2,2,0.000000e+000,0,,0,
1699959625.815,,1.750000e+003,2.999941e+002,-3.957414e-006,9.074923e-009,-3.633751e-001,6.746025e-003,3,8.468069e-001,1.825000e+000,,,,,,,,,,,,,,,,,,0,4.000000e+000,1.000000e+000,2,2,1.409912e-002,0,,0,
1699959754.006,,2.000000e+003,2.999977e+002,-8.212699e-006,1.010441e-007,-2.186983e-001,1.508287e-002,3,8.990375e-001,1.825000e+000,,,,,,,,,,,,,,,,,,0,4.000000e+000,1.000000e+000,2,2,1.409912e-002,0,,0,
1699959897.814,,3.000000e+003,2.999977e+002,-3.007922e-005,1.080026e-007,-1.302278e-001,7.896491e-003,3,9.526204e-001,1.825000e+000,,,,,,,,,,,,,,,,,,0,4.000000e+000,1.000000e+000,2,2,1.409912e-002,0,,0,
1699960031.005,,4.000000e+003,3.000012e+002,-5.477098e-005,1.419215e-008,-1.023921e-001,1.208013e-003,3,9.613190e-001,1.825000e+000,,,,,,,,,,,,,,,,,,0,4.000000e+000,1.000000e+000,2,2,0.000000e+000,0,,0,
1699960163.947,,5.000000e+003,2.999941e+002,-8.103128e-005,1.016628e-007,-9.970417e-002,9.164938e-004,3,9.644236e-001,1.825000e+000,,,,,,,,,,,,,,,,,,0,4.000000e+000,1.000000e+000,2,2,1.409912e-002,0,,0,
1699960297.691,,6.000000e+003,3.000012e+002,-1.080195e-004,2.056511e-007,-9.169674e-002,3.299587e-003,3,9.657485e-001,1.825000e+000,,,,,,,,,,,,,,,,,,0,4.000000e+000,1.000000e+000,2,2,0.000000e+000,0,,0,
1699960432.134,,7.000000e+003,3.000012e+002,-1.356708e-004,9.013828e-009,-9.190813e-002,1.184916e-003,3,9.675715e-001,1.825000e+000,,,,,,,,,,,,,,,,,,0,4.000000e+000,1.000000e+000,2,2,0.000000e+000,0,,0,
1699960553.825,,8.000000e+003,3.000012e+002,-1.628532e-004,1.664163e-007,-9.069930e-002,6.058083e-004,3,9.678844e-001,1.825000e+000,,,,,,,,,,,,,,,,,,0,4.000000e+000,1.000000e+000,2,2,0.000000e+000,0,,0,
1699960675.741,,9.000000e+003,3.000012e+002,-1.910031e-004,3.907021e-008,-8.911014e-002,1.775399e-003,3,9.687622e-001,1.825000e+000,,,,,,,,,,,,,,,,,,0,4.000000e+000,1.000000e+000,2,2,0.000000e+000,0,,0,
1699960796.932,,1.000000e+004,3.000012e+002,-2.193707e-004,1.738763e-007,-8.819650e-002,8.259413e-004,3,9.705743e-001,1.825000e+000,,,,,,,,,,,,,,,,,,0,4.000000e+000,1.000000e+000,2,2,0.000000e+000,0,,0,
1699960935.874,,1.500000e+004,3.000012e+002,-3.614541e-004,2.013706e-007,-8.463043e-002,1.400750e-004,3,9.711899e-001,1.825000e+000,,,,,,,,,,,,,,,,,,0,4.000000e+000,1.000000e+000,2,2,0.000000e+000,0,,0,
1699961082.542,,2.000000e+004,3.000012e+002,-5.050221e-004,7.543216e-007,-8.244596e-002,3.061020e-004,3,9.731137e-001,1.825000e+000,,,,,,,,,,,,,,,,,,0,4.000000e+000,1.000000e+000,2,2,0.000000e+000,0,,0,
1699961217.287,,2.500000e+004,3.000012e+002,-6.479340e-004,5.569229e-007,-8.020753e-002,1.161636e-003,3,9.720376e-001,1.825000e+000,,,,,,,,,,,,,,,,,,0,4.000000e+000,1.000000e+000,2,2,0.000000e+000,0,,0,
1699961353.268,,3.000000e+004,3.000012e+002,-7.917833e-004,1.955058e-008,-7.989234e-002,6.743601e-004,3,9.724132e-001,1.825000e+000,,,,,,,,,,,,,,,,,,0,4.000000e+000,1.000000e+000,2,2,0.000000e+000,0,,0,
1699961496.513,,3.500000e+004,2.999977e+002,-9.350301e-004,1.259466e-007,-7.848611e-002,1.944708e-004,3,9.722142e-001,1.825000e+000,,,,,,,,,,,,,,,,,,0,4.000000e+000,1.000000e+000,2,2,1.409912e-002,0,,0,
1699961641.247,,4.000000e+004,3.000012e+002,-1.078331e-003,3.305070e-007,-7.721481e-002,1.632453e-004,3,9.721043e-001,1.825000e+000,,,,,,,,,,,,,,,,,,0,4.000000e+000,1.000000e+000,2,2,0.000000e+000,0,,0,
1699961781.196,,4.500000e+004,2.999977e+002,-1.221704e-003,2.724728e-007,-7.602297e-002,3.212591e-004,3,9.725766e-001,1.825000e+000,,,,,,,,,,,,,,,,,,0,4.000000e+000,1.000000e+000,2,2,1.409912e-002,0,,0,
1699961921.937,,5.000000e+004,2.999977e+002,-1.367142e-003,3.292723e-009,-7.478473e-002,9.917680e-005,3,9.722701e-001,1.825000e+000,,,,,,,,,,,,,,,,,,0,4.000000e+000,1.000000e+000,2,2,1.409912e-002,0,,0,
1699962069.630,,5.500000e+004,3.000012e+002,-1.510845e-003,8.569315e-008,-7.385552e-002,1.142864e-004,3,9.721249e-001,1.825000e+000,,,,,,,,,,,,,,,,,,0,4.000000e+000,1.000000e+000,2,2,0.000000e+000,0,,0,
1699962213.129,,6.000000e+004,2.999977e+002,-1.650370e-003,5.169574e-008,-7.301950e-002,7.267697e-005,3,9.722553e-001,1.825000e+000,,,,,,,,,,,,,,,,,,0,4.000000e+000,1.000000e+000,2,2,1.409912e-002,0,,0,
1699962356.632,,6.500000e+004,3.000012e+002,-1.793478e-003,8.305896e-008,-7.229292e-002,1.249496e-004,3,9.722344e-001,1.825000e+000,,,,,,,,,,,,,,,,,,0,4.000000e+000,1.000000e+000,2,2,0.000000e+000,0,,0,
1699962502.575,,7.000000e+004,2.999977e+002,-1.935811e-003,5.663483e-008,-7.171996e-002,9.004147e-005,3,9.722855e-001,1.825000e+000,,,,,,,,,,,,,,,,,,0,4.000000e+000,1.000000e+000,2,2,1.409912e-002,0,,0,
1699962657.269,,6.500000e+004,3.000012e+002,-1.792066e-003,1.309681e-007,-7.198811e-002,1.215304e-004,3,9.723162e-001,1.825000e+000,,,,,,,,,,,,,,,,,,0,4.000000e+000,1.000000e+000,2,2,0.000000e+000,0,,0,
1699962825.212,,5.500000e+004,2.999977e+002,-1.505348e-003,2.568324e-008,-7.266432e-002,8.170166e-005,3,9.722911e-001,1.825000e+000,,,,,,,,,,,,,,,,,,0,4.000000e+000,1.000000e+000,2,2,1.409912e-002,0,,0,
1699962998.656,,4.500000e+004,2.999977e+002,-1.220073e-003,1.536055e-007,-7.332026e-002,1.552374e-003,3,9.731481e-001,1.825000e+000,,,,,,,,,,,,,,,,,,0,4.000000e+000,1.000000e+000,2,2,1.409912e-002,0,,0,
1699963175.634,,3.500000e+004,3.000012e+002,-9.333252e-004,5.399241e-007,-7.440276e-002,1.361765e-004,3,9.721522e-001,1.825000e+000,,,,,,,,,,,,,,,,,,0,4.000000e+000,1.000000e+000,2,2,0.000000e+000,0,,0,
1699963343.879,,2.500000e+004,2.999977e+002,-6.471586e-004,6.548403e-008,-7.447590e-002,3.762502e-004,3,9.729927e-001,1.825000e+000,,,,,,,,,,,,,,,,,,0,4.000000e+000,1.000000e+000,2,2,1.409912e-002,0,,0,
1699963503.370,,1.500000e+004,2.999977e+002,-3.604464e-004,2.615657e-008,-7.645383e-002,1.356918e-004,3,9.704055e-001,1.825000e+000,,,,,,,,,,,,,,,,,,0,4.000000e+000,1.000000e+000,2,2,1.409912e-002,0,,0,
1699963641.354,,1.000000e+004,3.000012e+002,-2.186530e-004,1.647082e-007,-7.800309e-002,1.882278e-003,3,9.696858e-001,1.825000e+000,,,,,,,,,,,,,,,,,,0,4.000000e+000,1.000000e+000,2,2,0.000000e+000,0,,0,
1699963768.512,,9.000000e+003,3.000012e+002,-1.904076e-004,8.012634e-008,-7.925057e-002,1.288851e-004,3,9.700235e-001,1.825000e+000,,,,,,,,,,,,,,,,,,0,4.000000e+000,1.000000e+000,2,2,0.000000e+000,0,,0,
1699963883.229,,8.000000e+003,2.999977e+002,-1.622236e-004,3.866891e-008,-7.957160e-002,8.181915e-004,3,9.690556e-001,1.825000e+000,,,,,,,,,,,,,,,,,,0,4.000000e+000,1.000000e+000,2,2,1.409912e-002,0,,0,
1699964011.170,,7.000000e+003,3.000012e+002,-1.348632e-004,2.060421e-007,-8.216257e-002,3.032018e-003,3,9.646992e-001,1.825000e+000,,,,,,,,,,,,,,,,,,0,4.000000e+000,1.000000e+000,2,2,0.000000e+000,0,,0,
1699964143.362,,6.000000e+003,3.000012e+002,-1.071847e-004,2.008561e-008,-8.264793e-002,2.304210e-003,3,9.642920e-001,1.825000e+000,,,,,,,,,,,,,,,,,,0,4.000000e+000,1.000000e+000,2,2,0.000000e+000,0,,0,
1699964276.309,,5.000000e+003,2.999941e+002,-8.029293e-005,1.318735e-007,-8.516508e-002,3.496782e-003,3,9.651150e-001,1.825000e+000,,,,,,,,,,,,,,,,,,0,4.000000e+000,1.000000e+000,2,2,1.409912e-002,0,,0,
1699964409.751,,4.000000e+003,2.999977e+002,-5.394637e-005,7.218780e-008,-9.657491e-002,4.316607e-003,3,9.578503e-001,1.825000e+000,,,,,,,,,,,,,,,,,,0,4.000000e+000,1.000000e+000,2,2,1.409912e-002,0,,0,
1699964543.443,,3.000000e+003,2.999977e+002,-2.910081e-005,1.238102e-007,-1.139256e-001,4.569429e-003,3,9.462085e-001,1.825000e+000,,,,,,,,,,,,,,,,,,0,4.000000e+000,1.000000e+000,2,2,1.409912e-002,0,,0,
1699964676.207,,2.000000e+003,3.000012e+002,-6.970447e-006,2.847819e-008,-2.230565e-001,2.334113e-003,3,8.533453e-001,1.825000e+000,,,,,,,,,,,,,,,,,,0,4.000000e+000,1.000000e+000,2,2,0.000000e+000,0,,0,
1699964798.148,,1.750000e+003,2.999941e+002,-2.720501e-006,1.536045e-007,-6.557696e-001,7.388747e-002,3,7.170911e-001,1.825000e+000,,,,,,,,,,,,,,,,,,0,4.000000e+000,1.000000e+000,2,2,1.409912e-002,0,,0,
1699964925.840,,1.500000e+003,3.000012e+002,3.186590e-006,2.021225e-007,1.837508e-001,2.396962e-002,3,7.352949e-001,1.825000e+000,,,,,,,,,,,,,,,,,,0,4.000000e+000,1.000000e+000,2,2,0.000000e+000,0,,0,
1699965048.060,,1.250000e+003,3.000012e+002,7.031735e-006,1.264676e-007,5.080688e-002,1.596121e-002,3,9.186213e-001,1.825000e+000,,,,,,,,,,,,,,,,,,0,4.000000e+000,1.000000e+000,2,2,0.000000e+000,0,,0,
1699965169.751,,1.000000e+003,3.000012e+002,9.993359e-006,1.241067e-007,1.898028e-002,1.058568e-002,3,9.424630e-001,1.825000e+000,,,,,,,,,,,,,,,,,,0,4.000000e+000,1.000000e+000,2,2,0.000000e+000,0,,0,
1699965290.942,,9.000000e+002,3.000012e+002,1.091729e-005,7.767288e-008,3.893360e-003,3.657017e-003,3,9.303156e-001,1.825000e+000,,,,,,,,,,,,,,,,,,0,4.000000e+000,1.000000e+000,2,2,0.000000e+000,0,,0,
1699965406.449,,8.000000e+002,3.000012e+002,1.170949e-005,1.920262e-008,-8.394585e-003,3.904082e-003,3,9.413476e-001,1.825000e+000,,,,,,,,,,,,,,,,,,0,4.000000e+000,1.000000e+000,2,2,0.000000e+000,0,,0,
1699965528.204,,7.000000e+002,3.000012e+002,1.266307e-005,2.909834e-007,-7.444507e-003,6.359891e-003,3,9.477388e-001,1.825000e+000,,,,,,,,,,,,,,,,,,0,4.000000e+000,1.000000e+000,2,2,0.000000e+000,0,,0,
1699965649.147,,6.000000e+002,3.000012e+002,1.331559e-005,5.566052e-008,-2.573796e-002,4.211005e-003,3,9.548692e-001,1.825000e+000,,,,,,,,,,,,,,,,,,0,4.000000e+000,1.000000e+000,2,2,0.000000e+000,0,,0,
1699965770.338,,5.000000e+002,3.000012e+002,1.327036e-005,1.942655e-007,-1.891773e-002,9.083602e-003,3,9.298495e-001,1.825000e+000,,,,,,,,,,,,,,,,,,0,4.000000e+000,1.000000e+000,2,2,0.000000e+000,0,,0,
1699965891.779,,4.000000e+002,3.000012e+002,1.350380e-005,7.634421e-008,-3.835097e-002,1.442695e-002,3,9.601717e-001,1.825000e+000,,,,,,,,,,,,,,,,,,0,4.000000e+000,1.000000e+000,2,2,0.000000e+000,0,,0,
1699966014.255,,3.000000e+002,3.000012e+002,1.327153e-005,2.197596e-007,-4.002531e-002,8.958257e-003,3,9.465377e-001,1.825000e+000,,,,,,,,,,,,,,,,,,0,4.000000e+000,1.000000e+000,2,2,0.000000e+000,0,,0,
1699966135.946,,2.000000e+002,3.000012e+002,1.190059e-005,1.000145e-007,-3.394178e-002,7.406245e-003,3,9.582241e-001,1.825000e+000,,,,,,,,,,,,,,,,,,0,4.000000e+000,1.000000e+000,2,2,0.000000e+000,0,,0,
1699966256.687,,1.000000e+002,3.000012e+002,1.077654e-005,7.866713e-008,-4.689399e-002,1.210030e-002,3,9.514451e-001,1.825000e+000,,,,,,,,,,,,,,,,,,0,4.000000e+000,1.000000e+000,2,2,0.000000e+000,0,,0,
1699966366.438,,7.500000e+001,2.999941e+002,9.994078e-006,4.636179e-008,-4.175466e-002,1.640949e-002,3,9.500754e-001,1.825000e+000,,,,,,,,,,,,,,,,,,0,4.000000e+000,1.000000e+000,2,2,1.409912e-002,0,,0,
1699966481.628,,5.000000e+001,3.000012e+002,9.241790e-006,2.011538e-007,-4.126191e-002,1.649890e-002,3,9.328196e-001,1.825000e+000,,,,,,,,,,,,,,,,,,0,4.000000e+000,1.000000e+000,2,2,0.000000e+000,0,,0,
1699966595.850,,2.500000e+001,3.000012e+002,8.163554e-006,1.119944e-007,-3.956054e-002,4.141117e-003,3,8.965802e-001,1.825000e+000,,,,,,,,,,,,,,,,,,0,4.000000e+000,1.000000e+000,2,2,0.000000e+000,0,,0,
1699966711.790,,0.000000e+000,2.999977e+002,6.465770e-006,1.564159e-007,-9.957179e-002,2.221450e-003,3,8.902786e-001,1.825000e+000,,,,,,,,,,,,,,,,,,0,4.000000e+000,1.000000e+000,2,2,1.409912e-002,0,,0,
1699966820.481,,-2.500000e+001,3.000012e+002,5.639841e-006,4.491126e-007,-9.923030e-002,7.213244e-003,3,9.393288e-001,1.825000e+000,,,,,,,,,,,,,,,,,,0,4.000000e+000,1.000000e+000,2,2,0.000000e+000,0,,0,
1699966934.921,,-5.000000e+001,3.000012e+002,4.899283e-006,1.633653e-007,-1.340283e-001,1.583818e-002,3,8.252258e-001,1.825000e+000,,,,,,,,,,,,,,,,,,0,4.000000e+000,1.000000e+000,2,2,0.000000e+000,0,,0,
1699967049.672,,-7.500000e+001,2.999977e+002,3.992392e-006,2.192358e-007,-1.839569e-001,5.370773e-004,3,9.146251e-001,1.825000e+000,,,,,,,,,,,,,,,,,,0,4.000000e+000,1.000000e+000,2,2,1.409912e-002,0,,0,
1699967159.136,,-1.000000e+002,3.000012e+002,3.165178e-006,3.782016e-008,-1.879779e-001,2.036208e-002,3,8.155951e-001,1.825000e+000,,,,,,,,,,,,,,,,,,0,4.000000e+000,1.000000e+000,2,2,0.000000e+000,0,,0,
1699967274.869,,-2.000000e+002,3.000012e+002,1.455232e-006,3.460259e-007,-8.313438e-001,1.333763e-001,3,5.009314e-001,1.825000e+000,,,,,,,,,,,,,,,,,,0,4.000000e+000,1.000000e+000,2,2,0.000000e+000,0,,0,
1699967390.071,,-3.000000e+002,3.000012e+002,-2.213128e-006,8.313787e-008,2.313583e-001,9.093503e-002,3,6.873194e-001,1.825000e+000,,,,,,,,,,,,,,,,,,0,4.000000e+000,1.000000e+000,2,2,0.000000e+000,0,,0,
1699967512.012,,-4.000000e+002,2.999977e+002,-3.777675e-006,4.403920e-008,2.327875e-001,1.744346e-001,3,5.586571e-001,1.825000e+000,,,,,,,,,,,,,,,,,,0,4.000000e+000,1.000000e+000,2,2,1.409912e-002,0,,0,
1699967633.974,,-5.000000e+002,2.999941e+002,-4.694277e-006,1.304561e-007,8.346710e-002,4.920339e-003,3,8.376372e-001,1.825000e+000,,,,,,,,,,,,,,,,,,0,4.000000e+000,1.000000e+000,2,2,1.409912e-002,0,,0,
1699967749.166,,-6.000000e+002,3.000012e+002,-5.408005e-006,4.027893e-008,3.048488e-002,2.723899e-002,3,7.877470e-001,1.825000e+000,,,,,,,,,,,,,,,,,,0,4.000000e+000,1.000000e+000,2,2,0.000000e+000,0,,0,
1699967865.356,,-7.000000e+002,3.000012e+002,-6.040298e-006,3.840842e-007,3.611629e-002,3.530912e-002,3,8.728006e-001,1.825000e+000,,,,,,,,,,,,,,,,,,0,4.000000e+000,1.000000e+000,2,2,0.000000e+000,0,,0,
1699967987.098,,-8.000000e+002,2.999977e+002,-5.798714e-006,2.004641e-007,3.797740e-002,2.700000e-002,3,8.704374e-001,1.825000e+000,,,,,,,,,,,,,,,,,,0,4.000000e+000,1.000000e+000,2,2,1.409912e-002,0,,0,
1699968108.789,,-9.000000e+002,3.000012e+002,-5.356443e-006,2.222202e-007,3.278378e-002,3.553651e-002,3,8.341452e-001,1.825000e+000,,,,,,,,,,,,,,,,,,0,4.000000e+000,1.000000e+000,2,2,0.000000e+000,0,,0,
1699968229.782,,-1.000000e+003,3.000012e+002,-5.018133e-006,4.047315e-008,9.522039e-002,6.722828e-003,3,9.090785e-001,1.825000e+000,,,,,,,,,,,,,,,,,,0,4.000000e+000,1.000000e+000,2,2,0.000000e+000,0,,0,
1699968357.974,,-1.250000e+003,3.000012e+002,-2.964104e-006,6.164305e-008,1.863814e-001,8.267810e-003,3,7.448587e-001,1.825000e+000,,,,,,,,,,,,,,,,,,0,4.000000e+000,1.000000e+000,2,2,0.000000e+000,0,,0,
1699968479.915,,-1.500000e+003,3.000012e+002,1.896523e-007,3.956174e-008,0.000000e+000,0.000000e+000,3,0.000000e+000,1.825000e+000,,,,,,,,,,,,,,,,,,0,4.000000e+000,1.000000e+000,2,2,0.000000e+000,0,,0,
1699968602.106,,-1.750000e+003,3.000012e+002,5.009948e-006,6.190026e-007,-3.376541e-001,5.559370e-002,3,7.283028e-001,1.825000e+000,,,,,,,,,,,,,,,,,,0,4.000000e+000,1.000000e+000,2,2,0.000000e+000,0,,0,
1699968724.297,,-2.000000e+003,3.000012e+002,8.955674e-006,9.016336e-008,-1.898036e-001,4.263048e-004,3,9.199320e-001,1.825000e+000,,,,,,,,,,,,,,,,,,0,4.000000e+000,1.000000e+000,2,2,0.000000e+000,0,,0,
1699968856.524,,-3.000000e+003,3.000012e+002,3.041258e-005,3.606689e-008,-1.075189e-001,6.850918e-004,3,9.536220e-001,1.825000e+000,,,,,,,,,,,,,,,,,,0,4.000000e+000,1.000000e+000,2,2,0.000000e+000,0,,0,
1699968989.716,,-4.000000e+003,3.000012e+002,5.494956e-005,4.196343e-007,-8.680482e-002,1.906281e-003,3,9.526090e-001,1.825000e+000,,,,,,,,,,,,,,,,,,0,4.000000e+000,1.000000e+000,2,2,0.000000e+000,0,,0,
1699969122.447,,-5.000000e+003,2.999977e+002,8.116714e-005,6.710466e-007,-8.252623e-002,7.431543e-004,3,9.617181e-001,1.825000e+000,,,,,,,,,,,,,,,,,,0,4.000000e+000,1.000000e+000,2,2,1.409912e-002,0,,0,
1699969255.936,,-6.000000e+003,3.000012e+002,1.081013e-004,3.984863e-007,-7.906073e-002,2.517853e-004,3,9.647497e-001,1.825000e+000,,,,,,,,,,,,,,,,,,0,4.000000e+000,1.000000e+000,2,2,0.000000e+000,0,,0,
1699969381.926,,-7.000000e+003,2.999977e+002,1.357775e-004,6.997035e-010,-7.783324e-002,5.580501e-003,3,9.669122e-001,1.825000e+000,,,,,,,,,,,,,,,,,,0,4.000000e+000,1.000000e+000,2,2,1.409912e-002,0,,0,
1699969503.617,,-8.000000e+003,2.999977e+002,1.630905e-004,4.599522e-008,-8.439603e-002,5.809532e-003,3,9.661430e-001,1.825000e+000,,,,,,,,,,,,,,,,,,0,4.000000e+000,1.000000e+000,2,2,1.409912e-002,0,,0,
1699969625.308,,-9.000000e+003,3.000012e+002,1.910633e-004,1.595118e-007,-7.497977e-002,2.648929e-004,3,9.704665e-001,1.825000e+000,,,,,,,,,,,,,,,,,,0,4.000000e+000,1.000000e+000,2,2,0.000000e+000,0,,0,
1699969746.753,,-1.000000e+004,2.999977e+002,2.188640e-004,4.985388e-007,-7.371084e-002,4.123621e-003,3,9.697602e-001,1.825000e+000,,,,,,,,,,,,,,,,,,0,4.000000e+000,1.000000e+000,2,2,1.409912e-002,0,,0,
1699969913.177,,-2.000000e+004,3.000012e+002,5.044058e-004,2.448551e-007,-7.167438e-002,1.992498e-003,3,9.724817e-001,1.825000e+000,,,,,,,,,,,,,,,,,,0,4.000000e+000,1.000000e+000,2,2,0.000000e+000,0,,0,
1699970074.678,,-3.000000e+004,2.999977e+002,7.908164e-004,9.637387e-007,-6.943658e-002,8.982916e-004,3,9.724916e-001,1.825000e+000,,,,,,,,,,,,,,,,,,0,4.000000e+000,1.000000e+000,2,2,1.409912e-002,0,,0,
1699970243.277,,-4.000000e+004,2.999977e+002,1.077223e-003,4.199028e-009,-6.827132e-002,2.037010e-004,3,9.725971e-001,1.825000e+000,,,,,,,,,,,,,,,,,,0,4.000000e+000,1.000000e+000,2,2,1.409912e-002,0,,0,
1699970404.033,,-5.000000e+004,3.000012e+002,1.362979e-003,9.540667e-008,-6.672147e-002,6.932103e-005,3,9.721888e-001,1.825000e+000,,,,,,,,,,,,,,,,,,0,4.000000e+000,1.000000e+000,2,2,0.000000e+000,0,,0,
1699970573.976,,-6.000000e+004,2.999977e+002,1.648839e-003,7.737898e-009,-6.585359e-002,1.808521e-004,3,9.722592e-001,1.825000e+000,,,,,,,,,,,,,,,,,,0,4.000000e+000,1.000000e+000,2,2,1.409912e-002,0,,0,
1699970739.920,,-7.000000e+004,3.000012e+002,1.934704e-003,1.271814e-007,-6.514095e-002,6.028053e-005,3,9.721723e-001,1.825000e+000,,,,,,,,,,,,,,,,,,0,4.000000e+000,1.000000e+000,2,2,0.000000e+000,0,,0,
1699970888.362,,-6.500000e+004,2.999977e+002,1.790930e-003,2.016809e-008,-6.586996e-002,2.550938e-005,3,9.722546e-001,1.825000e+000,,,,,,,,,,,,,,,,,,0,4.000000e+000,1.000000e+000,2,2,1.409912e-002,0,,0,
1699971056.093,,-5.500000e+004,3.000012e+002,1.504542e-003,9.458349e-008,-6.703226e-002,7.122817e-006,3,9.721853e-001,1.825000e+000,,,,,,,,,,,,,,,,,,0,4.000000e+000,1.000000e+000,2,2,0.000000e+000,0,,0,
1699971228.787,,-4.500000e+004,2.999941e+002,1.218614e-003,1.985512e-007,-6.817394e-002,4.692841e-004,3,9.724301e-001,1.825000e+000,,,,,,,,,,,,,,,,,,0,4.000000e+000,1.000000e+000,2,2,1.409912e-002,0,,0,
1699971399.491,,-3.500000e+004,2.999941e+002,9.327382e-004,2.907474e-007,-6.929725e-002,3.659822e-004,3,9.721239e-001,1.825000e+000,,,,,,,,,,,,,,,,,,0,4.000000e+000,1.000000e+000,2,2,1.409912e-002,0,,0,
1699971566.934,,-2.500000e+004,3.000012e+002,6.463121e-004,2.335363e-007,-7.097235e-002,7.002593e-004,3,9.717993e-001,1.825000e+000,,,,,,,,,,,,,,,,,,0,4.000000e+000,1.000000e+000,2,2,0.000000e+000,0,,0,
1699971726.877,,-1.500000e+004,3.000012e+002,3.603646e-004,5.089315e-008,-7.318050e-002,1.533060e-003,3,9.707071e-001,1.825000e+000,,,,,,,,,,,,,,,,,,0,4.000000e+000,1.000000e+000,2,2,0.000000e+000,0,,0,
1699971871.787,,-1.000000e+004,3.000012e+002,2.182213e-004,1.745657e-007,-7.474755e-002,2.505630e-005,3,9.702596e-001,1.825000e+000,,,,,,,,,,,,,,,,,,0,4.000000e+000,1.000000e+000,2,2,0.000000e+000,0,,0,
1699971987.535,,-9.000000e+003,3.000012e+002,1.900232e-004,1.710055e-007,-7.517497e-002,2.481417e-003,3,9.678921e-001,1.825000e+000,,,,,,,,,,,,,,,,,,0,4.000000e+000,1.000000e+000,2,2,0.000000e+000,0,,0,
1699972108.726,,-8.000000e+003,2.999941e+002,1.620466e-004,5.319815e-009,-7.382374e-002,5.008521e-004,3,9.691621e-001,1.825000e+000,,,,,,,,,,,,,,,,,,0,4.000000e+000,1.000000e+000,2,2,1.409912e-002,0,,0,
1699972242.168,,-7.000000e+003,3.000012e+002,1.348086e-004,1.597073e-007,-7.797398e-002,1.801493e-003,3,9.683785e-001,1.825000e+000,,,,,,,,,,,,,,,,,,0,4.000000e+000,1.000000e+000,2,2,0.000000e+000,0,,0,
1699972374.859,,-6.000000e+003,3.000012e+002,1.072190e-004,1.474522e-008,-7.935128e-002,3.602159e-003,3,9.675883e-001,1.825000e+000,,,,,,,,,,,,,,,,,,0,4.000000e+000,1.000000e+000,2,2,0.000000e+000,0,,0,
1699972515.308,,-5.000000e+003,3.000012e+002,8.011117e-005,1.272483e-007,-8.340468e-002,2.824966e-003,3,9.662673e-001,1.825000e+000,,,,,,,,,,,,,,,,,,0,4.000000e+000,1.000000e+000,2,2,0.000000e+000,0,,0,
1699972648.000,,-4.000000e+003,2.999941e+002,5.377915e-005,1.663082e-007,-8.667426e-002,1.379630e-003,3,9.588276e-001,1.825000e+000,,,,,,,,,,,,,,,,,,0,4.000000e+000,1.000000e+000,2,2,1.409912e-002,0,,0,
1699972781.443,,-3.000000e+003,3.000012e+002,2.931584e-005,1.681977e-007,-1.069325e-001,7.880718e-003,3,9.439787e-001,1.825000e+000,,,,,,,,,,,,,,,,,,0,4.000000e+000,1.000000e+000,2,2,0.000000e+000,0,,0,
1699972914.134,,-2.000000e+003,3.000012e+002,7.077860e-006,2.968933e-007,-2.331170e-001,1.871942e-003,3,8.612164e-001,1.825000e+000,,,,,,,,,,,,,,,,,,0,4.000000e+000,1.000000e+000,2,2,0.000000e+000,0,,0,
1699973041.895,,-1.750000e+003,3.000012e+002,2.757465e-006,9.959891e-008,-5.609876e-001,4.183045e-002,3,7.398317e-001,1.825000e+000,,,,,,,,,,,,,,,,,,0,4.000000e+000,1.000000e+000,2,2,0.000000e+000,0,,0,
1699973164.337,,-1.500000e+003,3.000012e+002,-3.297765e-006,9.826735e-008,1.826664e-001,3.601660e-002,3,7.839392e-001,1.825000e+000,,,,,,,,,,,,,,,,,,0,4.000000e+000,1.000000e+000,2,2,0.000000e+000,0,,0,
1699973285.777,,-1.250000e+003,3.000012e+002,-6.691132e-006,2.242814e-008,3.991928e-002,2.876951e-002,3,8.714515e-001,1.825000e+000,,,,,,,,,,,,,,,,,,0,4.000000e+000,1.000000e+000,2,2,0.000000e+000,0,,0,
1699973407.718,,-1.000000e+003,3.000012e+002,-1.014076e-005,6.042403e-008,2.812190e-002,6.233417e-003,3,9.362372e-001,1.825000e+000,,,,,,,,,,,,,,,,,,0,4.000000e+000,1.000000e+000,2,2,0.000000e+000,0,,0,
1699973528.909,,-9.000000e+002,3.000012e+002,-1.106586e-005,2.962318e-007,4.114381e-003,2.238746e-003,3,9.526594e-001,1.825000e+000,,,,,,,,,,,,,,,,,,0,4.000000e+000,1.000000e+000,2,2,0.000000e+000,0,,0,
1699973651.110,,-8.000000e+002,3.000012e+002,-1.211191e-005,1.436090e-007,-1.107285e-002,2.242798e-002,3,9.450738e-001,1.825000e+000,,,,,,,,,,,,,,,,,,0,4.000000e+000,1.000000e+000,2,2,0.000000e+000,0,,0,
1699973773.301,,-7.000000e+002,3.000012e+002,-1.287068e-005,4.418268e-007,-2.277989e-002,4.301652e-004,3,9.405921e-001,1.825000e+000,,,,,,,,,,,,,,,,,,0,4.000000e+000,1.000000e+000,2,2,0.000000e+000,0,,0,
1699973894.783,,-6.000000e+002,3.000012e+002,-1.335066e-005,2.275908e-007,-1.364642e-002,1.914152e-003,3,9.384726e-001,1.825000e+000,,,,,,,,,,,,,,,,,,0,4.000000e+000,1.000000e+000,2,2,0.000000e+000,0,,0,
1699974016.785,,-5.000000e+002,3.000012e+002,-1.335383e-005,2.884161e-007,-1.158794e-002,2.016209e-002,3,9.406800e-001,1.825000e+000,,,,,,,,,,,,,,,,,,0,4.000000e+000,1.000000e+000,2,2,0.000000e+000,0,,0,
1699974138.504,,-4.000000e+002,3.000012e+002,-1.368312e-005,1.560757e-007,-2.214603e-002,3.913522e-003,3,9.641790e-001,1.825000e+000,,,,,,,,,,,,,,,,,,0,4.000000e+000,1.000000e+000,2,2,0.000000e+000,0,,0,
1699974260.969,,-3.000000e+002,2.999977e+002,-1.310589e-005,2.436357e-008,-2.373853e-002,5.998494e-003,3,9.552079e-001,1.825000e+000,,,,,,,,,,,,,,,,,,0,4.000000e+000,1.000000e+000,2,2,1.409912e-002,0,,0,
1699974382.161,,-2.000000e+002,3.000012e+002,-1.219050e-005,1.308362e-007,-2.924818e-002,1.354693e-002,3,9.603559e-001,1.825000e+000,,,,,,,,,,,,,,,,,,0,4.000000e+000,1.000000e+000,2,2,0.000000e+000,0,,0,
1699974504.352,,-1.000000e+002,3.000012e+002,-1.031880e-005,5.390933e-008,-3.571865e-002,7.820795e-003,3,9.527600e-001,1.825000e+000,,,,,,,,,,,,,,,,,,0,4.000000e+000,1.000000e+000,2,2,0.000000e+000,0,,0,
1699974612.545,,-7.500000e+001,2.999977e+002,-9.783624e-006,2.778665e-007,-3.349484e-002,8.074503e-003,3,9.346030e-001,1.825000e+000,,,,,,,,,,,,,,,,,,0,4.000000e+000,1.000000e+000,2,2,1.409912e-002,0,,0,
1699974720.986,,-5.000000e+001,3.000012e+002,-9.512314e-006,1.587240e-007,-4.205145e-002,4.080895e-004,3,9.567062e-001,1.825000e+000,,,,,,,,,,,,,,,,,,0,4.000000e+000,1.000000e+000,2,2,0.000000e+000,0,,0,
1699974836.676,,-2.500000e+001,3.000012e+002,-8.163157e-006,2.096725e-007,-5.574597e-002,1.390027e-003,3,9.501205e-001,1.825000e+000,,,,,,,,,,,,,,,,,,0,4.000000e+000,1.000000e+000,2,2,0.000000e+000,0,,0,
1699974951.888,,0.000000e+000,3.000012e+002,-6.653416e-006,4.217871e-007,-8.713283e-002,1.271655e-003,3,9.559055e-001,1.825000e+000,,,,,,,,,,,,,,,,,,0,4.000000e+000,1.000000e+000,2,2,0.000000e+000,0,,0,
1699975061.883,,2.500000e+001,3.000012e+002,-5.717724e-006,1.085193e-007,-1.147625e-001,3.696535e-002,3,8.660563e-001,1.825000e+000,,,,,,,,,,,,,,,,,,0,4.000000e+000,1.000000e+000,2,2,0.000000e+000,0,,0,
1699975169.910,,5.000000e+001,3.000012e+002,-4.906135e-006,2.878991e-007,-1.160195e-001,1.979138e-002,3,9.079742e-001,1.825000e+000,,,,,,,,,,,,,,,,,,0,4.000000e+000,1.000000e+000,2,2,0.000000e+000,0,,0,
1699975284.880,,7.500000e+001,2.999977e+002,-3.736800e-006,2.014992e-008,-1.664565e-001,2.500567e-002,3,8.009347e-001,1.825000e+000,,,,,,,,,,,,,,,,,,0,4.000000e+000,1.000000e+000,2,2,1.409912e-002,0,,0,
1699975393.320,,1.000000e+002,3.000012e+002,-3.238537e-006,1.651207e-007,-1.913830e-001,3.019253e-003,3,8.965435e-001,1.825000e+000,,,,,,,,,,,,,,,,,,0,4.000000e+000,1.000000e+000,2,2,0.000000e+000,0,,0,
1699975516.262,,2.000000e+002,3.000012e+002,-7.992693e-008,1.247397e-006,1.543283e-001,1.397676e+000,3,1.690287e-001,1.825000e+000,,,,,,,,,,,,,,,,,,0,4.000000e+000,1.000000e+000,2,2,0.000000e+000,0,,0,
1699975638.954,,3.000000e+002,3.000012e+002,2.858312e-006,2.024558e-008,4.055915e-001,7.740267e-002,3,3.134064e-001,1.825000e+000,,,,,,,,,,,,,,,,,,0,4.000000e+000,1.000000e+000,2,2,0.000000e+000,0,,0,
1699975760.395,,4.000000e+002,3.000012e+002,3.808573e-006,1.152131e-008,1.273138e-001,1.988984e-002,3,8.463287e-001,1.825000e+000,,,,,,,,,,,,,,,,,,0,4.000000e+000,1.000000e+000,2,2,0.000000e+000,0,,0,
1699975882.336,,5.000000e+002,3.000012e+002,4.671057e-006,4.601072e-007,7.100564e-002,2.101074e-002,3,9.064494e-001,1.825000e+000,,,,,,,,,,,,,,,,,,0,4.000000e+000,1.000000e+000,2,2,0.000000e+000,0,,0,
1699976004.527,,6.000000e+002,3.000012e+002,5.679205e-006,2.083509e-007,3.985091e-002,3.909403e-002,3,8.131827e-001,1.825000e+000,,,,,,,,,,,,,,,,,,0,4.000000e+000,1.000000e+000,2,2,0.000000e+000,0,,0,
1699976119.244,,7.000000e+002,2.999977e+002,5.846011e-006,1.328591e-007,5.791182e-002,3.247116e-002,3,8.639523e-001,1.825000e+000,,,,,,,,,,,,,,,,,,0,4.000000e+000,1.000000e+000,2,2,1.409912e-002,0,,0,
1699976235.185,,8.000000e+002,3.000012e+002,5.725929e-006,4.572222e-008,7.147284e-002,9.453380e-003,3,9.202999e-001,1.825000e+000,,,,,,,,,,,,,,,,,,0,4.000000e+000,1.000000e+000,2,2,0.000000e+000,0,,0,
1699976356.198,,9.000000e+002,3.000012e+002,5.687558e-006,1.648400e-007,3.731462e-002,1.391560e-002,3,8.502136e-001,1.825000e+000,,,,,,,,,,,,,,,,,,0,4.000000e+000,1.000000e+000,2,2,0.000000e+000,0,,0,
1699976478.162,,1.000000e+003,3.000012e+002,5.082334e-006,3.304745e-007,7.718933e-002,9.803304e-003,3,7.493436e-001,1.825000e+000,,,,,,,,,,,,,,,,,,0,4.000000e+000,1.000000e+000,2,2,0.000000e+000,0,,0,
1699976607.353,,1.250000e+003,3.000012e+002,2.893404e-006,2.207372e-007,2.438705e-001,3.339669e-002,3,6.167246e-001,1.825000e+000,,,,,,,,,,,,,,,,,,0,4.000000e+000,1.000000e+000,2,2,0.000000e+000,0,,0,
1699976729.547,,1.500000e+003,2.999977e+002,-1.516794e-007,8.326781e-008,0.000000e+000,0.000000e+000,3,0.000000e+000,1.825000e+000,,,,,,,,,,,,,,,,,,0,4.000000e+000,1.000000e+000,2,2,1.409912e-002,0,,0,
1699976851.518,,1.750000e+003,2.999906e+002,-4.173109e-006,7.025856e-007,-5.607175e-001,3.730425e-001,3,4.349722e-001,1.825000e+000,,,,,,,,,,,,,,,,,,0,4.000000e+000,1.000000e+000,2,2,1.409912e-002,0,,0,
1699976978.473,,2.000000e+003,3.000012e+002,-8.827812e-006,9.389404e-010,-1.864826e-001,8.545010e-003,3,9.199840e-001,1.825000e+000,,,,,,,,,,,,,,,,,,0,4.000000e+000,1.000000e+000,2,2,0.000000e+000,0,,0,
1699977104.914,,3.000000e+003,3.000012e+002,-3.035681e-005,2.246048e-007,-1.050999e-001,2.522157e-003,3,9.482228e-001,1.825000e+000,,,,,,,,,,,,,,,,,,0,4.000000e+000,1.000000e+000,2,2,0.000000e+000,0,,0,
1699977231.888,,4.000000e+003,3.000012e+002,-5.513046e-005,3.128858e-007,-8.833779e-002,1.471599e-003,3,9.584868e-001,1.825000e+000,,,,,,,,,,,,,,,,,,0,4.000000e+000,1.000000e+000,2,2,0.000000e+000,0,,0,
1699977365.830,,5.000000e+003,3.000012e+002,-8.127410e-005,1.045748e-007,-8.478197e-002,2.872044e-003,3,9.657298e-001,1.825000e+000,,,,,,,,,,,,,,,,,,0,4.000000e+000,1.000000e+000,2,2,0.000000e+000,0,,0,