File: dane/Trt_TEOS — kopia/Big TEOS/FeTrz_Trt_big_FC_FH.rso.dat
[Header]
TITLE,MPMS RSO Measurement
BYAPP,MPMS Measurement,1.1,Summary
FILEOPENTIME, 1654679784.330000 6/8/2022, 11:16:24 AM

INFO, APPNAME, MPMS MultiVu Application, Revision 1.60,  Build 081

INFO, NAME, AP_FeTrz_trt_big
INFO, WEIGHT, 6.600
INFO, AREA, 0.000
INFO, LENGTH, 0.000
INFO, SHAPE, 0
INFO, COMMENT, na Cu drutu, w foli Al
INFO, SEQUENCE FILE: FC_FH_300-390.seq


INFO, BACKGROUND DATA FILE:, None


STARTUPAXIS,X,4,LINEAR,AUTO,0.000000,0.000000
STARTUPAXIS,Y1,5,LINEAR,AUTO,0.000000,0.000000


STARTUPGROUP,Longitudinal
FIELDGROUP,Longitudinal,1,2,3,4,5,6,7,8,9,10,11,19,20,21,22,23,35
FIELDGROUP,Transverse,1,2,3,4,12,13,14,15,16,17,18,24,25,26,27,28,35

PLOT_APPEARANCE,ALL,HORZ_GRID_ON,VERT_GRID_ON,MARKERS_AND_LINES

[Data]
Time,Comment,Field (Oe),Temperature (K),Long Moment (emu),Long Scan Std Dev,Long Offset (cm),Long Offset Std Dev,Long Algorithm,Long Reg Fit,Long Reg Factor,Trans Moment (emu),Trans Scan Std Dev,Trans Offset (cm),Trans Offset Std Dev,Trans Algorithm,Trans Reg Fit,Trans Reg Factor,Long Moment [w/o ABS] (emu),Long Scan Std Dev [w/o ABS],Long Offset [w/o ABS] (cm),Long Offset Std Dev [w/o ABS],Long Reg Fit [w/o ABS],Trans Moment [w/o ABS] (emu),Trans Scan Std Dev [w/o ABS],Trans Offset [w/o ABS] (cm),Trans Offset Std Dev [w/o ABS],Trans Reg Fit [w/o ABS],RSO Position (deg),Amplitude (cm),Frequency,Cycles to Average,Scans per Measurement,Delta Temp (K),Error,EC Comp. Running,Using ABS,
1654679784.329,,1.000000e+003,2.999981e+002,4.101315e-005,4.416879e-009,-3.205599e-002,4.011853e-005,3,9.434696e-001,1.825000e+000,,,,,,,,,,,,,,,,,,0,4.000000e+000,1.000000e+000,2,2,1.409912e-002,0,,0,
1654679951.089,,1.000000e+003,3.021215e+002,4.091299e-005,4.791426e-008,-3.168267e-002,8.529732e-005,3,9.425594e-001,1.825000e+000,,,,,,,,,,,,,,,,,,0,4.000000e+000,1.000000e+000,2,2,2.445068e-001,0,,0,
1654680058.483,,1.000000e+003,3.041205e+002,4.077659e-005,5.880082e-008,-3.193814e-002,6.245268e-004,3,9.422966e-001,1.825000e+000,,,,,,,,,,,,,,,,,,0,4.000000e+000,1.000000e+000,2,2,2.188110e-001,0,,0,
1654680171.367,,1.000000e+003,3.061481e+002,4.064581e-005,1.989010e-008,-3.283670e-002,5.300783e-004,3,9.416992e-001,1.825000e+000,,,,,,,,,,,,,,,,,,0,4.000000e+000,1.000000e+000,2,2,2.366943e-001,0,,0,
1654680286.742,,1.000000e+003,3.081636e+002,4.055700e-005,1.200558e-008,-3.403375e-002,9.996863e-004,3,9.418938e-001,1.825000e+000,,,,,,,,,,,,,,,,,,0,4.000000e+000,1.000000e+000,2,2,2.401123e-001,0,,0,
1654680404.128,,1.000000e+003,3.101545e+002,4.047290e-005,4.697789e-008,-3.448205e-002,7.678997e-004,3,9.416332e-001,1.825000e+000,,,,,,,,,,,,,,,,,,0,4.000000e+000,1.000000e+000,2,2,1.826172e-001,0,,0,
1654680520.896,,1.000000e+003,3.121269e+002,4.037292e-005,5.420131e-009,-3.503314e-002,4.347579e-004,3,9.419136e-001,1.825000e+000,,,,,,,,,,,,,,,,,,0,4.000000e+000,1.000000e+000,2,2,2.158813e-001,0,,0,
1654680642.271,,1.000000e+003,3.141301e+002,4.023235e-005,1.580764e-008,-3.458720e-002,1.304005e-003,3,9.417284e-001,1.825000e+000,,,,,,,,,,,,,,,,,,0,4.000000e+000,1.000000e+000,2,2,2.033081e-001,0,,0,
1654680761.955,,1.000000e+003,3.161294e+002,4.023372e-005,6.971311e-009,-3.598487e-002,1.328477e-003,3,9.409937e-001,1.825000e+000,,,,,,,,,,,,,,,,,,0,4.000000e+000,1.000000e+000,2,2,1.901855e-001,0,,0,
1654680882.893,,1.000000e+003,3.181439e+002,4.008673e-005,3.443210e-008,-3.727152e-002,8.624299e-004,3,9.414864e-001,1.825000e+000,,,,,,,,,,,,,,,,,,0,4.000000e+000,1.000000e+000,2,2,2.088013e-001,0,,0,
1654681003.416,,1.000000e+003,3.201575e+002,4.005353e-005,1.329694e-008,-3.848244e-002,3.828435e-004,3,9.421847e-001,1.825000e+000,,,,,,,,,,,,,,,,,,0,4.000000e+000,1.000000e+000,2,2,1.954041e-001,0,,0,
1654681122.891,,1.000000e+003,3.221407e+002,4.002858e-005,6.518562e-009,-3.769669e-002,2.481309e-003,3,9.419436e-001,1.825000e+000,,,,,,,,,,,,,,,,,,0,4.000000e+000,1.000000e+000,2,2,2.145081e-001,0,,0,
1654681241.050,,1.000000e+003,3.241169e+002,3.996372e-005,3.331052e-008,-4.009020e-002,7.309370e-004,3,9.419429e-001,1.825000e+000,,,,,,,,,,,,,,,,,,0,4.000000e+000,1.000000e+000,2,2,1.838989e-001,0,,0,
1654681360.732,,1.000000e+003,3.261232e+002,3.992916e-005,4.312180e-008,-4.078247e-002,1.866131e-004,3,9.413128e-001,1.825000e+000,,,,,,,,,,,,,,,,,,0,4.000000e+000,1.000000e+000,2,2,2.031860e-001,0,,0,
1654681482.174,,1.000000e+003,3.281368e+002,3.989039e-005,2.067470e-008,-4.123730e-002,8.368152e-004,3,9.423146e-001,1.825000e+000,,,,,,,,,,,,,,,,,,0,4.000000e+000,1.000000e+000,2,2,2.144775e-001,0,,0,
1654681602.366,,1.000000e+003,3.301444e+002,3.985775e-005,7.486313e-008,-4.367446e-002,1.819311e-003,3,9.416504e-001,1.825000e+000,,,,,,,,,,,,,,,,,,0,4.000000e+000,1.000000e+000,2,2,2.171936e-001,0,,0,
1654681721.742,,1.000000e+003,3.321387e+002,3.987226e-005,3.189825e-010,-4.277674e-002,3.432861e-004,3,9.419665e-001,1.825000e+000,,,,,,,,,,,,,,,,,,0,4.000000e+000,1.000000e+000,2,2,2.201233e-001,0,,0,
1654681842.197,,1.000000e+003,3.341521e+002,3.983615e-005,9.914181e-009,-4.364900e-002,3.555535e-004,3,9.427148e-001,1.825000e+000,,,,,,,,,,,,,,,,,,0,4.000000e+000,1.000000e+000,2,2,1.783142e-001,0,,0,
1654681959.628,,1.000000e+003,3.361145e+002,3.986194e-005,6.510845e-009,-4.492543e-002,3.486466e-004,3,9.422029e-001,1.825000e+000,,,,,,,,,,,,,,,,,,0,4.000000e+000,1.000000e+000,2,2,2.166748e-001,0,,0,
1654682081.272,,1.000000e+003,3.381405e+002,3.987920e-005,4.424596e-010,-4.572812e-002,6.667736e-004,3,9.420158e-001,1.825000e+000,,,,,,,,,,,,,,,,,,0,4.000000e+000,1.000000e+000,2,2,2.285767e-001,0,,0,
1654682200.920,,1.000000e+003,3.401276e+002,3.988721e-005,3.419287e-008,-4.698804e-002,4.549910e-004,3,9.427670e-001,1.825000e+000,,,,,,,,,,,,,,,,,,0,4.000000e+000,1.000000e+000,2,2,1.852112e-001,0,,0,
1654682320.922,,1.000000e+003,3.421372e+002,3.991603e-005,1.495102e-008,-4.751151e-002,7.839103e-004,3,9.426272e-001,1.825000e+000,,,,,,,,,,,,,,,,,,0,4.000000e+000,1.000000e+000,2,2,1.968994e-001,0,,0,
1654682440.100,,1.000000e+003,3.441199e+002,3.994208e-005,5.966773e-008,-4.988448e-002,1.228970e-003,3,9.422175e-001,1.825000e+000,,,,,,,,,,,,,,,,,,0,4.000000e+000,1.000000e+000,2,2,2.087097e-001,0,,0,
1654682558.785,,1.000000e+003,3.461100e+002,3.999488e-005,1.241202e-008,-5.119685e-002,6.015383e-004,3,9.432377e-001,1.825000e+000,,,,,,,,,,,,,,,,,,0,4.000000e+000,1.000000e+000,2,2,2.112122e-001,0,,0,
1654682680.714,,1.000000e+003,3.481418e+002,4.002891e-005,7.396021e-008,-5.149721e-002,6.090536e-004,3,9.426734e-001,1.825000e+000,,,,,,,,,,,,,,,,,,0,4.000000e+000,1.000000e+000,2,2,2.041931e-001,0,,0,
1654682800.664,,1.000000e+003,3.501371e+002,4.011051e-005,4.029984e-008,-5.289973e-002,7.454276e-004,3,9.433087e-001,1.825000e+000,,,,,,,,,,,,,,,,,,0,4.000000e+000,1.000000e+000,2,2,2.066956e-001,0,,0,
1654682920.590,,1.000000e+003,3.521343e+002,4.020156e-005,4.337390e-008,-5.411532e-002,2.784221e-003,3,9.429938e-001,1.825000e+000,,,,,,,,,,,,,,,,,,0,4.000000e+000,1.000000e+000,2,2,2.090759e-001,0,,0,
1654683039.477,,1.000000e+003,3.541229e+002,4.024429e-005,1.396835e-008,-5.418415e-002,4.789305e-004,3,9.432775e-001,1.825000e+000,,,,,,,,,,,,,,,,,,0,4.000000e+000,1.000000e+000,2,2,2.015991e-001,0,,0,
1654683158.887,,1.000000e+003,3.561173e+002,4.035805e-005,1.347701e-008,-5.642107e-002,8.990186e-005,3,9.440706e-001,1.825000e+000,,,,,,,,,,,,,,,,,,0,4.000000e+000,1.000000e+000,2,2,2.243958e-001,0,,0,
1654683279.310,,1.000000e+003,3.581252e+002,4.046123e-005,6.783266e-008,-5.778164e-002,5.161329e-004,3,9.447657e-001,1.825000e+000,,,,,,,,,,,,,,,,,,0,4.000000e+000,1.000000e+000,2,2,2.476196e-001,0,,0,
1654683399.510,,1.000000e+003,3.601361e+002,4.060009e-005,1.461146e-008,-5.870183e-002,4.047942e-005,3,9.434932e-001,1.825000e+000,,,,,,,,,,,,,,,,,,0,4.000000e+000,1.000000e+000,2,2,1.983948e-001,0,,0,
1654683519.159,,1.000000e+003,3.621286e+002,4.072380e-005,3.454787e-009,-6.062715e-002,7.770193e-004,3,9.452245e-001,1.825000e+000,,,,,,,,,,,,,,,,,,0,4.000000e+000,1.000000e+000,2,2,2.323914e-001,0,,0,
1654683637.822,,1.000000e+003,3.641016e+002,4.083761e-005,5.017801e-008,-6.001250e-002,1.464669e-003,3,9.452029e-001,1.825000e+000,,,,,,,,,,,,,,,,,,0,4.000000e+000,1.000000e+000,2,2,2.028809e-001,0,,0,
1654683759.506,,1.000000e+003,3.661296e+002,4.098412e-005,2.343235e-008,-6.179979e-002,8.170588e-004,3,9.444454e-001,1.825000e+000,,,,,,,,,,,,,,,,,,0,4.000000e+000,1.000000e+000,2,2,1.944885e-001,0,,0,
1654683879.265,,1.000000e+003,3.681377e+002,4.110545e-005,2.159306e-008,-6.191441e-002,1.639246e-003,3,9.444128e-001,1.825000e+000,,,,,,,,,,,,,,,,,,0,4.000000e+000,1.000000e+000,2,2,2.077026e-001,0,,0,
1654683999.433,,1.000000e+003,3.701330e+002,4.131994e-005,1.922641e-008,-6.561568e-002,9.774012e-004,3,9.451418e-001,1.825000e+000,,,,,,,,,,,,,,,,,,0,4.000000e+000,1.000000e+000,2,2,2.322998e-001,0,,0,
1654684118.314,,1.000000e+003,3.721232e+002,4.149873e-005,1.366994e-008,-6.606656e-002,1.885729e-003,3,9.455183e-001,1.825000e+000,,,,,,,,,,,,,,,,,,0,4.000000e+000,1.000000e+000,2,2,1.900024e-001,0,,0,
1654684240.011,,1.000000e+003,3.741471e+002,4.179719e-005,2.393655e-008,-6.736410e-002,1.291732e-003,3,9.458759e-001,1.825000e+000,,,,,,,,,,,,,,,,,,0,4.000000e+000,1.000000e+000,2,2,2.148743e-001,0,,0,
1654684358.481,,1.000000e+003,3.761256e+002,4.210005e-005,5.581936e-008,-6.822734e-002,1.213882e-003,3,9.466841e-001,1.825000e+000,,,,,,,,,,,,,,,,,,0,4.000000e+000,1.000000e+000,2,2,1.942749e-001,0,,0,
1654684477.862,,1.000000e+003,3.781202e+002,4.319145e-005,3.046540e-008,-7.382332e-002,3.629060e-003,3,9.487389e-001,1.825000e+000,,,,,,,,,,,,,,,,,,0,4.000000e+000,1.000000e+000,2,2,2.080994e-001,0,,0,
1654684598.834,,1.000000e+003,3.801429e+002,4.650901e-005,2.178676e-007,-8.296243e-002,1.947606e-004,3,9.532448e-001,1.825000e+000,,,,,,,,,,,,,,,,,,0,4.000000e+000,1.000000e+000,2,2,2.104187e-001,0,,0,
1654684718.716,,1.000000e+003,3.821468e+002,5.580713e-005,4.343693e-007,-1.021294e-001,3.618728e-004,3,9.602368e-001,1.825000e+000,,,,,,,,,,,,,,,,,,0,4.000000e+000,1.000000e+000,2,2,2.245178e-001,0,,0,
1654684837.845,,1.000000e+003,3.841191e+002,6.785206e-005,4.215456e-007,-1.192748e-001,3.690641e-004,3,9.687750e-001,1.825000e+000,,,,,,,,,,,,,,,,,,0,4.000000e+000,1.000000e+000,2,2,2.030945e-001,0,,0,
1654684958.005,,1.000000e+003,3.861429e+002,8.015551e-005,5.854307e-007,-1.299560e-001,4.306670e-004,3,9.743073e-001,1.825000e+000,,,,,,,,,,,,,,,,,,0,4.000000e+000,1.000000e+000,2,2,1.810913e-001,0,,0,
1654685077.168,,1.000000e+003,3.881281e+002,9.704049e-005,6.741592e-007,-1.405986e-001,9.366926e-004,3,9.795200e-001,1.825000e+000,,,,,,,,,,,,,,,,,,0,4.000000e+000,1.000000e+000,2,2,2.074890e-001,0,,0,
1654685195.587,,1.000000e+003,3.901006e+002,1.117189e-004,3.120163e-007,-1.484118e-001,4.280750e-004,3,9.824376e-001,1.825000e+000,,,,,,,,,,,,,,,,,,0,4.000000e+000,1.000000e+000,2,2,1.972961e-001,0,,0,
1654685318.467,,1.000000e+003,3.921470e+002,1.185422e-004,1.833995e-007,-1.503490e-001,1.384945e-004,3,9.832256e-001,1.825000e+000,,,,,,,,,,,,,,,,,,0,4.000000e+000,1.000000e+000,2,2,1.994934e-001,0,,0,
1654685436.453,,1.000000e+003,3.941025e+002,1.219782e-004,3.316389e-008,-1.511425e-001,2.254119e-004,3,9.842355e-001,1.825000e+000,,,,,,,,,,,,,,,,,,0,4.000000e+000,1.000000e+000,2,2,2.015076e-001,0,,0,
1654685555.797,,1.000000e+003,3.961098e+002,1.218548e-004,9.144508e-008,-1.488337e-001,7.775145e-004,3,9.818282e-001,1.825000e+000,,,,,,,,,,,,,,,,,,0,4.000000e+000,1.000000e+000,2,2,1.654053e-001,0,,0,
1654685677.746,,1.000000e+003,3.981353e+002,1.235929e-004,5.173690e-008,-1.492989e-001,2.553361e-004,3,9.828150e-001,1.825000e+000,,,,,,,,,,,,,,,,,,0,4.000000e+000,1.000000e+000,2,2,2.310791e-001,0,,0,
1654686042.473,,1.000000e+003,3.999784e+002,1.258413e-004,3.107507e-009,-1.471178e-001,5.181955e-004,3,9.827384e-001,1.825000e+000,,,,,,,,,,,,,,,,,,0,4.000000e+000,1.000000e+000,2,2,3.878784e-002,0,,0,
1654686362.931,,1.000000e+003,3.988747e+002,1.264019e-004,4.908225e-009,-1.450250e-001,2.304800e-004,3,9.825735e-001,1.825000e+000,,,,,,,,,,,,,,,,,,0,4.000000e+000,1.000000e+000,2,2,2.575989e-001,0,,0,
1654686449.827,,1.000000e+003,3.967914e+002,1.267070e-004,5.247776e-009,-1.433845e-001,4.136502e-004,3,9.830841e-001,1.825000e+000,,,,,,,,,,,,,,,,,,0,4.000000e+000,1.000000e+000,2,2,3.828125e-001,0,,0,
1654686506.954,,1.000000e+003,3.947242e+002,1.270423e-004,1.413813e-008,-1.420077e-001,2.720579e-005,3,9.829887e-001,1.825000e+000,,,,,,,,,,,,,,,,,,0,4.000000e+000,1.000000e+000,2,2,4.676208e-001,0,,0,
1654686562.184,,1.000000e+003,3.927310e+002,1.273911e-004,2.634178e-009,-1.400083e-001,3.390714e-005,3,9.824479e-001,1.825000e+000,,,,,,,,,,,,,,,,,,0,4.000000e+000,1.000000e+000,2,2,4.629211e-001,0,,0,
1654686628.128,,1.000000e+003,3.908020e+002,1.275759e-004,1.651506e-008,-1.394804e-001,1.869107e-004,3,9.827631e-001,1.825000e+000,,,,,,,,,,,,,,,,,,0,4.000000e+000,1.000000e+000,2,2,3.342896e-001,0,,0,
1654686947.525,,1.000000e+003,3.889263e+002,1.273498e-004,1.769838e-009,-1.389732e-001,8.185972e-005,3,9.819540e-001,1.825000e+000,,,,,,,,,,,,,,,,,,0,4.000000e+000,1.000000e+000,2,2,1.226196e-001,0,,0,
1654687071.955,,1.000000e+003,3.868145e+002,1.277448e-004,2.035314e-008,-1.377195e-001,7.967862e-005,3,9.814330e-001,1.825000e+000,,,,,,,,,,,,,,,,,,0,4.000000e+000,1.000000e+000,2,2,3.031006e-001,0,,0,
1654687151.184,,1.000000e+003,3.848253e+002,1.281484e-004,1.175811e-007,-1.367624e-001,1.799354e-004,3,9.816492e-001,1.825000e+000,,,,,,,,,,,,,,,,,,0,4.000000e+000,1.000000e+000,2,2,3.237915e-001,0,,0,
1654687245.087,,1.000000e+003,3.828869e+002,1.284038e-004,4.941142e-008,-1.358072e-001,1.303392e-005,3,9.818906e-001,1.825000e+000,,,,,,,,,,,,,,,,,,0,4.000000e+000,1.000000e+000,2,2,2.254028e-001,0,,0,
1654687393.291,,1.000000e+003,3.808837e+002,1.287883e-004,8.516832e-008,-1.348277e-001,1.833388e-006,3,9.818442e-001,1.825000e+000,,,,,,,,,,,,,,,,,,0,4.000000e+000,1.000000e+000,2,2,1.643982e-001,0,,0,
1654687524.496,,1.000000e+003,3.788848e+002,1.291409e-004,3.746501e-008,-1.341555e-001,2.767362e-004,3,9.816453e-001,1.825000e+000,,,,,,,,,,,,,,,,,,0,4.000000e+000,1.000000e+000,2,2,2.204895e-001,0,,0,
1654687637.653,,1.000000e+003,3.768932e+002,1.293363e-004,4.735347e-008,-1.328318e-001,5.077115e-004,3,9.812170e-001,1.825000e+000,,,,,,,,,,,,,,,,,,0,4.000000e+000,1.000000e+000,2,2,1.952209e-001,0,,0,
1654687756.044,,1.000000e+003,3.748808e+002,1.292855e-004,1.644303e-008,-1.319307e-001,4.311623e-005,3,9.813596e-001,1.825000e+000,,,,,,,,,,,,,,,,,,0,4.000000e+000,1.000000e+000,2,2,2.043762e-001,0,,0,
1654687879.923,,1.000000e+003,3.728795e+002,1.291751e-004,4.113845e-008,-1.309491e-001,3.369325e-004,3,9.802976e-001,1.825000e+000,,,,,,,,,,,,,,,,,,0,4.000000e+000,1.000000e+000,2,2,2.132874e-001,0,,0,
1654688003.080,,1.000000e+003,3.708698e+002,1.292734e-004,6.243825e-008,-1.303239e-001,3.174185e-004,3,9.804270e-001,1.825000e+000,,,,,,,,,,,,,,,,,,0,4.000000e+000,1.000000e+000,2,2,2.109070e-001,0,,0,
1654688122.521,,1.000000e+003,3.688744e+002,1.292183e-004,4.836186e-009,-1.298706e-001,1.119736e-004,3,9.805984e-001,1.825000e+000,,,,,,,,,,,,,,,,,,0,4.000000e+000,1.000000e+000,2,2,1.976013e-001,0,,0,
1654688243.233,,1.000000e+003,3.668660e+002,1.290212e-004,1.832606e-008,-1.293027e-001,6.421073e-005,3,9.807024e-001,1.825000e+000,,,,,,,,,,,,,,,,,,0,4.000000e+000,1.000000e+000,2,2,2.387085e-001,0,,0,
1654688363.632,,1.000000e+003,3.648643e+002,1.285784e-004,1.707071e-008,-1.289262e-001,6.958234e-004,3,9.806933e-001,1.825000e+000,,,,,,,,,,,,,,,,,,0,4.000000e+000,1.000000e+000,2,2,1.930847e-001,0,,0,
1654688484.290,,1.000000e+003,3.628801e+002,1.278038e-004,8.376892e-008,-1.283633e-001,1.848139e-005,3,9.803255e-001,1.825000e+000,,,,,,,,,,,,,,,,,,0,4.000000e+000,1.000000e+000,2,2,2.120972e-001,0,,0,
1654688605.477,,1.000000e+003,3.608737e+002,1.264848e-004,5.476209e-008,-1.277233e-001,3.102430e-004,3,9.803590e-001,1.825000e+000,,,,,,,,,,,,,,,,,,0,4.000000e+000,1.000000e+000,2,2,2.203064e-001,0,,0,
1654688725.106,,1.000000e+003,3.588775e+002,1.242116e-004,1.309269e-007,-1.276868e-001,1.188225e-004,3,9.801066e-001,1.825000e+000,,,,,,,,,,,,,,,,,,0,4.000000e+000,1.000000e+000,2,2,2.177124e-001,0,,0,
1654688846.061,,1.000000e+003,3.568710e+002,1.196311e-004,3.637481e-007,-1.276756e-001,4.787882e-004,3,9.795997e-001,1.825000e+000,,,,,,,,,,,,,,,,,,0,4.000000e+000,1.000000e+000,2,2,2.253113e-001,0,,0,
1654688966.442,,1.000000e+003,3.548804e+002,1.089542e-004,3.549246e-007,-1.295730e-001,8.402290e-004,3,9.772729e-001,1.825000e+000,,,,,,,,,,,,,,,,,,0,4.000000e+000,1.000000e+000,2,2,2.225952e-001,0,,0,
1654689086.136,,1.000000e+003,3.528929e+002,9.197379e-005,1.717371e-006,-1.256359e-001,3.619150e-004,3,9.731817e-001,1.825000e+000,,,,,,,,,,,,,,,,,,0,4.000000e+000,1.000000e+000,2,2,1.901245e-001,0,,0,
1654689208.142,,1.000000e+003,3.508546e+002,4.337506e-005,3.582945e-007,-4.720460e-002,1.259922e-003,3,9.468575e-001,1.825000e+000,,,,,,,,,,,,,,,,,,0,4.000000e+000,1.000000e+000,2,2,2.174988e-001,0,,0,
1654689326.578,,1.000000e+003,3.488872e+002,4.172419e-005,3.081783e-009,-4.296578e-002,1.723221e-003,3,9.449921e-001,1.825000e+000,,,,,,,,,,,,,,,,,,0,4.000000e+000,1.000000e+000,2,2,2.051086e-001,0,,0,
1654689447.769,,1.000000e+003,3.468657e+002,4.129896e-005,5.605860e-008,-4.069121e-002,4.121066e-004,3,9.426106e-001,1.825000e+000,,,,,,,,,,,,,,,,,,0,4.000000e+000,1.000000e+000,2,2,2.122192e-001,0,,0,
1654689569.234,,1.000000e+003,3.448544e+002,4.111108e-005,4.009404e-008,-4.032641e-002,9.813340e-004,3,9.438828e-001,1.825000e+000,,,,,,,,,,,,,,,,,,0,4.000000e+000,1.000000e+000,2,2,2.001953e-001,0,,0,
1654689688.359,,1.000000e+003,3.428888e+002,4.091538e-005,3.418258e-008,-3.843933e-002,6.848626e-004,3,9.439876e-001,1.825000e+000,,,,,,,,,,,,,,,,,,0,4.000000e+000,1.000000e+000,2,2,1.978149e-001,0,,0,
1654689808.555,,1.000000e+003,3.408885e+002,4.086456e-005,9.235058e-009,-3.680255e-002,3.263641e-004,3,9.430828e-001,1.825000e+000,,,,,,,,,,,,,,,,,,0,4.000000e+000,1.000000e+000,2,2,2.047119e-001,0,,0,
1654689929.932,,1.000000e+003,3.388736e+002,4.083750e-005,8.489051e-010,-3.597925e-002,8.567401e-005,3,9.430764e-001,1.825000e+000,,,,,,,,,,,,,,,,,,0,4.000000e+000,1.000000e+000,2,2,2.204895e-001,0,,0,
1654690050.867,,1.000000e+003,3.368655e+002,4.082626e-005,2.118147e-008,-3.554011e-002,2.617030e-004,3,9.434818e-001,1.825000e+000,,,,,,,,,,,,,,,,,,0,4.000000e+000,1.000000e+000,2,2,1.996155e-001,0,,0,
1654690170.021,,1.000000e+003,3.348894e+002,4.081850e-005,2.227218e-008,-3.418437e-002,2.679064e-004,3,9.437127e-001,1.825000e+000,,,,,,,,,,,,,,,,,,0,4.000000e+000,1.000000e+000,2,2,1.791992e-001,0,,0,
1654690290.464,,1.000000e+003,3.328932e+002,4.079952e-005,2.921262e-008,-3.227291e-002,2.535396e-004,3,9.431392e-001,1.825000e+000,,,,,,,,,,,,,,,,,,0,4.000000e+000,1.000000e+000,2,2,2.034912e-001,0,,0,
1654690413.139,,1.000000e+003,3.308522e+002,4.082160e-005,4.272823e-009,-3.266720e-002,9.717220e-005,3,9.438246e-001,1.825000e+000,,,,,,,,,,,,,,,,,,0,4.000000e+000,1.000000e+000,2,2,2.269897e-001,0,,0,
1654690531.014,,1.000000e+003,3.288807e+002,4.084755e-005,4.778564e-008,-3.150562e-002,9.553927e-004,3,9.427972e-001,1.825000e+000,,,,,,,,,,,,,,,,,,0,4.000000e+000,1.000000e+000,2,2,1.984253e-001,0,,0,
1654690650.962,,1.000000e+003,3.268850e+002,4.084400e-005,9.857589e-009,-3.123522e-002,1.307674e-003,3,9.429083e-001,1.825000e+000,,,,,,,,,,,,,,,,,,0,4.000000e+000,1.000000e+000,2,2,2.126770e-001,0,,0,
1654690773.158,,1.000000e+003,3.248667e+002,4.092404e-005,2.163164e-008,-3.095654e-002,3.800408e-004,3,9.430581e-001,1.825000e+000,,,,,,,,,,,,,,,,,,0,4.000000e+000,1.000000e+000,2,2,2.183838e-001,0,,0,
1654690892.282,,1.000000e+003,3.228788e+002,4.095471e-005,3.159213e-008,-2.994989e-002,2.184629e-004,3,9.429830e-001,1.825000e+000,,,,,,,,,,,,,,,,,,0,4.000000e+000,1.000000e+000,2,2,2.071838e-001,0,,0,
1654691013.721,,1.000000e+003,3.208531e+002,4.104171e-005,5.106293e-009,-2.857980e-002,6.817147e-004,3,9.430332e-001,1.825000e+000,,,,,,,,,,,,,,,,,,0,4.000000e+000,1.000000e+000,2,2,2.207947e-001,0,,0,
1654691134.959,,1.000000e+003,3.188343e+002,4.106886e-005,6.482547e-010,-2.859345e-002,5.379097e-004,3,9.431365e-001,1.825000e+000,,,,,,,,,,,,,,,,,,0,4.000000e+000,1.000000e+000,2,2,2.017212e-001,0,,0,
1654691252.966,,1.000000e+003,3.168900e+002,4.112193e-005,2.747365e-009,-2.786891e-002,8.956837e-004,3,9.437356e-001,1.825000e+000,,,,,,,,,,,,,,,,,,0,4.000000e+000,1.000000e+000,2,2,2.149963e-001,0,,0,
1654691374.120,,1.000000e+003,3.148688e+002,4.121581e-005,4.465755e-009,-2.669365e-002,4.242265e-004,3,9.434684e-001,1.825000e+000,,,,,,,,,,,,,,,,,,0,4.000000e+000,1.000000e+000,2,2,2.120972e-001,0,,0,
1654691494.548,,1.000000e+003,3.128748e+002,4.129055e-005,1.443396e-008,-2.594178e-002,2.032058e-004,3,9.429511e-001,1.825000e+000,,,,,,,,,,,,,,,,,,0,4.000000e+000,1.000000e+000,2,2,2.247925e-001,0,,0,
1654691613.197,,1.000000e+003,3.108829e+002,4.138811e-005,3.205774e-008,-2.588507e-002,1.110938e-004,3,9.436280e-001,1.825000e+000,,,,,,,,,,,,,,,,,,0,4.000000e+000,1.000000e+000,2,2,2.140808e-001,0,,0,
1654691732.888,,1.000000e+003,3.088820e+002,4.145165e-005,4.054679e-008,-2.316879e-002,4.299242e-004,3,9.423649e-001,1.825000e+000,,,,,,,,,,,,,,,,,,0,4.000000e+000,1.000000e+000,2,2,2.111816e-001,0,,0,
1654691854.340,,1.000000e+003,3.068602e+002,4.156093e-005,6.010247e-008,-2.446317e-002,1.138484e-003,3,9.430430e-001,1.825000e+000,,,,,,,,,,,,,,,,,,0,4.000000e+000,1.000000e+000,2,2,1.933899e-001,0,,0,
1654691973.772,,1.000000e+003,3.048775e+002,4.164374e-005,1.976663e-008,-2.327478e-002,1.079815e-004,3,9.438125e-001,1.825000e+000,,,,,,,,,,,,,,,,,,0,4.000000e+000,1.000000e+000,2,2,2.053223e-001,0,,0,
1654692092.337,,1.000000e+003,3.029022e+002,4.175986e-005,3.472889e-010,-2.333735e-002,1.550272e-003,3,9.442806e-001,1.825000e+000,,,,,,,,,,,,,,,,,,0,4.000000e+000,1.000000e+000,2,2,2.096863e-001,0,,0,
1654692213.475,,1.000000e+003,3.008721e+002,4.189750e-005,5.408297e-008,-2.235615e-002,9.975869e-004,3,9.438796e-001,1.825000e+000,,,,,,,,,,,,,,,,,,0,4.000000e+000,1.000000e+000,2,2,2.138062e-001,0,,0,
1654692811.629,,1.000000e+003,3.000212e+002,4.189515e-005,3.501347e-008,-2.315620e-002,1.904911e-003,3,9.440506e-001,1.825000e+000,,,,,,,,,,,,,,,,,,0,4.000000e+000,1.000000e+000,2,2,2.130127e-002,0,,0,
1654692970.006,,1.000000e+003,3.021378e+002,4.175097e-005,2.201494e-008,-2.470936e-002,5.187750e-005,3,9.429500e-001,1.825000e+000,,,,,,,,,,,,,,,,,,0,4.000000e+000,1.000000e+000,2,2,2.518005e-001,0,,0,
1654693072.385,,1.000000e+003,3.041351e+002,4.162692e-005,3.716918e-008,-2.602958e-002,4.952123e-005,3,9.430229e-001,1.825000e+000,,,,,,,,,,,,,,,,,,0,4.000000e+000,1.000000e+000,2,2,2.041931e-001,0,,0,
1654693189.068,,1.000000e+003,3.061666e+002,4.155739e-005,1.921870e-008,-2.745165e-002,1.921725e-004,3,9.434882e-001,1.825000e+000,,,,,,,,,,,,,,,,,,0,4.000000e+000,1.000000e+000,2,2,2.073059e-001,0,,0,
1654693308.758,,1.000000e+003,3.081355e+002,4.143672e-005,3.206289e-008,-2.892069e-002,1.378346e-003,3,9.446640e-001,1.825000e+000,,,,,,,,,,,,,,,,,,0,4.000000e+000,1.000000e+000,2,2,2.326050e-001,0,,0,
1654693430.139,,1.000000e+003,3.101488e+002,4.128412e-005,2.716496e-009,-2.852295e-002,3.782956e-004,3,9.428994e-001,1.825000e+000,,,,,,,,,,,,,,,,,,0,4.000000e+000,1.000000e+000,2,2,1.976929e-001,0,,0,
1654693547.766,,1.000000e+003,3.121133e+002,4.122064e-005,4.335589e-008,-2.885856e-002,9.452616e-005,3,9.433187e-001,1.825000e+000,,,,,,,,,,,,,,,,,,0,4.000000e+000,1.000000e+000,2,2,2.081909e-001,0,,0,
1654693667.391,,1.000000e+003,3.141145e+002,4.108790e-005,6.688343e-010,-3.177134e-002,6.180229e-004,3,9.427063e-001,1.825000e+000,,,,,,,,,,,,,,,,,,0,4.000000e+000,1.000000e+000,2,2,2.190247e-001,0,,0,
1654693788.035,,1.000000e+003,3.161373e+002,4.104593e-005,1.367252e-008,-3.087278e-002,2.868080e-004,3,9.424696e-001,1.825000e+000,,,,,,,,,,,,,,,,,,0,4.000000e+000,1.000000e+000,2,2,1.901855e-001,0,,0,
1654693907.425,,1.000000e+003,3.181238e+002,4.089256e-005,4.259960e-009,-3.211883e-002,9.438023e-004,3,9.429448e-001,1.825000e+000,,,,,,,,,,,,,,,,,,0,4.000000e+000,1.000000e+000,2,2,1.928101e-001,0,,0,
1654694027.301,,1.000000e+003,3.201208e+002,4.083778e-005,3.333882e-009,-3.311762e-002,4.583812e-004,3,9.422075e-001,1.825000e+000,,,,,,,,,,,,,,,,,,0,4.000000e+000,1.000000e+000,2,2,2.197876e-001,0,,0,
1654694148.992,,1.000000e+003,3.221654e+002,4.076410e-005,2.383622e-008,-3.513680e-002,4.673058e-004,3,9.426450e-001,1.825000e+000,,,,,,,,,,,,,,,,,,0,4.000000e+000,1.000000e+000,2,2,2.062988e-001,0,,0,
1654694266.651,,1.000000e+003,3.241190e+002,4.069166e-005,1.188982e-008,-3.521784e-002,1.899244e-006,3,9.436690e-001,1.825000e+000,,,,,,,,,,,,,,,,,,0,4.000000e+000,1.000000e+000,2,2,2.089233e-001,0,,0,
1654694386.352,,1.000000e+003,3.261190e+002,4.066163e-005,5.186038e-009,-3.624072e-002,3.899637e-004,3,9.430565e-001,1.825000e+000,,,,,,,,,,,,,,,,,,0,4.000000e+000,1.000000e+000,2,2,2.370911e-001,0,,0,
1654694506.486,,1.000000e+003,3.281325e+002,4.058504e-005,9.389404e-009,-3.651526e-002,8.506367e-004,3,9.421389e-001,1.825000e+000,,,,,,,,,,,,,,,,,,0,4.000000e+000,1.000000e+000,2,2,1.972961e-001,0,,0,
1654694626.665,,1.000000e+003,3.301271e+002,4.050625e-005,4.167352e-009,-3.723904e-002,9.993913e-004,3,9.428077e-001,1.825000e+000,,,,,,,,,,,,,,,,,,0,4.000000e+000,1.000000e+000,2,2,2.171936e-001,0,,0,
1654694746.550,,1.000000e+003,3.321212e+002,4.050474e-005,3.845025e-008,-3.890151e-002,7.613301e-004,3,9.426140e-001,1.825000e+000,,,,,,,,,,,,,,,,,,0,4.000000e+000,1.000000e+000,2,2,2.376099e-001,0,,0,
1654694866.981,,1.000000e+003,3.341410e+002,4.043531e-005,2.654243e-008,-3.914554e-002,6.975303e-006,3,9.428521e-001,1.825000e+000,,,,,,,,,,,,,,,,,,0,4.000000e+000,1.000000e+000,2,2,2.049866e-001,0,,0,
1654694985.393,,1.000000e+003,3.361077e+002,4.039063e-005,2.421952e-008,-3.963984e-002,6.421073e-004,3,9.425223e-001,1.825000e+000,,,,,,,,,,,,,,,,,,0,4.000000e+000,1.000000e+000,2,2,2.075806e-001,0,,0,
1654695107.351,,1.000000e+003,3.381542e+002,4.041048e-005,7.547538e-009,-4.116724e-002,1.749647e-004,3,9.435526e-001,1.825000e+000,,,,,,,,,,,,,,,,,,0,4.000000e+000,1.000000e+000,2,2,2.193909e-001,0,,0,
1654695227.258,,1.000000e+003,3.401484e+002,4.038148e-005,8.360428e-009,-4.233773e-002,5.210141e-004,3,9.432909e-001,1.825000e+000,,,,,,,,,,,,,,,,,,0,4.000000e+000,1.000000e+000,2,2,1.943970e-001,0,,0,
1654695345.640,,1.000000e+003,3.421232e+002,4.036766e-005,7.848513e-009,-4.351047e-002,1.592729e-003,3,9.432756e-001,1.825000e+000,,,,,,,,,,,,,,,,,,0,4.000000e+000,1.000000e+000,2,2,2.155151e-001,0,,0,
1654695465.104,,1.000000e+003,3.441175e+002,4.034823e-005,2.278924e-008,-4.424248e-002,5.049482e-004,3,9.432370e-001,1.825000e+000,,,,,,,,,,,,,,,,,,0,4.000000e+000,1.000000e+000,2,2,2.371826e-001,0,,0,
1654695585.086,,1.000000e+003,3.461221e+002,4.040026e-005,1.833892e-008,-4.553246e-002,6.245188e-004,3,9.434321e-001,1.825000e+000,,,,,,,,,,,,,,,,,,0,4.000000e+000,1.000000e+000,2,2,2.209778e-001,0,,0,
1654695705.711,,1.000000e+003,3.481418e+002,4.039327e-005,1.265640e-008,-4.645133e-002,3.654184e-004,3,9.429731e-001,1.825000e+000,,,,,,,,,,,,,,,,,,0,4.000000e+000,1.000000e+000,2,2,2.041931e-001,0,,0,
1654695824.451,,1.000000e+003,3.501076e+002,4.042867e-005,3.001265e-008,-4.830572e-002,9.163489e-004,3,9.441999e-001,1.825000e+000,,,,,,,,,,,,,,,,,,0,4.000000e+000,1.000000e+000,2,2,2.066040e-001,0,,0,
1654695944.581,,1.000000e+003,3.521119e+002,4.045411e-005,3.381215e-008,-4.922425e-002,1.139129e-003,3,9.431946e-001,1.825000e+000,,,,,,,,,,,,,,,,,,0,4.000000e+000,1.000000e+000,2,2,2.289734e-001,0,,0,
1654696064.460,,1.000000e+003,3.541229e+002,4.051690e-005,4.848020e-008,-5.016540e-002,1.470187e-004,3,9.428868e-001,1.825000e+000,,,,,,,,,,,,,,,,,,0,4.000000e+000,1.000000e+000,2,2,2.217102e-001,0,,0,
1654696183.447,,1.000000e+003,3.561148e+002,4.058880e-005,1.322234e-009,-5.109019e-002,1.256893e-003,3,9.442009e-001,1.825000e+000,,,,,,,,,,,,,,,,,,0,4.000000e+000,1.000000e+000,2,2,2.243958e-001,0,,0,
1654696305.078,,1.000000e+003,3.581303e+002,4.067819e-005,2.404202e-008,-5.244681e-002,1.042228e-003,3,9.439080e-001,1.825000e+000,,,,,,,,,,,,,,,,,,0,4.000000e+000,1.000000e+000,2,2,2.475891e-001,0,,0,
1654696424.460,,1.000000e+003,3.601309e+002,4.077539e-005,6.086392e-009,-5.358289e-002,1.253026e-003,3,9.449775e-001,1.825000e+000,,,,,,,,,,,,,,,,,,0,4.000000e+000,1.000000e+000,2,2,1.983948e-001,0,,0,
1654696544.114,,1.000000e+003,3.621259e+002,4.085239e-005,1.161456e-008,-5.487827e-002,4.649904e-004,3,9.438086e-001,1.825000e+000,,,,,,,,,,,,,,,,,,0,4.000000e+000,1.000000e+000,2,2,1.901245e-001,0,,0,
1654696663.661,,1.000000e+003,3.641123e+002,4.097187e-005,3.065062e-008,-5.615001e-002,1.865986e-003,3,9.442869e-001,1.825000e+000,,,,,,,,,,,,,,,,,,0,4.000000e+000,1.000000e+000,2,2,2.243042e-001,0,,0,
1654696784.052,,1.000000e+003,3.661350e+002,4.114111e-005,5.510165e-009,-5.798432e-002,2.245242e-004,3,9.444503e-001,1.825000e+000,,,,,,,,,,,,,,,,,,0,4.000000e+000,1.000000e+000,2,2,1.944885e-001,0,,0,
1654696903.977,,1.000000e+003,3.681240e+002,4.138007e-005,8.515032e-008,-5.828445e-002,4.257859e-004,3,9.472548e-001,1.825000e+000,,,,,,,,,,,,,,,,,,0,4.000000e+000,1.000000e+000,2,2,2.185974e-001,0,,0,
1654697024.857,,1.000000e+003,3.701386e+002,4.167834e-005,4.771618e-008,-6.008818e-002,2.056766e-003,3,9.449381e-001,1.825000e+000,,,,,,,,,,,,,,,,,,0,4.000000e+000,1.000000e+000,2,2,2.322998e-001,0,,0,
1654697145.487,,1.000000e+003,3.721567e+002,4.269581e-005,7.642461e-008,-6.376034e-002,1.260702e-003,3,9.466045e-001,1.825000e+000,,,,,,,,,,,,,,,,,,0,4.000000e+000,1.000000e+000,2,2,2.124939e-001,0,,0,
1654697263.189,,1.000000e+003,3.741273e+002,5.615526e-005,1.667507e-006,-8.954238e-002,3.597560e-003,3,9.607660e-001,1.825000e+000,,,,,,,,,,,,,,,,,,0,4.000000e+000,1.000000e+000,2,2,2.033997e-001,0,,0,
1654697383.212,,1.000000e+003,3.761227e+002,1.083997e-004,9.994493e-007,-1.366858e-001,7.471583e-004,3,9.775693e-001,1.825000e+000,,,,,,,,,,,,,,,,,,0,4.000000e+000,1.000000e+000,2,2,2.172852e-001,0,,0,
1654697503.869,,1.000000e+003,3.781491e+002,1.182201e-004,2.195628e-007,-1.396370e-001,1.594521e-004,3,9.795257e-001,1.825000e+000,,,,,,,,,,,,,,,,,,0,4.000000e+000,1.000000e+000,2,2,1.735229e-001,0,,0,
1654697623.765,,1.000000e+003,3.801399e+002,1.214891e-004,1.204262e-007,-1.403040e-001,1.615173e-004,3,9.804839e-001,1.825000e+000,,,,,,,,,,,,,,,,,,0,4.000000e+000,1.000000e+000,2,2,1.871033e-001,0,,0,
1654697742.448,,1.000000e+003,3.821232e+002,1.235031e-004,7.953989e-009,-1.408123e-001,5.726703e-005,3,9.812839e-001,1.825000e+000,,,,,,,,,,,,,,,,,,0,4.000000e+000,1.000000e+000,2,2,2.481079e-001,0,,0,
1654697863.892,,1.000000e+003,3.841580e+002,1.247524e-004,4.846476e-008,-1.408591e-001,1.837181e-004,3,9.817668e-001,1.825000e+000,,,,,,,,,,,,,,,,,,0,4.000000e+000,1.000000e+000,2,2,1.911926e-001,0,,0,
1654697983.602,,1.000000e+003,3.861460e+002,1.256881e-004,2.870842e-008,-1.414469e-001,1.051353e-004,3,9.825532e-001,1.825000e+000,,,,,,,,,,,,,,,,,,0,4.000000e+000,1.000000e+000,2,2,2.174072e-001,0,,0,
1654698104.257,,1.000000e+003,3.881555e+002,1.261890e-004,2.061039e-008,-1.419376e-001,6.889956e-005,3,9.824026e-001,1.825000e+000,,,,,,,,,,,,,,,,,,0,4.000000e+000,1.000000e+000,2,2,2.319031e-001,0,,0,
1654698221.655,,1.000000e+003,3.901222e+002,1.259029e-004,8.777169e-009,-1.425167e-001,4.815289e-006,3,9.818728e-001,1.825000e+000,,,,,,,,,,,,,,,,,,0,4.000000e+000,1.000000e+000,2,2,2.219849e-001,0,,0,
1654698342.099,,1.000000e+003,3.921284e+002,1.260480e-004,3.360635e-008,-1.425588e-001,2.523542e-004,3,9.819974e-001,1.825000e+000,,,,,,,,,,,,,,,,,,0,4.000000e+000,1.000000e+000,2,2,1.994934e-001,0,,0,
1654698460.531,,1.000000e+003,3.940931e+002,1.260299e-004,2.302848e-008,-1.429804e-001,3.463839e-004,3,9.823416e-001,1.825000e+000,,,,,,,,,,,,,,,,,,0,4.000000e+000,1.000000e+000,2,2,1.889038e-001,0,,0,
1654698581.729,,1.000000e+003,3.961130e+002,1.260257e-004,2.489093e-008,-1.432355e-001,2.306381e-004,3,9.826745e-001,1.825000e+000,,,,,,,,,,,,,,,,,,0,4.000000e+000,1.000000e+000,2,2,2.162781e-001,0,,0,
1654698703.153,,1.000000e+003,3.981417e+002,1.259285e-004,6.070957e-009,-1.434903e-001,1.877010e-004,3,9.828095e-001,1.825000e+000,,,,,,,,,,,,,,,,,,0,4.000000e+000,1.000000e+000,2,2,2.052917e-001,0,,0,
1654699067.797,,1.000000e+003,3.999816e+002,1.262000e-004,1.419987e-009,-1.423909e-001,1.753309e-005,3,9.832543e-001,1.825000e+000,,,,,,,,,,,,,,,,,,0,4.000000e+000,1.000000e+000,2,2,1.300049e-002,0,,0,
1654699388.445,,1.000000e+003,3.988650e+002,1.264336e-004,2.973758e-009,-1.400033e-001,3.607349e-004,3,9.830880e-001,1.825000e+000,,,,,,,,,,,,,,,,,,0,4.000000e+000,1.000000e+000,2,2,2.447205e-001,0,,0,
1654699476.130,,1.000000e+003,3.967819e+002,1.266933e-004,7.763622e-008,-1.381422e-001,3.270490e-004,3,9.824945e-001,1.825000e+000,,,,,,,,,,,,,,,,,,0,4.000000e+000,1.000000e+000,2,2,4.210205e-001,0,,0,
1654699533.596,,1.000000e+003,3.947431e+002,1.270381e-004,9.320463e-008,-1.367164e-001,1.011524e-004,3,9.827436e-001,1.825000e+000,,,,,,,,,,,,,,,,,,0,4.000000e+000,1.000000e+000,2,2,5.056152e-001,0,,0,
1654699591.222,,1.000000e+003,3.927560e+002,1.274739e-004,5.772563e-009,-1.359993e-001,1.117418e-004,3,9.825261e-001,1.825000e+000,,,,,,,,,,,,,,,,,,0,4.000000e+000,1.000000e+000,2,2,3.878174e-001,0,,0,
1654699662.098,,1.000000e+003,3.908237e+002,1.276533e-004,6.616315e-008,-1.348766e-001,3.617148e-004,3,9.824454e-001,1.825000e+000,,,,,,,,,,,,,,,,,,0,4.000000e+000,1.000000e+000,2,2,2.723999e-001,0,,0,
1654699984.243,,1.000000e+003,3.888802e+002,1.275431e-004,4.867066e-009,-1.345403e-001,5.072900e-004,3,9.817669e-001,1.825000e+000,,,,,,,,,,,,,,,,,,0,4.000000e+000,1.000000e+000,2,2,1.837769e-001,0,,0,
1654700091.873,,1.000000e+003,3.867781e+002,1.279544e-004,4.123106e-008,-1.335392e-001,1.277050e-005,3,9.819490e-001,1.825000e+000,,,,,,,,,,,,,,,,,,0,4.000000e+000,1.000000e+000,2,2,3.392944e-001,0,,0,
1654700169.749,,1.000000e+003,3.848283e+002,1.283279e-004,5.224110e-008,-1.321087e-001,1.623813e-004,3,9.820002e-001,1.825000e+000,,,,,,,,,,,,,,,,,,0,4.000000e+000,1.000000e+000,2,2,2.997131e-001,0,,0,
1654700270.945,,1.000000e+003,3.828839e+002,1.286417e-004,4.420480e-008,-1.312568e-001,2.814672e-004,3,9.816819e-001,1.825000e+000,,,,,,,,,,,,,,,,,,0,4.000000e+000,1.000000e+000,2,2,2.135925e-001,0,,0,
1654700420.159,,1.000000e+003,3.808925e+002,1.291084e-004,2.315218e-009,-1.303529e-001,2.360224e-005,3,9.820554e-001,1.825000e+000,,,,,,,,,,,,,,,,,,0,4.000000e+000,1.000000e+000,2,2,1.761169e-001,0,,0,
1654700548.791,,1.000000e+003,3.788731e+002,1.293716e-004,4.879403e-008,-1.293821e-001,2.468752e-005,3,9.817908e-001,1.825000e+000,,,,,,,,,,,,,,,,,,0,4.000000e+000,1.000000e+000,2,2,2.204895e-001,0,,0,
1654700662.184,,1.000000e+003,3.768731e+002,1.296083e-004,2.156733e-008,-1.283115e-001,2.351056e-004,3,9.814672e-001,1.825000e+000,,,,,,,,,,,,,,,,,,0,4.000000e+000,1.000000e+000,2,2,2.066956e-001,0,,0,
1654700779.817,,1.000000e+003,3.749006e+002,1.295990e-004,9.466578e-010,-1.275055e-001,1.861626e-004,3,9.809263e-001,1.825000e+000,,,,,,,,,,,,,,,,,,0,4.000000e+000,1.000000e+000,2,2,1.930847e-001,0,,0,
1654700906.531,,1.000000e+003,3.728655e+002,1.296602e-004,1.027947e-007,-1.267746e-001,3.112966e-004,3,9.804103e-001,1.825000e+000,,,,,,,,,,,,,,,,,,0,4.000000e+000,1.000000e+000,2,2,1.797180e-001,0,,0,
1654701029.072,,1.000000e+003,3.708560e+002,1.297420e-004,1.151424e-008,-1.259027e-001,1.517181e-004,3,9.803686e-001,1.825000e+000,,,,,,,,,,,,,,,,,,0,4.000000e+000,1.000000e+000,2,2,2.442017e-001,0,,0,
1654701146.701,,1.000000e+003,3.688881e+002,1.298537e-004,4.343307e-008,-1.256317e-001,1.135858e-005,3,9.804080e-001,1.825000e+000,,,,,,,,,,,,,,,,,,0,4.000000e+000,1.000000e+000,2,2,1.867065e-001,0,,0,
1654701267.335,,1.000000e+003,3.668823e+002,1.298065e-004,4.645826e-008,-1.250537e-001,3.350675e-004,3,9.804146e-001,1.825000e+000,,,,,,,,,,,,,,,,,,0,4.000000e+000,1.000000e+000,2,2,2.170105e-001,0,,0,
1654701388.730,,1.000000e+003,3.648777e+002,1.295655e-004,6.673937e-008,-1.247923e-001,1.089796e-003,3,9.809581e-001,1.825000e+000,,,,,,,,,,,,,,,,,,0,4.000000e+000,1.000000e+000,2,2,2.038879e-001,0,,0,
1654701510.115,,1.000000e+003,3.628694e+002,1.290180e-004,3.737240e-008,-1.241731e-001,2.859927e-004,3,9.803473e-001,1.825000e+000,,,,,,,,,,,,,,,,,,0,4.000000e+000,1.000000e+000,2,2,2.122192e-001,0,,0,
1654701630.163,,1.000000e+003,3.608684e+002,1.280908e-004,1.605202e-009,-1.235878e-001,3.485597e-004,3,9.803874e-001,1.825000e+000,,,,,,,,,,,,,,,,,,0,4.000000e+000,1.000000e+000,2,2,1.782837e-001,0,,0,
1654701750.041,,1.000000e+003,3.588956e+002,1.266302e-004,7.621624e-008,-1.233047e-001,6.408428e-005,3,9.801557e-001,1.825000e+000,,,,,,,,,,,,,,,,,,0,4.000000e+000,1.000000e+000,2,2,2.073059e-001,0,,0,
1654701871.171,,1.000000e+003,3.568787e+002,1.238226e-004,1.923773e-007,-1.231939e-001,3.013500e-006,3,9.797580e-001,1.825000e+000,,,,,,,,,,,,,,,,,,0,4.000000e+000,1.000000e+000,2,2,2.149963e-001,0,,0,
1654701993.388,,1.000000e+003,3.548728e+002,1.170647e-004,3.666807e-007,-1.237577e-001,1.510806e-004,3,9.789143e-001,1.825000e+000,,,,,,,,,,,,,,,,,,0,4.000000e+000,1.000000e+000,2,2,2.124939e-001,0,,0,
1654702116.596,,1.000000e+003,3.528754e+002,1.076059e-004,4.579200e-007,-1.251840e-001,2.272137e-004,3,9.773047e-001,1.825000e+000,,,,,,,,,,,,,,,,,,0,4.000000e+000,1.000000e+000,2,2,2.100830e-001,0,,0,
1654702237.476,,1.000000e+003,3.508718e+002,6.912755e-005,2.627243e-006,-1.084159e-001,3.229871e-003,3,9.642566e-001,1.825000e+000,,,,,,,,,,,,,,,,,,0,4.000000e+000,1.000000e+000,2,2,2.074890e-001,0,,0,
1654702357.708,,1.000000e+003,3.488774e+002,4.246991e-005,6.048835e-008,-4.167708e-002,2.286730e-005,3,9.461153e-001,1.825000e+000,,,,,,,,,,,,,,,,,,0,4.000000e+000,1.000000e+000,2,2,2.247009e-001,0,,0,
1654702477.908,,1.000000e+003,3.468849e+002,4.146358e-005,3.143521e-009,-3.913706e-002,6.684253e-004,3,9.441985e-001,1.825000e+000,,,,,,,,,,,,,,,,,,0,4.000000e+000,1.000000e+000,2,2,1.929932e-001,0,,0,
1654702599.284,,1.000000e+003,3.448807e+002,4.106518e-005,4.535212e-009,-3.646518e-002,1.486777e-003,3,9.440538e-001,1.825000e+000,,,,,,,,,,,,,,,,,,0,4.000000e+000,1.000000e+000,2,2,1.907043e-001,0,,0,
1654702719.709,,1.000000e+003,3.428864e+002,4.087204e-005,1.544235e-008,-3.507884e-002,6.091115e-004,3,9.438758e-001,1.825000e+000,,,,,,,,,,,,,,,,,,0,4.000000e+000,1.000000e+000,2,2,2.070923e-001,0,,0,
1654702842.618,,1.000000e+003,3.408885e+002,4.075496e-005,1.137018e-008,-3.452864e-002,2.625538e-004,3,9.440120e-001,1.825000e+000,,,,,,,,,,,,,,,,,,0,4.000000e+000,1.000000e+000,2,2,2.047119e-001,0,,0,
1654702965.541,,1.000000e+003,3.388690e+002,4.069707e-005,2.491150e-008,-3.364778e-002,2.849891e-004,3,9.439888e-001,1.825000e+000,,,,,,,,,,,,,,,,,,0,4.000000e+000,1.000000e+000,2,2,2.203979e-001,0,,0,
1654703087.917,,1.000000e+003,3.368565e+002,4.060919e-005,2.814249e-009,-3.222030e-002,1.494132e-004,3,9.428020e-001,1.825000e+000,,,,,,,,,,,,,,,,,,0,4.000000e+000,1.000000e+000,2,2,2.358093e-001,0,,0,
1654703208.113,,1.000000e+003,3.348647e+002,4.061069e-005,4.978957e-008,-3.217543e-002,1.491653e-003,3,9.434717e-001,1.825000e+000,,,,,,,,,,,,,,,,,,0,4.000000e+000,1.000000e+000,2,2,2.060242e-001,0,,0,
1654703328.740,,1.000000e+003,3.328667e+002,4.066537e-005,6.330774e-008,-3.168669e-002,6.559367e-005,3,9.432610e-001,1.825000e+000,,,,,,,,,,,,,,,,,,0,4.000000e+000,1.000000e+000,2,2,2.299805e-001,0,,0,
1654703448.881,,1.000000e+003,3.308784e+002,4.065249e-005,3.776341e-009,-3.137426e-002,2.172565e-004,3,9.431781e-001,1.825000e+000,,,,,,,,,,,,,,,,,,0,4.000000e+000,1.000000e+000,2,2,2.095947e-001,0,,0,
1654703570.017,,1.000000e+003,3.288743e+002,4.070205e-005,1.329180e-008,-2.882351e-002,1.284926e-003,3,9.435354e-001,1.825000e+000,,,,,,,,,,,,,,,,,,0,4.000000e+000,1.000000e+000,2,2,2.070007e-001,0,,0,
1654703691.392,,1.000000e+003,3.268681e+002,4.068632e-005,1.348987e-008,-2.969078e-002,1.509898e-004,3,9.424795e-001,1.825000e+000,,,,,,,,,,,,,,,,,,0,4.000000e+000,1.000000e+000,2,2,1.957092e-001,0,,0,
1654703812.321,,1.000000e+003,3.248646e+002,4.072938e-005,3.347516e-008,-2.817235e-002,1.163102e-003,3,9.426917e-001,1.825000e+000,,,,,,,,,,,,,,,,,,0,4.000000e+000,1.000000e+000,2,2,2.099915e-001,0,,0,
1654703931.269,,1.000000e+003,3.228849e+002,4.083605e-005,4.775991e-008,-2.762536e-002,2.277537e-004,3,9.431422e-001,1.825000e+000,,,,,,,,,,,,,,,,,,0,4.000000e+000,1.000000e+000,2,2,2.155762e-001,0,,0,
1654704051.651,,1.000000e+003,3.208940e+002,4.085802e-005,2.119433e-008,-2.723689e-002,4.496674e-005,3,9.435337e-001,1.825000e+000,,,,,,,,,,,,,,,,,,0,4.000000e+000,1.000000e+000,2,2,1.882019e-001,0,,0,
1654704113.589,,1.000000e+003,3.198708e+002,4.087921e-005,9.759836e-009,-2.684258e-002,5.858412e-004,3,9.432533e-001,1.825000e+000,,,,,,,,,,,,,,,,,,0,4.000000e+000,1.000000e+000,2,2,2.031860e-001,0,,0,